ts_event,rtype,publisher_id,instrument_id,action,side,price,size,channel_id,order_id,flags,ts_in_delta,sequence,symbol
2025-09-24 19:41:47.028710863+00:00,160,1,432669,A,A,64.83,1,26,8058566367057,128,21977,94371240,CLX5
2025-09-24 19:41:47.028727411+00:00,160,1,432669,A,A,64.83,2,26,8058566367062,128,15055,94371245,CLX5
2025-09-24 19:41:47.028806413+00:00,160,1,432669,A,A,64.83,2,26,8058566367066,128,14297,94371249,CLX5
2025-09-24 19:41:47.028814613+00:00,160,1,432669,A,B,64.81,1,26,8058566367076,128,14967,94371272,CLX5
2025-09-24 19:41:47.028815805+00:00,160,1,432669,A,A,64.83,1,26,8058566367079,128,14715,94371278,CLX5
2025-09-24 19:41:47.028825001+00:00,160,1,432669,A,A,64.86,1,26,8058566367087,128,14946,94371289,CLX5
2025-09-24 19:41:47.028830051+00:00,160,1,432669,A,A,64.82,1,26,8058566367089,128,17806,94371290,CLX5
2025-09-24 19:41:47.028835755+00:00,160,1,432669,A,B,64.81,1,26,8058566367096,128,15292,94371302,CLX5
2025-09-24 19:41:47.028864571+00:00,160,1,432669,A,A,64.83,1,26,8058566367102,128,15358,94371322,CLX5
2025-09-24 19:41:47.028898725+00:00,160,1,432669,A,A,64.82,2,26,8058566367111,128,14755,94371330,CLX5
2025-09-24 19:41:47.028921305+00:00,160,1,432669,M,A,64.83,1,26,8058566173085,128,14867,94371333,CLX5
2025-09-24 19:41:47.028978653+00:00,160,1,432669,A,A,64.82,1,26,8058566367116,128,16113,94371336,CLX5
2025-09-24 19:41:47.029082309+00:00,160,1,432669,A,A,64.82,3,26,8058566367120,128,14689,94371344,CLX5
2025-09-24 19:41:47.029088895+00:00,160,1,432669,A,A,64.82,1,26,8058566367121,128,19530,94371349,CLX5
2025-09-24 19:41:47.029091063+00:00,160,1,432669,T,B,64.82,1,26,8058566367122,0,14633,94371350,CLX5
2025-09-24 19:41:47.029091063+00:00,160,1,432669,F,A,64.82,1,26,8058566367036,0,14633,94371350,CLX5
2025-09-24 19:41:47.029091063+00:00,160,1,432669,C,A,64.82,1,26,8058566367036,128,14633,94371350,CLX5
2025-09-24 19:41:47.029117999+00:00,160,1,432669,A,A,64.82,1,26,8058566367123,128,16253,94371353,CLX5
2025-09-24 19:41:47.029140059+00:00,160,1,432669,C,A,64.84,1,26,8058566364299,128,17939,94371354,CLX5
2025-09-24 19:41:47.029149371+00:00,160,1,432669,A,A,64.82,2,26,8058566367127,128,16047,94371361,CLX5
2025-09-24 19:41:47.029215243+00:00,160,1,432669,A,A,64.82,2,26,8058566367135,128,16139,94371370,CLX5
2025-09-24 19:41:47.029235305+00:00,160,1,432669,M,A,64.82,1,26,8058566366218,128,15683,94371372,CLX5
2025-09-24 19:41:47.029325311+00:00,160,1,432669,A,A,64.82,1,26,8058566367142,128,15713,94371390,CLX5
2025-09-24 19:41:47.029405699+00:00,160,1,432669,C,B,64.81,2,26,8058566358051,128,14856,94371395,CLX5
2025-09-24 19:41:47.029476177+00:00,160,1,432669,M,A,64.82,2,26,8058566362865,128,16158,94371401,CLX5
2025-09-24 19:41:47.029482513+00:00,160,1,432669,A,A,64.82,2,26,8058566367146,128,15171,94371402,CLX5
2025-09-24 19:41:47.029539079+00:00,160,1,432669,A,A,64.82,2,26,8058566367149,128,14287,94371406,CLX5
2025-09-24 19:41:47.029560809+00:00,160,1,432669,C,A,64.86,1,26,8058566354507,128,13657,94371411,CLX5
2025-09-24 19:41:47.029577089+00:00,160,1,432669,A,A,64.85,1,26,8058566367153,128,14673,94371413,CLX5
2025-09-24 19:41:47.029605101+00:00,160,1,432669,A,B,64.81,1,26,8058566367158,128,15141,94371425,CLX5
2025-09-24 19:41:47.029761861+00:00,160,1,432669,M,A,64.84,4,26,8058566342145,128,13499,94371483,CLX5
2025-09-24 19:41:47.029795633+00:00,160,1,432669,C,A,64.83,1,26,8058566365712,128,15045,94371489,CLX5
2025-09-24 19:41:47.029795965+00:00,160,1,432669,T,A,64.81,2,26,8058566367183,0,14629,94371490,CLX5
2025-09-24 19:41:47.029795965+00:00,160,1,432669,F,B,64.81,1,26,8058566356317,0,14629,94371490,CLX5
2025-09-24 19:41:47.029795965+00:00,160,1,432669,F,B,64.81,1,26,8058566356356,0,14629,94371490,CLX5
2025-09-24 19:41:47.029795965+00:00,160,1,432669,C,B,64.81,1,26,8058566356317,0,18751,94371491,CLX5
2025-09-24 19:41:47.029795965+00:00,160,1,432669,C,B,64.81,1,26,8058566356356,128,18751,94371491,CLX5
2025-09-24 19:41:47.029797169+00:00,160,1,432669,T,A,64.81,1,26,8058566367184,0,14580,94371492,CLX5
2025-09-24 19:41:47.029797169+00:00,160,1,432669,F,B,64.81,1,26,8058566356357,0,14580,94371492,CLX5
2025-09-24 19:41:47.029797169+00:00,160,1,432669,C,B,64.81,1,26,8058566356357,128,14953,94371493,CLX5
2025-09-24 19:41:47.029797345+00:00,160,1,432669,C,A,64.83,1,26,8058566365806,128,15181,94371494,CLX5
2025-09-24 19:41:47.029881839+00:00,160,1,432669,T,A,64.81,1,26,8058566367187,0,14860,94371499,CLX5
2025-09-24 19:41:47.029881839+00:00,160,1,432669,F,B,64.81,1,26,8058566356397,0,14860,94371499,CLX5
2025-09-24 19:41:47.029881839+00:00,160,1,432669,C,B,64.81,1,26,8058566356397,128,14854,94371500,CLX5
2025-09-24 19:41:47.029892551+00:00,160,1,432669,C,B,64.79,1,26,8058566357917,128,18251,94371501,CLX5
2025-09-24 19:41:47.030032169+00:00,160,1,432669,T,A,64.81,1,26,8058566367195,0,14708,94371522,CLX5
2025-09-24 19:41:47.030032169+00:00,160,1,432669,F,B,64.81,1,26,8058566356476,0,14708,94371522,CLX5
2025-09-24 19:41:47.030032169+00:00,160,1,432669,C,B,64.81,1,26,8058566356476,128,14969,94371523,CLX5
2025-09-24 19:41:47.030046393+00:00,160,1,432669,T,A,64.81,1,26,8058566367196,0,13621,94371524,CLX5
2025-09-24 19:41:47.030046393+00:00,160,1,432669,F,B,64.81,1,26,8058566221991,0,13621,94371524,CLX5
2025-09-24 19:41:47.030046393+00:00,160,1,432669,C,B,64.81,1,26,8058566221991,128,13621,94371524,CLX5
2025-09-24 19:41:47.030121097+00:00,160,1,432669,C,B,64.81,1,26,8058566357915,128,14907,94371537,CLX5
2025-09-24 19:41:47.030721129+00:00,160,1,432669,M,A,64.94,1,26,8058565075241,128,17858,94371605,CLX5
2025-09-24 19:41:47.030881653+00:00,160,1,432669,C,B,64.81,1,26,8058566367076,128,15543,94371618,CLX5
2025-09-24 19:41:47.030975595+00:00,160,1,432669,C,B,64.8,2,26,8058566358149,128,14400,94371622,CLX5
2025-09-24 19:41:47.032384677+00:00,160,1,432669,M,A,64.82,1,26,8058566239191,128,14211,94371699,CLX5
2025-09-24 19:41:47.032739113+00:00,160,1,432669,M,A,64.83,3,26,8058566321460,128,14961,94371713,CLX5
2025-09-24 19:41:47.032787263+00:00,160,1,432669,C,A,64.82,2,26,8058566367135,128,13826,94371716,CLX5
2025-09-24 19:41:47.032803449+00:00,160,1,432669,A,A,64.85,2,26,8058566367269,128,14826,94371717,CLX5
2025-09-24 19:41:47.033150263+00:00,160,1,432669,M,A,64.84,1,26,8058566173085,128,20478,94371742,CLX5
2025-09-24 19:41:47.033189161+00:00,160,1,432669,M,B,63.66,4,26,8058566319508,128,14520,94371745,CLX5
2025-09-24 19:41:47.033952347+00:00,160,1,432669,C,A,64.82,2,26,8058566367146,128,15093,94371783,CLX5
2025-09-24 19:41:47.033953941+00:00,160,1,432669,A,A,64.83,1,26,8058566367287,128,13607,94371784,CLX5
2025-09-24 19:41:47.034345679+00:00,160,1,432669,M,B,63.65,4,26,8058566319851,128,14506,94371831,CLX5
2025-09-24 19:41:47.036354429+00:00,160,1,432669,C,B,64.81,3,26,8058566358168,128,16020,94371921,CLX5
2025-09-24 19:41:47.037737497+00:00,160,1,432669,M,A,64.83,1,26,8058566349378,128,18457,94372032,CLX5
2025-09-24 19:41:47.038547703+00:00,160,1,432669,A,B,64.81,1,26,8058566367335,128,15256,94372085,CLX5
2025-09-24 19:41:47.038668503+00:00,160,1,432669,C,B,64.81,1,26,8058566367335,128,14937,94372087,CLX5
2025-09-24 19:41:47.041182881+00:00,160,1,432669,C,A,64.83,1,26,8058566367287,128,15155,94372199,CLX5
2025-09-24 19:41:47.044418131+00:00,160,1,432669,A,A,64.82,1,26,8058566367390,128,17957,94372302,CLX5
2025-09-24 19:41:47.045595519+00:00,160,1,432669,A,B,64.81,1,26,8058566367398,128,14969,94372340,CLX5
2025-09-24 19:41:47.047424717+00:00,160,1,432669,M,A,64.82,1,26,8058566361816,128,17793,94372400,CLX5
2025-09-24 19:41:47.080029199+00:00,160,1,432669,A,A,64.82,1,26,8058566367586,128,18758,94372913,CLX5
2025-09-24 19:41:47.080228179+00:00,160,1,432669,A,A,64.82,1,26,8058566367587,128,18100,94372914,CLX5
2025-09-24 19:41:47.105004953+00:00,160,1,432669,C,B,64.81,1,26,8058566367096,128,15525,94372989,CLX5
2025-09-24 19:41:47.105006067+00:00,160,1,432669,C,B,64.81,1,26,8058566367158,128,19179,94372990,CLX5
2025-09-24 19:41:47.112416979+00:00,160,1,432669,C,A,64.87,2,26,8058566364454,128,18341,94373013,CLX5
2025-09-24 19:41:47.112417633+00:00,160,1,432669,A,B,64.78,2,26,8058566367628,128,14300,94373014,CLX5
2025-09-24 19:41:47.115035745+00:00,160,1,432669,T,A,64.81,1,26,8058566367629,0,18033,94373016,CLX5
2025-09-24 19:41:47.115035745+00:00,160,1,432669,F,B,64.81,1,26,8058566356716,0,18033,94373016,CLX5
2025-09-24 19:41:47.115035745+00:00,160,1,432669,M,B,64.81,1,26,8058566356716,128,15891,94373017,CLX5
2025-09-24 19:41:47.118094631+00:00,160,1,432669,C,A,65.9,1,26,8058566358031,128,17332,94373022,CLX5
2025-09-24 19:41:47.118143645+00:00,160,1,432669,A,B,64.16,2,26,8058566367633,128,15972,94373024,CLX5
2025-09-24 19:41:47.118150211+00:00,160,1,432669,C,A,65.7,6,26,8058566358032,128,14124,94373025,CLX5
2025-09-24 19:41:47.240787429+00:00,160,1,432669,A,B,64.78,1,26,8058566367754,128,14567,94373211,CLX5
2025-09-24 19:41:47.524164677+00:00,160,1,432669,C,B,64.78,1,26,8058566367754,128,17922,94373407,CLX5
2025-09-24 19:41:47.524750731+00:00,160,1,432669,A,B,64.81,1,26,8058566367869,128,15910,94373415,CLX5
2025-09-24 19:41:47.618080039+00:00,160,1,432669,A,A,65.7,6,26,8058566367917,128,18188,94373500,CLX5
2025-09-24 19:41:47.731268567+00:00,160,1,432669,C,A,64.82,2,26,8058566367149,128,18556,94373555,CLX5
2025-09-24 19:41:47.839114681+00:00,160,1,432669,M,A,64.82,1,26,8058566366236,128,19812,94373614,CLX5
2025-09-24 19:41:48.292462853+00:00,160,1,432669,C,A,64.82,1,26,8058566361816,128,19576,94373821,CLX5
2025-09-24 19:41:48.340743595+00:00,160,1,432669,A,B,64.78,1,26,8058566368080,128,18219,94373830,CLX5
2025-09-24 19:41:49.753175173+00:00,160,1,432669,C,B,64.81,1,26,8058566367869,128,16897,94374060,CLX5
2025-09-24 19:41:49.755014529+00:00,160,1,432669,A,B,64.81,1,26,8058566368194,128,15126,94374141,CLX5
2025-09-24 19:41:49.818354973+00:00,160,1,432669,C,A,65.7,6,26,8058566367917,128,18121,94374305,CLX5
2025-09-24 19:41:49.819360413+00:00,160,1,432669,C,B,64.78,1,26,8058566368080,128,14703,94374307,CLX5
2025-09-24 19:41:50.293727245+00:00,160,1,432669,A,A,64.82,1,26,8058566368315,128,18540,94374494,CLX5
2025-09-24 19:41:50.293737495+00:00,160,1,432669,C,B,64.81,1,26,8058566356779,128,15733,94374498,CLX5
2025-09-24 19:41:50.293737861+00:00,160,1,432669,C,B,64.81,1,26,8058566367398,128,15901,94374500,CLX5
2025-09-24 19:41:50.293796073+00:00,160,1,432669,A,A,64.82,2,26,8058566368321,128,14916,94374512,CLX5
2025-09-24 19:41:50.293796975+00:00,160,1,432669,T,A,64.81,1,26,8058566368322,0,14787,94374514,CLX5
2025-09-24 19:41:50.293796975+00:00,160,1,432669,F,B,64.81,1,26,8058566356716,0,14787,94374514,CLX5
2025-09-24 19:41:50.293796975+00:00,160,1,432669,C,B,64.81,1,26,8058566356716,128,16566,94374515,CLX5
2025-09-24 19:41:50.293806363+00:00,160,1,432669,T,A,64.81,2,26,8058566368323,0,16960,94374516,CLX5
2025-09-24 19:41:50.293806363+00:00,160,1,432669,F,B,64.81,1,26,8058566357958,0,16960,94374516,CLX5
2025-09-24 19:41:50.293806363+00:00,160,1,432669,F,B,64.81,1,26,8058566358079,0,16960,94374516,CLX5
2025-09-24 19:41:50.293806363+00:00,160,1,432669,C,B,64.81,1,26,8058566357958,0,16960,94374516,CLX5
2025-09-24 19:41:50.293806363+00:00,160,1,432669,M,B,64.81,1,26,8058566358079,128,16960,94374516,CLX5
2025-09-24 19:41:50.293812181+00:00,160,1,432669,T,A,64.81,1,26,8058566368325,0,15024,94374521,CLX5
2025-09-24 19:41:50.293812181+00:00,160,1,432669,F,B,64.81,1,26,8058566358079,0,15024,94374521,CLX5
2025-09-24 19:41:50.293812181+00:00,160,1,432669,C,B,64.81,1,26,8058566358079,128,15024,94374521,CLX5
2025-09-24 19:41:50.293820013+00:00,160,1,432669,T,A,64.81,2,26,8058566368326,0,14441,94374524,CLX5
2025-09-24 19:41:50.293820013+00:00,160,1,432669,F,B,64.81,1,26,8058566197138,0,14441,94374524,CLX5
2025-09-24 19:41:50.293820013+00:00,160,1,432669,F,B,64.81,1,26,8058566365981,0,14441,94374524,CLX5
2025-09-24 19:41:50.293820013+00:00,160,1,432669,C,B,64.81,1,26,8058566197138,0,19596,94374525,CLX5
2025-09-24 19:41:50.293820013+00:00,160,1,432669,C,B,64.81,1,26,8058566365981,128,19596,94374525,CLX5
2025-09-24 19:41:50.293949435+00:00,160,1,432669,C,B,64.81,1,26,8058566368194,128,18236,94374541,CLX5
2025-09-24 19:41:50.294497815+00:00,160,1,432669,A,A,64.82,2,26,8058566368345,128,13726,94374613,CLX5
2025-09-24 19:41:50.294499835+00:00,160,1,432669,T,A,64.81,1,26,8058566368350,0,16076,94374625,CLX5
2025-09-24 19:41:50.294499835+00:00,160,1,432669,F,B,64.81,1,26,8058566367028,0,16076,94374625,CLX5
2025-09-24 19:41:50.294499835+00:00,160,1,432669,C,B,64.81,1,26,8058566367028,128,16076,94374625,CLX5
2025-09-24 19:41:50.294571265+00:00,160,1,432669,A,A,64.81,2,26,8058566368355,128,14642,94374636,CLX5
2025-09-24 19:41:50.294571795+00:00,160,1,432669,A,A,64.81,2,26,8058566368358,128,14736,94374642,CLX5
2025-09-24 19:41:50.294571975+00:00,160,1,432669,A,A,64.81,1,26,8058566368359,128,14289,94374644,CLX5
2025-09-24 19:41:50.294950019+00:00,160,1,432669,A,B,64.8,1,26,8058566368370,128,18206,94374675,CLX5
2025-09-24 19:41:50.295789771+00:00,160,1,432669,M,A,64.93,1,26,8058565075241,128,14911,94374737,CLX5
2025-09-24 19:41:50.296078833+00:00,160,1,432669,C,B,64.78,1,26,8058566340353,128,17283,94374747,CLX5
2025-09-24 19:41:50.296815715+00:00,160,1,432669,M,A,64.83,1,26,8058566173085,128,14914,94374790,CLX5
2025-09-24 19:41:50.296838447+00:00,160,1,432669,A,A,64.81,1,26,8058566368399,128,22219,94374791,CLX5
2025-09-24 19:41:50.296888385+00:00,160,1,432669,T,N,64.81,1,26,0,0,16669,94374794,CLX5
2025-09-24 19:41:50.296888385+00:00,160,1,432669,F,N,64.81,1,26,8058566368355,0,16669,94374794,CLX5
2025-09-24 19:41:50.296888385+00:00,160,1,432669,M,A,64.81,1,26,8058566368355,128,14755,94374795,CLX5
2025-09-24 19:41:50.297031819+00:00,160,1,432669,A,A,64.81,1,26,8058566368402,128,18602,94374802,CLX5
2025-09-24 19:41:50.297130735+00:00,160,1,432669,M,A,64.81,2,26,8058566362865,128,20792,94374812,CLX5
2025-09-24 19:41:50.297145941+00:00,160,1,432669,A,A,64.81,1,26,8058566368407,128,16605,94374813,CLX5
2025-09-24 19:41:50.297157825+00:00,160,1,432669,C,B,64.79,2,26,8058566365698,128,15013,94374814,CLX5
2025-09-24 19:41:50.297159015+00:00,160,1,432669,A,A,64.81,2,26,8058566368409,128,19149,94374815,CLX5
2025-09-24 19:41:50.297215691+00:00,160,1,432669,A,A,64.81,2,26,8058566368420,128,16311,94374843,CLX5
2025-09-24 19:41:50.297340103+00:00,160,1,432669,A,A,64.81,1,26,8058566368431,128,14677,94374885,CLX5
2025-09-24 19:41:50.297342387+00:00,160,1,432669,A,A,64.81,1,26,8058566368432,128,19496,94374887,CLX5
2025-09-24 19:41:50.297362489+00:00,160,1,432669,C,B,64.8,3,26,8058566332677,128,14883,94374889,CLX5
2025-09-24 19:41:50.297379883+00:00,160,1,432669,C,B,64.8,1,26,8058566329044,128,18325,94374893,CLX5
2025-09-24 19:41:50.297401213+00:00,160,1,432669,A,A,64.81,1,26,8058566368434,128,15661,94374894,CLX5
2025-09-24 19:41:50.297487283+00:00,160,1,432669,M,A,64.81,1,26,8058566366055,128,15820,94374910,CLX5
2025-09-24 19:41:50.297487783+00:00,160,1,432669,C,B,64.8,1,26,8058566340896,128,17252,94374911,CLX5
2025-09-24 19:41:50.297487955+00:00,160,1,432669,C,B,64.8,1,26,8058566340897,128,15462,94374912,CLX5
2025-09-24 19:41:50.297538583+00:00,160,1,432669,T,B,64.81,1,26,8058566368443,0,14409,94374919,CLX5
2025-09-24 19:41:50.297538583+00:00,160,1,432669,F,A,64.81,1,26,8058566368355,0,14409,94374919,CLX5
2025-09-24 19:41:50.297538583+00:00,160,1,432669,C,A,64.81,1,26,8058566368355,128,19807,94374920,CLX5
2025-09-24 19:41:50.297571335+00:00,160,1,432669,M,A,64.82,4,26,8058566363632,128,14765,94374923,CLX5
2025-09-24 19:41:50.297848111+00:00,160,1,432669,M,A,64.82,1,26,8058566349378,128,15257,94374952,CLX5
2025-09-24 19:41:50.297893153+00:00,160,1,432669,C,A,64.82,1,26,8058566367587,128,14954,94374955,CLX5
2025-09-24 19:41:50.298022287+00:00,160,1,432669,C,B,64.8,2,26,8058566340680,128,18658,94374964,CLX5
2025-09-24 19:41:50.298029255+00:00,160,1,432669,A,A,64.84,1,26,8058566368454,128,14511,94374965,CLX5
2025-09-24 19:41:50.298397055+00:00,160,1,432669,A,A,64.81,1,26,8058566368462,128,15137,94374996,CLX5
2025-09-24 19:41:50.298412029+00:00,160,1,432669,A,A,64.81,2,26,8058566368465,128,16335,94375013,CLX5
2025-09-24 19:41:50.299024385+00:00,160,1,432669,T,N,64.81,1,26,0,0,14245,94375077,CLX5
2025-09-24 19:41:50.299024385+00:00,160,1,432669,F,N,64.81,1,26,8058566368358,0,14245,94375077,CLX5
2025-09-24 19:41:50.299024385+00:00,160,1,432669,M,A,64.81,1,26,8058566368358,128,14245,94375077,CLX5
2025-09-24 19:41:50.299492539+00:00,160,1,432669,C,A,64.82,1,26,8058566367586,128,18046,94375096,CLX5
2025-09-24 19:41:50.299926555+00:00,160,1,432669,C,A,64.81,1,26,8058566368432,128,16988,94375138,CLX5
2025-09-24 19:41:50.299972883+00:00,160,1,432669,T,B,64.81,5,26,8058566368502,0,14738,94375142,CLX5
2025-09-24 19:41:50.299972883+00:00,160,1,432669,F,A,64.81,1,26,8058566368358,0,14738,94375142,CLX5
2025-09-24 19:41:50.299972883+00:00,160,1,432669,F,A,64.81,1,26,8058566368359,0,14738,94375142,CLX5
2025-09-24 19:41:50.299972883+00:00,160,1,432669,F,A,64.81,1,26,8058566368399,0,14738,94375142,CLX5
2025-09-24 19:41:50.299972883+00:00,160,1,432669,F,A,64.81,1,26,8058566368402,0,14738,94375142,CLX5
2025-09-24 19:41:50.299972883+00:00,160,1,432669,F,A,64.81,1,26,8058566362865,0,14738,94375142,CLX5
2025-09-24 19:41:50.299972883+00:00,160,1,432669,C,A,64.81,1,26,8058566368358,0,20598,94375143,CLX5
2025-09-24 19:41:50.299972883+00:00,160,1,432669,C,A,64.81,1,26,8058566368359,0,20598,94375143,CLX5
2025-09-24 19:41:50.299972883+00:00,160,1,432669,C,A,64.81,1,26,8058566368399,0,20598,94375143,CLX5
2025-09-24 19:41:50.299972883+00:00,160,1,432669,C,A,64.81,1,26,8058566368402,0,20598,94375143,CLX5
2025-09-24 19:41:50.299972883+00:00,160,1,432669,M,A,64.81,1,26,8058566362865,128,20598,94375143,CLX5
2025-09-24 19:41:50.299974629+00:00,160,1,432669,C,A,64.81,1,26,8058566368434,128,14834,94375144,CLX5
2025-09-24 19:41:50.300134519+00:00,160,1,432669,A,A,64.84,2,26,8058566368507,128,14927,94375165,CLX5
2025-09-24 19:41:50.300361819+00:00,160,1,432669,C,A,64.81,2,26,8058566368420,128,16433,94375183,CLX5
2025-09-24 19:41:50.300899049+00:00,160,1,432669,C,A,64.81,2,26,8058566368409,128,20354,94375198,CLX5
2025-09-24 19:41:50.300917229+00:00,160,1,432669,M,B,64.46,10,26,8058566151203,128,15149,94375199,CLX5
2025-09-24 19:41:50.301053985+00:00,160,1,432669,C,A,64.81,2,26,8058566368465,128,16970,94375203,CLX5
2025-09-24 19:41:50.301948609+00:00,160,1,432669,T,B,64.81,2,26,8058566368522,0,14939,94375225,CLX5
2025-09-24 19:41:50.301948609+00:00,160,1,432669,F,A,64.81,1,26,8058566362865,0,14939,94375225,CLX5
2025-09-24 19:41:50.301948609+00:00,160,1,432669,F,A,64.81,1,26,8058566368407,0,14939,94375225,CLX5
2025-09-24 19:41:50.301948609+00:00,160,1,432669,C,A,64.81,1,26,8058566362865,0,23233,94375226,CLX5
2025-09-24 19:41:50.301948609+00:00,160,1,432669,C,A,64.81,1,26,8058566368407,128,23233,94375226,CLX5
2025-09-24 19:41:50.301950279+00:00,160,1,432669,C,A,64.81,1,26,8058566368462,128,13551,94375227,CLX5
2025-09-24 19:41:50.302281005+00:00,160,1,432669,C,A,64.81,1,26,8058566368431,128,18534,94375243,CLX5
2025-09-24 19:41:50.302467543+00:00,160,1,432669,A,B,64.8,1,26,8058566368530,128,18644,94375256,CLX5
2025-09-24 19:41:50.303450117+00:00,160,1,432669,A,A,64.81,1,26,8058566368538,128,14559,94375299,CLX5
2025-09-24 19:41:50.303567751+00:00,160,1,432669,A,B,64.8,1,26,8058566368539,128,15089,94375302,CLX5
2025-09-24 19:41:50.303592651+00:00,160,1,432669,C,A,64.81,1,26,8058566368538,128,18226,94375306,CLX5
2025-09-24 19:41:50.303762083+00:00,160,1,432669,C,B,64.8,1,26,8058566368530,128,14918,94375319,CLX5
2025-09-24 19:41:50.304117423+00:00,160,1,432669,A,B,64.8,1,26,8058566368548,128,14764,94375349,CLX5
2025-09-24 19:41:50.304117671+00:00,160,1,432669,A,B,64.8,2,26,8058566368549,128,14083,94375350,CLX5
2025-09-24 19:41:50.304144357+00:00,160,1,432669,T,N,64.81,1,26,0,0,14617,94375354,CLX5
2025-09-24 19:41:50.304144357+00:00,160,1,432669,F,N,64.81,1,26,8058566366055,0,14617,94375354,CLX5
2025-09-24 19:41:50.304144357+00:00,160,1,432669,C,A,64.81,1,26,8058566366055,128,19764,94375355,CLX5
2025-09-24 19:41:50.304236187+00:00,160,1,432669,C,A,64.84,2,26,8058566368507,128,14861,94375364,CLX5
2025-09-24 19:41:50.304342723+00:00,160,1,432669,A,B,64.8,2,26,8058566368553,128,15005,94375368,CLX5
2025-09-24 19:41:50.304342901+00:00,160,1,432669,A,B,64.8,1,26,8058566368554,128,16981,94375369,CLX5
2025-09-24 19:41:50.305397859+00:00,160,1,432669,C,B,64.77,1,26,8058566331225,128,17975,94375403,CLX5
2025-09-24 19:41:50.305398007+00:00,160,1,432669,C,B,64.76,1,26,8058566321133,128,14645,94375404,CLX5
2025-09-24 19:41:50.306849845+00:00,160,1,432669,T,A,64.81,1,26,8058566357512,0,13639,94375615,CLX5
2025-09-24 19:41:50.306849845+00:00,160,1,432669,F,A,64.81,1,26,8058566357512,0,13639,94375615,CLX5
2025-09-24 19:41:50.306849845+00:00,160,1,432669,C,A,64.85,1,26,8058566357512,128,19501,94375616,CLX5
2025-09-24 19:41:50.306946321+00:00,160,1,432669,A,A,64.85,2,26,8058566368599,128,18661,94375631,CLX5
2025-09-24 19:41:50.307311163+00:00,160,1,432669,A,B,64.81,1,26,8058566368606,128,15652,94375688,CLX5
2025-09-24 19:41:50.308883303+00:00,160,1,432669,A,B,64.81,1,26,8058566368621,128,16778,94375747,CLX5
2025-09-24 19:41:50.308897107+00:00,160,1,432669,A,B,64.8,2,26,8058566368623,128,14918,94375752,CLX5
2025-09-24 19:41:50.309459509+00:00,160,1,432669,C,B,64.81,1,26,8058566368621,128,13667,94375762,CLX5
2025-09-24 19:41:50.309788679+00:00,160,1,432669,C,B,64.8,2,26,8058566368623,128,14791,94375768,CLX5
2025-09-24 19:41:50.310461839+00:00,160,1,432669,C,B,64.8,1,26,8058566368539,128,14689,94375780,CLX5
2025-09-24 19:41:50.310474089+00:00,160,1,432669,A,B,64.8,2,26,8058566368631,128,14454,94375782,CLX5
2025-09-24 19:41:50.310764437+00:00,160,1,432669,C,B,64.8,2,26,8058566368631,128,17561,94375785,CLX5
2025-09-24 19:41:50.313051115+00:00,160,1,432669,A,B,64.8,1,26,8058566368651,128,17794,94375853,CLX5
2025-09-24 19:41:50.313946735+00:00,160,1,432669,A,B,64.8,2,26,8058566368659,128,14491,94375873,CLX5
2025-09-24 19:41:50.314330411+00:00,160,1,432669,M,A,65.98,4,26,8058566363632,128,14679,94375914,CLX5
2025-09-24 19:41:50.314361111+00:00,160,1,432669,M,B,64.8,4,26,8058566319851,128,18224,94375916,CLX5
2025-09-24 19:41:50.314547151+00:00,160,1,432669,C,B,64.8,2,26,8058566368659,128,15243,94375925,CLX5
2025-09-24 19:41:50.314671483+00:00,160,1,432669,C,B,64.8,4,26,8058566319851,128,14936,94375928,CLX5
2025-09-24 19:41:50.316446351+00:00,160,1,432669,A,B,64.77,1,26,8058566368670,128,14840,94375956,CLX5
2025-09-24 19:41:50.316853217+00:00,160,1,432669,A,B,64.8,1,26,8058566368676,128,15190,94375975,CLX5
2025-09-24 19:41:50.317121797+00:00,160,1,432669,A,B,64.8,1,26,8058566368678,128,14927,94375978,CLX5
2025-09-24 19:41:50.317176339+00:00,160,1,432669,A,B,64.81,2,26,8058566368680,128,17800,94375984,CLX5
2025-09-24 19:41:50.317176519+00:00,160,1,432669,A,B,64.81,2,26,8058566368681,128,14068,94375986,CLX5
2025-09-24 19:41:50.317176781+00:00,160,1,432669,A,B,64.81,2,26,8058566368682,128,16772,94375988,CLX5
2025-09-24 19:41:50.317176961+00:00,160,1,432669,A,B,64.81,1,26,8058566368683,128,19772,94375989,CLX5
2025-09-24 19:41:50.317330759+00:00,160,1,432669,A,B,64.81,2,26,8058566368688,128,15522,94376003,CLX5
2025-09-24 19:41:50.317343199+00:00,160,1,432669,C,A,64.82,2,26,8058566368321,128,13899,94376005,CLX5
2025-09-24 19:41:50.319373893+00:00,160,1,432669,C,A,64.82,1,26,8058566368315,128,18302,94376064,CLX5
2025-09-24 19:41:50.319448483+00:00,160,1,432669,A,B,64.81,1,26,8058566368705,128,15789,94376065,CLX5
2025-09-24 19:41:50.320017237+00:00,160,1,432669,C,A,64.82,2,26,8058566368345,128,18772,94376082,CLX5
2025-09-24 19:41:50.320206579+00:00,160,1,432669,C,A,64.82,2,26,8058566367127,128,18150,94376092,CLX5
2025-09-24 19:41:50.320801659+00:00,160,1,432669,C,B,64.81,2,26,8058566368688,128,22470,94376133,CLX5
2025-09-24 19:41:50.320982245+00:00,160,1,432669,M,B,64.8,4,26,8058566319508,128,18143,94376138,CLX5
2025-09-24 19:41:50.321535663+00:00,160,1,432669,A,B,64.78,1,26,8058566368731,128,18380,94376157,CLX5
2025-09-24 19:41:50.321783311+00:00,160,1,432669,A,B,64.81,1,26,8058566368735,128,15700,94376168,CLX5
2025-09-24 19:41:50.321788015+00:00,160,1,432669,A,B,64.81,1,26,8058566368736,128,15629,94376169,CLX5
2025-09-24 19:41:50.321927631+00:00,160,1,432669,A,B,64.81,1,26,8058566368739,128,14907,94376175,CLX5
2025-09-24 19:41:50.322079343+00:00,160,1,432669,M,A,64.94,1,26,8058565075241,128,14693,94376222,CLX5
2025-09-24 19:41:50.322674575+00:00,160,1,432669,A,B,64.81,2,26,8058566368764,128,14914,94376267,CLX5
2025-09-24 19:41:50.322768267+00:00,160,1,432669,C,A,64.82,1,26,8058566367142,128,17859,94376272,CLX5
2025-09-24 19:41:50.323143803+00:00,160,1,432669,A,B,64.81,1,26,8058566368778,128,18196,94376325,CLX5
2025-09-24 19:41:50.325912933+00:00,160,1,432669,C,B,64.81,1,26,8058566368739,128,16407,94376423,CLX5
2025-09-24 19:41:50.333538415+00:00,160,1,432669,A,B,64.8,1,26,8058566368829,128,14621,94376544,CLX5
2025-09-24 19:41:50.344443151+00:00,160,1,432669,T,A,64.81,1,26,8058566368842,0,18410,94376574,CLX5
2025-09-24 19:41:50.344443151+00:00,160,1,432669,F,B,64.81,1,26,8058566368606,0,18410,94376574,CLX5
2025-09-24 19:41:50.344443151+00:00,160,1,432669,C,B,64.81,1,26,8058566368606,128,15944,94376575,CLX5
2025-09-24 19:41:50.344726759+00:00,160,1,432669,C,B,64.81,1,26,8058566368778,128,15162,94376578,CLX5
2025-09-24 19:41:50.348326947+00:00,160,1,432669,A,A,64.82,1,26,8058566368849,128,19054,94376593,CLX5
2025-09-24 19:41:50.349939137+00:00,160,1,432669,A,A,64.82,1,26,8058566368852,128,18617,94376597,CLX5
2025-09-24 19:41:50.359653985+00:00,160,1,432669,A,B,64.79,2,26,8058566368882,128,18518,94376653,CLX5
2025-09-24 19:41:50.399072745+00:00,160,1,432669,A,B,64.81,1,26,8058566368955,128,18456,94376788,CLX5
2025-09-24 19:41:50.440792773+00:00,160,1,432669,A,B,64.78,1,26,8058566369032,128,16579,94376909,CLX5
2025-09-24 19:41:50.474566099+00:00,160,1,432669,C,A,64.84,1,26,8058566368454,128,18064,94376978,CLX5
2025-09-24 19:41:50.474720845+00:00,160,1,432669,C,B,64.8,1,26,8058566368678,128,18204,94376979,CLX5
2025-09-24 19:41:50.563861437+00:00,160,1,432669,C,B,64.81,1,26,8058566368955,128,18857,94377098,CLX5
2025-09-24 19:41:50.591741409+00:00,160,1,432669,A,B,64.81,2,26,8058566369168,128,19158,94377145,CLX5
2025-09-24 19:41:50.618147691+00:00,160,1,432669,A,A,65.7,6,26,8058566369177,128,18260,94377165,CLX5
2025-09-24 19:41:51.475934007+00:00,160,1,432669,C,B,64.8,1,26,8058566368676,128,18138,94377388,CLX5
2025-09-24 19:41:51.475946293+00:00,160,1,432669,C,B,64.8,1,26,8058566368651,128,14565,94377389,CLX5
2025-09-24 19:41:51.669760821+00:00,160,1,432669,C,B,64.81,2,26,8058566368764,128,15252,94377520,CLX5
2025-09-24 19:41:51.718147197+00:00,160,1,432669,C,A,65.7,6,26,8058566369177,128,16263,94377640,CLX5
2025-09-24 19:41:52.504575809+00:00,160,1,432669,A,B,64.76,1,26,8058566369432,128,18005,94377786,CLX5
2025-09-24 19:41:53.251461843+00:00,160,1,432669,A,B,64.81,2,26,8058566369475,128,14982,94377859,CLX5
2025-09-24 19:41:55.244052675+00:00,160,1,432669,A,B,64.26,1,26,8058566369534,128,18035,94378035,CLX5
2025-09-24 19:41:55.849180405+00:00,160,1,432669,C,B,64.81,2,26,8058566369475,128,15118,94378059,CLX5
2025-09-24 19:41:55.849580227+00:00,160,1,432669,A,A,64.82,1,26,8058566369540,128,14898,94378069,CLX5
2025-09-24 19:41:55.851298687+00:00,160,1,432669,A,B,64.81,2,26,8058566369547,128,17762,94378100,CLX5
2025-09-24 19:41:55.851431929+00:00,160,1,432669,C,A,64.82,1,26,8058566369540,128,15327,94378103,CLX5
2025-09-24 19:41:57.254820689+00:00,160,1,432669,T,B,64.82,2,26,8058566369600,0,18533,94378236,CLX5
2025-09-24 19:41:57.254820689+00:00,160,1,432669,F,A,64.82,2,26,8058566367045,0,18533,94378236,CLX5
2025-09-24 19:41:57.254820689+00:00,160,1,432669,C,A,64.82,2,26,8058566367045,128,15114,94378237,CLX5
2025-09-24 19:41:57.255142965+00:00,160,1,432669,A,B,64.81,1,26,8058566369603,128,14959,94378240,CLX5
2025-09-24 19:41:57.255157251+00:00,160,1,432669,C,A,64.82,1,26,8058566367123,128,17925,94378241,CLX5
2025-09-24 19:41:57.255180999+00:00,160,1,432669,T,B,64.82,12,26,8058566369605,0,17359,94378248,CLX5
2025-09-24 19:41:57.255180999+00:00,160,1,432669,F,A,64.82,1,26,8058566367047,0,17359,94378248,CLX5
2025-09-24 19:41:57.255180999+00:00,160,1,432669,F,A,64.82,1,26,8058566367054,0,17359,94378248,CLX5
2025-09-24 19:41:57.255180999+00:00,160,1,432669,F,A,64.82,1,26,8058566367089,0,17359,94378248,CLX5
2025-09-24 19:41:57.255180999+00:00,160,1,432669,F,A,64.82,2,26,8058566367111,0,17359,94378248,CLX5
2025-09-24 19:41:57.255180999+00:00,160,1,432669,F,A,64.82,1,26,8058566367116,0,17359,94378248,CLX5
2025-09-24 19:41:57.255180999+00:00,160,1,432669,F,A,64.82,3,26,8058566367120,0,17359,94378248,CLX5
2025-09-24 19:41:57.255180999+00:00,160,1,432669,F,A,64.82,1,26,8058566367121,0,17359,94378248,CLX5
2025-09-24 19:41:57.255180999+00:00,160,1,432669,F,A,64.82,1,26,8058566366218,0,17359,94378248,CLX5
2025-09-24 19:41:57.255180999+00:00,160,1,432669,F,A,64.82,1,26,8058566239191,0,17359,94378248,CLX5
2025-09-24 19:41:57.255180999+00:00,160,1,432669,C,A,64.82,1,26,8058566367047,0,15374,94378249,CLX5
2025-09-24 19:41:57.255180999+00:00,160,1,432669,C,A,64.82,1,26,8058566367054,0,15374,94378249,CLX5
2025-09-24 19:41:57.255180999+00:00,160,1,432669,C,A,64.82,1,26,8058566367089,0,15374,94378249,CLX5
2025-09-24 19:41:57.255180999+00:00,160,1,432669,C,A,64.82,2,26,8058566367111,0,15374,94378249,CLX5
2025-09-24 19:41:57.255180999+00:00,160,1,432669,C,A,64.82,1,26,8058566367116,0,15374,94378249,CLX5
2025-09-24 19:41:57.255180999+00:00,160,1,432669,C,A,64.82,3,26,8058566367120,0,15374,94378249,CLX5
2025-09-24 19:41:57.255180999+00:00,160,1,432669,C,A,64.82,1,26,8058566367121,0,15374,94378249,CLX5
2025-09-24 19:41:57.255180999+00:00,160,1,432669,C,A,64.82,1,26,8058566366218,0,15374,94378249,CLX5
2025-09-24 19:41:57.255180999+00:00,160,1,432669,C,A,64.82,1,26,8058566239191,128,15374,94378249,CLX5
2025-09-24 19:41:57.255592995+00:00,160,1,432669,A,B,64.81,1,26,8058566369607,128,18762,94378254,CLX5
2025-09-24 19:41:57.255634483+00:00,160,1,432669,A,B,64.81,1,26,8058566369609,128,18479,94378260,CLX5
2025-09-24 19:41:57.255722939+00:00,160,1,432669,T,N,64.82,1,26,0,0,18545,94378281,CLX5
2025-09-24 19:41:57.255722939+00:00,160,1,432669,F,N,64.82,1,26,8058566367390,0,18545,94378281,CLX5
2025-09-24 19:41:57.255722939+00:00,160,1,432669,C,A,64.82,1,26,8058566367390,128,15706,94378282,CLX5
2025-09-24 19:41:57.255723293+00:00,160,1,432669,T,B,64.82,4,26,8058566369620,0,19679,94378287,CLX5
2025-09-24 19:41:57.255723293+00:00,160,1,432669,F,A,64.82,1,26,8058566366236,0,19679,94378287,CLX5
2025-09-24 19:41:57.255723293+00:00,160,1,432669,F,A,64.82,1,26,8058566368849,0,19679,94378287,CLX5
2025-09-24 19:41:57.255723293+00:00,160,1,432669,F,A,64.82,1,26,8058566368852,0,19679,94378287,CLX5
2025-09-24 19:41:57.255723293+00:00,160,1,432669,F,A,64.82,1,26,8058566349378,0,19679,94378287,CLX5
2025-09-24 19:41:57.255723293+00:00,160,1,432669,C,A,64.82,1,26,8058566366236,0,14880,94378288,CLX5
2025-09-24 19:41:57.255723293+00:00,160,1,432669,C,A,64.82,1,26,8058566368849,0,14880,94378288,CLX5
2025-09-24 19:41:57.255723293+00:00,160,1,432669,C,A,64.82,1,26,8058566368852,0,14880,94378288,CLX5
2025-09-24 19:41:57.255723293+00:00,160,1,432669,C,A,64.82,1,26,8058566349378,128,14880,94378288,CLX5
2025-09-24 19:41:57.255724527+00:00,160,1,432669,A,B,64.81,1,26,8058566369621,128,17878,94378291,CLX5
2025-09-24 19:41:57.255735069+00:00,160,1,432669,C,B,64.81,1,26,8058566369609,128,16692,94378296,CLX5
2025-09-24 19:41:57.255755325+00:00,160,1,432669,A,B,64.81,2,26,8058566369628,128,17495,94378304,CLX5
2025-09-24 19:41:57.255767323+00:00,160,1,432669,M,B,64.81,1,26,8058566368370,128,18354,94378311,CLX5
2025-09-24 19:41:57.255919553+00:00,160,1,432669,A,A,64.82,1,26,8058566369631,128,14539,94378317,CLX5
2025-09-24 19:41:57.256508879+00:00,160,1,432669,T,B,64.82,1,26,8058566369642,0,15126,94378353,CLX5
2025-09-24 19:41:57.256508879+00:00,160,1,432669,F,A,64.82,1,26,8058566369631,0,15126,94378353,CLX5
2025-09-24 19:41:57.256508879+00:00,160,1,432669,C,A,64.82,1,26,8058566369631,128,18404,94378354,CLX5
2025-09-24 19:41:57.256661157+00:00,160,1,432669,A,B,64.79,1,26,8058566369648,128,13896,94378370,CLX5
2025-09-24 19:41:57.256724975+00:00,160,1,432669,A,B,64.81,1,26,8058566369659,128,18344,94378402,CLX5
2025-09-24 19:41:57.256753199+00:00,160,1,432669,A,B,64.81,1,26,8058566369660,128,15575,94378404,CLX5
2025-09-24 19:41:57.256768769+00:00,160,1,432669,A,B,64.81,1,26,8058566369661,128,14899,94378406,CLX5
2025-09-24 19:41:57.256774799+00:00,160,1,432669,A,B,64.81,1,26,8058566369662,128,18181,94378407,CLX5
2025-09-24 19:41:57.256824255+00:00,160,1,432669,A,A,65.14,1,26,8058566369663,128,14689,94378408,CLX5
2025-09-24 19:41:57.256964427+00:00,160,1,432669,M,A,65.99,4,26,8058566321460,128,18686,94378422,CLX5
2025-09-24 19:41:57.257130845+00:00,160,1,432669,C,B,64.78,1,26,8058566369032,128,13486,94378438,CLX5
2025-09-24 19:41:57.257186429+00:00,160,1,432669,A,B,64.81,1,26,8058566369670,128,15159,94378441,CLX5
2025-09-24 19:41:57.257218241+00:00,160,1,432669,C,A,64.85,2,26,8058566367269,128,17769,94378445,CLX5
2025-09-24 19:41:57.257232635+00:00,160,1,432669,A,B,64.82,1,26,8058566369673,128,14545,94378447,CLX5
2025-09-24 19:41:57.257263243+00:00,160,1,432669,C,B,64.81,1,26,8058566369662,128,14695,94378455,CLX5
2025-09-24 19:41:57.257355899+00:00,160,1,432669,A,B,64.82,1,26,8058566369675,128,15168,94378457,CLX5
2025-09-24 19:41:57.257437975+00:00,160,1,432669,C,B,64.81,1,26,8058566369661,128,14406,94378465,CLX5
2025-09-24 19:41:57.257449129+00:00,160,1,432669,C,B,64.81,1,26,8058566369660,128,14973,94378466,CLX5
2025-09-24 19:41:57.257450705+00:00,160,1,432669,C,B,64.81,1,26,8058566369659,128,14815,94378467,CLX5
2025-09-24 19:41:57.257461777+00:00,160,1,432669,C,B,64.82,1,26,8058566369675,128,14366,94378470,CLX5
2025-09-24 19:41:57.257518823+00:00,160,1,432669,M,B,64.82,1,26,8058566369168,128,14470,94378475,CLX5
2025-09-24 19:41:57.258472753+00:00,160,1,432669,A,B,64.81,1,26,8058566369687,128,18617,94378513,CLX5
2025-09-24 19:41:57.258585413+00:00,160,1,432669,C,B,64.82,1,26,8058566369673,128,13505,94378521,CLX5
2025-09-24 19:41:57.258626173+00:00,160,1,432669,A,B,64.81,3,26,8058566369689,128,14554,94378529,CLX5
2025-09-24 19:41:57.258853125+00:00,160,1,432669,C,B,64.81,1,26,8058566369687,128,15881,94378538,CLX5
2025-09-24 19:41:57.259191165+00:00,160,1,432669,A,B,64.81,1,26,8058566369695,128,14965,94378550,CLX5
2025-09-24 19:41:57.259376917+00:00,160,1,432669,C,B,64.81,1,26,8058566369695,128,14692,94378564,CLX5
2025-09-24 19:41:57.260332113+00:00,160,1,432669,A,B,64.81,1,26,8058566369702,128,14832,94378581,CLX5
2025-09-24 19:41:57.260557127+00:00,160,1,432669,A,B,64.82,1,26,8058566369705,128,17915,94378588,CLX5
2025-09-24 19:41:57.260565575+00:00,160,1,432669,C,B,64.8,1,26,8058566368829,128,17060,94378590,CLX5
2025-09-24 19:41:57.260571373+00:00,160,1,432669,A,B,64.82,2,26,8058566369706,128,14716,94378592,CLX5
2025-09-24 19:41:57.260723873+00:00,160,1,432669,A,A,64.86,1,26,8058566369708,128,17947,94378599,CLX5
2025-09-24 19:41:57.262754969+00:00,160,1,432669,M,A,64.84,1,26,8058566173085,128,18852,94378698,CLX5
2025-09-24 19:41:57.263520075+00:00,160,1,432669,A,B,64.82,2,26,8058566369738,128,13653,94378720,CLX5
2025-09-24 19:41:57.312749025+00:00,160,1,432669,A,A,64.87,2,26,8058566369754,128,17726,94378782,CLX5
2025-09-24 19:41:57.312879061+00:00,160,1,432669,C,B,64.82,2,26,8058566369738,128,20678,94378783,CLX5
2025-09-24 19:41:57.318412929+00:00,160,1,432669,A,A,65.9,1,26,8058566369756,128,17592,94378788,CLX5
2025-09-24 19:41:57.318460447+00:00,160,1,432669,A,A,65.7,6,26,8058566369757,128,14310,94378789,CLX5
2025-09-24 19:41:57.478027197+00:00,160,1,432669,A,B,64.81,1,26,8058566369797,128,18898,94378871,CLX5
2025-09-24 19:41:57.564602265+00:00,160,1,432669,C,B,64.79,1,26,8058566369648,128,17956,94378881,CLX5
2025-09-24 19:41:57.564759525+00:00,160,1,432669,C,B,64.81,1,26,8058566369702,128,18266,94378882,CLX5
2025-09-24 19:41:58.508448879+00:00,160,1,432669,T,A,64.82,1,26,8058566369828,0,19516,94378936,CLX5
2025-09-24 19:41:58.508448879+00:00,160,1,432669,F,B,64.82,1,26,8058566369168,0,19516,94378936,CLX5
2025-09-24 19:41:58.508448879+00:00,160,1,432669,C,B,64.82,1,26,8058566369168,128,17599,94378937,CLX5
2025-09-24 19:41:58.508743739+00:00,160,1,432669,A,A,64.86,1,26,8058566369830,128,15167,94378942,CLX5
2025-09-24 19:41:58.508755489+00:00,160,1,432669,C,B,64.82,2,26,8058566369706,128,17782,94378943,CLX5
2025-09-24 19:41:58.542369749+00:00,160,1,432669,T,A,64.82,1,26,8058566369838,0,17778,94378965,CLX5
2025-09-24 19:41:58.542369749+00:00,160,1,432669,F,B,64.82,1,26,8058566369705,0,17778,94378965,CLX5
2025-09-24 19:41:58.542369749+00:00,160,1,432669,C,B,64.82,1,26,8058566369705,128,17209,94378966,CLX5
2025-09-24 19:41:58.543292979+00:00,160,1,432669,A,A,64.85,2,26,8058566369841,128,18345,94378975,CLX5
2025-09-24 19:41:58.565367129+00:00,160,1,432669,C,A,64.86,1,26,8058566369830,128,18030,94379046,CLX5
2025-09-24 19:41:58.612370321+00:00,160,1,432669,C,A,64.87,2,26,8058566369754,128,18497,94379072,CLX5
2025-09-24 19:41:58.618139397+00:00,160,1,432669,C,A,65.9,1,26,8058566369756,128,18353,94379073,CLX5
2025-09-24 19:41:58.740776309+00:00,160,1,432669,A,B,64.78,1,26,8058566369877,128,17962,94379089,CLX5
2025-09-24 19:42:00.024400275+00:00,160,1,432669,A,A,64.87,1,26,8058566369899,128,18016,94379135,CLX5
2025-09-24 19:42:02.123181331+00:00,160,1,432669,T,B,64.83,1,26,8058566369988,0,18329,94379386,CLX5
2025-09-24 19:42:02.123181331+00:00,160,1,432669,F,A,64.83,1,26,8058566365417,0,18329,94379386,CLX5
2025-09-24 19:42:02.123181331+00:00,160,1,432669,M,A,64.83,1,26,8058566365417,128,15342,94379387,CLX5
2025-09-24 19:42:02.123538357+00:00,160,1,432669,A,B,64.82,2,26,8058566369989,128,17247,94379390,CLX5
2025-09-24 19:42:02.123545519+00:00,160,1,432669,C,A,64.83,1,26,8058566367079,128,16447,94379395,CLX5
2025-09-24 19:42:02.123645527+00:00,160,1,432669,A,B,64.81,1,26,8058566369993,128,14285,94379398,CLX5
2025-09-24 19:42:02.123857545+00:00,160,1,432669,A,A,64.83,1,26,8058566369995,128,16120,94379404,CLX5
2025-09-24 19:42:02.123859155+00:00,160,1,432669,C,B,64.82,2,26,8058566369989,128,18262,94379405,CLX5
2025-09-24 19:42:02.124128155+00:00,160,1,432669,A,B,64.81,1,26,8058566370000,128,13782,94379414,CLX5
2025-09-24 19:42:02.124184773+00:00,160,1,432669,C,B,64.78,1,26,8058566369877,128,18179,94379415,CLX5
2025-09-24 19:42:02.124222135+00:00,160,1,432669,A,B,64.81,1,26,8058566370002,128,13699,94379420,CLX5
2025-09-24 19:42:02.429172723+00:00,160,1,432669,M,A,64.93,1,26,8058566157942,128,17970,94379450,CLX5
2025-09-24 19:42:03.041024419+00:00,160,1,432669,A,B,64.78,1,26,8058566370019,128,18417,94379481,CLX5
2025-09-24 19:42:03.099043873+00:00,160,1,432669,C,A,64.83,1,26,8058566369995,128,19164,94379484,CLX5
2025-09-24 19:42:04.543074167+00:00,160,1,432669,C,A,65.1,1,26,8058566364843,128,24922,94379490,CLX5
2025-09-24 19:42:05.014517407+00:00,160,1,432669,C,A,65.07,1,26,8058566364716,128,21301,94379491,CLX5
2025-09-24 19:42:05.061265769+00:00,160,1,432669,A,A,65.06,1,26,8058566370024,128,20546,94379492,CLX5
2025-09-24 19:42:05.201975535+00:00,160,1,432669,C,A,65.1,1,26,8058566364828,128,20553,94379494,CLX5
2025-09-24 19:42:05.264534111+00:00,160,1,432669,A,A,65.09,1,26,8058566370025,128,20852,94379495,CLX5
2025-09-24 19:42:05.498361419+00:00,160,1,432669,C,B,64.66,4,26,8058564618281,128,28168,94379496,CLX5
2025-09-24 19:42:06.441906217+00:00,160,1,432669,A,A,64.83,1,26,8058566370028,128,19853,94379506,CLX5
2025-09-24 19:42:07.200582685+00:00,160,1,432669,A,A,64.83,1,26,8058566370042,128,18313,94379601,CLX5
2025-09-24 19:42:07.366939723+00:00,160,1,432669,A,B,64.82,2,26,8058566370063,128,16352,94379686,CLX5
2025-09-24 19:42:07.366940051+00:00,160,1,432669,A,B,64.82,3,26,8058566370064,128,18284,94379691,CLX5
2025-09-24 19:42:07.366941003+00:00,160,1,432669,A,B,64.82,2,26,8058566370066,128,15828,94379695,CLX5
2025-09-24 19:42:07.366942513+00:00,160,1,432669,C,A,64.85,2,26,8058566369841,128,18678,94379700,CLX5
2025-09-24 19:42:07.367292327+00:00,160,1,432669,C,A,64.85,1,26,8058566367153,128,17353,94379755,CLX5
2025-09-24 19:42:07.367303195+00:00,160,1,432669,A,B,64.82,1,26,8058566370086,128,19993,94379761,CLX5
2025-09-24 19:42:07.367323565+00:00,160,1,432669,A,B,64.82,1,26,8058566370087,128,13448,94379762,CLX5
2025-09-24 19:42:07.367523581+00:00,160,1,432669,C,B,64.78,1,26,8058566370019,128,14675,94379773,CLX5
2025-09-24 19:42:07.367531127+00:00,160,1,432669,C,B,64.82,2,26,8058566370066,128,14927,94379775,CLX5
2025-09-24 19:42:07.367542417+00:00,160,1,432669,A,B,64.79,1,26,8058566370097,128,14414,94379781,CLX5
2025-09-24 19:42:07.367648451+00:00,160,1,432669,A,B,64.82,1,26,8058566370103,128,19855,94379794,CLX5
2025-09-24 19:42:07.367686563+00:00,160,1,432669,A,B,64.82,2,26,8058566370108,128,15876,94379800,CLX5
2025-09-24 19:42:07.367791869+00:00,160,1,432669,A,B,64.8,2,26,8058566370110,128,15785,94379807,CLX5
2025-09-24 19:42:07.367985781+00:00,160,1,432669,A,B,64.82,1,26,8058566370120,128,14380,94379825,CLX5
2025-09-24 19:42:07.368005809+00:00,160,1,432669,A,B,64.82,1,26,8058566370122,128,15911,94379837,CLX5
2025-09-24 19:42:07.368065131+00:00,160,1,432669,A,B,64.82,1,26,8058566370126,128,15607,94379859,CLX5
2025-09-24 19:42:07.368094891+00:00,160,1,432669,A,B,64.82,1,26,8058566370128,128,14388,94379866,CLX5
2025-09-24 19:42:07.368121807+00:00,160,1,432669,A,B,64.82,1,26,8058566370130,128,18778,94379870,CLX5
2025-09-24 19:42:07.368327545+00:00,160,1,432669,C,B,64.82,1,26,8058566370120,128,15019,94379883,CLX5
2025-09-24 19:42:07.368589287+00:00,160,1,432669,C,B,64.82,3,26,8058566370064,128,20182,94379895,CLX5
2025-09-24 19:42:07.368599559+00:00,160,1,432669,C,B,64.82,2,26,8058566370063,128,16041,94379896,CLX5
2025-09-24 19:42:07.369079693+00:00,160,1,432669,A,B,64.82,3,26,8058566370142,128,14806,94379913,CLX5
2025-09-24 19:42:07.369188955+00:00,160,1,432669,C,B,64.82,2,26,8058566370108,128,15927,94379926,CLX5
2025-09-24 19:42:07.369831407+00:00,160,1,432669,A,A,64.83,1,26,8058566370157,128,15447,94379980,CLX5
2025-09-24 19:42:07.369844067+00:00,160,1,432669,C,B,64.82,1,26,8058566370103,128,15912,94379982,CLX5
2025-09-24 19:42:07.371339489+00:00,160,1,432669,C,B,64.82,1,26,8058566370122,128,16054,94380039,CLX5
2025-09-24 19:42:07.371610467+00:00,160,1,432669,M,B,64.81,3,26,8058566345944,128,14931,94380050,CLX5
2025-09-24 19:42:07.372368257+00:00,160,1,432669,C,B,64.8,2,26,8058566370110,128,13534,94380069,CLX5
2025-09-24 19:42:07.372980845+00:00,160,1,432669,C,B,64.82,3,26,8058566370142,128,13597,94380098,CLX5
2025-09-24 19:42:07.418130955+00:00,160,1,432669,A,A,65.9,1,26,8058566370239,128,18358,94380279,CLX5
2025-09-24 19:42:07.512434159+00:00,160,1,432669,A,A,64.87,2,26,8058566370295,128,18190,94380359,CLX5
2025-09-24 19:42:07.515293875+00:00,160,1,432669,C,B,64.82,1,26,8058566370130,128,22535,94380362,CLX5
2025-09-24 19:42:07.515308313+00:00,160,1,432669,C,B,64.82,1,26,8058566370128,128,13337,94380363,CLX5
2025-09-24 19:42:07.527436187+00:00,160,1,432669,C,B,64.82,1,26,8058566370126,128,18446,94380374,CLX5
2025-09-24 19:42:07.527602701+00:00,160,1,432669,A,A,64.85,2,26,8058566370305,128,15594,94380394,CLX5
2025-09-24 19:42:07.612431335+00:00,160,1,432669,C,A,64.87,2,26,8058566370295,128,20143,94380446,CLX5
2025-09-24 19:42:07.618114017+00:00,160,1,432669,C,A,65.9,1,26,8058566370239,128,17978,94380447,CLX5
2025-09-24 19:42:07.640844085+00:00,160,1,432669,A,B,64.79,1,26,8058566370342,128,18485,94380465,CLX5
2025-09-24 19:42:07.641140903+00:00,160,1,432669,A,B,64.82,2,26,8058566370344,128,14365,94380471,CLX5
2025-09-24 19:42:07.674658593+00:00,160,1,432669,C,B,64.79,1,26,8058566370097,128,18212,94380505,CLX5
2025-09-24 19:42:08.944454923+00:00,160,1,432669,C,B,64.81,1,26,8058566370002,128,18515,94380596,CLX5
2025-09-24 19:42:08.944632017+00:00,160,1,432669,C,B,64.81,1,26,8058566370000,128,14840,94380598,CLX5
2025-09-24 19:42:08.944766007+00:00,160,1,432669,C,B,64.82,2,26,8058566370344,128,14646,94380601,CLX5
2025-09-24 19:42:08.944782441+00:00,160,1,432669,C,B,64.81,1,26,8058566369993,128,14109,94380603,CLX5
2025-09-24 19:42:08.944982919+00:00,160,1,432669,T,A,64.82,2,26,8058566370420,0,18625,94380607,CLX5
2025-09-24 19:42:08.944982919+00:00,160,1,432669,F,B,64.82,1,26,8058566370086,0,18625,94380607,CLX5
2025-09-24 19:42:08.944982919+00:00,160,1,432669,F,B,64.82,1,26,8058566370087,0,18625,94380607,CLX5
2025-09-24 19:42:08.944982919+00:00,160,1,432669,C,B,64.82,1,26,8058566370086,0,14600,94380608,CLX5
2025-09-24 19:42:08.944982919+00:00,160,1,432669,C,B,64.82,1,26,8058566370087,128,14600,94380608,CLX5
2025-09-24 19:42:08.945303507+00:00,160,1,432669,A,A,64.82,1,26,8058566370421,128,18810,94380612,CLX5
2025-09-24 19:42:08.945305715+00:00,160,1,432669,A,A,64.82,1,26,8058566370424,128,14479,94380618,CLX5
2025-09-24 19:42:08.945502201+00:00,160,1,432669,T,B,64.82,1,26,8058566370431,0,14425,94380633,CLX5
2025-09-24 19:42:08.945502201+00:00,160,1,432669,F,A,64.82,1,26,8058566370421,0,14425,94380633,CLX5
2025-09-24 19:42:08.945502201+00:00,160,1,432669,C,A,64.82,1,26,8058566370421,128,18365,94380634,CLX5
2025-09-24 19:42:08.945636979+00:00,160,1,432669,M,B,63.66,4,26,8058566345944,128,18321,94380647,CLX5
2025-09-24 19:42:08.945637515+00:00,160,1,432669,M,A,64.82,1,26,8058566369899,128,14773,94380648,CLX5
2025-09-24 19:42:08.945686013+00:00,160,1,432669,C,A,64.83,1,26,8058566370028,128,18244,94380653,CLX5
2025-09-24 19:42:08.945910355+00:00,160,1,432669,T,N,64.82,1,26,0,0,15109,94380668,CLX5
2025-09-24 19:42:08.945910355+00:00,160,1,432669,F,N,64.82,1,26,8058566370424,0,15109,94380668,CLX5
2025-09-24 19:42:08.945910355+00:00,160,1,432669,C,A,64.82,1,26,8058566370424,128,15109,94380668,CLX5
2025-09-24 19:42:08.946080229+00:00,160,1,432669,A,A,64.85,1,26,8058566370445,128,18318,94380676,CLX5
2025-09-24 19:42:08.946287867+00:00,160,1,432669,A,A,64.83,1,26,8058566370447,128,14538,94380679,CLX5
2025-09-24 19:42:08.946388375+00:00,160,1,432669,T,B,64.82,1,26,8058566370448,0,15578,94380685,CLX5
2025-09-24 19:42:08.946388375+00:00,160,1,432669,F,A,64.82,1,26,8058566369899,0,15578,94380685,CLX5
2025-09-24 19:42:08.946388375+00:00,160,1,432669,C,A,64.82,1,26,8058566369899,128,14496,94380686,CLX5
2025-09-24 19:42:08.946770285+00:00,160,1,432669,A,B,64.82,1,26,8058566370456,128,18110,94380705,CLX5
2025-09-24 19:42:08.946960875+00:00,160,1,432669,C,B,64.79,1,26,8058566370342,128,13650,94380710,CLX5
2025-09-24 19:42:08.946973833+00:00,160,1,432669,A,B,64.79,1,26,8058566370459,128,14942,94380716,CLX5
2025-09-24 19:42:08.947440335+00:00,160,1,432669,C,A,64.83,1,26,8058566370447,128,14877,94380739,CLX5
2025-09-24 19:42:08.955601281+00:00,160,1,432669,A,A,64.83,1,26,8058566370474,128,18382,94380780,CLX5
2025-09-24 19:42:08.955755525+00:00,160,1,432669,A,A,64.83,1,26,8058566370475,128,16063,94380784,CLX5
2025-09-24 19:42:09.124667311+00:00,160,1,432669,C,A,64.85,1,26,8058566370445,128,18126,94380805,CLX5
2025-09-24 19:42:09.124837933+00:00,160,1,432669,C,A,64.83,1,26,8058566370475,128,14934,94380807,CLX5
2025-09-24 19:42:09.124842733+00:00,160,1,432669,C,A,64.83,1,26,8058566370474,128,15233,94380808,CLX5
2025-09-24 19:42:09.124989493+00:00,160,1,432669,A,B,64.82,1,26,8058566370486,128,14250,94380813,CLX5
2025-09-24 19:42:09.140871665+00:00,160,1,432669,A,B,64.78,1,26,8058566370489,128,18091,94380819,CLX5
2025-09-24 19:42:09.254666849+00:00,160,1,432669,C,B,64.79,1,26,8058566370459,128,18275,94380828,CLX5
2025-09-24 19:42:09.537861761+00:00,160,1,432669,C,B,64.77,1,26,8058566219742,128,22785,94380864,CLX5
2025-09-24 19:42:10.462992677+00:00,160,1,432669,T,A,64.82,2,26,8058566370550,0,18899,94380948,CLX5
2025-09-24 19:42:10.462992677+00:00,160,1,432669,F,B,64.82,1,26,8058566370456,0,18899,94380948,CLX5
2025-09-24 19:42:10.462992677+00:00,160,1,432669,F,B,64.82,1,26,8058566370486,0,18899,94380948,CLX5
2025-09-24 19:42:10.462992677+00:00,160,1,432669,C,B,64.82,1,26,8058566370456,0,14552,94380949,CLX5
2025-09-24 19:42:10.462992677+00:00,160,1,432669,C,B,64.82,1,26,8058566370486,128,14552,94380949,CLX5
2025-09-24 19:42:10.463883689+00:00,160,1,432669,A,A,64.83,1,26,8058566370551,128,17406,94380955,CLX5
2025-09-24 19:42:10.463941343+00:00,160,1,432669,A,A,64.83,1,26,8058566370552,128,15233,94380956,CLX5
2025-09-24 19:42:10.464065043+00:00,160,1,432669,A,A,64.83,1,26,8058566370553,128,18642,94380957,CLX5
2025-09-24 19:42:10.464093803+00:00,160,1,432669,A,A,64.83,1,26,8058566370554,128,14735,94380958,CLX5
2025-09-24 19:42:10.470195219+00:00,160,1,432669,A,B,63.67,4,26,8058566370556,128,17684,94380960,CLX5
2025-09-24 19:42:10.833802943+00:00,160,1,432669,C,A,64.83,1,26,8058566370554,128,20905,94381108,CLX5
2025-09-24 19:42:10.833815403+00:00,160,1,432669,C,A,64.83,1,26,8058566370553,128,14893,94381109,CLX5
2025-09-24 19:42:10.833817131+00:00,160,1,432669,C,A,64.83,1,26,8058566370552,128,14794,94381110,CLX5
2025-09-24 19:42:11.089817057+00:00,160,1,432669,A,B,64.81,1,26,8058566370641,128,14805,94381201,CLX5
2025-09-24 19:42:11.090018205+00:00,160,1,432669,A,B,64.82,2,26,8058566370642,128,14555,94381203,CLX5
2025-09-24 19:42:11.090136627+00:00,160,1,432669,T,A,64.82,2,26,8058566370644,0,17756,94381213,CLX5
2025-09-24 19:42:11.090136627+00:00,160,1,432669,F,B,64.82,2,26,8058566370642,0,17756,94381213,CLX5
2025-09-24 19:42:11.090136627+00:00,160,1,432669,C,B,64.82,2,26,8058566370642,128,14529,94381214,CLX5
2025-09-24 19:42:11.090231491+00:00,160,1,432669,A,B,64.81,1,26,8058566370645,128,14690,94381217,CLX5
2025-09-24 19:42:11.090301875+00:00,160,1,432669,A,B,64.82,1,26,8058566370647,128,16254,94381220,CLX5
2025-09-24 19:42:11.090458885+00:00,160,1,432669,T,A,64.82,2,26,8058566370649,0,17345,94381227,CLX5
2025-09-24 19:42:11.090458885+00:00,160,1,432669,F,B,64.82,1,26,8058566370647,0,17345,94381227,CLX5
2025-09-24 19:42:11.090458885+00:00,160,1,432669,C,B,64.82,1,26,8058566370647,128,14824,94381228,CLX5
2025-09-24 19:42:11.090494385+00:00,160,1,432669,A,A,64.87,1,26,8058566370651,128,17059,94381233,CLX5
2025-09-24 19:42:11.090523587+00:00,160,1,432669,A,B,64.81,1,26,8058566370652,128,18103,94381235,CLX5
2025-09-24 19:42:11.090870343+00:00,160,1,432669,A,A,64.82,1,26,8058566370659,128,14316,94381246,CLX5
2025-09-24 19:42:11.091293205+00:00,160,1,432669,T,B,64.82,1,26,8058566370663,0,18222,94381254,CLX5
2025-09-24 19:42:11.091293205+00:00,160,1,432669,F,A,64.82,1,26,8058566370659,0,18222,94381254,CLX5
2025-09-24 19:42:11.091293205+00:00,160,1,432669,C,A,64.82,1,26,8058566370659,128,14533,94381255,CLX5
2025-09-24 19:42:11.091401947+00:00,160,1,432669,M,A,64.82,1,26,8058566370651,128,16777,94381261,CLX5
2025-09-24 19:42:11.091456877+00:00,160,1,432669,C,A,64.83,1,26,8058566370551,128,14538,94381267,CLX5
2025-09-24 19:42:11.091589735+00:00,160,1,432669,A,B,64.79,1,26,8058566370670,128,15921,94381273,CLX5
2025-09-24 19:42:11.091816245+00:00,160,1,432669,A,A,64.85,1,26,8058566370671,128,14344,94381281,CLX5
2025-09-24 19:42:11.141889959+00:00,160,1,432669,A,A,64.82,1,26,8058566370675,128,16849,94381300,CLX5
2025-09-24 19:42:11.142075865+00:00,160,1,432669,C,B,64.81,1,26,8058566369670,128,14696,94381304,CLX5
2025-09-24 19:42:11.142089975+00:00,160,1,432669,A,B,64.8,1,26,8058566370676,128,14474,94381305,CLX5
2025-09-24 19:42:11.274676753+00:00,160,1,432669,C,B,64.79,1,26,8058566370670,128,18334,94381318,CLX5
2025-09-24 19:42:11.386878021+00:00,160,1,432669,C,B,64.81,1,26,8058566370652,128,18856,94381321,CLX5
2025-09-24 19:42:11.386880633+00:00,160,1,432669,C,B,64.81,1,26,8058566370645,128,14788,94381322,CLX5
2025-09-24 19:42:11.501787007+00:00,160,1,432669,C,B,64.81,1,26,8058566370641,128,15237,94381368,CLX5
2025-09-24 19:42:13.871475109+00:00,160,1,432669,M,A,64.83,3,26,8058566321460,128,18157,94381463,CLX5
2025-09-24 19:42:14.324862797+00:00,160,1,432669,A,A,64.82,2,26,8058566370745,128,19451,94381479,CLX5
2025-09-24 19:42:14.325397591+00:00,160,1,432669,A,A,64.82,1,26,8058566370752,128,20867,94381501,CLX5
2025-09-24 19:42:14.325538703+00:00,160,1,432669,A,A,64.82,1,26,8058566370754,128,16571,94381508,CLX5
2025-09-24 19:42:14.442718083+00:00,160,1,432669,M,A,64.82,1,26,8058566370042,128,21875,94381538,CLX5
2025-09-24 19:42:14.549192015+00:00,160,1,432669,A,A,64.82,1,26,8058566370780,128,19472,94381590,CLX5
2025-09-24 19:42:14.554028435+00:00,160,1,432669,T,A,64.81,1,26,8058566370042,0,16774,94381594,CLX5
2025-09-24 19:42:14.554028435+00:00,160,1,432669,F,A,64.81,1,26,8058566370042,0,16774,94381594,CLX5
2025-09-24 19:42:14.554028435+00:00,160,1,432669,F,B,64.81,1,26,8058566368680,0,16774,94381594,CLX5
2025-09-24 19:42:14.554028435+00:00,160,1,432669,M,B,64.81,1,26,8058566368680,0,16513,94381595,CLX5
2025-09-24 19:42:14.554028435+00:00,160,1,432669,C,A,64.82,1,26,8058566370042,128,16513,94381595,CLX5
2025-09-24 19:42:14.554294843+00:00,160,1,432669,A,A,64.82,2,26,8058566370782,128,19456,94381596,CLX5
2025-09-24 19:42:14.554304365+00:00,160,1,432669,A,A,64.82,1,26,8058566370783,128,16171,94381597,CLX5
2025-09-24 19:42:14.554370315+00:00,160,1,432669,C,A,64.82,1,26,8058566370783,128,14845,94381601,CLX5
2025-09-24 19:42:14.559858777+00:00,160,1,432669,T,A,64.81,1,26,8058566370790,0,17999,94381617,CLX5
2025-09-24 19:42:14.559858777+00:00,160,1,432669,F,B,64.81,1,26,8058566368680,0,17999,94381617,CLX5
2025-09-24 19:42:14.559858777+00:00,160,1,432669,C,B,64.81,1,26,8058566368680,128,14961,94381618,CLX5
2025-09-24 19:42:14.564582823+00:00,160,1,432669,T,A,64.81,1,26,8058566370796,0,19356,94381647,CLX5
2025-09-24 19:42:14.564582823+00:00,160,1,432669,F,B,64.81,1,26,8058566368681,0,19356,94381647,CLX5
2025-09-24 19:42:14.564582823+00:00,160,1,432669,M,B,64.81,1,26,8058566368681,128,14894,94381648,CLX5
2025-09-24 19:42:14.564846581+00:00,160,1,432669,C,A,64.82,2,26,8058566370782,128,19505,94381649,CLX5
2025-09-24 19:42:14.564898073+00:00,160,1,432669,A,A,64.82,1,26,8058566370798,128,19720,94381654,CLX5
2025-09-24 19:42:14.565017531+00:00,160,1,432669,A,A,64.82,1,26,8058566370799,128,16039,94381655,CLX5
2025-09-24 19:42:14.565117597+00:00,160,1,432669,A,A,64.82,1,26,8058566370800,128,17646,94381656,CLX5
2025-09-24 19:42:14.569347843+00:00,160,1,432669,T,A,64.81,1,26,8058566370816,0,18138,94381701,CLX5
2025-09-24 19:42:14.569347843+00:00,160,1,432669,F,B,64.81,1,26,8058566368681,0,18138,94381701,CLX5
2025-09-24 19:42:14.569347843+00:00,160,1,432669,C,B,64.81,1,26,8058566368681,128,15597,94381702,CLX5
2025-09-24 19:42:14.569578213+00:00,160,1,432669,A,A,64.82,1,26,8058566370818,128,16814,94381704,CLX5
2025-09-24 19:42:14.569594513+00:00,160,1,432669,A,A,64.82,1,26,8058566370819,128,14397,94381705,CLX5
2025-09-24 19:42:14.573900691+00:00,160,1,432669,T,A,64.81,1,26,8058566370825,0,18221,94381724,CLX5
2025-09-24 19:42:14.573900691+00:00,160,1,432669,F,B,64.81,1,26,8058566368682,0,18221,94381724,CLX5
2025-09-24 19:42:14.573900691+00:00,160,1,432669,M,B,64.81,1,26,8058566368682,128,15473,94381725,CLX5
2025-09-24 19:42:14.574512241+00:00,160,1,432669,A,A,64.82,1,26,8058566370831,128,19756,94381739,CLX5
2025-09-24 19:42:14.574671593+00:00,160,1,432669,C,A,64.82,1,26,8058566370831,128,17803,94381740,CLX5
2025-09-24 19:42:14.574942245+00:00,160,1,432669,A,A,64.82,1,26,8058566370832,128,18957,94381741,CLX5
2025-09-24 19:42:14.575199783+00:00,160,1,432669,C,A,64.82,1,26,8058566370832,128,15441,94381744,CLX5
2025-09-24 19:42:14.576907453+00:00,160,1,432669,A,A,64.82,1,26,8058566370836,128,19471,94381750,CLX5
2025-09-24 19:42:14.578536807+00:00,160,1,432669,A,A,64.82,1,26,8058566370837,128,19834,94381763,CLX5
2025-09-24 19:42:14.578688615+00:00,160,1,432669,C,A,64.82,1,26,8058566370836,128,19081,94381765,CLX5
2025-09-24 19:42:14.618206903+00:00,160,1,432669,C,A,65.7,6,26,8058566369757,128,18220,94381771,CLX5
2025-09-24 19:42:14.835658907+00:00,160,1,432669,C,A,64.82,1,26,8058566370819,128,20315,94381808,CLX5
2025-09-24 19:42:15.811529075+00:00,160,1,432669,C,A,64.82,1,26,8058566370800,128,21224,94381860,CLX5
2025-09-24 19:42:15.811691173+00:00,160,1,432669,C,A,64.82,1,26,8058566370818,128,15811,94381863,CLX5
2025-09-24 19:42:15.811865059+00:00,160,1,432669,C,A,64.82,1,26,8058566370799,128,16078,94381869,CLX5
2025-09-24 19:42:16.043485233+00:00,160,1,432669,A,A,64.82,1,26,8058566370895,128,15983,94381917,CLX5
2025-09-24 19:42:16.043667105+00:00,160,1,432669,C,A,64.82,1,26,8058566370895,128,16072,94381919,CLX5
2025-09-24 19:42:16.043707769+00:00,160,1,432669,A,A,64.82,1,26,8058566370896,128,18770,94381921,CLX5
2025-09-24 19:42:16.043820487+00:00,160,1,432669,A,A,64.82,1,26,8058566370897,128,14430,94381924,CLX5
2025-09-24 19:42:16.364629059+00:00,160,1,432669,C,A,64.82,1,26,8058566370897,128,19283,94381937,CLX5
2025-09-24 19:42:16.364639387+00:00,160,1,432669,C,A,64.82,1,26,8058566370896,128,15772,94381938,CLX5
2025-09-24 19:42:17.470797845+00:00,160,1,432669,C,A,64.82,1,26,8058566370798,128,21290,94382014,CLX5
2025-09-24 19:42:18.845888035+00:00,160,1,432669,C,B,64.75,1,26,8058566347345,128,18886,94382024,CLX5
2025-09-24 19:42:19.003588647+00:00,160,1,432669,A,B,64.76,1,26,8058566370942,128,19658,94382025,CLX5
2025-09-24 19:42:20.212884839+00:00,160,1,432669,A,A,64.82,2,26,8058566370946,128,28029,94382031,CLX5
2025-09-24 19:42:20.212963941+00:00,160,1,432669,A,A,64.82,1,26,8058566370947,128,19769,94382032,CLX5
2025-09-24 19:42:20.843525491+00:00,160,1,432669,T,A,64.81,1,26,8058566370837,0,20707,94382041,CLX5
2025-09-24 19:42:20.843525491+00:00,160,1,432669,F,A,64.81,1,26,8058566370837,0,20707,94382041,CLX5
2025-09-24 19:42:20.843525491+00:00,160,1,432669,F,B,64.81,1,26,8058566368682,0,20707,94382041,CLX5
2025-09-24 19:42:20.843525491+00:00,160,1,432669,C,B,64.81,1,26,8058566368682,0,18736,94382042,CLX5
2025-09-24 19:42:20.843525491+00:00,160,1,432669,C,A,64.82,1,26,8058566370837,128,18736,94382042,CLX5
2025-09-24 19:42:20.843819911+00:00,160,1,432669,A,A,64.82,1,26,8058566370949,128,19133,94382044,CLX5
2025-09-24 19:42:20.843822273+00:00,160,1,432669,A,A,64.82,1,26,8058566370950,128,19118,94382045,CLX5
2025-09-24 19:42:20.843831085+00:00,160,1,432669,A,A,64.82,1,26,8058566370951,128,21437,94382047,CLX5
2025-09-24 19:42:20.843879467+00:00,160,1,432669,C,A,64.82,1,26,8058566370951,128,18234,94382049,CLX5
2025-09-24 19:42:20.844024997+00:00,160,1,432669,A,A,64.82,1,26,8058566370955,128,18513,94382053,CLX5
2025-09-24 19:42:20.849500077+00:00,160,1,432669,T,A,64.81,1,26,8058566370959,0,20575,94382073,CLX5
2025-09-24 19:42:20.849500077+00:00,160,1,432669,F,B,64.81,1,26,8058566368683,0,20575,94382073,CLX5
2025-09-24 19:42:20.849500077+00:00,160,1,432669,C,B,64.81,1,26,8058566368683,128,17460,94382074,CLX5
2025-09-24 19:42:20.853827239+00:00,160,1,432669,T,A,64.81,1,26,8058566370960,0,21809,94382084,CLX5
2025-09-24 19:42:20.853827239+00:00,160,1,432669,F,B,64.81,1,26,8058566368705,0,21809,94382084,CLX5
2025-09-24 19:42:20.853827239+00:00,160,1,432669,C,B,64.81,1,26,8058566368705,128,22637,94382085,CLX5
2025-09-24 19:42:20.858192609+00:00,160,1,432669,A,A,64.82,1,26,8058566370963,128,23245,94382093,CLX5
2025-09-24 19:42:20.858366495+00:00,160,1,432669,A,B,64.81,1,26,8058566370964,128,21968,94382094,CLX5
2025-09-24 19:42:20.864238959+00:00,160,1,432669,C,B,64.81,1,26,8058566370964,128,23051,94382095,CLX5
2025-09-24 19:42:21.289284933+00:00,160,1,432669,C,A,64.82,1,26,8058566370955,128,23410,94382098,CLX5
2025-09-24 19:42:21.289457763+00:00,160,1,432669,C,A,64.82,1,26,8058566370950,128,22119,94382105,CLX5
2025-09-24 19:42:21.289654805+00:00,160,1,432669,C,A,64.82,1,26,8058566370949,128,18003,94382107,CLX5
2025-09-24 19:42:21.573507271+00:00,160,1,432669,A,A,64.82,1,26,8058566370967,128,24737,94382115,CLX5
2025-09-24 19:42:24.314564801+00:00,160,1,432669,A,B,64.35,2,26,8058566370970,128,23487,94382128,CLX5
2025-09-24 19:42:25.248123877+00:00,160,1,432669,C,A,64.82,2,26,8058566370946,128,22811,94382142,CLX5
2025-09-24 19:42:25.248124453+00:00,160,1,432669,C,A,64.82,1,26,8058566370947,128,19061,94382143,CLX5
2025-09-24 19:42:25.248445405+00:00,160,1,432669,A,B,64.81,1,26,8058566370977,128,21933,94382147,CLX5
2025-09-24 19:42:25.249277073+00:00,160,1,432669,C,A,64.82,1,26,8058566370754,128,19315,94382162,CLX5
2025-09-24 19:42:25.318438259+00:00,160,1,432669,A,A,65.7,6,26,8058566370999,128,22552,94382201,CLX5
2025-09-24 19:42:25.564641263+00:00,160,1,432669,C,A,64.82,2,26,8058566370745,128,22482,94382211,CLX5
2025-09-24 19:42:25.565379181+00:00,160,1,432669,A,B,64.81,2,26,8058566371004,128,20774,94382213,CLX5
2025-09-24 19:42:25.565379701+00:00,160,1,432669,A,B,64.81,2,26,8058566371005,128,16716,94382214,CLX5
2025-09-24 19:42:25.565379879+00:00,160,1,432669,A,B,64.81,2,26,8058566371006,128,20355,94382215,CLX5
2025-09-24 19:42:25.565380053+00:00,160,1,432669,A,B,64.81,1,26,8058566371007,128,17260,94382216,CLX5
2025-09-24 19:42:25.566933237+00:00,160,1,432669,T,B,64.82,1,26,8058566369797,0,20339,94382243,CLX5
2025-09-24 19:42:25.566933237+00:00,160,1,432669,F,B,64.82,1,26,8058566369797,0,20339,94382243,CLX5
2025-09-24 19:42:25.566933237+00:00,160,1,432669,F,A,64.82,1,26,8058566370651,0,20339,94382243,CLX5
2025-09-24 19:42:25.566933237+00:00,160,1,432669,C,B,64.81,1,26,8058566369797,0,19283,94382244,CLX5
2025-09-24 19:42:25.566933237+00:00,160,1,432669,C,A,64.82,1,26,8058566370651,128,19283,94382244,CLX5
2025-09-24 19:42:25.567246815+00:00,160,1,432669,T,B,64.82,2,26,8058566371012,0,20646,94382248,CLX5
2025-09-24 19:42:25.567246815+00:00,160,1,432669,F,A,64.82,1,26,8058566370675,0,20646,94382248,CLX5
2025-09-24 19:42:25.567246815+00:00,160,1,432669,F,A,64.82,1,26,8058566370752,0,20646,94382248,CLX5
2025-09-24 19:42:25.567246815+00:00,160,1,432669,C,A,64.82,1,26,8058566370675,0,18938,94382249,CLX5
2025-09-24 19:42:25.567246815+00:00,160,1,432669,C,A,64.82,1,26,8058566370752,128,18938,94382249,CLX5
2025-09-24 19:42:25.612487127+00:00,160,1,432669,A,B,64.81,1,26,8058566371028,128,20924,94382295,CLX5
2025-09-24 19:42:25.612652373+00:00,160,1,432669,A,B,64.81,1,26,8058566371029,128,20527,94382296,CLX5
2025-09-24 19:42:25.612801609+00:00,160,1,432669,T,B,64.82,3,26,8058566371030,0,22121,94382297,CLX5
2025-09-24 19:42:25.612801609+00:00,160,1,432669,F,A,64.82,1,26,8058566370780,0,22121,94382297,CLX5
2025-09-24 19:42:25.612801609+00:00,160,1,432669,F,A,64.82,1,26,8058566370963,0,22121,94382297,CLX5
2025-09-24 19:42:25.612801609+00:00,160,1,432669,F,A,64.82,1,26,8058566370967,0,22121,94382297,CLX5
2025-09-24 19:42:25.612801609+00:00,160,1,432669,C,A,64.82,1,26,8058566370780,0,17718,94382298,CLX5
2025-09-24 19:42:25.612801609+00:00,160,1,432669,C,A,64.82,1,26,8058566370963,0,17718,94382298,CLX5
2025-09-24 19:42:25.612801609+00:00,160,1,432669,C,A,64.82,1,26,8058566370967,128,17718,94382298,CLX5
2025-09-24 19:42:25.612807251+00:00,160,1,432669,A,B,64.81,1,26,8058566371031,128,19649,94382301,CLX5
2025-09-24 19:42:25.613281549+00:00,160,1,432669,C,A,64.83,3,26,8058566321460,128,16056,94382332,CLX5
2025-09-24 19:42:25.613689837+00:00,160,1,432669,C,A,64.85,1,26,8058566370671,128,15982,94382350,CLX5
2025-09-24 19:42:25.613702625+00:00,160,1,432669,C,B,64.78,1,26,8058566370489,128,18877,94382351,CLX5
2025-09-24 19:42:25.613946991+00:00,160,1,432669,A,A,64.83,1,26,8058566371043,128,16495,94382361,CLX5
2025-09-24 19:42:25.620024675+00:00,160,1,432669,A,A,64.82,1,26,8058566371053,128,16939,94382412,CLX5
2025-09-24 19:42:25.620210177+00:00,160,1,432669,A,A,64.82,2,26,8058566371054,128,17847,94382415,CLX5
2025-09-24 19:42:25.620245869+00:00,160,1,432669,A,B,64.81,1,26,8058566371056,128,14766,94382421,CLX5
2025-09-24 19:42:25.621646639+00:00,160,1,432669,T,B,64.82,1,26,8058566371057,0,17072,94382424,CLX5
2025-09-24 19:42:25.621646639+00:00,160,1,432669,F,A,64.82,1,26,8058566371053,0,17072,94382424,CLX5
2025-09-24 19:42:25.621646639+00:00,160,1,432669,C,A,64.82,1,26,8058566371053,128,15140,94382425,CLX5
2025-09-24 19:42:25.626138509+00:00,160,1,432669,A,A,64.82,1,26,8058566371061,128,17974,94382434,CLX5
2025-09-24 19:42:25.626304103+00:00,160,1,432669,C,B,64.81,1,26,8058566371056,128,18438,94382437,CLX5
2025-09-24 19:42:25.659345539+00:00,160,1,432669,A,A,64.85,1,26,8058566371070,128,18499,94382454,CLX5
2025-09-24 19:42:25.840901941+00:00,160,1,432669,A,B,64.78,1,26,8058566371099,128,18787,94382516,CLX5
2025-09-24 19:42:26.074779547+00:00,160,1,432669,C,B,64.81,1,26,8058566371031,128,19039,94382523,CLX5
2025-09-24 19:42:26.074793947+00:00,160,1,432669,C,B,64.81,1,26,8058566371029,128,14555,94382524,CLX5
2025-09-24 19:42:26.074964667+00:00,160,1,432669,C,B,64.81,1,26,8058566371028,128,18419,94382525,CLX5
2025-09-24 19:42:27.682970211+00:00,160,1,432669,A,B,64.81,4,26,8058566371116,128,18606,94382565,CLX5
2025-09-24 19:42:29.622068315+00:00,160,1,432669,T,A,64.81,4,26,8058566371127,0,25995,94382597,CLX5
2025-09-24 19:42:29.622068315+00:00,160,1,432669,F,B,64.81,1,26,8058566368735,0,25995,94382597,CLX5
2025-09-24 19:42:29.622068315+00:00,160,1,432669,F,B,64.81,1,26,8058566368736,0,25995,94382597,CLX5
2025-09-24 19:42:29.622068315+00:00,160,1,432669,F,B,64.81,2,26,8058566369547,0,25995,94382597,CLX5
2025-09-24 19:42:29.622068315+00:00,160,1,432669,C,B,64.81,1,26,8058566368735,0,19826,94382598,CLX5
2025-09-24 19:42:29.622068315+00:00,160,1,432669,C,B,64.81,1,26,8058566368736,0,19826,94382598,CLX5
2025-09-24 19:42:29.622068315+00:00,160,1,432669,C,B,64.81,2,26,8058566369547,128,19826,94382598,CLX5
2025-09-24 19:42:29.622363903+00:00,160,1,432669,A,A,64.82,1,26,8058566371128,128,18846,94382599,CLX5
2025-09-24 19:42:29.622366649+00:00,160,1,432669,A,A,64.82,1,26,8058566371129,128,18316,94382601,CLX5
2025-09-24 19:42:29.622378629+00:00,160,1,432669,A,A,64.82,1,26,8058566371130,128,17017,94382602,CLX5
2025-09-24 19:42:29.622431795+00:00,160,1,432669,A,A,64.82,1,26,8058566371134,128,16720,94382610,CLX5
2025-09-24 19:42:29.622447343+00:00,160,1,432669,A,A,64.82,2,26,8058566371135,128,19388,94382611,CLX5
2025-09-24 19:42:29.622497971+00:00,160,1,432669,A,B,64.81,1,26,8058566371137,128,15284,94382617,CLX5
2025-09-24 19:42:29.622555895+00:00,160,1,432669,A,A,64.82,1,26,8058566371140,128,16277,94382621,CLX5
2025-09-24 19:42:29.622581209+00:00,160,1,432669,C,A,64.82,1,26,8058566371130,128,17958,94382622,CLX5
2025-09-24 19:42:29.622716035+00:00,160,1,432669,C,A,64.82,2,26,8058566371135,128,16236,94382623,CLX5
2025-09-24 19:42:29.623097965+00:00,160,1,432669,C,A,64.82,1,26,8058566371134,128,19657,94382636,CLX5
2025-09-24 19:42:32.504308487+00:00,160,1,432669,C,B,64.78,1,26,8058566368731,128,17477,94382690,CLX5
2025-09-24 19:42:32.504308633+00:00,160,1,432669,C,B,64.77,1,26,8058566368670,128,20927,94382691,CLX5
2025-09-24 19:42:32.504309533+00:00,160,1,432669,C,B,64.78,1,26,8058566371099,128,16707,94382693,CLX5
2025-09-24 19:42:32.504309839+00:00,160,1,432669,C,B,64.79,2,26,8058566368882,128,16417,94382695,CLX5
2025-09-24 19:42:32.504311241+00:00,160,1,432669,C,B,64.72,2,26,8058566331591,128,20358,94382700,CLX5
2025-09-24 19:42:32.504311539+00:00,160,1,432669,C,B,64.78,2,26,8058566367628,128,16897,94382703,CLX5
2025-09-24 19:42:32.504343401+00:00,160,1,432669,A,A,64.82,1,26,8058566371156,128,22909,94382707,CLX5
2025-09-24 19:42:32.504388575+00:00,160,1,432669,A,A,64.82,3,26,8058566371158,128,16480,94382709,CLX5
2025-09-24 19:42:32.504468399+00:00,160,1,432669,A,A,64.82,2,26,8058566371162,128,19485,94382720,CLX5
2025-09-24 19:42:32.504468755+00:00,160,1,432669,A,A,64.82,1,26,8058566371164,128,14920,94382722,CLX5
2025-09-24 19:42:32.504469731+00:00,160,1,432669,A,A,64.82,2,26,8058566371166,128,15748,94382725,CLX5
2025-09-24 19:42:32.504493865+00:00,160,1,432669,C,B,64.81,2,26,8058566371005,128,14121,94382730,CLX5
2025-09-24 19:42:32.504494017+00:00,160,1,432669,C,B,64.81,1,26,8058566371007,128,15068,94382731,CLX5
2025-09-24 19:42:32.504507053+00:00,160,1,432669,C,B,64.81,2,26,8058566371004,128,18957,94382732,CLX5
2025-09-24 19:42:32.504507225+00:00,160,1,432669,A,A,64.82,2,26,8058566371167,128,15869,94382733,CLX5
2025-09-24 19:42:32.504507571+00:00,160,1,432669,A,A,64.82,2,26,8058566371168,128,16229,94382734,CLX5
2025-09-24 19:42:32.504520551+00:00,160,1,432669,C,B,64.81,2,26,8058566371006,128,16163,94382737,CLX5
2025-09-24 19:42:32.505160919+00:00,160,1,432669,C,A,64.82,1,26,8058566371156,128,14381,94382749,CLX5
2025-09-24 19:42:32.505182633+00:00,160,1,432669,C,A,64.82,2,26,8058566371166,128,19275,94382750,CLX5
2025-09-24 19:42:32.505733669+00:00,160,1,432669,A,A,64.82,1,26,8058566371179,128,15444,94382782,CLX5
2025-09-24 19:42:32.505825977+00:00,160,1,432669,C,A,64.82,2,26,8058566371168,128,15700,94382787,CLX5
2025-09-24 19:42:32.524786889+00:00,160,1,432669,A,B,64.77,1,26,8058566371203,128,17953,94382877,CLX5
2025-09-24 19:42:32.541174767+00:00,160,1,432669,A,B,64.78,1,26,8058566371213,128,18964,94382892,CLX5
2025-09-24 19:42:32.573939715+00:00,160,1,432669,A,B,64.79,2,26,8058566371218,128,17936,94382897,CLX5
2025-09-24 19:42:32.573943995+00:00,160,1,432669,A,B,64.78,2,26,8058566371219,128,14522,94382898,CLX5
2025-09-24 19:42:34.140395501+00:00,160,1,432669,C,A,64.82,2,26,8058566371167,128,19369,94382944,CLX5
2025-09-24 19:42:34.140556081+00:00,160,1,432669,A,B,64.78,1,26,8058566371248,128,14561,94382948,CLX5
2025-09-24 19:42:39.256801885+00:00,160,1,432669,A,B,64.81,2,26,8058566371324,128,19469,94383112,CLX5
2025-09-24 19:42:42.232266533+00:00,160,1,432669,A,A,64.82,1,26,8058566371341,128,19280,94383147,CLX5
2025-09-24 19:42:42.232275077+00:00,160,1,432669,C,B,64.81,1,26,8058566371137,128,22393,94383148,CLX5
2025-09-24 19:42:42.232508539+00:00,160,1,432669,A,B,64.81,1,26,8058566371343,128,21987,94383152,CLX5
2025-09-24 19:42:42.232571781+00:00,160,1,432669,C,A,64.82,1,26,8058566371341,128,19098,94383155,CLX5
2025-09-24 19:42:42.232574259+00:00,160,1,432669,C,B,64.81,1,26,8058566371343,128,27053,94383157,CLX5
2025-09-24 19:42:42.232785583+00:00,160,1,432669,A,B,64.81,1,26,8058566371349,128,16754,94383170,CLX5
2025-09-24 19:42:42.318642369+00:00,160,1,432669,C,A,65.7,6,26,8058566370999,128,18932,94383177,CLX5
2025-09-24 19:42:50.970411487+00:00,160,1,432669,M,A,64.89,3,26,8058566144143,128,20709,94383331,CLX5
2025-09-24 19:42:51.361548493+00:00,160,1,432669,T,A,64.81,1,26,8058566371404,0,19815,94383332,CLX5
2025-09-24 19:42:51.361548493+00:00,160,1,432669,F,B,64.81,1,26,8058566369603,0,19815,94383332,CLX5
2025-09-24 19:42:51.361548493+00:00,160,1,432669,C,B,64.81,1,26,8058566369603,128,15160,94383333,CLX5
2025-09-24 19:42:51.361882539+00:00,160,1,432669,A,A,64.82,1,26,8058566371406,128,15774,94383336,CLX5
2025-09-24 19:42:51.361886187+00:00,160,1,432669,C,B,64.81,1,26,8058566371349,128,18669,94383337,CLX5
2025-09-24 19:42:51.362041699+00:00,160,1,432669,C,A,64.82,1,26,8058566371406,128,15538,94383341,CLX5
2025-09-24 19:42:51.362098663+00:00,160,1,432669,A,B,64.81,1,26,8058566371408,128,14746,94383348,CLX5
2025-09-24 19:42:51.724563825+00:00,160,1,432669,T,A,64.81,1,26,8058566371415,0,19572,94383363,CLX5
2025-09-24 19:42:51.724563825+00:00,160,1,432669,F,B,64.81,1,26,8058566369607,0,19572,94383363,CLX5
2025-09-24 19:42:51.724563825+00:00,160,1,432669,C,B,64.81,1,26,8058566369607,128,14884,94383364,CLX5
2025-09-24 19:42:51.724873873+00:00,160,1,432669,A,A,64.82,1,26,8058566371416,128,15416,94383366,CLX5
2025-09-24 19:42:51.724877365+00:00,160,1,432669,A,A,64.82,1,26,8058566371417,128,15503,94383367,CLX5
2025-09-24 19:42:51.724957965+00:00,160,1,432669,C,A,64.82,1,26,8058566371416,128,18428,94383369,CLX5
2025-09-24 19:42:51.724964857+00:00,160,1,432669,C,B,64.81,1,26,8058566371408,128,15257,94383370,CLX5
2025-09-24 19:42:51.725113361+00:00,160,1,432669,C,A,64.82,1,26,8058566371417,128,14455,94383378,CLX5
2025-09-24 19:42:52.088516897+00:00,160,1,432669,T,A,64.81,1,26,8058566371420,0,17717,94383388,CLX5
2025-09-24 19:42:52.088516897+00:00,160,1,432669,F,B,64.81,1,26,8058566369621,0,17717,94383388,CLX5
2025-09-24 19:42:52.088516897+00:00,160,1,432669,C,B,64.81,1,26,8058566369621,128,15621,94383389,CLX5
2025-09-24 19:42:52.088785203+00:00,160,1,432669,A,A,64.82,2,26,8058566371421,128,18954,94383390,CLX5
2025-09-24 19:42:52.088806745+00:00,160,1,432669,A,A,64.82,1,26,8058566371422,128,15078,94383391,CLX5
2025-09-24 19:42:52.088970823+00:00,160,1,432669,A,A,64.82,1,26,8058566371423,128,18848,94383392,CLX5
2025-09-24 19:42:52.451612515+00:00,160,1,432669,T,A,64.81,1,26,8058566371426,0,18066,94383402,CLX5
2025-09-24 19:42:52.451612515+00:00,160,1,432669,F,B,64.81,1,26,8058566369628,0,18066,94383402,CLX5
2025-09-24 19:42:52.451612515+00:00,160,1,432669,M,B,64.81,1,26,8058566369628,128,16578,94383403,CLX5
2025-09-24 19:42:52.451923963+00:00,160,1,432669,C,B,64.81,3,26,8058566369689,128,15539,94383411,CLX5
2025-09-24 19:42:52.452043499+00:00,160,1,432669,M,A,64.82,1,26,8058566369708,128,16598,94383412,CLX5
2025-09-24 19:42:52.452140549+00:00,160,1,432669,A,A,64.86,2,26,8058566371432,128,17989,94383413,CLX5
2025-09-24 19:42:52.704253029+00:00,160,1,432669,A,B,64.81,1,26,8058566371442,128,19345,94383455,CLX5
2025-09-24 19:42:52.704437801+00:00,160,1,432669,C,A,64.82,1,26,8058566371422,128,16212,94383457,CLX5
2025-09-24 19:42:52.814734093+00:00,160,1,432669,T,A,64.81,1,26,8058566371444,0,19013,94383459,CLX5
2025-09-24 19:42:52.814734093+00:00,160,1,432669,F,B,64.81,1,26,8058566369628,0,19013,94383459,CLX5
2025-09-24 19:42:52.814734093+00:00,160,1,432669,C,B,64.81,1,26,8058566369628,128,15547,94383460,CLX5
2025-09-24 19:42:52.825440193+00:00,160,1,432669,A,B,64.81,1,26,8058566371445,128,19242,94383469,CLX5
2025-09-24 19:42:52.825633355+00:00,160,1,432669,A,A,64.82,1,26,8058566371446,128,20053,94383470,CLX5
2025-09-24 19:42:52.825800293+00:00,160,1,432669,A,A,64.82,1,26,8058566371447,128,18183,94383471,CLX5
2025-09-24 19:42:52.825959011+00:00,160,1,432669,A,A,64.82,1,26,8058566371448,128,14993,94383473,CLX5
2025-09-24 19:42:53.177834091+00:00,160,1,432669,T,A,64.81,1,26,8058566371451,0,20470,94383485,CLX5
2025-09-24 19:42:53.177834091+00:00,160,1,432669,F,B,64.81,1,26,8058566368370,0,20470,94383485,CLX5
2025-09-24 19:42:53.177834091+00:00,160,1,432669,C,B,64.81,1,26,8058566368370,128,16394,94383486,CLX5
2025-09-24 19:42:53.178194497+00:00,160,1,432669,A,B,64.8,1,26,8058566371452,128,17241,94383487,CLX5
2025-09-24 19:42:53.540934129+00:00,160,1,432669,T,A,64.81,1,26,8058566371455,0,19217,94383490,CLX5
2025-09-24 19:42:53.540934129+00:00,160,1,432669,F,B,64.81,1,26,8058566370977,0,19217,94383490,CLX5
2025-09-24 19:42:53.540934129+00:00,160,1,432669,C,B,64.81,1,26,8058566370977,128,16238,94383491,CLX5
2025-09-24 19:42:53.904073695+00:00,160,1,432669,T,A,64.81,1,26,8058566371457,0,22952,94383493,CLX5
2025-09-24 19:42:53.904073695+00:00,160,1,432669,F,B,64.81,1,26,8058566371116,0,22952,94383493,CLX5
2025-09-24 19:42:53.904073695+00:00,160,1,432669,M,B,64.81,3,26,8058566371116,128,18796,94383494,CLX5
2025-09-24 19:42:54.267138541+00:00,160,1,432669,T,A,64.81,1,26,8058566371460,0,17790,94383510,CLX5
2025-09-24 19:42:54.267138541+00:00,160,1,432669,F,B,64.81,1,26,8058566371116,0,17790,94383510,CLX5
2025-09-24 19:42:54.267138541+00:00,160,1,432669,M,B,64.81,2,26,8058566371116,128,17515,94383511,CLX5
2025-09-24 19:42:54.273859859+00:00,160,1,432669,T,A,64.81,6,26,8058566371461,0,17987,94383519,CLX5
2025-09-24 19:42:54.273859859+00:00,160,1,432669,F,B,64.81,2,26,8058566371116,0,17987,94383519,CLX5
2025-09-24 19:42:54.273859859+00:00,160,1,432669,F,B,64.81,2,26,8058566371324,0,17987,94383519,CLX5
2025-09-24 19:42:54.273859859+00:00,160,1,432669,F,B,64.81,1,26,8058566371442,0,17987,94383519,CLX5
2025-09-24 19:42:54.273859859+00:00,160,1,432669,F,B,64.81,1,26,8058566371445,0,17987,94383519,CLX5
2025-09-24 19:42:54.273859859+00:00,160,1,432669,C,B,64.81,2,26,8058566371116,0,14570,94383520,CLX5
2025-09-24 19:42:54.273859859+00:00,160,1,432669,C,B,64.81,2,26,8058566371324,0,14570,94383520,CLX5
2025-09-24 19:42:54.273859859+00:00,160,1,432669,C,B,64.81,1,26,8058566371442,0,14570,94383520,CLX5
2025-09-24 19:42:54.273859859+00:00,160,1,432669,C,B,64.81,1,26,8058566371445,128,14570,94383520,CLX5
2025-09-24 19:42:54.274202831+00:00,160,1,432669,A,A,64.82,1,26,8058566371468,128,15020,94383544,CLX5
2025-09-24 19:42:54.274203007+00:00,160,1,432669,A,A,64.82,2,26,8058566371469,128,18777,94383545,CLX5
2025-09-24 19:42:54.274206269+00:00,160,1,432669,A,A,64.82,1,26,8058566371471,128,15280,94383550,CLX5
2025-09-24 19:42:54.274227809+00:00,160,1,432669,A,A,64.82,1,26,8058566371475,128,15379,94383558,CLX5
2025-09-24 19:42:54.274253691+00:00,160,1,432669,A,A,64.82,3,26,8058566371476,128,15053,94383559,CLX5
2025-09-24 19:42:54.274270451+00:00,160,1,432669,T,A,64.81,2,26,8058566371477,128,15005,94383560,CLX5
2025-09-24 19:42:54.274276191+00:00,160,1,432669,M,A,64.83,1,26,8058566173085,128,16964,94383565,CLX5
2025-09-24 19:42:54.274339931+00:00,160,1,432669,A,A,64.82,2,26,8058566371478,128,14654,94383566,CLX5
2025-09-24 19:42:54.274760259+00:00,160,1,432669,C,A,64.82,2,26,8058566371469,128,15277,94383574,CLX5
2025-09-24 19:42:54.274825421+00:00,160,1,432669,C,B,64.78,1,26,8058566371248,128,17981,94383576,CLX5
2025-09-24 19:42:54.274833505+00:00,160,1,432669,C,B,64.8,1,26,8058566370676,128,14490,94383579,CLX5
2025-09-24 19:42:54.275154667+00:00,160,1,432669,C,A,64.82,1,26,8058566371471,128,15292,94383605,CLX5
2025-09-24 19:42:54.275159331+00:00,160,1,432669,C,A,64.82,1,26,8058566371475,128,15360,94383606,CLX5
2025-09-24 19:42:54.275186845+00:00,160,1,432669,A,B,64.8,2,26,8058566371490,128,14852,94383607,CLX5
2025-09-24 19:42:54.275515495+00:00,160,1,432669,C,B,64.8,2,26,8058566371490,128,14581,94383617,CLX5
2025-09-24 19:42:54.275686925+00:00,160,1,432669,A,A,64.82,1,26,8058566371502,128,13984,94383632,CLX5
2025-09-24 19:42:54.275719583+00:00,160,1,432669,C,B,64.79,2,26,8058566371218,128,14562,94383633,CLX5
2025-09-24 19:42:54.275726265+00:00,160,1,432669,T,A,64.81,1,26,8058566371504,128,14565,94383635,CLX5
2025-09-24 19:42:54.275891263+00:00,160,1,432669,M,A,64.83,3,26,8058566363632,128,18754,94383646,CLX5
2025-09-24 19:42:54.275935997+00:00,160,1,432669,M,B,63.65,3,26,8058566319508,128,17981,94383649,CLX5
2025-09-24 19:42:54.276124321+00:00,160,1,432669,M,A,64.93,1,26,8058565075241,128,14688,94383662,CLX5
2025-09-24 19:42:54.276252131+00:00,160,1,432669,C,A,64.82,1,26,8058566371502,128,18915,94383691,CLX5
2025-09-24 19:42:54.276865753+00:00,160,1,432669,A,A,64.82,1,26,8058566371529,128,18069,94383751,CLX5
2025-09-24 19:42:54.277422911+00:00,160,1,432669,A,B,64.81,1,26,8058566371537,128,18082,94383798,CLX5
2025-09-24 19:42:54.277426215+00:00,160,1,432669,A,B,64.81,1,26,8058566371538,128,15082,94383800,CLX5
2025-09-24 19:42:54.277606821+00:00,160,1,432669,C,A,64.83,3,26,8058566363632,128,14768,94383818,CLX5
2025-09-24 19:42:54.278058963+00:00,160,1,432669,C,A,64.82,1,26,8058566371529,128,15601,94383838,CLX5
2025-09-24 19:42:54.279042187+00:00,160,1,432669,A,B,64.8,2,26,8058566371555,128,17787,94383877,CLX5
2025-09-24 19:42:54.280617939+00:00,160,1,432669,C,A,64.82,1,26,8058566371468,128,15066,94383910,CLX5
2025-09-24 19:42:54.281172833+00:00,160,1,432669,A,B,64.81,2,26,8058566371569,128,14277,94383918,CLX5
2025-09-24 19:42:54.282387851+00:00,160,1,432669,T,A,64.81,1,26,8058566371061,0,14587,94383950,CLX5
2025-09-24 19:42:54.282387851+00:00,160,1,432669,F,A,64.81,1,26,8058566371061,0,14587,94383950,CLX5
2025-09-24 19:42:54.282387851+00:00,160,1,432669,F,B,64.81,1,26,8058566371537,0,14587,94383950,CLX5
2025-09-24 19:42:54.282387851+00:00,160,1,432669,C,B,64.81,1,26,8058566371537,0,14587,94383950,CLX5
2025-09-24 19:42:54.282387851+00:00,160,1,432669,C,A,64.82,1,26,8058566371061,128,14587,94383950,CLX5
2025-09-24 19:42:54.282488379+00:00,160,1,432669,A,B,64.78,1,26,8058566371575,128,18181,94383955,CLX5
2025-09-24 19:42:54.283015165+00:00,160,1,432669,A,B,64.81,1,26,8058566371585,128,20574,94383991,CLX5
2025-09-24 19:42:54.283039203+00:00,160,1,432669,C,A,64.82,2,26,8058566371478,128,16183,94383996,CLX5
2025-09-24 19:42:54.283151057+00:00,160,1,432669,M,A,64.94,1,26,8058565075241,128,14676,94384008,CLX5
2025-09-24 19:42:54.283154071+00:00,160,1,432669,A,B,64.81,2,26,8058566371593,128,14676,94384008,CLX5
2025-09-24 19:42:54.283429079+00:00,160,1,432669,A,B,64.81,1,26,8058566371603,128,18091,94384021,CLX5
2025-09-24 19:42:54.283432631+00:00,160,1,432669,A,B,64.81,1,26,8058566371604,128,14578,94384022,CLX5
2025-09-24 19:42:54.283831303+00:00,160,1,432669,A,B,64.81,2,26,8058566371614,128,15970,94384049,CLX5
2025-09-24 19:42:54.283831481+00:00,160,1,432669,A,B,64.81,1,26,8058566371615,128,18928,94384050,CLX5
2025-09-24 19:42:54.283962491+00:00,160,1,432669,A,B,64.81,1,26,8058566371616,128,14932,94384056,CLX5
2025-09-24 19:42:54.284231009+00:00,160,1,432669,A,B,64.81,2,26,8058566371620,128,14189,94384066,CLX5
2025-09-24 19:42:54.286074993+00:00,160,1,432669,M,B,64.8,4,26,8058566345944,128,14493,94384132,CLX5
2025-09-24 19:42:54.286150463+00:00,160,1,432669,A,A,64.82,1,26,8058566371639,128,18209,94384134,CLX5
2025-09-24 19:42:54.286317131+00:00,160,1,432669,C,A,64.82,1,26,8058566371639,128,18449,94384158,CLX5
2025-09-24 19:42:54.286528399+00:00,160,1,432669,A,A,64.82,1,26,8058566371652,128,18263,94384168,CLX5
2025-09-24 19:42:54.287535413+00:00,160,1,432669,C,B,64.81,1,26,8058566371616,128,14674,94384201,CLX5
2025-09-24 19:42:54.287831505+00:00,160,1,432669,C,A,64.82,1,26,8058566371652,128,14981,94384206,CLX5
2025-09-24 19:42:54.288294395+00:00,160,1,432669,A,A,64.82,1,26,8058566371662,128,16194,94384223,CLX5
2025-09-24 19:42:54.288382501+00:00,160,1,432669,A,A,64.82,1,26,8058566371664,128,18009,94384226,CLX5
2025-09-24 19:42:54.288545693+00:00,160,1,432669,C,A,64.82,1,26,8058566371662,128,18045,94384239,CLX5
2025-09-24 19:42:54.288546865+00:00,160,1,432669,C,A,64.82,1,26,8058566371423,128,15326,94384240,CLX5
2025-09-24 19:42:54.296294527+00:00,160,1,432669,C,A,64.82,1,26,8058566371448,128,18382,94384357,CLX5
2025-09-24 19:42:54.296446873+00:00,160,1,432669,A,B,64.8,1,26,8058566371714,128,18023,94384358,CLX5
2025-09-24 19:42:54.312944975+00:00,160,1,432669,A,B,64.79,2,26,8058566371722,128,18206,94384373,CLX5
2025-09-24 19:42:54.318728315+00:00,160,1,432669,A,A,65.7,6,26,8058566371724,128,14359,94384377,CLX5
2025-09-24 19:42:54.630232357+00:00,160,1,432669,T,A,64.81,1,26,8058566371827,0,17656,94384579,CLX5
2025-09-24 19:42:54.630232357+00:00,160,1,432669,F,B,64.81,1,26,8058566371538,0,17656,94384579,CLX5
2025-09-24 19:42:54.630232357+00:00,160,1,432669,C,B,64.81,1,26,8058566371538,128,16831,94384580,CLX5
2025-09-24 19:42:54.993325525+00:00,160,1,432669,T,A,64.81,1,26,8058566371850,0,18629,94384615,CLX5
2025-09-24 19:42:54.993325525+00:00,160,1,432669,F,B,64.81,1,26,8058566371569,0,18629,94384615,CLX5
2025-09-24 19:42:54.993325525+00:00,160,1,432669,M,B,64.81,1,26,8058566371569,128,16248,94384616,CLX5
2025-09-24 19:42:56.186539275+00:00,160,1,432669,C,A,64.82,1,26,8058566371447,128,18278,94384773,CLX5
2025-09-24 19:42:56.186553693+00:00,160,1,432669,C,A,64.82,1,26,8058566371446,128,15345,94384774,CLX5
2025-09-24 19:43:00.021333429+00:00,160,1,432669,A,B,64.71,1,26,8058566371963,128,21399,94384932,CLX5
2025-09-24 19:43:00.393332979+00:00,160,1,432669,C,B,64.81,2,26,8058566371593,128,15714,94384942,CLX5
2025-09-24 19:43:00.418470315+00:00,160,1,432669,C,A,65.7,6,26,8058566371724,128,18136,94384959,CLX5
2025-09-24 19:43:00.679941555+00:00,160,1,432669,C,A,64.82,2,26,8058566371421,128,20109,94384968,CLX5
2025-09-24 19:43:00.680100755+00:00,160,1,432669,A,B,64.81,2,26,8058566371980,128,16044,94384976,CLX5
2025-09-24 19:43:00.718439295+00:00,160,1,432669,A,A,65.7,6,26,8058566371985,128,18622,94385014,CLX5
2025-09-24 19:43:01.611976547+00:00,160,1,432669,C,B,64.78,1,26,8058566371213,128,18269,94385043,CLX5
2025-09-24 19:43:02.101549253+00:00,160,1,432669,A,A,64.82,1,26,8058566372003,128,15586,94385071,CLX5
2025-09-24 19:43:02.101709527+00:00,160,1,432669,C,B,64.81,2,26,8058566371980,128,16030,94385158,CLX5
2025-09-24 19:43:02.133094323+00:00,160,1,432669,C,B,64.81,2,26,8058566371614,128,18652,94385467,CLX5
2025-09-24 19:43:02.133094479+00:00,160,1,432669,C,B,64.81,1,26,8058566371615,128,16283,94385468,CLX5
2025-09-24 19:43:03.915289407+00:00,160,1,432669,C,A,65.09,1,26,8058566370025,128,19318,94385795,CLX5
2025-09-24 19:43:04.009125513+00:00,160,1,432669,A,A,65.08,1,26,8058566372242,128,19203,94385796,CLX5
2025-09-24 19:43:04.353303081+00:00,160,1,432669,A,A,65.08,1,26,8058566372244,128,18033,94385804,CLX5
2025-09-24 19:43:04.541141967+00:00,160,1,432669,C,A,65.07,1,26,8058566364722,128,19660,94385805,CLX5
2025-09-24 19:43:04.651295779+00:00,160,1,432669,A,A,65.06,1,26,8058566372245,128,17878,94385806,CLX5
2025-09-24 19:43:04.729453669+00:00,160,1,432669,C,A,65.06,1,26,8058566370024,128,17643,94385807,CLX5
2025-09-24 19:43:04.760818249+00:00,160,1,432669,A,A,65.05,1,26,8058566372246,128,18528,94385808,CLX5
2025-09-24 19:43:06.211208099+00:00,160,1,432669,A,A,64.82,1,26,8058566372283,128,15785,94386017,CLX5
2025-09-24 19:43:06.303279901+00:00,160,1,432669,C,B,64.81,2,26,8058566371620,128,20226,94386177,CLX5
2025-09-24 19:43:06.303445859+00:00,160,1,432669,C,B,64.81,1,26,8058566371585,128,18641,94386189,CLX5
2025-09-24 19:43:06.303450541+00:00,160,1,432669,A,A,64.82,1,26,8058566372332,128,17544,94386190,CLX5
2025-09-24 19:43:06.303577891+00:00,160,1,432669,C,B,64.81,1,26,8058566371569,128,15925,94386205,CLX5
2025-09-24 19:43:06.303739453+00:00,160,1,432669,A,A,64.82,2,26,8058566372336,128,15202,94386222,CLX5
2025-09-24 19:43:06.303794343+00:00,160,1,432669,A,A,64.82,2,26,8058566372341,128,16144,94386239,CLX5
2025-09-24 19:43:06.303830725+00:00,160,1,432669,T,A,64.81,1,26,8058566372342,0,13479,94386245,CLX5
2025-09-24 19:43:06.303830725+00:00,160,1,432669,F,B,64.81,1,26,8058566371603,0,13479,94386245,CLX5
2025-09-24 19:43:06.303830725+00:00,160,1,432669,C,B,64.81,1,26,8058566371603,128,13479,94386245,CLX5
2025-09-24 19:43:06.303854379+00:00,160,1,432669,T,A,64.81,1,26,8058566372343,0,14639,94386250,CLX5
2025-09-24 19:43:06.303854379+00:00,160,1,432669,F,B,64.81,1,26,8058566371604,0,14639,94386250,CLX5
2025-09-24 19:43:06.303854379+00:00,160,1,432669,C,B,64.81,1,26,8058566371604,128,14639,94386250,CLX5
2025-09-24 19:43:06.304056181+00:00,160,1,432669,T,A,64.81,1,26,8058566372344,128,14460,94386279,CLX5
2025-09-24 19:43:06.304092159+00:00,160,1,432669,A,A,64.82,2,26,8058566372345,128,15520,94386284,CLX5
2025-09-24 19:43:06.304175043+00:00,160,1,432669,T,A,64.81,2,26,8058566372351,128,15187,94386292,CLX5
2025-09-24 19:43:06.304448975+00:00,160,1,432669,T,A,64.81,1,26,8058566372355,0,14350,94386301,CLX5
2025-09-24 19:43:06.304448975+00:00,160,1,432669,A,A,64.81,1,26,8058566372355,128,17196,94386302,CLX5
2025-09-24 19:43:06.304454755+00:00,160,1,432669,A,A,64.81,1,26,8058566372360,128,14669,94386314,CLX5
2025-09-24 19:43:06.304464853+00:00,160,1,432669,A,A,64.81,1,26,8058566372362,128,14623,94386317,CLX5
2025-09-24 19:43:06.304557067+00:00,160,1,432669,A,A,64.81,1,26,8058566372364,128,14775,94386322,CLX5
2025-09-24 19:43:06.304678483+00:00,160,1,432669,A,A,64.81,1,26,8058566372366,128,22569,94386331,CLX5
2025-09-24 19:43:06.304823955+00:00,160,1,432669,C,B,64.8,2,26,8058566371555,128,13982,94386345,CLX5
2025-09-24 19:43:06.305230439+00:00,160,1,432669,A,A,64.81,1,26,8058566372384,128,14758,94386373,CLX5
2025-09-24 19:43:06.305463997+00:00,160,1,432669,C,A,64.81,1,26,8058566372360,128,14907,94386420,CLX5
2025-09-24 19:43:06.305472597+00:00,160,1,432669,A,A,64.82,1,26,8058566372394,128,17937,94386424,CLX5
2025-09-24 19:43:06.305499745+00:00,160,1,432669,C,A,64.81,1,26,8058566372364,128,18105,94386426,CLX5
2025-09-24 19:43:06.305616309+00:00,160,1,432669,A,A,64.81,1,26,8058566372398,128,17911,94386435,CLX5
2025-09-24 19:43:06.305853335+00:00,160,1,432669,M,A,64.81,2,26,8058566371054,128,20507,94386446,CLX5
2025-09-24 19:43:06.306002091+00:00,160,1,432669,M,A,64.81,2,26,8058566371432,128,19874,94386483,CLX5
2025-09-24 19:43:06.306041679+00:00,160,1,432669,C,B,64.78,1,26,8058566371575,128,14602,94386517,CLX5
2025-09-24 19:43:06.306098775+00:00,160,1,432669,M,A,64.83,3,26,8058566331102,128,14451,94386539,CLX5
2025-09-24 19:43:06.306168049+00:00,160,1,432669,C,B,64.8,2,26,8058566368553,128,14816,94386550,CLX5
2025-09-24 19:43:06.306168201+00:00,160,1,432669,C,B,64.8,1,26,8058566368554,128,15316,94386551,CLX5
2025-09-24 19:43:06.306168375+00:00,160,1,432669,A,A,64.81,2,26,8058566372433,128,19430,94386552,CLX5
2025-09-24 19:43:06.306168555+00:00,160,1,432669,A,A,64.81,1,26,8058566372434,128,15941,94386553,CLX5
2025-09-24 19:43:06.306197713+00:00,160,1,432669,C,B,64.8,1,26,8058566368548,128,14005,94386559,CLX5
2025-09-24 19:43:06.306212399+00:00,160,1,432669,C,B,64.8,2,26,8058566368549,128,18116,94386562,CLX5
2025-09-24 19:43:06.306223765+00:00,160,1,432669,C,B,64.8,1,26,8058566355166,128,14048,94386564,CLX5
2025-09-24 19:43:06.306223937+00:00,160,1,432669,A,A,64.81,2,26,8058566372438,128,15755,94386565,CLX5
2025-09-24 19:43:06.306442463+00:00,160,1,432669,A,A,64.81,2,26,8058566372442,128,15321,94386589,CLX5
2025-09-24 19:43:06.306468707+00:00,160,1,432669,A,A,64.81,1,26,8058566372446,128,18879,94386596,CLX5
2025-09-24 19:43:06.307374409+00:00,160,1,432669,A,A,64.81,1,26,8058566372466,128,15870,94386686,CLX5
2025-09-24 19:43:06.307624401+00:00,160,1,432669,M,B,63.64,3,26,8058566345944,128,14732,94386713,CLX5
2025-09-24 19:43:06.308113843+00:00,160,1,432669,A,A,64.81,1,26,8058566372488,128,14145,94386746,CLX5
2025-09-24 19:43:06.308277957+00:00,160,1,432669,A,A,64.81,1,26,8058566372490,128,14983,94386755,CLX5
2025-09-24 19:43:06.308309119+00:00,160,1,432669,C,B,64.8,1,26,8058566371714,128,14439,94386761,CLX5
2025-09-24 19:43:06.308324285+00:00,160,1,432669,A,A,64.81,2,26,8058566372493,128,14941,94386762,CLX5
2025-09-24 19:43:06.308646313+00:00,160,1,432669,A,A,64.82,1,26,8058566372502,128,15015,94386805,CLX5
2025-09-24 19:43:06.309466503+00:00,160,1,432669,C,B,64.79,2,26,8058566371722,128,14320,94386847,CLX5
2025-09-24 19:43:06.309489503+00:00,160,1,432669,A,A,64.84,2,26,8058566372513,128,14823,94386849,CLX5
2025-09-24 19:43:06.309509047+00:00,160,1,432669,M,A,64.93,1,26,8058565075241,128,19483,94386854,CLX5
2025-09-24 19:43:06.309790295+00:00,160,1,432669,A,A,64.81,2,26,8058566372536,128,15483,94386910,CLX5
2025-09-24 19:43:06.311151093+00:00,160,1,432669,C,A,64.81,1,26,8058566372490,128,15186,94387097,CLX5
2025-09-24 19:43:06.311175301+00:00,160,1,432669,C,A,64.81,2,26,8058566372493,128,15092,94387103,CLX5
2025-09-24 19:43:06.311961777+00:00,160,1,432669,M,A,64.82,3,26,8058566354590,128,14907,94387144,CLX5
2025-09-24 19:43:06.312841713+00:00,160,1,432669,A,A,64.81,2,26,8058566372582,128,14938,94387213,CLX5
2025-09-24 19:43:06.312916627+00:00,160,1,432669,C,B,64.8,3,26,8058566340905,128,17570,94387219,CLX5
2025-09-24 19:43:06.312978737+00:00,160,1,432669,C,A,64.86,2,26,8058566365758,128,14560,94387222,CLX5
2025-09-24 19:43:06.315057409+00:00,160,1,432669,A,B,64.79,1,26,8058566372615,128,15290,94387337,CLX5
2025-09-24 19:43:06.315624419+00:00,160,1,432669,M,A,64.81,1,26,8058566371664,128,16158,94387352,CLX5
2025-09-24 19:43:06.317401607+00:00,160,1,432669,A,A,64.92,2,26,8058566372672,128,16445,94387509,CLX5
2025-09-24 19:43:06.317405543+00:00,160,1,432669,C,B,64.8,1,26,8058566340604,128,16445,94387509,CLX5
2025-09-24 19:43:06.318744915+00:00,160,1,432669,C,A,65.48,2,26,8058566302430,128,15035,94387549,CLX5
2025-09-24 19:43:06.318748869+00:00,160,1,432669,C,A,65.7,6,26,8058566371985,128,15035,94387549,CLX5
2025-09-24 19:43:06.319459277+00:00,160,1,432669,A,B,63.66,3,26,8058566372703,128,14503,94387601,CLX5
2025-09-24 19:43:06.319977461+00:00,160,1,432669,C,A,64.82,1,26,8058566372502,128,14518,94387645,CLX5
2025-09-24 19:43:06.319986851+00:00,160,1,432669,C,A,64.82,1,26,8058566372394,128,18094,94387646,CLX5
2025-09-24 19:43:06.320497355+00:00,160,1,432669,C,B,64.8,1,26,8058566340266,128,14848,94387676,CLX5
2025-09-24 19:43:06.320500139+00:00,160,1,432669,C,B,64.8,1,26,8058566340410,128,18148,94387677,CLX5
2025-09-24 19:43:06.321340603+00:00,160,1,432669,C,A,64.81,2,26,8058566372442,128,18970,94387716,CLX5
2025-09-24 19:43:06.321982199+00:00,160,1,432669,A,A,64.84,1,26,8058566372739,128,14748,94387738,CLX5
2025-09-24 19:43:06.322090885+00:00,160,1,432669,A,A,64.81,3,26,8058566372746,128,15736,94387757,CLX5
2025-09-24 19:43:06.322117129+00:00,160,1,432669,T,A,64.8,1,26,8058566372747,0,14525,94387759,CLX5
2025-09-24 19:43:06.322117129+00:00,160,1,432669,F,B,64.8,1,26,8058566250102,0,14525,94387759,CLX5
2025-09-24 19:43:06.322117129+00:00,160,1,432669,M,B,64.8,1,26,8058566250102,128,14525,94387759,CLX5
2025-09-24 19:43:06.322200031+00:00,160,1,432669,C,B,64.77,1,26,8058566371203,128,14720,94387763,CLX5
2025-09-24 19:43:06.323493191+00:00,160,1,432669,A,B,64.8,2,26,8058566372753,128,14916,94387792,CLX5
2025-09-24 19:43:06.325146987+00:00,160,1,432669,A,B,64.77,1,26,8058566372772,128,17762,94387896,CLX5
2025-09-24 19:43:06.325991691+00:00,160,1,432669,C,B,64.54,8,26,8058566358150,128,14462,94387931,CLX5
2025-09-24 19:43:06.335129627+00:00,160,1,432669,C,B,64.78,2,26,8058566371219,128,14940,94388289,CLX5
2025-09-24 19:43:06.335131115+00:00,160,1,432669,C,B,64.77,1,26,8058566372772,128,18170,94388299,CLX5
2025-09-24 19:43:06.335131267+00:00,160,1,432669,C,B,64.76,1,26,8058566369432,128,14859,94388300,CLX5
2025-09-24 19:43:06.335172707+00:00,160,1,432669,C,B,64.8,1,26,8058566250102,128,15103,94388351,CLX5
2025-09-24 19:43:06.335189813+00:00,160,1,432669,T,A,64.8,16,26,8058566372898,0,18317,94388355,CLX5
2025-09-24 19:43:06.335189813+00:00,160,1,432669,F,B,64.8,1,26,8058566253602,0,18317,94388355,CLX5
2025-09-24 19:43:06.335189813+00:00,160,1,432669,F,B,64.8,3,26,8058566253809,0,18317,94388355,CLX5
2025-09-24 19:43:06.335189813+00:00,160,1,432669,F,B,64.8,1,26,8058565996850,0,18317,94388355,CLX5
2025-09-24 19:43:06.335189813+00:00,160,1,432669,F,B,64.8,1,26,8058566304485,0,18317,94388355,CLX5
2025-09-24 19:43:06.335189813+00:00,160,1,432669,F,B,64.8,1,26,8058566328479,0,18317,94388355,CLX5
2025-09-24 19:43:06.335189813+00:00,160,1,432669,F,B,64.8,1,26,8058566354454,0,18317,94388355,CLX5
2025-09-24 19:43:06.335189813+00:00,160,1,432669,F,B,64.8,5,26,8058566363486,0,18317,94388355,CLX5
2025-09-24 19:43:06.335189813+00:00,160,1,432669,F,B,64.8,1,26,8058566371452,0,18317,94388355,CLX5
2025-09-24 19:43:06.335189813+00:00,160,1,432669,F,B,64.8,1,26,8058566372753,0,18317,94388355,CLX5
2025-09-24 19:43:06.335189813+00:00,160,1,432669,F,B,64.8,1,26,8058566342783,0,18317,94388355,CLX5
2025-09-24 19:43:06.335189813+00:00,160,1,432669,C,B,64.8,1,26,8058566253602,0,18713,94388356,CLX5
2025-09-24 19:43:06.335189813+00:00,160,1,432669,C,B,64.8,3,26,8058566253809,0,18713,94388356,CLX5
2025-09-24 19:43:06.335189813+00:00,160,1,432669,C,B,64.8,1,26,8058565996850,0,18713,94388356,CLX5
2025-09-24 19:43:06.335189813+00:00,160,1,432669,C,B,64.8,1,26,8058566304485,0,18713,94388356,CLX5
2025-09-24 19:43:06.335189813+00:00,160,1,432669,C,B,64.8,1,26,8058566328479,0,18713,94388356,CLX5
2025-09-24 19:43:06.335189813+00:00,160,1,432669,C,B,64.8,1,26,8058566354454,0,18713,94388356,CLX5
2025-09-24 19:43:06.335189813+00:00,160,1,432669,C,B,64.8,5,26,8058566363486,0,18713,94388356,CLX5
2025-09-24 19:43:06.335189813+00:00,160,1,432669,C,B,64.8,1,26,8058566371452,0,18713,94388356,CLX5
2025-09-24 19:43:06.335189813+00:00,160,1,432669,C,B,64.8,1,26,8058566342783,0,18713,94388356,CLX5
2025-09-24 19:43:06.335189813+00:00,160,1,432669,M,B,64.8,1,26,8058566372753,128,18713,94388356,CLX5
2025-09-24 19:43:06.335194133+00:00,160,1,432669,T,A,64.8,2,26,8058566372899,0,16251,94388361,CLX5
2025-09-24 19:43:06.335194133+00:00,160,1,432669,F,B,64.8,1,26,8058566372753,0,16251,94388361,CLX5
2025-09-24 19:43:06.335194133+00:00,160,1,432669,C,B,64.8,1,26,8058566372753,128,16251,94388361,CLX5
2025-09-24 19:43:06.335302265+00:00,160,1,432669,A,A,64.8,1,26,8058566372917,128,18775,94388397,CLX5
2025-09-24 19:43:06.335372533+00:00,160,1,432669,A,A,64.8,1,26,8058566372921,128,14315,94388411,CLX5
2025-09-24 19:43:06.335458813+00:00,160,1,432669,A,B,64.79,1,26,8058566372923,128,14079,94388417,CLX5
2025-09-24 19:43:06.335630167+00:00,160,1,432669,C,A,64.8,1,26,8058566372921,128,18581,94388431,CLX5
2025-09-24 19:43:06.335771511+00:00,160,1,432669,T,N,64.8,1,26,0,0,14991,94388439,CLX5
2025-09-24 19:43:06.335771511+00:00,160,1,432669,F,N,64.8,1,26,8058566372917,0,14991,94388439,CLX5
2025-09-24 19:43:06.335771511+00:00,160,1,432669,C,A,64.8,1,26,8058566372917,128,19219,94388440,CLX5
2025-09-24 19:43:06.336525595+00:00,160,1,432669,A,B,64.79,1,26,8058566372953,128,18453,94388504,CLX5
2025-09-24 19:43:06.339176249+00:00,160,1,432669,A,B,64.78,1,26,8058566372991,128,14702,94388655,CLX5
2025-09-24 19:43:06.340500647+00:00,160,1,432669,A,A,64.8,1,26,8058566373015,128,14492,94388746,CLX5
2025-09-24 19:43:06.340503525+00:00,160,1,432669,A,A,64.81,1,26,8058566373017,128,13593,94388750,CLX5
2025-09-24 19:43:06.340613479+00:00,160,1,432669,A,B,64.79,1,26,8058566373022,128,14863,94388755,CLX5
2025-09-24 19:43:06.340616417+00:00,160,1,432669,C,B,64.55,1,26,8058566302298,128,14516,94388756,CLX5
2025-09-24 19:43:06.340681327+00:00,160,1,432669,A,B,64.79,2,26,8058566373027,128,14489,94388768,CLX5
2025-09-24 19:43:06.340688355+00:00,160,1,432669,A,B,64.79,2,26,8058566373028,128,17118,94388769,CLX5
2025-09-24 19:43:06.340688533+00:00,160,1,432669,A,B,64.79,1,26,8058566373029,128,14750,94388770,CLX5
2025-09-24 19:43:06.340704503+00:00,160,1,432669,M,A,64.8,2,26,8058566372582,128,17993,94388772,CLX5
2025-09-24 19:43:06.340728251+00:00,160,1,432669,T,B,64.8,2,26,8058566373030,0,14628,94388775,CLX5
2025-09-24 19:43:06.340728251+00:00,160,1,432669,F,A,64.8,1,26,8058566373015,0,14628,94388775,CLX5
2025-09-24 19:43:06.340728251+00:00,160,1,432669,F,A,64.8,1,26,8058566372582,0,14628,94388775,CLX5
2025-09-24 19:43:06.340728251+00:00,160,1,432669,C,A,64.8,1,26,8058566373015,0,14847,94388776,CLX5
2025-09-24 19:43:06.340728251+00:00,160,1,432669,M,A,64.8,1,26,8058566372582,128,14847,94388776,CLX5
2025-09-24 19:43:06.340744397+00:00,160,1,432669,T,B,64.8,1,26,8058566373031,0,14118,94388779,CLX5
2025-09-24 19:43:06.340744397+00:00,160,1,432669,F,A,64.8,1,26,8058566372582,0,14118,94388779,CLX5
2025-09-24 19:43:06.340744397+00:00,160,1,432669,A,B,64.8,2,26,8058566373031,0,14670,94388780,CLX5
2025-09-24 19:43:06.340744397+00:00,160,1,432669,C,A,64.8,1,26,8058566372582,128,14670,94388780,CLX5
2025-09-24 19:43:06.340788037+00:00,160,1,432669,C,B,64.79,3,26,8058566201605,128,14832,94388785,CLX5
2025-09-24 19:43:06.341155317+00:00,160,1,432669,C,A,66.16,4,26,8058566230492,128,14620,94388807,CLX5
2025-09-24 19:43:06.341155529+00:00,160,1,432669,C,A,64.81,1,26,8058566373017,128,14620,94388807,CLX5
2025-09-24 19:43:06.341330451+00:00,160,1,432669,T,A,64.8,2,26,8058566371054,0,14040,94388822,CLX5
2025-09-24 19:43:06.341330451+00:00,160,1,432669,F,A,64.8,2,26,8058566371054,0,14040,94388822,CLX5
2025-09-24 19:43:06.341330451+00:00,160,1,432669,F,B,64.8,2,26,8058566373031,0,14040,94388822,CLX5
2025-09-24 19:43:06.341330451+00:00,160,1,432669,C,B,64.8,2,26,8058566373031,0,14040,94388822,CLX5
2025-09-24 19:43:06.341330451+00:00,160,1,432669,C,A,64.81,2,26,8058566371054,128,14040,94388822,CLX5
2025-09-24 19:43:06.341332507+00:00,160,1,432669,A,A,64.8,3,26,8058566373039,128,14592,94388825,CLX5
2025-09-24 19:43:06.341482797+00:00,160,1,432669,M,A,64.8,2,26,8058566368599,128,14913,94388845,CLX5
2025-09-24 19:43:06.341518745+00:00,160,1,432669,T,B,64.8,5,26,8058566373048,0,15008,94388849,CLX5
2025-09-24 19:43:06.341518745+00:00,160,1,432669,F,A,64.8,3,26,8058566373039,0,15008,94388849,CLX5
2025-09-24 19:43:06.341518745+00:00,160,1,432669,F,A,64.8,2,26,8058566368599,0,15008,94388849,CLX5
2025-09-24 19:43:06.341518745+00:00,160,1,432669,C,A,64.8,3,26,8058566373039,0,18535,94388850,CLX5
2025-09-24 19:43:06.341518745+00:00,160,1,432669,C,A,64.8,2,26,8058566368599,128,18535,94388850,CLX5
2025-09-24 19:43:06.341552835+00:00,160,1,432669,M,A,64.82,1,26,8058566338645,128,14858,94388856,CLX5
2025-09-24 19:43:06.341692931+00:00,160,1,432669,C,A,64.81,1,26,8058566372446,128,15282,94388862,CLX5
2025-09-24 19:43:06.341901301+00:00,160,1,432669,A,A,64.83,1,26,8058566373058,128,14459,94388865,CLX5
2025-09-24 19:43:06.341904105+00:00,160,1,432669,C,A,64.89,1,26,8058566302714,128,14598,94388866,CLX5
2025-09-24 19:43:06.341952177+00:00,160,1,432669,A,B,64.8,2,26,8058566373060,128,16749,94388871,CLX5
2025-09-24 19:43:06.342469921+00:00,160,1,432669,M,A,65.96,3,26,8058566354590,128,14573,94388900,CLX5
2025-09-24 19:43:06.342491463+00:00,160,1,432669,C,A,64.82,1,26,8058566338645,128,19090,94388901,CLX5
2025-09-24 19:43:06.342638279+00:00,160,1,432669,C,B,64.8,2,26,8058566373060,128,15284,94388902,CLX5
2025-09-24 19:43:06.343522419+00:00,160,1,432669,A,B,64.8,2,26,8058566373087,128,17670,94388972,CLX5
2025-09-24 19:43:06.343524435+00:00,160,1,432669,A,B,64.8,2,26,8058566373088,128,14910,94388974,CLX5
2025-09-24 19:43:06.343648999+00:00,160,1,432669,A,B,64.8,2,26,8058566373095,128,16897,94388992,CLX5
2025-09-24 19:43:06.344044835+00:00,160,1,432669,A,B,64.8,1,26,8058566373104,128,16670,94389024,CLX5
2025-09-24 19:43:06.344046293+00:00,160,1,432669,A,B,64.8,2,26,8058566373111,128,16125,94389032,CLX5
2025-09-24 19:43:06.344057481+00:00,160,1,432669,C,A,64.81,2,26,8058566372536,128,14774,94389037,CLX5
2025-09-24 19:43:06.344068405+00:00,160,1,432669,A,B,64.79,1,26,8058566373114,128,14390,94389039,CLX5
2025-09-24 19:43:06.344133911+00:00,160,1,432669,A,B,64.8,3,26,8058566373116,128,13891,94389041,CLX5
2025-09-24 19:43:06.344786261+00:00,160,1,432669,A,B,64.79,1,26,8058566373123,128,14686,94389062,CLX5
2025-09-24 19:43:06.344900515+00:00,160,1,432669,A,B,64.8,1,26,8058566373125,128,15807,94389067,CLX5
2025-09-24 19:43:06.344924629+00:00,160,1,432669,A,B,64.8,1,26,8058566373126,128,19441,94389068,CLX5
2025-09-24 19:43:06.344955077+00:00,160,1,432669,C,B,64.79,1,26,8058566373114,128,14495,94389071,CLX5
2025-09-24 19:43:06.345134727+00:00,160,1,432669,A,B,64.8,1,26,8058566373133,128,14271,94389084,CLX5
2025-09-24 19:43:06.345135589+00:00,160,1,432669,C,A,64.84,2,26,8058566372513,128,18253,94389085,CLX5
2025-09-24 19:43:06.345146091+00:00,160,1,432669,A,B,64.8,1,26,8058566373139,128,15591,94389097,CLX5
2025-09-24 19:43:06.345200503+00:00,160,1,432669,A,B,64.79,1,26,8058566373141,128,14783,94389102,CLX5
2025-09-24 19:43:06.345278835+00:00,160,1,432669,C,A,64.81,1,26,8058566372488,128,15846,94389108,CLX5
2025-09-24 19:43:06.345641123+00:00,160,1,432669,A,B,64.78,1,26,8058566373151,128,14230,94389126,CLX5
2025-09-24 19:43:06.345666639+00:00,160,1,432669,C,B,64.79,1,26,8058566373141,128,14687,94389128,CLX5
2025-09-24 19:43:06.345968335+00:00,160,1,432669,M,A,64.82,1,26,8058566173085,128,14889,94389166,CLX5
2025-09-24 19:43:06.346310327+00:00,160,1,432669,A,B,64.79,1,26,8058566373161,128,14790,94389177,CLX5
2025-09-24 19:43:06.346441247+00:00,160,1,432669,A,B,64.79,1,26,8058566373162,128,15104,94389180,CLX5
2025-09-24 19:43:06.346799925+00:00,160,1,432669,A,B,64.77,1,26,8058566373167,128,15057,94389186,CLX5
2025-09-24 19:43:06.346802997+00:00,160,1,432669,A,B,64.8,1,26,8058566373169,128,14166,94389189,CLX5
2025-09-24 19:43:06.346823233+00:00,160,1,432669,A,A,64.81,2,26,8058566373174,128,17858,94389191,CLX5
2025-09-24 19:43:06.347026475+00:00,160,1,432669,C,A,64.83,3,26,8058566331102,128,14721,94389194,CLX5
2025-09-24 19:43:06.347261703+00:00,160,1,432669,A,B,64.8,1,26,8058566373180,128,13978,94389202,CLX5
2025-09-24 19:43:06.347407349+00:00,160,1,432669,C,B,64.79,1,26,8058566373161,128,14771,94389209,CLX5
2025-09-24 19:43:06.347567891+00:00,160,1,432669,A,A,64.81,1,26,8058566373191,128,14796,94389216,CLX5
2025-09-24 19:43:06.347571503+00:00,160,1,432669,A,B,64.8,1,26,8058566373193,128,17678,94389217,CLX5
2025-09-24 19:43:06.347583807+00:00,160,1,432669,A,B,64.8,1,26,8058566373197,128,19917,94389222,CLX5
2025-09-24 19:43:06.347743085+00:00,160,1,432669,A,B,64.8,2,26,8058566373205,128,14797,94389235,CLX5
2025-09-24 19:43:06.347746329+00:00,160,1,432669,T,A,64.8,2,26,8058566364431,0,14965,94389236,CLX5
2025-09-24 19:43:06.347746329+00:00,160,1,432669,F,A,64.8,2,26,8058566364431,0,14965,94389236,CLX5
2025-09-24 19:43:06.347746329+00:00,160,1,432669,F,B,64.8,2,26,8058566373087,0,14965,94389236,CLX5
2025-09-24 19:43:06.347746329+00:00,160,1,432669,C,B,64.8,2,26,8058566373087,0,16063,94389237,CLX5
2025-09-24 19:43:06.347746329+00:00,160,1,432669,C,A,64.84,2,26,8058566364431,128,16063,94389237,CLX5
2025-09-24 19:43:06.347769407+00:00,160,1,432669,A,B,64.8,1,26,8058566373207,128,15199,94389239,CLX5
2025-09-24 19:43:06.347842921+00:00,160,1,432669,A,A,64.84,2,26,8058566373208,128,17804,94389242,CLX5
2025-09-24 19:43:06.348116015+00:00,160,1,432669,C,B,64.8,3,26,8058566373116,128,15094,94389273,CLX5
2025-09-24 19:43:06.348116335+00:00,160,1,432669,C,B,64.8,2,26,8058566373095,128,15199,94389274,CLX5
2025-09-24 19:43:06.348116489+00:00,160,1,432669,C,B,64.8,1,26,8058566373180,128,18816,94389275,CLX5
2025-09-24 19:43:06.348142541+00:00,160,1,432669,M,B,64.79,2,26,8058566319508,128,13842,94389277,CLX5
2025-09-24 19:43:06.348155385+00:00,160,1,432669,C,A,64.81,1,26,8058566373191,128,14835,94389278,CLX5
2025-09-24 19:43:06.348196051+00:00,160,1,432669,C,B,64.8,1,26,8058566373197,128,14355,94389280,CLX5
2025-09-24 19:43:06.349395747+00:00,160,1,432669,C,B,64.8,1,26,8058566373207,128,18607,94389352,CLX5
2025-09-24 19:43:06.349423701+00:00,160,1,432669,A,A,64.81,1,26,8058566373248,128,14988,94389354,CLX5
2025-09-24 19:43:06.349545961+00:00,160,1,432669,A,A,64.85,1,26,8058566373250,128,14771,94389356,CLX5
2025-09-24 19:43:06.349553083+00:00,160,1,432669,A,B,64.8,1,26,8058566373251,128,15486,94389358,CLX5
2025-09-24 19:43:06.349584899+00:00,160,1,432669,C,A,64.81,1,26,8058566373248,128,18631,94389362,CLX5
2025-09-24 19:43:06.349905023+00:00,160,1,432669,A,A,64.81,1,26,8058566373255,128,14901,94389372,CLX5
2025-09-24 19:43:06.349967921+00:00,160,1,432669,A,A,64.81,2,26,8058566373257,128,17997,94389374,CLX5
2025-09-24 19:43:06.350033179+00:00,160,1,432669,C,A,64.81,1,26,8058566373255,128,14831,94389377,CLX5
2025-09-24 19:43:06.350156649+00:00,160,1,432669,A,A,64.81,1,26,8058566373258,128,18386,94389379,CLX5
2025-09-24 19:43:06.350262531+00:00,160,1,432669,M,B,63.63,4,26,8058566319508,128,17957,94389384,CLX5
2025-09-24 19:43:06.350582619+00:00,160,1,432669,A,B,64.79,1,26,8058566373260,128,14667,94389386,CLX5
2025-09-24 19:43:06.351678547+00:00,160,1,432669,C,B,64.8,1,26,8058566373139,128,15883,94389422,CLX5
2025-09-24 19:43:06.351856139+00:00,160,1,432669,C,B,64.8,1,26,8058566373251,128,14673,94389425,CLX5
2025-09-24 19:43:06.351894497+00:00,160,1,432669,M,B,64.79,2,26,8058566370556,128,14730,94389428,CLX5
2025-09-24 19:43:06.352298697+00:00,160,1,432669,C,B,64.8,1,26,8058566373169,128,15741,94389433,CLX5
2025-09-24 19:43:06.352524133+00:00,160,1,432669,C,B,64.8,2,26,8058566373205,128,15658,94389437,CLX5
2025-09-24 19:43:06.352784993+00:00,160,1,432669,M,B,64.79,1,26,8058566365565,128,14963,94389447,CLX5
2025-09-24 19:43:06.353182761+00:00,160,1,432669,C,A,64.81,1,26,8058566373258,128,18155,94389465,CLX5
2025-09-24 19:43:06.353348105+00:00,160,1,432669,A,A,64.81,1,26,8058566373283,128,14322,94389467,CLX5
2025-09-24 19:43:06.353572637+00:00,160,1,432669,C,A,64.81,1,26,8058566373283,128,15015,94389476,CLX5
2025-09-24 19:43:06.354991723+00:00,160,1,432669,C,A,64.81,2,26,8058566373174,128,14204,94389516,CLX5
2025-09-24 19:43:06.356097557+00:00,160,1,432669,M,A,64.83,3,26,8058566275289,128,15378,94389548,CLX5
2025-09-24 19:43:06.356254221+00:00,160,1,432669,C,B,64.79,1,26,8058566373260,128,14821,94389550,CLX5
2025-09-24 19:43:06.356263035+00:00,160,1,432669,C,B,64.79,1,26,8058566373162,128,13763,94389551,CLX5
2025-09-24 19:43:06.356754743+00:00,160,1,432669,C,B,64.8,1,26,8058566373193,128,15848,94389560,CLX5
2025-09-24 19:43:06.359537277+00:00,160,1,432669,A,B,64.8,1,26,8058566373330,128,14804,94389601,CLX5
2025-09-24 19:43:06.359592915+00:00,160,1,432669,A,B,64.8,1,26,8058566373331,128,15804,94389603,CLX5
2025-09-24 19:43:06.360554889+00:00,160,1,432669,C,B,64.8,1,26,8058566373330,128,19768,94389613,CLX5
2025-09-24 19:43:06.360686173+00:00,160,1,432669,A,B,64.8,1,26,8058566373338,128,14421,94389618,CLX5
2025-09-24 19:43:06.360832165+00:00,160,1,432669,C,B,64.8,1,26,8058566373331,128,15356,94389625,CLX5
2025-09-24 19:43:06.361018049+00:00,160,1,432669,A,A,65.95,3,26,8058566373342,128,13967,94389633,CLX5
2025-09-24 19:43:06.361722333+00:00,160,1,432669,A,B,63.68,4,26,8058566373348,128,14557,94389653,CLX5
2025-09-24 19:43:06.362152951+00:00,160,1,432669,C,B,64.8,1,26,8058566373338,128,15906,94389664,CLX5
2025-09-24 19:43:06.362360723+00:00,160,1,432669,A,B,64.8,1,26,8058566373355,128,16381,94389675,CLX5
2025-09-24 19:43:06.362511667+00:00,160,1,432669,C,B,64.8,1,26,8058566373355,128,14514,94389677,CLX5
2025-09-24 19:43:06.364199445+00:00,160,1,432669,A,A,64.81,2,26,8058566373371,128,18011,94389742,CLX5
2025-09-24 19:43:06.365113017+00:00,160,1,432669,A,A,64.81,1,26,8058566373380,128,19407,94389758,CLX5
2025-09-24 19:43:06.374272837+00:00,160,1,432669,A,A,64.84,2,26,8058566373402,128,17725,94389821,CLX5
2025-09-24 19:43:06.380474337+00:00,160,1,432669,A,A,65.94,4,26,8058566373408,128,17693,94389845,CLX5
2025-09-24 19:43:06.381308885+00:00,160,1,432669,A,B,63.67,4,26,8058566373409,128,17906,94389846,CLX5
2025-09-24 19:43:06.384822197+00:00,160,1,432669,A,B,64.8,1,26,8058566373417,128,19329,94389861,CLX5
2025-09-24 19:43:06.395929733+00:00,160,1,432669,A,B,64.78,2,26,8058566373431,128,18549,94389923,CLX5
2025-09-24 19:43:06.395932037+00:00,160,1,432669,A,B,64.77,2,26,8058566373432,128,14568,94389924,CLX5
2025-09-24 19:43:06.415572385+00:00,160,1,432669,A,A,64.81,1,26,8058566373469,128,19261,94389993,CLX5
2025-09-24 19:43:06.415737919+00:00,160,1,432669,A,A,64.81,1,26,8058566373470,128,18459,94389994,CLX5
2025-09-24 19:43:06.415889343+00:00,160,1,432669,A,A,64.81,1,26,8058566373472,128,13886,94389998,CLX5
2025-09-24 19:43:06.416715081+00:00,160,1,432669,C,B,64.8,2,26,8058566373111,128,15778,94390029,CLX5
2025-09-24 19:43:06.416739809+00:00,160,1,432669,T,A,64.8,1,26,8058566373483,0,14534,94390032,CLX5
2025-09-24 19:43:06.416739809+00:00,160,1,432669,F,B,64.8,1,26,8058566373088,0,14534,94390032,CLX5
2025-09-24 19:43:06.416739809+00:00,160,1,432669,M,B,64.8,1,26,8058566373088,128,15786,94390033,CLX5
2025-09-24 19:43:06.417156315+00:00,160,1,432669,A,A,64.81,2,26,8058566373494,128,14130,94390061,CLX5
2025-09-24 19:43:06.417414413+00:00,160,1,432669,C,B,64.8,1,26,8058566373104,128,19938,94390077,CLX5
2025-09-24 19:43:06.417423817+00:00,160,1,432669,T,A,64.8,1,26,8058566373499,0,14409,94390080,CLX5
2025-09-24 19:43:06.417423817+00:00,160,1,432669,F,B,64.8,1,26,8058566373088,0,14409,94390080,CLX5
2025-09-24 19:43:06.417423817+00:00,160,1,432669,C,B,64.8,1,26,8058566373088,128,22203,94390081,CLX5
2025-09-24 19:43:06.417475809+00:00,160,1,432669,T,A,64.8,1,26,8058566373500,0,14665,94390083,CLX5
2025-09-24 19:43:06.417475809+00:00,160,1,432669,F,B,64.8,1,26,8058566373125,0,14665,94390083,CLX5
2025-09-24 19:43:06.417475809+00:00,160,1,432669,C,B,64.8,1,26,8058566373125,128,14665,94390083,CLX5
2025-09-24 19:43:06.418689271+00:00,160,1,432669,T,A,64.8,1,26,8058566373506,0,14616,94390114,CLX5
2025-09-24 19:43:06.418689271+00:00,160,1,432669,F,B,64.8,1,26,8058566373126,0,14616,94390114,CLX5
2025-09-24 19:43:06.418689271+00:00,160,1,432669,C,B,64.8,1,26,8058566373126,128,17791,94390115,CLX5
2025-09-24 19:43:06.418911311+00:00,160,1,432669,T,A,64.8,1,26,8058566373508,0,14239,94390124,CLX5
2025-09-24 19:43:06.418911311+00:00,160,1,432669,F,B,64.8,1,26,8058566373133,0,14239,94390124,CLX5
2025-09-24 19:43:06.418911311+00:00,160,1,432669,C,B,64.8,1,26,8058566373133,128,18531,94390125,CLX5
2025-09-24 19:43:06.432305137+00:00,160,1,432669,C,B,64.79,1,26,8058566373123,128,19093,94390234,CLX5
2025-09-24 19:43:06.435620505+00:00,160,1,432669,T,A,64.8,1,26,8058566373565,0,18049,94390241,CLX5
2025-09-24 19:43:06.435620505+00:00,160,1,432669,F,B,64.8,1,26,8058566373417,0,18049,94390241,CLX5
2025-09-24 19:43:06.435620505+00:00,160,1,432669,C,B,64.8,1,26,8058566373417,128,14755,94390242,CLX5
2025-09-24 19:43:06.436056017+00:00,160,1,432669,C,A,64.82,1,26,8058566372283,128,18228,94390248,CLX5
2025-09-24 19:43:06.436178969+00:00,160,1,432669,M,B,63.62,4,26,8058566370556,128,18820,94390249,CLX5
2025-09-24 19:43:06.436198705+00:00,160,1,432669,M,B,63.61,4,26,8058566365565,128,18978,94390252,CLX5
2025-09-24 19:43:06.436358595+00:00,160,1,432669,A,A,64.81,1,26,8058566373570,128,15002,94390258,CLX5
2025-09-24 19:43:06.438083333+00:00,160,1,432669,A,B,63.65,4,26,8058566373581,128,17729,94390283,CLX5
2025-09-24 19:43:06.460929615+00:00,160,1,432669,A,A,64.8,1,26,8058566373621,128,17878,94390352,CLX5
2025-09-24 19:43:06.461149541+00:00,160,1,432669,A,A,64.8,1,26,8058566373622,128,18276,94390355,CLX5
2025-09-24 19:43:06.461270361+00:00,160,1,432669,M,A,64.8,1,26,8058566373250,128,14550,94390367,CLX5
2025-09-24 19:43:06.461388915+00:00,160,1,432669,M,A,64.82,4,26,8058566354590,128,14698,94390371,CLX5
2025-09-24 19:43:06.472243273+00:00,160,1,432669,C,B,64.78,1,26,8058566373151,128,17907,94390426,CLX5
2025-09-24 19:43:06.472472491+00:00,160,1,432669,A,B,64.78,1,26,8058566373651,128,14599,94390430,CLX5
2025-09-24 19:43:06.472486527+00:00,160,1,432669,C,A,64.81,1,26,8058566373472,128,14839,94390432,CLX5
2025-09-24 19:43:06.472491441+00:00,160,1,432669,C,A,64.81,1,26,8058566373470,128,18354,94390433,CLX5
2025-09-24 19:43:06.472500617+00:00,160,1,432669,C,A,64.81,1,26,8058566373469,128,14941,94390434,CLX5
2025-09-24 19:43:06.472675541+00:00,160,1,432669,T,B,64.8,1,26,8058566373653,0,17529,94390436,CLX5
2025-09-24 19:43:06.472675541+00:00,160,1,432669,F,A,64.8,1,26,8058566373621,0,17529,94390436,CLX5
2025-09-24 19:43:06.472675541+00:00,160,1,432669,C,A,64.8,1,26,8058566373621,128,14623,94390437,CLX5
2025-09-24 19:43:06.472940625+00:00,160,1,432669,T,B,64.8,2,26,8058566373655,0,18132,94390443,CLX5
2025-09-24 19:43:06.472940625+00:00,160,1,432669,F,A,64.8,1,26,8058566373622,0,18132,94390443,CLX5
2025-09-24 19:43:06.472940625+00:00,160,1,432669,F,A,64.8,1,26,8058566373250,0,18132,94390443,CLX5
2025-09-24 19:43:06.472940625+00:00,160,1,432669,C,A,64.8,1,26,8058566373622,0,14734,94390444,CLX5
2025-09-24 19:43:06.472940625+00:00,160,1,432669,C,A,64.8,1,26,8058566373250,128,14734,94390444,CLX5
2025-09-24 19:43:06.473187851+00:00,160,1,432669,M,A,65.96,4,26,8058566275289,128,13539,94390451,CLX5
2025-09-24 19:43:06.473358223+00:00,160,1,432669,A,B,64.79,1,26,8058566373663,128,14058,94390464,CLX5
2025-09-24 19:43:06.473426093+00:00,160,1,432669,A,B,64.79,1,26,8058566373664,128,14840,94390465,CLX5
2025-09-24 19:43:06.473790187+00:00,160,1,432669,M,A,64.83,3,26,8058566373342,128,14304,94390474,CLX5
2025-09-24 19:43:06.473910027+00:00,160,1,432669,A,B,64.78,1,26,8058566373672,128,18494,94390476,CLX5
2025-09-24 19:43:06.475943005+00:00,160,1,432669,A,A,65.95,3,26,8058566373687,128,14004,94390500,CLX5
2025-09-24 19:43:06.505769237+00:00,160,1,432669,A,B,64.78,1,26,8058566373788,128,16725,94390639,CLX5
2025-09-24 19:43:06.509174089+00:00,160,1,432669,A,B,64.79,4,26,8058566373792,128,18591,94390648,CLX5
2025-09-24 19:43:06.509310403+00:00,160,1,432669,A,B,64.8,2,26,8058566373793,128,18130,94390649,CLX5
2025-09-24 19:43:06.509543635+00:00,160,1,432669,A,B,64.8,1,26,8058566373795,128,13943,94390655,CLX5
2025-09-24 19:43:06.509710573+00:00,160,1,432669,M,A,65.97,3,26,8058566354590,128,18514,94390662,CLX5
2025-09-24 19:43:06.509736127+00:00,160,1,432669,M,B,64.79,3,26,8058566365565,128,14680,94390663,CLX5
2025-09-24 19:43:06.522291911+00:00,160,1,432669,C,A,64.83,1,26,8058566373058,128,18030,94390704,CLX5
2025-09-24 19:43:06.522446061+00:00,160,1,432669,A,A,64.81,1,26,8058566373829,128,15060,94390709,CLX5
2025-09-24 19:43:06.522592129+00:00,160,1,432669,A,A,64.81,1,26,8058566373830,128,18238,94390710,CLX5
2025-09-24 19:43:06.522736141+00:00,160,1,432669,A,A,64.81,1,26,8058566373831,128,18256,94390711,CLX5
2025-09-24 19:43:06.533706595+00:00,160,1,432669,C,B,64.78,1,26,8058566373788,128,17663,94390733,CLX5
2025-09-24 19:43:06.590035411+00:00,160,1,432669,A,B,64.79,2,26,8058566373929,128,17975,94390848,CLX5
2025-09-24 19:43:06.641154423+00:00,160,1,432669,A,B,64.77,1,26,8058566373988,128,18574,94390939,CLX5
2025-09-24 19:43:06.654989487+00:00,160,1,432669,C,B,64.77,1,26,8058566373167,128,18389,94390960,CLX5
2025-09-24 19:43:06.654991079+00:00,160,1,432669,A,B,64.76,1,26,8058566374003,128,14574,94390961,CLX5
2025-09-24 19:43:06.654993535+00:00,160,1,432669,A,B,64.75,1,26,8058566374004,128,14539,94390962,CLX5
2025-09-24 19:43:06.655160339+00:00,160,1,432669,C,A,64.81,1,26,8058566373831,128,14933,94390964,CLX5
2025-09-24 19:43:06.667080977+00:00,160,1,432669,A,B,64.55,1,26,8058566374013,128,17665,94391000,CLX5
2025-09-24 19:43:06.944033861+00:00,160,1,432669,C,A,64.81,1,26,8058566373830,128,18689,94391225,CLX5
2025-09-24 19:43:06.944039621+00:00,160,1,432669,C,A,64.81,1,26,8058566373829,128,14821,94391226,CLX5
2025-09-24 19:43:06.945115561+00:00,160,1,432669,C,A,64.81,2,26,8058566373371,128,18231,94391249,CLX5
2025-09-24 19:43:06.945483303+00:00,160,1,432669,A,B,64.8,2,26,8058566374169,128,14064,94391260,CLX5
2025-09-24 19:43:06.946263535+00:00,160,1,432669,A,B,64.77,1,26,8058566374183,128,17937,94391300,CLX5
2025-09-24 19:43:07.018465385+00:00,160,1,432669,A,A,65.48,2,26,8058566374206,128,17904,94391366,CLX5
2025-09-24 19:43:07.044933893+00:00,160,1,432669,C,B,64.77,1,26,8058566373988,128,17785,94391383,CLX5
2025-09-24 19:43:07.064333523+00:00,160,1,432669,A,B,64.79,1,26,8058566374245,128,17871,94391419,CLX5
2025-09-24 19:43:07.241120049+00:00,160,1,432669,A,B,64.78,1,26,8058566374292,128,18653,94391486,CLX5
2025-09-24 19:43:07.627284453+00:00,160,1,432669,A,B,64.8,1,26,8058566374322,128,20475,94391553,CLX5
2025-09-24 19:43:07.944870923+00:00,160,1,432669,A,A,64.81,50,26,8058566374339,128,18733,94391586,CLX5
2025-09-24 19:43:07.945029603+00:00,160,1,432669,T,A,64.8,5,26,8058566374340,0,17930,94391587,CLX5
2025-09-24 19:43:07.945029603+00:00,160,1,432669,F,B,64.8,2,26,8058566373793,0,17930,94391587,CLX5
2025-09-24 19:43:07.945029603+00:00,160,1,432669,F,B,64.8,1,26,8058566373795,0,17930,94391587,CLX5
2025-09-24 19:43:07.945029603+00:00,160,1,432669,F,B,64.8,2,26,8058566374169,0,17930,94391587,CLX5
2025-09-24 19:43:07.945029603+00:00,160,1,432669,C,B,64.8,2,26,8058566373793,0,14689,94391588,CLX5
2025-09-24 19:43:07.945029603+00:00,160,1,432669,C,B,64.8,1,26,8058566373795,0,14689,94391588,CLX5
2025-09-24 19:43:07.945029603+00:00,160,1,432669,C,B,64.8,2,26,8058566374169,0,14689,94391588,CLX5
2025-09-24 19:43:07.945029603+00:00,160,1,432669,C,B,64.8,1,26,8058566374322,128,14689,94391588,CLX5
2025-09-24 19:43:07.945030535+00:00,160,1,432669,A,A,64.8,2,26,8058566374344,128,14510,94391598,CLX5
2025-09-24 19:43:07.945030711+00:00,160,1,432669,A,A,64.8,1,26,8058566374345,128,14648,94391602,CLX5
2025-09-24 19:43:07.945030889+00:00,160,1,432669,C,B,64.79,2,26,8058566373028,128,14800,94391604,CLX5
2025-09-24 19:43:07.945031037+00:00,160,1,432669,C,B,64.79,1,26,8058566373029,128,18534,94391606,CLX5
2025-09-24 19:43:07.945036617+00:00,160,1,432669,A,A,64.8,1,26,8058566374350,128,16492,94391612,CLX5
2025-09-24 19:43:07.945039739+00:00,160,1,432669,A,A,64.8,1,26,8058566374353,128,14483,94391615,CLX5
2025-09-24 19:43:07.945067041+00:00,160,1,432669,A,A,64.8,1,26,8058566374356,128,18509,94391618,CLX5
2025-09-24 19:43:07.945091789+00:00,160,1,432669,C,B,64.79,1,26,8058566226389,128,16457,94391619,CLX5
2025-09-24 19:43:07.945420459+00:00,160,1,432669,A,A,64.8,1,26,8058566374361,128,20554,94391627,CLX5
2025-09-24 19:43:07.945486869+00:00,160,1,432669,A,A,64.8,1,26,8058566374367,128,16633,94391643,CLX5
2025-09-24 19:43:07.945492071+00:00,160,1,432669,C,B,64.55,1,26,8058566374013,128,14310,94391644,CLX5
2025-09-24 19:43:07.945494721+00:00,160,1,432669,C,A,64.8,1,26,8058566374361,128,15472,94391646,CLX5
2025-09-24 19:43:07.945673255+00:00,160,1,432669,C,A,64.8,1,26,8058566374353,128,17428,94391668,CLX5
2025-09-24 19:43:07.945674079+00:00,160,1,432669,C,A,64.8,1,26,8058566374345,128,18216,94391669,CLX5
2025-09-24 19:43:07.945727167+00:00,160,1,432669,A,B,64.79,1,26,8058566374376,128,14756,94391677,CLX5
2025-09-24 19:43:07.945798913+00:00,160,1,432669,M,A,64.8,2,26,8058566373208,128,17984,94391687,CLX5
2025-09-24 19:43:07.946048599+00:00,160,1,432669,M,A,64.82,4,26,8058566354590,128,13558,94391705,CLX5
2025-09-24 19:43:07.946052707+00:00,160,1,432669,C,B,64.77,1,26,8058566374183,128,18045,94391706,CLX5
2025-09-24 19:43:07.946072675+00:00,160,1,432669,A,A,64.83,1,26,8058566374388,128,13352,94391712,CLX5
2025-09-24 19:43:07.946323705+00:00,160,1,432669,A,A,64.8,1,26,8058566374393,128,16432,94391721,CLX5
2025-09-24 19:43:07.946325949+00:00,160,1,432669,C,A,64.81,1,26,8058566373570,128,13509,94391722,CLX5
2025-09-24 19:43:07.946491581+00:00,160,1,432669,T,N,64.8,2,26,0,0,15052,94391726,CLX5
2025-09-24 19:43:07.946491581+00:00,160,1,432669,F,N,64.8,2,26,8058566374344,0,15052,94391726,CLX5
2025-09-24 19:43:07.946491581+00:00,160,1,432669,C,A,64.8,2,26,8058566374344,128,18860,94391727,CLX5
2025-09-24 19:43:07.946543323+00:00,160,1,432669,M,B,63.61,4,26,8058566365565,128,18630,94391732,CLX5
2025-09-24 19:43:07.946754937+00:00,160,1,432669,C,A,64.8,1,26,8058566374367,128,19276,94391738,CLX5
2025-09-24 19:43:07.947484137+00:00,160,1,432669,C,B,64.78,1,26,8058566374292,128,18152,94391756,CLX5
2025-09-24 19:43:07.947519963+00:00,160,1,432669,C,A,64.83,3,26,8058566373342,128,14383,94391760,CLX5
2025-09-24 19:43:07.948345277+00:00,160,1,432669,A,B,64.77,1,26,8058566374406,128,14378,94391778,CLX5
2025-09-24 19:43:07.948803677+00:00,160,1,432669,T,B,64.8,3,26,8058566374408,0,14535,94391781,CLX5
2025-09-24 19:43:07.948803677+00:00,160,1,432669,F,A,64.8,1,26,8058566374350,0,14535,94391781,CLX5
2025-09-24 19:43:07.948803677+00:00,160,1,432669,F,A,64.8,1,26,8058566374356,0,14535,94391781,CLX5
2025-09-24 19:43:07.948803677+00:00,160,1,432669,F,A,64.8,1,26,8058566373208,0,14535,94391781,CLX5
2025-09-24 19:43:07.948803677+00:00,160,1,432669,C,A,64.8,1,26,8058566374350,0,14607,94391782,CLX5
2025-09-24 19:43:07.948803677+00:00,160,1,432669,C,A,64.8,1,26,8058566374356,0,14607,94391782,CLX5
2025-09-24 19:43:07.948803677+00:00,160,1,432669,M,A,64.8,1,26,8058566373208,128,14607,94391782,CLX5
2025-09-24 19:43:07.949795851+00:00,160,1,432669,T,B,64.8,1,26,8058566373929,0,14562,94391811,CLX5
2025-09-24 19:43:07.949795851+00:00,160,1,432669,F,B,64.8,1,26,8058566373929,0,14562,94391811,CLX5
2025-09-24 19:43:07.949795851+00:00,160,1,432669,F,A,64.8,1,26,8058566373208,0,14562,94391811,CLX5
2025-09-24 19:43:07.949795851+00:00,160,1,432669,C,B,64.79,2,26,8058566373929,0,19805,94391812,CLX5
2025-09-24 19:43:07.949795851+00:00,160,1,432669,C,A,64.8,1,26,8058566373208,128,19805,94391812,CLX5
2025-09-24 19:43:07.949961979+00:00,160,1,432669,T,B,64.8,1,26,8058566374425,0,14592,94391838,CLX5
2025-09-24 19:43:07.949961979+00:00,160,1,432669,F,A,64.8,1,26,8058566374393,0,14592,94391838,CLX5
2025-09-24 19:43:07.949961979+00:00,160,1,432669,C,A,64.8,1,26,8058566374393,128,14558,94391839,CLX5
2025-09-24 19:43:07.950106609+00:00,160,1,432669,C,A,64.82,4,26,8058566354590,128,14534,94391850,CLX5
2025-09-24 19:43:07.950846371+00:00,160,1,432669,M,B,64.79,3,26,8058566370556,128,17049,94391880,CLX5
2025-09-24 19:43:07.951024769+00:00,160,1,432669,A,B,64.79,2,26,8058566374443,128,15619,94391882,CLX5
2025-09-24 19:43:07.951024981+00:00,160,1,432669,A,B,64.79,1,26,8058566374444,128,14994,94391883,CLX5
2025-09-24 19:43:07.951035847+00:00,160,1,432669,A,B,64.79,1,26,8058566374445,128,14781,94391886,CLX5
2025-09-24 19:43:07.951301121+00:00,160,1,432669,A,A,64.81,1,26,8058566374447,128,18441,94391894,CLX5
2025-09-24 19:43:07.951876385+00:00,160,1,432669,A,A,64.81,1,26,8058566374450,128,17971,94391900,CLX5
2025-09-24 19:43:07.951925997+00:00,160,1,432669,C,B,64.79,1,26,8058566374445,128,14836,94391901,CLX5
2025-09-24 19:43:07.951948499+00:00,160,1,432669,A,A,64.81,1,26,8058566374451,128,14570,94391902,CLX5
2025-09-24 19:43:07.952158403+00:00,160,1,432669,A,B,64.79,1,26,8058566374453,128,14674,94391911,CLX5
2025-09-24 19:43:07.952500225+00:00,160,1,432669,C,A,64.81,1,26,8058566374451,128,18666,94391920,CLX5
2025-09-24 19:43:07.952507289+00:00,160,1,432669,C,A,64.81,1,26,8058566374450,128,15386,94391921,CLX5
2025-09-24 19:43:07.952516639+00:00,160,1,432669,C,A,64.81,1,26,8058566374447,128,15111,94391922,CLX5
2025-09-24 19:43:07.952582551+00:00,160,1,432669,M,B,64.78,1,26,8058566374453,128,18490,94391929,CLX5
2025-09-24 19:43:07.953394423+00:00,160,1,432669,M,B,64.79,1,26,8058566374453,128,19347,94391961,CLX5
2025-09-24 19:43:07.953550783+00:00,160,1,432669,A,B,64.78,1,26,8058566374469,128,16520,94391964,CLX5
2025-09-24 19:43:07.956952583+00:00,160,1,432669,C,B,64.79,4,26,8058566373792,128,19016,94391969,CLX5
2025-09-24 19:43:07.966885401+00:00,160,1,432669,A,B,64.8,1,26,8058566374474,128,17960,94391988,CLX5
2025-09-24 19:43:07.967168933+00:00,160,1,432669,A,B,64.8,1,26,8058566374476,128,13509,94391996,CLX5
2025-09-24 19:43:07.967237705+00:00,160,1,432669,M,B,64.78,1,26,8058566374453,128,14783,94391999,CLX5
2025-09-24 19:43:08.067068539+00:00,160,1,432669,A,B,64.55,1,26,8058566374518,128,14043,94392073,CLX5
2025-09-24 19:43:08.124998063+00:00,160,1,432669,C,A,64.83,1,26,8058566374388,128,18257,94392120,CLX5
2025-09-24 19:43:08.141154613+00:00,160,1,432669,A,B,64.78,1,26,8058566374540,128,18314,94392123,CLX5
2025-09-24 19:43:09.119738989+00:00,160,1,432669,T,A,64.8,1,26,8058566374580,0,17995,94392189,CLX5
2025-09-24 19:43:09.119738989+00:00,160,1,432669,F,B,64.8,1,26,8058566374474,0,17995,94392189,CLX5
2025-09-24 19:43:09.119738989+00:00,160,1,432669,C,B,64.8,1,26,8058566374474,128,14324,94392190,CLX5
2025-09-24 19:43:09.120038361+00:00,160,1,432669,T,A,64.8,1,26,8058566374581,0,18500,94392193,CLX5
2025-09-24 19:43:09.120038361+00:00,160,1,432669,F,B,64.8,1,26,8058566374476,0,18500,94392193,CLX5
2025-09-24 19:43:09.120038361+00:00,160,1,432669,C,B,64.8,1,26,8058566374476,128,14699,94392194,CLX5
2025-09-24 19:43:09.120259209+00:00,160,1,432669,A,B,64.8,4,26,8058566374583,128,14707,94392200,CLX5
2025-09-24 19:43:09.120292423+00:00,160,1,432669,C,B,64.55,1,26,8058566374518,128,14445,94392204,CLX5
2025-09-24 19:43:09.120480787+00:00,160,1,432669,T,A,64.8,1,26,8058566374585,0,18858,94392208,CLX5
2025-09-24 19:43:09.120480787+00:00,160,1,432669,F,B,64.8,1,26,8058566374583,0,18858,94392208,CLX5
2025-09-24 19:43:09.120480787+00:00,160,1,432669,M,B,64.8,3,26,8058566374583,128,14391,94392209,CLX5
2025-09-24 19:43:09.128673871+00:00,160,1,432669,A,B,64.8,1,26,8058566374590,128,21873,94392221,CLX5
2025-09-24 19:43:09.128824875+00:00,160,1,432669,A,B,64.8,1,26,8058566374591,128,22733,94392222,CLX5
2025-09-24 19:43:09.129821327+00:00,160,1,432669,A,B,64.8,1,26,8058566374593,128,20373,94392224,CLX5
2025-09-24 19:43:09.152632821+00:00,160,1,432669,A,B,64.77,1,26,8058566374603,128,14758,94392260,CLX5
2025-09-24 19:43:09.152851269+00:00,160,1,432669,A,B,64.8,2,26,8058566374606,128,19256,94392268,CLX5
2025-09-24 19:43:09.171033615+00:00,160,1,432669,M,B,64.8,2,26,8058566374583,128,19372,94392286,CLX5
2025-09-24 19:43:09.233759973+00:00,160,1,432669,C,B,64.8,2,26,8058566374583,128,19871,94392295,CLX5
2025-09-24 19:43:09.233926737+00:00,160,1,432669,C,B,64.8,2,26,8058566374606,128,18131,94392296,CLX5
2025-09-24 19:43:09.267024885+00:00,160,1,432669,A,B,64.55,1,26,8058566374614,128,17900,94392299,CLX5
2025-09-24 19:43:09.312958341+00:00,160,1,432669,A,B,64.76,2,26,8058566374618,128,18510,94392307,CLX5
2025-09-24 19:43:10.013636229+00:00,160,1,432669,A,B,64.79,1,26,8058566374625,128,18592,94392319,CLX5
2025-09-24 19:43:10.023963527+00:00,160,1,432669,A,A,64.84,1,26,8058566374626,128,17873,94392320,CLX5
2025-09-24 19:43:10.045927913+00:00,160,1,432669,C,B,64.8,1,26,8058566374593,128,18012,94392326,CLX5
2025-09-24 19:43:10.345098651+00:00,160,1,432669,A,B,64.8,1,26,8058566374637,128,14530,94392346,CLX5
2025-09-24 19:43:10.345320439+00:00,160,1,432669,T,A,64.8,2,26,8058566374639,0,17882,94392353,CLX5
2025-09-24 19:43:10.345320439+00:00,160,1,432669,F,B,64.8,1,26,8058566374590,0,17882,94392353,CLX5
2025-09-24 19:43:10.345320439+00:00,160,1,432669,F,B,64.8,1,26,8058566374591,0,17882,94392353,CLX5
2025-09-24 19:43:10.345320439+00:00,160,1,432669,C,B,64.8,1,26,8058566374590,0,14885,94392354,CLX5
2025-09-24 19:43:10.345320439+00:00,160,1,432669,C,B,64.8,1,26,8058566374591,128,14885,94392354,CLX5
2025-09-24 19:43:10.345553883+00:00,160,1,432669,C,B,64.8,1,26,8058566374637,128,13775,94392359,CLX5
2025-09-24 19:43:10.345734183+00:00,160,1,432669,C,B,64.55,1,26,8058566374614,128,14984,94392371,CLX5
2025-09-24 19:43:10.346188743+00:00,160,1,432669,C,B,64.77,1,26,8058566374603,128,14674,94392389,CLX5
2025-09-24 19:43:10.346474253+00:00,160,1,432669,A,B,64.77,1,26,8058566374654,128,14779,94392409,CLX5
2025-09-24 19:43:10.346672713+00:00,160,1,432669,A,B,64.79,1,26,8058566374657,128,14841,94392419,CLX5
2025-09-24 19:43:10.348693597+00:00,160,1,432669,C,B,64.76,2,26,8058566374618,128,18496,94392445,CLX5
2025-09-24 19:43:10.423737513+00:00,160,1,432669,A,B,64.79,1,26,8058566374666,128,17558,94392459,CLX5
2025-09-24 19:43:10.423886191+00:00,160,1,432669,C,B,64.79,1,26,8058566374666,128,18151,94392460,CLX5
2025-09-24 19:43:10.424391397+00:00,160,1,432669,A,B,64.79,1,26,8058566374667,128,18178,94392461,CLX5
2025-09-24 19:43:10.467412337+00:00,160,1,432669,A,B,62.95,1,26,8058566374668,128,18416,94392463,CLX5
2025-09-24 19:43:10.479931951+00:00,160,1,432669,A,B,63.24,1,26,8058566374669,128,18194,94392464,CLX5
2025-09-24 19:43:10.612671963+00:00,160,1,432669,A,B,64.76,2,26,8058566374675,128,18061,94392472,CLX5
2025-09-24 19:43:10.612674825+00:00,160,1,432669,A,B,64.75,2,26,8058566374676,128,14318,94392473,CLX5
2025-09-24 19:43:11.119744551+00:00,160,1,432669,A,B,64.77,1,26,8058566374682,128,18652,94392491,CLX5
2025-09-24 19:43:11.122420395+00:00,160,1,432669,A,B,64.79,4,26,8058566374683,128,18373,94392492,CLX5
2025-09-24 19:43:11.122588117+00:00,160,1,432669,C,B,64.79,1,26,8058566374667,128,14649,94392495,CLX5
2025-09-24 19:43:11.586152587+00:00,160,1,432669,C,B,64.79,4,26,8058566374683,128,18602,94392514,CLX5
2025-09-24 19:43:12.139885435+00:00,160,1,432669,A,B,64.8,1,26,8058566374744,128,16201,94392705,CLX5
2025-09-24 19:43:12.139924647+00:00,160,1,432669,A,B,64.8,2,26,8058566374748,128,14506,94392717,CLX5
2025-09-24 19:43:12.139924825+00:00,160,1,432669,C,A,64.81,2,26,8058566372438,128,15849,94392719,CLX5
2025-09-24 19:43:12.139924973+00:00,160,1,432669,A,B,64.8,2,26,8058566374749,128,22543,94392721,CLX5
2025-09-24 19:43:12.139925153+00:00,160,1,432669,A,B,64.8,3,26,8058566374750,128,18532,94392722,CLX5
2025-09-24 19:43:12.139946001+00:00,160,1,432669,C,B,64.8,2,26,8058566374749,128,16839,94392723,CLX5
2025-09-24 19:43:12.140102761+00:00,160,1,432669,A,B,64.8,1,26,8058566374752,128,16767,94392727,CLX5
2025-09-24 19:43:12.140182939+00:00,160,1,432669,A,B,64.8,1,26,8058566374755,128,16171,94392732,CLX5
2025-09-24 19:43:12.142255487+00:00,160,1,432669,C,B,64.8,3,26,8058566374750,128,13902,94392833,CLX5
2025-09-24 19:43:12.142566859+00:00,160,1,432669,C,B,64.8,1,26,8058566374752,128,19688,94392843,CLX5
2025-09-24 19:43:12.143091705+00:00,160,1,432669,C,B,64.8,2,26,8058566374748,128,18118,94392846,CLX5
2025-09-24 19:43:12.179971317+00:00,160,1,432669,C,B,63.24,1,26,8058566374669,128,18715,94392880,CLX5
2025-09-24 19:43:12.185022691+00:00,160,1,432669,A,B,64.74,1,26,8058566374787,128,18484,94392881,CLX5
2025-09-24 19:43:12.267057189+00:00,160,1,432669,A,B,64.55,1,26,8058566374798,128,17704,94392900,CLX5
2025-09-24 19:43:12.289528377+00:00,160,1,432669,A,B,64.77,1,26,8058566374806,128,13664,94392922,CLX5
2025-09-24 19:43:12.289826539+00:00,160,1,432669,A,B,64.8,2,26,8058566374809,128,14572,94392934,CLX5
2025-09-24 19:43:12.300426007+00:00,160,1,432669,C,B,64.8,2,26,8058566374809,128,18231,94392951,CLX5
2025-09-24 19:43:13.508502731+00:00,160,1,432669,T,A,64.8,1,26,8058566374855,0,18330,94393023,CLX5
2025-09-24 19:43:13.508502731+00:00,160,1,432669,F,B,64.8,1,26,8058566374744,0,18330,94393023,CLX5
2025-09-24 19:43:13.508502731+00:00,160,1,432669,C,B,64.8,1,26,8058566374744,128,16051,94393024,CLX5
2025-09-24 19:43:14.976064277+00:00,160,1,432669,A,A,65.0,2,26,8058566374865,128,19556,94393072,CLX5
2025-09-24 19:43:15.903286225+00:00,160,1,432669,M,B,64.71,35,26,8058566342993,128,18100,94393211,CLX5
2025-09-24 19:43:16.747832571+00:00,160,1,432669,T,A,64.8,1,26,8058566374949,0,19049,94393279,CLX5
2025-09-24 19:43:16.747832571+00:00,160,1,432669,F,B,64.8,1,26,8058566374755,0,19049,94393279,CLX5
2025-09-24 19:43:16.747832571+00:00,160,1,432669,C,B,64.8,1,26,8058566374755,128,17794,94393280,CLX5
2025-09-24 19:43:16.748182281+00:00,160,1,432669,C,B,64.79,1,26,8058566373022,128,18105,94393283,CLX5
2025-09-24 19:43:16.748188963+00:00,160,1,432669,C,B,64.55,1,26,8058566374798,128,14745,94393285,CLX5
2025-09-24 19:43:16.748812995+00:00,160,1,432669,C,B,64.77,1,26,8058566374806,128,14912,94393315,CLX5
2025-09-24 19:43:16.811859155+00:00,160,1,432669,C,B,64.76,2,26,8058566374675,128,18391,94393426,CLX5
2025-09-24 19:43:16.818786555+00:00,160,1,432669,C,A,65.48,2,26,8058566374206,128,14727,94393430,CLX5
2025-09-24 19:43:16.879946919+00:00,160,1,432669,A,B,63.24,1,26,8058566374987,128,18602,94393442,CLX5
2025-09-24 19:43:16.898195695+00:00,160,1,432669,A,A,64.8,2,26,8058566374994,128,18440,94393459,CLX5
2025-09-24 19:43:16.898571171+00:00,160,1,432669,M,A,64.8,1,26,8058566374626,128,15021,94393512,CLX5
2025-09-24 19:43:16.898761455+00:00,160,1,432669,M,A,64.82,4,26,8058566275289,128,15079,94393517,CLX5
2025-09-24 19:43:16.899428779+00:00,160,1,432669,A,A,64.8,1,26,8058566375018,128,15565,94393557,CLX5
2025-09-24 19:43:16.899482517+00:00,160,1,432669,A,A,64.83,1,26,8058566375021,128,16973,94393565,CLX5
2025-09-24 19:43:16.979977713+00:00,160,1,432669,C,A,66.36,1,26,8058566227548,128,18294,94393746,CLX5
2025-09-24 19:43:16.987730025+00:00,160,1,432669,C,A,64.8,1,26,8058566375018,128,18959,94393749,CLX5
2025-09-24 19:43:17.067082967+00:00,160,1,432669,A,A,65.05,1,26,8058566375109,128,23366,94393807,CLX5
2025-09-24 19:43:17.448359513+00:00,160,1,432669,C,A,64.8,2,26,8058566374994,128,14925,94394103,CLX5
2025-09-24 19:43:17.449724687+00:00,160,1,432669,T,B,64.8,1,26,8058566375221,0,17932,94394191,CLX5
2025-09-24 19:43:17.449724687+00:00,160,1,432669,F,A,64.8,1,26,8058566374626,0,17932,94394191,CLX5
2025-09-24 19:43:17.449724687+00:00,160,1,432669,C,A,64.8,1,26,8058566374626,128,14952,94394192,CLX5
2025-09-24 19:43:17.451101881+00:00,160,1,432669,A,B,64.77,1,26,8058566375244,128,15315,94394268,CLX5
2025-09-24 19:43:17.451109905+00:00,160,1,432669,A,B,64.79,1,26,8058566375245,128,15694,94394278,CLX5
2025-09-24 19:43:17.451148843+00:00,160,1,432669,C,A,65.05,1,26,8058566375109,128,14754,94394303,CLX5
2025-09-24 19:43:17.451329507+00:00,160,1,432669,C,A,64.82,4,26,8058566275289,128,15047,94394312,CLX5
2025-09-24 19:43:17.451566155+00:00,160,1,432669,M,B,64.79,1,26,8058566374453,128,15709,94394318,CLX5
2025-09-24 19:43:17.451652935+00:00,160,1,432669,C,A,64.83,1,26,8058566375021,128,14871,94394322,CLX5
2025-09-24 19:43:17.452717607+00:00,160,1,432669,M,A,64.83,3,26,8058566373687,128,15055,94394361,CLX5
2025-09-24 19:43:17.463326999+00:00,160,1,432669,C,B,64.79,1,26,8058566375245,128,18518,94394457,CLX5
2025-09-24 19:43:17.463927013+00:00,160,1,432669,M,B,64.78,1,26,8058566374453,128,18602,94394478,CLX5
2025-09-24 19:43:17.470046761+00:00,160,1,432669,A,A,65.95,3,26,8058566375302,128,19247,94394496,CLX5
2025-09-24 19:43:17.580415571+00:00,160,1,432669,A,A,66.36,1,26,8058566375430,128,18874,94394709,CLX5
2025-09-24 19:43:17.635051773+00:00,160,1,432669,C,B,64.77,1,26,8058566375244,128,18541,94394758,CLX5
2025-09-24 19:43:18.359918311+00:00,160,1,432669,A,B,64.79,1,26,8058566375550,128,18653,94394926,CLX5
2025-09-24 19:43:19.085021257+00:00,160,1,432669,A,A,64.81,1,26,8058566375561,128,19093,94394959,CLX5
2025-09-24 19:43:19.518554799+00:00,160,1,432669,A,A,65.48,2,26,8058566375572,128,19149,94395034,CLX5
2025-09-24 19:43:20.560303317+00:00,160,1,432669,A,B,64.79,1,26,8058566375595,128,14992,94395090,CLX5
2025-09-24 19:43:21.427594019+00:00,160,1,432669,T,A,64.79,1,26,8058566375603,0,19392,94395122,CLX5
2025-09-24 19:43:21.427594019+00:00,160,1,432669,F,B,64.79,1,26,8058564297544,0,19392,94395122,CLX5
2025-09-24 19:43:21.427594019+00:00,160,1,432669,T,A,64.79,2,26,8058565496184,0,15986,94395123,CLX5
2025-09-24 19:43:21.427594019+00:00,160,1,432669,F,B,64.79,1,26,8058564297544,0,15986,94395123,CLX5
2025-09-24 19:43:21.427594019+00:00,160,1,432669,F,B,64.79,1,26,8058564363073,0,15986,94395123,CLX5
2025-09-24 19:43:21.427594019+00:00,160,1,432669,C,B,64.79,2,26,8058564297544,0,15986,94395123,CLX5
2025-09-24 19:43:21.427594019+00:00,160,1,432669,M,B,64.79,1,26,8058564363073,128,15986,94395123,CLX5
2025-09-24 19:43:21.438297087+00:00,160,1,432669,A,B,64.79,1,26,8058566375621,128,18663,94395184,CLX5
2025-09-24 19:43:21.643250717+00:00,160,1,432669,A,B,64.79,4,26,8058566375638,128,19123,94395204,CLX5
2025-09-24 19:43:21.645249753+00:00,160,1,432669,C,B,64.79,4,26,8058566375638,128,19148,94395206,CLX5
2025-09-24 19:43:22.409072657+00:00,160,1,432669,C,B,64.79,1,26,8058566375550,128,20033,94395214,CLX5
2025-09-24 19:43:23.420115533+00:00,160,1,432669,A,B,64.79,1,26,8058566375642,128,20422,94395244,CLX5
2025-09-24 19:43:23.425250211+00:00,160,1,432669,A,B,64.79,4,26,8058566375644,128,17928,94395248,CLX5
2025-09-24 19:43:23.941499485+00:00,160,1,432669,A,B,64.79,3,26,8058566375645,128,20876,94395249,CLX5
2025-09-24 19:43:24.847304585+00:00,160,1,432669,T,A,64.79,1,26,8058566375647,0,22654,94395254,CLX5
2025-09-24 19:43:24.847304585+00:00,160,1,432669,F,B,64.79,1,26,8058564363073,0,22654,94395254,CLX5
2025-09-24 19:43:24.847304585+00:00,160,1,432669,C,B,64.79,1,26,8058564363073,128,16237,94395255,CLX5
2025-09-24 19:43:24.850918309+00:00,160,1,432669,C,B,64.79,4,26,8058566375644,128,18335,94395277,CLX5
2025-09-24 19:43:24.854314851+00:00,160,1,432669,A,B,64.79,4,26,8058566375655,128,18587,94395278,CLX5
2025-09-24 19:43:24.857799957+00:00,160,1,432669,A,B,64.79,1,26,8058566375656,128,18552,94395279,CLX5
2025-09-24 19:43:24.904329047+00:00,160,1,432669,A,B,64.51,1,26,8058566375658,128,17635,94395281,CLX5
2025-09-24 19:43:29.421594081+00:00,160,1,432669,A,B,64.77,1,26,8058566375676,128,18613,94395347,CLX5
2025-09-24 19:43:29.421971595+00:00,160,1,432669,A,B,64.8,2,26,8058566375679,128,21243,94395359,CLX5
2025-09-24 19:43:29.422324839+00:00,160,1,432669,A,B,64.8,1,26,8058566375682,128,18083,94395371,CLX5
2025-09-24 19:43:29.422383551+00:00,160,1,432669,A,B,64.8,1,26,8058566375684,128,18150,94395374,CLX5
2025-09-24 19:43:29.422517657+00:00,160,1,432669,A,A,64.84,1,26,8058566375686,128,14633,94395377,CLX5
2025-09-24 19:43:29.480003723+00:00,160,1,432669,C,B,63.24,1,26,8058566374987,128,19350,94395388,CLX5
2025-09-24 19:43:29.480163651+00:00,160,1,432669,A,A,64.81,1,26,8058566375688,128,18288,94395389,CLX5
2025-09-24 19:43:29.480307473+00:00,160,1,432669,C,B,64.8,1,26,8058566375682,128,14449,94395391,CLX5
2025-09-24 19:43:29.480327169+00:00,160,1,432669,A,A,64.81,1,26,8058566375689,128,13915,94395393,CLX5
2025-09-24 19:43:29.480465077+00:00,160,1,432669,C,B,64.8,2,26,8058566375679,128,16219,94395395,CLX5
2025-09-24 19:43:29.480482337+00:00,160,1,432669,A,A,64.81,1,26,8058566375691,128,15974,94395397,CLX5
2025-09-24 19:43:29.488967575+00:00,160,1,432669,T,A,64.8,1,26,8058566375703,0,17579,94395460,CLX5
2025-09-24 19:43:29.488967575+00:00,160,1,432669,F,B,64.8,1,26,8058566375684,0,17579,94395460,CLX5
2025-09-24 19:43:29.488967575+00:00,160,1,432669,C,B,64.8,1,26,8058566375684,128,14761,94395461,CLX5
2025-09-24 19:43:29.492781353+00:00,160,1,432669,C,B,64.79,4,26,8058566375655,128,17951,94395485,CLX5
2025-09-24 19:43:29.492950901+00:00,160,1,432669,C,A,64.81,1,26,8058566375691,128,14291,94395487,CLX5
2025-09-24 19:43:29.492962249+00:00,160,1,432669,C,A,64.81,1,26,8058566375689,128,14524,94395488,CLX5
2025-09-24 19:43:29.492967087+00:00,160,1,432669,C,A,64.81,1,26,8058566375688,128,14867,94395489,CLX5
2025-09-24 19:43:29.605117287+00:00,160,1,432669,C,B,64.77,1,26,8058566375676,128,17863,94395503,CLX5
2025-09-24 19:43:29.607304319+00:00,160,1,432669,A,B,64.79,4,26,8058566375720,128,18340,94395505,CLX5
2025-09-24 19:43:29.679997803+00:00,160,1,432669,A,B,63.24,1,26,8058566375724,128,18529,94395510,CLX5
2025-09-24 19:43:30.024281599+00:00,160,1,432669,A,A,64.85,1,26,8058566375726,128,22730,94395512,CLX5
2025-09-24 19:43:31.571305587+00:00,160,1,432669,T,B,64.81,3,26,8058566375823,0,18194,94395718,CLX5
2025-09-24 19:43:31.571305587+00:00,160,1,432669,F,A,64.81,1,26,8058566372355,0,18194,94395718,CLX5
2025-09-24 19:43:31.571305587+00:00,160,1,432669,F,A,64.81,1,26,8058566372362,0,18194,94395718,CLX5
2025-09-24 19:43:31.571305587+00:00,160,1,432669,F,A,64.81,1,26,8058566372366,0,18194,94395718,CLX5
2025-09-24 19:43:31.571305587+00:00,160,1,432669,C,A,64.81,1,26,8058566372355,0,16704,94395719,CLX5
2025-09-24 19:43:31.571305587+00:00,160,1,432669,C,A,64.81,1,26,8058566372362,0,16704,94395719,CLX5
2025-09-24 19:43:31.571305587+00:00,160,1,432669,C,A,64.81,1,26,8058566372366,128,16704,94395719,CLX5
2025-09-24 19:43:31.571639387+00:00,160,1,432669,A,B,64.8,2,26,8058566375826,128,17990,94395722,CLX5
2025-09-24 19:43:31.572025807+00:00,160,1,432669,A,B,64.8,1,26,8058566375838,128,18601,94395770,CLX5
2025-09-24 19:43:31.580443655+00:00,160,1,432669,C,B,63.24,1,26,8058566375724,128,17898,94395915,CLX5
2025-09-24 19:43:31.585617867+00:00,160,1,432669,A,B,64.8,1,26,8058566375849,128,21650,94395932,CLX5
2025-09-24 19:43:31.712779865+00:00,160,1,432669,A,B,64.76,2,26,8058566375867,128,18015,94395974,CLX5
2025-09-24 19:43:31.741206437+00:00,160,1,432669,A,A,66.16,4,26,8058566375873,128,18332,94395985,CLX5
2025-09-24 19:43:31.767124583+00:00,160,1,432669,A,B,64.55,1,26,8058566375878,128,19046,94395991,CLX5
2025-09-24 19:43:32.323508903+00:00,160,1,432669,C,B,64.79,1,26,8058566375642,128,18402,94396019,CLX5
2025-09-24 19:43:32.600008531+00:00,160,1,432669,C,B,64.8,1,26,8058566375838,128,19375,94396020,CLX5
2025-09-24 19:43:32.929487837+00:00,160,1,432669,T,A,64.8,1,26,8058566375898,0,18923,94396025,CLX5
2025-09-24 19:43:32.929487837+00:00,160,1,432669,F,B,64.8,1,26,8058566375826,0,18923,94396025,CLX5
2025-09-24 19:43:32.929487837+00:00,160,1,432669,M,B,64.8,1,26,8058566375826,128,14753,94396026,CLX5
2025-09-24 19:43:32.929780951+00:00,160,1,432669,C,B,64.8,1,26,8058566375826,128,17871,94396029,CLX5
2025-09-24 19:43:32.941194271+00:00,160,1,432669,C,A,66.16,4,26,8058566375873,128,18280,94396045,CLX5
2025-09-24 19:43:33.547632683+00:00,160,1,432669,T,A,64.8,1,26,8058566375912,0,17893,94396102,CLX5
2025-09-24 19:43:33.547632683+00:00,160,1,432669,F,B,64.8,1,26,8058566375849,0,17893,94396102,CLX5
2025-09-24 19:43:33.547632683+00:00,160,1,432669,C,B,64.8,1,26,8058566375849,128,15906,94396103,CLX5
2025-09-24 19:43:33.547942345+00:00,160,1,432669,C,B,64.55,1,26,8058566375878,128,13992,94396107,CLX5
2025-09-24 19:43:33.548010733+00:00,160,1,432669,A,A,64.81,1,26,8058566375914,128,14924,94396110,CLX5
2025-09-24 19:43:33.548097531+00:00,160,1,432669,A,A,64.81,1,26,8058566375915,128,14615,94396112,CLX5
2025-09-24 19:43:33.548177323+00:00,160,1,432669,A,A,64.81,1,26,8058566375916,128,17899,94396113,CLX5
2025-09-24 19:43:33.548577069+00:00,160,1,432669,C,B,64.76,2,26,8058566375867,128,17485,94396123,CLX5
2025-09-24 19:43:33.552295561+00:00,160,1,432669,C,B,64.79,4,26,8058566375720,128,17848,94396134,CLX5
2025-09-24 19:43:33.552465857+00:00,160,1,432669,C,A,64.81,1,26,8058566375916,128,18431,94396135,CLX5
2025-09-24 19:43:33.552479757+00:00,160,1,432669,C,A,64.81,1,26,8058566375915,128,14711,94396136,CLX5
2025-09-24 19:43:33.552481485+00:00,160,1,432669,C,A,64.81,1,26,8058566375914,128,14603,94396137,CLX5
2025-09-24 19:43:33.679993157+00:00,160,1,432669,A,B,63.24,1,26,8058566375925,128,20959,94396145,CLX5
2025-09-24 19:43:33.753172185+00:00,160,1,432669,M,B,64.74,1,26,8058566194413,128,19810,94396148,CLX5
2025-09-24 19:43:34.347741047+00:00,160,1,432669,A,B,64.79,1,26,8058566375931,128,18491,94396177,CLX5
2025-09-24 19:43:36.715813703+00:00,160,1,432669,A,A,64.8,2,26,8058566375973,128,14542,94396318,CLX5
2025-09-24 19:43:36.716174705+00:00,160,1,432669,M,A,64.8,1,26,8058566375726,128,13658,94396333,CLX5
2025-09-24 19:43:36.716355713+00:00,160,1,432669,M,A,64.82,4,26,8058566375302,128,18526,94396337,CLX5
2025-09-24 19:43:36.716359591+00:00,160,1,432669,C,A,64.81,1,26,8058566375561,128,14484,94396338,CLX5
2025-09-24 19:43:36.716657833+00:00,160,1,432669,A,A,64.83,1,26,8058566375979,128,13438,94396341,CLX5
2025-09-24 19:43:36.718613095+00:00,160,1,432669,C,A,65.48,2,26,8058566375572,128,18115,94396349,CLX5
2025-09-24 19:43:36.740149645+00:00,160,1,432669,T,B,64.8,1,26,8058566375988,0,13621,94396411,CLX5
2025-09-24 19:43:36.740149645+00:00,160,1,432669,F,A,64.8,1,26,8058566375973,0,13621,94396411,CLX5
2025-09-24 19:43:36.740149645+00:00,160,1,432669,M,A,64.8,1,26,8058566375973,128,13621,94396411,CLX5
2025-09-24 19:43:36.740236715+00:00,160,1,432669,T,B,64.8,2,26,8058566375991,0,18243,94396416,CLX5
2025-09-24 19:43:36.740236715+00:00,160,1,432669,F,A,64.8,1,26,8058566375973,0,18243,94396416,CLX5
2025-09-24 19:43:36.740236715+00:00,160,1,432669,F,A,64.8,1,26,8058566375726,0,18243,94396416,CLX5
2025-09-24 19:43:36.740236715+00:00,160,1,432669,C,A,64.8,1,26,8058566375973,0,14896,94396417,CLX5
2025-09-24 19:43:36.740236715+00:00,160,1,432669,C,A,64.8,1,26,8058566375726,128,14896,94396417,CLX5
2025-09-24 19:43:36.740884955+00:00,160,1,432669,C,A,64.82,4,26,8058566375302,128,18711,94396457,CLX5
2025-09-24 19:43:36.740949829+00:00,160,1,432669,A,B,64.79,3,26,8058566376004,128,17905,94396467,CLX5
2025-09-24 19:43:36.755122779+00:00,160,1,432669,A,A,65.95,3,26,8058566376042,128,14220,94396622,CLX5
2025-09-24 19:43:36.766571693+00:00,160,1,432669,A,A,64.81,1,26,8058566376054,128,18170,94396645,CLX5
2025-09-24 19:43:36.818907719+00:00,160,1,432669,A,A,65.48,2,26,8058566376070,128,17987,94396673,CLX5
2025-09-24 19:43:36.843040401+00:00,160,1,432669,C,B,64.79,3,26,8058566376004,128,15428,94396678,CLX5
2025-09-24 19:43:36.944416785+00:00,160,1,432669,A,B,64.79,3,26,8058566376105,128,18493,94396744,CLX5
2025-09-24 19:43:36.975155587+00:00,160,1,432669,C,A,64.83,1,26,8058566375979,128,17816,94396759,CLX5
2025-09-24 19:43:37.045784989+00:00,160,1,432669,C,B,64.79,3,26,8058566376105,128,18753,94396762,CLX5
2025-09-24 19:43:37.147194489+00:00,160,1,432669,A,B,64.8,3,26,8058566376117,128,18655,94396768,CLX5
2025-09-24 19:43:37.179945693+00:00,160,1,432669,T,A,64.8,1,26,8058566376137,0,17535,94396813,CLX5
2025-09-24 19:43:37.179945693+00:00,160,1,432669,F,B,64.8,1,26,8058566376117,0,17535,94396813,CLX5
2025-09-24 19:43:37.179945693+00:00,160,1,432669,M,B,64.8,2,26,8058566376117,128,14421,94396814,CLX5
2025-09-24 19:43:37.180030937+00:00,160,1,432669,C,B,63.24,1,26,8058566375925,128,14551,94396816,CLX5
2025-09-24 19:43:37.198022673+00:00,160,1,432669,M,B,64.8,1,26,8058566376117,128,17523,94396863,CLX5
2025-09-24 19:43:37.250245557+00:00,160,1,432669,C,B,64.8,1,26,8058566376117,128,18086,94396884,CLX5
2025-09-24 19:43:37.250443559+00:00,160,1,432669,A,A,64.81,1,26,8058566376154,128,17675,94396887,CLX5
2025-09-24 19:43:37.250617253+00:00,160,1,432669,A,A,64.81,1,26,8058566376155,128,18389,94396888,CLX5
2025-09-24 19:43:37.250770099+00:00,160,1,432669,A,A,64.81,1,26,8058566376156,128,17765,94396889,CLX5
2025-09-24 19:43:37.380023325+00:00,160,1,432669,A,B,63.24,1,26,8058566376164,128,17580,94396911,CLX5
2025-09-24 19:43:37.478518933+00:00,160,1,432669,C,A,64.81,1,26,8058566376156,128,18538,94396914,CLX5
2025-09-24 19:43:37.478533813+00:00,160,1,432669,C,A,64.81,1,26,8058566376155,128,14778,94396915,CLX5
2025-09-24 19:43:37.478535253+00:00,160,1,432669,C,A,64.81,1,26,8058566376154,128,14365,94396916,CLX5
2025-09-24 19:43:37.568934481+00:00,160,1,432669,A,A,64.84,2,26,8058566376166,128,18506,94396918,CLX5
2025-09-24 19:43:38.582285719+00:00,160,1,432669,A,B,64.8,2,26,8058566376197,128,17645,94396977,CLX5
2025-09-24 19:43:38.582933365+00:00,160,1,432669,A,B,64.8,1,26,8058566376211,128,14240,94397025,CLX5
2025-09-24 19:43:38.583662203+00:00,160,1,432669,A,A,64.83,1,26,8058566376217,128,14516,94397062,CLX5
2025-09-24 19:43:38.593566007+00:00,160,1,432669,M,B,64.79,35,26,8058566342993,128,18077,94397091,CLX5
2025-09-24 19:43:38.593727183+00:00,160,1,432669,A,B,64.8,2,26,8058566376233,128,20405,94397092,CLX5
2025-09-24 19:43:38.593729623+00:00,160,1,432669,A,B,64.8,1,26,8058566376234,128,17226,94397093,CLX5
2025-09-24 19:43:38.594318481+00:00,160,1,432669,A,B,64.77,1,26,8058566376237,128,17576,94397097,CLX5
2025-09-24 19:43:38.594442813+00:00,160,1,432669,A,B,64.8,2,26,8058566376239,128,20574,94397099,CLX5
2025-09-24 19:43:38.594442989+00:00,160,1,432669,A,B,64.8,1,26,8058566376240,128,16039,94397100,CLX5
2025-09-24 19:43:38.594584483+00:00,160,1,432669,A,B,64.8,1,26,8058566376247,128,18781,94397116,CLX5
2025-09-24 19:43:38.624391571+00:00,160,1,432669,M,B,64.68,1,26,8058566194413,128,17537,94397212,CLX5
2025-09-24 19:43:38.680056655+00:00,160,1,432669,C,B,63.24,1,26,8058566376164,128,18120,94397220,CLX5
2025-09-24 19:43:38.765164155+00:00,160,1,432669,C,A,64.83,1,26,8058566376217,128,18052,94397247,CLX5
2025-09-24 19:43:38.767157757+00:00,160,1,432669,A,B,64.55,1,26,8058566376294,128,18068,94397248,CLX5
2025-09-24 19:43:39.600008719+00:00,160,1,432669,C,B,64.8,1,26,8058566376211,128,23248,94397271,CLX5
2025-09-24 19:43:40.023450829+00:00,160,1,432669,A,A,64.85,1,26,8058566376307,128,21603,94397273,CLX5
2025-09-24 19:43:42.712815313+00:00,160,1,432669,A,B,64.76,2,26,8058566376344,128,22060,94397445,CLX5
2025-09-24 19:43:43.033342977+00:00,160,1,432669,C,B,64.76,2,26,8058566376344,128,22658,94397480,CLX5
2025-09-24 19:43:43.212816215+00:00,160,1,432669,A,B,64.76,2,26,8058566376385,128,20012,94397557,CLX5
2025-09-24 19:43:43.499485485+00:00,160,1,432669,T,A,64.8,1,26,8058566376391,0,21006,94397564,CLX5
2025-09-24 19:43:43.499485485+00:00,160,1,432669,F,B,64.8,1,26,8058566376197,0,21006,94397564,CLX5
2025-09-24 19:43:43.499485485+00:00,160,1,432669,M,B,64.8,1,26,8058566376197,128,17850,94397565,CLX5
2025-09-24 19:43:43.499801735+00:00,160,1,432669,C,B,64.8,1,26,8058566376247,128,18343,94397570,CLX5
2025-09-24 19:43:43.499801883+00:00,160,1,432669,C,B,64.8,1,26,8058566376240,128,20620,94397571,CLX5
2025-09-24 19:43:43.509924353+00:00,160,1,432669,A,B,64.8,1,26,8058566376399,128,22126,94397582,CLX5
2025-09-24 19:43:44.895197771+00:00,160,1,432669,A,A,65.0,1,26,8058566376405,128,18552,94397617,CLX5
2025-09-24 19:43:46.329530539+00:00,160,1,432669,T,A,64.8,1,26,8058566376412,0,17491,94397655,CLX5
2025-09-24 19:43:46.329530539+00:00,160,1,432669,F,B,64.8,1,26,8058566376197,0,17491,94397655,CLX5
2025-09-24 19:43:46.329530539+00:00,160,1,432669,C,B,64.8,1,26,8058566376197,128,16116,94397656,CLX5
2025-09-24 19:43:46.355451103+00:00,160,1,432669,C,B,64.8,1,26,8058566376399,128,19912,94397676,CLX5
2025-09-24 19:43:46.355623473+00:00,160,1,432669,C,B,64.8,1,26,8058566376234,128,16497,94397678,CLX5
2025-09-24 19:43:46.517066693+00:00,160,1,432669,C,B,64.78,1,26,8058566374469,128,19163,94397795,CLX5
2025-09-24 19:43:46.517071299+00:00,160,1,432669,C,B,64.77,1,26,8058566374682,128,14375,94397796,CLX5
2025-09-24 19:43:46.517079747+00:00,160,1,432669,C,B,64.78,1,26,8058566373651,128,14196,94397797,CLX5
2025-09-24 19:43:46.517276883+00:00,160,1,432669,C,B,64.77,1,26,8058566374654,128,17657,94397798,CLX5
2025-09-24 19:43:46.689120093+00:00,160,1,432669,A,B,64.8,2,26,8058566376475,128,21270,94397840,CLX5
2025-09-24 19:43:46.748466459+00:00,160,1,432669,T,A,64.8,2,26,8058566376478,0,18311,94397845,CLX5
2025-09-24 19:43:46.748466459+00:00,160,1,432669,F,B,64.8,2,26,8058566376233,0,18311,94397845,CLX5
2025-09-24 19:43:46.748466459+00:00,160,1,432669,C,B,64.8,2,26,8058566376233,128,17238,94397846,CLX5
2025-09-24 19:43:46.748728757+00:00,160,1,432669,C,B,64.8,2,26,8058566376239,128,17773,94397847,CLX5
2025-09-24 19:43:46.749445749+00:00,160,1,432669,C,B,64.8,2,26,8058566376475,128,17961,94397853,CLX5
2025-09-24 19:43:46.749598133+00:00,160,1,432669,C,B,64.55,1,26,8058566376294,128,19647,94397856,CLX5
2025-09-24 19:43:46.749636703+00:00,160,1,432669,A,A,64.81,1,26,8058566376482,128,14884,94397858,CLX5
2025-09-24 19:43:46.749719319+00:00,160,1,432669,A,A,64.81,1,26,8058566376483,128,18274,94397859,CLX5
2025-09-24 19:43:46.749797765+00:00,160,1,432669,A,A,64.81,1,26,8058566376484,128,14823,94397860,CLX5
2025-09-24 19:43:46.750194173+00:00,160,1,432669,C,B,64.77,1,26,8058566376237,128,13767,94397866,CLX5
2025-09-24 19:43:46.750197283+00:00,160,1,432669,A,A,64.83,1,26,8058566376486,128,15203,94397867,CLX5
2025-09-24 19:43:46.880083467+00:00,160,1,432669,A,B,63.24,1,26,8058566376516,128,18207,94397950,CLX5
2025-09-24 19:43:47.070185069+00:00,160,1,432669,C,A,64.81,1,26,8058566376484,128,18460,94397986,CLX5
2025-09-24 19:43:47.070192213+00:00,160,1,432669,C,A,64.81,1,26,8058566376483,128,14412,94397987,CLX5
2025-09-24 19:43:47.070202637+00:00,160,1,432669,C,A,64.81,1,26,8058566376482,128,14595,94397988,CLX5
2025-09-24 19:43:47.623225673+00:00,160,1,432669,A,B,64.77,1,26,8058566376562,128,18533,94398002,CLX5
2025-09-24 19:43:48.329595359+00:00,160,1,432669,T,A,64.79,1,26,8058566376572,0,18230,94398030,CLX5
2025-09-24 19:43:48.329595359+00:00,160,1,432669,F,B,64.79,1,26,8058564363614,0,18230,94398030,CLX5
2025-09-24 19:43:48.329595359+00:00,160,1,432669,M,B,64.79,2,26,8058564363614,128,14946,94398031,CLX5
2025-09-24 19:43:49.004005349+00:00,160,1,432669,C,A,64.83,1,26,8058566376486,128,15713,94398076,CLX5
2025-09-24 19:43:49.004007865+00:00,160,1,432669,A,B,64.77,1,26,8058566376586,128,18410,94398077,CLX5
2025-09-24 19:43:49.004192329+00:00,160,1,432669,A,B,64.8,2,26,8058566376588,128,16939,94398081,CLX5
2025-09-24 19:43:49.052596389+00:00,160,1,432669,T,A,64.8,1,26,8058566376605,0,19681,94398160,CLX5
2025-09-24 19:43:49.052596389+00:00,160,1,432669,F,B,64.8,1,26,8058566376588,0,19681,94398160,CLX5
2025-09-24 19:43:49.052596389+00:00,160,1,432669,M,B,64.8,1,26,8058566376588,128,16132,94398161,CLX5
2025-09-24 19:43:49.080523075+00:00,160,1,432669,C,B,63.24,1,26,8058566376516,128,19022,94398170,CLX5
2025-09-24 19:43:49.167238237+00:00,160,1,432669,A,B,64.55,1,26,8058566376609,128,18852,94398179,CLX5
2025-09-24 19:43:49.208918061+00:00,160,1,432669,C,B,64.8,1,26,8058566376588,128,18413,94398183,CLX5
2025-09-24 19:43:49.209075803+00:00,160,1,432669,C,B,64.55,1,26,8058566376609,128,16136,94398186,CLX5
2025-09-24 19:43:49.209110437+00:00,160,1,432669,A,A,64.81,1,26,8058566376612,128,14523,94398187,CLX5
2025-09-24 19:43:49.209200981+00:00,160,1,432669,A,A,64.81,1,26,8058566376613,128,18146,94398188,CLX5
2025-09-24 19:43:49.209265701+00:00,160,1,432669,A,A,64.81,1,26,8058566376614,128,14423,94398189,CLX5
2025-09-24 19:43:49.255220235+00:00,160,1,432669,C,B,64.77,1,26,8058566376586,128,18253,94398246,CLX5
2025-09-24 19:43:49.300040697+00:00,160,1,432669,A,B,64.77,1,26,8058566376626,128,18490,94398248,CLX5
2025-09-24 19:43:49.380084805+00:00,160,1,432669,A,B,63.24,1,26,8058566376633,128,18722,94398256,CLX5
2025-09-24 19:43:49.497128871+00:00,160,1,432669,M,A,65.03,1,26,8058566376405,128,18680,94398265,CLX5
2025-09-24 19:43:49.497287399+00:00,160,1,432669,C,A,64.81,1,26,8058566376614,128,18071,94398266,CLX5
2025-09-24 19:43:49.835526555+00:00,160,1,432669,A,B,64.77,1,26,8058566376645,128,20522,94398272,CLX5
2025-09-24 19:43:53.374685609+00:00,160,1,432669,C,B,64.79,1,26,8058566375931,128,29156,94398337,CLX5
2025-09-24 19:43:53.707150019+00:00,160,1,432669,C,A,64.81,1,26,8058566376613,128,25345,94398338,CLX5
2025-09-24 19:43:53.707164725+00:00,160,1,432669,C,A,64.81,1,26,8058566376612,128,17375,94398339,CLX5
2025-09-24 19:43:54.386254919+00:00,160,1,432669,A,B,64.79,1,26,8058566376669,128,19200,94398353,CLX5
2025-09-24 19:43:54.876986565+00:00,160,1,432669,C,B,64.76,2,26,8058566376385,128,14677,94398369,CLX5
2025-09-24 19:43:55.588750877+00:00,160,1,432669,M,B,64.77,35,26,8058566342993,128,18808,94398400,CLX5
2025-09-24 19:43:55.589438091+00:00,160,1,432669,A,A,64.8,2,26,8058566376682,128,18169,94398413,CLX5
2025-09-24 19:43:55.589647977+00:00,160,1,432669,T,B,64.8,1,26,8058566376683,0,17830,94398422,CLX5
2025-09-24 19:43:55.589647977+00:00,160,1,432669,F,A,64.8,1,26,8058566376682,0,17830,94398422,CLX5
2025-09-24 19:43:55.589647977+00:00,160,1,432669,M,A,64.8,1,26,8058566376682,128,15049,94398423,CLX5
2025-09-24 19:43:55.589683957+00:00,160,1,432669,T,B,64.8,1,26,8058566376688,0,18004,94398444,CLX5
2025-09-24 19:43:55.589683957+00:00,160,1,432669,F,A,64.8,1,26,8058566376682,0,18004,94398444,CLX5
2025-09-24 19:43:55.589683957+00:00,160,1,432669,C,A,64.8,1,26,8058566376682,128,15087,94398445,CLX5
2025-09-24 19:43:55.589688181+00:00,160,1,432669,C,B,64.77,1,26,8058566376626,128,13667,94398450,CLX5
2025-09-24 19:43:55.589690849+00:00,160,1,432669,A,A,64.83,1,26,8058566376690,128,14575,94398451,CLX5
2025-09-24 19:43:55.589786191+00:00,160,1,432669,M,A,64.8,1,26,8058566376307,128,18536,94398453,CLX5
2025-09-24 19:43:55.589886623+00:00,160,1,432669,M,A,64.82,4,26,8058566376042,128,16667,94398456,CLX5
2025-09-24 19:43:55.589936309+00:00,160,1,432669,C,A,64.81,1,26,8058566376054,128,15161,94398457,CLX5
2025-09-24 19:43:55.590016773+00:00,160,1,432669,T,B,64.8,1,26,8058566376695,0,15168,94398467,CLX5
2025-09-24 19:43:55.590016773+00:00,160,1,432669,F,A,64.8,1,26,8058566376307,0,15168,94398467,CLX5
2025-09-24 19:43:55.590016773+00:00,160,1,432669,C,A,64.8,1,26,8058566376307,128,15168,94398467,CLX5
2025-09-24 19:43:55.590625001+00:00,160,1,432669,C,A,64.82,4,26,8058566376042,128,14801,94398498,CLX5
2025-09-24 19:43:55.590758629+00:00,160,1,432669,A,B,64.8,1,26,8058566376706,128,16466,94398503,CLX5
2025-09-24 19:43:55.590792323+00:00,160,1,432669,A,A,64.81,1,26,8058566376707,128,15202,94398505,CLX5
2025-09-24 19:43:55.590980187+00:00,160,1,432669,A,B,64.8,2,26,8058566376713,128,18099,94398516,CLX5
2025-09-24 19:43:55.591300103+00:00,160,1,432669,C,A,64.81,1,26,8058566376707,128,14661,94398546,CLX5
2025-09-24 19:43:55.591477753+00:00,160,1,432669,A,B,64.79,4,26,8058566376723,128,14713,94398558,CLX5
2025-09-24 19:43:55.592918359+00:00,160,1,432669,A,B,64.8,1,26,8058566376731,128,23123,94398593,CLX5
2025-09-24 19:43:55.593471851+00:00,160,1,432669,A,B,64.77,1,26,8058566376738,128,18113,94398621,CLX5
2025-09-24 19:43:55.593523729+00:00,160,1,432669,A,B,64.8,2,26,8058566376739,128,17546,94398628,CLX5
2025-09-24 19:43:55.603925235+00:00,160,1,432669,A,A,65.95,3,26,8058566376748,128,17849,94398673,CLX5
2025-09-24 19:43:55.680122371+00:00,160,1,432669,C,B,63.24,1,26,8058566376633,128,17836,94398711,CLX5
2025-09-24 19:43:55.690288457+00:00,160,1,432669,A,B,64.8,2,26,8058566376766,128,15732,94398720,CLX5
2025-09-24 19:43:55.690455795+00:00,160,1,432669,A,B,64.8,1,26,8058566376767,128,19220,94398722,CLX5
2025-09-24 19:43:55.741329213+00:00,160,1,432669,A,A,66.16,4,26,8058566376804,128,14061,94398790,CLX5
2025-09-24 19:43:55.765255675+00:00,160,1,432669,C,A,64.83,1,26,8058566376690,128,17750,94398800,CLX5
2025-09-24 19:43:55.767254135+00:00,160,1,432669,A,B,64.55,1,26,8058566376809,128,18082,94398804,CLX5
2025-09-24 19:43:56.472523313+00:00,160,1,432669,A,B,64.78,1,26,8058566376838,128,18459,94398857,CLX5
2025-09-24 19:43:56.716797413+00:00,160,1,432669,A,A,64.81,1,26,8058566376844,128,18429,94398865,CLX5
2025-09-24 19:43:56.719822087+00:00,160,1,432669,A,A,64.81,1,26,8058566376850,128,17981,94398904,CLX5
2025-09-24 19:43:56.923306935+00:00,160,1,432669,C,B,64.8,2,26,8058566376766,128,16402,94398919,CLX5
2025-09-24 19:43:56.923458187+00:00,160,1,432669,C,B,64.8,2,26,8058566376739,128,20229,94398928,CLX5
2025-09-24 19:43:56.941309483+00:00,160,1,432669,C,A,66.16,4,26,8058566376804,128,18359,94398937,CLX5
2025-09-24 19:43:57.578734731+00:00,160,1,432669,A,B,64.78,1,26,8058566376877,128,17753,94398957,CLX5
2025-09-24 19:43:57.656712917+00:00,160,1,432669,C,B,64.8,1,26,8058566376731,128,20376,94398958,CLX5
2025-09-24 19:43:58.489169207+00:00,160,1,432669,T,A,64.8,1,26,8058566376881,0,18574,94398972,CLX5
2025-09-24 19:43:58.489169207+00:00,160,1,432669,F,B,64.8,1,26,8058566376706,0,18574,94398972,CLX5
2025-09-24 19:43:58.489169207+00:00,160,1,432669,C,B,64.8,1,26,8058566376706,128,14213,94398973,CLX5
2025-09-24 19:44:00.172021037+00:00,160,1,432669,A,B,64.8,2,26,8058566376889,128,22110,94398999,CLX5
2025-09-24 19:44:00.341328115+00:00,160,1,432669,A,A,66.16,4,26,8058566376891,128,17871,94399003,CLX5
2025-09-24 19:44:00.460831571+00:00,160,1,432669,C,B,64.79,1,26,8058566376669,128,17312,94399005,CLX5
2025-09-24 19:44:00.823550607+00:00,160,1,432669,M,A,64.93,1,26,8058566376405,128,17708,94399123,CLX5
2025-09-24 19:44:01.356525311+00:00,160,1,432669,A,B,64.8,1,26,8058566376939,128,19365,94399152,CLX5
2025-09-24 19:44:01.681542913+00:00,160,1,432669,A,B,64.8,1,26,8058566376971,128,20062,94399247,CLX5
2025-09-24 19:44:01.681703361+00:00,160,1,432669,A,B,64.8,1,26,8058566376972,128,19233,94399248,CLX5
2025-09-24 19:44:01.712895743+00:00,160,1,432669,A,B,64.76,2,26,8058566376979,128,17914,94399257,CLX5
2025-09-24 19:44:02.422397925+00:00,160,1,432669,A,B,64.8,2,26,8058566377029,128,24843,94399360,CLX5
2025-09-24 19:44:02.484017955+00:00,160,1,432669,A,B,64.8,1,26,8058566377032,128,22686,94399370,CLX5
2025-09-24 19:44:02.664841509+00:00,160,1,432669,A,B,64.79,1,26,8058566377034,128,21885,94399372,CLX5
2025-09-24 19:44:04.051092925+00:00,160,1,432669,C,A,65.08,1,26,8058566372244,128,18217,94399512,CLX5
2025-09-24 19:44:04.113615157+00:00,160,1,432669,A,A,65.06,1,26,8058566377073,128,20459,94399513,CLX5
2025-09-24 19:44:04.646740883+00:00,160,1,432669,C,A,65.06,1,26,8058566372245,128,23483,94399529,CLX5
2025-09-24 19:44:04.740548789+00:00,160,1,432669,A,A,65.04,1,26,8058566377079,128,22779,94399531,CLX5
2025-09-24 19:44:04.960979331+00:00,160,1,432669,C,A,65.08,1,26,8058566372242,128,24423,94399533,CLX5
2025-09-24 19:44:05.023430643+00:00,160,1,432669,C,A,65.05,1,26,8058566372246,128,21031,94399535,CLX5
2025-09-24 19:44:05.054996181+00:00,160,1,432669,A,A,65.06,1,26,8058566377080,128,21795,94399537,CLX5
2025-09-24 19:44:05.465311513+00:00,160,1,432669,T,A,64.8,1,26,8058566377081,0,25097,94399539,CLX5
2025-09-24 19:44:05.465311513+00:00,160,1,432669,F,B,64.8,1,26,8058566376713,0,25097,94399539,CLX5
2025-09-24 19:44:05.465311513+00:00,160,1,432669,M,B,64.8,1,26,8058566376713,128,18080,94399540,CLX5
2025-09-24 19:44:05.465736543+00:00,160,1,432669,T,A,64.8,1,26,8058566377084,0,17750,94399545,CLX5
2025-09-24 19:44:05.465736543+00:00,160,1,432669,F,B,64.8,1,26,8058566376713,0,17750,94399545,CLX5
2025-09-24 19:44:05.465736543+00:00,160,1,432669,C,B,64.8,1,26,8058566376713,128,18806,94399546,CLX5
2025-09-24 19:44:05.465851201+00:00,160,1,432669,A,A,64.85,2,26,8058566377086,128,14580,94399548,CLX5
2025-09-24 19:44:05.466568825+00:00,160,1,432669,C,B,64.8,2,26,8058566377029,128,15562,94399594,CLX5
2025-09-24 19:44:05.541587673+00:00,160,1,432669,C,A,66.16,4,26,8058566376891,128,17931,94399615,CLX5
2025-09-24 19:44:05.652058965+00:00,160,1,432669,M,B,64.61,1,26,8058566375658,128,18419,94399624,CLX5
2025-09-24 19:44:05.688172877+00:00,160,1,432669,C,B,64.8,2,26,8058566376889,128,20062,94399701,CLX5
2025-09-24 19:44:05.688732841+00:00,160,1,432669,C,B,64.8,1,26,8058566376972,128,17068,94399723,CLX5
2025-09-24 19:44:05.690149969+00:00,160,1,432669,C,B,64.77,1,26,8058566376738,128,17878,94399776,CLX5
2025-09-24 19:44:05.690152983+00:00,160,1,432669,A,A,64.83,1,26,8058566377125,128,14594,94399777,CLX5
2025-09-24 19:44:05.998231209+00:00,160,1,432669,C,A,64.83,1,26,8058566377125,128,16388,94399861,CLX5
2025-09-24 19:44:05.998232745+00:00,160,1,432669,A,B,64.77,1,26,8058566377167,128,14391,94399862,CLX5
2025-09-24 19:44:05.998521633+00:00,160,1,432669,A,B,64.8,1,26,8058566377169,128,22378,94399866,CLX5
2025-09-24 19:44:05.998619281+00:00,160,1,432669,A,B,64.8,2,26,8058566377171,128,15657,94399869,CLX5
2025-09-24 19:44:06.065795735+00:00,160,1,432669,C,B,64.8,2,26,8058566377171,128,19878,94399890,CLX5
2025-09-24 19:44:06.338886441+00:00,160,1,432669,C,B,64.8,1,26,8058566377032,128,21833,94399913,CLX5
2025-09-24 19:44:06.378297675+00:00,160,1,432669,C,B,64.8,1,26,8058566377169,128,17482,94399918,CLX5
2025-09-24 19:44:06.867055519+00:00,160,1,432669,M,A,65.03,1,26,8058566376405,128,19045,94399932,CLX5
2025-09-24 19:44:06.869072815+00:00,160,1,432669,A,B,64.8,1,26,8058566377198,128,18445,94399935,CLX5
2025-09-24 19:44:06.869073463+00:00,160,1,432669,A,B,64.8,2,26,8058566377199,128,21023,94399936,CLX5
2025-09-24 19:44:06.869073733+00:00,160,1,432669,A,B,64.8,2,26,8058566377200,128,14839,94399937,CLX5
2025-09-24 19:44:06.869073925+00:00,160,1,432669,A,B,64.8,1,26,8058566377201,128,15993,94399938,CLX5
2025-09-24 19:44:06.869075689+00:00,160,1,432669,A,B,64.8,1,26,8058566377203,128,19687,94399940,CLX5
2025-09-24 19:44:06.869311745+00:00,160,1,432669,A,B,64.8,1,26,8058566377206,128,14824,94399945,CLX5
2025-09-24 19:44:06.869321563+00:00,160,1,432669,A,B,64.8,1,26,8058566377207,128,14759,94399947,CLX5
2025-09-24 19:44:06.869337759+00:00,160,1,432669,C,B,64.79,1,26,8058566375595,128,14594,94399948,CLX5
2025-09-24 19:44:06.869423393+00:00,160,1,432669,T,B,64.81,1,26,8058566377211,0,17762,94399956,CLX5
2025-09-24 19:44:06.869423393+00:00,160,1,432669,F,A,64.81,1,26,8058566372384,0,17762,94399956,CLX5
2025-09-24 19:44:06.869423393+00:00,160,1,432669,C,A,64.81,1,26,8058566372384,128,14696,94399957,CLX5
2025-09-24 19:44:06.869425133+00:00,160,1,432669,C,A,64.84,2,26,8058566373402,128,17700,94399963,CLX5
2025-09-24 19:44:06.869425877+00:00,160,1,432669,C,A,64.85,2,26,8058566370305,128,17822,94399966,CLX5
2025-09-24 19:44:06.869437709+00:00,160,1,432669,C,A,64.81,2,26,8058566373257,128,14648,94399978,CLX5
2025-09-24 19:44:06.869437883+00:00,160,1,432669,A,B,64.8,2,26,8058566377214,128,14890,94399979,CLX5
2025-09-24 19:44:06.869440593+00:00,160,1,432669,A,B,64.8,1,26,8058566377218,128,15241,94399988,CLX5
2025-09-24 19:44:06.869446867+00:00,160,1,432669,C,A,64.81,2,26,8058566372433,128,13617,94400012,CLX5
2025-09-24 19:44:06.869447015+00:00,160,1,432669,C,A,64.81,1,26,8058566372434,128,14620,94400014,CLX5
2025-09-24 19:44:06.869447165+00:00,160,1,432669,A,B,64.8,2,26,8058566377227,128,18361,94400015,CLX5
2025-09-24 19:44:06.869447521+00:00,160,1,432669,C,A,64.81,2,26,8058566373494,128,13653,94400017,CLX5
2025-09-24 19:44:06.869481887+00:00,160,1,432669,A,B,64.8,1,26,8058566377243,128,15165,94400057,CLX5
2025-09-24 19:44:06.869525333+00:00,160,1,432669,C,B,64.8,1,26,8058566377207,128,15281,94400072,CLX5
2025-09-24 19:44:06.869562043+00:00,160,1,432669,C,A,64.81,3,26,8058566372746,128,14377,94400081,CLX5
2025-09-24 19:44:06.869763731+00:00,160,1,432669,A,B,64.8,1,26,8058566377252,128,14860,94400093,CLX5
2025-09-24 19:44:06.870055653+00:00,160,1,432669,A,B,64.79,2,26,8058566377256,128,13441,94400107,CLX5
2025-09-24 19:44:06.870062469+00:00,160,1,432669,C,B,64.76,2,26,8058566376979,128,17836,94400108,CLX5
2025-09-24 19:44:06.870208129+00:00,160,1,432669,C,B,64.8,2,26,8058566377214,128,14974,94400118,CLX5
2025-09-24 19:44:06.872428439+00:00,160,1,432669,M,B,64.8,1,26,8058566374657,128,19117,94400188,CLX5
2025-09-24 19:44:06.873323771+00:00,160,1,432669,M,A,64.94,1,26,8058565075241,128,14568,94400252,CLX5
2025-09-24 19:44:06.873358907+00:00,160,1,432669,M,B,64.8,2,26,8058566365565,128,17205,94400254,CLX5
2025-09-24 19:44:06.873527553+00:00,160,1,432669,M,B,64.8,1,26,8058566319508,128,13583,94400262,CLX5
2025-09-24 19:44:06.874123821+00:00,160,1,432669,A,B,64.78,1,26,8058566377312,128,17768,94400300,CLX5
2025-09-24 19:44:06.877937221+00:00,160,1,432669,A,B,64.8,1,26,8058566377358,128,17872,94400438,CLX5
2025-09-24 19:44:06.879020871+00:00,160,1,432669,A,B,64.8,1,26,8058566377365,128,14697,94400467,CLX5
2025-09-24 19:44:06.879153481+00:00,160,1,432669,A,B,64.8,1,26,8058566377367,128,18192,94400469,CLX5
2025-09-24 19:44:06.880175739+00:00,160,1,432669,A,B,64.8,1,26,8058566377375,128,17991,94400498,CLX5
2025-09-24 19:44:06.880661401+00:00,160,1,432669,A,A,64.81,1,26,8058566377377,128,15026,94400507,CLX5
2025-09-24 19:44:06.881595361+00:00,160,1,432669,A,A,64.82,1,26,8058566377383,128,14601,94400592,CLX5
2025-09-24 19:44:06.883811771+00:00,160,1,432669,C,B,64.8,1,26,8058566377358,128,14546,94400728,CLX5
2025-09-24 19:44:06.892886557+00:00,160,1,432669,M,A,64.82,1,26,8058566371664,128,18866,94400871,CLX5
2025-09-24 19:44:06.903410553+00:00,160,1,432669,A,A,64.85,2,26,8058566377437,128,18045,94400888,CLX5
2025-09-24 19:44:06.903414585+00:00,160,1,432669,A,A,64.86,2,26,8058566377438,128,14616,94400889,CLX5
2025-09-24 19:44:06.913030805+00:00,160,1,432669,C,B,64.77,2,26,8058566373432,128,18490,94400909,CLX5
2025-09-24 19:44:06.939574961+00:00,160,1,432669,M,A,64.81,1,26,8058566371664,128,18320,94401053,CLX5
2025-09-24 19:44:06.965449543+00:00,160,1,432669,A,B,64.8,1,26,8058566377478,128,14974,94401082,CLX5
2025-09-24 19:44:06.971442347+00:00,160,1,432669,C,B,64.8,1,26,8058566377478,128,18233,94401085,CLX5
2025-09-24 19:44:06.976804133+00:00,160,1,432669,A,B,64.8,1,26,8058566377487,128,18201,94401096,CLX5
2025-09-24 19:44:06.976944997+00:00,160,1,432669,C,B,64.8,1,26,8058566377487,128,18227,94401097,CLX5
2025-09-24 19:44:07.003119969+00:00,160,1,432669,A,B,64.8,1,26,8058566377514,128,18926,94401144,CLX5
2025-09-24 19:44:07.036476251+00:00,160,1,432669,C,B,64.8,1,26,8058566377514,128,17034,94401204,CLX5
2025-09-24 19:44:07.041656145+00:00,160,1,432669,A,A,66.16,4,26,8058566377560,128,14367,94401218,CLX5
2025-09-24 19:44:07.296046283+00:00,160,1,432669,T,N,64.8,6,26,0,0,18337,94401427,CLX5
2025-09-24 19:44:07.296046283+00:00,160,1,432669,F,N,64.8,1,26,8058566376767,0,18337,94401427,CLX5
2025-09-24 19:44:07.296046283+00:00,160,1,432669,F,N,64.8,1,26,8058566376939,0,18337,94401427,CLX5
2025-09-24 19:44:07.296046283+00:00,160,1,432669,F,N,64.8,1,26,8058566376971,0,18337,94401427,CLX5
2025-09-24 19:44:07.296046283+00:00,160,1,432669,F,N,64.8,1,26,8058566377198,0,18337,94401427,CLX5
2025-09-24 19:44:07.296046283+00:00,160,1,432669,F,N,64.8,2,26,8058566377199,0,18337,94401427,CLX5
2025-09-24 19:44:07.296046283+00:00,160,1,432669,C,B,64.8,1,26,8058566376767,0,16936,94401428,CLX5
2025-09-24 19:44:07.296046283+00:00,160,1,432669,C,B,64.8,1,26,8058566376939,0,16936,94401428,CLX5
2025-09-24 19:44:07.296046283+00:00,160,1,432669,C,B,64.8,1,26,8058566376971,0,16936,94401428,CLX5
2025-09-24 19:44:07.296046283+00:00,160,1,432669,C,B,64.8,1,26,8058566377198,0,16936,94401428,CLX5
2025-09-24 19:44:07.296046283+00:00,160,1,432669,C,B,64.8,2,26,8058566377199,128,16936,94401428,CLX5
2025-09-24 19:44:07.296681947+00:00,160,1,432669,C,B,64.8,2,26,8058566377227,128,15980,94401440,CLX5
2025-09-24 19:44:07.296731213+00:00,160,1,432669,C,B,64.8,1,26,8058566377206,128,16136,94401441,CLX5
2025-09-24 19:44:07.296732461+00:00,160,1,432669,C,B,64.8,2,26,8058566377200,128,20067,94401442,CLX5
2025-09-24 19:44:07.296732613+00:00,160,1,432669,C,B,64.8,1,26,8058566377201,128,16251,94401443,CLX5
2025-09-24 19:44:07.296733789+00:00,160,1,432669,A,A,64.81,1,26,8058566377678,128,14018,94401450,CLX5
2025-09-24 19:44:07.296824329+00:00,160,1,432669,A,A,64.81,1,26,8058566377686,128,18146,94401469,CLX5
2025-09-24 19:44:07.296954633+00:00,160,1,432669,C,A,64.81,1,26,8058566377686,128,14501,94401485,CLX5
2025-09-24 19:44:07.297090391+00:00,160,1,432669,A,B,64.8,1,26,8058566377695,128,15939,94401493,CLX5
2025-09-24 19:44:07.297139599+00:00,160,1,432669,C,B,64.8,1,26,8058566377218,128,16381,94401495,CLX5
2025-09-24 19:44:07.297357299+00:00,160,1,432669,M,B,63.63,3,26,8058566319508,128,16400,94401514,CLX5
2025-09-24 19:44:07.297440259+00:00,160,1,432669,M,A,64.93,1,26,8058565075241,128,15498,94401538,CLX5
2025-09-24 19:44:07.297470649+00:00,160,1,432669,A,A,64.81,1,26,8058566377704,128,14479,94401540,CLX5
2025-09-24 19:44:07.297546411+00:00,160,1,432669,C,A,64.81,1,26,8058566377704,128,14813,94401544,CLX5
2025-09-24 19:44:07.297593641+00:00,160,1,432669,C,B,64.77,1,26,8058566377167,128,18339,94401548,CLX5
2025-09-24 19:44:07.297909581+00:00,160,1,432669,A,B,64.8,1,26,8058566377714,128,16190,94401567,CLX5
2025-09-24 19:44:07.298592071+00:00,160,1,432669,A,B,64.77,1,26,8058566377719,128,17569,94401586,CLX5
2025-09-24 19:44:07.301413695+00:00,160,1,432669,A,B,64.8,2,26,8058566377735,128,15132,94401683,CLX5
2025-09-24 19:44:07.302252103+00:00,160,1,432669,A,B,64.8,2,26,8058566377741,128,14831,94401714,CLX5
2025-09-24 19:44:07.302252281+00:00,160,1,432669,A,B,64.8,1,26,8058566377742,128,18138,94401715,CLX5
2025-09-24 19:44:07.350579289+00:00,160,1,432669,A,B,64.8,1,26,8058566377767,128,19729,94401771,CLX5
2025-09-24 19:44:07.376663757+00:00,160,1,432669,C,B,64.79,2,26,8058566377256,128,17944,94401773,CLX5
2025-09-24 19:44:07.412974923+00:00,160,1,432669,A,B,64.77,2,26,8058566377773,128,17680,94401789,CLX5
2025-09-24 19:44:07.415139877+00:00,160,1,432669,A,B,64.8,1,26,8058566377775,128,20013,94401792,CLX5
2025-09-24 19:44:07.415288171+00:00,160,1,432669,C,A,64.81,1,26,8058566377678,128,13702,94401795,CLX5
2025-09-24 19:44:07.415292645+00:00,160,1,432669,C,B,64.8,1,26,8058566377775,128,15424,94401796,CLX5
2025-09-24 19:44:07.415383111+00:00,160,1,432669,A,B,64.79,2,26,8058566377778,128,13394,94401799,CLX5
2025-09-24 19:44:07.415463651+00:00,160,1,432669,M,A,64.94,1,26,8058565075241,128,12991,94401802,CLX5
2025-09-24 19:44:07.512981523+00:00,160,1,432669,C,B,64.77,2,26,8058566377773,128,18258,94401923,CLX5
2025-09-24 19:44:07.598084169+00:00,160,1,432669,A,B,64.8,1,26,8058566377845,128,18957,94401965,CLX5
2025-09-24 19:44:08.341454353+00:00,160,1,432669,M,B,64.76,35,26,8058566342993,128,17655,94402047,CLX5
2025-09-24 19:44:08.341634653+00:00,160,1,432669,C,B,64.78,1,26,8058566377312,128,18152,94402048,CLX5
2025-09-24 19:44:08.341795255+00:00,160,1,432669,C,B,64.78,1,26,8058566376877,128,17809,94402049,CLX5
2025-09-24 19:44:08.341943893+00:00,160,1,432669,C,B,64.78,1,26,8058566376838,128,17652,94402050,CLX5
2025-09-24 19:44:12.651263169+00:00,160,1,432669,T,A,64.8,1,26,8058566376844,0,19963,94402523,CLX5
2025-09-24 19:44:12.651263169+00:00,160,1,432669,F,A,64.8,1,26,8058566376844,0,19963,94402523,CLX5
2025-09-24 19:44:12.651263169+00:00,160,1,432669,F,B,64.8,1,26,8058566377203,0,19963,94402523,CLX5
2025-09-24 19:44:12.651263169+00:00,160,1,432669,C,B,64.8,1,26,8058566377203,0,16607,94402524,CLX5
2025-09-24 19:44:12.651263169+00:00,160,1,432669,C,A,64.81,1,26,8058566376844,128,16607,94402524,CLX5
2025-09-24 19:44:12.651399945+00:00,160,1,432669,T,A,64.8,1,26,8058566376850,0,16607,94402524,CLX5
2025-09-24 19:44:12.651399945+00:00,160,1,432669,F,A,64.8,1,26,8058566376850,0,16607,94402524,CLX5
2025-09-24 19:44:12.651399945+00:00,160,1,432669,F,B,64.8,1,26,8058566377243,0,16607,94402524,CLX5
2025-09-24 19:44:12.651399945+00:00,160,1,432669,C,B,64.8,1,26,8058566377243,0,16607,94402524,CLX5
2025-09-24 19:44:12.651399945+00:00,160,1,432669,C,A,64.81,1,26,8058566376850,128,16607,94402524,CLX5
2025-09-24 19:44:12.651579663+00:00,160,1,432669,C,B,64.8,2,26,8058566377741,128,16006,94402528,CLX5
2025-09-24 19:44:12.651579813+00:00,160,1,432669,C,B,64.8,1,26,8058566377742,128,15693,94402530,CLX5
2025-09-24 19:44:12.651982737+00:00,160,1,432669,A,B,63.99,1,26,8058566378050,128,16401,94402540,CLX5
2025-09-24 19:44:12.731753525+00:00,160,1,432669,A,B,62.8,1,26,8058566378066,128,16955,94402614,CLX5
2025-09-24 19:44:14.281342561+00:00,160,1,432669,A,B,64.8,1,26,8058566378105,128,20362,94402692,CLX5
2025-09-24 19:44:14.281526219+00:00,160,1,432669,A,A,64.81,1,26,8058566378106,128,17886,94402693,CLX5
2025-09-24 19:44:14.281584125+00:00,160,1,432669,A,B,64.8,1,26,8058566378107,128,18886,94402696,CLX5
2025-09-24 19:44:17.402012217+00:00,160,1,432669,C,B,64.8,1,26,8058566378107,128,15451,94402856,CLX5
2025-09-24 19:44:17.489692541+00:00,160,1,432669,A,B,64.78,1,26,8058566378152,128,18277,94402884,CLX5
2025-09-24 19:44:18.156104463+00:00,160,1,432669,A,B,64.8,1,26,8058566378155,128,20107,94402887,CLX5
2025-09-24 19:44:18.156308147+00:00,160,1,432669,A,B,64.8,1,26,8058566378157,128,14578,94402890,CLX5
2025-09-24 19:44:18.156485143+00:00,160,1,432669,A,B,64.8,2,26,8058566378158,128,19199,94402892,CLX5
2025-09-24 19:44:18.156485321+00:00,160,1,432669,A,B,64.8,1,26,8058566378159,128,16160,94402893,CLX5
2025-09-24 19:44:18.862933957+00:00,160,1,432669,A,B,64.75,1,26,8058566378200,128,19148,94403078,CLX5
2025-09-24 19:44:18.863117463+00:00,160,1,432669,C,B,64.79,1,26,8058566372615,128,18239,94403079,CLX5
2025-09-24 19:44:19.868266617+00:00,160,1,432669,C,B,64.8,1,26,8058566378157,128,25878,94403105,CLX5
2025-09-24 19:44:19.868277869+00:00,160,1,432669,A,B,64.79,1,26,8058566378213,128,17260,94403106,CLX5
2025-09-24 19:44:19.868661045+00:00,160,1,432669,C,B,64.8,1,26,8058566378155,128,23126,94403110,CLX5
2025-09-24 19:44:20.020717489+00:00,160,1,432669,A,A,64.81,1,26,8058566378223,128,18603,94403145,CLX5
2025-09-24 19:44:22.426589747+00:00,160,1,432669,A,B,64.8,1,26,8058566378243,128,22210,94403186,CLX5
2025-09-24 19:44:22.426877503+00:00,160,1,432669,A,B,64.8,1,26,8058566378244,128,15776,94403188,CLX5
2025-09-24 19:44:22.581760485+00:00,160,1,432669,C,B,64.79,1,26,8058566377034,128,19029,94403204,CLX5
2025-09-24 19:44:23.015824451+00:00,160,1,432669,C,B,64.8,1,26,8058566378244,128,19522,94403212,CLX5
2025-09-24 19:44:23.130142907+00:00,160,1,432669,A,B,64.8,1,26,8058566378252,128,18469,94403234,CLX5
2025-09-24 19:44:23.130332711+00:00,160,1,432669,A,B,64.8,1,26,8058566378255,128,14469,94403239,CLX5
2025-09-24 19:44:23.130500761+00:00,160,1,432669,C,B,64.8,1,26,8058566378252,128,14537,94403241,CLX5
2025-09-24 19:44:23.182830739+00:00,160,1,432669,C,B,64.79,1,26,8058566378213,128,17857,94403255,CLX5
2025-09-24 19:44:24.030703897+00:00,160,1,432669,M,B,64.77,35,26,8058566342993,128,18326,94403272,CLX5
2025-09-24 19:44:24.389799207+00:00,160,1,432669,C,B,64.79,2,26,8058566377778,128,20322,94403275,CLX5
2025-09-24 19:44:24.389805291+00:00,160,1,432669,C,B,64.8,1,26,8058566378255,128,15854,94403276,CLX5
2025-09-24 19:44:24.389812935+00:00,160,1,432669,A,B,64.79,1,26,8058566378269,128,17790,94403278,CLX5
2025-09-24 19:44:24.475440407+00:00,160,1,432669,A,B,64.79,2,26,8058566378271,128,18139,94403286,CLX5
2025-09-24 19:44:26.385212931+00:00,160,1,432669,C,B,64.8,1,26,8058566378159,128,15690,94403410,CLX5
2025-09-24 19:44:26.385337399+00:00,160,1,432669,C,B,64.8,2,26,8058566378158,128,18710,94403411,CLX5
2025-09-24 19:44:26.385468895+00:00,160,1,432669,A,B,64.8,1,26,8058566378313,128,15427,94403413,CLX5
2025-09-24 19:44:26.503289431+00:00,160,1,432669,C,A,64.81,1,26,8058566378106,128,14777,94403433,CLX5
2025-09-24 19:44:26.503296783+00:00,160,1,432669,C,A,64.85,2,26,8058566377437,128,14545,94403435,CLX5
2025-09-24 19:44:26.503298933+00:00,160,1,432669,T,B,64.81,1,26,8058566378327,0,18360,94403437,CLX5
2025-09-24 19:44:26.503298933+00:00,160,1,432669,F,A,64.81,1,26,8058566372398,0,18360,94403437,CLX5
2025-09-24 19:44:26.503298933+00:00,160,1,432669,C,A,64.81,1,26,8058566372398,128,18360,94403437,CLX5
2025-09-24 19:44:26.503316193+00:00,160,1,432669,A,B,64.8,3,26,8058566378341,128,18222,94403473,CLX5
2025-09-24 19:44:26.503317903+00:00,160,1,432669,A,B,64.8,1,26,8058566378342,128,15371,94403474,CLX5
2025-09-24 19:44:26.503323405+00:00,160,1,432669,A,B,64.8,2,26,8058566378344,128,17471,94403476,CLX5
2025-09-24 19:44:26.503356147+00:00,160,1,432669,A,B,64.8,2,26,8058566378353,128,14006,94403495,CLX5
2025-09-24 19:44:26.503378477+00:00,160,1,432669,C,A,64.81,1,26,8058566373380,128,15008,94403504,CLX5
2025-09-24 19:44:26.503606755+00:00,160,1,432669,C,A,64.81,1,26,8058566372466,128,14665,94403518,CLX5
2025-09-24 19:44:26.503810111+00:00,160,1,432669,A,B,64.77,1,26,8058566378367,128,15671,94403535,CLX5
2025-09-24 19:44:26.504254283+00:00,160,1,432669,T,B,64.81,4,26,8058566378377,0,14665,94403558,CLX5
2025-09-24 19:44:26.504254283+00:00,160,1,432669,F,A,64.81,2,26,8058566371432,0,14665,94403558,CLX5
2025-09-24 19:44:26.504254283+00:00,160,1,432669,F,A,64.81,2,26,8058566374339,0,14665,94403558,CLX5
2025-09-24 19:44:26.504254283+00:00,160,1,432669,C,A,64.81,2,26,8058566371432,0,15169,94403559,CLX5
2025-09-24 19:44:26.504254283+00:00,160,1,432669,M,A,64.81,48,26,8058566374339,128,15169,94403559,CLX5
2025-09-24 19:44:26.504687359+00:00,160,1,432669,C,B,64.78,1,26,8058566374540,128,16809,94403588,CLX5
2025-09-24 19:44:26.504690353+00:00,160,1,432669,C,B,64.75,2,26,8058566374676,128,14343,94403589,CLX5
2025-09-24 19:44:26.504949139+00:00,160,1,432669,A,A,64.81,1,26,8058566378387,128,14863,94403602,CLX5
2025-09-24 19:44:26.505047007+00:00,160,1,432669,A,B,64.8,2,26,8058566378391,128,14828,94403607,CLX5
2025-09-24 19:44:26.505051953+00:00,160,1,432669,C,A,64.81,1,26,8058566378387,128,14785,94403608,CLX5
2025-09-24 19:44:26.505258197+00:00,160,1,432669,M,B,64.8,1,26,8058566319508,128,18117,94403613,CLX5
2025-09-24 19:44:26.507189701+00:00,160,1,432669,A,A,64.81,1,26,8058566378416,128,13624,94403690,CLX5
2025-09-24 19:44:26.507192235+00:00,160,1,432669,T,B,64.81,52,26,8058566378417,0,14719,94403692,CLX5
2025-09-24 19:44:26.507192235+00:00,160,1,432669,F,A,64.81,48,26,8058566374339,0,14719,94403692,CLX5
2025-09-24 19:44:26.507192235+00:00,160,1,432669,F,A,64.81,1,26,8058566377377,0,14719,94403692,CLX5
2025-09-24 19:44:26.507192235+00:00,160,1,432669,F,A,64.81,1,26,8058566371664,0,14719,94403692,CLX5
2025-09-24 19:44:26.507192235+00:00,160,1,432669,F,A,64.81,1,26,8058566378223,0,14719,94403692,CLX5
2025-09-24 19:44:26.507192235+00:00,160,1,432669,F,A,64.81,1,26,8058566378416,0,14719,94403692,CLX5
2025-09-24 19:44:26.507192235+00:00,160,1,432669,C,A,64.81,48,26,8058566374339,0,19103,94403693,CLX5
2025-09-24 19:44:26.507192235+00:00,160,1,432669,C,A,64.81,1,26,8058566377377,0,19103,94403693,CLX5
2025-09-24 19:44:26.507192235+00:00,160,1,432669,C,A,64.81,1,26,8058566371664,0,19103,94403693,CLX5
2025-09-24 19:44:26.507192235+00:00,160,1,432669,C,A,64.81,1,26,8058566378223,0,19103,94403693,CLX5
2025-09-24 19:44:26.507192235+00:00,160,1,432669,C,A,64.81,1,26,8058566378416,128,19103,94403693,CLX5
2025-09-24 19:44:26.507216637+00:00,160,1,432669,A,B,64.8,3,26,8058566378418,128,15082,94403697,CLX5
2025-09-24 19:44:26.507635619+00:00,160,1,432669,A,B,64.8,3,26,8058566378423,128,17260,94403709,CLX5
2025-09-24 19:44:26.507988863+00:00,160,1,432669,C,B,64.78,1,26,8058566378152,128,14795,94403715,CLX5
2025-09-24 19:44:26.510218021+00:00,160,1,432669,A,B,64.81,1,26,8058566378429,128,15697,94403734,CLX5
2025-09-24 19:44:26.510236107+00:00,160,1,432669,A,A,64.82,1,26,8058566378457,128,18405,94403803,CLX5
2025-09-24 19:44:26.510259855+00:00,160,1,432669,M,B,64.8,1,26,8058566372953,128,14410,94403814,CLX5
2025-09-24 19:44:26.510361783+00:00,160,1,432669,C,A,64.82,1,26,8058566377383,128,15331,94403824,CLX5
2025-09-24 19:44:26.510562301+00:00,160,1,432669,A,B,64.81,3,26,8058566378464,128,14454,94403830,CLX5
2025-09-24 19:44:26.510634469+00:00,160,1,432669,A,B,64.81,2,26,8058566378466,128,18927,94403834,CLX5
2025-09-24 19:44:26.510733959+00:00,160,1,432669,A,B,64.8,1,26,8058566378470,128,14609,94403839,CLX5
2025-09-24 19:44:26.510864571+00:00,160,1,432669,A,B,64.81,1,26,8058566378472,128,15653,94403852,CLX5
2025-09-24 19:44:26.510925453+00:00,160,1,432669,C,A,64.84,1,26,8058566372739,128,14397,94403862,CLX5
2025-09-24 19:44:26.510928293+00:00,160,1,432669,A,B,64.78,1,26,8058566378476,128,18437,94403863,CLX5
2025-09-24 19:44:26.510992783+00:00,160,1,432669,C,B,64.81,3,26,8058566378464,128,14677,94403865,CLX5
2025-09-24 19:44:26.511090295+00:00,160,1,432669,A,B,64.81,1,26,8058566378480,128,18425,94403875,CLX5
2025-09-24 19:44:26.511160007+00:00,160,1,432669,A,B,64.81,1,26,8058566378482,128,14645,94403881,CLX5
2025-09-24 19:44:26.511263741+00:00,160,1,432669,A,A,64.86,2,26,8058566378484,128,14473,94403892,CLX5
2025-09-24 19:44:26.511306939+00:00,160,1,432669,C,B,64.81,2,26,8058566378466,128,21363,94403893,CLX5
2025-09-24 19:44:26.511307093+00:00,160,1,432669,C,B,64.81,1,26,8058566378472,128,15066,94403894,CLX5
2025-09-24 19:44:26.511327483+00:00,160,1,432669,A,A,64.82,1,26,8058566378486,128,14648,94403899,CLX5
2025-09-24 19:44:26.511441909+00:00,160,1,432669,M,A,65.97,4,26,8058566373687,128,14767,94403913,CLX5
2025-09-24 19:44:26.511508875+00:00,160,1,432669,C,B,64.81,1,26,8058566378480,128,16506,94403922,CLX5
2025-09-24 19:44:26.513208059+00:00,160,1,432669,M,B,64.8,1,26,8058566345944,128,14469,94403999,CLX5
2025-09-24 19:44:26.513671429+00:00,160,1,432669,A,A,64.82,1,26,8058566378506,128,14967,94404017,CLX5
2025-09-24 19:44:26.516531757+00:00,160,1,432669,M,A,64.83,1,26,8058566173085,128,15270,94404095,CLX5
2025-09-24 19:44:26.518803229+00:00,160,1,432669,A,A,65.7,6,26,8058566378543,128,13959,94404201,CLX5
2025-09-24 19:44:26.521919539+00:00,160,1,432669,T,A,64.81,1,26,8058566378582,0,13784,94404343,CLX5
2025-09-24 19:44:26.521919539+00:00,160,1,432669,F,B,64.81,1,26,8058566378429,0,13784,94404343,CLX5
2025-09-24 19:44:26.521919539+00:00,160,1,432669,C,B,64.81,1,26,8058566378429,128,13784,94404343,CLX5
2025-09-24 19:44:26.522402551+00:00,160,1,432669,A,A,64.82,1,26,8058566378588,128,18168,94404361,CLX5
2025-09-24 19:44:26.522404087+00:00,160,1,432669,T,A,64.81,2,26,8058566378590,0,18190,94404365,CLX5
2025-09-24 19:44:26.522404087+00:00,160,1,432669,F,B,64.81,1,26,8058566378482,0,18190,94404365,CLX5
2025-09-24 19:44:26.522404087+00:00,160,1,432669,C,B,64.81,1,26,8058566378482,128,18190,94404365,CLX5
2025-09-24 19:44:26.522721259+00:00,160,1,432669,A,A,64.82,1,26,8058566378596,128,14719,94404383,CLX5
2025-09-24 19:44:26.522826027+00:00,160,1,432669,A,A,64.82,1,26,8058566378598,128,18689,94404385,CLX5
2025-09-24 19:44:26.522878327+00:00,160,1,432669,A,A,64.82,1,26,8058566378599,128,14736,94404387,CLX5
2025-09-24 19:44:26.523091705+00:00,160,1,432669,C,B,64.8,1,26,8058566345944,128,13858,94404399,CLX5
2025-09-24 19:44:26.523122481+00:00,160,1,432669,A,A,64.81,1,26,8058566378603,128,18343,94404400,CLX5
2025-09-24 19:44:26.523334383+00:00,160,1,432669,C,B,64.79,4,26,8058566376723,128,15454,94404421,CLX5
2025-09-24 19:44:26.523702929+00:00,160,1,432669,T,B,64.81,1,26,8058566378609,0,17602,94404447,CLX5
2025-09-24 19:44:26.523702929+00:00,160,1,432669,F,A,64.81,1,26,8058566378603,0,17602,94404447,CLX5
2025-09-24 19:44:26.523702929+00:00,160,1,432669,C,A,64.81,1,26,8058566378603,128,14488,94404448,CLX5
2025-09-24 19:44:26.523845635+00:00,160,1,432669,M,A,64.81,2,26,8058566378484,128,18411,94404458,CLX5
2025-09-24 19:44:26.523981107+00:00,160,1,432669,M,A,64.83,3,26,8058566376748,128,16055,94404461,CLX5
2025-09-24 19:44:26.524092865+00:00,160,1,432669,T,B,64.81,1,26,8058566378613,0,14207,94404464,CLX5
2025-09-24 19:44:26.524092865+00:00,160,1,432669,F,A,64.81,1,26,8058566378484,0,14207,94404464,CLX5
2025-09-24 19:44:26.524092865+00:00,160,1,432669,M,A,64.81,1,26,8058566378484,128,18579,94404465,CLX5
2025-09-24 19:44:26.524747421+00:00,160,1,432669,T,B,64.81,1,26,8058566378622,0,14588,94404499,CLX5
2025-09-24 19:44:26.524747421+00:00,160,1,432669,F,A,64.81,1,26,8058566378484,0,14588,94404499,CLX5
2025-09-24 19:44:26.524747421+00:00,160,1,432669,C,A,64.81,1,26,8058566378484,128,14588,94404499,CLX5
2025-09-24 19:44:26.528171647+00:00,160,1,432669,A,A,64.82,1,26,8058566378647,128,18212,94404567,CLX5
2025-09-24 19:44:26.529992455+00:00,160,1,432669,A,A,65.95,3,26,8058566378650,128,17281,94404574,CLX5
2025-09-24 19:44:26.537564237+00:00,160,1,432669,C,A,64.82,1,26,8058566378599,128,18236,94404599,CLX5
2025-09-24 19:44:26.537719559+00:00,160,1,432669,C,A,64.82,1,26,8058566378598,128,18543,94404600,CLX5
2025-09-24 19:44:26.537862823+00:00,160,1,432669,C,A,64.82,1,26,8058566378596,128,17974,94404601,CLX5
2025-09-24 19:44:26.563007321+00:00,160,1,432669,A,A,64.85,2,26,8058566378683,128,14796,94404713,CLX5
2025-09-24 19:44:26.563133881+00:00,160,1,432669,C,B,64.77,1,26,8058566378367,128,18016,94404715,CLX5
2025-09-24 19:44:26.568438625+00:00,160,1,432669,A,A,65.96,4,26,8058566378696,128,17439,94404733,CLX5
2025-09-24 19:44:26.577415287+00:00,160,1,432669,A,A,64.82,1,26,8058566378700,128,18759,94404741,CLX5
2025-09-24 19:44:26.577567517+00:00,160,1,432669,A,A,64.82,1,26,8058566378701,128,17840,94404742,CLX5
2025-09-24 19:44:26.577726447+00:00,160,1,432669,A,A,64.82,1,26,8058566378702,128,17751,94404743,CLX5
2025-09-24 19:44:26.587204263+00:00,160,1,432669,T,A,64.8,1,26,8058566378704,0,17697,94404753,CLX5
2025-09-24 19:44:26.587204263+00:00,160,1,432669,F,B,64.8,1,26,8058566377252,0,17697,94404753,CLX5
2025-09-24 19:44:26.587204263+00:00,160,1,432669,C,B,64.8,1,26,8058566377252,128,14840,94404754,CLX5
2025-09-24 19:44:26.587467847+00:00,160,1,432669,A,A,64.81,2,26,8058566378706,128,14334,94404756,CLX5
2025-09-24 19:44:26.587591605+00:00,160,1,432669,C,B,64.8,3,26,8058566378423,128,14739,94404767,CLX5
2025-09-24 19:44:26.592584997+00:00,160,1,432669,A,A,64.81,1,26,8058566378716,128,17772,94404795,CLX5
2025-09-24 19:44:26.606875445+00:00,160,1,432669,A,A,64.81,1,26,8058566378729,128,14328,94404812,CLX5
2025-09-24 19:44:26.607111017+00:00,160,1,432669,C,A,64.82,1,26,8058566378702,128,14889,94404816,CLX5
2025-09-24 19:44:26.607121885+00:00,160,1,432669,C,A,64.82,1,26,8058566378701,128,14660,94404817,CLX5
2025-09-24 19:44:26.618855985+00:00,160,1,432669,C,A,65.7,6,26,8058566378543,128,17919,94404831,CLX5
2025-09-24 19:44:26.641490463+00:00,160,1,432669,A,B,64.78,1,26,8058566378744,128,18229,94404850,CLX5
2025-09-24 19:44:26.689077503+00:00,160,1,432669,A,B,64.8,3,26,8058566378785,128,17700,94404904,CLX5
2025-09-24 19:44:26.689218539+00:00,160,1,432669,C,B,64.78,1,26,8058566378476,128,17552,94404905,CLX5
2025-09-24 19:44:26.689224893+00:00,160,1,432669,C,A,64.81,1,26,8058566378716,128,14342,94404906,CLX5
2025-09-24 19:44:26.689251485+00:00,160,1,432669,C,A,64.82,1,26,8058566378700,128,13538,94404908,CLX5
2025-09-24 19:44:26.713078689+00:00,160,1,432669,A,B,64.76,2,26,8058566378804,128,17634,94404937,CLX5
2025-09-24 19:44:26.843591861+00:00,160,1,432669,A,B,64.79,3,26,8058566378878,128,18195,94405085,CLX5
2025-09-24 19:44:26.889400753+00:00,160,1,432669,A,B,64.8,1,26,8058566378890,128,18252,94405102,CLX5
2025-09-24 19:44:27.064770863+00:00,160,1,432669,A,B,64.8,1,26,8058566378925,128,18363,94405157,CLX5
2025-09-24 19:44:27.394436465+00:00,160,1,432669,C,B,64.8,1,26,8058566377767,128,18277,94405241,CLX5
2025-09-24 19:44:27.618824777+00:00,160,1,432669,A,A,65.7,6,26,8058566378992,128,18630,94405272,CLX5
2025-09-24 19:44:28.396838673+00:00,160,1,432669,T,A,64.8,1,26,8058566379001,0,17723,94405297,CLX5
2025-09-24 19:44:28.396838673+00:00,160,1,432669,F,B,64.8,1,26,8058566374657,0,17723,94405297,CLX5
2025-09-24 19:44:28.396838673+00:00,160,1,432669,C,B,64.8,1,26,8058566374657,128,16085,94405298,CLX5
2025-09-24 19:44:28.521786703+00:00,160,1,432669,M,A,64.92,1,26,8058566157942,128,18083,94405314,CLX5
2025-09-24 19:44:29.005986579+00:00,160,1,432669,M,A,64.88,3,26,8058566144143,128,20324,94405320,CLX5
2025-09-24 19:44:29.941442799+00:00,160,1,432669,A,A,64.81,1,26,8058566379025,128,14535,94405348,CLX5
2025-09-24 19:44:29.941442991+00:00,160,1,432669,A,A,64.81,2,26,8058566379026,128,13815,94405350,CLX5
2025-09-24 19:44:29.941623309+00:00,160,1,432669,A,A,64.81,1,26,8058566379028,128,19564,94405354,CLX5
2025-09-24 19:44:29.941628051+00:00,160,1,432669,A,A,64.81,1,26,8058566379029,128,16126,94405358,CLX5
2025-09-24 19:44:30.432589759+00:00,160,1,432669,C,A,64.81,1,26,8058566379028,128,20628,94405416,CLX5
2025-09-24 19:44:30.791122643+00:00,160,1,432669,A,A,64.81,1,26,8058566379046,128,20258,94405422,CLX5
2025-09-24 19:44:31.536221537+00:00,160,1,432669,C,B,64.8,1,26,8058566378243,128,20328,94405439,CLX5
2025-09-24 19:44:31.548164447+00:00,160,1,432669,T,B,64.81,1,26,8058566379052,0,17788,94405440,CLX5
2025-09-24 19:44:31.548164447+00:00,160,1,432669,F,A,64.81,1,26,8058566378706,0,17788,94405440,CLX5
2025-09-24 19:44:31.548164447+00:00,160,1,432669,M,A,64.81,1,26,8058566378706,128,17004,94405441,CLX5
2025-09-24 19:44:31.548470431+00:00,160,1,432669,T,B,64.81,2,26,8058566379057,0,17719,94405449,CLX5
2025-09-24 19:44:31.548470431+00:00,160,1,432669,F,A,64.81,1,26,8058566378706,0,17719,94405449,CLX5
2025-09-24 19:44:31.548470431+00:00,160,1,432669,F,A,64.81,1,26,8058566378729,0,17719,94405449,CLX5
2025-09-24 19:44:31.548470431+00:00,160,1,432669,C,A,64.81,1,26,8058566378706,0,18226,94405450,CLX5
2025-09-24 19:44:31.548470431+00:00,160,1,432669,C,A,64.81,1,26,8058566378729,128,18226,94405450,CLX5
2025-09-24 19:44:31.548644195+00:00,160,1,432669,M,A,64.81,2,26,8058566377086,128,15079,94405453,CLX5
2025-09-24 19:44:31.548740707+00:00,160,1,432669,A,A,64.85,1,26,8058566379062,128,17552,94405455,CLX5
2025-09-24 19:44:31.548880727+00:00,160,1,432669,T,B,64.81,3,26,8058566379068,0,15021,94405467,CLX5
2025-09-24 19:44:31.548880727+00:00,160,1,432669,F,A,64.81,1,26,8058566379025,0,15021,94405467,CLX5
2025-09-24 19:44:31.548880727+00:00,160,1,432669,F,A,64.81,2,26,8058566379026,0,15021,94405467,CLX5
2025-09-24 19:44:31.548880727+00:00,160,1,432669,C,A,64.81,1,26,8058566379025,0,15021,94405467,CLX5
2025-09-24 19:44:31.548880727+00:00,160,1,432669,C,A,64.81,2,26,8058566379026,128,15021,94405467,CLX5
2025-09-24 19:44:31.549359649+00:00,160,1,432669,T,B,64.81,4,26,8058566379075,0,14232,94405503,CLX5
2025-09-24 19:44:31.549359649+00:00,160,1,432669,F,A,64.81,1,26,8058566379029,0,14232,94405503,CLX5
2025-09-24 19:44:31.549359649+00:00,160,1,432669,F,A,64.81,1,26,8058566379046,0,14232,94405503,CLX5
2025-09-24 19:44:31.549359649+00:00,160,1,432669,F,A,64.81,2,26,8058566377086,0,14232,94405503,CLX5
2025-09-24 19:44:31.549359649+00:00,160,1,432669,C,A,64.81,1,26,8058566379029,0,14232,94405503,CLX5
2025-09-24 19:44:31.549359649+00:00,160,1,432669,C,A,64.81,1,26,8058566379046,0,14232,94405503,CLX5
2025-09-24 19:44:31.549359649+00:00,160,1,432669,C,A,64.81,2,26,8058566377086,128,14232,94405503,CLX5
2025-09-24 19:44:31.550492957+00:00,160,1,432669,C,A,64.82,1,26,8058566378588,128,17682,94405556,CLX5
2025-09-24 19:44:31.550562979+00:00,160,1,432669,C,B,64.78,1,26,8058566378744,128,14238,94405562,CLX5
2025-09-24 19:44:31.550976143+00:00,160,1,432669,M,B,64.79,1,26,8058566378878,128,17808,94405578,CLX5
2025-09-24 19:44:31.651678731+00:00,160,1,432669,C,B,64.8,3,26,8058566378785,128,18969,94405668,CLX5
2025-09-24 19:44:31.651902055+00:00,160,1,432669,A,A,64.82,1,26,8058566379118,128,18528,94405669,CLX5
2025-09-24 19:44:31.652092375+00:00,160,1,432669,A,A,64.82,1,26,8058566379119,128,18149,94405670,CLX5
2025-09-24 19:44:31.652244511+00:00,160,1,432669,A,A,64.82,1,26,8058566379120,128,18407,94405671,CLX5
2025-09-24 19:44:31.729246629+00:00,160,1,432669,A,A,64.82,1,26,8058566379130,128,18402,94405698,CLX5
2025-09-24 19:44:31.729400011+00:00,160,1,432669,A,A,64.81,3,26,8058566379131,128,18625,94405699,CLX5
2025-09-24 19:44:31.729626445+00:00,160,1,432669,A,A,64.81,2,26,8058566379133,128,13272,94405707,CLX5
2025-09-24 19:44:31.729824715+00:00,160,1,432669,C,A,64.81,2,26,8058566379133,128,16352,94405715,CLX5
2025-09-24 19:44:31.730185755+00:00,160,1,432669,A,A,64.81,1,26,8058566379136,128,15071,94405721,CLX5
2025-09-24 19:44:31.732577585+00:00,160,1,432669,A,A,64.81,1,26,8058566379142,128,21740,94405734,CLX5
2025-09-24 19:44:31.779473917+00:00,160,1,432669,C,A,64.82,1,26,8058566379130,128,18208,94405754,CLX5
2025-09-24 19:44:31.831064113+00:00,160,1,432669,A,B,64.8,3,26,8058566379153,128,18161,94405763,CLX5
2025-09-24 19:44:31.831223445+00:00,160,1,432669,C,A,64.81,1,26,8058566379142,128,16650,94405771,CLX5
2025-09-24 19:44:31.831771793+00:00,160,1,432669,C,A,64.81,1,26,8058566379136,128,16751,94405774,CLX5
2025-09-24 19:44:31.841484991+00:00,160,1,432669,A,B,64.78,1,26,8058566379156,128,18023,94405780,CLX5
2025-09-24 19:44:31.887741067+00:00,160,1,432669,A,A,64.81,1,26,8058566379163,128,19412,94405791,CLX5
2025-09-24 19:44:31.887938837+00:00,160,1,432669,C,A,64.82,1,26,8058566379120,128,18054,94405794,CLX5
2025-09-24 19:44:31.887949991+00:00,160,1,432669,C,A,64.82,1,26,8058566379119,128,14660,94405795,CLX5
2025-09-24 19:44:31.887954619+00:00,160,1,432669,C,A,64.82,1,26,8058566379118,128,14744,94405796,CLX5
2025-09-24 19:44:35.488997527+00:00,160,1,432669,C,B,64.78,1,26,8058566379156,128,14404,94406082,CLX5
2025-09-24 19:44:35.489008241+00:00,160,1,432669,C,A,64.81,3,26,8058566379131,128,16105,94406086,CLX5
2025-09-24 19:44:35.489845399+00:00,160,1,432669,C,B,64.8,1,26,8058566378105,128,18079,94406130,CLX5
2025-09-24 19:44:35.490846059+00:00,160,1,432669,T,B,64.81,1,26,8058566379284,0,18085,94406169,CLX5
2025-09-24 19:44:35.490846059+00:00,160,1,432669,F,A,64.81,1,26,8058566379163,0,18085,94406169,CLX5
2025-09-24 19:44:35.490846059+00:00,160,1,432669,C,A,64.81,1,26,8058566379163,128,14206,94406170,CLX5
2025-09-24 19:44:35.492367957+00:00,160,1,432669,A,B,64.8,2,26,8058566379297,128,17991,94406229,CLX5
2025-09-24 19:44:35.592772749+00:00,160,1,432669,C,B,64.8,3,26,8058566379153,128,18051,94406259,CLX5
2025-09-24 19:44:35.694133599+00:00,160,1,432669,A,B,64.81,3,26,8058566379332,128,18658,94406313,CLX5
2025-09-24 19:44:35.694429305+00:00,160,1,432669,A,B,64.81,1,26,8058566379333,128,18989,94406317,CLX5
2025-09-24 19:44:35.694619471+00:00,160,1,432669,M,A,65.98,4,26,8058566376748,128,14747,94406322,CLX5
2025-09-24 19:44:35.694627307+00:00,160,1,432669,A,A,64.82,1,26,8058566379335,128,14960,94406323,CLX5
2025-09-24 19:44:35.741396287+00:00,160,1,432669,A,A,64.82,1,26,8058566379345,128,18326,94406369,CLX5
2025-09-24 19:44:35.741571691+00:00,160,1,432669,A,A,64.82,1,26,8058566379349,128,14853,94406373,CLX5
2025-09-24 19:44:35.813364081+00:00,160,1,432669,A,B,64.77,2,26,8058566379362,128,17505,94406391,CLX5
2025-09-24 19:44:36.700009017+00:00,160,1,432669,C,B,64.81,1,26,8058566379333,128,17915,94406500,CLX5
2025-09-24 19:44:37.379754787+00:00,160,1,432669,T,A,64.81,1,26,8058566379438,0,19305,94406552,CLX5
2025-09-24 19:44:37.379754787+00:00,160,1,432669,F,B,64.81,1,26,8058566379332,0,19305,94406552,CLX5
2025-09-24 19:44:37.379754787+00:00,160,1,432669,M,B,64.81,2,26,8058566379332,128,16111,94406553,CLX5
2025-09-24 19:44:37.396361651+00:00,160,1,432669,M,B,64.81,1,26,8058566379332,128,17607,94406580,CLX5
2025-09-24 19:44:37.451008237+00:00,160,1,432669,T,A,64.81,1,26,8058566379451,0,18346,94406587,CLX5
2025-09-24 19:44:37.451008237+00:00,160,1,432669,F,B,64.81,1,26,8058566379332,0,18346,94406587,CLX5
2025-09-24 19:44:37.451008237+00:00,160,1,432669,C,B,64.81,1,26,8058566379332,128,15453,94406588,CLX5
2025-09-24 19:44:38.506884183+00:00,160,1,432669,A,A,64.83,1,26,8058566379504,128,21449,94406708,CLX5
2025-09-24 19:44:38.523670481+00:00,160,1,432669,A,B,64.81,1,26,8058566379505,128,17688,94406712,CLX5
2025-09-24 19:44:38.523917229+00:00,160,1,432669,C,A,64.82,1,26,8058566379349,128,17996,94406715,CLX5
2025-09-24 19:44:38.523926677+00:00,160,1,432669,C,A,64.83,1,26,8058566379504,128,14594,94406719,CLX5
2025-09-24 19:44:38.523928289+00:00,160,1,432669,C,A,64.82,1,26,8058566379345,128,14823,94406721,CLX5
2025-09-24 19:44:38.523929845+00:00,160,1,432669,C,A,64.82,1,26,8058566379335,128,14668,94406722,CLX5
2025-09-24 19:44:38.523944261+00:00,160,1,432669,A,B,64.81,1,26,8058566379507,128,17565,94406725,CLX5
2025-09-24 19:44:39.059871713+00:00,160,1,432669,A,A,64.82,1,26,8058566379573,128,17732,94406960,CLX5
2025-09-24 19:44:39.060059347+00:00,160,1,432669,A,A,64.82,1,26,8058566379574,128,17892,94406961,CLX5
2025-09-24 19:44:39.060204433+00:00,160,1,432669,A,A,64.82,1,26,8058566379575,128,18184,94406962,CLX5
2025-09-24 19:44:39.600008595+00:00,160,1,432669,C,B,64.81,1,26,8058566379507,128,17605,94407016,CLX5
2025-09-24 19:44:40.023657445+00:00,160,1,432669,A,A,64.86,1,26,8058566379610,128,20091,94407065,CLX5
2025-09-24 19:44:41.825324427+00:00,160,1,432669,C,B,64.78,1,26,8058566372991,128,18599,94407252,CLX5
2025-09-24 19:44:42.378382721+00:00,160,1,432669,C,A,64.82,1,26,8058566379575,128,18182,94407368,CLX5
2025-09-24 19:44:42.378575729+00:00,160,1,432669,C,A,64.82,1,26,8058566379574,128,17877,94407369,CLX5
2025-09-24 19:44:45.143825047+00:00,160,1,432669,C,A,64.82,1,26,8058566379573,128,18408,94407630,CLX5
2025-09-24 19:44:45.282318981+00:00,160,1,432669,A,B,64.81,1,26,8058566379862,128,13398,94407651,CLX5
2025-09-24 19:44:45.282327389+00:00,160,1,432669,A,B,64.78,1,26,8058566379864,128,14243,94407656,CLX5
2025-09-24 19:44:45.282383471+00:00,160,1,432669,A,B,64.81,1,26,8058566379865,128,17892,94407657,CLX5
2025-09-24 19:44:45.282782139+00:00,160,1,432669,C,A,64.82,1,26,8058566378506,128,14548,94407676,CLX5
2025-09-24 19:44:45.284519413+00:00,160,1,432669,A,B,64.81,1,26,8058566379903,128,14303,94407853,CLX5
