ts_event,rtype,publisher_id,instrument_id,action,side,price,size,channel_id,order_id,flags,ts_in_delta,sequence,symbol
2025-09-24 19:44:45.284519591+00:00,160,1,432669,A,B,64.81,2,26,8058566379904,128,20499,94407855,CLX5
2025-09-24 19:44:45.286428079+00:00,160,1,432669,C,A,64.82,2,26,8058566372341,128,14647,94407932,CLX5
2025-09-24 19:44:45.625769189+00:00,160,1,432669,A,B,64.81,1,26,8058566380015,128,19221,94408121,CLX5
2025-09-24 19:44:45.625941177+00:00,160,1,432669,A,B,64.81,1,26,8058566380016,128,19090,94408122,CLX5
2025-09-24 19:44:45.625987003+00:00,160,1,432669,C,A,64.82,1,26,8058566378457,128,14510,94408125,CLX5
2025-09-24 19:44:49.078774149+00:00,160,1,432669,A,B,64.81,2,26,8058566380192,128,18731,94408506,CLX5
2025-09-24 19:44:51.016466057+00:00,160,1,432669,C,B,64.81,2,26,8058566380192,128,19203,94409090,CLX5
2025-09-24 19:44:51.016653095+00:00,160,1,432669,A,A,64.82,1,26,8058566380402,128,17993,94409091,CLX5
2025-09-24 19:44:51.016812775+00:00,160,1,432669,C,B,64.81,1,26,8058566380016,128,18633,94409092,CLX5
2025-09-24 19:44:55.122735729+00:00,160,1,432669,T,B,64.82,1,26,8058566380552,0,18013,94409422,CLX5
2025-09-24 19:44:55.122735729+00:00,160,1,432669,F,A,64.82,1,26,8058566371128,0,18013,94409422,CLX5
2025-09-24 19:44:55.122735729+00:00,160,1,432669,C,A,64.82,1,26,8058566371128,128,14577,94409423,CLX5
2025-09-24 19:44:55.123104871+00:00,160,1,432669,C,A,64.82,1,26,8058566380402,128,14910,94409425,CLX5
2025-09-24 19:44:55.123713101+00:00,160,1,432669,A,B,64.81,2,26,8058566380559,128,15513,94409436,CLX5
2025-09-24 19:44:55.123838261+00:00,160,1,432669,A,A,64.82,1,26,8058566380560,128,15187,94409438,CLX5
2025-09-24 19:44:55.123876159+00:00,160,1,432669,A,B,64.81,1,26,8058566380561,128,15672,94409439,CLX5
2025-09-24 19:44:55.123892115+00:00,160,1,432669,C,A,64.82,1,26,8058566380560,128,17017,94409440,CLX5
2025-09-24 19:44:55.124049125+00:00,160,1,432669,A,A,64.82,1,26,8058566380563,128,14008,94409444,CLX5
2025-09-24 19:44:55.124218557+00:00,160,1,432669,C,A,64.82,1,26,8058566380563,128,14808,94409451,CLX5
2025-09-24 19:44:55.467227541+00:00,160,1,432669,A,B,64.81,1,26,8058566380583,128,15368,94409490,CLX5
2025-09-24 19:44:55.467378619+00:00,160,1,432669,C,A,64.82,2,26,8058566372336,128,14581,94409495,CLX5
2025-09-24 19:44:55.995095983+00:00,160,1,432669,C,A,64.82,2,26,8058566372345,128,14530,94409597,CLX5
2025-09-24 19:44:55.995096281+00:00,160,1,432669,C,A,64.82,1,26,8058566378486,128,15077,94409600,CLX5
2025-09-24 19:44:55.995096429+00:00,160,1,432669,A,B,64.81,2,26,8058566380617,128,15434,94409601,CLX5
2025-09-24 19:44:55.995096807+00:00,160,1,432669,C,A,64.85,2,26,8058566378683,128,17526,94409602,CLX5
2025-09-24 19:44:55.995330213+00:00,160,1,432669,C,A,64.82,1,26,8058566372332,128,15277,94409621,CLX5
2025-09-24 19:44:55.995332361+00:00,160,1,432669,A,B,64.8,2,26,8058566380624,128,17422,94409622,CLX5
2025-09-24 19:44:55.995337047+00:00,160,1,432669,A,B,64.54,8,26,8058566380626,128,15991,94409623,CLX5
2025-09-24 19:44:55.995340157+00:00,160,1,432669,C,B,64.77,2,26,8058566379362,128,14356,94409624,CLX5
2025-09-24 19:44:55.995384547+00:00,160,1,432669,A,B,64.81,1,26,8058566380629,128,18678,94409635,CLX5
2025-09-24 19:44:55.995414017+00:00,160,1,432669,C,B,64.81,2,26,8058566380617,128,19053,94409637,CLX5
2025-09-24 19:44:55.995465893+00:00,160,1,432669,A,B,64.81,1,26,8058566380630,128,15762,94409639,CLX5
2025-09-24 19:44:55.999478881+00:00,160,1,432669,M,B,64.81,1,26,8058566378878,128,19063,94409724,CLX5
2025-09-24 19:44:56.004881715+00:00,160,1,432669,C,B,64.79,1,26,8058566378269,128,18127,94409726,CLX5
2025-09-24 19:44:56.013194505+00:00,160,1,432669,C,B,64.78,2,26,8058566373431,128,17781,94409767,CLX5
2025-09-24 19:44:56.018948243+00:00,160,1,432669,A,A,65.9,1,26,8058566380672,128,17022,94409796,CLX5
2025-09-24 19:44:56.113199261+00:00,160,1,432669,A,A,64.87,2,26,8058566380692,128,17665,94409846,CLX5
2025-09-24 19:44:56.113203927+00:00,160,1,432669,A,B,64.77,2,26,8058566380693,128,14469,94409847,CLX5
2025-09-24 19:44:56.161224097+00:00,160,1,432669,C,B,64.77,2,26,8058566380693,128,14264,94409871,CLX5
2025-09-24 19:44:56.413183347+00:00,160,1,432669,A,B,64.77,2,26,8058566380728,128,16832,94409931,CLX5
2025-09-24 19:44:56.459960411+00:00,160,1,432669,T,B,64.82,1,26,8058566380733,0,17637,94409939,CLX5
2025-09-24 19:44:56.459960411+00:00,160,1,432669,F,A,64.82,1,26,8058566371129,0,17637,94409939,CLX5
2025-09-24 19:44:56.459960411+00:00,160,1,432669,C,A,64.82,1,26,8058566371129,128,15435,94409940,CLX5
2025-09-24 19:44:56.787816767+00:00,160,1,432669,M,A,64.9,3,26,8058566144143,128,17999,94409989,CLX5
2025-09-24 19:44:56.827103897+00:00,160,1,432669,T,B,64.82,1,26,8058566380764,0,17400,94409997,CLX5
2025-09-24 19:44:56.827103897+00:00,160,1,432669,F,A,64.82,1,26,8058566371140,0,17400,94409997,CLX5
2025-09-24 19:44:56.827103897+00:00,160,1,432669,C,A,64.82,1,26,8058566371140,128,15831,94409998,CLX5
2025-09-24 19:44:56.827379825+00:00,160,1,432669,A,B,64.81,1,26,8058566380765,128,19153,94409999,CLX5
2025-09-24 19:44:56.827534751+00:00,160,1,432669,C,B,64.81,1,26,8058566380765,128,18798,94410005,CLX5
2025-09-24 19:44:56.827575465+00:00,160,1,432669,M,B,64.81,2,26,8058566373581,128,14565,94410006,CLX5
2025-09-24 19:44:56.828600875+00:00,160,1,432669,C,B,64.77,2,26,8058566380728,128,18737,94410009,CLX5
2025-09-24 19:44:56.829042723+00:00,160,1,432669,M,B,63.65,4,26,8058566373581,128,18842,94410011,CLX5
2025-09-24 19:44:57.838304507+00:00,160,1,432669,A,A,64.82,2,26,8058566380847,128,15498,94410240,CLX5
2025-09-24 19:44:57.838305681+00:00,160,1,432669,A,A,64.82,2,26,8058566380852,128,14525,94410251,CLX5
2025-09-24 19:44:57.838394975+00:00,160,1,432669,A,A,64.82,2,26,8058566380858,128,18292,94410260,CLX5
2025-09-24 19:44:57.838434391+00:00,160,1,432669,A,A,64.82,1,26,8058566380859,128,14770,94410261,CLX5
2025-09-24 19:44:57.838533917+00:00,160,1,432669,A,A,64.82,1,26,8058566380864,128,15608,94410270,CLX5
2025-09-24 19:44:57.838577941+00:00,160,1,432669,A,A,64.82,1,26,8058566380865,128,17848,94410278,CLX5
2025-09-24 19:44:57.838650495+00:00,160,1,432669,C,A,64.82,1,26,8058566380859,128,14607,94410288,CLX5
2025-09-24 19:44:57.838819659+00:00,160,1,432669,C,A,64.82,2,26,8058566380852,128,14629,94410313,CLX5
2025-09-24 19:44:57.838844235+00:00,160,1,432669,C,A,64.82,2,26,8058566380858,128,14199,94410320,CLX5
2025-09-24 19:44:57.838863625+00:00,160,1,432669,C,B,64.81,1,26,8058566380630,128,18836,94410324,CLX5
2025-09-24 19:44:57.838985731+00:00,160,1,432669,A,B,64.81,2,26,8058566380874,128,13631,94410343,CLX5
2025-09-24 19:44:57.839185825+00:00,160,1,432669,A,B,64.81,1,26,8058566380879,128,15578,94410353,CLX5
2025-09-24 19:44:57.839258283+00:00,160,1,432669,C,B,64.81,1,26,8058566380561,128,13228,94410357,CLX5
2025-09-24 19:44:57.839819397+00:00,160,1,432669,A,B,64.81,1,26,8058566380884,128,15221,94410375,CLX5
2025-09-24 19:44:57.839928007+00:00,160,1,432669,C,B,64.81,1,26,8058566380879,128,15202,94410377,CLX5
2025-09-24 19:44:57.840103699+00:00,160,1,432669,A,B,64.81,1,26,8058566380888,128,16118,94410390,CLX5
2025-09-24 19:44:57.840268549+00:00,160,1,432669,C,B,64.81,1,26,8058566380888,128,15819,94410397,CLX5
2025-09-24 19:44:57.841092781+00:00,160,1,432669,A,B,64.81,1,26,8058566380897,128,15730,94410417,CLX5
2025-09-24 19:44:57.841356693+00:00,160,1,432669,C,B,64.81,1,26,8058566380897,128,18950,94410424,CLX5
2025-09-24 19:44:57.841898685+00:00,160,1,432669,A,B,64.81,1,26,8058566380905,128,15603,94410438,CLX5
2025-09-24 19:44:57.841901969+00:00,160,1,432669,C,A,64.82,1,26,8058566380864,128,18545,94410439,CLX5
2025-09-24 19:44:57.842173193+00:00,160,1,432669,C,B,64.81,1,26,8058566380905,128,18468,94410452,CLX5
2025-09-24 19:44:57.842631555+00:00,160,1,432669,A,B,64.81,1,26,8058566380909,128,18670,94410458,CLX5
2025-09-24 19:44:57.842917777+00:00,160,1,432669,C,B,64.81,1,26,8058566380909,128,15509,94410460,CLX5
2025-09-24 19:44:57.843296095+00:00,160,1,432669,A,B,64.81,1,26,8058566380912,128,18967,94410471,CLX5
2025-09-24 19:44:57.843634345+00:00,160,1,432669,C,B,64.81,1,26,8058566380912,128,15717,94410474,CLX5
2025-09-24 19:44:57.849592189+00:00,160,1,432669,C,A,64.82,2,26,8058566380847,128,15383,94410496,CLX5
2025-09-24 19:44:57.943540375+00:00,160,1,432669,A,B,64.81,1,26,8058566380944,128,19943,94410570,CLX5
2025-09-24 19:44:57.943685485+00:00,160,1,432669,A,B,64.81,1,26,8058566380945,128,19204,94410571,CLX5
2025-09-24 19:44:57.943698039+00:00,160,1,432669,C,B,64.81,1,26,8058566380944,128,14022,94410572,CLX5
2025-09-24 19:44:58.013212101+00:00,160,1,432669,A,B,64.77,2,26,8058566380964,128,17296,94410608,CLX5
2025-09-24 19:44:58.273726811+00:00,160,1,432669,T,N,64.82,1,26,0,0,18258,94410707,CLX5
2025-09-24 19:44:58.273726811+00:00,160,1,432669,F,N,64.82,1,26,8058566371158,0,18258,94410707,CLX5
2025-09-24 19:44:58.273726811+00:00,160,1,432669,M,A,64.82,2,26,8058566371158,128,15050,94410708,CLX5
2025-09-24 19:44:58.274955787+00:00,160,1,432669,A,B,64.72,2,26,8058566381007,128,17798,94410721,CLX5
2025-09-24 19:44:58.319251129+00:00,160,1,432669,C,B,64.16,2,26,8058566367633,128,17789,94410727,CLX5
2025-09-24 19:44:58.418995177+00:00,160,1,432669,A,B,64.16,2,26,8058566381015,128,17808,94410739,CLX5
2025-09-24 19:44:58.524984997+00:00,160,1,432669,A,A,64.82,1,26,8058566381027,128,20508,94410755,CLX5
2025-09-24 19:44:58.525149515+00:00,160,1,432669,A,A,64.82,1,26,8058566381028,128,18466,94410756,CLX5
2025-09-24 19:44:58.547357999+00:00,160,1,432669,C,B,64.81,2,26,8058566380874,128,18526,94410759,CLX5
2025-09-24 19:44:58.547362261+00:00,160,1,432669,C,B,64.77,2,26,8058566380964,128,13353,94410764,CLX5
2025-09-24 19:44:58.804182345+00:00,160,1,432669,T,B,64.82,1,26,8058566381056,0,17645,94410853,CLX5
2025-09-24 19:44:58.804182345+00:00,160,1,432669,F,A,64.82,1,26,8058566371158,0,17645,94410853,CLX5
2025-09-24 19:44:58.804182345+00:00,160,1,432669,M,A,64.82,1,26,8058566371158,128,15431,94410854,CLX5
2025-09-24 19:44:58.804481909+00:00,160,1,432669,C,A,64.82,1,26,8058566381028,128,16132,94410857,CLX5
2025-09-24 19:44:58.832617709+00:00,160,1,432669,A,A,64.82,1,26,8058566381059,128,19566,94410861,CLX5
2025-09-24 19:44:58.833251645+00:00,160,1,432669,A,A,64.82,1,26,8058566381065,128,14699,94410882,CLX5
2025-09-24 19:44:58.913209143+00:00,160,1,432669,A,B,64.77,2,26,8058566381081,128,17655,94410915,CLX5
2025-09-24 19:45:00.012742149+00:00,160,1,432669,M,A,64.95,1,26,8058565075241,128,18499,94411243,CLX5
2025-09-24 19:45:00.027821489+00:00,160,1,432669,A,B,64.81,1,26,8058566381249,128,19447,94411454,CLX5
2025-09-24 19:45:00.027985545+00:00,160,1,432669,C,A,64.82,1,26,8058566381059,128,15632,94411456,CLX5
2025-09-24 19:45:00.041481991+00:00,160,1,432669,M,A,64.94,1,26,8058565075241,128,15434,94411480,CLX5
2025-09-24 19:45:00.042019607+00:00,160,1,432669,A,B,64.81,1,26,8058566381254,128,13680,94411499,CLX5
2025-09-24 19:45:00.265261431+00:00,160,1,432669,M,A,64.89,3,26,8058566144143,128,19006,94411578,CLX5
2025-09-24 19:45:00.283693039+00:00,160,1,432669,A,B,64.81,1,26,8058566381314,128,17448,94411599,CLX5
2025-09-24 19:45:00.283825203+00:00,160,1,432669,M,A,64.95,1,26,8058565075241,128,18018,94411604,CLX5
2025-09-24 19:45:00.284961277+00:00,160,1,432669,C,A,64.82,1,26,8058566372003,128,15419,94411649,CLX5
2025-09-24 19:45:00.285442023+00:00,160,1,432669,C,B,64.81,1,26,8058566381314,128,19016,94411657,CLX5
2025-09-24 19:45:00.285585383+00:00,160,1,432669,A,B,64.81,1,26,8058566381323,128,19219,94411659,CLX5
2025-09-24 19:45:00.288712003+00:00,160,1,432669,C,A,64.82,1,26,8058566380865,128,18654,94411681,CLX5
2025-09-24 19:45:00.289054441+00:00,160,1,432669,C,B,64.81,1,26,8058566381323,128,15726,94411696,CLX5
2025-09-24 19:45:00.289060737+00:00,160,1,432669,A,A,64.82,1,26,8058566381327,128,16270,94411697,CLX5
2025-09-24 19:45:00.291004249+00:00,160,1,432669,M,A,64.83,1,26,8058566378647,128,17684,94411706,CLX5
2025-09-24 19:45:00.319386105+00:00,160,1,432669,C,B,64.16,2,26,8058566381015,128,14064,94411716,CLX5
2025-09-24 19:45:00.361575991+00:00,160,1,432669,A,A,64.82,1,26,8058566381348,128,15418,94411778,CLX5
2025-09-24 19:45:00.364543449+00:00,160,1,432669,A,A,64.82,1,26,8058566381354,128,15614,94411793,CLX5
2025-09-24 19:45:00.364543627+00:00,160,1,432669,C,B,64.81,1,26,8058566380945,128,18957,94411794,CLX5
2025-09-24 19:45:00.364549097+00:00,160,1,432669,A,A,64.82,2,26,8058566381356,128,15633,94411796,CLX5
2025-09-24 19:45:00.364549401+00:00,160,1,432669,C,B,64.8,2,26,8058566380624,128,17590,94411797,CLX5
2025-09-24 19:45:00.364573477+00:00,160,1,432669,C,B,64.81,1,26,8058566380629,128,16135,94411812,CLX5
2025-09-24 19:45:00.364604003+00:00,160,1,432669,A,A,64.82,2,26,8058566381363,128,14122,94411813,CLX5
2025-09-24 19:45:00.364667285+00:00,160,1,432669,A,A,64.82,2,26,8058566381365,128,22987,94411814,CLX5
2025-09-24 19:45:00.364695451+00:00,160,1,432669,A,A,64.82,1,26,8058566381368,128,14991,94411818,CLX5
2025-09-24 19:45:00.364733309+00:00,160,1,432669,A,A,64.82,1,26,8058566381370,128,18112,94411826,CLX5
2025-09-24 19:45:00.364849235+00:00,160,1,432669,C,A,64.82,1,26,8058566381370,128,14950,94411832,CLX5
2025-09-24 19:45:00.364908523+00:00,160,1,432669,M,A,64.94,1,26,8058565075241,128,14145,94411833,CLX5
2025-09-24 19:45:00.365000717+00:00,160,1,432669,C,A,64.82,2,26,8058566381363,128,14725,94411838,CLX5
2025-09-24 19:45:00.365170169+00:00,160,1,432669,A,A,64.82,1,26,8058566381374,128,14805,94411846,CLX5
2025-09-24 19:45:00.365390805+00:00,160,1,432669,C,A,64.82,1,26,8058566381374,128,17923,94411853,CLX5
2025-09-24 19:45:00.365719897+00:00,160,1,432669,A,A,64.82,1,26,8058566381378,128,14199,94411859,CLX5
2025-09-24 19:45:00.365988129+00:00,160,1,432669,C,A,64.82,1,26,8058566381378,128,14753,94411865,CLX5
2025-09-24 19:45:00.368869365+00:00,160,1,432669,M,A,64.82,1,26,8058566378647,128,18121,94411894,CLX5
2025-09-24 19:45:00.369024649+00:00,160,1,432669,C,A,64.82,1,26,8058566381368,128,18162,94411895,CLX5
2025-09-24 19:45:00.375574247+00:00,160,1,432669,A,B,64.79,1,26,8058566381388,128,18207,94411896,CLX5
2025-09-24 19:45:00.413246687+00:00,160,1,432669,A,B,64.78,2,26,8058566381393,128,18079,94411902,CLX5
2025-09-24 19:45:00.419105135+00:00,160,1,432669,A,B,64.16,2,26,8058566381395,128,14296,94411907,CLX5
2025-09-24 19:45:00.427270765+00:00,160,1,432669,C,B,64.54,8,26,8058566380626,128,18401,94411908,CLX5
2025-09-24 19:45:00.514992879+00:00,160,1,432669,A,B,64.8,2,26,8058566381414,128,13653,94411951,CLX5
2025-09-24 19:45:00.514995433+00:00,160,1,432669,A,B,64.54,8,26,8058566381415,128,13683,94411954,CLX5
2025-09-24 19:45:00.514998793+00:00,160,1,432669,C,B,64.77,2,26,8058566381081,128,13683,94411954,CLX5
2025-09-24 19:45:00.583328459+00:00,160,1,432669,A,B,64.8,1,26,8058566381419,128,19656,94411970,CLX5
2025-09-24 19:45:00.613229237+00:00,160,1,432669,C,B,64.78,2,26,8058566381393,128,17427,94411972,CLX5
2025-09-24 19:45:01.402169227+00:00,160,1,432669,M,B,64.8,1,26,8058566373581,128,20821,94412159,CLX5
2025-09-24 19:45:02.497072685+00:00,160,1,432669,C,B,64.8,2,26,8058566381414,128,15072,94412268,CLX5
2025-09-24 19:45:02.513200009+00:00,160,1,432669,A,B,64.78,2,26,8058566381542,128,18160,94412300,CLX5
2025-09-24 19:45:02.526860169+00:00,160,1,432669,C,B,64.54,8,26,8058566381415,128,17801,94412301,CLX5
2025-09-24 19:45:02.613191477+00:00,160,1,432669,A,B,64.77,2,26,8058566381549,128,18259,94412318,CLX5
2025-09-24 19:45:03.651945655+00:00,160,1,432669,C,A,65.06,1,26,8058566377073,128,19379,94412445,CLX5
2025-09-24 19:45:03.730392937+00:00,160,1,432669,A,A,65.05,1,26,8058566381608,128,17906,94412458,CLX5
2025-09-24 19:45:04.876091141+00:00,160,1,432669,C,A,65.06,1,26,8058566377080,128,21017,94412493,CLX5
2025-09-24 19:45:04.907426961+00:00,160,1,432669,A,A,65.05,1,26,8058566381627,128,18287,94412498,CLX5
2025-09-24 19:45:05.033336123+00:00,160,1,432669,A,A,65.02,1,26,8058566381630,128,18248,94412505,CLX5
2025-09-24 19:45:05.033531821+00:00,160,1,432669,C,A,65.04,1,26,8058566377079,128,17432,94412506,CLX5
2025-09-24 19:45:05.111176825+00:00,160,1,432669,A,A,65.03,1,26,8058566381637,128,17855,94412518,CLX5
2025-09-24 19:45:05.922270825+00:00,160,1,432669,C,A,64.82,2,26,8058566381365,128,19321,94412579,CLX5
2025-09-24 19:45:09.479472403+00:00,160,1,432669,C,B,64.79,1,26,8058566374625,128,17951,94412792,CLX5
2025-09-24 19:45:09.492620213+00:00,160,1,432669,A,A,64.82,1,26,8058566381769,128,19881,94412793,CLX5
2025-09-24 19:45:11.420165991+00:00,160,1,432669,A,A,64.82,2,26,8058566381835,128,15204,94412931,CLX5
2025-09-24 19:45:11.420179833+00:00,160,1,432669,A,A,64.82,2,26,8058566381836,128,14582,94412932,CLX5
2025-09-24 19:45:11.420459087+00:00,160,1,432669,A,A,64.82,2,26,8058566381838,128,16393,94412935,CLX5
2025-09-24 19:45:11.420481759+00:00,160,1,432669,C,B,64.81,1,26,8058566380884,128,15565,94412938,CLX5
2025-09-24 19:45:11.420502207+00:00,160,1,432669,A,A,64.82,1,26,8058566381839,128,17921,94412939,CLX5
2025-09-24 19:45:11.420607611+00:00,160,1,432669,A,A,64.82,1,26,8058566381843,128,17951,94412950,CLX5
2025-09-24 19:45:11.421327769+00:00,160,1,432669,A,A,64.85,2,26,8058566381846,128,13464,94412965,CLX5
2025-09-24 19:45:11.421893877+00:00,160,1,432669,C,B,64.81,2,26,8058566380559,128,18944,94412972,CLX5
2025-09-24 19:45:11.434068309+00:00,160,1,432669,C,A,64.82,1,26,8058566381839,128,19103,94412984,CLX5
2025-09-24 19:45:11.440127581+00:00,160,1,432669,C,A,65.9,1,26,8058566380672,128,17835,94412991,CLX5
2025-09-24 19:45:11.458629363+00:00,160,1,432669,C,A,64.87,2,26,8058566380692,128,17836,94412996,CLX5
2025-09-24 19:45:11.808576569+00:00,160,1,432669,C,A,64.85,1,26,8058566371070,128,15125,94413111,CLX5
2025-09-24 19:45:11.808576717+00:00,160,1,432669,C,A,64.87,1,26,8058566364396,128,18692,94413112,CLX5
2025-09-24 19:45:11.808576867+00:00,160,1,432669,C,A,64.86,1,26,8058566367087,128,15188,94413113,CLX5
2025-09-24 19:45:11.808579851+00:00,160,1,432669,C,A,64.92,2,26,8058566372672,128,17176,94413119,CLX5
2025-09-24 19:45:11.808689633+00:00,160,1,432669,C,A,64.88,1,26,8058566329644,128,17863,94413124,CLX5
2025-09-24 19:45:11.808894363+00:00,160,1,432669,T,B,64.82,24,26,8058566381934,0,18460,94413199,CLX5
2025-09-24 19:45:11.808894363+00:00,160,1,432669,F,A,64.82,1,26,8058566371158,0,18460,94413199,CLX5
2025-09-24 19:45:11.808894363+00:00,160,1,432669,F,A,64.82,2,26,8058566371162,0,18460,94413199,CLX5
2025-09-24 19:45:11.808894363+00:00,160,1,432669,F,A,64.82,1,26,8058566371164,0,18460,94413199,CLX5
2025-09-24 19:45:11.808894363+00:00,160,1,432669,F,A,64.82,1,26,8058566371179,0,18460,94413199,CLX5
2025-09-24 19:45:11.808894363+00:00,160,1,432669,F,A,64.82,1,26,8058566369708,0,18460,94413199,CLX5
2025-09-24 19:45:11.808894363+00:00,160,1,432669,F,A,64.82,3,26,8058566371476,0,18460,94413199,CLX5
2025-09-24 19:45:11.808894363+00:00,160,1,432669,F,A,64.82,1,26,8058566381027,0,18460,94413199,CLX5
2025-09-24 19:45:11.808894363+00:00,160,1,432669,F,A,64.82,1,26,8058566381065,0,18460,94413199,CLX5
2025-09-24 19:45:11.808894363+00:00,160,1,432669,F,A,64.82,1,26,8058566381327,0,18460,94413199,CLX5
2025-09-24 19:45:11.808894363+00:00,160,1,432669,F,A,64.82,1,26,8058566381348,0,18460,94413199,CLX5
2025-09-24 19:45:11.808894363+00:00,160,1,432669,F,A,64.82,2,26,8058566381356,0,18460,94413199,CLX5
2025-09-24 19:45:11.808894363+00:00,160,1,432669,F,A,64.82,1,26,8058566378647,0,18460,94413199,CLX5
2025-09-24 19:45:11.808894363+00:00,160,1,432669,F,A,64.82,1,26,8058566381769,0,18460,94413199,CLX5
2025-09-24 19:45:11.808894363+00:00,160,1,432669,F,A,64.82,2,26,8058566381835,0,18460,94413199,CLX5
2025-09-24 19:45:11.808894363+00:00,160,1,432669,F,A,64.82,2,26,8058566381836,0,18460,94413199,CLX5
2025-09-24 19:45:11.808894363+00:00,160,1,432669,F,A,64.82,2,26,8058566381838,0,18460,94413199,CLX5
2025-09-24 19:45:11.808894363+00:00,160,1,432669,F,A,64.82,1,26,8058566381843,0,18460,94413199,CLX5
2025-09-24 19:45:11.808894363+00:00,160,1,432669,C,A,64.82,1,26,8058566371158,0,16559,94413200,CLX5
2025-09-24 19:45:11.808894363+00:00,160,1,432669,C,A,64.82,2,26,8058566371162,0,16559,94413200,CLX5
2025-09-24 19:45:11.808894363+00:00,160,1,432669,C,A,64.82,1,26,8058566371164,0,16559,94413200,CLX5
2025-09-24 19:45:11.808894363+00:00,160,1,432669,C,A,64.82,1,26,8058566371179,0,16559,94413200,CLX5
2025-09-24 19:45:11.808894363+00:00,160,1,432669,C,A,64.82,1,26,8058566369708,0,16559,94413200,CLX5
2025-09-24 19:45:11.808894363+00:00,160,1,432669,C,A,64.82,3,26,8058566371476,0,16559,94413200,CLX5
2025-09-24 19:45:11.808894363+00:00,160,1,432669,C,A,64.82,1,26,8058566381027,0,16559,94413200,CLX5
2025-09-24 19:45:11.808894363+00:00,160,1,432669,C,A,64.82,1,26,8058566381065,0,16559,94413200,CLX5
2025-09-24 19:45:11.808894363+00:00,160,1,432669,C,A,64.82,1,26,8058566381327,0,16559,94413200,CLX5
2025-09-24 19:45:11.808894363+00:00,160,1,432669,C,A,64.82,1,26,8058566381348,0,16559,94413200,CLX5
2025-09-24 19:45:11.808894363+00:00,160,1,432669,C,A,64.82,2,26,8058566381356,0,16559,94413200,CLX5
2025-09-24 19:45:11.808894363+00:00,160,1,432669,C,A,64.82,1,26,8058566378647,0,16559,94413200,CLX5
2025-09-24 19:45:11.808894363+00:00,160,1,432669,C,A,64.82,1,26,8058566381769,0,16559,94413200,CLX5
2025-09-24 19:45:11.808894363+00:00,160,1,432669,C,A,64.82,2,26,8058566381835,0,16559,94413200,CLX5
2025-09-24 19:45:11.808894363+00:00,160,1,432669,C,A,64.82,2,26,8058566381836,0,16559,94413200,CLX5
2025-09-24 19:45:11.808894363+00:00,160,1,432669,C,A,64.82,2,26,8058566381838,0,16559,94413200,CLX5
2025-09-24 19:45:11.808894363+00:00,160,1,432669,C,A,64.82,1,26,8058566381843,0,16559,94413200,CLX5
2025-09-24 19:45:11.808894363+00:00,160,1,432669,C,A,64.82,1,26,8058566381354,128,16559,94413200,CLX5
2025-09-24 19:45:11.808894893+00:00,160,1,432669,A,B,64.81,1,26,8058566381937,128,19484,94413206,CLX5
2025-09-24 19:45:11.808921957+00:00,160,1,432669,A,B,64.81,2,26,8058566381968,128,14929,94413316,CLX5
2025-09-24 19:45:11.808951991+00:00,160,1,432669,A,B,64.81,2,26,8058566381980,128,16351,94413337,CLX5
2025-09-24 19:45:11.808957501+00:00,160,1,432669,A,B,64.81,2,26,8058566381983,128,16977,94413342,CLX5
2025-09-24 19:45:11.809498147+00:00,160,1,432669,A,B,64.81,1,26,8058566382002,128,18515,94413376,CLX5
2025-09-24 19:45:11.809755589+00:00,160,1,432669,A,B,64.81,1,26,8058566382010,128,15049,94413402,CLX5
2025-09-24 19:45:11.809919799+00:00,160,1,432669,A,B,64.81,2,26,8058566382017,128,14610,94413420,CLX5
2025-09-24 19:45:11.810019427+00:00,160,1,432669,A,B,64.82,3,26,8058566382055,128,16730,94413473,CLX5
2025-09-24 19:45:11.810046821+00:00,160,1,432669,A,B,64.82,2,26,8058566382064,128,27647,94413491,CLX5
2025-09-24 19:45:11.810047001+00:00,160,1,432669,C,A,64.83,1,26,8058566371043,128,13628,94413492,CLX5
2025-09-24 19:45:11.810084263+00:00,160,1,432669,A,B,64.82,3,26,8058566382080,128,20059,94413509,CLX5
2025-09-24 19:45:11.810084509+00:00,160,1,432669,A,B,64.82,1,26,8058566382081,128,14006,94413510,CLX5
2025-09-24 19:45:11.810176359+00:00,160,1,432669,M,A,64.95,1,26,8058565075241,128,14368,94413524,CLX5
2025-09-24 19:45:11.810463673+00:00,160,1,432669,A,B,64.81,1,26,8058566382107,128,14821,94413602,CLX5
2025-09-24 19:45:11.810854243+00:00,160,1,432669,A,B,64.82,3,26,8058566382145,128,16864,94413682,CLX5
2025-09-24 19:45:11.810854895+00:00,160,1,432669,A,B,64.82,1,26,8058566382147,128,14269,94413684,CLX5
2025-09-24 19:45:11.810863553+00:00,160,1,432669,A,B,64.81,1,26,8058566382154,128,18268,94413691,CLX5
2025-09-24 19:45:11.810881217+00:00,160,1,432669,A,B,64.82,1,26,8058566382159,128,17252,94413695,CLX5
2025-09-24 19:45:11.810907809+00:00,160,1,432669,A,B,64.81,2,26,8058566382164,128,14918,94413716,CLX5
2025-09-24 19:45:11.810920919+00:00,160,1,432669,M,B,64.81,1,26,8058566372953,128,18131,94413723,CLX5
2025-09-24 19:45:11.811019835+00:00,160,1,432669,A,B,64.81,3,26,8058566382181,128,14660,94413747,CLX5
2025-09-24 19:45:11.811840101+00:00,160,1,432669,C,B,64.82,1,26,8058566382159,128,15794,94413928,CLX5
2025-09-24 19:45:11.811866959+00:00,160,1,432669,C,B,64.82,3,26,8058566382080,128,16717,94413932,CLX5
2025-09-24 19:45:11.811934827+00:00,160,1,432669,A,B,64.79,1,26,8058566382239,128,14532,94413939,CLX5
2025-09-24 19:45:11.812629185+00:00,160,1,432669,A,A,64.83,1,26,8058566382250,128,15245,94413997,CLX5
2025-09-24 19:45:11.813792615+00:00,160,1,432669,A,B,64.54,8,26,8058566382274,128,14743,94414108,CLX5
2025-09-24 19:45:11.814362291+00:00,160,1,432669,C,A,64.85,2,26,8058566381846,128,14582,94414153,CLX5
2025-09-24 19:45:11.814362943+00:00,160,1,432669,C,A,64.86,2,26,8058566377438,128,15250,94414154,CLX5
2025-09-24 19:45:11.814658707+00:00,160,1,432669,A,B,64.8,2,26,8058566382288,128,18927,94414181,CLX5
2025-09-24 19:45:11.814665427+00:00,160,1,432669,C,B,64.77,2,26,8058566381549,128,14691,94414183,CLX5
2025-09-24 19:45:11.815488111+00:00,160,1,432669,C,B,64.82,1,26,8058566382081,128,18861,94414240,CLX5
2025-09-24 19:45:11.816335541+00:00,160,1,432669,C,B,64.82,3,26,8058566382055,128,15021,94414278,CLX5
2025-09-24 19:45:11.816346179+00:00,160,1,432669,A,A,64.83,1,26,8058566382305,128,14762,94414280,CLX5
2025-09-24 19:45:11.816796207+00:00,160,1,432669,T,A,64.82,3,26,8058566382309,0,15224,94414301,CLX5
2025-09-24 19:45:11.816796207+00:00,160,1,432669,F,B,64.82,2,26,8058566382064,0,15224,94414301,CLX5
2025-09-24 19:45:11.816796207+00:00,160,1,432669,F,B,64.82,1,26,8058566382145,0,15224,94414301,CLX5
2025-09-24 19:45:11.816796207+00:00,160,1,432669,C,B,64.82,2,26,8058566382064,0,18184,94414302,CLX5
2025-09-24 19:45:11.816796207+00:00,160,1,432669,M,B,64.82,2,26,8058566382145,128,18184,94414302,CLX5
2025-09-24 19:45:11.816808899+00:00,160,1,432669,C,B,64.79,1,26,8058566381388,128,15297,94414304,CLX5
2025-09-24 19:45:11.816835449+00:00,160,1,432669,C,B,64.78,1,26,8058566374453,128,14479,94414305,CLX5
2025-09-24 19:45:11.817234863+00:00,160,1,432669,C,B,64.81,1,26,8058566381249,128,14931,94414343,CLX5
2025-09-24 19:45:11.817890827+00:00,160,1,432669,M,B,64.81,1,26,8058566381419,128,18011,94414378,CLX5
2025-09-24 19:45:11.818384995+00:00,160,1,432669,A,B,64.82,1,26,8058566382335,128,16814,94414390,CLX5
2025-09-24 19:45:11.818396187+00:00,160,1,432669,C,B,64.8,1,26,8058566378313,128,14419,94414391,CLX5
2025-09-24 19:45:11.818879815+00:00,160,1,432669,C,B,64.82,2,26,8058566382145,128,14361,94414406,CLX5
2025-09-24 19:45:11.819058193+00:00,160,1,432669,M,B,64.82,1,26,8058566381254,128,14828,94414409,CLX5
2025-09-24 19:45:11.819254715+00:00,160,1,432669,M,B,64.81,3,26,8058566372703,128,14759,94414418,CLX5
2025-09-24 19:45:11.820292201+00:00,160,1,432669,M,A,64.84,1,26,8058566173085,128,13930,94414453,CLX5
2025-09-24 19:45:11.820439227+00:00,160,1,432669,C,B,64.82,1,26,8058566382335,128,17636,94414458,CLX5
2025-09-24 19:45:11.821027047+00:00,160,1,432669,A,A,64.89,1,26,8058566382371,128,13428,94414482,CLX5
2025-09-24 19:45:11.821460239+00:00,160,1,432669,T,A,64.82,1,26,8058566382386,0,14467,94414511,CLX5
2025-09-24 19:45:11.821460239+00:00,160,1,432669,F,B,64.82,1,26,8058566382147,0,14467,94414511,CLX5
2025-09-24 19:45:11.821460239+00:00,160,1,432669,C,B,64.82,1,26,8058566382147,128,14427,94414512,CLX5
2025-09-24 19:45:11.823647501+00:00,160,1,432669,A,B,64.82,1,26,8058566382454,128,18076,94414812,CLX5
2025-09-24 19:45:11.824265491+00:00,160,1,432669,C,A,64.83,2,26,8058566367066,128,15369,94414874,CLX5
2025-09-24 19:45:11.824301385+00:00,160,1,432669,C,A,64.83,1,26,8058566367057,128,15272,94414881,CLX5
2025-09-24 19:45:11.824883695+00:00,160,1,432669,T,A,64.82,2,26,8058566382479,0,14823,94414896,CLX5
2025-09-24 19:45:11.824883695+00:00,160,1,432669,F,B,64.82,1,26,8058566381254,0,14823,94414896,CLX5
2025-09-24 19:45:11.824883695+00:00,160,1,432669,F,B,64.82,1,26,8058566382454,0,14823,94414896,CLX5
2025-09-24 19:45:11.824883695+00:00,160,1,432669,C,B,64.82,1,26,8058566381254,0,14846,94414897,CLX5
2025-09-24 19:45:11.824883695+00:00,160,1,432669,C,B,64.82,1,26,8058566382454,128,14846,94414897,CLX5
2025-09-24 19:45:11.825423653+00:00,160,1,432669,C,B,64.81,3,26,8058566372703,128,14788,94414906,CLX5
2025-09-24 19:45:11.827079983+00:00,160,1,432669,A,B,64.8,1,26,8058566382494,128,17732,94414955,CLX5
2025-09-24 19:45:11.827082671+00:00,160,1,432669,C,B,64.74,1,26,8058566374787,128,14969,94414956,CLX5
2025-09-24 19:45:11.827853921+00:00,160,1,432669,A,A,64.88,1,26,8058566382504,128,13636,94414972,CLX5
2025-09-24 19:45:11.829233091+00:00,160,1,432669,A,B,64.82,1,26,8058566382524,128,17621,94415043,CLX5
2025-09-24 19:45:11.829561589+00:00,160,1,432669,A,B,64.82,1,26,8058566382530,128,18461,94415054,CLX5
2025-09-24 19:45:11.829562799+00:00,160,1,432669,A,B,64.82,1,26,8058566382531,128,15207,94415056,CLX5
2025-09-24 19:45:11.830585479+00:00,160,1,432669,A,B,64.81,1,26,8058566382556,128,15081,94415111,CLX5
2025-09-24 19:45:11.830586921+00:00,160,1,432669,C,B,64.75,1,26,8058566374004,128,14572,94415112,CLX5
2025-09-24 19:45:11.830587783+00:00,160,1,432669,C,B,64.76,1,26,8058566374003,128,18065,94415113,CLX5
2025-09-24 19:45:11.830721045+00:00,160,1,432669,C,B,64.81,1,26,8058566382556,128,14454,94415157,CLX5
2025-09-24 19:45:11.830932851+00:00,160,1,432669,C,B,64.82,1,26,8058566382530,128,14673,94415165,CLX5
2025-09-24 19:45:11.831309691+00:00,160,1,432669,T,A,64.82,3,26,8058566382570,0,14689,94415190,CLX5
2025-09-24 19:45:11.831309691+00:00,160,1,432669,F,B,64.82,1,26,8058566382524,0,14689,94415190,CLX5
2025-09-24 19:45:11.831309691+00:00,160,1,432669,F,B,64.82,1,26,8058566382531,0,14689,94415190,CLX5
2025-09-24 19:45:11.831309691+00:00,160,1,432669,C,B,64.82,1,26,8058566382524,0,18509,94415191,CLX5
2025-09-24 19:45:11.831309691+00:00,160,1,432669,C,B,64.82,1,26,8058566382531,128,18509,94415191,CLX5
2025-09-24 19:45:11.831313185+00:00,160,1,432669,A,B,64.82,1,26,8058566382571,128,18312,94415194,CLX5
2025-09-24 19:45:11.831371703+00:00,160,1,432669,T,A,64.82,2,26,8058566382572,0,17927,94415198,CLX5
2025-09-24 19:45:11.831371703+00:00,160,1,432669,F,B,64.82,1,26,8058566382571,0,17927,94415198,CLX5
2025-09-24 19:45:11.831371703+00:00,160,1,432669,C,B,64.82,1,26,8058566382571,128,15148,94415199,CLX5
2025-09-24 19:45:11.831504889+00:00,160,1,432669,A,A,64.87,1,26,8058566382574,128,14670,94415205,CLX5
2025-09-24 19:45:11.831565577+00:00,160,1,432669,A,A,64.87,1,26,8058566382575,128,14399,94415208,CLX5
2025-09-24 19:45:11.836190865+00:00,160,1,432669,T,A,64.82,1,26,8058566382615,128,14874,94415333,CLX5
2025-09-24 19:45:11.836623767+00:00,160,1,432669,T,A,64.82,1,26,8058566382622,128,13608,94415358,CLX5
2025-09-24 19:45:11.837466629+00:00,160,1,432669,C,A,64.83,2,26,8058566367062,128,15209,94415408,CLX5
2025-09-24 19:45:11.837466995+00:00,160,1,432669,C,A,64.87,1,26,8058566382574,128,14606,94415410,CLX5
2025-09-24 19:45:11.837660407+00:00,160,1,432669,A,B,64.82,1,26,8058566382652,128,17866,94415423,CLX5
2025-09-24 19:45:11.837667741+00:00,160,1,432669,A,B,64.82,2,26,8058566382653,128,15659,94415425,CLX5
2025-09-24 19:45:11.837870579+00:00,160,1,432669,A,B,64.82,3,26,8058566382659,128,17020,94415444,CLX5
2025-09-24 19:45:11.838007435+00:00,160,1,432669,A,B,64.82,3,26,8058566382663,128,19480,94415454,CLX5
2025-09-24 19:45:11.840495487+00:00,160,1,432669,C,B,64.82,3,26,8058566382663,128,19318,94415567,CLX5
2025-09-24 19:45:11.840517471+00:00,160,1,432669,T,A,64.82,2,26,8058566382694,0,14124,94415568,CLX5
2025-09-24 19:45:11.840517471+00:00,160,1,432669,F,B,64.82,1,26,8058566382652,0,14124,94415568,CLX5
2025-09-24 19:45:11.840517471+00:00,160,1,432669,F,B,64.82,1,26,8058566382653,0,14124,94415568,CLX5
2025-09-24 19:45:11.840517471+00:00,160,1,432669,C,B,64.82,1,26,8058566382652,0,14124,94415568,CLX5
2025-09-24 19:45:11.840517471+00:00,160,1,432669,M,B,64.82,1,26,8058566382653,128,14124,94415568,CLX5
2025-09-24 19:45:11.840520101+00:00,160,1,432669,C,B,64.8,1,26,8058566382494,128,15313,94415573,CLX5
2025-09-24 19:45:11.840541603+00:00,160,1,432669,C,B,64.79,1,26,8058566382239,128,17856,94415586,CLX5
2025-09-24 19:45:11.840541751+00:00,160,1,432669,C,B,64.78,1,26,8058566379864,128,14339,94415587,CLX5
2025-09-24 19:45:11.840541901+00:00,160,1,432669,C,B,64.77,1,26,8058566377719,128,17251,94415588,CLX5
2025-09-24 19:45:11.840542049+00:00,160,1,432669,T,A,64.82,1,26,8058566382698,0,14676,94415589,CLX5
2025-09-24 19:45:11.840542049+00:00,160,1,432669,F,B,64.82,1,26,8058566382653,0,14676,94415589,CLX5
2025-09-24 19:45:11.840542049+00:00,160,1,432669,C,B,64.82,1,26,8058566382653,128,22419,94415590,CLX5
2025-09-24 19:45:11.840542229+00:00,160,1,432669,T,A,64.82,2,26,8058566382699,0,13517,94415591,CLX5
2025-09-24 19:45:11.840542229+00:00,160,1,432669,F,B,64.82,2,26,8058566382659,0,13517,94415591,CLX5
2025-09-24 19:45:11.840542229+00:00,160,1,432669,M,B,64.82,1,26,8058566382659,128,13517,94415591,CLX5
2025-09-24 19:45:11.840571997+00:00,160,1,432669,T,A,64.82,2,26,8058566382700,0,15023,94415596,CLX5
2025-09-24 19:45:11.840571997+00:00,160,1,432669,F,B,64.82,1,26,8058566382659,0,15023,94415596,CLX5
2025-09-24 19:45:11.840571997+00:00,160,1,432669,C,B,64.82,1,26,8058566382659,128,17592,94415597,CLX5
2025-09-24 19:45:11.840573705+00:00,160,1,432669,C,B,64.81,1,26,8058566382154,128,15176,94415601,CLX5
2025-09-24 19:45:11.841046273+00:00,160,1,432669,A,B,64.82,1,26,8058566382704,128,14436,94415614,CLX5
2025-09-24 19:45:11.841347451+00:00,160,1,432669,A,A,64.83,2,26,8058566382713,128,16217,94415639,CLX5
2025-09-24 19:45:11.841884411+00:00,160,1,432669,C,A,64.88,1,26,8058566382504,128,14357,94415665,CLX5
2025-09-24 19:45:11.841884559+00:00,160,1,432669,C,A,64.89,1,26,8058566382371,128,18174,94415666,CLX5
2025-09-24 19:45:11.842283927+00:00,160,1,432669,M,B,64.8,1,26,8058566379297,128,14415,94415671,CLX5
2025-09-24 19:45:11.843495759+00:00,160,1,432669,M,A,64.94,1,26,8058565075241,128,14461,94415786,CLX5
2025-09-24 19:45:11.843865975+00:00,160,1,432669,A,B,64.82,1,26,8058566382753,128,17895,94415795,CLX5
2025-09-24 19:45:11.844378401+00:00,160,1,432669,C,B,64.82,1,26,8058566382753,128,17532,94415816,CLX5
2025-09-24 19:45:11.846470071+00:00,160,1,432669,C,B,64.81,2,26,8058566382164,128,18562,94415883,CLX5
2025-09-24 19:45:11.846715571+00:00,160,1,432669,A,A,64.83,2,26,8058566382785,128,14831,94415899,CLX5
2025-09-24 19:45:11.847861895+00:00,160,1,432669,A,A,64.83,1,26,8058566382798,128,18272,94415949,CLX5
2025-09-24 19:45:11.849971537+00:00,160,1,432669,M,A,64.95,1,26,8058565075241,128,15778,94415985,CLX5
2025-09-24 19:45:11.850644621+00:00,160,1,432669,A,B,64.82,1,26,8058566382815,128,16901,94416020,CLX5
2025-09-24 19:45:11.851114271+00:00,160,1,432669,C,A,64.83,2,26,8058566382785,128,14169,94416031,CLX5
2025-09-24 19:45:11.853074389+00:00,160,1,432669,A,A,64.89,1,26,8058566382837,128,14464,94416107,CLX5
2025-09-24 19:45:11.853098963+00:00,160,1,432669,A,A,64.83,2,26,8058566382839,128,17828,94416116,CLX5
2025-09-24 19:45:11.853123329+00:00,160,1,432669,A,A,64.83,1,26,8058566382840,128,14769,94416117,CLX5
2025-09-24 19:45:11.853736605+00:00,160,1,432669,C,B,64.82,1,26,8058566382704,128,14288,94416137,CLX5
2025-09-24 19:45:11.855669173+00:00,160,1,432669,C,A,64.83,2,26,8058566382839,128,18229,94416166,CLX5
2025-09-24 19:45:11.857106613+00:00,160,1,432669,A,B,64.79,1,26,8058566382871,128,17695,94416193,CLX5
2025-09-24 19:45:11.860530669+00:00,160,1,432669,C,B,64.82,1,26,8058566382815,128,14710,94416282,CLX5
2025-09-24 19:45:11.862155955+00:00,160,1,432669,T,A,64.82,1,26,8058566382798,0,14863,94416335,CLX5
2025-09-24 19:45:11.862155955+00:00,160,1,432669,F,A,64.82,1,26,8058566382798,0,14863,94416335,CLX5
2025-09-24 19:45:11.862155955+00:00,160,1,432669,C,A,64.83,1,26,8058566382798,128,14201,94416336,CLX5
2025-09-24 19:45:11.864927619+00:00,160,1,432669,T,A,64.82,1,26,8058566382935,128,14655,94416414,CLX5
2025-09-24 19:45:11.865102813+00:00,160,1,432669,C,B,64.16,2,26,8058566381395,128,14710,94416419,CLX5
2025-09-24 19:45:11.867284585+00:00,160,1,432669,A,A,64.83,1,26,8058566382955,128,15351,94416488,CLX5
2025-09-24 19:45:11.868487295+00:00,160,1,432669,A,A,64.83,2,26,8058566382963,128,18114,94416527,CLX5
2025-09-24 19:45:11.871897123+00:00,160,1,432669,M,A,64.82,1,26,8058566382955,128,17895,94416587,CLX5
2025-09-24 19:45:11.872113711+00:00,160,1,432669,A,A,64.88,1,26,8058566382984,128,14975,94416591,CLX5
2025-09-24 19:45:11.872133427+00:00,160,1,432669,T,N,64.82,1,26,0,0,19110,94416599,CLX5
2025-09-24 19:45:11.872133427+00:00,160,1,432669,F,N,64.82,1,26,8058566382955,0,19110,94416599,CLX5
2025-09-24 19:45:11.872133427+00:00,160,1,432669,C,A,64.82,1,26,8058566382955,128,14440,94416600,CLX5
2025-09-24 19:45:11.872150513+00:00,160,1,432669,A,A,64.83,1,26,8058566382990,128,16113,94416604,CLX5
2025-09-24 19:45:11.872248449+00:00,160,1,432669,M,A,64.82,1,26,8058566382575,128,14500,94416607,CLX5
2025-09-24 19:45:11.872572243+00:00,160,1,432669,C,A,64.83,1,26,8058566382990,128,18281,94416616,CLX5
2025-09-24 19:45:11.872867025+00:00,160,1,432669,A,A,64.83,1,26,8058566382997,128,18175,94416628,CLX5
2025-09-24 19:45:11.873622513+00:00,160,1,432669,T,B,64.82,1,26,8058566382998,0,17766,94416631,CLX5
2025-09-24 19:45:11.873622513+00:00,160,1,432669,F,A,64.82,1,26,8058566382575,0,17766,94416631,CLX5
2025-09-24 19:45:11.873622513+00:00,160,1,432669,C,A,64.82,1,26,8058566382575,128,14656,94416632,CLX5
2025-09-24 19:45:11.873963395+00:00,160,1,432669,C,A,64.83,1,26,8058566382997,128,14019,94416642,CLX5
2025-09-24 19:45:11.876983899+00:00,160,1,432669,T,A,64.82,1,26,8058566383005,128,17918,94416658,CLX5
2025-09-24 19:45:11.881601949+00:00,160,1,432669,A,A,64.82,1,26,8058566383008,128,17855,94416666,CLX5
2025-09-24 19:45:11.888714813+00:00,160,1,432669,T,N,64.82,1,26,0,0,18424,94416731,CLX5
2025-09-24 19:45:11.888714813+00:00,160,1,432669,F,N,64.82,1,26,8058566383008,0,18424,94416731,CLX5
2025-09-24 19:45:11.888714813+00:00,160,1,432669,C,A,64.82,1,26,8058566383008,128,14705,94416732,CLX5
2025-09-24 19:45:11.892804099+00:00,160,1,432669,C,B,64.78,2,26,8058566381542,128,17701,94416781,CLX5
2025-09-24 19:45:11.893261537+00:00,160,1,432669,A,A,64.82,1,26,8058566383032,128,15764,94416794,CLX5
2025-09-24 19:45:11.893574675+00:00,160,1,432669,A,A,64.82,1,26,8058566383038,128,14290,94416805,CLX5
2025-09-24 19:45:11.894186285+00:00,160,1,432669,A,A,64.82,1,26,8058566383046,128,18137,94416823,CLX5
2025-09-24 19:45:11.901652431+00:00,160,1,432669,T,B,64.82,2,26,8058566383073,0,20889,94416900,CLX5
2025-09-24 19:45:11.901652431+00:00,160,1,432669,F,A,64.82,1,26,8058566383032,0,20889,94416900,CLX5
2025-09-24 19:45:11.901652431+00:00,160,1,432669,F,A,64.82,1,26,8058566383038,0,20889,94416900,CLX5
2025-09-24 19:45:11.901652431+00:00,160,1,432669,C,A,64.82,1,26,8058566383032,0,17135,94416901,CLX5
2025-09-24 19:45:11.901652431+00:00,160,1,432669,C,A,64.82,1,26,8058566383038,128,17135,94416901,CLX5
2025-09-24 19:45:11.902156831+00:00,160,1,432669,M,B,64.81,3,26,8058566373409,128,17906,94416904,CLX5
2025-09-24 19:45:11.904466393+00:00,160,1,432669,C,A,64.82,1,26,8058566383046,128,18472,94416924,CLX5
2025-09-24 19:45:11.906217913+00:00,160,1,432669,A,A,64.82,1,26,8058566383084,128,17444,94416942,CLX5
2025-09-24 19:45:11.906996457+00:00,160,1,432669,T,B,64.82,1,26,8058566383088,0,17808,94416952,CLX5
2025-09-24 19:45:11.906996457+00:00,160,1,432669,F,A,64.82,1,26,8058566383084,0,17808,94416952,CLX5
2025-09-24 19:45:11.906996457+00:00,160,1,432669,C,A,64.82,1,26,8058566383084,128,14523,94416953,CLX5
2025-09-24 19:45:11.911443865+00:00,160,1,432669,A,B,63.67,4,26,8058566383096,128,17742,94416983,CLX5
2025-09-24 19:45:11.911503075+00:00,160,1,432669,A,A,64.83,1,26,8058566383097,128,15441,94416984,CLX5
2025-09-24 19:45:11.911659529+00:00,160,1,432669,A,B,64.81,1,26,8058566383098,128,18206,94416985,CLX5
2025-09-24 19:45:11.917136433+00:00,160,1,432669,A,B,64.82,1,26,8058566383106,128,16678,94417000,CLX5
2025-09-24 19:45:11.917517403+00:00,160,1,432669,C,B,64.81,1,26,8058566379505,128,17616,94417014,CLX5
2025-09-24 19:45:11.917704805+00:00,160,1,432669,A,B,64.81,1,26,8058566383109,128,18131,94417016,CLX5
2025-09-24 19:45:11.928766109+00:00,160,1,432669,C,A,64.83,2,26,8058566382963,128,15261,94417041,CLX5
2025-09-24 19:45:11.928934257+00:00,160,1,432669,C,B,64.81,1,26,8058566383109,128,15004,94417046,CLX5
2025-09-24 19:45:11.928939113+00:00,160,1,432669,C,B,64.81,1,26,8058566383098,128,17901,94417047,CLX5
2025-09-24 19:45:11.941681053+00:00,160,1,432669,A,A,64.86,2,26,8058566383122,128,18826,94417053,CLX5
2025-09-24 19:45:11.941685161+00:00,160,1,432669,A,A,64.87,2,26,8058566383123,128,14582,94417054,CLX5
2025-09-24 19:45:11.956145887+00:00,160,1,432669,A,A,64.87,1,26,8058566383138,128,17909,94417098,CLX5
2025-09-24 19:45:11.963279255+00:00,160,1,432669,M,A,64.94,1,26,8058565075241,128,14035,94417128,CLX5
2025-09-24 19:45:11.964999001+00:00,160,1,432669,T,A,64.82,1,26,8058566383097,0,17784,94417135,CLX5
2025-09-24 19:45:11.964999001+00:00,160,1,432669,F,A,64.82,1,26,8058566383097,0,17784,94417135,CLX5
2025-09-24 19:45:11.964999001+00:00,160,1,432669,F,B,64.82,1,26,8058566383106,0,17784,94417135,CLX5
2025-09-24 19:45:11.964999001+00:00,160,1,432669,C,B,64.82,1,26,8058566383106,0,14686,94417136,CLX5
2025-09-24 19:45:11.964999001+00:00,160,1,432669,C,A,64.83,1,26,8058566383097,128,14686,94417136,CLX5
2025-09-24 19:45:11.965257133+00:00,160,1,432669,A,A,64.83,2,26,8058566383159,128,15154,94417141,CLX5
2025-09-24 19:45:11.965263699+00:00,160,1,432669,A,A,64.86,1,26,8058566383160,128,15243,94417142,CLX5
2025-09-24 19:45:11.968699791+00:00,160,1,432669,M,A,64.95,1,26,8058565075241,128,13927,94417153,CLX5
2025-09-24 19:45:11.970675921+00:00,160,1,432669,A,A,64.82,1,26,8058566383166,128,17790,94417167,CLX5
2025-09-24 19:45:11.971010525+00:00,160,1,432669,M,A,64.82,1,26,8058566379610,128,14783,94417175,CLX5
2025-09-24 19:45:11.974883089+00:00,160,1,432669,M,A,64.83,1,26,8058566383166,128,17624,94417188,CLX5
2025-09-24 19:45:11.975596203+00:00,160,1,432669,A,A,65.9,1,26,8058566383177,128,18099,94417193,CLX5
2025-09-24 19:45:11.975648253+00:00,160,1,432669,A,B,64.16,2,26,8058566383179,128,14398,94417196,CLX5
2025-09-24 19:45:11.977687105+00:00,160,1,432669,T,B,64.82,1,26,8058566383180,0,17875,94417199,CLX5
2025-09-24 19:45:11.977687105+00:00,160,1,432669,F,A,64.82,1,26,8058566379610,0,17875,94417199,CLX5
2025-09-24 19:45:11.977687105+00:00,160,1,432669,C,A,64.82,1,26,8058566379610,128,14491,94417200,CLX5
2025-09-24 19:45:12.079261781+00:00,160,1,432669,A,B,64.82,1,26,8058566383339,128,17703,94417425,CLX5
2025-09-24 19:45:12.465013447+00:00,160,1,432669,A,B,64.81,1,26,8058566383639,128,17706,94417840,CLX5
2025-09-24 19:45:12.908634181+00:00,160,1,432669,C,A,64.83,2,26,8058566383159,128,15026,94418019,CLX5
2025-09-24 19:45:13.061907967+00:00,160,1,432669,A,A,64.83,2,26,8058566383729,128,20938,94418119,CLX5
2025-09-24 19:45:13.062081643+00:00,160,1,432669,T,A,64.82,1,26,8058566383730,0,17732,94418123,CLX5
2025-09-24 19:45:13.062081643+00:00,160,1,432669,F,B,64.82,1,26,8058566383339,0,17732,94418123,CLX5
2025-09-24 19:45:13.062081643+00:00,160,1,432669,C,B,64.82,1,26,8058566383339,128,14576,94418124,CLX5
2025-09-24 19:45:13.062435753+00:00,160,1,432669,A,A,64.83,1,26,8058566383734,128,18482,94418154,CLX5
2025-09-24 19:45:13.062664645+00:00,160,1,432669,A,A,64.83,1,26,8058566383738,128,14838,94418166,CLX5
2025-09-24 19:45:13.062697533+00:00,160,1,432669,A,A,64.83,1,26,8058566383740,128,14922,94418168,CLX5
2025-09-24 19:45:13.075172837+00:00,160,1,432669,C,A,64.83,1,26,8058566383740,128,15031,94418373,CLX5
2025-09-24 19:45:13.075186563+00:00,160,1,432669,C,A,64.83,1,26,8058566383738,128,16871,94418374,CLX5
2025-09-24 19:45:13.075188195+00:00,160,1,432669,C,A,64.83,1,26,8058566383734,128,14996,94418375,CLX5
2025-09-24 19:45:13.155970473+00:00,160,1,432669,A,B,64.77,2,26,8058566383894,128,17924,94418753,CLX5
2025-09-24 19:45:13.196093229+00:00,160,1,432669,M,B,63.66,4,26,8058566373409,128,18608,94418824,CLX5
2025-09-24 19:45:13.738185763+00:00,160,1,432669,A,B,64.8,1,26,8058566384076,128,18020,94419058,CLX5
2025-09-24 19:45:14.195656131+00:00,160,1,432669,A,B,64.78,1,26,8058566384096,128,18199,94419091,CLX5
2025-09-24 19:45:15.113862315+00:00,160,1,432669,C,A,65.04,1,26,8058565929843,128,18662,94419105,CLX5
2025-09-24 19:45:15.594653377+00:00,160,1,432669,C,A,64.83,1,26,8058566370157,128,14564,94419138,CLX5
2025-09-24 19:45:16.380353247+00:00,160,1,432669,A,B,64.81,3,26,8058566384177,128,18625,94419446,CLX5
2025-09-24 19:45:16.468598141+00:00,160,1,432669,C,B,64.16,2,26,8058566383179,128,17252,94419505,CLX5
2025-09-24 19:45:16.685669579+00:00,160,1,432669,A,B,64.77,1,26,8058566384269,128,17310,94419615,CLX5
2025-09-24 19:45:16.885255485+00:00,160,1,432669,A,B,64.16,2,26,8058566384286,128,18572,94419640,CLX5
2025-09-24 19:45:16.991933985+00:00,160,1,432669,C,B,64.16,2,26,8058566384286,128,17860,94419738,CLX5
2025-09-24 19:45:18.879696783+00:00,160,1,432669,C,B,64.75,1,26,8058566378200,128,20121,94419863,CLX5
2025-09-24 19:45:19.618332289+00:00,160,1,432669,A,B,64.81,1,26,8058566384370,128,23401,94419867,CLX5
2025-09-24 19:45:20.425853053+00:00,160,1,432669,C,A,64.83,2,26,8058566383729,128,18860,94419896,CLX5
2025-09-24 19:45:20.459651703+00:00,160,1,432669,A,A,64.83,2,26,8058566384417,128,14730,94420007,CLX5
2025-09-24 19:45:21.380519343+00:00,160,1,432669,A,B,64.81,3,26,8058566384486,128,20708,94420321,CLX5
2025-09-24 19:45:21.380684551+00:00,160,1,432669,C,A,64.83,2,26,8058566384417,128,14832,94420324,CLX5
2025-09-24 19:45:21.380881535+00:00,160,1,432669,A,B,64.82,3,26,8058566384488,128,17307,94420327,CLX5
2025-09-24 19:45:21.381118797+00:00,160,1,432669,A,B,64.82,1,26,8058566384490,128,13215,94420334,CLX5
2025-09-24 19:45:21.381254461+00:00,160,1,432669,A,B,64.82,1,26,8058566384496,128,14312,94420349,CLX5
2025-09-24 19:45:21.381350263+00:00,160,1,432669,M,B,64.81,3,26,8058566373409,128,14688,94420355,CLX5
2025-09-24 19:45:21.381645431+00:00,160,1,432669,C,A,64.83,1,26,8058566382840,128,18300,94420361,CLX5
2025-09-24 19:45:21.381715335+00:00,160,1,432669,A,B,64.82,1,26,8058566384499,128,17288,94420365,CLX5
2025-09-24 19:45:21.484043651+00:00,160,1,432669,A,B,64.82,3,26,8058566384514,128,16335,94420416,CLX5
2025-09-24 19:45:21.486628355+00:00,160,1,432669,A,B,64.82,1,26,8058566384532,128,15835,94420493,CLX5
2025-09-24 19:45:21.486816757+00:00,160,1,432669,C,B,64.82,1,26,8058566384532,128,15486,94420501,CLX5
2025-09-24 19:45:21.622520151+00:00,160,1,432669,A,B,64.82,1,26,8058566384552,128,19098,94420533,CLX5
2025-09-24 19:45:21.622679081+00:00,160,1,432669,C,B,64.82,1,26,8058566384552,128,14387,94420539,CLX5
2025-09-24 19:45:21.622679543+00:00,160,1,432669,C,A,64.83,1,26,8058566382250,128,15478,94420540,CLX5
2025-09-24 19:45:21.623287235+00:00,160,1,432669,A,B,64.82,1,26,8058566384561,128,15763,94420571,CLX5
2025-09-24 19:45:21.623314863+00:00,160,1,432669,A,B,64.82,1,26,8058566384564,128,18654,94420578,CLX5
2025-09-24 19:45:21.623556137+00:00,160,1,432669,A,B,64.82,1,26,8058566384576,128,14400,94420604,CLX5
2025-09-24 19:45:21.624182899+00:00,160,1,432669,C,A,64.83,1,26,8058566365450,128,18239,94420663,CLX5
2025-09-24 19:45:21.624510719+00:00,160,1,432669,C,B,64.82,1,26,8058566384576,128,15624,94420676,CLX5
2025-09-24 19:45:21.624940473+00:00,160,1,432669,A,B,64.82,1,26,8058566384598,128,18367,94420695,CLX5
2025-09-24 19:45:21.624954643+00:00,160,1,432669,C,B,64.82,1,26,8058566384598,128,15362,94420696,CLX5
2025-09-24 19:45:21.625166275+00:00,160,1,432669,A,B,64.82,1,26,8058566384599,128,15264,94420702,CLX5
2025-09-24 19:45:21.631965769+00:00,160,1,432669,C,B,64.76,2,26,8058566378804,128,17900,94420724,CLX5
2025-09-24 19:45:21.635501639+00:00,160,1,432669,C,B,64.82,1,26,8058566384564,128,19134,94420726,CLX5
2025-09-24 19:45:21.635502559+00:00,160,1,432669,C,B,64.82,1,26,8058566384599,128,15406,94420727,CLX5
2025-09-24 19:45:21.641034547+00:00,160,1,432669,C,B,64.82,3,26,8058566384514,128,18806,94420776,CLX5
2025-09-24 19:45:21.641190099+00:00,160,1,432669,A,A,64.83,1,26,8058566384612,128,15493,94420779,CLX5
2025-09-24 19:45:21.856051081+00:00,160,1,432669,A,B,64.82,6,26,8058566384655,128,19497,94420872,CLX5
2025-09-24 19:45:21.856223491+00:00,160,1,432669,C,A,64.83,1,26,8058566384612,128,16074,94420877,CLX5
2025-09-24 19:45:21.864189045+00:00,160,1,432669,A,B,64.82,3,26,8058566384664,128,19027,94420907,CLX5
2025-09-24 19:45:23.901429433+00:00,160,1,432669,C,A,64.83,2,26,8058566382713,128,15044,94421249,CLX5
2025-09-24 19:45:23.901883743+00:00,160,1,432669,A,B,64.82,1,26,8058566384807,128,15859,94421286,CLX5
2025-09-24 19:45:23.902003449+00:00,160,1,432669,C,B,64.82,1,26,8058566384807,128,15467,94421299,CLX5
2025-09-24 19:45:23.902170751+00:00,160,1,432669,A,B,64.82,1,26,8058566384815,128,18642,94421309,CLX5
2025-09-24 19:45:23.902175781+00:00,160,1,432669,C,A,64.86,2,26,8058566383122,128,14576,94421310,CLX5
2025-09-24 19:45:23.902177337+00:00,160,1,432669,C,A,64.83,1,26,8058566382305,128,15759,94421314,CLX5
2025-09-24 19:45:23.902494449+00:00,160,1,432669,A,B,64.82,1,26,8058566384825,128,18995,94421340,CLX5
2025-09-24 19:45:23.902725895+00:00,160,1,432669,C,A,64.83,3,26,8058566365804,128,15751,94421345,CLX5
2025-09-24 19:45:23.902904775+00:00,160,1,432669,C,B,64.82,1,26,8058566384825,128,15273,94421357,CLX5
2025-09-24 19:45:23.903716705+00:00,160,1,432669,A,A,64.83,2,26,8058566384843,128,15147,94421400,CLX5
2025-09-24 19:45:23.904054379+00:00,160,1,432669,C,A,64.83,1,26,8058566367102,128,19450,94421407,CLX5
2025-09-24 19:45:23.904789343+00:00,160,1,432669,A,B,64.82,1,26,8058566384848,128,17157,94421423,CLX5
2025-09-24 19:45:23.906104945+00:00,160,1,432669,A,A,64.83,2,26,8058566384860,128,14574,94421468,CLX5
2025-09-24 19:45:23.906186293+00:00,160,1,432669,A,A,64.83,1,26,8058566384861,128,15776,94421471,CLX5
2025-09-24 19:45:23.906836587+00:00,160,1,432669,C,B,64.82,1,26,8058566384815,128,15509,94421478,CLX5
2025-09-24 19:45:23.906981271+00:00,160,1,432669,A,A,64.83,1,26,8058566384866,128,15716,94421483,CLX5
2025-09-24 19:45:23.907956895+00:00,160,1,432669,C,B,64.82,1,26,8058566384848,128,17618,94421512,CLX5
2025-09-24 19:45:23.922629043+00:00,160,1,432669,A,A,64.83,1,26,8058566384887,128,17577,94421560,CLX5
2025-09-24 19:45:23.931942705+00:00,160,1,432669,A,A,64.86,2,26,8058566384898,128,18660,94421597,CLX5
2025-09-24 19:45:24.032228287+00:00,160,1,432669,A,B,64.78,2,26,8058566384969,128,17774,94421778,CLX5
2025-09-24 19:45:24.469187695+00:00,160,1,432669,C,B,64.82,3,26,8058566384664,128,15362,94421887,CLX5
2025-09-24 19:45:25.232447495+00:00,160,1,432669,C,B,64.78,2,26,8058566384969,128,19028,94421937,CLX5
2025-09-24 19:45:25.232885927+00:00,160,1,432669,C,B,64.82,1,26,8058566384561,128,15737,94421950,CLX5
2025-09-24 19:45:25.232920639+00:00,160,1,432669,C,B,64.82,1,26,8058566384499,128,27229,94421952,CLX5
2025-09-24 19:45:26.521937503+00:00,160,1,432669,A,B,64.82,1,26,8058566385073,128,15072,94422014,CLX5
2025-09-24 19:45:26.521959177+00:00,160,1,432669,A,B,64.82,3,26,8058566385074,128,18145,94422017,CLX5
2025-09-24 19:45:26.522035499+00:00,160,1,432669,A,B,64.82,1,26,8058566385076,128,15000,94422019,CLX5
2025-09-24 19:45:26.522046239+00:00,160,1,432669,A,B,64.82,1,26,8058566385080,128,16001,94422030,CLX5
2025-09-24 19:45:26.522093975+00:00,160,1,432669,C,A,64.83,1,26,8058566384887,128,15532,94422051,CLX5
2025-09-24 19:45:26.522133699+00:00,160,1,432669,A,B,64.82,1,26,8058566385092,128,15553,94422057,CLX5
2025-09-24 19:45:26.522258647+00:00,160,1,432669,A,B,64.82,1,26,8058566385095,128,15185,94422066,CLX5
2025-09-24 19:45:26.522321045+00:00,160,1,432669,C,B,64.82,1,26,8058566385092,128,16940,94422067,CLX5
2025-09-24 19:45:26.522349689+00:00,160,1,432669,C,B,64.82,1,26,8058566385073,128,18426,94422082,CLX5
2025-09-24 19:45:26.522407171+00:00,160,1,432669,C,B,64.82,1,26,8058566385080,128,17874,94422085,CLX5
2025-09-24 19:45:26.522423569+00:00,160,1,432669,A,A,64.83,1,26,8058566385101,128,19363,94422092,CLX5
2025-09-24 19:45:26.522558577+00:00,160,1,432669,C,A,64.83,1,26,8058566385101,128,15361,94422104,CLX5
2025-09-24 19:45:26.523261669+00:00,160,1,432669,C,A,64.86,1,26,8058566383160,128,16821,94422161,CLX5
2025-09-24 19:45:26.523267313+00:00,160,1,432669,C,A,64.83,1,26,8058566384866,128,15836,94422163,CLX5
2025-09-24 19:45:26.523269521+00:00,160,1,432669,C,B,64.82,1,26,8058566385095,128,14770,94422164,CLX5
2025-09-24 19:45:26.523467963+00:00,160,1,432669,A,A,64.83,1,26,8058566385115,128,15752,94422173,CLX5
2025-09-24 19:45:26.523558795+00:00,160,1,432669,C,B,64.82,1,26,8058566385076,128,15809,94422177,CLX5
2025-09-24 19:45:26.524147689+00:00,160,1,432669,C,A,64.83,1,26,8058566385115,128,15823,94422186,CLX5
2025-09-24 19:45:26.526189115+00:00,160,1,432669,A,B,64.82,1,26,8058566385136,128,18496,94422246,CLX5
2025-09-24 19:45:26.526917341+00:00,160,1,432669,A,B,64.82,1,26,8058566385139,128,14726,94422269,CLX5
2025-09-24 19:45:26.537193361+00:00,160,1,432669,A,A,64.83,1,26,8058566385140,128,18861,94422291,CLX5
2025-09-24 19:45:26.537347051+00:00,160,1,432669,A,A,64.83,1,26,8058566385141,128,14223,94422294,CLX5
2025-09-24 19:45:27.052646971+00:00,160,1,432669,C,A,64.83,1,26,8058566385141,128,18576,94422471,CLX5
2025-09-24 19:45:30.499546303+00:00,160,1,432669,C,B,64.8,1,26,8058566384076,128,19476,94422644,CLX5
2025-09-24 19:45:30.512653621+00:00,160,1,432669,A,A,64.83,1,26,8058566385283,128,19475,94422646,CLX5
2025-09-24 19:45:31.073054655+00:00,160,1,432669,C,B,64.82,3,26,8058566385074,128,22770,94422651,CLX5
2025-09-24 19:45:32.042176367+00:00,160,1,432669,A,B,64.82,3,26,8058566385289,128,19167,94422658,CLX5
2025-09-24 19:45:32.042332361+00:00,160,1,432669,C,A,64.83,1,26,8058566385283,128,20633,94422663,CLX5
2025-09-24 19:45:32.464660423+00:00,160,1,432669,C,B,64.78,1,26,8058566373672,128,17656,94422692,CLX5
2025-09-24 19:45:34.121997399+00:00,160,1,432669,A,B,64.82,1,26,8058566385297,128,25255,94422757,CLX5
2025-09-24 19:45:38.674491649+00:00,160,1,432669,C,B,64.82,3,26,8058566385289,128,20152,94422794,CLX5
2025-09-24 19:45:38.674652441+00:00,160,1,432669,A,A,64.83,1,26,8058566385312,128,19174,94422795,CLX5
2025-09-24 19:45:39.678324573+00:00,160,1,432669,A,B,64.36,5,26,8058566385321,128,19829,94422823,CLX5
2025-09-24 19:45:43.457503715+00:00,160,1,432669,A,B,64.82,1,26,8058566385357,128,18826,94422902,CLX5
2025-09-24 19:45:43.457687987+00:00,160,1,432669,C,A,64.83,1,26,8058566385312,128,18758,94422903,CLX5
2025-09-24 19:45:44.122359087+00:00,160,1,432669,M,B,64.81,1,26,8058566379297,128,18858,94422909,CLX5
2025-09-24 19:45:44.373540511+00:00,160,1,432669,A,A,64.83,1,26,8058566385362,128,19536,94422913,CLX5
2025-09-24 19:45:44.373716623+00:00,160,1,432669,A,A,64.83,1,26,8058566385363,128,16160,94422915,CLX5
2025-09-24 19:45:44.851685367+00:00,160,1,432669,M,B,64.72,1,26,8058566360017,128,22200,94422993,CLX5
2025-09-24 19:45:45.000167737+00:00,160,1,432669,C,B,64.77,1,26,8058566376562,128,20224,94423058,CLX5
2025-09-24 19:45:45.000247741+00:00,160,1,432669,C,B,64.77,1,26,8058566376645,128,17567,94423065,CLX5
2025-09-24 19:45:45.000251023+00:00,160,1,432669,C,B,64.8,1,26,8058566377365,128,18457,94423066,CLX5
2025-09-24 19:45:45.000255575+00:00,160,1,432669,C,B,64.8,1,26,8058566377367,128,18875,94423067,CLX5
2025-09-24 19:45:45.000258051+00:00,160,1,432669,C,B,64.8,1,26,8058566377375,128,22438,94423068,CLX5
2025-09-24 19:45:45.000260221+00:00,160,1,432669,C,B,64.79,1,26,8058566373663,128,21844,94423069,CLX5
2025-09-24 19:45:45.000263677+00:00,160,1,432669,C,B,64.79,1,26,8058566373664,128,17948,94423070,CLX5
2025-09-24 19:45:45.000269531+00:00,160,1,432669,C,B,64.77,1,26,8058566374406,128,18204,94423071,CLX5
2025-09-24 19:45:48.160526919+00:00,160,1,432669,C,B,64.82,1,26,8058566385139,128,16870,94423235,CLX5
2025-09-24 19:45:49.266389043+00:00,160,1,432669,A,A,64.83,2,26,8058566385448,128,14972,94423381,CLX5
2025-09-24 19:45:50.197609105+00:00,160,1,432669,C,A,64.83,2,26,8058566385448,128,19284,94423411,CLX5
2025-09-24 19:45:50.197664149+00:00,160,1,432669,T,A,64.82,1,26,8058566385458,0,20986,94423413,CLX5
2025-09-24 19:45:50.197664149+00:00,160,1,432669,F,B,64.82,1,26,8058566384488,0,20986,94423413,CLX5
2025-09-24 19:45:50.197664149+00:00,160,1,432669,M,B,64.82,2,26,8058566384488,128,19722,94423414,CLX5
2025-09-24 19:45:50.198007563+00:00,160,1,432669,A,A,64.83,2,26,8058566385463,128,17911,94423429,CLX5
2025-09-24 19:45:50.198632251+00:00,160,1,432669,A,B,64.82,1,26,8058566385468,128,19135,94423442,CLX5
2025-09-24 19:45:50.198633533+00:00,160,1,432669,A,B,64.82,1,26,8058566385469,128,15520,94423443,CLX5
2025-09-24 19:45:50.198647451+00:00,160,1,432669,C,A,64.83,2,26,8058566385463,128,19293,94423447,CLX5
2025-09-24 19:45:50.205587369+00:00,160,1,432669,A,B,64.82,1,26,8058566385475,128,18487,94423467,CLX5
2025-09-24 19:45:50.205588447+00:00,160,1,432669,A,B,64.82,1,26,8058566385476,128,15053,94423468,CLX5
2025-09-24 19:45:50.205741291+00:00,160,1,432669,C,A,64.83,1,26,8058566385363,128,19073,94423470,CLX5
2025-09-24 19:45:50.205763485+00:00,160,1,432669,C,B,64.82,1,26,8058566385476,128,15031,94423472,CLX5
2025-09-24 19:45:50.285580083+00:00,160,1,432669,C,B,64.82,1,26,8058566385469,128,19267,94423476,CLX5
2025-09-24 19:45:50.285732869+00:00,160,1,432669,A,A,64.83,1,26,8058566385479,128,15344,94423478,CLX5
2025-09-24 19:45:50.286311745+00:00,160,1,432669,C,B,64.82,1,26,8058566385468,128,18819,94423480,CLX5
2025-09-24 19:45:50.713324251+00:00,160,1,432669,A,B,64.82,1,26,8058566385486,128,18093,94423504,CLX5
2025-09-24 19:45:50.713458203+00:00,160,1,432669,A,B,64.82,1,26,8058566385487,128,19551,94423505,CLX5
2025-09-24 19:45:50.732673137+00:00,160,1,432669,C,A,64.83,1,26,8058566385479,128,18885,94423508,CLX5
2025-09-24 19:45:50.751679051+00:00,160,1,432669,C,B,64.82,1,26,8058566385486,128,19279,94423511,CLX5
2025-09-24 19:45:50.751821565+00:00,160,1,432669,C,B,64.82,1,26,8058566385487,128,18948,94423512,CLX5
2025-09-24 19:45:50.772668467+00:00,160,1,432669,A,A,64.83,1,26,8058566385492,128,18917,94423514,CLX5
2025-09-24 19:45:52.912333563+00:00,160,1,432669,C,B,64.82,1,26,8058566385475,128,15525,94423616,CLX5
2025-09-24 19:45:52.912342721+00:00,160,1,432669,A,A,64.83,2,26,8058566385529,128,15845,94423617,CLX5
2025-09-24 19:45:54.218591003+00:00,160,1,432669,T,B,64.83,2,26,8058566385540,0,19568,94423670,CLX5
2025-09-24 19:45:54.218591003+00:00,160,1,432669,F,A,64.83,1,26,8058566365417,0,19568,94423670,CLX5
2025-09-24 19:45:54.218591003+00:00,160,1,432669,F,A,64.83,1,26,8058566365429,0,19568,94423670,CLX5
2025-09-24 19:45:54.218591003+00:00,160,1,432669,C,A,64.83,1,26,8058566365417,0,15786,94423671,CLX5
2025-09-24 19:45:54.218591003+00:00,160,1,432669,M,A,64.83,2,26,8058566365429,128,15786,94423671,CLX5
2025-09-24 19:45:54.218920267+00:00,160,1,432669,A,B,64.82,1,26,8058566385541,128,17763,94423672,CLX5
2025-09-24 19:45:54.218925835+00:00,160,1,432669,A,B,64.82,1,26,8058566385542,128,16016,94423673,CLX5
2025-09-24 19:45:54.218952483+00:00,160,1,432669,A,B,64.82,1,26,8058566385543,128,19682,94423675,CLX5
2025-09-24 19:45:54.218964599+00:00,160,1,432669,C,A,64.83,1,26,8058566385492,128,15251,94423676,CLX5
2025-09-24 19:45:54.240859409+00:00,160,1,432669,C,B,64.82,1,26,8058566385542,128,18505,94423689,CLX5
2025-09-24 19:45:54.241648379+00:00,160,1,432669,A,A,64.83,1,26,8058566385548,128,17835,94423692,CLX5
2025-09-24 19:45:54.241806907+00:00,160,1,432669,C,B,64.82,1,26,8058566385543,128,18741,94423699,CLX5
2025-09-24 19:45:54.241984403+00:00,160,1,432669,A,A,64.83,1,26,8058566385551,128,15171,94423700,CLX5
2025-09-24 19:45:54.242092877+00:00,160,1,432669,A,A,64.83,1,26,8058566385552,128,15208,94423702,CLX5
2025-09-24 19:45:54.722628753+00:00,160,1,432669,C,B,64.82,1,26,8058566385541,128,14912,94423735,CLX5
2025-09-24 19:45:54.943436209+00:00,160,1,432669,A,B,64.82,1,26,8058566385620,128,13708,94423973,CLX5
2025-09-24 19:45:54.943726557+00:00,160,1,432669,C,A,64.83,1,26,8058566385552,128,15736,94424001,CLX5
2025-09-24 19:45:54.943991217+00:00,160,1,432669,C,A,64.83,1,26,8058566385551,128,14467,94424027,CLX5
2025-09-24 19:45:54.944077767+00:00,160,1,432669,A,B,64.82,2,26,8058566385633,128,18981,94424037,CLX5
2025-09-24 19:45:54.944089633+00:00,160,1,432669,C,A,64.83,2,26,8058566384860,128,13523,94424045,CLX5
2025-09-24 19:45:54.944131563+00:00,160,1,432669,A,B,64.82,1,26,8058566385640,128,15160,94424049,CLX5
2025-09-24 19:45:54.944137189+00:00,160,1,432669,A,B,64.82,1,26,8058566385641,128,15402,94424050,CLX5
2025-09-24 19:45:54.970814643+00:00,160,1,432669,C,B,64.82,1,26,8058566385641,128,17394,94424291,CLX5
2025-09-24 19:45:54.970871817+00:00,160,1,432669,A,A,64.83,1,26,8058566385700,128,15690,94424293,CLX5
2025-09-24 19:45:54.971046433+00:00,160,1,432669,C,B,64.82,2,26,8058566385633,128,14777,94424296,CLX5
2025-09-24 19:45:54.971046779+00:00,160,1,432669,C,B,64.82,1,26,8058566385640,128,15448,94424298,CLX5
2025-09-24 19:45:54.972681587+00:00,160,1,432669,A,A,64.83,1,26,8058566385703,128,19577,94424306,CLX5
2025-09-24 19:45:54.998171013+00:00,160,1,432669,T,A,64.82,1,26,8058566383166,0,18162,94424331,CLX5
2025-09-24 19:45:54.998171013+00:00,160,1,432669,F,A,64.82,1,26,8058566383166,0,18162,94424331,CLX5
2025-09-24 19:45:54.998171013+00:00,160,1,432669,F,B,64.82,1,26,8058566384488,0,18162,94424331,CLX5
2025-09-24 19:45:54.998171013+00:00,160,1,432669,M,B,64.82,1,26,8058566384488,0,16273,94424332,CLX5
2025-09-24 19:45:54.998171013+00:00,160,1,432669,C,A,64.83,1,26,8058566383166,128,16273,94424332,CLX5
2025-09-24 19:45:54.998457303+00:00,160,1,432669,C,B,64.82,1,26,8058566385620,128,18570,94424345,CLX5
2025-09-24 19:45:55.003963609+00:00,160,1,432669,T,A,64.82,1,26,8058566385723,0,18186,94424370,CLX5
2025-09-24 19:45:55.003963609+00:00,160,1,432669,F,B,64.82,1,26,8058566384488,0,18186,94424370,CLX5
2025-09-24 19:45:55.003963609+00:00,160,1,432669,C,B,64.82,1,26,8058566384488,128,15573,94424371,CLX5
2025-09-24 19:45:55.010155395+00:00,160,1,432669,T,A,64.82,1,26,8058566385725,0,17673,94424374,CLX5
2025-09-24 19:45:55.010155395+00:00,160,1,432669,F,B,64.82,1,26,8058566384490,0,17673,94424374,CLX5
2025-09-24 19:45:55.010155395+00:00,160,1,432669,C,B,64.82,1,26,8058566384490,128,15985,94424375,CLX5
2025-09-24 19:45:55.014667061+00:00,160,1,432669,T,A,64.82,1,26,8058566385727,0,18210,94424380,CLX5
2025-09-24 19:45:55.014667061+00:00,160,1,432669,F,B,64.82,1,26,8058566384496,0,18210,94424380,CLX5
2025-09-24 19:45:55.014667061+00:00,160,1,432669,C,B,64.82,1,26,8058566384496,128,15584,94424381,CLX5
2025-09-24 19:45:55.014903615+00:00,160,1,432669,A,A,64.83,1,26,8058566385728,128,19111,94424382,CLX5
2025-09-24 19:45:55.019333511+00:00,160,1,432669,T,A,64.82,1,26,8058566385730,0,18400,94424384,CLX5
2025-09-24 19:45:55.019333511+00:00,160,1,432669,F,B,64.82,1,26,8058566384655,0,18400,94424384,CLX5
2025-09-24 19:45:55.019333511+00:00,160,1,432669,M,B,64.82,5,26,8058566384655,128,16044,94424385,CLX5
2025-09-24 19:45:55.023994605+00:00,160,1,432669,T,A,64.82,1,26,8058566385731,0,20360,94424386,CLX5
2025-09-24 19:45:55.023994605+00:00,160,1,432669,F,B,64.82,1,26,8058566384655,0,20360,94424386,CLX5
2025-09-24 19:45:55.023994605+00:00,160,1,432669,M,B,64.82,4,26,8058566384655,128,15821,94424387,CLX5
2025-09-24 19:45:55.028296731+00:00,160,1,432669,T,A,64.82,1,26,8058566385735,0,17801,94424396,CLX5
2025-09-24 19:45:55.028296731+00:00,160,1,432669,F,B,64.82,1,26,8058566384655,0,17801,94424396,CLX5
2025-09-24 19:45:55.028296731+00:00,160,1,432669,M,B,64.82,3,26,8058566384655,128,15828,94424397,CLX5
2025-09-24 19:45:55.032753181+00:00,160,1,432669,T,A,64.82,1,26,8058566385744,0,17610,94424412,CLX5
2025-09-24 19:45:55.032753181+00:00,160,1,432669,F,B,64.82,1,26,8058566384655,0,17610,94424412,CLX5
2025-09-24 19:45:55.032753181+00:00,160,1,432669,M,B,64.82,2,26,8058566384655,128,16970,94424413,CLX5
2025-09-24 19:45:55.032984531+00:00,160,1,432669,C,B,64.82,1,26,8058566385136,128,18632,94424419,CLX5
2025-09-24 19:45:55.037522461+00:00,160,1,432669,T,A,64.82,1,26,8058566385751,0,17738,94424432,CLX5
2025-09-24 19:45:55.037522461+00:00,160,1,432669,F,B,64.82,1,26,8058566384655,0,17738,94424432,CLX5
2025-09-24 19:45:55.037522461+00:00,160,1,432669,M,B,64.82,1,26,8058566384655,128,14275,94424433,CLX5
2025-09-24 19:45:55.042378483+00:00,160,1,432669,T,A,64.82,1,26,8058566385752,0,18156,94424436,CLX5
2025-09-24 19:45:55.042378483+00:00,160,1,432669,F,B,64.82,1,26,8058566384655,0,18156,94424436,CLX5
2025-09-24 19:45:55.042378483+00:00,160,1,432669,C,B,64.82,1,26,8058566384655,128,14592,94424437,CLX5
2025-09-24 19:45:55.046997129+00:00,160,1,432669,T,A,64.82,1,26,8058566385753,0,18513,94424440,CLX5
2025-09-24 19:45:55.046997129+00:00,160,1,432669,F,B,64.82,1,26,8058566385297,0,18513,94424440,CLX5
2025-09-24 19:45:55.046997129+00:00,160,1,432669,C,B,64.82,1,26,8058566385297,128,14263,94424441,CLX5
2025-09-24 19:45:55.051431691+00:00,160,1,432669,T,A,64.82,1,26,8058566385774,0,17861,94424585,CLX5
2025-09-24 19:45:55.051431691+00:00,160,1,432669,F,B,64.82,1,26,8058566385357,0,17861,94424585,CLX5
2025-09-24 19:45:55.051431691+00:00,160,1,432669,C,B,64.82,1,26,8058566385357,128,14473,94424586,CLX5
2025-09-24 19:45:55.051734673+00:00,160,1,432669,A,A,64.83,1,26,8058566385777,128,14227,94424595,CLX5
2025-09-24 19:45:55.051751933+00:00,160,1,432669,A,A,64.83,3,26,8058566385778,128,16995,94424597,CLX5
2025-09-24 19:45:55.051791175+00:00,160,1,432669,A,A,64.82,2,26,8058566385779,128,14863,94424598,CLX5
2025-09-24 19:45:55.051960051+00:00,160,1,432669,M,B,63.66,4,26,8058566373409,128,17574,94424602,CLX5
2025-09-24 19:45:55.052192719+00:00,160,1,432669,A,A,64.82,3,26,8058566385782,128,17778,94424612,CLX5
2025-09-24 19:45:55.052200867+00:00,160,1,432669,A,A,64.82,1,26,8058566385783,128,14263,94424622,CLX5
2025-09-24 19:45:55.052337967+00:00,160,1,432669,M,A,64.82,1,26,8058566379062,128,18553,94424637,CLX5
2025-09-24 19:45:55.052346089+00:00,160,1,432669,T,B,64.82,2,26,8058566385787,0,17583,94424643,CLX5
2025-09-24 19:45:55.052346089+00:00,160,1,432669,F,A,64.82,2,26,8058566385779,0,17583,94424643,CLX5
2025-09-24 19:45:55.052346089+00:00,160,1,432669,C,A,64.82,2,26,8058566385779,128,17583,94424643,CLX5
2025-09-24 19:45:55.052534969+00:00,160,1,432669,C,A,64.83,1,26,8058566385362,128,15035,94424662,CLX5
2025-09-24 19:45:55.052787765+00:00,160,1,432669,A,A,64.86,1,26,8058566385797,128,14221,94424689,CLX5
2025-09-24 19:45:55.052868267+00:00,160,1,432669,A,A,64.82,1,26,8058566385803,128,16558,94424710,CLX5
2025-09-24 19:45:55.052887253+00:00,160,1,432669,A,A,64.82,1,26,8058566385804,128,17846,94424713,CLX5
2025-09-24 19:45:55.052906511+00:00,160,1,432669,C,A,64.82,1,26,8058566385803,128,16607,94424719,CLX5
2025-09-24 19:45:55.053024471+00:00,160,1,432669,C,B,64.79,1,26,8058566382871,128,14568,94424733,CLX5
2025-09-24 19:45:55.053213871+00:00,160,1,432669,A,B,64.81,1,26,8058566385814,128,14765,94424748,CLX5
2025-09-24 19:45:55.053520545+00:00,160,1,432669,T,B,64.82,6,26,8058566385825,0,14528,94424769,CLX5
2025-09-24 19:45:55.053520545+00:00,160,1,432669,F,A,64.82,3,26,8058566385782,0,14528,94424769,CLX5
2025-09-24 19:45:55.053520545+00:00,160,1,432669,F,A,64.82,1,26,8058566385783,0,14528,94424769,CLX5
2025-09-24 19:45:55.053520545+00:00,160,1,432669,F,A,64.82,1,26,8058566379062,0,14528,94424769,CLX5
2025-09-24 19:45:55.053520545+00:00,160,1,432669,F,A,64.82,1,26,8058566385804,0,14528,94424769,CLX5
2025-09-24 19:45:55.053520545+00:00,160,1,432669,C,A,64.82,3,26,8058566385782,0,18077,94424770,CLX5
2025-09-24 19:45:55.053520545+00:00,160,1,432669,C,A,64.82,1,26,8058566385783,0,18077,94424770,CLX5
2025-09-24 19:45:55.053520545+00:00,160,1,432669,C,A,64.82,1,26,8058566379062,0,18077,94424770,CLX5
2025-09-24 19:45:55.053520545+00:00,160,1,432669,C,A,64.82,1,26,8058566385804,128,18077,94424770,CLX5
2025-09-24 19:45:55.054312889+00:00,160,1,432669,C,A,64.83,1,26,8058566385777,128,15258,94424828,CLX5
2025-09-24 19:45:55.055685839+00:00,160,1,432669,A,B,64.82,1,26,8058566385854,128,14883,94424873,CLX5
2025-09-24 19:45:55.055689641+00:00,160,1,432669,A,A,64.83,1,26,8058566385860,128,18258,94424883,CLX5
2025-09-24 19:45:55.055787231+00:00,160,1,432669,C,B,64.81,1,26,8058566385814,128,14437,94424905,CLX5
2025-09-24 19:45:55.056033575+00:00,160,1,432669,C,A,64.83,1,26,8058566385860,128,14982,94424920,CLX5
2025-09-24 19:45:55.056282107+00:00,160,1,432669,A,B,64.82,2,26,8058566385878,128,14274,94424928,CLX5
2025-09-24 19:45:55.056307449+00:00,160,1,432669,T,A,64.82,1,26,8058566385880,0,17878,94424932,CLX5
2025-09-24 19:45:55.056307449+00:00,160,1,432669,F,B,64.82,1,26,8058566385854,0,17878,94424932,CLX5
2025-09-24 19:45:55.056307449+00:00,160,1,432669,C,B,64.82,1,26,8058566385854,128,17878,94424932,CLX5
2025-09-24 19:45:55.056365007+00:00,160,1,432669,A,B,64.82,1,26,8058566385882,128,18156,94424936,CLX5
2025-09-24 19:45:55.056774737+00:00,160,1,432669,C,A,64.83,1,26,8058566385703,128,15542,94424963,CLX5
2025-09-24 19:45:55.057625299+00:00,160,1,432669,A,B,64.82,1,26,8058566385895,128,14248,94424975,CLX5
2025-09-24 19:45:55.057972459+00:00,160,1,432669,A,B,64.79,1,26,8058566385900,128,16835,94424991,CLX5
2025-09-24 19:45:55.058484903+00:00,160,1,432669,M,B,64.81,3,26,8058566383096,128,14394,94424998,CLX5
2025-09-24 19:45:55.061124113+00:00,160,1,432669,T,A,64.82,1,26,8058566385925,0,17618,94425059,CLX5
2025-09-24 19:45:55.061124113+00:00,160,1,432669,F,B,64.82,1,26,8058566385878,0,17618,94425059,CLX5
2025-09-24 19:45:55.061124113+00:00,160,1,432669,M,B,64.82,1,26,8058566385878,128,14241,94425060,CLX5
2025-09-24 19:45:55.061629607+00:00,160,1,432669,T,A,64.82,1,26,8058566385926,0,17386,94425070,CLX5
2025-09-24 19:45:55.061629607+00:00,160,1,432669,F,B,64.82,1,26,8058566385878,0,17386,94425070,CLX5
2025-09-24 19:45:55.061629607+00:00,160,1,432669,C,B,64.82,1,26,8058566385878,128,14334,94425071,CLX5
2025-09-24 19:45:55.061630453+00:00,160,1,432669,T,A,64.82,1,26,8058566385927,0,14677,94425073,CLX5
2025-09-24 19:45:55.061630453+00:00,160,1,432669,F,B,64.82,1,26,8058566385882,0,14677,94425073,CLX5
2025-09-24 19:45:55.061630453+00:00,160,1,432669,C,B,64.82,1,26,8058566385882,128,14677,94425073,CLX5
2025-09-24 19:45:55.061898321+00:00,160,1,432669,T,A,64.82,1,26,8058566385928,0,17896,94425077,CLX5
2025-09-24 19:45:55.061898321+00:00,160,1,432669,F,B,64.82,1,26,8058566385895,0,17896,94425077,CLX5
2025-09-24 19:45:55.061898321+00:00,160,1,432669,C,B,64.82,1,26,8058566385895,128,14807,94425078,CLX5
2025-09-24 19:45:55.062140461+00:00,160,1,432669,A,A,64.83,1,26,8058566385929,128,15149,94425086,CLX5
2025-09-24 19:45:55.062161195+00:00,160,1,432669,A,A,64.83,1,26,8058566385930,128,14593,94425087,CLX5
2025-09-24 19:45:55.062534137+00:00,160,1,432669,C,B,64.81,1,26,8058566382010,128,16512,94425096,CLX5
2025-09-24 19:45:55.063476817+00:00,160,1,432669,M,B,63.65,4,26,8058566383096,128,18848,94425119,CLX5
2025-09-24 19:45:55.063617681+00:00,160,1,432669,C,A,64.83,1,26,8058566385930,128,15085,94425121,CLX5
2025-09-24 19:45:55.063775727+00:00,160,1,432669,A,A,64.83,1,26,8058566385950,128,14734,94425123,CLX5
2025-09-24 19:45:55.065501637+00:00,160,1,432669,A,A,64.82,1,26,8058566385959,128,17532,94425157,CLX5
2025-09-24 19:45:55.065712711+00:00,160,1,432669,A,A,64.82,1,26,8058566385960,128,14665,94425164,CLX5
2025-09-24 19:45:55.065839177+00:00,160,1,432669,M,A,64.82,1,26,8058566375686,128,17938,94425172,CLX5
2025-09-24 19:45:55.065867283+00:00,160,1,432669,A,A,64.82,1,26,8058566385962,128,19045,94425175,CLX5
2025-09-24 19:45:55.070017641+00:00,160,1,432669,A,B,63.67,4,26,8058566385977,128,18433,94425242,CLX5
2025-09-24 19:45:55.074064419+00:00,160,1,432669,C,A,64.83,1,26,8058566385950,128,18143,94425254,CLX5
2025-09-24 19:45:55.102751889+00:00,160,1,432669,A,A,64.82,1,26,8058566386020,128,20713,94425344,CLX5
2025-09-24 19:45:55.103635991+00:00,160,1,432669,A,A,64.85,1,26,8058566386021,128,17537,94425350,CLX5
2025-09-24 19:45:55.220283723+00:00,160,1,432669,T,B,64.82,1,26,8058566386120,0,14635,94425507,CLX5
2025-09-24 19:45:55.220283723+00:00,160,1,432669,F,A,64.82,1,26,8058566385959,0,14635,94425507,CLX5
2025-09-24 19:45:55.220283723+00:00,160,1,432669,C,A,64.82,1,26,8058566385959,128,14635,94425507,CLX5
2025-09-24 19:45:55.220407769+00:00,160,1,432669,T,B,64.82,4,26,8058566386121,0,18089,94425514,CLX5
2025-09-24 19:45:55.220407769+00:00,160,1,432669,F,A,64.82,1,26,8058566375686,0,18089,94425514,CLX5
2025-09-24 19:45:55.220407769+00:00,160,1,432669,F,A,64.82,1,26,8058566385962,0,18089,94425514,CLX5
2025-09-24 19:45:55.220407769+00:00,160,1,432669,F,A,64.82,1,26,8058566386020,0,18089,94425514,CLX5
2025-09-24 19:45:55.220407769+00:00,160,1,432669,F,A,64.82,1,26,8058566385960,0,18089,94425514,CLX5
2025-09-24 19:45:55.220407769+00:00,160,1,432669,C,A,64.82,1,26,8058566375686,0,14690,94425515,CLX5
2025-09-24 19:45:55.220407769+00:00,160,1,432669,C,A,64.82,1,26,8058566385962,0,14690,94425515,CLX5
2025-09-24 19:45:55.220407769+00:00,160,1,432669,C,A,64.82,1,26,8058566386020,0,14690,94425515,CLX5
2025-09-24 19:45:55.220407769+00:00,160,1,432669,C,A,64.82,1,26,8058566385960,128,14690,94425515,CLX5
2025-09-24 19:45:55.221436325+00:00,160,1,432669,C,A,64.83,1,26,8058566385929,128,15079,94425582,CLX5
2025-09-24 19:45:55.222155507+00:00,160,1,432669,A,A,64.83,1,26,8058566386147,128,18370,94425627,CLX5
2025-09-24 19:45:55.227111709+00:00,160,1,432669,A,A,64.82,1,26,8058566386156,128,17553,94425669,CLX5
2025-09-24 19:45:55.227319773+00:00,160,1,432669,C,A,64.83,1,26,8058566386147,128,13816,94425674,CLX5
2025-09-24 19:45:55.227775349+00:00,160,1,432669,M,A,65.99,4,26,8058566342145,128,17956,94425681,CLX5
2025-09-24 19:45:55.227795431+00:00,160,1,432669,M,A,66.0,4,26,8058566275145,128,14465,94425682,CLX5
2025-09-24 19:45:55.228764469+00:00,160,1,432669,A,B,64.81,5,26,8058566386160,128,17806,94425685,CLX5
2025-09-24 19:45:55.230489189+00:00,160,1,432669,C,B,64.81,5,26,8058566386160,128,18378,94425686,CLX5
2025-09-24 19:45:55.230880753+00:00,160,1,432669,T,B,64.82,1,26,8058566386162,0,18171,94425691,CLX5
2025-09-24 19:45:55.230880753+00:00,160,1,432669,F,A,64.82,1,26,8058566386156,0,18171,94425691,CLX5
2025-09-24 19:45:55.230880753+00:00,160,1,432669,C,A,64.82,1,26,8058566386156,128,14308,94425692,CLX5
2025-09-24 19:45:55.231384617+00:00,160,1,432669,M,A,64.85,3,26,8058566376748,128,14442,94425702,CLX5
2025-09-24 19:45:55.235620929+00:00,160,1,432669,A,A,64.82,1,26,8058566386170,128,17987,94425722,CLX5
2025-09-24 19:45:55.235831717+00:00,160,1,432669,C,B,64.79,1,26,8058566385900,128,17478,94425726,CLX5
2025-09-24 19:45:55.236098239+00:00,160,1,432669,M,A,65.98,4,26,8058566376748,128,18207,94425728,CLX5
2025-09-24 19:45:55.238970259+00:00,160,1,432669,T,B,64.82,1,26,8058566386173,0,18132,94425735,CLX5
2025-09-24 19:45:55.238970259+00:00,160,1,432669,F,A,64.82,1,26,8058566386170,0,18132,94425735,CLX5
2025-09-24 19:45:55.238970259+00:00,160,1,432669,C,A,64.82,1,26,8058566386170,128,14708,94425736,CLX5
2025-09-24 19:45:55.239517685+00:00,160,1,432669,M,A,64.85,3,26,8058566373687,128,18254,94425747,CLX5
2025-09-24 19:45:55.246428209+00:00,160,1,432669,A,A,65.97,4,26,8058566386181,128,17216,94425761,CLX5
2025-09-24 19:45:55.248026787+00:00,160,1,432669,A,A,64.82,1,26,8058566386183,128,18172,94425763,CLX5
2025-09-24 19:45:55.248231221+00:00,160,1,432669,A,B,64.81,1,26,8058566386185,128,14053,94425768,CLX5
2025-09-24 19:45:55.248426781+00:00,160,1,432669,C,B,64.81,1,26,8058566386185,128,18325,94425774,CLX5
2025-09-24 19:45:55.248532607+00:00,160,1,432669,M,A,66.01,4,26,8058566373687,128,17701,94425777,CLX5
2025-09-24 19:45:55.248588747+00:00,160,1,432669,A,B,64.81,1,26,8058566386188,128,14419,94425778,CLX5
2025-09-24 19:45:55.250811837+00:00,160,1,432669,C,B,64.81,1,26,8058566386188,128,18187,94425787,CLX5
2025-09-24 19:45:55.293311483+00:00,160,1,432669,T,B,64.82,1,26,8058566386225,0,14511,94425858,CLX5
2025-09-24 19:45:55.293311483+00:00,160,1,432669,F,A,64.82,1,26,8058566386183,0,14511,94425858,CLX5
2025-09-24 19:45:55.293311483+00:00,160,1,432669,C,A,64.82,1,26,8058566386183,128,14511,94425858,CLX5
2025-09-24 19:45:55.293670409+00:00,160,1,432669,C,A,64.85,1,26,8058566386021,128,14623,94425877,CLX5
2025-09-24 19:45:55.298719903+00:00,160,1,432669,A,A,64.82,1,26,8058566386260,128,17609,94425981,CLX5
2025-09-24 19:45:56.053621093+00:00,160,1,432669,M,A,64.84,4,26,8058566373687,128,18259,94426288,CLX5
2025-09-24 19:45:56.342749001+00:00,160,1,432669,C,B,64.81,3,26,8058566384486,128,18381,94426512,CLX5
2025-09-24 19:45:56.342751959+00:00,160,1,432669,M,B,64.81,1,26,8058566384177,128,15010,94426513,CLX5
2025-09-24 19:45:56.525891003+00:00,160,1,432669,A,B,64.76,1,26,8058566386508,128,17977,94426652,CLX5
2025-09-24 19:45:56.868532773+00:00,160,1,432669,A,A,64.82,1,26,8058566386537,128,16613,94426700,CLX5
2025-09-24 19:45:56.868532951+00:00,160,1,432669,A,A,64.82,2,26,8058566386538,128,17857,94426703,CLX5
2025-09-24 19:45:56.922995509+00:00,160,1,432669,T,B,64.82,1,26,8058566386561,0,20613,94426787,CLX5
2025-09-24 19:45:56.922995509+00:00,160,1,432669,F,A,64.82,1,26,8058566386260,0,20613,94426787,CLX5
2025-09-24 19:45:56.922995509+00:00,160,1,432669,C,A,64.82,1,26,8058566386260,128,16742,94426788,CLX5
2025-09-24 19:45:56.923070271+00:00,160,1,432669,T,B,64.82,1,26,8058566386562,0,19555,94426790,CLX5
2025-09-24 19:45:56.923070271+00:00,160,1,432669,F,A,64.82,1,26,8058566386537,0,19555,94426790,CLX5
2025-09-24 19:45:56.923070271+00:00,160,1,432669,C,A,64.82,1,26,8058566386537,128,16925,94426791,CLX5
2025-09-24 19:45:56.923283791+00:00,160,1,432669,C,A,64.82,2,26,8058566386538,128,19337,94426796,CLX5
2025-09-24 19:45:56.923487679+00:00,160,1,432669,A,A,64.83,1,26,8058566386568,128,16874,94426811,CLX5
2025-09-24 19:45:56.924340851+00:00,160,1,432669,C,A,64.83,1,26,8058566386568,128,14768,94426903,CLX5
2025-09-24 19:45:56.926450069+00:00,160,1,432669,A,B,64.82,2,26,8058566386603,128,14406,94427004,CLX5
2025-09-24 19:45:56.926473627+00:00,160,1,432669,A,B,64.81,1,26,8058566386604,128,13428,94427008,CLX5
2025-09-24 19:45:56.927229497+00:00,160,1,432669,A,A,64.83,1,26,8058566386607,128,13563,94427020,CLX5
2025-09-24 19:45:56.927469775+00:00,160,1,432669,M,B,64.81,3,26,8058566383096,128,17010,94427026,CLX5
2025-09-24 19:45:56.927507273+00:00,160,1,432669,M,A,66.01,4,26,8058566373687,128,17728,94427029,CLX5
2025-09-24 19:45:56.927517331+00:00,160,1,432669,A,B,64.82,1,26,8058566386609,128,14380,94427030,CLX5
2025-09-24 19:45:56.927742499+00:00,160,1,432669,A,B,64.79,1,26,8058566386612,128,14550,94427042,CLX5
2025-09-24 19:45:56.930576697+00:00,160,1,432669,T,A,64.82,1,26,8058566386624,0,17588,94427073,CLX5
2025-09-24 19:45:56.930576697+00:00,160,1,432669,F,B,64.82,1,26,8058566386603,0,17588,94427073,CLX5
2025-09-24 19:45:56.930576697+00:00,160,1,432669,M,B,64.82,1,26,8058566386603,128,14460,94427074,CLX5
2025-09-24 19:45:56.930799927+00:00,160,1,432669,C,B,64.82,1,26,8058566386603,128,17973,94427078,CLX5
2025-09-24 19:45:56.935690681+00:00,160,1,432669,T,A,64.82,1,26,8058566386628,0,18140,94427107,CLX5
2025-09-24 19:45:56.935690681+00:00,160,1,432669,F,B,64.82,1,26,8058566386609,0,18140,94427107,CLX5
2025-09-24 19:45:56.935690681+00:00,160,1,432669,C,B,64.82,1,26,8058566386609,128,14454,94427108,CLX5
2025-09-24 19:45:56.935960813+00:00,160,1,432669,C,B,64.81,1,26,8058566386604,128,14277,94427115,CLX5
2025-09-24 19:45:56.940258215+00:00,160,1,432669,A,A,64.82,1,26,8058566386631,128,18102,94427119,CLX5
2025-09-24 19:45:56.940461843+00:00,160,1,432669,C,A,64.83,1,26,8058566386607,128,14150,94427124,CLX5
2025-09-24 19:45:56.940468447+00:00,160,1,432669,A,B,64.81,1,26,8058566386633,128,14454,94427130,CLX5
2025-09-24 19:45:56.940587041+00:00,160,1,432669,M,A,64.82,1,26,8058566357626,128,17944,94427134,CLX5
2025-09-24 19:45:56.940746433+00:00,160,1,432669,C,B,64.81,1,26,8058566386633,128,14604,94427138,CLX5
2025-09-24 19:45:56.940881325+00:00,160,1,432669,A,B,64.81,1,26,8058566386635,128,16664,94427144,CLX5
2025-09-24 19:45:56.941477727+00:00,160,1,432669,C,B,64.81,1,26,8058566386635,128,14543,94427166,CLX5
2025-09-24 19:45:56.941690627+00:00,160,1,432669,A,B,64.81,1,26,8058566386642,128,18180,94427167,CLX5
2025-09-24 19:45:56.986728653+00:00,160,1,432669,C,B,64.81,1,26,8058566386642,128,18109,94427186,CLX5
2025-09-24 19:45:57.000932377+00:00,160,1,432669,T,B,64.82,1,26,8058566386654,0,16846,94427195,CLX5
2025-09-24 19:45:57.000932377+00:00,160,1,432669,F,A,64.82,1,26,8058566386631,0,16846,94427195,CLX5
2025-09-24 19:45:57.000932377+00:00,160,1,432669,C,A,64.82,1,26,8058566386631,128,16794,94427196,CLX5
2025-09-24 19:45:57.006418095+00:00,160,1,432669,A,A,64.82,1,26,8058566386672,128,18269,94427226,CLX5
2025-09-24 19:45:57.105894395+00:00,160,1,432669,C,B,64.79,1,26,8058566386612,128,18017,94427306,CLX5
2025-09-24 19:45:57.832177839+00:00,160,1,432669,A,B,64.81,2,26,8058566386744,128,18562,94427367,CLX5
2025-09-24 19:45:57.832184845+00:00,160,1,432669,C,B,64.79,2,26,8058566378271,128,14355,94427368,CLX5
2025-09-24 19:45:57.832187111+00:00,160,1,432669,A,B,64.78,2,26,8058566386745,128,14255,94427369,CLX5
2025-09-24 19:45:58.799166653+00:00,160,1,432669,A,A,64.82,1,26,8058566386756,128,18117,94427386,CLX5
2025-09-24 19:45:58.799723467+00:00,160,1,432669,M,A,64.84,4,26,8058566373687,128,14308,94427403,CLX5
2025-09-24 19:45:58.800983297+00:00,160,1,432669,A,A,64.82,1,26,8058566386760,128,21837,94427419,CLX5
2025-09-24 19:45:59.362593605+00:00,160,1,432669,A,A,64.82,2,26,8058566386789,128,19889,94427493,CLX5
2025-09-24 19:45:59.362594125+00:00,160,1,432669,A,A,64.82,1,26,8058566386790,128,16261,94427494,CLX5
2025-09-24 19:45:59.362594303+00:00,160,1,432669,A,A,64.82,2,26,8058566386791,128,16099,94427495,CLX5
2025-09-24 19:45:59.362612133+00:00,160,1,432669,A,A,64.82,1,26,8058566386793,128,19118,94427501,CLX5
2025-09-24 19:45:59.362622713+00:00,160,1,432669,A,A,64.82,2,26,8058566386795,128,19251,94427506,CLX5
2025-09-24 19:45:59.362623519+00:00,160,1,432669,A,A,64.82,1,26,8058566386797,128,16278,94427511,CLX5
2025-09-24 19:45:59.362637419+00:00,160,1,432669,A,A,64.82,2,26,8058566386800,128,16714,94427519,CLX5
2025-09-24 19:45:59.362643793+00:00,160,1,432669,A,A,64.82,2,26,8058566386802,128,14339,94427522,CLX5
2025-09-24 19:45:59.362648631+00:00,160,1,432669,A,A,64.82,1,26,8058566386803,128,14772,94427524,CLX5
2025-09-24 19:45:59.362653855+00:00,160,1,432669,C,B,64.81,2,26,8058566381980,128,15300,94427525,CLX5
2025-09-24 19:45:59.362697743+00:00,160,1,432669,A,A,64.82,1,26,8058566386805,128,15737,94427527,CLX5
2025-09-24 19:45:59.362776575+00:00,160,1,432669,A,A,64.82,1,26,8058566386806,128,15472,94427529,CLX5
2025-09-24 19:45:59.362810137+00:00,160,1,432669,C,A,64.82,1,26,8058566386803,128,15435,94427533,CLX5
2025-09-24 19:45:59.362941495+00:00,160,1,432669,C,A,64.82,1,26,8058566386806,128,19369,94427540,CLX5
2025-09-24 19:45:59.362941669+00:00,160,1,432669,C,A,64.82,2,26,8058566386802,128,15685,94427541,CLX5
2025-09-24 19:45:59.363132239+00:00,160,1,432669,C,A,64.82,1,26,8058566386797,128,16355,94427565,CLX5
2025-09-24 19:45:59.363136597+00:00,160,1,432669,C,A,64.82,1,26,8058566386793,128,15551,94427566,CLX5
2025-09-24 19:45:59.363179489+00:00,160,1,432669,C,A,64.82,2,26,8058566386791,128,15875,94427568,CLX5
2025-09-24 19:45:59.363233419+00:00,160,1,432669,C,A,64.82,2,26,8058566386800,128,15905,94427572,CLX5
2025-09-24 19:45:59.363275407+00:00,160,1,432669,A,B,64.81,1,26,8058566386818,128,17791,94427583,CLX5
2025-09-24 19:45:59.363280841+00:00,160,1,432669,C,A,64.82,2,26,8058566386789,128,14624,94427587,CLX5
2025-09-24 19:45:59.363281551+00:00,160,1,432669,C,A,64.82,1,26,8058566386790,128,16470,94427588,CLX5
2025-09-24 19:45:59.363329337+00:00,160,1,432669,C,B,64.81,1,26,8058566386818,128,14006,94427591,CLX5
2025-09-24 19:45:59.363703857+00:00,160,1,432669,M,B,63.65,4,26,8058566383096,128,14949,94427623,CLX5
2025-09-24 19:45:59.366184635+00:00,160,1,432669,C,A,64.82,2,26,8058566386795,128,16744,94427688,CLX5
2025-09-24 19:45:59.366184905+00:00,160,1,432669,C,A,64.82,1,26,8058566386805,128,20826,94427689,CLX5
2025-09-24 19:45:59.395639053+00:00,160,1,432669,A,B,64.16,2,26,8058566386845,128,18104,94427727,CLX5
2025-09-24 19:45:59.505976045+00:00,160,1,432669,T,B,64.82,1,26,8058566379297,0,18007,94427755,CLX5
2025-09-24 19:45:59.505976045+00:00,160,1,432669,F,B,64.82,1,26,8058566379297,0,18007,94427755,CLX5
2025-09-24 19:45:59.505976045+00:00,160,1,432669,F,A,64.82,1,26,8058566357626,0,18007,94427755,CLX5
2025-09-24 19:45:59.505976045+00:00,160,1,432669,C,B,64.81,1,26,8058566379297,0,14388,94427756,CLX5
2025-09-24 19:45:59.505976045+00:00,160,1,432669,C,A,64.82,1,26,8058566357626,128,14388,94427756,CLX5
2025-09-24 19:45:59.506279661+00:00,160,1,432669,T,B,64.82,2,26,8058566386858,0,18000,94427759,CLX5
2025-09-24 19:45:59.506279661+00:00,160,1,432669,F,A,64.82,1,26,8058566386672,0,18000,94427759,CLX5
2025-09-24 19:45:59.506279661+00:00,160,1,432669,F,A,64.82,1,26,8058566386756,0,18000,94427759,CLX5
2025-09-24 19:45:59.506279661+00:00,160,1,432669,C,A,64.82,1,26,8058566386672,0,15130,94427760,CLX5
2025-09-24 19:45:59.506279661+00:00,160,1,432669,C,A,64.82,1,26,8058566386756,128,15130,94427760,CLX5
2025-09-24 19:45:59.506525121+00:00,160,1,432669,C,A,64.82,1,26,8058566386760,128,17348,94427772,CLX5
2025-09-24 19:45:59.506534203+00:00,160,1,432669,A,B,64.81,1,26,8058566386861,128,16199,94427776,CLX5
2025-09-24 19:45:59.506561581+00:00,160,1,432669,C,B,64.81,1,26,8058566386861,128,18423,94427784,CLX5
2025-09-24 19:45:59.506772811+00:00,160,1,432669,A,A,64.83,1,26,8058566386863,128,14845,94427800,CLX5
2025-09-24 19:45:59.506996807+00:00,160,1,432669,C,A,64.83,1,26,8058566386863,128,14422,94427817,CLX5
2025-09-24 19:45:59.507323231+00:00,160,1,432669,A,B,64.81,2,26,8058566386865,128,14808,94427825,CLX5
2025-09-24 19:45:59.507354891+00:00,160,1,432669,A,B,64.79,1,26,8058566386869,128,18291,94427832,CLX5
2025-09-24 19:45:59.512819891+00:00,160,1,432669,A,A,64.82,1,26,8058566386880,128,17624,94427873,CLX5
2025-09-24 19:45:59.513049397+00:00,160,1,432669,A,B,64.81,1,26,8058566386881,128,15296,94427878,CLX5
2025-09-24 19:45:59.513291557+00:00,160,1,432669,M,A,66.01,4,26,8058566373687,128,19578,94427881,CLX5
2025-09-24 19:45:59.513317533+00:00,160,1,432669,M,B,64.81,3,26,8058566383096,128,14472,94427882,CLX5
2025-09-24 19:45:59.514264031+00:00,160,1,432669,T,B,64.82,1,26,8058566386887,0,18208,94427894,CLX5
2025-09-24 19:45:59.514264031+00:00,160,1,432669,F,A,64.82,1,26,8058566386880,0,18208,94427894,CLX5
2025-09-24 19:45:59.514264031+00:00,160,1,432669,C,A,64.82,1,26,8058566386880,128,14489,94427895,CLX5
2025-09-24 19:45:59.514512275+00:00,160,1,432669,A,A,64.83,1,26,8058566386888,128,18596,94427900,CLX5
2025-09-24 19:45:59.515383055+00:00,160,1,432669,C,A,64.83,1,26,8058566386888,128,15044,94427906,CLX5
2025-09-24 19:45:59.518939161+00:00,160,1,432669,A,A,64.82,1,26,8058566386897,128,18822,94427921,CLX5
2025-09-24 19:45:59.560180437+00:00,160,1,432669,A,A,64.85,1,26,8058566386912,128,18421,94427958,CLX5
2025-09-24 19:45:59.595914187+00:00,160,1,432669,C,B,64.16,2,26,8058566386845,128,19198,94427962,CLX5
2025-09-24 19:45:59.631631561+00:00,160,1,432669,C,B,64.81,1,26,8058566386881,128,16732,94427982,CLX5
2025-09-24 19:45:59.685906721+00:00,160,1,432669,C,B,64.79,1,26,8058566386869,128,18998,94427997,CLX5
2025-09-24 19:46:02.003829973+00:00,160,1,432669,M,A,64.94,1,26,8058565075241,128,15651,94428207,CLX5
2025-09-24 19:46:02.004642787+00:00,160,1,432669,M,A,64.95,1,26,8058565075241,128,13945,94428225,CLX5
2025-09-24 19:46:02.066261739+00:00,160,1,432669,T,B,64.82,1,26,8058566387008,0,18891,94428229,CLX5
2025-09-24 19:46:02.066261739+00:00,160,1,432669,F,A,64.82,1,26,8058566386897,0,18891,94428229,CLX5
2025-09-24 19:46:02.066261739+00:00,160,1,432669,C,A,64.82,1,26,8058566386897,128,16715,94428230,CLX5
2025-09-24 19:46:02.066470645+00:00,160,1,432669,C,A,64.85,1,26,8058566386912,128,14879,94428239,CLX5
2025-09-24 19:46:02.066473351+00:00,160,1,432669,A,B,64.79,1,26,8058566387012,128,17909,94428240,CLX5
2025-09-24 19:46:02.066583171+00:00,160,1,432669,A,B,64.81,1,26,8058566387015,128,15207,94428244,CLX5
2025-09-24 19:46:02.066616653+00:00,160,1,432669,A,B,64.81,1,26,8058566387018,128,13786,94428249,CLX5
2025-09-24 19:46:02.066645643+00:00,160,1,432669,C,B,64.81,1,26,8058566387015,128,17142,94428267,CLX5
2025-09-24 19:46:02.066899649+00:00,160,1,432669,M,A,64.85,3,26,8058566373687,128,14495,94428276,CLX5
2025-09-24 19:46:02.066936819+00:00,160,1,432669,C,B,64.81,1,26,8058566387018,128,17411,94428278,CLX5
2025-09-24 19:46:02.073237617+00:00,160,1,432669,A,A,64.82,1,26,8058566387031,128,18169,94428321,CLX5
2025-09-24 19:46:02.073708667+00:00,160,1,432669,M,A,66.01,4,26,8058566373687,128,14521,94428335,CLX5
2025-09-24 19:46:02.077076123+00:00,160,1,432669,A,B,64.81,3,26,8058566387047,128,18468,94428383,CLX5
2025-09-24 19:46:02.077227467+00:00,160,1,432669,T,B,64.82,1,26,8058566387048,0,17693,94428384,CLX5
2025-09-24 19:46:02.077227467+00:00,160,1,432669,F,A,64.82,1,26,8058566387031,0,17693,94428384,CLX5
2025-09-24 19:46:02.077227467+00:00,160,1,432669,C,A,64.82,1,26,8058566387031,128,14485,94428385,CLX5
2025-09-24 19:46:02.077234419+00:00,160,1,432669,A,B,64.81,1,26,8058566387049,128,16270,94428389,CLX5
2025-09-24 19:46:02.077502323+00:00,160,1,432669,C,B,64.81,1,26,8058566387049,128,16620,94428390,CLX5
2025-09-24 19:46:02.077531275+00:00,160,1,432669,A,A,64.83,1,26,8058566387051,128,14242,94428392,CLX5
2025-09-24 19:46:02.081918839+00:00,160,1,432669,A,A,64.82,1,26,8058566387055,128,17790,94428401,CLX5
2025-09-24 19:46:02.082142759+00:00,160,1,432669,C,A,64.83,1,26,8058566387051,128,18585,94428405,CLX5
2025-09-24 19:46:02.082147023+00:00,160,1,432669,C,B,64.81,3,26,8058566387047,128,14709,94428406,CLX5
2025-09-24 19:46:02.084206743+00:00,160,1,432669,A,B,64.81,3,26,8058566387056,128,17782,94428408,CLX5
2025-09-24 19:46:02.118054583+00:00,160,1,432669,T,B,64.82,1,26,8058566387063,0,17788,94428420,CLX5
2025-09-24 19:46:02.118054583+00:00,160,1,432669,F,A,64.82,1,26,8058566387055,0,17788,94428420,CLX5
2025-09-24 19:46:02.118054583+00:00,160,1,432669,C,A,64.82,1,26,8058566387055,128,14949,94428421,CLX5
2025-09-24 19:46:02.118307357+00:00,160,1,432669,A,A,64.83,1,26,8058566387066,128,14979,94428428,CLX5
2025-09-24 19:46:02.118489673+00:00,160,1,432669,C,A,64.83,1,26,8058566387066,128,18416,94428434,CLX5
2025-09-24 19:46:02.122738137+00:00,160,1,432669,C,B,64.81,3,26,8058566387056,128,18411,94428452,CLX5
2025-09-24 19:46:02.122910317+00:00,160,1,432669,A,A,64.82,1,26,8058566387073,128,17971,94428453,CLX5
2025-09-24 19:46:02.125479239+00:00,160,1,432669,A,B,64.81,3,26,8058566387076,128,18296,94428461,CLX5
2025-09-24 19:46:02.127206203+00:00,160,1,432669,C,B,64.81,3,26,8058566387076,128,18229,94428462,CLX5
2025-09-24 19:46:02.129005471+00:00,160,1,432669,A,B,64.81,1,26,8058566387078,128,14845,94428465,CLX5
2025-09-24 19:46:02.131440443+00:00,160,1,432669,A,B,64.81,3,26,8058566387080,128,17918,94428467,CLX5
2025-09-24 19:46:02.168721395+00:00,160,1,432669,C,B,64.81,1,26,8058566387078,128,14828,94428492,CLX5
2025-09-24 19:46:02.170412149+00:00,160,1,432669,C,B,64.81,3,26,8058566387080,128,18469,94428495,CLX5
2025-09-24 19:46:03.138398981+00:00,160,1,432669,T,B,64.82,1,26,8058566387121,0,18439,94428555,CLX5
2025-09-24 19:46:03.138398981+00:00,160,1,432669,F,A,64.82,1,26,8058566387073,0,18439,94428555,CLX5
2025-09-24 19:46:03.138398981+00:00,160,1,432669,C,A,64.82,1,26,8058566387073,128,14580,94428556,CLX5
2025-09-24 19:46:03.138724505+00:00,160,1,432669,A,A,64.83,1,26,8058566387123,128,19914,94428561,CLX5
2025-09-24 19:46:03.145093401+00:00,160,1,432669,A,A,64.82,1,26,8058566387132,128,17977,94428595,CLX5
2025-09-24 19:46:03.145311523+00:00,160,1,432669,C,A,64.83,1,26,8058566387123,128,18975,94428599,CLX5
2025-09-24 19:46:03.145318069+00:00,160,1,432669,A,B,64.81,1,26,8058566387133,128,14539,94428604,CLX5
2025-09-24 19:46:03.150940567+00:00,160,1,432669,C,B,64.81,1,26,8058566387133,128,14497,94428621,CLX5
2025-09-24 19:46:03.295841153+00:00,160,1,432669,C,A,65.02,1,26,8058566381630,128,17685,94428647,CLX5
2025-09-24 19:46:03.405045053+00:00,160,1,432669,A,A,65.01,1,26,8058566387155,128,18249,94428673,CLX5
2025-09-24 19:46:04.198718077+00:00,160,1,432669,A,A,64.82,1,26,8058566387163,128,17674,94428696,CLX5
2025-09-24 19:46:04.423712777+00:00,160,1,432669,C,A,65.05,1,26,8058566381627,128,18904,94428717,CLX5
2025-09-24 19:46:04.470097645+00:00,160,1,432669,A,A,65.04,1,26,8058566387169,128,18697,94428718,CLX5
2025-09-24 19:46:04.893918673+00:00,160,1,432669,C,A,65.03,1,26,8058566381637,128,20027,94428719,CLX5
2025-09-24 19:46:04.988543483+00:00,160,1,432669,A,A,65.02,1,26,8058566387170,128,19287,94428720,CLX5
2025-09-24 19:46:06.680358281+00:00,160,1,432669,M,B,64.42,1,26,8058566360017,128,19952,94428777,CLX5
2025-09-24 19:46:08.678136275+00:00,160,1,432669,C,B,64.06,1,26,8058559819232,128,18135,94428864,CLX5
2025-09-24 19:46:08.799411795+00:00,160,1,432669,A,B,64.06,1,26,8058566387230,128,17874,94428865,CLX5
2025-09-24 19:46:09.685259999+00:00,160,1,432669,A,B,64.8,3,26,8058566387231,128,20294,94428866,CLX5
2025-09-24 19:46:13.571935749+00:00,160,1,432669,M,A,64.84,4,26,8058566373687,128,18161,94428886,CLX5
2025-09-24 19:46:17.286935295+00:00,160,1,432669,A,B,64.8,18,26,8058566387258,128,17942,94428955,CLX5
2025-09-24 19:46:17.287125847+00:00,160,1,432669,T,B,64.82,2,26,8058566387260,0,18082,94428960,CLX5
2025-09-24 19:46:17.287125847+00:00,160,1,432669,F,A,64.82,1,26,8058566387132,0,18082,94428960,CLX5
2025-09-24 19:46:17.287125847+00:00,160,1,432669,F,A,64.82,1,26,8058566387163,0,18082,94428960,CLX5
2025-09-24 19:46:17.287125847+00:00,160,1,432669,C,A,64.82,1,26,8058566387132,0,14546,94428961,CLX5
2025-09-24 19:46:17.287125847+00:00,160,1,432669,C,A,64.82,1,26,8058566387163,128,14546,94428961,CLX5
2025-09-24 19:46:17.287502437+00:00,160,1,432669,A,B,64.81,1,26,8058566387264,128,14939,94428977,CLX5
2025-09-24 19:46:17.287821931+00:00,160,1,432669,C,B,64.81,1,26,8058566387264,128,15148,94429004,CLX5
2025-09-24 19:46:17.287868355+00:00,160,1,432669,M,A,64.85,3,26,8058566275145,128,14562,94429007,CLX5
2025-09-24 19:46:17.289095717+00:00,160,1,432669,A,B,64.81,1,26,8058566387275,128,14667,94429048,CLX5
2025-09-24 19:46:17.289406495+00:00,160,1,432669,A,B,64.82,2,26,8058566387276,128,18532,94429050,CLX5
2025-09-24 19:46:17.289411371+00:00,160,1,432669,C,B,64.81,1,26,8058566387275,128,17276,94429052,CLX5
2025-09-24 19:46:17.289634503+00:00,160,1,432669,A,B,64.82,1,26,8058566387278,128,14391,94429055,CLX5
2025-09-24 19:46:17.289644045+00:00,160,1,432669,A,B,64.82,1,26,8058566387279,128,17745,94429058,CLX5
2025-09-24 19:46:17.289675993+00:00,160,1,432669,A,B,64.82,1,26,8058566387280,128,13973,94429060,CLX5
2025-09-24 19:46:17.289965651+00:00,160,1,432669,M,A,66.0,4,26,8058566373687,128,17642,94429068,CLX5
2025-09-24 19:46:17.290073089+00:00,160,1,432669,A,B,64.82,1,26,8058566387282,128,19958,94429070,CLX5
2025-09-24 19:46:17.293649431+00:00,160,1,432669,T,A,64.82,1,26,8058566387284,0,18058,94429076,CLX5
2025-09-24 19:46:17.293649431+00:00,160,1,432669,F,B,64.82,1,26,8058566387276,0,18058,94429076,CLX5
2025-09-24 19:46:17.293649431+00:00,160,1,432669,M,B,64.82,1,26,8058566387276,128,18760,94429077,CLX5
2025-09-24 19:46:17.293934211+00:00,160,1,432669,A,A,64.86,1,26,8058566387289,128,20116,94429082,CLX5
2025-09-24 19:46:17.298643803+00:00,160,1,432669,T,A,64.82,1,26,8058566387292,0,18231,94429087,CLX5
2025-09-24 19:46:17.298643803+00:00,160,1,432669,F,B,64.82,1,26,8058566387276,0,18231,94429087,CLX5
2025-09-24 19:46:17.298643803+00:00,160,1,432669,C,B,64.82,1,26,8058566387276,128,15454,94429088,CLX5
2025-09-24 19:46:17.298875173+00:00,160,1,432669,C,B,64.82,1,26,8058566387279,128,16750,94429090,CLX5
2025-09-24 19:46:17.300342927+00:00,160,1,432669,C,B,64.79,1,26,8058566387012,128,18537,94429095,CLX5
2025-09-24 19:46:17.303451749+00:00,160,1,432669,T,A,64.82,1,26,8058566387293,0,18134,94429097,CLX5
2025-09-24 19:46:17.303451749+00:00,160,1,432669,F,B,64.82,1,26,8058566387278,0,18134,94429097,CLX5
2025-09-24 19:46:17.303451749+00:00,160,1,432669,C,B,64.82,1,26,8058566387278,128,14480,94429098,CLX5
2025-09-24 19:46:17.308018769+00:00,160,1,432669,T,A,64.82,1,26,8058566387297,0,18030,94429104,CLX5
2025-09-24 19:46:17.308018769+00:00,160,1,432669,F,B,64.82,1,26,8058566387280,0,18030,94429104,CLX5
2025-09-24 19:46:17.308018769+00:00,160,1,432669,C,B,64.82,1,26,8058566387280,128,14496,94429105,CLX5
2025-09-24 19:46:17.309139327+00:00,160,1,432669,A,A,64.83,1,26,8058566387301,128,18294,94429122,CLX5
2025-09-24 19:46:17.312390491+00:00,160,1,432669,T,A,64.82,1,26,8058566387302,0,17791,94429123,CLX5
2025-09-24 19:46:17.312390491+00:00,160,1,432669,F,B,64.82,1,26,8058566387282,0,17791,94429123,CLX5
2025-09-24 19:46:17.312390491+00:00,160,1,432669,C,B,64.82,1,26,8058566387282,128,16346,94429124,CLX5
2025-09-24 19:46:17.312648989+00:00,160,1,432669,A,A,64.83,1,26,8058566387305,128,14812,94429131,CLX5
2025-09-24 19:46:17.312795327+00:00,160,1,432669,C,A,64.83,1,26,8058566387301,128,17366,94429133,CLX5
2025-09-24 19:46:17.312837507+00:00,160,1,432669,C,A,64.83,1,26,8058566387305,128,15263,94429134,CLX5
2025-09-24 19:46:17.312963395+00:00,160,1,432669,A,A,64.83,1,26,8058566387306,128,18179,94429135,CLX5
2025-09-24 19:46:17.313084657+00:00,160,1,432669,A,A,64.83,1,26,8058566387307,128,18435,94429136,CLX5
2025-09-24 19:46:17.316722705+00:00,160,1,432669,A,A,64.82,1,26,8058566387308,128,18053,94429138,CLX5
2025-09-24 19:46:17.317240197+00:00,160,1,432669,M,A,66.01,4,26,8058566275145,128,14843,94429148,CLX5
2025-09-24 19:46:17.363315457+00:00,160,1,432669,C,A,64.83,1,26,8058566387307,128,17952,94429191,CLX5
2025-09-24 19:46:17.363456955+00:00,160,1,432669,C,A,64.86,1,26,8058566387289,128,19108,94429192,CLX5
2025-09-24 19:46:17.370187773+00:00,160,1,432669,C,A,64.83,1,26,8058566387306,128,14793,94429195,CLX5
2025-09-24 19:46:17.459578625+00:00,160,1,432669,A,A,64.82,1,26,8058566387333,128,19007,94429217,CLX5
2025-09-24 19:46:17.810259715+00:00,160,1,432669,A,A,64.82,2,26,8058566387344,128,21357,94429239,CLX5
2025-09-24 19:46:17.810421677+00:00,160,1,432669,A,A,64.82,1,26,8058566387346,128,19044,94429245,CLX5
2025-09-24 19:46:17.810421869+00:00,160,1,432669,A,A,64.82,2,26,8058566387347,128,16754,94429246,CLX5
2025-09-24 19:46:17.810423175+00:00,160,1,432669,C,B,64.81,2,26,8058566386865,128,17175,94429247,CLX5
2025-09-24 19:46:17.810636881+00:00,160,1,432669,M,A,64.84,4,26,8058566275145,128,14947,94429253,CLX5
2025-09-24 19:46:17.813419815+00:00,160,1,432669,M,B,63.65,4,26,8058566383096,128,18164,94429383,CLX5
2025-09-24 19:46:17.813636461+00:00,160,1,432669,C,A,64.82,2,26,8058566387347,128,19987,94429406,CLX5
2025-09-24 19:46:17.814456575+00:00,160,1,432669,C,A,64.82,1,26,8058566387346,128,22202,94429452,CLX5
2025-09-24 19:46:18.512461629+00:00,160,1,432669,M,A,64.91,1,26,8058566157942,128,17494,94429624,CLX5
2025-09-24 19:46:25.032714933+00:00,160,1,432669,A,A,64.82,1,26,8058566387513,128,21660,94429761,CLX5
2025-09-24 19:46:29.071944853+00:00,160,1,432669,A,B,64.81,1,26,8058566387539,128,24278,94429855,CLX5
2025-09-24 19:46:29.072130455+00:00,160,1,432669,C,A,64.82,1,26,8058566387513,128,25966,94429859,CLX5
2025-09-24 19:46:29.406942361+00:00,160,1,432669,A,B,64.8,1,26,8058566387540,128,20584,94429871,CLX5
2025-09-24 19:46:30.237934383+00:00,160,1,432669,C,B,64.81,2,26,8058566386744,128,25310,94429872,CLX5
2025-09-24 19:46:30.238120481+00:00,160,1,432669,A,A,64.82,1,26,8058566387541,128,24897,94429892,CLX5
2025-09-24 19:46:30.238217667+00:00,160,1,432669,A,B,64.79,1,26,8058566387544,128,21486,94429898,CLX5
2025-09-24 19:46:30.239932785+00:00,160,1,432669,C,B,64.8,2,26,8058566382288,128,21259,94429913,CLX5
2025-09-24 19:46:30.241932665+00:00,160,1,432669,C,B,64.78,2,26,8058566386745,128,19831,94429941,CLX5
2025-09-24 19:46:30.241950943+00:00,160,1,432669,C,B,64.54,1,26,8058566301815,128,19727,94429946,CLX5
2025-09-24 19:46:30.243932641+00:00,160,1,432669,C,A,64.86,2,26,8058566384898,128,22124,94429962,CLX5
2025-09-24 19:46:30.243950189+00:00,160,1,432669,C,B,64.54,8,26,8058566382274,128,16890,94429966,CLX5
2025-09-24 19:46:30.243992043+00:00,160,1,432669,C,B,64.72,2,26,8058566381007,128,16150,94429970,CLX5
2025-09-24 19:46:30.245932749+00:00,160,1,432669,C,B,64.77,2,26,8058566383894,128,20561,94429985,CLX5
2025-09-24 19:46:30.245950375+00:00,160,1,432669,C,A,65.14,9,26,8058566301808,128,17596,94429989,CLX5
2025-09-24 19:46:30.245992709+00:00,160,1,432669,C,B,64.68,2,26,8058566302432,128,16653,94429995,CLX5
2025-09-24 19:46:30.247932765+00:00,160,1,432669,C,A,64.87,2,26,8058566383123,128,22582,94430003,CLX5
2025-09-24 19:46:30.247992167+00:00,160,1,432669,C,A,64.96,2,26,8058566302417,128,16843,94430011,CLX5
2025-09-24 19:46:30.249992143+00:00,160,1,432669,C,B,64.64,2,26,8058566302433,128,14318,94430025,CLX5
2025-09-24 19:46:30.251950417+00:00,160,1,432669,C,B,64.46,9,26,8058566301816,128,16391,94430038,CLX5
2025-09-24 19:46:30.251992291+00:00,160,1,432669,C,A,65.0,1,26,8058566331179,128,13893,94430043,CLX5
2025-09-24 19:46:30.253951275+00:00,160,1,432669,C,A,65.22,9,26,8058566301809,128,14949,94430052,CLX5
2025-09-24 19:46:30.253992095+00:00,160,1,432669,C,A,65.0,2,26,8058566302418,128,13857,94430056,CLX5
2025-09-24 19:46:30.255954323+00:00,160,1,432669,C,B,64.56,2,26,8058566301917,128,17758,94430066,CLX5
2025-09-24 19:46:30.259951185+00:00,160,1,432669,C,B,64.38,9,26,8058566301817,128,14346,94430105,CLX5
2025-09-24 19:46:30.261951255+00:00,160,1,432669,C,A,65.3,9,26,8058566301810,128,17485,94430129,CLX5
2025-09-24 19:46:30.261953963+00:00,160,1,432669,C,A,65.12,2,26,8058566301915,128,14144,94430130,CLX5
2025-09-24 19:46:30.261992765+00:00,160,1,432669,C,B,64.6,1,26,8058566302407,128,13980,94430135,CLX5
2025-09-24 19:46:30.262221369+00:00,160,1,432669,C,A,64.82,2,26,8058566387344,128,13720,94430140,CLX5
2025-09-24 19:46:30.263992663+00:00,160,1,432669,C,B,64.6,1,26,8058566302819,128,14621,94430175,CLX5
2025-09-24 19:46:30.264110471+00:00,160,1,432669,C,B,64.42,1,26,8058566307701,128,14318,94430178,CLX5
2025-09-24 19:46:30.267951433+00:00,160,1,432669,C,B,64.3,9,26,8058566301818,128,15712,94430197,CLX5
2025-09-24 19:46:30.267953775+00:00,160,1,432669,C,B,64.48,2,26,8058566301918,128,15693,94430198,CLX5
2025-09-24 19:46:30.269992763+00:00,160,1,432669,C,B,64.6,2,26,8058566302434,128,14373,94430216,CLX5
2025-09-24 19:46:30.270444961+00:00,160,1,432669,C,A,65.38,9,26,8058566301811,128,14037,94430220,CLX5
2025-09-24 19:46:30.271992989+00:00,160,1,432669,C,A,65.04,2,26,8058566302419,128,14815,94430230,CLX5
2025-09-24 19:46:30.273954009+00:00,160,1,432669,C,A,65.2,2,26,8058566301916,128,14377,94430238,CLX5
2025-09-24 19:46:30.275992787+00:00,160,1,432669,C,B,64.56,2,26,8058566302435,128,15965,94430258,CLX5
2025-09-24 19:46:30.276109593+00:00,160,1,432669,C,A,65.24,1,26,8058566303699,128,14665,94430261,CLX5
2025-09-24 19:46:30.276444139+00:00,160,1,432669,C,B,64.22,9,26,8058566301819,128,14132,94430265,CLX5
2025-09-24 19:46:30.277993185+00:00,160,1,432669,C,B,64.55,1,26,8058566301537,128,17527,94430275,CLX5
2025-09-24 19:46:30.278444173+00:00,160,1,432669,C,A,65.46,9,26,8058566301812,128,17327,94430279,CLX5
2025-09-24 19:46:30.279954243+00:00,160,1,432669,C,B,64.4,2,26,8058566340482,128,14581,94430284,CLX5
2025-09-24 19:46:30.283993093+00:00,160,1,432669,C,A,65.08,2,26,8058566302420,128,14269,94430317,CLX5
2025-09-24 19:46:30.284109515+00:00,160,1,432669,C,B,64.36,1,26,8058566303703,128,14113,94430320,CLX5
2025-09-24 19:46:30.284444293+00:00,160,1,432669,C,B,64.14,9,26,8058566301820,128,17874,94430323,CLX5
2025-09-24 19:46:30.286444095+00:00,160,1,432669,C,A,65.54,9,26,8058566301813,128,17223,94430343,CLX5
2025-09-24 19:46:30.291994031+00:00,160,1,432669,C,A,65.1,1,26,8058566302398,128,17942,94430378,CLX5
2025-09-24 19:46:30.292444157+00:00,160,1,432669,C,B,64.06,9,26,8058566301821,128,17583,94430382,CLX5
2025-09-24 19:46:30.293994429+00:00,160,1,432669,C,A,65.1,1,26,8058566301519,128,14532,94430389,CLX5
2025-09-24 19:46:30.294109951+00:00,160,1,432669,C,A,65.3,1,26,8058566303700,128,18321,94430390,CLX5
2025-09-24 19:46:30.294444305+00:00,160,1,432669,C,A,65.62,9,26,8058566301814,128,13122,94430394,CLX5
2025-09-24 19:46:30.296124575+00:00,160,1,432669,C,B,64.52,2,26,8058566302436,128,17455,94430404,CLX5
2025-09-24 19:46:30.300109743+00:00,160,1,432669,C,B,64.3,1,26,8058566303704,128,17362,94430436,CLX5
2025-09-24 19:46:30.300121687+00:00,160,1,432669,C,A,65.12,2,26,8058566302421,128,14492,94430437,CLX5
2025-09-24 19:46:30.300444539+00:00,160,1,432669,C,B,63.98,9,26,8058566301822,128,17186,94430440,CLX5
2025-09-24 19:46:30.302122525+00:00,160,1,432669,C,B,64.5,1,26,8058566302408,128,13827,94430452,CLX5
2025-09-24 19:46:30.304110369+00:00,160,1,432669,C,A,65.36,1,26,8058566303701,128,15657,94430470,CLX5
2025-09-24 19:46:30.304122655+00:00,160,1,432669,C,B,64.5,1,26,8058566301538,128,14057,94430471,CLX5
2025-09-24 19:46:30.312109867+00:00,160,1,432669,C,B,64.24,1,26,8058566303705,128,17015,94430523,CLX5
2025-09-24 19:46:30.312122827+00:00,160,1,432669,C,A,65.15,1,26,8058566301520,128,13908,94430524,CLX5
2025-09-24 19:46:30.314109805+00:00,160,1,432669,C,B,64.24,1,26,8058566307702,128,17694,94430534,CLX5
2025-09-24 19:46:30.318109851+00:00,160,1,432669,C,A,65.42,1,26,8058566303702,128,14137,94430557,CLX5
2025-09-24 19:46:30.318122907+00:00,160,1,432669,C,B,64.48,2,26,8058566302437,128,14360,94430558,CLX5
2025-09-24 19:46:30.320007535+00:00,160,1,432669,C,B,64.55,1,26,8058566376809,128,13872,94430568,CLX5
2025-09-24 19:46:30.320110039+00:00,160,1,432669,C,A,65.44,1,26,8058566303707,128,13869,94430570,CLX5
2025-09-24 19:46:30.320122901+00:00,160,1,432669,C,A,65.16,2,26,8058566302422,128,14241,94430571,CLX5
2025-09-24 19:46:30.322122935+00:00,160,1,432669,C,B,64.45,1,26,8058566301539,128,17102,94430579,CLX5
2025-09-24 19:46:30.324109855+00:00,160,1,432669,C,B,64.18,1,26,8058566303706,128,18281,94430589,CLX5
2025-09-24 19:46:30.326124443+00:00,160,1,432669,C,B,64.44,2,26,8058566302438,128,13988,94430599,CLX5
2025-09-24 19:46:30.328124341+00:00,160,1,432669,C,A,65.2,1,26,8058566302399,128,14081,94430609,CLX5
2025-09-24 19:46:30.330110473+00:00,160,1,432669,C,B,64.16,1,26,8058566303711,128,17709,94430621,CLX5
2025-09-24 19:46:30.330124893+00:00,160,1,432669,C,A,65.2,1,26,8058566301521,128,14247,94430622,CLX5
2025-09-24 19:46:30.334110349+00:00,160,1,432669,C,A,65.48,1,26,8058566307217,128,17434,94430639,CLX5
2025-09-24 19:46:30.336124783+00:00,160,1,432669,C,A,65.2,2,26,8058566302423,128,17494,94430649,CLX5
2025-09-24 19:46:30.338110339+00:00,160,1,432669,C,A,65.52,1,26,8058566303708,128,18042,94430656,CLX5
2025-09-24 19:46:30.344110515+00:00,160,1,432669,C,B,64.08,1,26,8058566303712,128,17692,94430689,CLX5
2025-09-24 19:46:30.344125357+00:00,160,1,432669,C,B,64.4,1,26,8058566302409,128,14233,94430690,CLX5
2025-09-24 19:46:30.346110549+00:00,160,1,432669,C,A,65.6,1,26,8058566303709,128,17281,94430697,CLX5
2025-09-24 19:46:30.346125199+00:00,160,1,432669,C,B,64.4,1,26,8058566301540,128,13937,94430698,CLX5
2025-09-24 19:46:30.348125443+00:00,160,1,432669,C,B,64.4,2,26,8058566302439,128,17078,94430705,CLX5
2025-09-24 19:46:30.352125777+00:00,160,1,432669,C,A,65.24,2,26,8058566302424,128,17566,94430717,CLX5
2025-09-24 19:46:30.354110567+00:00,160,1,432669,C,B,64.0,1,26,8058566303713,128,17767,94430723,CLX5
2025-09-24 19:46:30.354129095+00:00,160,1,432669,C,A,65.25,1,26,8058566301522,128,14000,94430724,CLX5
2025-09-24 19:46:30.356110581+00:00,160,1,432669,C,A,65.68,1,26,8058566303710,128,17938,94430731,CLX5
2025-09-24 19:46:30.358110655+00:00,160,1,432669,C,B,63.92,1,26,8058566303714,128,17278,94430739,CLX5
2025-09-24 19:46:30.360111339+00:00,160,1,432669,C,A,65.76,1,26,8058566307218,128,16885,94430747,CLX5
2025-09-24 19:46:30.368135261+00:00,160,1,432669,C,B,64.36,2,26,8058566302440,128,14038,94430787,CLX5
2025-09-24 19:46:30.370134931+00:00,160,1,432669,C,B,64.35,1,26,8058566301541,128,13817,94430795,CLX5
2025-09-24 19:46:30.372135059+00:00,160,1,432669,C,A,65.28,2,26,8058566302425,128,13907,94430802,CLX5
2025-09-24 19:46:30.374135129+00:00,160,1,432669,C,A,65.3,1,26,8058566302400,128,13947,94430809,CLX5
2025-09-24 19:46:30.376135547+00:00,160,1,432669,C,A,65.3,1,26,8058566301523,128,13910,94430815,CLX5
2025-09-24 19:46:30.382135801+00:00,160,1,432669,C,B,64.32,2,26,8058566302441,128,14235,94430833,CLX5
2025-09-24 19:46:30.388136285+00:00,160,1,432669,C,A,65.32,2,26,8058566302426,128,14362,94430848,CLX5
2025-09-24 19:46:30.390136185+00:00,160,1,432669,C,B,64.3,1,26,8058566302410,128,14395,94430853,CLX5
2025-09-24 19:46:30.392136199+00:00,160,1,432669,C,B,64.3,1,26,8058566301542,128,14342,94430858,CLX5
2025-09-24 19:46:30.400139037+00:00,160,1,432669,C,A,65.35,1,26,8058566301524,128,13954,94430890,CLX5
2025-09-24 19:46:30.402139763+00:00,160,1,432669,C,B,64.28,2,26,8058566302442,128,14251,94430896,CLX5
2025-09-24 19:46:30.406140155+00:00,160,1,432669,C,A,65.36,2,26,8058566302427,128,14626,94430909,CLX5
2025-09-24 19:46:30.412140295+00:00,160,1,432669,C,B,64.25,1,26,8058566301543,128,13917,94430924,CLX5
2025-09-24 19:46:30.416076983+00:00,160,1,432669,C,B,64.79,1,26,8058566387544,128,17727,94430932,CLX5
2025-09-24 19:46:30.420009757+00:00,160,1,432669,C,A,65.25,1,26,8058566302109,128,14003,94430944,CLX5
2025-09-24 19:46:30.422140635+00:00,160,1,432669,C,B,64.24,2,26,8058566302443,128,14331,94430952,CLX5
2025-09-24 19:46:30.424140839+00:00,160,1,432669,C,A,65.4,1,26,8058566302401,128,17209,94430956,CLX5
2025-09-24 19:46:30.426141277+00:00,160,1,432669,C,A,65.4,1,26,8058566301525,128,17171,94430962,CLX5
2025-09-24 19:46:30.428141119+00:00,160,1,432669,C,A,65.4,2,26,8058566302428,128,18002,94430966,CLX5
2025-09-24 19:46:30.432141951+00:00,160,1,432669,C,B,64.2,1,26,8058566302411,128,17603,94430975,CLX5
2025-09-24 19:46:30.434141199+00:00,160,1,432669,C,B,64.2,1,26,8058566301544,128,17392,94430978,CLX5
2025-09-24 19:46:30.438009961+00:00,160,1,432669,C,B,64.35,1,26,8058566302299,128,14643,94430985,CLX5
2025-09-24 19:46:30.438142627+00:00,160,1,432669,C,B,64.2,2,26,8058566302444,128,17477,94430986,CLX5
2025-09-24 19:46:30.444142075+00:00,160,1,432669,C,A,65.44,2,26,8058566302429,128,17854,94430998,CLX5
2025-09-24 19:46:30.446142531+00:00,160,1,432669,C,A,65.45,1,26,8058566301526,128,17289,94431002,CLX5
2025-09-24 19:46:30.454146197+00:00,160,1,432669,C,B,64.15,1,26,8058566301545,128,17591,94431015,CLX5
2025-09-24 19:46:30.458145993+00:00,160,1,432669,C,A,65.48,2,26,8058566376070,128,17109,94431019,CLX5
2025-09-24 19:46:30.464147131+00:00,160,1,432669,C,A,65.5,1,26,8058566302402,128,17498,94431030,CLX5
2025-09-24 19:46:30.466146857+00:00,160,1,432669,C,A,65.5,1,26,8058566301527,128,17165,94431034,CLX5
2025-09-24 19:46:30.476147695+00:00,160,1,432669,C,B,64.1,1,26,8058566302412,128,17525,94431050,CLX5
2025-09-24 19:46:30.478147767+00:00,160,1,432669,C,B,64.1,1,26,8058566301546,128,13803,94431055,CLX5
2025-09-24 19:46:30.482147893+00:00,160,1,432669,C,A,65.55,1,26,8058566301528,128,17763,94431061,CLX5
2025-09-24 19:46:30.496148913+00:00,160,1,432669,C,B,64.05,1,26,8058566301547,128,17819,94431083,CLX5
2025-09-24 19:46:30.498149195+00:00,160,1,432669,C,A,65.6,1,26,8058566302403,128,17553,94431087,CLX5
2025-09-24 19:46:30.500148787+00:00,160,1,432669,C,A,65.6,1,26,8058566301529,128,17866,94431089,CLX5
2025-09-24 19:46:30.512150235+00:00,160,1,432669,C,B,64.0,1,26,8058566302413,128,14553,94431106,CLX5
2025-09-24 19:46:30.514149999+00:00,160,1,432669,C,B,64.0,1,26,8058566301548,128,17898,94431108,CLX5
2025-09-24 19:46:30.520150213+00:00,160,1,432669,C,A,65.65,1,26,8058566301530,128,17595,94431115,CLX5
2025-09-24 19:46:30.524011817+00:00,160,1,432669,C,A,65.45,1,26,8058566302110,128,17985,94431120,CLX5
2025-09-24 19:46:30.526150277+00:00,160,1,432669,C,B,63.95,1,26,8058566301549,128,17608,94431123,CLX5
2025-09-24 19:46:30.538012281+00:00,160,1,432669,C,B,64.15,1,26,8058566302300,128,18110,94431139,CLX5
2025-09-24 19:46:30.538150457+00:00,160,1,432669,C,A,65.7,1,26,8058566302404,128,17668,94431140,CLX5
2025-09-24 19:46:30.540150739+00:00,160,1,432669,C,A,65.7,1,26,8058566301531,128,16272,94431143,CLX5
2025-09-24 19:46:30.544150711+00:00,160,1,432669,C,B,63.9,1,26,8058566302414,128,17701,94431148,CLX5
2025-09-24 19:46:30.546150725+00:00,160,1,432669,C,B,63.9,1,26,8058566301550,128,18193,94431150,CLX5
2025-09-24 19:46:30.556150929+00:00,160,1,432669,C,A,65.75,1,26,8058566301532,128,17837,94431161,CLX5
2025-09-24 19:46:30.562150953+00:00,160,1,432669,C,B,63.85,1,26,8058566301551,128,14587,94431170,CLX5
2025-09-24 19:46:30.568151053+00:00,160,1,432669,C,A,65.8,1,26,8058566302405,128,17253,94431181,CLX5
2025-09-24 19:46:30.570151241+00:00,160,1,432669,C,A,65.8,1,26,8058566301533,128,17809,94431183,CLX5
2025-09-24 19:46:30.582151517+00:00,160,1,432669,C,B,63.8,1,26,8058566302415,128,17313,94431202,CLX5
2025-09-24 19:46:30.584151799+00:00,160,1,432669,C,B,63.8,1,26,8058566301552,128,17286,94431205,CLX5
2025-09-24 19:46:30.588151867+00:00,160,1,432669,C,A,65.85,1,26,8058566301534,128,17932,94431209,CLX5
2025-09-24 19:46:30.602013445+00:00,160,1,432669,C,A,65.65,1,26,8058566302111,128,17756,94431230,CLX5
2025-09-24 19:46:30.602370165+00:00,160,1,432669,C,B,63.75,1,26,8058566301553,128,17789,94431231,CLX5
2025-09-24 19:46:30.604370159+00:00,160,1,432669,C,A,65.9,1,26,8058566383177,128,17692,94431233,CLX5
2025-09-24 19:46:30.606370191+00:00,160,1,432669,C,A,65.9,1,26,8058566301535,128,17532,94431235,CLX5
2025-09-24 19:46:30.614370555+00:00,160,1,432669,C,B,63.7,1,26,8058566301554,128,17634,94431248,CLX5
2025-09-24 19:46:30.616013733+00:00,160,1,432669,C,B,63.95,1,26,8058566302301,128,18524,94431250,CLX5
2025-09-24 19:46:30.618370565+00:00,160,1,432669,C,A,65.95,1,26,8058566301536,128,18155,94431253,CLX5
2025-09-24 19:46:30.670015075+00:00,160,1,432669,C,A,65.85,1,26,8058566302112,128,18128,94431300,CLX5
2025-09-24 19:46:30.680015147+00:00,160,1,432669,C,B,63.75,1,26,8058566302302,128,17645,94431308,CLX5
2025-09-24 19:46:30.714015847+00:00,160,1,432669,C,A,66.05,1,26,8058566302294,128,18309,94431329,CLX5
2025-09-24 19:46:30.718015989+00:00,160,1,432669,C,B,63.55,1,26,8058566302303,128,18139,94431330,CLX5
2025-09-24 19:46:30.744016595+00:00,160,1,432669,C,A,66.25,1,26,8058566302295,128,17615,94431338,CLX5
2025-09-24 19:46:30.748016759+00:00,160,1,432669,C,B,63.35,1,26,8058566302304,128,17444,94431339,CLX5
2025-09-24 19:46:30.770017279+00:00,160,1,432669,C,A,66.45,1,26,8058566302296,128,17867,94431345,CLX5
2025-09-24 19:46:30.772017101+00:00,160,1,432669,C,B,63.15,1,26,8058566302305,128,17872,94431346,CLX5
2025-09-24 19:46:30.790017439+00:00,160,1,432669,C,A,66.65,1,26,8058566302297,128,17647,94431351,CLX5
2025-09-24 19:46:30.792017549+00:00,160,1,432669,C,B,62.95,1,26,8058566374668,128,17701,94431352,CLX5
2025-09-24 19:46:33.791457409+00:00,160,1,432669,A,B,64.81,1,26,8058566387697,128,19577,94431639,CLX5
2025-09-24 19:46:34.332265309+00:00,160,1,432669,A,B,64.78,2,26,8058566387702,128,18459,94431652,CLX5
2025-09-24 19:46:34.332270433+00:00,160,1,432669,A,B,64.77,2,26,8058566387703,128,14330,94431653,CLX5
2025-09-24 19:46:34.609124157+00:00,160,1,432669,T,B,64.82,1,26,8058566387708,0,18340,94431669,CLX5
2025-09-24 19:46:34.609124157+00:00,160,1,432669,F,A,64.82,1,26,8058566387308,0,18340,94431669,CLX5
2025-09-24 19:46:34.609124157+00:00,160,1,432669,C,A,64.82,1,26,8058566387308,128,16902,94431670,CLX5
2025-09-24 19:46:34.609434109+00:00,160,1,432669,A,B,64.81,1,26,8058566387709,128,18058,94431673,CLX5
2025-09-24 19:46:34.609473393+00:00,160,1,432669,T,B,64.82,1,26,8058566387711,0,17248,94431675,CLX5
2025-09-24 19:46:34.609473393+00:00,160,1,432669,F,A,64.82,1,26,8058566387333,0,17248,94431675,CLX5
2025-09-24 19:46:34.609473393+00:00,160,1,432669,C,A,64.82,1,26,8058566387333,128,15089,94431676,CLX5
2025-09-24 19:46:34.609484679+00:00,160,1,432669,C,A,64.82,1,26,8058566387541,128,16736,94431678,CLX5
2025-09-24 19:46:34.610004575+00:00,160,1,432669,M,B,64.81,3,26,8058566383096,128,18853,94431731,CLX5
2025-09-24 19:46:34.610027093+00:00,160,1,432669,M,A,64.85,3,26,8058566373687,128,14767,94431733,CLX5
2025-09-24 19:46:34.610283863+00:00,160,1,432669,A,B,64.79,1,26,8058566387723,128,13761,94431747,CLX5
2025-09-24 19:46:34.610423097+00:00,160,1,432669,A,A,64.83,1,26,8058566387724,128,15601,94431756,CLX5
2025-09-24 19:46:34.610584041+00:00,160,1,432669,A,A,64.83,1,26,8058566387728,128,14848,94431766,CLX5
2025-09-24 19:46:34.611363047+00:00,160,1,432669,C,B,64.81,1,26,8058566387709,128,14894,94431785,CLX5
2025-09-24 19:46:34.617397667+00:00,160,1,432669,A,A,64.82,1,26,8058566387746,128,17864,94431826,CLX5
2025-09-24 19:46:34.617643917+00:00,160,1,432669,A,A,64.82,1,26,8058566387747,128,14514,94431834,CLX5
2025-09-24 19:46:34.617894695+00:00,160,1,432669,M,A,66.0,4,26,8058566275145,128,17180,94431838,CLX5
2025-09-24 19:46:34.617915853+00:00,160,1,432669,M,A,66.01,4,26,8058566373687,128,14424,94431840,CLX5
2025-09-24 19:46:34.621807579+00:00,160,1,432669,T,B,64.82,1,26,8058566387752,0,17863,94431850,CLX5
2025-09-24 19:46:34.621807579+00:00,160,1,432669,F,A,64.82,1,26,8058566387746,0,17863,94431850,CLX5
2025-09-24 19:46:34.621807579+00:00,160,1,432669,C,A,64.82,1,26,8058566387746,128,14376,94431851,CLX5
2025-09-24 19:46:34.622020977+00:00,160,1,432669,A,B,64.81,3,26,8058566387753,128,14608,94431855,CLX5
2025-09-24 19:46:34.622113269+00:00,160,1,432669,C,A,64.82,1,26,8058566387747,128,17838,94431856,CLX5
2025-09-24 19:46:34.622258203+00:00,160,1,432669,A,A,64.83,1,26,8058566387755,128,18696,94431862,CLX5
2025-09-24 19:46:34.622559935+00:00,160,1,432669,C,A,64.83,1,26,8058566387755,128,18710,94431867,CLX5
2025-09-24 19:46:34.624670729+00:00,160,1,432669,C,B,64.81,3,26,8058566387753,128,18136,94431870,CLX5
2025-09-24 19:46:34.626731221+00:00,160,1,432669,A,A,64.82,1,26,8058566387757,128,18096,94431872,CLX5
2025-09-24 19:46:34.626946751+00:00,160,1,432669,A,A,64.82,1,26,8058566387758,128,17672,94431876,CLX5
2025-09-24 19:46:34.630330313+00:00,160,1,432669,A,B,64.81,3,26,8058566387760,128,18518,94431880,CLX5
2025-09-24 19:46:34.660850303+00:00,160,1,432669,C,A,64.83,1,26,8058566387724,128,18283,94431899,CLX5
2025-09-24 19:46:34.663688131+00:00,160,1,432669,C,B,64.81,3,26,8058566387760,128,17974,94431902,CLX5
2025-09-24 19:46:35.018077559+00:00,160,1,432669,A,A,64.82,1,26,8058566387806,128,21874,94431998,CLX5
2025-09-24 19:46:35.025563385+00:00,160,1,432669,C,B,64.79,1,26,8058566387723,128,17836,94432002,CLX5
2025-09-24 19:46:35.356099245+00:00,160,1,432669,T,B,64.82,1,26,8058566388179,0,19099,94432353,CLX5
2025-09-24 19:46:35.356099245+00:00,160,1,432669,F,A,64.82,1,26,8058566387757,0,19099,94432353,CLX5
2025-09-24 19:46:35.356099245+00:00,160,1,432669,C,A,64.82,1,26,8058566387757,128,15892,94432354,CLX5
2025-09-24 19:46:35.357295947+00:00,160,1,432669,T,B,64.82,2,26,8058566388180,0,17759,94432368,CLX5
2025-09-24 19:46:35.357295947+00:00,160,1,432669,F,A,64.82,1,26,8058566387758,0,17759,94432368,CLX5
2025-09-24 19:46:35.357295947+00:00,160,1,432669,F,A,64.82,1,26,8058566387806,0,17759,94432368,CLX5
2025-09-24 19:46:35.357295947+00:00,160,1,432669,C,A,64.82,1,26,8058566387758,0,15754,94432369,CLX5
2025-09-24 19:46:35.357295947+00:00,160,1,432669,C,A,64.82,1,26,8058566387806,128,15754,94432369,CLX5
2025-09-24 19:46:35.357593765+00:00,160,1,432669,A,B,64.81,1,26,8058566388183,128,14602,94432375,CLX5
2025-09-24 19:46:35.357601927+00:00,160,1,432669,C,A,64.83,1,26,8058566387728,128,14822,94432380,CLX5
2025-09-24 19:46:35.357609011+00:00,160,1,432669,A,A,64.83,1,26,8058566388185,128,18462,94432387,CLX5
2025-09-24 19:46:35.357766001+00:00,160,1,432669,C,B,64.81,1,26,8058566388183,128,13796,94432412,CLX5
2025-09-24 19:46:35.362745917+00:00,160,1,432669,A,A,64.82,1,26,8058566388188,128,17644,94432433,CLX5
2025-09-24 19:46:35.362968281+00:00,160,1,432669,C,A,64.83,1,26,8058566388185,128,14632,94432439,CLX5
2025-09-24 19:46:35.367043839+00:00,160,1,432669,T,B,64.82,1,26,8058566388191,0,17831,94432445,CLX5
2025-09-24 19:46:35.367043839+00:00,160,1,432669,F,A,64.82,1,26,8058566388188,0,17831,94432445,CLX5
2025-09-24 19:46:35.367043839+00:00,160,1,432669,C,A,64.82,1,26,8058566388188,128,15443,94432446,CLX5
2025-09-24 19:46:35.367334053+00:00,160,1,432669,A,A,64.83,1,26,8058566388195,128,14338,94432455,CLX5
2025-09-24 19:46:35.367601401+00:00,160,1,432669,C,A,64.83,1,26,8058566388195,128,16948,94432466,CLX5
2025-09-24 19:46:35.371838999+00:00,160,1,432669,A,A,64.82,1,26,8058566388201,128,17867,94432476,CLX5
2025-09-24 19:46:35.390465903+00:00,160,1,432669,T,B,64.82,1,26,8058566388210,0,14614,94432495,CLX5
2025-09-24 19:46:35.390465903+00:00,160,1,432669,F,A,64.82,1,26,8058566388201,0,14614,94432495,CLX5
2025-09-24 19:46:35.390465903+00:00,160,1,432669,C,A,64.82,1,26,8058566388201,128,14614,94432495,CLX5
2025-09-24 19:46:35.390808241+00:00,160,1,432669,A,A,64.83,1,26,8058566388220,128,18082,94432531,CLX5
2025-09-24 19:46:35.391266123+00:00,160,1,432669,C,A,64.83,1,26,8058566388220,128,14270,94432542,CLX5
2025-09-24 19:46:35.395102287+00:00,160,1,432669,A,A,64.82,1,26,8058566388223,128,17017,94432550,CLX5
2025-09-24 19:46:35.432338487+00:00,160,1,432669,T,B,64.82,1,26,8058566388233,0,17906,94432588,CLX5
2025-09-24 19:46:35.432338487+00:00,160,1,432669,F,A,64.82,1,26,8058566388223,0,17906,94432588,CLX5
2025-09-24 19:46:35.432338487+00:00,160,1,432669,C,A,64.82,1,26,8058566388223,128,14569,94432589,CLX5
2025-09-24 19:46:35.432607237+00:00,160,1,432669,A,A,64.83,1,26,8058566388235,128,17220,94432599,CLX5
2025-09-24 19:46:35.432833709+00:00,160,1,432669,C,A,64.83,1,26,8058566388235,128,14821,94432604,CLX5
2025-09-24 19:46:35.432835399+00:00,160,1,432669,A,A,64.82,2,26,8058566388237,128,13579,94432605,CLX5
2025-09-24 19:46:35.432943529+00:00,160,1,432669,A,B,64.81,7,26,8058566388238,128,16654,94432609,CLX5
2025-09-24 19:46:35.569557059+00:00,160,1,432669,C,A,64.82,2,26,8058566388237,128,18025,94432732,CLX5
2025-09-24 19:46:35.570214899+00:00,160,1,432669,M,A,64.85,3,26,8058566373687,128,16083,94432769,CLX5
2025-09-24 19:46:35.702416483+00:00,160,1,432669,A,B,64.82,1,26,8058566388360,128,18539,94432804,CLX5
2025-09-24 19:46:35.702429385+00:00,160,1,432669,A,B,64.82,3,26,8058566388362,128,15132,94432807,CLX5
2025-09-24 19:46:35.702505393+00:00,160,1,432669,C,A,64.83,2,26,8058566385529,128,15052,94432824,CLX5
2025-09-24 19:46:35.702674903+00:00,160,1,432669,A,B,64.82,1,26,8058566388372,128,14688,94432836,CLX5
2025-09-24 19:46:35.702679851+00:00,160,1,432669,A,B,64.82,3,26,8058566388374,128,20123,94432842,CLX5
2025-09-24 19:46:35.702682527+00:00,160,1,432669,A,B,64.82,1,26,8058566388375,128,15509,94432845,CLX5
2025-09-24 19:46:35.702789023+00:00,160,1,432669,A,B,64.82,1,26,8058566388379,128,15484,94432852,CLX5
2025-09-24 19:46:35.702912205+00:00,160,1,432669,A,B,64.82,8,26,8058566388382,128,19679,94432856,CLX5
2025-09-24 19:46:35.703783713+00:00,160,1,432669,C,B,64.82,1,26,8058566388375,128,14174,94432894,CLX5
2025-09-24 19:46:35.705198823+00:00,160,1,432669,M,B,64.82,1,26,8058566378878,128,20948,94432938,CLX5
2025-09-24 19:46:35.732347597+00:00,160,1,432669,C,B,64.77,2,26,8058566387703,128,17429,94432951,CLX5
2025-09-24 19:46:35.732349749+00:00,160,1,432669,A,B,64.79,2,26,8058566388406,128,14456,94432952,CLX5
2025-09-24 19:46:35.890177477+00:00,160,1,432669,A,B,64.82,1,26,8058566388429,128,18993,94432987,CLX5
2025-09-24 19:46:35.890329767+00:00,160,1,432669,C,A,64.86,1,26,8058566385797,128,18044,94432988,CLX5
2025-09-24 19:46:35.890335431+00:00,160,1,432669,C,A,64.83,1,26,8058566385728,128,15541,94432989,CLX5
2025-09-24 19:46:35.890338099+00:00,160,1,432669,A,B,64.82,1,26,8058566388430,128,18505,94432991,CLX5
2025-09-24 19:46:35.890338943+00:00,160,1,432669,C,A,64.83,1,26,8058566385140,128,15471,94432992,CLX5
2025-09-24 19:46:36.254838607+00:00,160,1,432669,A,A,65.12,2,26,8058566388481,128,14092,94433056,CLX5
2025-09-24 19:46:36.254841275+00:00,160,1,432669,A,A,65.2,2,26,8058566388482,128,14153,94433057,CLX5
2025-09-24 19:46:36.254842349+00:00,160,1,432669,A,B,64.56,2,26,8058566388483,128,14012,94433058,CLX5
2025-09-24 19:46:36.254843387+00:00,160,1,432669,A,B,64.48,2,26,8058566388484,128,14116,94433059,CLX5
2025-09-24 19:46:36.266888271+00:00,160,1,432669,C,A,64.83,1,26,8058566385700,128,17739,94433334,CLX5
2025-09-24 19:46:36.266920057+00:00,160,1,432669,C,A,64.83,1,26,8058566384861,128,15508,94433347,CLX5
2025-09-24 19:46:36.266920383+00:00,160,1,432669,C,A,64.83,1,26,8058566385548,128,17901,94433348,CLX5
2025-09-24 19:46:36.266950317+00:00,160,1,432669,A,B,64.82,1,26,8058566388753,128,15824,94433368,CLX5
2025-09-24 19:46:36.266969379+00:00,160,1,432669,A,A,65.25,1,26,8058566388756,128,13709,94433374,CLX5
2025-09-24 19:46:36.266969571+00:00,160,1,432669,A,A,65.45,1,26,8058566388757,128,13709,94433374,CLX5
2025-09-24 19:46:36.266973795+00:00,160,1,432669,A,A,65.65,1,26,8058566388759,128,14234,94433375,CLX5
2025-09-24 19:46:36.266979631+00:00,160,1,432669,A,A,65.85,1,26,8058566388760,128,14234,94433375,CLX5
2025-09-24 19:46:36.266982263+00:00,160,1,432669,A,A,66.05,1,26,8058566388762,128,15043,94433376,CLX5
2025-09-24 19:46:36.266982439+00:00,160,1,432669,A,A,66.25,1,26,8058566388763,128,15043,94433376,CLX5
2025-09-24 19:46:36.266982619+00:00,160,1,432669,A,A,66.45,1,26,8058566388764,128,15043,94433376,CLX5
2025-09-24 19:46:36.266982795+00:00,160,1,432669,A,A,66.65,1,26,8058566388765,128,15043,94433376,CLX5
2025-09-24 19:46:36.266982973+00:00,160,1,432669,A,B,64.55,1,26,8058566388766,128,15043,94433376,CLX5
2025-09-24 19:46:36.266996929+00:00,160,1,432669,A,B,64.35,1,26,8058566388767,128,15043,94433376,CLX5
2025-09-24 19:46:36.266998139+00:00,160,1,432669,C,A,64.83,2,26,8058566367038,128,16841,94433377,CLX5
2025-09-24 19:46:36.266999887+00:00,160,1,432669,A,B,64.15,1,26,8058566388768,128,14571,94433378,CLX5
2025-09-24 19:46:36.267004609+00:00,160,1,432669,A,B,63.95,1,26,8058566388769,128,14571,94433378,CLX5
2025-09-24 19:46:36.267007605+00:00,160,1,432669,A,B,63.75,1,26,8058566388771,128,16435,94433379,CLX5
2025-09-24 19:46:36.267011905+00:00,160,1,432669,A,B,63.55,1,26,8058566388773,128,14781,94433383,CLX5
2025-09-24 19:46:36.267014631+00:00,160,1,432669,A,B,63.35,1,26,8058566388774,128,14781,94433383,CLX5
2025-09-24 19:46:36.267014809+00:00,160,1,432669,A,B,63.15,1,26,8058566388775,128,14781,94433383,CLX5
2025-09-24 19:46:36.267284157+00:00,160,1,432669,C,A,64.83,2,26,8058566384843,128,16252,94433427,CLX5
2025-09-24 19:46:36.267557855+00:00,160,1,432669,C,A,64.83,1,26,8058566365436,128,19783,94433442,CLX5
2025-09-24 19:46:36.267587869+00:00,160,1,432669,C,A,64.83,2,26,8058566365429,128,17119,94433453,CLX5
2025-09-24 19:46:36.267604815+00:00,160,1,432669,C,B,64.79,2,26,8058566388406,128,18103,94433460,CLX5
2025-09-24 19:46:36.267687967+00:00,160,1,432669,A,B,64.82,1,26,8058566388833,128,18417,94433469,CLX5
2025-09-24 19:46:36.267737213+00:00,160,1,432669,M,A,64.96,1,26,8058565075241,128,20925,94433489,CLX5
2025-09-24 19:46:36.267783675+00:00,160,1,432669,T,B,64.83,2,26,8058566388853,0,15066,94433508,CLX5
2025-09-24 19:46:36.267783675+00:00,160,1,432669,F,A,64.83,1,26,8058566365462,0,15066,94433508,CLX5
2025-09-24 19:46:36.267783675+00:00,160,1,432669,F,A,64.83,1,26,8058566365639,0,15066,94433508,CLX5
2025-09-24 19:46:36.267783675+00:00,160,1,432669,C,A,64.83,1,26,8058566365462,0,15066,94433508,CLX5
2025-09-24 19:46:36.267783675+00:00,160,1,432669,C,A,64.83,1,26,8058566365639,128,15066,94433508,CLX5
2025-09-24 19:46:36.267816083+00:00,160,1,432669,A,B,64.82,2,26,8058566388855,128,15003,94433519,CLX5
2025-09-24 19:46:36.268073197+00:00,160,1,432669,C,A,64.83,3,26,8058566385778,128,18400,94433552,CLX5
2025-09-24 19:46:36.269121527+00:00,160,1,432669,A,B,64.79,1,26,8058566388893,128,15048,94433660,CLX5
2025-09-24 19:46:36.269124637+00:00,160,1,432669,A,B,64.8,1,26,8058566388894,128,14550,94433661,CLX5
2025-09-24 19:46:36.269294877+00:00,160,1,432669,A,B,64.82,1,26,8058566388899,128,14879,94433690,CLX5
2025-09-24 19:46:36.269330281+00:00,160,1,432669,A,B,64.83,2,26,8058566388904,128,16403,94433697,CLX5
2025-09-24 19:46:36.269631823+00:00,160,1,432669,M,B,64.82,3,26,8058566373409,128,14780,94433721,CLX5
2025-09-24 19:46:36.270424421+00:00,160,1,432669,A,A,65.14,9,26,8058566388920,128,18342,94433771,CLX5
2025-09-24 19:46:36.270428241+00:00,160,1,432669,A,A,65.22,9,26,8058566388921,128,18342,94433771,CLX5
2025-09-24 19:46:36.270429107+00:00,160,1,432669,A,A,65.3,9,26,8058566388922,128,18342,94433771,CLX5
2025-09-24 19:46:36.270430259+00:00,160,1,432669,A,A,65.38,9,26,8058566388923,128,15369,94433772,CLX5
2025-09-24 19:46:36.270431101+00:00,160,1,432669,A,A,65.46,9,26,8058566388924,128,15369,94433772,CLX5
2025-09-24 19:46:36.270432253+00:00,160,1,432669,A,A,65.54,9,26,8058566388925,128,15369,94433772,CLX5
2025-09-24 19:46:36.270433253+00:00,160,1,432669,A,A,65.62,9,26,8058566388926,128,15369,94433772,CLX5
2025-09-24 19:46:36.270434635+00:00,160,1,432669,A,B,64.54,9,26,8058566388927,128,15369,94433772,CLX5
2025-09-24 19:46:36.270435595+00:00,160,1,432669,A,B,64.82,2,26,8058566388928,128,15369,94433772,CLX5
2025-09-24 19:46:36.270435773+00:00,160,1,432669,A,B,64.46,9,26,8058566388929,128,14566,94433774,CLX5
2025-09-24 19:46:36.270436651+00:00,160,1,432669,A,B,64.38,9,26,8058566388930,128,14566,94433774,CLX5
2025-09-24 19:46:36.270437515+00:00,160,1,432669,A,B,64.3,9,26,8058566388931,128,15676,94433775,CLX5
2025-09-24 19:46:36.270438283+00:00,160,1,432669,A,B,64.22,9,26,8058566388932,128,15676,94433775,CLX5
2025-09-24 19:46:36.270438973+00:00,160,1,432669,A,B,64.14,9,26,8058566388933,128,15676,94433775,CLX5
2025-09-24 19:46:36.270440011+00:00,160,1,432669,A,B,64.06,9,26,8058566388934,128,15676,94433775,CLX5
2025-09-24 19:46:36.270445347+00:00,160,1,432669,A,B,63.98,9,26,8058566388935,128,14169,94433776,CLX5
2025-09-24 19:46:36.271954593+00:00,160,1,432669,M,B,64.82,1,26,8058566372953,128,13517,94433839,CLX5
2025-09-24 19:46:36.272075415+00:00,160,1,432669,C,A,64.86,4,26,8058566151297,128,14681,94433842,CLX5
2025-09-24 19:46:36.272851483+00:00,160,1,432669,A,A,64.84,1,26,8058566388973,128,14812,94433901,CLX5
2025-09-24 19:46:36.272982631+00:00,160,1,432669,M,B,64.83,1,26,8058566378878,128,17759,94433906,CLX5
2025-09-24 19:46:36.273396027+00:00,160,1,432669,M,A,66.01,4,26,8058566373687,128,14812,94433928,CLX5
2025-09-24 19:46:36.275051859+00:00,160,1,432669,A,B,64.83,1,26,8058566388981,128,17962,94433967,CLX5
2025-09-24 19:46:36.275091447+00:00,160,1,432669,A,B,64.83,2,26,8058566388982,128,15785,94433970,CLX5
2025-09-24 19:46:36.275897505+00:00,160,1,432669,C,B,64.82,1,26,8058566388899,128,14615,94433985,CLX5
2025-09-24 19:46:36.275911041+00:00,160,1,432669,C,B,64.8,1,26,8058566378342,128,14704,94433988,CLX5
2025-09-24 19:46:36.275914763+00:00,160,1,432669,C,A,64.84,2,26,8058566365394,128,14979,94433990,CLX5
2025-09-24 19:46:36.275955427+00:00,160,1,432669,A,B,64.83,1,26,8058566388985,128,19000,94433991,CLX5
2025-09-24 19:46:36.276989821+00:00,160,1,432669,M,B,64.82,1,26,8058566381419,128,14555,94434063,CLX5
2025-09-24 19:46:36.277346735+00:00,160,1,432669,C,A,64.84,1,26,8058566388973,128,15027,94434087,CLX5
2025-09-24 19:46:36.277621377+00:00,160,1,432669,A,A,64.84,1,26,8058566389002,128,15012,94434093,CLX5
2025-09-24 19:46:36.277624661+00:00,160,1,432669,M,B,64.82,1,26,8058566385977,128,14164,94434094,CLX5
2025-09-24 19:46:36.277915949+00:00,160,1,432669,C,A,64.84,1,26,8058566389002,128,15305,94434101,CLX5
2025-09-24 19:46:36.278147089+00:00,160,1,432669,A,A,64.84,1,26,8058566389006,128,18788,94434120,CLX5
2025-09-24 19:46:36.278386059+00:00,160,1,432669,M,A,64.85,1,26,8058566173085,128,15491,94434127,CLX5
2025-09-24 19:46:36.278556683+00:00,160,1,432669,C,A,64.84,1,26,8058566389006,128,14949,94434129,CLX5
2025-09-24 19:46:36.278941607+00:00,160,1,432669,M,A,64.86,4,26,8058566275145,128,14245,94434137,CLX5
2025-09-24 19:46:36.281441549+00:00,160,1,432669,A,B,64.83,1,26,8058566389024,128,19063,94434182,CLX5
2025-09-24 19:46:36.281524701+00:00,160,1,432669,A,A,64.84,1,26,8058566389026,128,13745,94434184,CLX5
2025-09-24 19:46:36.283249725+00:00,160,1,432669,C,A,64.84,1,26,8058566389026,128,14925,94434220,CLX5
2025-09-24 19:46:36.283399037+00:00,160,1,432669,A,A,64.84,1,26,8058566389036,128,18303,94434245,CLX5
2025-09-24 19:46:36.285740451+00:00,160,1,432669,C,A,64.84,1,26,8058566389036,128,19040,94434284,CLX5
2025-09-24 19:46:36.288800777+00:00,160,1,432669,A,A,64.84,1,26,8058566389071,128,14074,94434406,CLX5
2025-09-24 19:46:36.288942331+00:00,160,1,432669,A,B,64.83,1,26,8058566389072,128,19768,94434407,CLX5
2025-09-24 19:46:36.294054585+00:00,160,1,432669,C,A,64.84,1,26,8058566389071,128,15372,94434485,CLX5
2025-09-24 19:46:36.296027373+00:00,160,1,432669,A,A,65.1,1,26,8058566389118,128,17966,94434492,CLX5
2025-09-24 19:46:36.296031503+00:00,160,1,432669,A,A,65.15,1,26,8058566389119,128,17966,94434492,CLX5
2025-09-24 19:46:36.296032749+00:00,160,1,432669,A,A,65.2,1,26,8058566389120,128,17966,94434492,CLX5
2025-09-24 19:46:36.296033807+00:00,160,1,432669,A,A,65.25,1,26,8058566389121,128,17966,94434492,CLX5
2025-09-24 19:46:36.296034997+00:00,160,1,432669,A,A,65.3,1,26,8058566389122,128,17966,94434492,CLX5
2025-09-24 19:46:36.296036071+00:00,160,1,432669,A,A,65.35,1,26,8058566389123,128,17966,94434492,CLX5
2025-09-24 19:46:36.296037243+00:00,160,1,432669,A,A,65.4,1,26,8058566389124,128,17966,94434492,CLX5
2025-09-24 19:46:36.296038145+00:00,160,1,432669,A,A,65.45,1,26,8058566389125,128,17966,94434492,CLX5
2025-09-24 19:46:36.296039355+00:00,160,1,432669,A,A,65.5,1,26,8058566389126,128,17966,94434492,CLX5
2025-09-24 19:46:36.296040373+00:00,160,1,432669,A,A,65.55,1,26,8058566389127,128,13602,94434493,CLX5
2025-09-24 19:46:36.296041447+00:00,160,1,432669,A,A,65.6,1,26,8058566389128,128,13602,94434493,CLX5
2025-09-24 19:46:36.296042715+00:00,160,1,432669,A,A,65.65,1,26,8058566389129,128,13602,94434493,CLX5
2025-09-24 19:46:36.296044097+00:00,160,1,432669,A,A,65.7,1,26,8058566389130,128,13602,94434493,CLX5
2025-09-24 19:46:36.296045019+00:00,160,1,432669,A,A,65.75,1,26,8058566389131,128,15873,94434494,CLX5
2025-09-24 19:46:36.296046093+00:00,160,1,432669,A,A,65.8,1,26,8058566389132,128,16583,94434495,CLX5
2025-09-24 19:46:36.296047053+00:00,160,1,432669,A,A,65.85,1,26,8058566389133,128,14396,94434496,CLX5
2025-09-24 19:46:36.296048301+00:00,160,1,432669,A,A,65.9,1,26,8058566389134,128,14572,94434497,CLX5
2025-09-24 19:46:36.296049435+00:00,160,1,432669,A,A,65.95,1,26,8058566389135,128,14363,94434498,CLX5
2025-09-24 19:46:36.296051181+00:00,160,1,432669,A,B,64.6,1,26,8058566389136,128,16657,94434499,CLX5
2025-09-24 19:46:36.296052583+00:00,160,1,432669,A,B,64.55,1,26,8058566389137,128,16639,94434500,CLX5
2025-09-24 19:46:36.296053369+00:00,160,1,432669,A,B,64.5,1,26,8058566389138,128,17765,94434501,CLX5
2025-09-24 19:46:36.296054695+00:00,160,1,432669,A,B,64.45,1,26,8058566389139,128,15905,94434502,CLX5
2025-09-24 19:46:36.296055559+00:00,160,1,432669,A,B,64.4,1,26,8058566389140,128,17601,94434503,CLX5
2025-09-24 19:46:36.296056539+00:00,160,1,432669,A,B,64.35,1,26,8058566389141,128,14536,94434504,CLX5
2025-09-24 19:46:36.296057691+00:00,160,1,432669,A,B,64.3,1,26,8058566389142,128,13894,94434505,CLX5
2025-09-24 19:46:36.296058745+00:00,160,1,432669,A,B,64.25,1,26,8058566389143,128,16164,94434506,CLX5
2025-09-24 19:46:36.296060051+00:00,160,1,432669,A,B,64.2,1,26,8058566389144,128,16256,94434507,CLX5
2025-09-24 19:46:36.296060915+00:00,160,1,432669,A,B,64.15,1,26,8058566389145,128,17032,94434508,CLX5
2025-09-24 19:46:36.296061895+00:00,160,1,432669,A,B,64.1,1,26,8058566389146,128,16417,94434509,CLX5
2025-09-24 19:46:36.296062835+00:00,160,1,432669,A,B,64.05,1,26,8058566389147,128,16365,94434510,CLX5
2025-09-24 19:46:36.296063949+00:00,160,1,432669,A,B,64.0,1,26,8058566389148,128,15751,94434511,CLX5
2025-09-24 19:46:36.296064929+00:00,160,1,432669,A,B,63.95,1,26,8058566389149,128,16443,94434512,CLX5
2025-09-24 19:46:36.296065869+00:00,160,1,432669,A,B,63.9,1,26,8058566389150,128,16517,94434513,CLX5
2025-09-24 19:46:36.296066715+00:00,160,1,432669,A,B,63.85,1,26,8058566389151,128,17594,94434514,CLX5
2025-09-24 19:46:36.296067807+00:00,160,1,432669,A,B,63.8,1,26,8058566389152,128,14071,94434515,CLX5
2025-09-24 19:46:36.296068767+00:00,160,1,432669,A,B,63.75,1,26,8058566389153,128,14106,94434516,CLX5
2025-09-24 19:46:36.296209959+00:00,160,1,432669,C,B,64.83,1,26,8058566389072,128,16522,94434574,CLX5
2025-09-24 19:46:36.296227129+00:00,160,1,432669,A,A,64.84,1,26,8058566389221,128,14960,94434578,CLX5
2025-09-24 19:46:36.297075975+00:00,160,1,432669,C,A,64.84,1,26,8058566389221,128,16367,94434616,CLX5
2025-09-24 19:46:36.298386585+00:00,160,1,432669,T,A,64.83,1,26,8058566389319,0,17835,94434654,CLX5
2025-09-24 19:46:36.298386585+00:00,160,1,432669,F,B,64.83,1,26,8058566388904,0,17835,94434654,CLX5
2025-09-24 19:46:36.298386585+00:00,160,1,432669,M,B,64.83,1,26,8058566388904,128,16030,94434655,CLX5
2025-09-24 19:46:36.322710049+00:00,160,1,432669,A,B,64.83,5,26,8058566389389,128,19105,94434765,CLX5
2025-09-24 19:46:36.322868597+00:00,160,1,432669,A,B,64.83,1,26,8058566389400,128,17374,94434772,CLX5
2025-09-24 19:46:36.322877313+00:00,160,1,432669,A,B,64.83,1,26,8058566389401,128,15659,94434773,CLX5
2025-09-24 19:46:36.322882497+00:00,160,1,432669,A,B,64.83,1,26,8058566389402,128,14742,94434774,CLX5
2025-09-24 19:46:36.322909299+00:00,160,1,432669,C,B,64.81,7,26,8058566388238,128,18034,94434775,CLX5
2025-09-24 19:46:36.322911181+00:00,160,1,432669,C,B,64.81,1,26,8058566384177,128,14564,94434776,CLX5
2025-09-24 19:46:36.332434325+00:00,160,1,432669,T,A,64.83,1,26,8058566389428,0,16819,94434807,CLX5
2025-09-24 19:46:36.332434325+00:00,160,1,432669,F,B,64.83,1,26,8058566388904,0,16819,94434807,CLX5
2025-09-24 19:46:36.332434325+00:00,160,1,432669,C,B,64.83,1,26,8058566388904,128,15772,94434808,CLX5
2025-09-24 19:46:36.339942615+00:00,160,1,432669,C,B,64.78,2,26,8058566387702,128,14246,94434814,CLX5
2025-09-24 19:46:36.341921855+00:00,160,1,432669,M,B,64.83,4,26,8058566389389,128,18833,94434818,CLX5
2025-09-24 19:46:36.361195867+00:00,160,1,432669,M,B,64.49,10,26,8058566151203,128,18198,94434849,CLX5
2025-09-24 19:46:36.369964695+00:00,160,1,432669,A,B,64.83,1,26,8058566389459,128,17673,94434861,CLX5
2025-09-24 19:46:36.457616069+00:00,160,1,432669,C,B,64.83,1,26,8058566389402,128,15479,94435093,CLX5
2025-09-24 19:46:36.457616433+00:00,160,1,432669,C,B,64.83,1,26,8058566389459,128,18843,94435095,CLX5
2025-09-24 19:46:36.457788551+00:00,160,1,432669,C,B,64.83,1,26,8058566389400,128,15955,94435096,CLX5
2025-09-24 19:46:36.532692397+00:00,160,1,432669,A,B,64.8,2,26,8058566389668,128,17899,94435171,CLX5
2025-09-24 19:46:36.532696543+00:00,160,1,432669,A,B,64.79,2,26,8058566389669,128,14251,94435172,CLX5
2025-09-24 19:46:36.635480209+00:00,160,1,432669,C,B,64.79,1,26,8058566374245,128,17699,94435234,CLX5
2025-09-24 19:46:37.300009797+00:00,160,1,432669,C,B,64.83,1,26,8058566388985,128,14259,94435490,CLX5
2025-09-24 19:46:38.841282353+00:00,160,1,432669,A,B,64.83,1,26,8058566389930,128,18828,94435680,CLX5
2025-09-24 19:46:38.841462133+00:00,160,1,432669,A,B,64.83,1,26,8058566389931,128,18734,94435681,CLX5
2025-09-24 19:46:40.296033767+00:00,160,1,432669,A,A,65.1,1,26,8058566390011,128,18314,94435823,CLX5
2025-09-24 19:46:40.296037783+00:00,160,1,432669,A,A,65.2,1,26,8058566390012,128,16492,94435824,CLX5
2025-09-24 19:46:40.296038971+00:00,160,1,432669,A,A,65.3,1,26,8058566390013,128,16551,94435825,CLX5
2025-09-24 19:46:40.296040565+00:00,160,1,432669,A,A,65.4,1,26,8058566390014,128,14232,94435826,CLX5
2025-09-24 19:46:40.296041929+00:00,160,1,432669,A,A,65.5,1,26,8058566390015,128,14202,94435827,CLX5
2025-09-24 19:46:40.296043061+00:00,160,1,432669,A,A,65.6,1,26,8058566390016,128,15843,94435828,CLX5
2025-09-24 19:46:40.296044385+00:00,160,1,432669,A,A,65.7,1,26,8058566390017,128,14767,94435829,CLX5
2025-09-24 19:46:40.296045711+00:00,160,1,432669,A,A,65.8,1,26,8058566390018,128,13205,94435830,CLX5
2025-09-24 19:46:40.296046901+00:00,160,1,432669,A,A,65.9,1,26,8058566390019,128,16055,94435831,CLX5
2025-09-24 19:46:40.296048399+00:00,160,1,432669,A,B,64.6,1,26,8058566390020,128,14970,94435832,CLX5
2025-09-24 19:46:40.296049723+00:00,160,1,432669,A,B,64.5,1,26,8058566390021,128,17708,94435833,CLX5
2025-09-24 19:46:40.296051547+00:00,160,1,432669,A,B,64.4,1,26,8058566390022,128,14302,94435834,CLX5
2025-09-24 19:46:40.296052621+00:00,160,1,432669,A,B,64.3,1,26,8058566390023,128,14410,94435835,CLX5
2025-09-24 19:46:40.296053543+00:00,160,1,432669,A,B,64.2,1,26,8058566390024,128,14114,94435836,CLX5
2025-09-24 19:46:40.296054561+00:00,160,1,432669,A,B,64.1,1,26,8058566390025,128,14051,94435837,CLX5
2025-09-24 19:46:40.296055521+00:00,160,1,432669,A,B,64.0,1,26,8058566390026,128,13974,94435838,CLX5
2025-09-24 19:46:40.296056731+00:00,160,1,432669,A,B,63.9,1,26,8058566390027,128,12993,94435839,CLX5
2025-09-24 19:46:40.296057767+00:00,160,1,432669,A,B,63.8,1,26,8058566390028,128,16019,94435840,CLX5
2025-09-24 19:46:40.296118495+00:00,160,1,432669,A,A,64.96,2,26,8058566390031,128,14902,94435843,CLX5
2025-09-24 19:46:40.296120453+00:00,160,1,432669,A,A,65.0,2,26,8058566390032,128,14809,94435844,CLX5
2025-09-24 19:46:40.296121299+00:00,160,1,432669,A,A,65.04,2,26,8058566390033,128,14809,94435844,CLX5
2025-09-24 19:46:40.296122565+00:00,160,1,432669,A,A,65.08,2,26,8058566390034,128,14809,94435844,CLX5
2025-09-24 19:46:40.296123391+00:00,160,1,432669,A,A,65.12,2,26,8058566390035,128,14809,94435844,CLX5
2025-09-24 19:46:40.296124579+00:00,160,1,432669,A,A,65.16,2,26,8058566390036,128,14809,94435844,CLX5
2025-09-24 19:46:40.296125503+00:00,160,1,432669,A,A,65.2,2,26,8058566390037,128,17761,94435845,CLX5
2025-09-24 19:46:40.296126519+00:00,160,1,432669,A,A,65.24,2,26,8058566390038,128,17761,94435845,CLX5
2025-09-24 19:46:40.296127403+00:00,160,1,432669,A,A,65.28,2,26,8058566390039,128,17761,94435845,CLX5
2025-09-24 19:46:40.296128921+00:00,160,1,432669,A,A,65.32,2,26,8058566390040,128,14048,94435846,CLX5
2025-09-24 19:46:40.296129955+00:00,160,1,432669,A,A,65.36,2,26,8058566390041,128,14662,94435847,CLX5
2025-09-24 19:46:40.296131165+00:00,160,1,432669,A,A,65.4,2,26,8058566390042,128,14080,94435848,CLX5
2025-09-24 19:46:40.296132165+00:00,160,1,432669,A,A,65.44,2,26,8058566390043,128,15916,94435849,CLX5
2025-09-24 19:46:40.296133335+00:00,160,1,432669,A,A,65.48,2,26,8058566390044,128,16297,94435850,CLX5
2025-09-24 19:46:40.296134813+00:00,160,1,432669,A,B,64.72,2,26,8058566390045,128,14146,94435851,CLX5
2025-09-24 19:46:40.296135715+00:00,160,1,432669,A,B,64.68,2,26,8058566390046,128,14173,94435852,CLX5
2025-09-24 19:46:40.296136907+00:00,160,1,432669,A,B,64.64,2,26,8058566390047,128,13962,94435853,CLX5
2025-09-24 19:46:40.296137943+00:00,160,1,432669,A,B,64.6,2,26,8058566390048,128,14017,94435854,CLX5
2025-09-24 19:46:40.296138943+00:00,160,1,432669,A,B,64.56,2,26,8058566390049,128,14219,94435855,CLX5
2025-09-24 19:46:40.296140593+00:00,160,1,432669,A,B,64.52,2,26,8058566390050,128,17487,94435856,CLX5
2025-09-24 19:46:40.296141419+00:00,160,1,432669,A,B,64.48,2,26,8058566390051,128,16134,94435857,CLX5
2025-09-24 19:46:40.296142379+00:00,160,1,432669,A,B,64.44,2,26,8058566390052,128,16792,94435858,CLX5
2025-09-24 19:46:40.296143607+00:00,160,1,432669,A,B,64.4,2,26,8058566390053,128,15192,94435859,CLX5
2025-09-24 19:46:40.296144739+00:00,160,1,432669,A,B,64.36,2,26,8058566390054,128,14045,94435860,CLX5
2025-09-24 19:46:40.296145835+00:00,160,1,432669,A,B,64.32,2,26,8058566390055,128,13903,94435861,CLX5
2025-09-24 19:46:40.296146815+00:00,160,1,432669,A,B,64.28,2,26,8058566390056,128,14328,94435862,CLX5
2025-09-24 19:46:40.296148119+00:00,160,1,432669,A,B,64.24,2,26,8058566390057,128,16227,94435863,CLX5
2025-09-24 19:46:40.296149675+00:00,160,1,432669,A,B,64.2,2,26,8058566390058,128,15708,94435864,CLX5
2025-09-24 19:46:40.332337139+00:00,160,1,432669,A,A,64.87,2,26,8058566390073,128,17703,94435885,CLX5
2025-09-24 19:46:40.332341305+00:00,160,1,432669,A,A,64.88,2,26,8058566390074,128,14167,94435886,CLX5
2025-09-24 19:46:40.332342613+00:00,160,1,432669,A,B,64.82,2,26,8058566390075,128,14149,94435887,CLX5
2025-09-24 19:46:40.332343957+00:00,160,1,432669,A,B,64.81,2,26,8058566390076,128,17766,94435888,CLX5
2025-09-24 19:46:43.020171305+00:00,160,1,432669,A,B,64.83,2,26,8058566390160,128,16906,94436191,CLX5
2025-09-24 19:46:43.021003109+00:00,160,1,432669,C,A,64.84,2,26,8058566364745,128,14900,94436227,CLX5
2025-09-24 19:46:43.021003263+00:00,160,1,432669,C,A,64.84,1,26,8058566364746,128,15043,94436228,CLX5
2025-09-24 19:46:43.021006693+00:00,160,1,432669,C,A,64.84,1,26,8058566364411,128,14830,94436230,CLX5
2025-09-24 19:46:43.021153535+00:00,160,1,432669,A,B,64.83,3,26,8058566390172,128,17950,94436232,CLX5
2025-09-24 19:46:43.021268057+00:00,160,1,432669,A,B,64.83,1,26,8058566390176,128,15142,94436244,CLX5
2025-09-24 19:46:43.021269305+00:00,160,1,432669,C,A,64.84,1,26,8058566364660,128,15599,94436245,CLX5
2025-09-24 19:46:43.021953869+00:00,160,1,432669,C,A,64.84,2,26,8058566364372,128,18936,94436254,CLX5
2025-09-24 19:46:43.022087957+00:00,160,1,432669,C,A,64.87,1,26,8058566383138,128,14381,94436272,CLX5
2025-09-24 19:46:43.022136397+00:00,160,1,432669,A,B,64.83,1,26,8058566390194,128,15164,94436278,CLX5
2025-09-24 19:46:43.022253703+00:00,160,1,432669,C,B,64.83,1,26,8058566390194,128,15127,94436289,CLX5
2025-09-24 19:46:43.836146899+00:00,160,1,432669,A,A,64.9,1,26,8058566390387,128,18284,94436772,CLX5
2025-09-24 19:46:46.342712213+00:00,160,1,432669,A,B,64.83,4,26,8058566390417,128,20766,94436860,CLX5
2025-09-24 19:46:46.352557769+00:00,160,1,432669,T,A,64.83,1,26,8058566390418,0,18027,94436862,CLX5
2025-09-24 19:46:46.352557769+00:00,160,1,432669,F,B,64.83,1,26,8058566378878,0,18027,94436862,CLX5
2025-09-24 19:46:46.352557769+00:00,160,1,432669,C,B,64.83,1,26,8058566378878,128,16502,94436863,CLX5
2025-09-24 19:46:53.962968607+00:00,160,1,432669,C,B,64.8,3,26,8058566387231,128,18227,94437070,CLX5
2025-09-24 19:46:54.308049355+00:00,160,1,432669,A,A,64.98,2,26,8058566390482,128,17726,94437073,CLX5
2025-09-24 19:46:54.314774433+00:00,160,1,432669,C,B,64.81,1,26,8058566387697,128,18184,94437074,CLX5
2025-09-24 19:46:54.656510555+00:00,160,1,432669,C,B,64.45,1,26,8058566285545,128,18846,94437076,CLX5
2025-09-24 19:46:54.713382631+00:00,160,1,432669,A,B,64.4,1,26,8058566390483,128,18869,94437077,CLX5
2025-09-24 19:46:54.754806129+00:00,160,1,432669,A,B,64.79,3,26,8058566390484,128,17846,94437078,CLX5
2025-09-24 19:46:56.052199405+00:00,160,1,432669,C,A,64.98,2,26,8058566390482,128,19167,94437080,CLX5
2025-09-24 19:46:56.328052235+00:00,160,1,432669,M,A,64.93,1,26,8058566125142,128,17354,94437083,CLX5
2025-09-24 19:46:57.017654501+00:00,160,1,432669,A,A,64.84,1,26,8058566390497,128,18736,94437154,CLX5
2025-09-24 19:46:57.298725947+00:00,160,1,432669,C,B,64.83,3,26,8058566390172,128,19651,94437156,CLX5
2025-09-24 19:46:57.298877851+00:00,160,1,432669,A,A,64.84,2,26,8058566390500,128,16500,94437159,CLX5
2025-09-24 19:46:58.515134841+00:00,160,1,432669,A,A,64.98,2,26,8058566390516,128,19376,94437217,CLX5
2025-09-24 19:47:00.037978049+00:00,160,1,432669,A,B,64.83,1,26,8058566390518,128,18752,94437222,CLX5
2025-09-24 19:47:00.086448747+00:00,160,1,432669,M,A,64.93,1,26,8058566131103,128,18072,94437226,CLX5
2025-09-24 19:47:01.777444715+00:00,160,1,432669,A,B,64.83,1,26,8058566390527,128,18514,94437242,CLX5
2025-09-24 19:47:03.376933587+00:00,160,1,432669,C,A,65.05,1,26,8058566381608,128,20949,94437292,CLX5
2025-09-24 19:47:03.486165459+00:00,160,1,432669,A,A,65.03,1,26,8058566390542,128,20710,94437295,CLX5
2025-09-24 19:47:04.568000547+00:00,160,1,432669,C,A,65.01,1,26,8058566387155,128,17360,94437388,CLX5
2025-09-24 19:47:04.662343667+00:00,160,1,432669,A,A,65.0,1,26,8058566390598,128,17617,94437395,CLX5
2025-09-24 19:47:05.008931035+00:00,160,1,432669,C,A,65.02,1,26,8058566387170,128,18444,94437397,CLX5
2025-09-24 19:47:05.026666983+00:00,160,1,432669,C,A,64.84,2,26,8058566390500,128,18492,94437398,CLX5
2025-09-24 19:47:05.087158463+00:00,160,1,432669,A,A,65.0,1,26,8058566390599,128,18553,94437401,CLX5
2025-09-24 19:47:05.286824873+00:00,160,1,432669,A,A,65.3,1,26,8058566390601,128,17480,94437403,CLX5
2025-09-24 19:47:05.286828021+00:00,160,1,432669,A,A,65.36,1,26,8058566390602,128,14577,94437404,CLX5
2025-09-24 19:47:05.286829135+00:00,160,1,432669,A,A,65.42,1,26,8058566390603,128,13871,94437405,CLX5
2025-09-24 19:47:05.286830383+00:00,160,1,432669,A,A,65.48,1,26,8058566390604,128,15481,94437406,CLX5
2025-09-24 19:47:05.286831939+00:00,160,1,432669,A,B,64.42,1,26,8058566390605,128,14411,94437407,CLX5
2025-09-24 19:47:05.286833915+00:00,160,1,432669,A,B,64.36,1,26,8058566390606,128,13996,94437408,CLX5
2025-09-24 19:47:05.286835221+00:00,160,1,432669,A,B,64.3,1,26,8058566390607,128,14136,94437409,CLX5
2025-09-24 19:47:05.286836239+00:00,160,1,432669,A,B,64.24,1,26,8058566390608,128,18302,94437410,CLX5
2025-09-24 19:47:05.286839023+00:00,160,1,432669,A,A,65.44,1,26,8058566390609,128,14400,94437411,CLX5
2025-09-24 19:47:05.286840979+00:00,160,1,432669,A,A,65.52,1,26,8058566390610,128,14172,94437412,CLX5
2025-09-24 19:47:05.286842747+00:00,160,1,432669,A,A,65.6,1,26,8058566390611,128,13904,94437413,CLX5
2025-09-24 19:47:05.286843687+00:00,160,1,432669,A,A,65.68,1,26,8058566390612,128,14283,94437414,CLX5
2025-09-24 19:47:05.286844475+00:00,160,1,432669,A,B,64.24,1,26,8058566390613,128,14133,94437415,CLX5
2025-09-24 19:47:05.286845243+00:00,160,1,432669,A,B,64.16,1,26,8058566390614,128,16999,94437416,CLX5
2025-09-24 19:47:05.286846683+00:00,160,1,432669,A,B,64.08,1,26,8058566390615,128,13964,94437417,CLX5
2025-09-24 19:47:05.286847527+00:00,160,1,432669,A,B,64.0,1,26,8058566390616,128,14192,94437418,CLX5
2025-09-24 19:47:06.843550545+00:00,160,1,432669,A,A,64.84,1,26,8058566390649,128,19511,94437469,CLX5
2025-09-24 19:47:07.054766183+00:00,160,1,432669,A,A,64.84,2,26,8058566390663,128,14919,94437518,CLX5
2025-09-24 19:47:07.253004709+00:00,160,1,432669,T,A,64.83,1,26,8058566390693,0,17664,94437641,CLX5
2025-09-24 19:47:07.253004709+00:00,160,1,432669,F,B,64.83,1,26,8058566388981,0,17664,94437641,CLX5
2025-09-24 19:47:07.253004709+00:00,160,1,432669,C,B,64.83,1,26,8058566388981,128,14812,94437642,CLX5
2025-09-24 19:47:07.653043131+00:00,160,1,432669,T,A,64.83,1,26,8058566390702,0,19741,94437655,CLX5
2025-09-24 19:47:07.653043131+00:00,160,1,432669,F,B,64.83,1,26,8058566388982,0,19741,94437655,CLX5
2025-09-24 19:47:07.653043131+00:00,160,1,432669,M,B,64.83,1,26,8058566388982,128,17526,94437656,CLX5
2025-09-24 19:47:08.053208919+00:00,160,1,432669,T,A,64.83,1,26,8058566390706,0,19573,94437661,CLX5
2025-09-24 19:47:08.053208919+00:00,160,1,432669,F,B,64.83,1,26,8058566388982,0,19573,94437661,CLX5
2025-09-24 19:47:08.053208919+00:00,160,1,432669,C,B,64.83,1,26,8058566388982,128,17284,94437662,CLX5
2025-09-24 19:47:08.453683393+00:00,160,1,432669,T,A,64.83,1,26,8058566390707,0,21947,94437666,CLX5
2025-09-24 19:47:08.453683393+00:00,160,1,432669,F,B,64.83,1,26,8058566389024,0,21947,94437666,CLX5
2025-09-24 19:47:08.453683393+00:00,160,1,432669,C,B,64.83,1,26,8058566389024,128,18226,94437667,CLX5
2025-09-24 19:47:08.453968885+00:00,160,1,432669,A,B,64.83,1,26,8058566390709,128,19466,94437668,CLX5
2025-09-24 19:47:08.665656857+00:00,160,1,432669,A,B,64.82,1,26,8058566390710,128,23328,94437673,CLX5
2025-09-24 19:47:08.854091071+00:00,160,1,432669,T,A,64.83,1,26,8058566390712,0,20352,94437675,CLX5
2025-09-24 19:47:08.854091071+00:00,160,1,432669,F,B,64.83,1,26,8058566389389,0,20352,94437675,CLX5
2025-09-24 19:47:08.854091071+00:00,160,1,432669,M,B,64.83,3,26,8058566389389,128,18112,94437676,CLX5
2025-09-24 19:47:09.062938879+00:00,160,1,432669,A,B,64.83,1,26,8058566390715,128,23076,94437681,CLX5
2025-09-24 19:47:09.135657073+00:00,160,1,432669,C,B,64.8,1,26,8058566378925,128,21062,94437690,CLX5
2025-09-24 19:47:09.254235915+00:00,160,1,432669,T,A,64.83,1,26,8058566390717,0,19377,94437691,CLX5
2025-09-24 19:47:09.254235915+00:00,160,1,432669,F,B,64.83,1,26,8058566389389,0,19377,94437691,CLX5
2025-09-24 19:47:09.254235915+00:00,160,1,432669,M,B,64.83,2,26,8058566389389,128,17576,94437692,CLX5
2025-09-24 19:47:09.654401147+00:00,160,1,432669,T,A,64.83,1,26,8058566390721,0,21401,94437698,CLX5
2025-09-24 19:47:09.654401147+00:00,160,1,432669,F,B,64.83,1,26,8058566389389,0,21401,94437698,CLX5
2025-09-24 19:47:09.654401147+00:00,160,1,432669,M,B,64.83,1,26,8058566389389,128,18982,94437699,CLX5
2025-09-24 19:47:09.687165233+00:00,160,1,432669,A,B,64.83,2,26,8058566390723,128,21559,94437700,CLX5
2025-09-24 19:47:10.054524141+00:00,160,1,432669,T,A,64.83,1,26,8058566390725,0,23252,94437706,CLX5
2025-09-24 19:47:10.054524141+00:00,160,1,432669,F,B,64.83,1,26,8058566389389,0,23252,94437706,CLX5
2025-09-24 19:47:10.054524141+00:00,160,1,432669,C,B,64.83,1,26,8058566389389,128,18921,94437707,CLX5
2025-09-24 19:47:10.054987551+00:00,160,1,432669,A,A,64.84,1,26,8058566390729,128,21435,94437715,CLX5
2025-09-24 19:47:10.055136901+00:00,160,1,432669,C,A,64.84,1,26,8058566390729,128,19894,94437719,CLX5
2025-09-24 19:47:10.454687337+00:00,160,1,432669,T,A,64.83,1,26,8058566390734,0,19292,94437732,CLX5
2025-09-24 19:47:10.454687337+00:00,160,1,432669,F,B,64.83,1,26,8058566389401,0,19292,94437732,CLX5
2025-09-24 19:47:10.454687337+00:00,160,1,432669,C,B,64.83,1,26,8058566389401,128,21912,94437733,CLX5
2025-09-24 19:47:10.454950961+00:00,160,1,432669,C,B,64.83,1,26,8058566390709,128,20140,94437734,CLX5
2025-09-24 19:47:10.454960309+00:00,160,1,432669,A,A,64.84,1,26,8058566390736,128,18618,94437735,CLX5
2025-09-24 19:47:10.455127439+00:00,160,1,432669,C,B,64.83,1,26,8058566390176,128,22159,94437737,CLX5
2025-09-24 19:47:10.455130817+00:00,160,1,432669,A,A,64.84,1,26,8058566390738,128,17922,94437738,CLX5
2025-09-24 19:47:10.455138151+00:00,160,1,432669,C,A,64.84,1,26,8058566390736,128,21752,94437739,CLX5
2025-09-24 19:47:10.455215121+00:00,160,1,432669,A,B,64.83,1,26,8058566390739,128,19385,94437740,CLX5
2025-09-24 19:47:10.455340147+00:00,160,1,432669,A,B,64.83,1,26,8058566390740,128,22415,94437741,CLX5
2025-09-24 19:47:10.459450091+00:00,160,1,432669,A,B,64.83,1,26,8058566390742,128,24895,94437751,CLX5
2025-09-24 19:47:10.854821463+00:00,160,1,432669,T,A,64.83,1,26,8058566390748,0,22400,94437763,CLX5
2025-09-24 19:47:10.854821463+00:00,160,1,432669,F,B,64.83,1,26,8058566389930,0,22400,94437763,CLX5
2025-09-24 19:47:10.854821463+00:00,160,1,432669,C,B,64.83,1,26,8058566389930,128,18997,94437764,CLX5
2025-09-24 19:47:14.647113785+00:00,160,1,432669,A,A,64.84,1,26,8058566390795,128,18362,94437880,CLX5
2025-09-24 19:47:14.647113963+00:00,160,1,432669,A,A,64.84,2,26,8058566390796,128,14997,94437882,CLX5
2025-09-24 19:47:14.647117725+00:00,160,1,432669,C,B,64.83,1,26,8058566390740,128,17909,94437884,CLX5
2025-09-24 19:47:14.647126711+00:00,160,1,432669,C,B,64.8,2,26,8058566389668,128,13493,94437885,CLX5
2025-09-24 19:47:14.647129859+00:00,160,1,432669,C,B,64.82,1,26,8058566388753,128,17564,94437887,CLX5
2025-09-24 19:47:14.647173115+00:00,160,1,432669,A,A,64.84,2,26,8058566390797,128,13777,94437889,CLX5
2025-09-24 19:47:14.647413373+00:00,160,1,432669,A,B,64.83,1,26,8058566390798,128,14786,94437893,CLX5
2025-09-24 19:47:14.647472949+00:00,160,1,432669,C,A,64.84,2,26,8058566390797,128,14900,94437894,CLX5
2025-09-24 19:47:23.485698477+00:00,160,1,432669,C,B,64.4,1,26,8058563669445,128,18525,94438026,CLX5
2025-09-24 19:47:23.488235299+00:00,160,1,432669,A,B,64.7,2,26,8058566390853,128,18482,94438027,CLX5
2025-09-24 19:47:32.808348085+00:00,160,1,432669,C,B,64.83,1,26,8058566390798,128,14531,94438375,CLX5
2025-09-24 19:47:32.870220159+00:00,160,1,432669,A,B,64.83,1,26,8058566390992,128,14470,94438445,CLX5
2025-09-24 19:47:32.870251817+00:00,160,1,432669,A,A,64.84,2,26,8058566390993,128,19597,94438447,CLX5
2025-09-24 19:47:32.870403009+00:00,160,1,432669,A,B,64.83,1,26,8058566390994,128,16199,94438448,CLX5
2025-09-24 19:47:32.870486969+00:00,160,1,432669,A,A,64.87,1,26,8058566390996,128,14479,94438451,CLX5
2025-09-24 19:47:32.870522737+00:00,160,1,432669,C,A,64.84,2,26,8058566390993,128,17827,94438452,CLX5
2025-09-24 19:47:32.870890073+00:00,160,1,432669,C,B,64.82,2,26,8058566390075,128,14828,94438457,CLX5
2025-09-24 19:47:32.870897293+00:00,160,1,432669,C,B,64.83,2,26,8058566390160,128,16233,94438467,CLX5
2025-09-24 19:47:32.871471309+00:00,160,1,432669,C,B,64.83,1,26,8058566390739,128,19405,94438506,CLX5
2025-09-24 19:47:32.932564165+00:00,160,1,432669,A,B,64.82,2,26,8058566391029,128,17039,94438572,CLX5
2025-09-24 19:47:33.123581931+00:00,160,1,432669,C,A,64.84,2,26,8058566390663,128,14395,94438632,CLX5
2025-09-24 19:47:33.123582315+00:00,160,1,432669,C,A,64.84,1,26,8058566390795,128,15214,94438633,CLX5
2025-09-24 19:47:33.123582469+00:00,160,1,432669,C,A,64.84,2,26,8058566390796,128,18106,94438634,CLX5
2025-09-24 19:47:36.453683701+00:00,160,1,432669,C,B,64.83,1,26,8058566390992,128,15874,94438793,CLX5
2025-09-24 19:47:38.163174095+00:00,160,1,432669,A,A,64.84,2,26,8058566391125,128,14848,94438833,CLX5
2025-09-24 19:47:44.312711111+00:00,160,1,432669,A,A,64.84,1,26,8058566391208,128,20764,94439076,CLX5
2025-09-24 19:47:46.776135635+00:00,160,1,432669,A,B,64.83,1,26,8058566391210,128,20729,94439092,CLX5
2025-09-24 19:47:50.969467475+00:00,160,1,432669,A,A,64.84,1,26,8058566391235,128,15215,94439221,CLX5
2025-09-24 19:47:50.969467655+00:00,160,1,432669,A,A,64.84,2,26,8058566391236,128,18118,94439222,CLX5
2025-09-24 19:47:50.969471219+00:00,160,1,432669,C,B,64.83,1,26,8058566390994,128,15906,94439224,CLX5
2025-09-24 19:47:53.186317919+00:00,160,1,432669,A,B,64.83,1,26,8058566391247,128,18560,94439263,CLX5
2025-09-24 19:47:56.713277365+00:00,160,1,432669,A,B,64.78,1,26,8058566391359,128,18478,94439544,CLX5
2025-09-24 19:48:03.926006349+00:00,160,1,432669,C,A,65.03,1,26,8058566390542,128,19192,94440937,CLX5
2025-09-24 19:48:04.516185323+00:00,160,1,432669,A,A,64.84,1,26,8058566391927,128,19816,94440938,CLX5
2025-09-24 19:48:04.517163865+00:00,160,1,432669,C,B,64.83,1,26,8058566391247,128,19346,94440939,CLX5
2025-09-24 19:48:04.614944803+00:00,160,1,432669,C,A,65.0,1,26,8058566390598,128,17782,94440947,CLX5
2025-09-24 19:48:04.645918565+00:00,160,1,432669,C,A,65.0,1,26,8058566390599,128,20710,94440948,CLX5
2025-09-24 19:48:04.678022581+00:00,160,1,432669,A,A,64.99,1,26,8058566391930,128,20244,94440949,CLX5
2025-09-24 19:48:04.693337209+00:00,160,1,432669,A,A,64.99,1,26,8058566391931,128,22761,94440950,CLX5
2025-09-24 19:48:06.612569103+00:00,160,1,432669,C,A,64.84,2,26,8058566391236,128,15332,94441060,CLX5
2025-09-24 19:48:06.612625511+00:00,160,1,432669,C,A,64.84,1,26,8058566391235,128,14994,94441061,CLX5
2025-09-24 19:48:06.613143331+00:00,160,1,432669,C,A,64.84,2,26,8058566391125,128,17999,94441066,CLX5
2025-09-24 19:48:06.613226619+00:00,160,1,432669,A,B,64.83,3,26,8058566391964,128,18647,94441067,CLX5
2025-09-24 19:48:06.613376773+00:00,160,1,432669,A,B,64.83,1,26,8058566391965,128,19243,94441071,CLX5
2025-09-24 19:48:06.615897045+00:00,160,1,432669,A,B,64.83,1,26,8058566391977,128,15434,94441122,CLX5
2025-09-24 19:48:06.616733537+00:00,160,1,432669,A,B,64.83,1,26,8058566391984,128,18340,94441149,CLX5
2025-09-24 19:48:06.617793173+00:00,160,1,432669,A,B,64.83,1,26,8058566391998,128,17815,94441189,CLX5
2025-09-24 19:48:06.618037081+00:00,160,1,432669,C,A,64.84,1,26,8058566390738,128,16340,94441198,CLX5
2025-09-24 19:48:06.628111471+00:00,160,1,432669,C,B,64.83,1,26,8058566391984,128,18159,94441213,CLX5
2025-09-24 19:48:07.155536229+00:00,160,1,432669,A,B,64.83,2,26,8058566392077,128,14713,94441400,CLX5
2025-09-24 19:48:07.482929989+00:00,160,1,432669,C,B,64.83,2,26,8058566392077,128,14278,94441436,CLX5
2025-09-24 19:48:09.858824193+00:00,160,1,432669,C,B,64.81,1,26,8058566384370,128,27494,94441537,CLX5
2025-09-24 19:48:09.882575983+00:00,160,1,432669,C,B,64.83,1,26,8058566391210,128,19122,94441538,CLX5
2025-09-24 19:48:11.321251025+00:00,160,1,432669,T,B,64.84,2,26,8058566392124,0,17968,94441546,CLX5
2025-09-24 19:48:11.321251025+00:00,160,1,432669,F,A,64.84,2,26,8058566364306,0,17968,94441546,CLX5
2025-09-24 19:48:11.321251025+00:00,160,1,432669,C,A,64.84,2,26,8058566364306,128,15679,94441547,CLX5
2025-09-24 19:48:11.321603521+00:00,160,1,432669,A,B,64.83,1,26,8058566392125,128,18139,94441548,CLX5
2025-09-24 19:48:11.360987279+00:00,160,1,432669,C,B,64.83,1,26,8058566392125,128,18468,94441582,CLX5
2025-09-24 19:48:13.050638073+00:00,160,1,432669,A,B,64.83,1,26,8058566392216,128,15636,94441806,CLX5
2025-09-24 19:48:13.948691369+00:00,160,1,432669,C,B,63.38,1,26,8058556159095,128,22108,94441846,CLX5
2025-09-24 19:48:14.151860341+00:00,160,1,432669,A,B,63.38,1,26,8058566392237,128,17426,94441849,CLX5
2025-09-24 19:48:16.080411975+00:00,160,1,432669,C,B,64.83,1,26,8058566392216,128,14916,94441854,CLX5
2025-09-24 19:48:23.434407283+00:00,160,1,432669,A,B,64.83,1,26,8058566392308,128,17392,94442038,CLX5
2025-09-24 19:48:24.805968453+00:00,160,1,432669,C,B,64.83,1,26,8058566392308,128,19118,94442053,CLX5
2025-09-24 19:48:25.018696707+00:00,160,1,432669,A,B,64.83,2,26,8058566392317,128,15162,94442059,CLX5
2025-09-24 19:48:25.018869917+00:00,160,1,432669,C,A,64.87,1,26,8058566390996,128,18079,94442061,CLX5
2025-09-24 19:48:27.821890005+00:00,160,1,432669,A,A,64.84,1,26,8058566392334,128,23082,94442100,CLX5
2025-09-24 19:48:32.500151299+00:00,160,1,432669,A,B,64.83,1,26,8058566392409,128,18937,94442364,CLX5
2025-09-24 19:48:32.500151473+00:00,160,1,432669,C,A,64.84,1,26,8058566364389,128,15842,94442365,CLX5
2025-09-24 19:48:32.500173339+00:00,160,1,432669,C,A,64.87,2,26,8058566390073,128,14278,94442369,CLX5
2025-09-24 19:48:32.500175903+00:00,160,1,432669,C,A,64.84,2,26,8058566365428,128,19185,94442373,CLX5
2025-09-24 19:48:32.500179271+00:00,160,1,432669,C,A,64.84,3,26,8058566364370,128,15979,94442382,CLX5
2025-09-24 19:48:32.500302837+00:00,160,1,432669,T,B,64.84,1,26,8058566392419,0,14992,94442396,CLX5
2025-09-24 19:48:32.500302837+00:00,160,1,432669,F,A,64.84,1,26,8058566364362,0,14992,94442396,CLX5
2025-09-24 19:48:32.500302837+00:00,160,1,432669,C,A,64.84,1,26,8058566364362,128,14992,94442396,CLX5
2025-09-24 19:48:32.500314491+00:00,160,1,432669,M,A,64.97,1,26,8058565075241,128,14528,94442400,CLX5
2025-09-24 19:48:32.500352929+00:00,160,1,432669,C,A,64.84,3,26,8058566365423,128,19040,94442401,CLX5
2025-09-24 19:48:32.500510035+00:00,160,1,432669,A,B,64.83,2,26,8058566392421,128,13880,94442407,CLX5
2025-09-24 19:48:32.501021865+00:00,160,1,432669,A,B,64.83,1,26,8058566392428,128,18096,94442449,CLX5
2025-09-24 19:48:32.501036935+00:00,160,1,432669,A,B,64.83,2,26,8058566392429,128,14833,94442453,CLX5
2025-09-24 19:48:32.501092825+00:00,160,1,432669,C,B,64.79,2,26,8058566389669,128,18795,94442456,CLX5
2025-09-24 19:48:32.501126885+00:00,160,1,432669,C,B,64.83,2,26,8058566392421,128,14620,94442459,CLX5
2025-09-24 19:48:32.501403639+00:00,160,1,432669,A,B,64.8,1,26,8058566392433,128,14398,94442479,CLX5
2025-09-24 19:48:32.501406751+00:00,160,1,432669,T,B,64.84,1,26,8058566392434,0,14134,94442480,CLX5
2025-09-24 19:48:32.501406751+00:00,160,1,432669,F,A,64.84,1,26,8058566364368,0,14134,94442480,CLX5
2025-09-24 19:48:32.501406751+00:00,160,1,432669,C,A,64.84,1,26,8058566364368,128,16278,94442481,CLX5
2025-09-24 19:48:32.501519987+00:00,160,1,432669,M,B,64.83,1,26,8058566372953,128,14054,94442486,CLX5
2025-09-24 19:48:32.501670719+00:00,160,1,432669,T,B,64.84,2,26,8058566392441,0,17281,94442497,CLX5
2025-09-24 19:48:32.501670719+00:00,160,1,432669,F,A,64.84,2,26,8058566376166,0,17281,94442497,CLX5
2025-09-24 19:48:32.501670719+00:00,160,1,432669,M,A,64.84,2,26,8058566376166,128,17281,94442497,CLX5
2025-09-24 19:48:32.501674829+00:00,160,1,432669,C,B,64.83,1,26,8058566390742,128,15097,94442498,CLX5
2025-09-24 19:48:32.501868759+00:00,160,1,432669,M,B,64.83,1,26,8058566390723,128,18174,94442507,CLX5
2025-09-24 19:48:32.501994687+00:00,160,1,432669,C,B,64.83,1,26,8058566390518,128,14634,94442508,CLX5
2025-09-24 19:48:32.502066433+00:00,160,1,432669,C,B,64.82,8,26,8058566388382,128,14364,94442512,CLX5
2025-09-24 19:48:32.503510191+00:00,160,1,432669,M,B,64.83,3,26,8058566373348,128,15139,94442596,CLX5
2025-09-24 19:48:32.504572133+00:00,160,1,432669,A,B,64.83,1,26,8058566392476,128,14516,94442642,CLX5
2025-09-24 19:48:32.504820593+00:00,160,1,432669,A,A,64.84,2,26,8058566392479,128,17813,94442646,CLX5
2025-09-24 19:48:32.504820949+00:00,160,1,432669,C,B,64.83,2,26,8058566392429,128,14563,94442648,CLX5
2025-09-24 19:48:32.504821275+00:00,160,1,432669,A,A,64.84,2,26,8058566392482,128,14976,94442650,CLX5
2025-09-24 19:48:32.504821895+00:00,160,1,432669,A,A,64.84,1,26,8058566392483,128,15152,94442651,CLX5
2025-09-24 19:48:32.504825273+00:00,160,1,432669,A,A,64.84,2,26,8058566392484,128,18547,94442652,CLX5
2025-09-24 19:48:32.504826505+00:00,160,1,432669,A,A,64.84,1,26,8058566392486,128,15180,94442654,CLX5
2025-09-24 19:48:32.504860563+00:00,160,1,432669,A,A,64.84,3,26,8058566392489,128,16211,94442660,CLX5
2025-09-24 19:48:32.504972993+00:00,160,1,432669,C,B,64.83,1,26,8058566392409,128,14663,94442673,CLX5
2025-09-24 19:48:32.504993823+00:00,160,1,432669,M,A,64.96,1,26,8058565075241,128,14743,94442675,CLX5
2025-09-24 19:48:32.505092027+00:00,160,1,432669,C,B,64.83,1,26,8058566392428,128,15044,94442678,CLX5
2025-09-24 19:48:32.506855931+00:00,160,1,432669,C,B,64.83,1,26,8058566392476,128,18252,94442727,CLX5
2025-09-24 19:48:32.507311489+00:00,160,1,432669,M,B,63.68,4,26,8058566373348,128,15395,94442729,CLX5
2025-09-24 19:48:32.507513655+00:00,160,1,432669,C,B,64.83,1,26,8058566390723,128,19650,94442736,CLX5
2025-09-24 19:48:32.508747679+00:00,160,1,432669,C,B,64.83,2,26,8058566392317,128,15603,94442778,CLX5
2025-09-24 19:48:32.533182615+00:00,160,1,432669,A,A,64.87,2,26,8058566392541,128,16653,94442853,CLX5
2025-09-24 19:48:32.565367615+00:00,160,1,432669,C,B,64.8,1,26,8058566392433,128,17240,94442874,CLX5
2025-09-24 19:48:32.565962365+00:00,160,1,432669,A,B,64.83,3,26,8058566392556,128,18654,94442875,CLX5
2025-09-24 19:48:32.566112945+00:00,160,1,432669,C,A,64.84,1,26,8058566392486,128,15418,94442877,CLX5
2025-09-24 19:48:32.606775809+00:00,160,1,432669,A,A,64.84,1,26,8058566392568,128,18209,94442912,CLX5
2025-09-24 19:48:32.732853669+00:00,160,1,432669,A,B,64.81,2,26,8058566392591,128,18063,94442957,CLX5
2025-09-24 19:48:32.732856377+00:00,160,1,432669,A,B,64.8,2,26,8058566392592,128,14336,94442958,CLX5
2025-09-24 19:48:32.915101685+00:00,160,1,432669,A,B,64.83,2,26,8058566392603,128,14171,94442979,CLX5
2025-09-24 19:48:32.915107137+00:00,160,1,432669,A,B,64.83,2,26,8058566392605,128,14644,94442984,CLX5
2025-09-24 19:48:32.915107329+00:00,160,1,432669,C,A,64.87,2,26,8058566392541,128,18076,94442985,CLX5
2025-09-24 19:48:32.915107983+00:00,160,1,432669,C,A,64.84,3,26,8058566392489,128,15409,94442989,CLX5
2025-09-24 19:48:32.915149683+00:00,160,1,432669,C,A,64.84,1,26,8058566392568,128,17440,94442998,CLX5
2025-09-24 19:48:32.915161663+00:00,160,1,432669,C,A,64.84,2,26,8058566392479,128,15422,94442999,CLX5
2025-09-24 19:48:32.915244739+00:00,160,1,432669,M,A,64.97,1,26,8058565075241,128,14154,94443000,CLX5
2025-09-24 19:48:32.915355037+00:00,160,1,432669,C,B,64.81,2,26,8058566392591,128,18078,94443005,CLX5
2025-09-24 19:48:32.915539657+00:00,160,1,432669,C,A,64.84,1,26,8058566392483,128,18259,94443010,CLX5
2025-09-24 19:48:32.915813263+00:00,160,1,432669,C,A,64.84,2,26,8058566392484,128,18537,94443016,CLX5
2025-09-24 19:48:32.916383861+00:00,160,1,432669,T,B,64.84,8,26,8058566392616,0,17843,94443023,CLX5
2025-09-24 19:48:32.916383861+00:00,160,1,432669,F,A,64.84,1,26,8058566390497,0,17843,94443023,CLX5
2025-09-24 19:48:32.916383861+00:00,160,1,432669,F,A,64.84,1,26,8058566390649,0,17843,94443023,CLX5
2025-09-24 19:48:32.916383861+00:00,160,1,432669,F,A,64.84,1,26,8058566391208,0,17843,94443023,CLX5
2025-09-24 19:48:32.916383861+00:00,160,1,432669,F,A,64.84,1,26,8058566391927,0,17843,94443023,CLX5
2025-09-24 19:48:32.916383861+00:00,160,1,432669,F,A,64.84,1,26,8058566392334,0,17843,94443023,CLX5
2025-09-24 19:48:32.916383861+00:00,160,1,432669,F,A,64.84,1,26,8058566392482,0,17843,94443023,CLX5
2025-09-24 19:48:32.916383861+00:00,160,1,432669,F,A,64.84,2,26,8058566376166,0,17843,94443023,CLX5
2025-09-24 19:48:32.916383861+00:00,160,1,432669,C,A,64.84,1,26,8058566390497,0,14445,94443024,CLX5
2025-09-24 19:48:32.916383861+00:00,160,1,432669,C,A,64.84,1,26,8058566390649,0,14445,94443024,CLX5
2025-09-24 19:48:32.916383861+00:00,160,1,432669,C,A,64.84,1,26,8058566391208,0,14445,94443024,CLX5
2025-09-24 19:48:32.916383861+00:00,160,1,432669,C,A,64.84,1,26,8058566391927,0,14445,94443024,CLX5
2025-09-24 19:48:32.916383861+00:00,160,1,432669,C,A,64.84,1,26,8058566392334,0,14445,94443024,CLX5
2025-09-24 19:48:32.916383861+00:00,160,1,432669,M,A,64.84,1,26,8058566392482,0,14445,94443024,CLX5
2025-09-24 19:48:32.916383861+00:00,160,1,432669,M,A,64.84,2,26,8058566376166,128,14445,94443024,CLX5
2025-09-24 19:48:32.916385553+00:00,160,1,432669,C,B,64.83,3,26,8058566392556,128,14183,94443026,CLX5
2025-09-24 19:48:32.916387125+00:00,160,1,432669,C,B,64.83,1,26,8058566390715,128,14183,94443026,CLX5
2025-09-24 19:48:32.916810101+00:00,160,1,432669,A,B,64.83,1,26,8058566392618,128,14712,94443029,CLX5
2025-09-24 19:48:32.916824273+00:00,160,1,432669,T,N,64.84,1,26,0,0,17493,94443044,CLX5
2025-09-24 19:48:32.916824273+00:00,160,1,432669,F,N,64.84,1,26,8058566392482,0,17493,94443044,CLX5
2025-09-24 19:48:32.916824273+00:00,160,1,432669,C,A,64.84,1,26,8058566392482,128,14280,94443045,CLX5
2025-09-24 19:48:32.916847579+00:00,160,1,432669,A,A,64.84,1,26,8058566392628,128,14107,94443060,CLX5
2025-09-24 19:48:32.916852973+00:00,160,1,432669,A,A,64.84,2,26,8058566392629,128,17900,94443062,CLX5
2025-09-24 19:48:32.916889395+00:00,160,1,432669,A,A,64.84,3,26,8058566392630,128,16129,94443065,CLX5
2025-09-24 19:48:32.917390569+00:00,160,1,432669,A,B,64.83,2,26,8058566392633,128,15351,94443072,CLX5
2025-09-24 19:48:32.917394563+00:00,160,1,432669,C,B,64.8,2,26,8058566392592,128,17832,94443074,CLX5
2025-09-24 19:48:32.917547293+00:00,160,1,432669,A,B,64.83,1,26,8058566392643,128,14774,94443095,CLX5
2025-09-24 19:48:32.917715075+00:00,160,1,432669,C,A,64.84,2,26,8058566392629,128,19585,94443112,CLX5
2025-09-24 19:48:32.917729397+00:00,160,1,432669,A,A,64.84,2,26,8058566392656,128,14759,94443113,CLX5
2025-09-24 19:48:32.917746177+00:00,160,1,432669,A,A,64.84,1,26,8058566392657,128,16136,94443115,CLX5
2025-09-24 19:48:32.917757389+00:00,160,1,432669,A,A,64.84,3,26,8058566392659,128,14431,94443118,CLX5
2025-09-24 19:48:32.918504179+00:00,160,1,432669,C,B,64.83,2,26,8058566392633,128,14165,94443142,CLX5
2025-09-24 19:48:32.918581877+00:00,160,1,432669,C,B,64.83,4,26,8058566390417,128,13996,94443145,CLX5
2025-09-24 19:48:32.918687895+00:00,160,1,432669,C,A,64.84,3,26,8058566392659,128,19681,94443149,CLX5
2025-09-24 19:48:32.937904653+00:00,160,1,432669,C,B,64.83,1,26,8058566392643,128,14474,94443241,CLX5
2025-09-24 19:48:32.938046899+00:00,160,1,432669,M,A,64.96,1,26,8058565075241,128,13230,94443245,CLX5
2025-09-24 19:48:32.984867623+00:00,160,1,432669,A,A,64.87,2,26,8058566392695,128,17332,94443274,CLX5
2025-09-24 19:48:32.988057985+00:00,160,1,432669,C,A,64.87,2,26,8058566392695,128,18208,94443277,CLX5
2025-09-24 19:48:32.988187139+00:00,160,1,432669,M,A,64.97,1,26,8058565075241,128,14283,94443285,CLX5
2025-09-24 19:48:33.033176147+00:00,160,1,432669,A,A,64.89,2,26,8058566392707,128,20832,94443308,CLX5
2025-09-24 19:48:33.033179469+00:00,160,1,432669,A,B,64.81,2,26,8058566392708,128,17178,94443309,CLX5
2025-09-24 19:48:33.033180755+00:00,160,1,432669,A,B,64.8,2,26,8058566392709,128,14056,94443310,CLX5
2025-09-24 19:48:33.196363761+00:00,160,1,432669,T,B,64.84,8,26,8058566393395,0,18157,94444878,CLX5
2025-09-24 19:48:33.196363761+00:00,160,1,432669,F,A,64.84,1,26,8058566392628,0,18157,94444878,CLX5
2025-09-24 19:48:33.196363761+00:00,160,1,432669,F,A,64.84,3,26,8058566392630,0,18157,94444878,CLX5
2025-09-24 19:48:33.196363761+00:00,160,1,432669,F,A,64.84,2,26,8058566392656,0,18157,94444878,CLX5
2025-09-24 19:48:33.196363761+00:00,160,1,432669,F,A,64.84,2,26,8058566376166,0,18157,94444878,CLX5
2025-09-24 19:48:33.196363761+00:00,160,1,432669,C,A,64.84,1,26,8058566392628,0,14575,94444879,CLX5
2025-09-24 19:48:33.196363761+00:00,160,1,432669,C,A,64.84,3,26,8058566392630,0,14575,94444879,CLX5
2025-09-24 19:48:33.196363761+00:00,160,1,432669,C,A,64.84,2,26,8058566392656,0,14575,94444879,CLX5
2025-09-24 19:48:33.196363761+00:00,160,1,432669,M,A,64.84,2,26,8058566376166,128,14575,94444879,CLX5
2025-09-24 19:48:33.196707199+00:00,160,1,432669,A,B,64.83,1,26,8058566393402,128,18549,94444885,CLX5
2025-09-24 19:48:33.196723203+00:00,160,1,432669,C,A,64.84,1,26,8058566392657,128,13315,94444895,CLX5
2025-09-24 19:48:33.196723353+00:00,160,1,432669,A,B,64.83,2,26,8058566393406,128,18934,94444898,CLX5
2025-09-24 19:48:33.196738493+00:00,160,1,432669,A,B,64.83,2,26,8058566393408,128,18302,94444903,CLX5
2025-09-24 19:48:33.196762511+00:00,160,1,432669,A,A,64.84,1,26,8058566393410,128,17353,94444908,CLX5
2025-09-24 19:48:33.196786163+00:00,160,1,432669,A,A,64.84,2,26,8058566393411,128,21987,94444914,CLX5
2025-09-24 19:48:33.196906389+00:00,160,1,432669,A,A,64.84,3,26,8058566393415,128,19675,94444922,CLX5
2025-09-24 19:48:33.196990039+00:00,160,1,432669,A,A,64.84,2,26,8058566393416,128,14698,94444923,CLX5
2025-09-24 19:48:33.196999505+00:00,160,1,432669,A,A,64.84,1,26,8058566393417,128,15408,94444924,CLX5
2025-09-24 19:48:33.197054797+00:00,160,1,432669,M,B,64.83,2,26,8058566373348,128,14419,94444927,CLX5
2025-09-24 19:48:33.197719837+00:00,160,1,432669,C,B,64.83,2,26,8058566393406,128,16976,94444946,CLX5
2025-09-24 19:48:33.198519387+00:00,160,1,432669,C,B,64.83,1,26,8058566393402,128,14782,94444978,CLX5
2025-09-24 19:48:38.160073347+00:00,160,1,432669,C,B,64.81,2,26,8058566392708,128,15454,94445658,CLX5
2025-09-24 19:48:38.202660235+00:00,160,1,432669,M,B,63.68,4,26,8058566373348,128,19491,94445664,CLX5
2025-09-24 19:48:38.332833425+00:00,160,1,432669,A,B,64.79,2,26,8058566393791,128,18581,94445667,CLX5
2025-09-24 19:48:40.000994341+00:00,160,1,432669,A,A,64.87,2,26,8058566393806,128,14464,94445706,CLX5
2025-09-24 19:48:40.001000311+00:00,160,1,432669,A,A,64.84,2,26,8058566393807,128,18541,94445708,CLX5
2025-09-24 19:48:40.001031971+00:00,160,1,432669,A,A,64.84,1,26,8058566393811,128,15427,94445712,CLX5
2025-09-24 19:48:40.001068085+00:00,160,1,432669,A,A,64.84,1,26,8058566393812,128,15415,94445713,CLX5
2025-09-24 19:48:40.001136375+00:00,160,1,432669,M,A,64.96,1,26,8058565075241,128,14339,94445714,CLX5
2025-09-24 19:48:40.001246175+00:00,160,1,432669,A,A,64.84,1,26,8058566393814,128,15632,94445716,CLX5
2025-09-24 19:48:40.003581585+00:00,160,1,432669,C,B,64.83,2,26,8058566393408,128,18589,94445856,CLX5
2025-09-24 19:48:40.004074885+00:00,160,1,432669,C,B,64.83,1,26,8058566392618,128,19622,94445883,CLX5
2025-09-24 19:48:40.004175257+00:00,160,1,432669,C,B,64.83,2,26,8058566392605,128,13844,94445895,CLX5
2025-09-24 19:48:40.006427259+00:00,160,1,432669,A,A,64.84,1,26,8058566393881,128,15113,94446035,CLX5
2025-09-24 19:48:40.007325991+00:00,160,1,432669,A,A,64.84,1,26,8058566393893,128,14841,94446075,CLX5
2025-09-24 19:48:40.007565115+00:00,160,1,432669,C,A,64.84,1,26,8058566393893,128,14919,94446082,CLX5
2025-09-24 19:48:40.007664433+00:00,160,1,432669,C,B,64.83,1,26,8058566391998,128,19486,94446084,CLX5
2025-09-24 19:48:40.007667465+00:00,160,1,432669,A,A,64.84,1,26,8058566393895,128,15421,94446085,CLX5
2025-09-24 19:48:40.007988535+00:00,160,1,432669,C,B,64.8,2,26,8058566392709,128,14406,94446105,CLX5
2025-09-24 19:48:40.033210539+00:00,160,1,432669,C,A,64.89,2,26,8058566392707,128,18037,94446369,CLX5
2025-09-24 19:48:40.071828865+00:00,160,1,432669,C,B,64.83,2,26,8058566392603,128,19178,94446413,CLX5
2025-09-24 19:48:43.814887495+00:00,160,1,432669,C,B,64.83,3,26,8058566391964,128,21446,94446896,CLX5
2025-09-24 19:48:43.815133839+00:00,160,1,432669,T,A,64.83,1,26,8058566394204,0,17739,94446912,CLX5
2025-09-24 19:48:43.815133839+00:00,160,1,432669,F,B,64.83,1,26,8058566389931,0,17739,94446912,CLX5
2025-09-24 19:48:43.815133839+00:00,160,1,432669,C,B,64.83,1,26,8058566389931,128,14264,94446913,CLX5
2025-09-24 19:48:43.815591277+00:00,160,1,432669,A,A,64.84,3,26,8058566394219,128,14891,94446950,CLX5
2025-09-24 19:48:43.848839987+00:00,160,1,432669,T,A,64.83,1,26,8058566394265,0,19215,94447103,CLX5
2025-09-24 19:48:43.848839987+00:00,160,1,432669,F,B,64.83,1,26,8058566390527,0,19215,94447103,CLX5
2025-09-24 19:48:43.848839987+00:00,160,1,432669,C,B,64.83,1,26,8058566390527,128,14268,94447104,CLX5
2025-09-24 19:48:43.849140127+00:00,160,1,432669,T,A,64.83,2,26,8058566394268,0,18823,94447111,CLX5
2025-09-24 19:48:43.849140127+00:00,160,1,432669,F,B,64.83,1,26,8058566391965,0,18823,94447111,CLX5
2025-09-24 19:48:43.849140127+00:00,160,1,432669,F,B,64.83,1,26,8058566391977,0,18823,94447111,CLX5
2025-09-24 19:48:43.849140127+00:00,160,1,432669,C,B,64.83,1,26,8058566391965,0,15098,94447112,CLX5
2025-09-24 19:48:43.849140127+00:00,160,1,432669,C,B,64.83,1,26,8058566391977,128,15098,94447112,CLX5
2025-09-24 19:48:43.849471237+00:00,160,1,432669,T,A,64.83,1,26,8058566394270,0,17411,94447118,CLX5
2025-09-24 19:48:43.849471237+00:00,160,1,432669,F,B,64.83,1,26,8058566372953,0,17411,94447118,CLX5
2025-09-24 19:48:43.849471237+00:00,160,1,432669,C,B,64.83,1,26,8058566372953,128,14292,94447119,CLX5
2025-09-24 19:48:43.849752427+00:00,160,1,432669,A,B,64.82,1,26,8058566394276,128,14369,94447138,CLX5
2025-09-24 19:48:43.849781897+00:00,160,1,432669,A,B,64.82,3,26,8058566394279,128,17999,94447141,CLX5
2025-09-24 19:48:43.849807587+00:00,160,1,432669,A,B,64.82,1,26,8058566394281,128,15826,94447145,CLX5
2025-09-24 19:48:43.849970127+00:00,160,1,432669,C,B,64.82,1,26,8058566394276,128,15168,94447151,CLX5
2025-09-24 19:48:43.850398881+00:00,160,1,432669,C,B,64.8,1,26,8058566388894,128,14481,94447158,CLX5
2025-09-24 19:48:43.932885429+00:00,160,1,432669,A,B,64.78,2,26,8058566394308,128,18033,94447231,CLX5
2025-09-24 19:48:44.066528101+00:00,160,1,432669,A,B,64.83,2,26,8058566394339,128,17632,94447297,CLX5
2025-09-24 19:48:44.066795335+00:00,160,1,432669,A,B,64.83,2,26,8058566394342,128,17953,94447303,CLX5
2025-09-24 19:48:44.066801901+00:00,160,1,432669,A,B,64.83,1,26,8058566394344,128,16992,94447306,CLX5
2025-09-24 19:48:44.066851897+00:00,160,1,432669,A,B,64.83,1,26,8058566394345,128,20245,94447310,CLX5
2025-09-24 19:48:44.067323349+00:00,160,1,432669,A,B,64.8,1,26,8058566394351,128,14942,94447318,CLX5
2025-09-24 19:48:45.100011177+00:00,160,1,432669,C,B,64.83,1,26,8058566394345,128,24044,94447744,CLX5
2025-09-24 19:48:45.100211945+00:00,160,1,432669,C,B,64.83,2,26,8058566394339,128,13370,94447746,CLX5
2025-09-24 19:48:45.100362637+00:00,160,1,432669,C,B,64.83,2,26,8058566394342,128,14399,94447751,CLX5
2025-09-24 19:48:45.147700395+00:00,160,1,432669,T,A,64.83,1,26,8058566394531,0,17854,94447774,CLX5
2025-09-24 19:48:45.147700395+00:00,160,1,432669,F,B,64.83,1,26,8058566394344,0,17854,94447774,CLX5
2025-09-24 19:48:45.147700395+00:00,160,1,432669,C,B,64.83,1,26,8058566394344,128,14136,94447775,CLX5
2025-09-24 19:48:45.148010807+00:00,160,1,432669,A,A,64.87,1,26,8058566394536,128,13418,94447782,CLX5
2025-09-24 19:48:45.148519757+00:00,160,1,432669,C,B,64.8,1,26,8058566394351,128,18514,94447788,CLX5
2025-09-24 19:48:45.983244563+00:00,160,1,432669,A,A,64.84,1,26,8058566394596,128,18154,94447894,CLX5
2025-09-24 19:48:46.638483863+00:00,160,1,432669,T,B,64.84,1,26,8058566394600,0,17436,94447908,CLX5
2025-09-24 19:48:46.638483863+00:00,160,1,432669,F,A,64.84,1,26,8058566376166,0,17436,94447908,CLX5
2025-09-24 19:48:46.638483863+00:00,160,1,432669,M,A,64.84,1,26,8058566376166,128,14903,94447909,CLX5
2025-09-24 19:48:46.638787691+00:00,160,1,432669,A,B,64.83,2,26,8058566394601,128,14128,94447911,CLX5
2025-09-24 19:48:46.639660869+00:00,160,1,432669,A,B,64.8,1,26,8058566394608,128,14523,94447935,CLX5
2025-09-24 19:48:50.205399827+00:00,160,1,432669,T,A,64.83,1,26,8058566394622,0,18735,94447978,CLX5
2025-09-24 19:48:50.205399827+00:00,160,1,432669,F,B,64.83,1,26,8058566394601,0,18735,94447978,CLX5
2025-09-24 19:48:50.205399827+00:00,160,1,432669,M,B,64.83,1,26,8058566394601,128,14660,94447979,CLX5
2025-09-24 19:48:50.205659495+00:00,160,1,432669,A,A,64.84,1,26,8058566394625,128,13791,94447983,CLX5
2025-09-24 19:48:50.206207265+00:00,160,1,432669,C,B,64.8,1,26,8058566394608,128,14153,94447985,CLX5
2025-09-24 19:48:50.260833847+00:00,160,1,432669,A,B,64.8,1,26,8058566394629,128,18744,94447996,CLX5
2025-09-24 19:48:50.261098733+00:00,160,1,432669,A,B,64.83,2,26,8058566394631,128,14454,94447999,CLX5
2025-09-24 19:48:50.262141309+00:00,160,1,432669,C,A,64.84,1,26,8058566394625,128,18107,94448004,CLX5
2025-09-24 19:48:50.407653339+00:00,160,1,432669,A,A,64.84,1,26,8058566394634,128,19375,94448014,CLX5
2025-09-24 19:48:50.613140907+00:00,160,1,432669,C,B,64.83,2,26,8058566394631,128,18409,94448015,CLX5
2025-09-24 19:48:51.243577125+00:00,160,1,432669,A,A,64.84,1,26,8058566394688,128,18619,94448159,CLX5
2025-09-24 19:48:55.018554157+00:00,160,1,432669,A,B,64.83,1,26,8058566394758,128,18993,94448314,CLX5
2025-09-24 19:48:55.254584259+00:00,160,1,432669,T,A,64.83,1,26,8058566394767,0,17682,94448331,CLX5
2025-09-24 19:48:55.254584259+00:00,160,1,432669,F,B,64.83,1,26,8058566394601,0,17682,94448331,CLX5
2025-09-24 19:48:55.254584259+00:00,160,1,432669,C,B,64.83,1,26,8058566394601,128,14232,94448332,CLX5
2025-09-24 19:48:57.605596651+00:00,160,1,432669,T,A,64.83,1,26,8058566395357,0,17604,94449818,CLX5
2025-09-24 19:48:57.605596651+00:00,160,1,432669,F,B,64.83,1,26,8058566394758,0,17604,94449818,CLX5
2025-09-24 19:48:57.605596651+00:00,160,1,432669,C,B,64.83,1,26,8058566394758,128,14263,94449819,CLX5
2025-09-24 19:48:57.606487281+00:00,160,1,432669,C,B,64.8,1,26,8058566394629,128,14498,94449857,CLX5
2025-09-24 19:48:57.607272009+00:00,160,1,432669,C,A,64.84,1,26,8058566394634,128,14696,94449894,CLX5
2025-09-24 19:49:03.187146927+00:00,160,1,432669,A,A,65.24,1,26,8058566395578,128,17645,94450415,CLX5
2025-09-24 19:49:03.704343161+00:00,160,1,432669,C,A,65.04,1,26,8058566387169,128,18235,94450433,CLX5
2025-09-24 19:49:03.799346231+00:00,160,1,432669,A,A,65.0,1,26,8058566395591,128,18146,94450435,CLX5
2025-09-24 19:49:04.770250249+00:00,160,1,432669,C,A,64.99,1,26,8058566391931,128,17987,94450468,CLX5
2025-09-24 19:49:04.864594517+00:00,160,1,432669,A,A,64.98,1,26,8058566395612,128,17895,94450470,CLX5
2025-09-24 19:49:04.958959733+00:00,160,1,432669,C,A,64.99,1,26,8058566391930,128,18093,94450472,CLX5
2025-09-24 19:49:04.974465411+00:00,160,1,432669,A,A,64.98,1,26,8058566395613,128,19466,94450473,CLX5
2025-09-24 19:49:15.050259301+00:00,160,1,432669,A,B,64.82,1,26,8058566395715,128,17707,94450790,CLX5
2025-09-24 19:49:15.060164739+00:00,160,1,432669,T,A,64.82,1,26,8058566395716,0,17837,94450791,CLX5
2025-09-24 19:49:15.060164739+00:00,160,1,432669,F,B,64.82,1,26,8058566388360,0,17837,94450791,CLX5
2025-09-24 19:49:15.060164739+00:00,160,1,432669,C,B,64.82,1,26,8058566388360,128,14763,94450792,CLX5
2025-09-24 19:49:17.364996867+00:00,160,1,432669,A,B,64.82,1,26,8058566395846,128,13961,94451272,CLX5
2025-09-24 19:49:17.865764123+00:00,160,1,432669,C,B,64.82,1,26,8058566395846,128,14593,94451396,CLX5
2025-09-24 19:49:19.094993043+00:00,160,1,432669,A,B,64.83,2,26,8058566395908,128,17333,94451487,CLX5
2025-09-24 19:49:19.095183767+00:00,160,1,432669,A,B,64.83,2,26,8058566395910,128,17582,94451491,CLX5
2025-09-24 19:49:19.095303895+00:00,160,1,432669,M,B,64.83,1,26,8058566395715,128,18422,94451496,CLX5
2025-09-24 19:49:19.095335747+00:00,160,1,432669,A,B,64.83,1,26,8058566395913,128,16581,94451498,CLX5
2025-09-24 19:49:19.095555519+00:00,160,1,432669,A,B,64.83,1,26,8058566395916,128,16027,94451505,CLX5
2025-09-24 19:49:19.095807625+00:00,160,1,432669,A,B,64.8,1,26,8058566395918,128,17453,94451512,CLX5
2025-09-24 19:49:19.102103679+00:00,160,1,432669,T,A,64.83,7,26,8058566395926,0,18797,94451535,CLX5
2025-09-24 19:49:19.102103679+00:00,160,1,432669,F,B,64.83,2,26,8058566395908,0,18797,94451535,CLX5
2025-09-24 19:49:19.102103679+00:00,160,1,432669,F,B,64.83,2,26,8058566395910,0,18797,94451535,CLX5
2025-09-24 19:49:19.102103679+00:00,160,1,432669,F,B,64.83,1,26,8058566395715,0,18797,94451535,CLX5
2025-09-24 19:49:19.102103679+00:00,160,1,432669,F,B,64.83,1,26,8058566395913,0,18797,94451535,CLX5
2025-09-24 19:49:19.102103679+00:00,160,1,432669,F,B,64.83,1,26,8058566395916,0,18797,94451535,CLX5
2025-09-24 19:49:19.102103679+00:00,160,1,432669,C,B,64.83,2,26,8058566395908,0,14420,94451536,CLX5
2025-09-24 19:49:19.102103679+00:00,160,1,432669,C,B,64.83,2,26,8058566395910,0,14420,94451536,CLX5
2025-09-24 19:49:19.102103679+00:00,160,1,432669,C,B,64.83,1,26,8058566395715,0,14420,94451536,CLX5
2025-09-24 19:49:19.102103679+00:00,160,1,432669,C,B,64.83,1,26,8058566395913,0,14420,94451536,CLX5
2025-09-24 19:49:19.102103679+00:00,160,1,432669,C,B,64.83,1,26,8058566395916,128,14420,94451536,CLX5
2025-09-24 19:49:19.102505115+00:00,160,1,432669,A,A,64.84,1,26,8058566395932,128,18251,94451554,CLX5
2025-09-24 19:49:19.103079917+00:00,160,1,432669,A,A,64.83,1,26,8058566395937,128,14375,94451564,CLX5
2025-09-24 19:49:19.103284905+00:00,160,1,432669,A,A,64.84,2,26,8058566395938,128,14454,94451568,CLX5
2025-09-24 19:49:19.103375853+00:00,160,1,432669,C,A,64.84,1,26,8058566395932,128,17945,94451573,CLX5
2025-09-24 19:49:19.103395359+00:00,160,1,432669,A,A,64.83,1,26,8058566395941,128,17283,94451579,CLX5
2025-09-24 19:49:19.103596337+00:00,160,1,432669,M,A,64.85,3,26,8058566373687,128,17695,94451587,CLX5
2025-09-24 19:49:19.103682713+00:00,160,1,432669,C,A,64.84,1,26,8058566394596,128,14760,94451591,CLX5
2025-09-24 19:49:19.117272143+00:00,160,1,432669,C,A,64.84,1,26,8058566394688,128,18492,94451615,CLX5
2025-09-24 19:49:19.117895175+00:00,160,1,432669,A,A,64.83,1,26,8058566395950,128,17424,94451616,CLX5
2025-09-24 19:49:19.118957789+00:00,160,1,432669,A,A,64.83,2,26,8058566395953,128,17575,94451622,CLX5
2025-09-24 19:49:19.118985513+00:00,160,1,432669,A,A,64.83,2,26,8058566395955,128,16369,94451629,CLX5
2025-09-24 19:49:19.119098883+00:00,160,1,432669,A,A,64.83,1,26,8058566395956,128,16397,94451630,CLX5
2025-09-24 19:49:19.119099061+00:00,160,1,432669,A,A,64.83,2,26,8058566395957,128,17620,94451631,CLX5
2025-09-24 19:49:19.153528723+00:00,160,1,432669,C,A,64.84,2,26,8058566395938,128,18139,94451683,CLX5
2025-09-24 19:49:19.153921021+00:00,160,1,432669,A,A,64.83,1,26,8058566395971,128,18905,94451684,CLX5
2025-09-24 19:49:19.277016885+00:00,160,1,432669,C,B,64.8,1,26,8058566395918,128,17775,94451727,CLX5
2025-09-24 19:49:19.333108477+00:00,160,1,432669,C,A,64.83,2,26,8058566395955,128,19032,94451731,CLX5
2025-09-24 19:49:19.575788799+00:00,160,1,432669,A,A,64.83,2,26,8058566396003,128,20659,94451755,CLX5
2025-09-24 19:49:19.968595819+00:00,160,1,432669,T,N,64.83,2,26,0,0,17701,94451771,CLX5
2025-09-24 19:49:19.968595819+00:00,160,1,432669,F,N,64.83,1,26,8058566395937,0,17701,94451771,CLX5
2025-09-24 19:49:19.968595819+00:00,160,1,432669,F,N,64.83,1,26,8058566395941,0,17701,94451771,CLX5
2025-09-24 19:49:19.968595819+00:00,160,1,432669,C,A,64.83,1,26,8058566395937,0,15920,94451772,CLX5
2025-09-24 19:49:19.968595819+00:00,160,1,432669,C,A,64.83,1,26,8058566395941,128,15920,94451772,CLX5
2025-09-24 19:49:19.969118303+00:00,160,1,432669,C,A,64.83,2,26,8058566395957,128,15959,94451773,CLX5
2025-09-24 19:49:19.969192125+00:00,160,1,432669,C,A,64.83,1,26,8058566395956,128,19308,94451783,CLX5
2025-09-24 19:49:19.969479939+00:00,160,1,432669,T,B,64.83,1,26,8058566396010,0,17799,94451795,CLX5
2025-09-24 19:49:19.969479939+00:00,160,1,432669,F,A,64.83,1,26,8058566395950,0,17799,94451795,CLX5
2025-09-24 19:49:19.969479939+00:00,160,1,432669,C,A,64.83,1,26,8058566395950,128,19555,94451796,CLX5
2025-09-24 19:49:19.969636355+00:00,160,1,432669,T,N,64.83,2,26,0,0,17933,94451800,CLX5
2025-09-24 19:49:19.969636355+00:00,160,1,432669,F,N,64.83,2,26,8058566395953,0,17933,94451800,CLX5
2025-09-24 19:49:19.969636355+00:00,160,1,432669,C,A,64.83,2,26,8058566395953,128,14867,94451801,CLX5
2025-09-24 19:49:19.970772925+00:00,160,1,432669,A,B,64.82,1,26,8058566396023,128,17927,94451859,CLX5
2025-09-24 19:49:19.976214503+00:00,160,1,432669,A,A,64.83,1,26,8058566396029,128,18111,94451887,CLX5
2025-09-24 19:49:20.015081477+00:00,160,1,432669,T,B,64.83,2,26,8058566396035,0,17729,94451907,CLX5
2025-09-24 19:49:20.015081477+00:00,160,1,432669,F,A,64.83,1,26,8058566395971,0,17729,94451907,CLX5
2025-09-24 19:49:20.015081477+00:00,160,1,432669,F,A,64.83,1,26,8058566396003,0,17729,94451907,CLX5
2025-09-24 19:49:20.015081477+00:00,160,1,432669,C,A,64.83,1,26,8058566395971,0,14524,94451908,CLX5
2025-09-24 19:49:20.015081477+00:00,160,1,432669,M,A,64.83,1,26,8058566396003,128,14524,94451908,CLX5
2025-09-24 19:49:20.032192185+00:00,160,1,432669,A,A,64.83,1,26,8058566396050,128,14170,94451957,CLX5
2025-09-24 19:49:20.032192363+00:00,160,1,432669,A,A,64.83,2,26,8058566396051,128,17388,94451960,CLX5
2025-09-24 19:49:20.033088171+00:00,160,1,432669,C,B,64.82,1,26,8058566396023,128,19425,94451968,CLX5
2025-09-24 19:49:20.587203323+00:00,160,1,432669,A,B,64.18,1,26,8058566396076,128,18845,94452037,CLX5
2025-09-24 19:49:20.587206379+00:00,160,1,432669,A,B,63.92,1,26,8058566396077,128,14493,94452038,CLX5
2025-09-24 19:49:21.774529527+00:00,160,1,432669,A,A,64.83,1,26,8058566396085,128,15085,94452067,CLX5
2025-09-24 19:49:21.774536553+00:00,160,1,432669,A,A,64.83,2,26,8058566396087,128,19812,94452070,CLX5
2025-09-24 19:49:21.774538069+00:00,160,1,432669,A,A,64.83,1,26,8058566396088,128,16610,94452071,CLX5
2025-09-24 19:49:21.774578273+00:00,160,1,432669,A,A,64.83,2,26,8058566396090,128,15761,94452074,CLX5
2025-09-24 19:49:21.774854781+00:00,160,1,432669,A,A,64.83,1,26,8058566396095,128,15419,94452087,CLX5
2025-09-24 19:49:21.774891661+00:00,160,1,432669,C,A,64.83,2,26,8058566396090,128,15936,94452096,CLX5
2025-09-24 19:49:21.775432713+00:00,160,1,432669,C,A,64.83,1,26,8058566396095,128,15516,94452141,CLX5
2025-09-24 19:49:21.778142655+00:00,160,1,432669,A,A,64.83,2,26,8058566396149,128,16740,94452254,CLX5
2025-09-24 19:49:21.778229855+00:00,160,1,432669,A,A,64.83,1,26,8058566396150,128,18508,94452258,CLX5
2025-09-24 19:49:21.778762787+00:00,160,1,432669,C,A,64.83,2,26,8058566396149,128,18967,94452262,CLX5
2025-09-24 19:49:21.779510575+00:00,160,1,432669,C,B,64.79,2,26,8058566393791,128,18287,94452264,CLX5
2025-09-24 19:49:21.807103577+00:00,160,1,432669,M,A,64.95,1,26,8058565075241,128,13954,94452302,CLX5
2025-09-24 19:49:21.808739823+00:00,160,1,432669,M,B,64.8,1,26,8058566387539,128,18049,94452305,CLX5
2025-09-24 19:49:21.851110185+00:00,160,1,432669,A,A,64.83,1,26,8058566396172,128,19530,94452314,CLX5
2025-09-24 19:49:21.851114907+00:00,160,1,432669,C,B,64.82,2,26,8058566391029,128,16287,94452317,CLX5
2025-09-24 19:49:21.851115057+00:00,160,1,432669,A,A,64.83,1,26,8058566396174,128,15480,94452319,CLX5
2025-09-24 19:49:21.851119343+00:00,160,1,432669,C,B,64.78,2,26,8058566394308,128,17824,94452326,CLX5
2025-09-24 19:49:21.851270325+00:00,160,1,432669,C,B,64.82,2,26,8058566388855,128,14894,94452330,CLX5
2025-09-24 19:49:21.851751803+00:00,160,1,432669,C,B,64.82,1,26,8058566388833,128,14581,94452369,CLX5
2025-09-24 19:49:21.858509135+00:00,160,1,432669,A,B,64.8,1,26,8058566396223,128,14350,94452520,CLX5
2025-09-24 19:49:21.877904927+00:00,160,1,432669,A,A,64.83,1,26,8058566396232,128,16293,94452565,CLX5
2025-09-24 19:49:21.896765329+00:00,160,1,432669,A,B,63.7,1,26,8058566396248,128,18034,94452608,CLX5
2025-09-24 19:49:21.933066259+00:00,160,1,432669,A,B,64.8,2,26,8058566396255,128,16016,94452624,CLX5
2025-09-24 19:49:22.033388993+00:00,160,1,432669,A,B,64.8,2,26,8058566396295,128,18107,94452703,CLX5
2025-09-24 19:49:22.033391431+00:00,160,1,432669,A,B,64.79,2,26,8058566396296,128,14230,94452704,CLX5
2025-09-24 19:49:22.379029495+00:00,160,1,432669,A,A,64.83,1,26,8058566396322,128,18857,94452756,CLX5
2025-09-24 19:49:22.379193437+00:00,160,1,432669,C,B,64.82,2,26,8058566388928,128,14580,94452758,CLX5
2025-09-24 19:49:22.380378675+00:00,160,1,432669,C,B,64.8,2,26,8058566396295,128,14242,94452797,CLX5
2025-09-24 19:49:22.380646081+00:00,160,1,432669,C,B,64.82,3,26,8058566394279,128,18815,94452799,CLX5
2025-09-24 19:49:22.380668065+00:00,160,1,432669,A,A,64.86,2,26,8058566396333,128,14543,94452800,CLX5
2025-09-24 19:49:22.380669871+00:00,160,1,432669,A,A,64.83,2,26,8058566396337,128,15549,94452805,CLX5
2025-09-24 19:49:22.380695865+00:00,160,1,432669,A,A,64.83,2,26,8058566396340,128,15268,94452808,CLX5
2025-09-24 19:49:22.380987195+00:00,160,1,432669,M,B,63.67,4,26,8058566385977,128,19296,94452816,CLX5
2025-09-24 19:49:22.380999097+00:00,160,1,432669,M,B,64.82,2,26,8058566373409,128,14744,94452817,CLX5
2025-09-24 19:49:22.381565089+00:00,160,1,432669,M,B,63.66,4,26,8058566373409,128,15260,94452873,CLX5
2025-09-24 19:49:22.384165709+00:00,160,1,432669,C,A,64.83,2,26,8058566396340,128,18477,94452967,CLX5
2025-09-24 19:49:22.433062437+00:00,160,1,432669,C,A,64.88,2,26,8058566390074,128,17603,94453038,CLX5
2025-09-24 19:49:22.458122381+00:00,160,1,432669,A,B,64.82,1,26,8058566396418,128,20136,94453227,CLX5
2025-09-24 19:49:22.458158877+00:00,160,1,432669,C,A,64.83,1,26,8058566396232,128,15220,94453233,CLX5
2025-09-24 19:49:22.512418409+00:00,160,1,432669,C,B,64.82,1,26,8058566396418,128,18584,94453325,CLX5
2025-09-24 19:49:22.633089347+00:00,160,1,432669,A,B,64.78,2,26,8058566396490,128,17774,94453400,CLX5
2025-09-24 19:49:22.938626235+00:00,160,1,432669,A,A,64.83,1,26,8058566396515,128,19102,94453449,CLX5
2025-09-24 19:49:22.938791059+00:00,160,1,432669,A,A,64.83,1,26,8058566396517,128,18606,94453451,CLX5
2025-09-24 19:49:23.400626019+00:00,160,1,432669,C,A,64.83,1,26,8058566396517,128,18836,94453547,CLX5
2025-09-24 19:49:23.935397623+00:00,160,1,432669,C,B,64.81,2,26,8058566390076,128,16696,94453604,CLX5
2025-09-24 19:49:23.935398725+00:00,160,1,432669,C,B,64.8,2,26,8058566396255,128,14219,94453611,CLX5
2025-09-24 19:49:23.935545801+00:00,160,1,432669,A,A,64.83,1,26,8058566396600,128,18832,94453635,CLX5
2025-09-24 19:49:23.935731551+00:00,160,1,432669,C,B,64.79,1,26,8058566388893,128,14526,94453641,CLX5
2025-09-24 19:49:23.935974729+00:00,160,1,432669,A,A,64.83,1,26,8058566396607,128,15275,94453654,CLX5
2025-09-24 19:49:23.935999015+00:00,160,1,432669,C,A,64.83,1,26,8058566396600,128,15389,94453663,CLX5
2025-09-24 19:49:23.936098947+00:00,160,1,432669,C,B,64.82,3,26,8058566388374,128,18705,94453672,CLX5
2025-09-24 19:49:23.937233483+00:00,160,1,432669,C,B,64.79,2,26,8058566396296,128,14102,94453724,CLX5
2025-09-24 19:49:23.986126813+00:00,160,1,432669,A,B,64.81,2,26,8058566396667,128,18364,94453875,CLX5
2025-09-24 19:49:23.986131037+00:00,160,1,432669,A,B,64.8,2,26,8058566396669,128,14094,94453877,CLX5
2025-09-24 19:49:24.087230893+00:00,160,1,432669,A,A,65.76,1,26,8058566396707,128,19159,94453956,CLX5
2025-09-24 19:49:25.018615335+00:00,160,1,432669,A,B,64.82,2,26,8058566396777,128,19845,94454059,CLX5
2025-09-24 19:49:25.043997689+00:00,160,1,432669,C,B,64.82,2,26,8058566396777,128,18857,94454123,CLX5
2025-09-24 19:49:29.643661043+00:00,160,1,432669,A,A,64.83,2,26,8058566396938,128,14799,94454589,CLX5
2025-09-24 19:49:29.643849845+00:00,160,1,432669,A,A,64.83,2,26,8058566396940,128,15176,94454593,CLX5
2025-09-24 19:49:29.643941617+00:00,160,1,432669,C,B,64.82,1,26,8058566388430,128,16072,94454597,CLX5
2025-09-24 19:49:29.643945015+00:00,160,1,432669,A,A,64.83,1,26,8058566396942,128,14819,94454598,CLX5
2025-09-24 19:49:29.646432537+00:00,160,1,432669,C,B,64.82,3,26,8058566388362,128,16245,94454785,CLX5
2025-09-24 19:49:29.646627579+00:00,160,1,432669,M,A,64.84,1,26,8058566173085,128,14250,94454804,CLX5
2025-09-24 19:49:29.649147103+00:00,160,1,432669,T,A,64.82,1,26,8058566397008,0,14044,94454884,CLX5
2025-09-24 19:49:29.649147103+00:00,160,1,432669,F,B,64.82,1,26,8058566388372,0,14044,94454884,CLX5
2025-09-24 19:49:29.649147103+00:00,160,1,432669,C,B,64.82,1,26,8058566388372,128,20960,94454885,CLX5
2025-09-24 19:49:29.649185023+00:00,160,1,432669,C,A,64.83,1,26,8058566396515,128,14823,94454887,CLX5
2025-09-24 19:49:29.649614507+00:00,160,1,432669,T,A,64.82,2,26,8058566397015,0,16572,94454904,CLX5
2025-09-24 19:49:29.649614507+00:00,160,1,432669,F,B,64.82,1,26,8058566388379,0,16572,94454904,CLX5
2025-09-24 19:49:29.649614507+00:00,160,1,432669,F,B,64.82,1,26,8058566388429,0,16572,94454904,CLX5
2025-09-24 19:49:29.649614507+00:00,160,1,432669,C,B,64.82,1,26,8058566388379,0,16572,94454904,CLX5
2025-09-24 19:49:29.649614507+00:00,160,1,432669,C,B,64.82,1,26,8058566388429,128,16572,94454904,CLX5
2025-09-24 19:49:29.649816943+00:00,160,1,432669,A,B,64.82,1,26,8058566397017,128,14281,94454907,CLX5
2025-09-24 19:49:29.649817119+00:00,160,1,432669,A,B,64.82,2,26,8058566397018,128,14906,94454909,CLX5
2025-09-24 19:49:29.650020167+00:00,160,1,432669,A,A,64.83,3,26,8058566397024,128,16124,94454928,CLX5
2025-09-24 19:49:29.650059353+00:00,160,1,432669,C,A,64.83,2,26,8058566396938,128,18063,94454932,CLX5
2025-09-24 19:49:29.666425765+00:00,160,1,432669,C,B,64.82,1,26,8058566390710,128,19879,94455297,CLX5
2025-09-24 19:49:29.702164853+00:00,160,1,432669,A,B,64.82,2,26,8058566397159,128,16670,94455380,CLX5
2025-09-24 19:49:29.702167445+00:00,160,1,432669,A,B,64.82,1,26,8058566397160,128,15865,94455381,CLX5
2025-09-24 19:49:29.702330255+00:00,160,1,432669,A,B,64.82,2,26,8058566397161,128,18595,94455382,CLX5
2025-09-24 19:49:29.702344673+00:00,160,1,432669,A,B,64.82,1,26,8058566397165,128,20269,94455386,CLX5
2025-09-24 19:49:29.702346919+00:00,160,1,432669,C,A,64.83,2,26,8058566396940,128,15625,94455387,CLX5
2025-09-24 19:49:29.703330991+00:00,160,1,432669,A,B,64.82,3,26,8058566397171,128,15465,94455423,CLX5
2025-09-24 19:49:29.703600163+00:00,160,1,432669,A,B,64.82,1,26,8058566397175,128,19140,94455430,CLX5
2025-09-24 19:49:29.703601391+00:00,160,1,432669,C,A,64.83,1,26,8058566396942,128,15527,94455431,CLX5
2025-09-24 19:49:29.703680875+00:00,160,1,432669,A,B,64.82,1,26,8058566397178,128,18251,94455436,CLX5
2025-09-24 19:49:29.788870031+00:00,160,1,432669,C,B,64.82,1,26,8058566397178,128,16542,94455557,CLX5
2025-09-24 19:49:29.789017941+00:00,160,1,432669,C,B,64.82,3,26,8058566397171,128,19156,94455558,CLX5
2025-09-24 19:49:31.493122805+00:00,160,1,432669,C,B,64.82,2,26,8058566397161,128,20021,94455920,CLX5
2025-09-24 19:49:31.493283059+00:00,160,1,432669,C,B,64.82,1,26,8058566397160,128,15570,94455938,CLX5
2025-09-24 19:49:31.493595429+00:00,160,1,432669,C,B,64.82,1,26,8058566397165,128,16708,94455957,CLX5
2025-09-24 19:49:31.493601689+00:00,160,1,432669,C,B,64.82,1,26,8058566397175,128,15857,94455959,CLX5
2025-09-24 19:49:31.493603187+00:00,160,1,432669,A,A,64.83,1,26,8058566397417,128,15945,94455961,CLX5
2025-09-24 19:49:31.994772299+00:00,160,1,432669,C,B,64.82,2,26,8058566397159,128,20852,94456133,CLX5
2025-09-24 19:49:31.994804073+00:00,160,1,432669,A,A,64.83,2,26,8058566397476,128,15113,94456134,CLX5
2025-09-24 19:49:33.438514103+00:00,160,1,432669,A,B,64.82,1,26,8058566397481,128,21116,94456146,CLX5
2025-09-24 19:49:33.438687875+00:00,160,1,432669,C,A,64.83,2,26,8058566397476,128,18161,94456147,CLX5
2025-09-24 19:49:33.438825167+00:00,160,1,432669,C,B,64.82,1,26,8058566397481,128,20238,94456148,CLX5
2025-09-24 19:49:33.439171021+00:00,160,1,432669,A,B,64.82,1,26,8058566397482,128,19705,94456149,CLX5
2025-09-24 19:49:34.443050523+00:00,160,1,432669,C,B,64.82,1,26,8058566397482,128,20656,94456152,CLX5
2025-09-24 19:49:34.443207551+00:00,160,1,432669,A,A,64.83,2,26,8058566397484,128,18989,94456153,CLX5
2025-09-24 19:49:34.786207857+00:00,160,1,432669,A,B,64.82,1,26,8058566397486,128,20463,94456155,CLX5
2025-09-24 19:49:35.048439291+00:00,160,1,432669,C,A,64.83,2,26,8058566397484,128,19571,94456156,CLX5
2025-09-24 19:49:37.469149753+00:00,160,1,432669,C,B,64.63,1,26,8058559535706,128,20343,94456327,CLX5
2025-09-24 19:49:37.480012481+00:00,160,1,432669,T,B,64.83,1,26,8058566397559,0,17463,94456329,CLX5
2025-09-24 19:49:37.480012481+00:00,160,1,432669,F,A,64.83,1,26,8058566396003,0,17463,94456329,CLX5
2025-09-24 19:49:37.480012481+00:00,160,1,432669,C,A,64.83,1,26,8058566396003,128,15772,94456330,CLX5
2025-09-24 19:49:37.480382907+00:00,160,1,432669,A,B,64.82,2,26,8058566397560,128,20068,94456331,CLX5
2025-09-24 19:49:39.935754635+00:00,160,1,432669,C,B,64.82,2,26,8058566397560,128,16241,94456437,CLX5
2025-09-24 19:49:39.935773277+00:00,160,1,432669,A,A,64.83,2,26,8058566397603,128,17448,94456438,CLX5
2025-09-24 19:49:39.935976385+00:00,160,1,432669,C,B,64.82,1,26,8058566397486,128,22001,94456439,CLX5
2025-09-24 19:49:40.331762383+00:00,160,1,432669,A,B,64.82,1,26,8058566397639,128,21623,94456521,CLX5
2025-09-24 19:49:40.332852261+00:00,160,1,432669,C,B,64.82,1,26,8058566397639,128,14787,94456614,CLX5
