ts_event,rtype,publisher_id,instrument_id,action,side,price,size,channel_id,order_id,flags,ts_in_delta,sequence,symbol
2025-09-24 19:37:08.756455779+00:00,160,1,432669,A,A,64.82,1,26,8058566345892,128,14805,94313998,CLX5
2025-09-24 19:37:08.756491951+00:00,160,1,432669,A,A,64.82,1,26,8058566345893,128,16765,94314010,CLX5
2025-09-24 19:37:08.756792593+00:00,160,1,432669,A,A,64.82,2,26,8058566345905,128,17676,94314032,CLX5
2025-09-24 19:37:08.757042353+00:00,160,1,432669,A,A,64.82,3,26,8058566345913,128,16758,94314060,CLX5
2025-09-24 19:37:08.757134049+00:00,160,1,432669,A,A,64.82,1,26,8058566345920,128,16233,94314074,CLX5
2025-09-24 19:37:08.757161541+00:00,160,1,432669,A,A,64.83,1,26,8058566345921,128,18457,94314075,CLX5
2025-09-24 19:37:08.757832111+00:00,160,1,432669,C,A,64.82,3,26,8058566345913,128,16829,94314106,CLX5
2025-09-24 19:37:08.757932809+00:00,160,1,432669,A,A,64.86,2,26,8058566345929,128,14815,94314111,CLX5
2025-09-24 19:37:08.757955483+00:00,160,1,432669,A,B,64.81,1,26,8058566345933,128,14917,94314119,CLX5
2025-09-24 19:37:08.758176715+00:00,160,1,432669,A,A,64.82,7,26,8058566345937,128,18361,94314126,CLX5
2025-09-24 19:37:08.758642985+00:00,160,1,432669,A,B,63.68,4,26,8058566345944,128,13857,94314139,CLX5
2025-09-24 19:37:08.759206309+00:00,160,1,432669,A,A,64.82,2,26,8058566345959,128,18350,94314164,CLX5
2025-09-24 19:37:08.759606917+00:00,160,1,432669,M,A,64.94,1,26,8058565075241,128,14822,94314179,CLX5
2025-09-24 19:37:08.759846869+00:00,160,1,432669,C,B,64.81,2,26,8058566345393,128,15033,94314185,CLX5
2025-09-24 19:37:08.759855317+00:00,160,1,432669,A,A,64.83,1,26,8058566345966,128,14818,94314188,CLX5
2025-09-24 19:37:08.760878575+00:00,160,1,432669,M,A,64.95,1,26,8058565075241,128,16438,94314217,CLX5
2025-09-24 19:37:08.761620813+00:00,160,1,432669,M,A,64.94,1,26,8058565075241,128,14545,94314259,CLX5
2025-09-24 19:37:08.762994015+00:00,160,1,432669,C,B,64.81,1,26,8058566345401,128,18764,94314358,CLX5
2025-09-24 19:37:08.763804235+00:00,160,1,432669,M,A,64.83,1,26,8058566332416,128,18664,94314405,CLX5
2025-09-24 19:37:08.765358563+00:00,160,1,432669,A,A,64.82,1,26,8058566346042,128,17512,94314426,CLX5
2025-09-24 19:37:08.765375669+00:00,160,1,432669,A,A,64.82,1,26,8058566346045,128,18722,94314433,CLX5
2025-09-24 19:37:08.765410649+00:00,160,1,432669,A,B,64.81,1,26,8058566346046,128,15076,94314434,CLX5
2025-09-24 19:37:08.765475889+00:00,160,1,432669,A,A,64.82,3,26,8058566346047,128,15017,94314435,CLX5
2025-09-24 19:37:08.765515957+00:00,160,1,432669,A,A,64.82,2,26,8058566346050,128,17243,94314440,CLX5
2025-09-24 19:37:08.765618115+00:00,160,1,432669,M,B,63.66,4,26,8058566329044,128,15248,94314448,CLX5
2025-09-24 19:37:08.765633475+00:00,160,1,432669,M,B,63.65,4,26,8058566319508,128,16959,94314451,CLX5
2025-09-24 19:37:08.765840211+00:00,160,1,432669,M,A,64.84,4,26,8058566321460,128,14734,94314462,CLX5
2025-09-24 19:37:08.766573023+00:00,160,1,432669,C,B,64.81,1,26,8058566346046,128,18017,94314470,CLX5
2025-09-24 19:37:08.767185995+00:00,160,1,432669,C,A,64.82,2,26,8058566346050,128,14983,94314488,CLX5
2025-09-24 19:37:08.769239343+00:00,160,1,432669,C,B,64.81,1,26,8058566345933,128,14819,94314536,CLX5
2025-09-24 19:37:08.769385257+00:00,160,1,432669,C,A,64.82,7,26,8058566345937,128,15992,94314541,CLX5
2025-09-24 19:37:08.769387235+00:00,160,1,432669,C,B,64.81,2,26,8058566344960,128,19217,94314542,CLX5
2025-09-24 19:37:08.769407125+00:00,160,1,432669,C,B,64.81,3,26,8058566345515,128,15041,94314544,CLX5
2025-09-24 19:37:08.774902691+00:00,160,1,432669,C,A,64.82,1,26,8058566346042,128,18962,94314675,CLX5
2025-09-24 19:37:08.775623445+00:00,160,1,432669,A,B,64.8,1,26,8058566346121,128,17245,94314694,CLX5
2025-09-24 19:37:08.776271879+00:00,160,1,432669,C,A,64.82,1,26,8058566346045,128,15742,94314709,CLX5
2025-09-24 19:37:08.776787357+00:00,160,1,432669,A,A,64.82,1,26,8058566346128,128,20336,94314713,CLX5
2025-09-24 19:37:08.777186699+00:00,160,1,432669,A,B,64.81,1,26,8058566346132,128,18309,94314723,CLX5
2025-09-24 19:37:08.778724265+00:00,160,1,432669,A,B,63.67,4,26,8058566346145,128,14737,94314747,CLX5
2025-09-24 19:37:08.785041861+00:00,160,1,432669,C,A,64.83,1,26,8058566345586,128,18399,94314811,CLX5
2025-09-24 19:37:08.788421679+00:00,160,1,432669,C,A,64.82,1,26,8058566346128,128,19224,94314823,CLX5
2025-09-24 19:37:08.794118375+00:00,160,1,432669,M,A,64.82,1,26,8058566331891,128,19617,94314831,CLX5
2025-09-24 19:37:08.807982505+00:00,160,1,432669,A,B,64.81,1,26,8058566346182,128,19138,94314863,CLX5
2025-09-24 19:37:08.808141263+00:00,160,1,432669,C,B,64.81,1,26,8058566346132,128,15087,94314865,CLX5
2025-09-24 19:37:08.808286889+00:00,160,1,432669,A,B,64.81,1,26,8058566346183,128,13915,94314867,CLX5
2025-09-24 19:37:08.816632895+00:00,160,1,432669,M,A,64.82,1,26,8058566332416,128,19102,94314950,CLX5
2025-09-24 19:37:08.820037827+00:00,160,1,432669,M,A,64.83,1,26,8058566332416,128,19619,94314955,CLX5
2025-09-24 19:37:08.820170511+00:00,160,1,432669,C,B,64.81,1,26,8058566346183,128,18676,94314956,CLX5
2025-09-24 19:37:08.829202329+00:00,160,1,432669,M,A,64.82,1,26,8058566332416,128,19805,94314965,CLX5
2025-09-24 19:37:08.829348167+00:00,160,1,432669,A,B,64.81,1,26,8058566346197,128,18568,94314966,CLX5
2025-09-24 19:37:08.829486787+00:00,160,1,432669,C,B,64.81,1,26,8058566346197,128,18472,94314967,CLX5
2025-09-24 19:37:08.846900629+00:00,160,1,432669,A,B,64.81,1,26,8058566346236,128,14341,94315025,CLX5
2025-09-24 19:37:08.847170935+00:00,160,1,432669,A,B,64.81,1,26,8058566346246,128,15409,94315036,CLX5
2025-09-24 19:37:08.847303139+00:00,160,1,432669,C,B,64.81,1,26,8058566346246,128,18813,94315040,CLX5
2025-09-24 19:37:08.855797277+00:00,160,1,432669,C,B,64.81,1,26,8058566343024,128,18768,94315072,CLX5
2025-09-24 19:37:08.855800895+00:00,160,1,432669,A,B,64.81,1,26,8058566346262,128,15306,94315075,CLX5
2025-09-24 19:37:08.855801933+00:00,160,1,432669,A,A,64.82,1,26,8058566346263,128,18983,94315076,CLX5
2025-09-24 19:37:08.855808433+00:00,160,1,432669,C,B,64.8,2,26,8058566345015,128,15128,94315080,CLX5
2025-09-24 19:37:08.855808613+00:00,160,1,432669,A,A,64.82,1,26,8058566346265,128,19079,94315081,CLX5
2025-09-24 19:37:08.855810263+00:00,160,1,432669,C,B,64.81,1,26,8058566346236,128,16855,94315082,CLX5
2025-09-24 19:37:08.855818693+00:00,160,1,432669,C,B,64.81,1,26,8058566346262,128,15281,94315086,CLX5
2025-09-24 19:37:08.855825701+00:00,160,1,432669,C,B,64.81,1,26,8058566346182,128,19229,94315087,CLX5
2025-09-24 19:37:08.856128009+00:00,160,1,432669,C,B,64.81,1,26,8058566344904,128,16065,94315106,CLX5
2025-09-24 19:37:08.856155425+00:00,160,1,432669,A,A,64.82,3,26,8058566346278,128,19128,94315112,CLX5
2025-09-24 19:37:08.867325091+00:00,160,1,432669,C,B,64.81,1,26,8058566345497,128,19335,94315273,CLX5
2025-09-24 19:37:08.867462115+00:00,160,1,432669,C,B,64.81,1,26,8058566344836,128,18172,94315280,CLX5
2025-09-24 19:37:08.867664225+00:00,160,1,432669,A,B,64.81,1,26,8058566346339,128,19447,94315281,CLX5
2025-09-24 19:37:08.889085257+00:00,160,1,432669,A,A,64.82,1,26,8058566346410,128,15189,94315414,CLX5
2025-09-24 19:37:08.890716725+00:00,160,1,432669,M,B,63.64,4,26,8058566319851,128,19642,94315428,CLX5
2025-09-24 19:37:08.911118897+00:00,160,1,432669,A,B,64.78,2,26,8058566346446,128,14980,94315475,CLX5
2025-09-24 19:37:08.911124905+00:00,160,1,432669,A,B,64.77,2,26,8058566346447,128,18143,94315476,CLX5
2025-09-24 19:37:08.913053173+00:00,160,1,432669,C,B,64.79,1,26,8058566345526,128,18509,94315488,CLX5
2025-09-24 19:37:08.923366189+00:00,160,1,432669,C,B,64.54,8,26,8058566341136,128,17908,94315552,CLX5
2025-09-24 19:37:09.005829127+00:00,160,1,432669,C,A,64.83,1,26,8058566345612,128,18848,94315720,CLX5
2025-09-24 19:37:09.006283551+00:00,160,1,432669,A,A,64.82,1,26,8058566346598,128,18830,94315721,CLX5
2025-09-24 19:37:09.006422687+00:00,160,1,432669,C,B,64.81,1,26,8058566346339,128,22380,94315722,CLX5
2025-09-24 19:37:09.009793789+00:00,160,1,432669,M,A,64.83,1,26,8058566173085,128,18919,94315731,CLX5
2025-09-24 19:37:09.020339787+00:00,160,1,432669,C,B,64.77,2,26,8058566346447,128,14736,94315839,CLX5
2025-09-24 19:37:09.102100513+00:00,160,1,432669,A,B,64.81,1,26,8058566346733,128,20557,94316001,CLX5
2025-09-24 19:37:13.046826379+00:00,160,1,432669,A,A,64.82,1,26,8058566346946,128,18940,94316492,CLX5
2025-09-24 19:37:14.397532889+00:00,160,1,432669,A,A,64.85,1,26,8058566346951,128,14945,94316504,CLX5
2025-09-24 19:37:14.397553103+00:00,160,1,432669,C,B,64.81,1,26,8058566346733,128,19297,94316513,CLX5
2025-09-24 19:37:15.023415121+00:00,160,1,432669,A,B,64.81,1,26,8058566346991,128,16348,94316669,CLX5
2025-09-24 19:37:18.565105679+00:00,160,1,432669,C,B,64.81,1,26,8058566346991,128,20788,94316889,CLX5
2025-09-24 19:37:18.565330615+00:00,160,1,432669,A,A,64.85,2,26,8058566347088,128,14584,94316892,CLX5
2025-09-24 19:37:18.565330979+00:00,160,1,432669,C,B,64.81,1,26,8058566342791,128,19524,94316893,CLX5
2025-09-24 19:37:18.565384719+00:00,160,1,432669,C,B,64.81,1,26,8058566344837,128,19507,94316909,CLX5
2025-09-24 19:37:18.611083925+00:00,160,1,432669,C,A,64.87,2,26,8058566343201,128,17874,94317076,CLX5
2025-09-24 19:37:18.616766047+00:00,160,1,432669,C,A,65.9,1,26,8058566343202,128,18553,94317077,CLX5
2025-09-24 19:37:18.796971005+00:00,160,1,432669,A,B,64.81,1,26,8058566347174,128,19949,94317247,CLX5
2025-09-24 19:37:18.797033941+00:00,160,1,432669,A,B,64.81,1,26,8058566347179,128,16702,94317258,CLX5
2025-09-24 19:37:18.797034133+00:00,160,1,432669,A,B,64.81,1,26,8058566347180,128,19799,94317259,CLX5
2025-09-24 19:37:18.797337939+00:00,160,1,432669,A,B,64.81,1,26,8058566347186,128,14914,94317278,CLX5
2025-09-24 19:37:18.797342355+00:00,160,1,432669,C,A,64.85,2,26,8058566347088,128,14804,94317280,CLX5
2025-09-24 19:37:18.797349383+00:00,160,1,432669,A,B,64.81,1,26,8058566347192,128,16300,94317293,CLX5
2025-09-24 19:37:18.798107211+00:00,160,1,432669,A,B,64.8,2,26,8058566347206,128,19414,94317337,CLX5
2025-09-24 19:37:18.798113279+00:00,160,1,432669,A,B,64.54,8,26,8058566347210,128,14737,94317340,CLX5
2025-09-24 19:37:18.798317173+00:00,160,1,432669,A,B,64.81,1,26,8058566347219,128,19400,94317361,CLX5
2025-09-24 19:37:18.799274519+00:00,160,1,432669,C,B,64.81,1,26,8058566347192,128,14657,94317424,CLX5
2025-09-24 19:37:18.799893021+00:00,160,1,432669,A,B,64.81,1,26,8058566347239,128,19403,94317443,CLX5
2025-09-24 19:37:18.800336693+00:00,160,1,432669,A,A,64.82,1,26,8058566347241,128,16091,94317460,CLX5
2025-09-24 19:37:18.800340035+00:00,160,1,432669,A,A,64.82,1,26,8058566347242,128,18802,94317461,CLX5
2025-09-24 19:37:18.800977905+00:00,160,1,432669,C,B,64.81,1,26,8058566347239,128,15013,94317482,CLX5
2025-09-24 19:37:18.801684533+00:00,160,1,432669,C,B,64.8,2,26,8058566347206,128,14739,94317524,CLX5
2025-09-24 19:37:18.801697799+00:00,160,1,432669,C,B,64.81,1,26,8058566347219,128,17924,94317529,CLX5
2025-09-24 19:37:18.817032565+00:00,160,1,432669,A,A,65.9,1,26,8058566347325,128,18210,94317731,CLX5
2025-09-24 19:37:18.823056163+00:00,160,1,432669,C,B,64.54,8,26,8058566347210,128,18087,94317736,CLX5
2025-09-24 19:37:18.886365313+00:00,160,1,432669,A,B,64.75,1,26,8058566347345,128,18384,94317775,CLX5
2025-09-24 19:37:18.911114479+00:00,160,1,432669,A,A,64.87,2,26,8058566347355,128,14891,94317795,CLX5
2025-09-24 19:37:18.911118817+00:00,160,1,432669,A,B,64.77,2,26,8058566347356,128,14744,94317796,CLX5
2025-09-24 19:37:19.034358353+00:00,160,1,432669,C,B,64.81,1,26,8058566347186,128,21635,94317838,CLX5
2025-09-24 19:37:20.672260509+00:00,160,1,432669,C,A,69.0,1,26,8058355891698,128,18436,94317905,CLX5
2025-09-24 19:37:24.108298697+00:00,160,1,432669,C,B,64.81,1,26,8058566347180,128,18657,94318054,CLX5
2025-09-24 19:37:24.108451213+00:00,160,1,432669,C,B,64.81,1,26,8058566347179,128,20301,94318069,CLX5
2025-09-24 19:37:24.109001751+00:00,160,1,432669,C,B,64.81,1,26,8058566347174,128,20090,94318112,CLX5
2025-09-24 19:37:24.109436745+00:00,160,1,432669,C,B,64.77,2,26,8058566347356,128,18562,94318264,CLX5
2025-09-24 19:37:24.118937889+00:00,160,1,432669,C,B,64.81,2,26,8058566342995,128,17407,94318856,CLX5
2025-09-24 19:37:24.121019461+00:00,160,1,432669,M,B,64.79,1,26,8058566337316,128,18474,94318929,CLX5
2025-09-24 19:37:24.212483629+00:00,160,1,432669,A,B,64.81,1,26,8058566347887,128,18541,94319315,CLX5
2025-09-24 19:37:24.212483841+00:00,160,1,432669,A,B,64.81,1,26,8058566347888,128,19154,94319316,CLX5
2025-09-24 19:37:24.212835953+00:00,160,1,432669,M,B,64.8,1,26,8058566337316,128,15068,94319348,CLX5
2025-09-24 19:37:24.212844633+00:00,160,1,432669,A,B,64.81,1,26,8058566347895,128,16593,94319350,CLX5
2025-09-24 19:37:24.356882649+00:00,160,1,432669,C,A,69.5,1,26,8058355890181,128,14480,94319748,CLX5
2025-09-24 19:37:28.391108673+00:00,160,1,432669,T,B,64.82,1,26,8058566348566,0,20177,94320674,CLX5
2025-09-24 19:37:28.391108673+00:00,160,1,432669,F,A,64.82,1,26,8058566345869,0,20177,94320674,CLX5
2025-09-24 19:37:28.391108673+00:00,160,1,432669,M,A,64.82,1,26,8058566345869,128,17617,94320675,CLX5
2025-09-24 19:37:28.391447787+00:00,160,1,432669,A,B,64.81,1,26,8058566348569,128,20420,94320679,CLX5
2025-09-24 19:37:28.391475471+00:00,160,1,432669,A,B,64.81,1,26,8058566348572,128,16790,94320685,CLX5
2025-09-24 19:37:28.391880863+00:00,160,1,432669,C,B,64.81,1,26,8058566348569,128,19776,94320707,CLX5
2025-09-24 19:37:28.393075759+00:00,160,1,432669,A,B,64.81,2,26,8058566348602,128,16009,94320784,CLX5
2025-09-24 19:37:28.511115377+00:00,160,1,432669,A,B,64.77,2,26,8058566348682,128,18004,94321033,CLX5
2025-09-24 19:37:28.587340393+00:00,160,1,432669,A,B,64.81,1,26,8058566348697,128,19224,94321059,CLX5
2025-09-24 19:37:28.587534381+00:00,160,1,432669,A,B,64.81,1,26,8058566348698,128,19260,94321060,CLX5
2025-09-24 19:37:28.587698937+00:00,160,1,432669,A,B,64.81,1,26,8058566348700,128,16051,94321062,CLX5
2025-09-24 19:37:29.314886941+00:00,160,1,432669,A,B,64.8,1,26,8058566348718,128,18958,94321092,CLX5
2025-09-24 19:37:29.314894061+00:00,160,1,432669,C,B,64.81,1,26,8058566348700,128,16441,94321093,CLX5
2025-09-24 19:37:29.314905351+00:00,160,1,432669,C,B,64.81,1,26,8058566348698,128,15735,94321094,CLX5
2025-09-24 19:37:32.074995371+00:00,160,1,432669,C,B,64.81,1,26,8058566348697,128,20854,94321322,CLX5
2025-09-24 19:37:32.633371189+00:00,160,1,432669,A,B,64.8,1,26,8058566348768,128,18838,94321477,CLX5
2025-09-24 19:37:33.739518907+00:00,160,1,432669,A,B,64.8,1,26,8058566348815,128,21216,94321541,CLX5
2025-09-24 19:37:35.512701327+00:00,160,1,432669,T,A,64.81,1,26,8058566348826,0,18260,94321553,CLX5
2025-09-24 19:37:35.512701327+00:00,160,1,432669,F,B,64.81,1,26,8058566344919,0,18260,94321553,CLX5
2025-09-24 19:37:35.512701327+00:00,160,1,432669,C,B,64.81,1,26,8058566344919,128,17423,94321554,CLX5
2025-09-24 19:37:35.513689045+00:00,160,1,432669,C,B,64.81,1,26,8058566348572,128,14746,94321560,CLX5
2025-09-24 19:37:35.513696993+00:00,160,1,432669,C,B,64.81,2,26,8058566348602,128,17020,94321561,CLX5
2025-09-24 19:37:36.203833779+00:00,160,1,432669,A,B,64.81,1,26,8058566348830,128,20293,94321574,CLX5
2025-09-24 19:37:36.204016171+00:00,160,1,432669,C,B,64.8,1,26,8058566348815,128,18383,94321575,CLX5
2025-09-24 19:37:36.204024675+00:00,160,1,432669,C,B,64.8,1,26,8058566348768,128,17382,94321576,CLX5
2025-09-24 19:37:36.695662915+00:00,160,1,432669,A,B,64.8,1,26,8058566348834,128,19297,94321590,CLX5
2025-09-24 19:37:37.057991289+00:00,160,1,432669,C,B,64.8,1,26,8058566348718,128,19386,94321591,CLX5
2025-09-24 19:37:38.929726699+00:00,160,1,432669,C,B,64.81,1,26,8058566348830,128,18818,94321600,CLX5
2025-09-24 19:37:38.929942363+00:00,160,1,432669,C,B,64.77,2,26,8058566348682,128,17195,94321604,CLX5
2025-09-24 19:37:40.478745769+00:00,160,1,432669,A,B,64.81,2,26,8058566348847,128,20019,94321654,CLX5
2025-09-24 19:37:40.478747497+00:00,160,1,432669,A,B,64.81,1,26,8058566348848,128,15958,94321655,CLX5
2025-09-24 19:37:40.611163461+00:00,160,1,432669,A,B,64.77,2,26,8058566348887,128,18120,94321738,CLX5
2025-09-24 19:37:49.646073981+00:00,160,1,432669,A,A,64.95,1,26,8058566349026,128,20347,94322025,CLX5
2025-09-24 19:37:50.911241681+00:00,160,1,432669,T,B,64.82,11,26,8058566349029,0,24726,94322034,CLX5
2025-09-24 19:37:50.911241681+00:00,160,1,432669,F,A,64.82,1,26,8058566345869,0,24726,94322034,CLX5
2025-09-24 19:37:50.911241681+00:00,160,1,432669,F,A,64.82,1,26,8058566345892,0,24726,94322034,CLX5
2025-09-24 19:37:50.911241681+00:00,160,1,432669,F,A,64.82,2,26,8058566345905,0,24726,94322034,CLX5
2025-09-24 19:37:50.911241681+00:00,160,1,432669,F,A,64.82,1,26,8058566345920,0,24726,94322034,CLX5
2025-09-24 19:37:50.911241681+00:00,160,1,432669,F,A,64.82,2,26,8058566345959,0,24726,94322034,CLX5
2025-09-24 19:37:50.911241681+00:00,160,1,432669,F,A,64.82,3,26,8058566346047,0,24726,94322034,CLX5
2025-09-24 19:37:50.911241681+00:00,160,1,432669,F,A,64.82,1,26,8058566345893,0,24726,94322034,CLX5
2025-09-24 19:37:50.911241681+00:00,160,1,432669,C,A,64.82,1,26,8058566345869,0,19975,94322035,CLX5
2025-09-24 19:37:50.911241681+00:00,160,1,432669,C,A,64.82,1,26,8058566345892,0,19975,94322035,CLX5
2025-09-24 19:37:50.911241681+00:00,160,1,432669,C,A,64.82,2,26,8058566345905,0,19975,94322035,CLX5
2025-09-24 19:37:50.911241681+00:00,160,1,432669,C,A,64.82,1,26,8058566345920,0,19975,94322035,CLX5
2025-09-24 19:37:50.911241681+00:00,160,1,432669,C,A,64.82,2,26,8058566345959,0,19975,94322035,CLX5
2025-09-24 19:37:50.911241681+00:00,160,1,432669,C,A,64.82,3,26,8058566346047,0,19975,94322035,CLX5
2025-09-24 19:37:50.911241681+00:00,160,1,432669,C,A,64.82,1,26,8058566345893,128,19975,94322035,CLX5
2025-09-24 19:37:50.911650413+00:00,160,1,432669,A,B,64.81,1,26,8058566349034,128,21124,94322040,CLX5
2025-09-24 19:37:50.911663487+00:00,160,1,432669,A,B,64.81,1,26,8058566349036,128,18904,94322044,CLX5
2025-09-24 19:37:50.911680671+00:00,160,1,432669,A,B,64.81,1,26,8058566349038,128,18746,94322047,CLX5
2025-09-24 19:37:50.911693457+00:00,160,1,432669,A,B,64.81,1,26,8058566349039,128,21323,94322048,CLX5
2025-09-24 19:37:50.911722757+00:00,160,1,432669,C,A,64.82,1,26,8058566346263,128,17967,94322049,CLX5
2025-09-24 19:37:50.911724963+00:00,160,1,432669,A,B,64.81,1,26,8058566349040,128,19335,94322050,CLX5
2025-09-24 19:37:50.911753601+00:00,160,1,432669,T,B,64.82,7,26,8058566349044,0,22700,94322060,CLX5
2025-09-24 19:37:50.911753601+00:00,160,1,432669,F,A,64.82,1,26,8058566331891,0,22700,94322060,CLX5
2025-09-24 19:37:50.911753601+00:00,160,1,432669,F,A,64.82,1,26,8058566346265,0,22700,94322060,CLX5
2025-09-24 19:37:50.911753601+00:00,160,1,432669,F,A,64.82,3,26,8058566346278,0,22700,94322060,CLX5
2025-09-24 19:37:50.911753601+00:00,160,1,432669,F,A,64.82,1,26,8058566346410,0,22700,94322060,CLX5
2025-09-24 19:37:50.911753601+00:00,160,1,432669,F,A,64.82,1,26,8058566332416,0,22700,94322060,CLX5
2025-09-24 19:37:50.911753601+00:00,160,1,432669,C,A,64.82,1,26,8058566331891,0,22700,94322060,CLX5
2025-09-24 19:37:50.911753601+00:00,160,1,432669,C,A,64.82,1,26,8058566346265,0,22700,94322060,CLX5
2025-09-24 19:37:50.911753601+00:00,160,1,432669,C,A,64.82,3,26,8058566346278,0,22700,94322060,CLX5
2025-09-24 19:37:50.911753601+00:00,160,1,432669,C,A,64.82,1,26,8058566346410,0,22700,94322060,CLX5
2025-09-24 19:37:50.911753601+00:00,160,1,432669,C,A,64.82,1,26,8058566332416,128,22700,94322060,CLX5
2025-09-24 19:37:50.911782773+00:00,160,1,432669,A,A,64.82,2,26,8058566349051,128,15080,94322075,CLX5
2025-09-24 19:37:50.911940205+00:00,160,1,432669,C,B,64.81,1,26,8058566349040,128,15807,94322089,CLX5
2025-09-24 19:37:50.912067899+00:00,160,1,432669,A,A,64.82,1,26,8058566349053,128,19638,94322091,CLX5
2025-09-24 19:37:50.912221185+00:00,160,1,432669,C,A,64.85,1,26,8058566346951,128,14968,94322102,CLX5
2025-09-24 19:37:50.912355445+00:00,160,1,432669,A,B,64.8,2,26,8058566349059,128,17715,94322104,CLX5
2025-09-24 19:37:50.912359265+00:00,160,1,432669,A,B,64.54,8,26,8058566349061,128,14210,94322107,CLX5
2025-09-24 19:37:50.912365275+00:00,160,1,432669,C,B,64.77,2,26,8058566348887,128,18267,94322108,CLX5
2025-09-24 19:37:50.912418417+00:00,160,1,432669,A,B,64.81,1,26,8058566349065,128,13943,94322112,CLX5
2025-09-24 19:37:50.912582687+00:00,160,1,432669,M,B,64.81,1,26,8058566337316,128,17411,94322144,CLX5
2025-09-24 19:37:50.912603709+00:00,160,1,432669,A,A,64.82,1,26,8058566349075,128,16594,94322146,CLX5
2025-09-24 19:37:50.912796143+00:00,160,1,432669,A,B,64.79,1,26,8058566349077,128,14556,94322160,CLX5
2025-09-24 19:37:50.913182907+00:00,160,1,432669,A,B,64.81,1,26,8058566349088,128,15116,94322200,CLX5
2025-09-24 19:37:50.913265601+00:00,160,1,432669,A,A,64.82,2,26,8058566349090,128,16530,94322203,CLX5
2025-09-24 19:37:50.914934697+00:00,160,1,432669,C,B,64.81,1,26,8058566349088,128,15611,94322306,CLX5
2025-09-24 19:37:50.915906041+00:00,160,1,432669,A,B,64.81,1,26,8058566349126,128,16038,94322371,CLX5
2025-09-24 19:37:50.916019065+00:00,160,1,432669,A,B,64.81,1,26,8058566349128,128,14237,94322376,CLX5
2025-09-24 19:37:50.917193383+00:00,160,1,432669,C,B,64.81,1,26,8058566349126,128,14175,94322418,CLX5
2025-09-24 19:37:50.917667101+00:00,160,1,432669,C,A,64.82,1,26,8058566349053,128,15671,94322426,CLX5
2025-09-24 19:37:50.917910489+00:00,160,1,432669,A,B,64.81,1,26,8058566349144,128,13729,94322429,CLX5
2025-09-24 19:37:50.918140419+00:00,160,1,432669,A,B,64.81,1,26,8058566349146,128,14949,94322441,CLX5
2025-09-24 19:37:50.919203477+00:00,160,1,432669,C,B,64.81,1,26,8058566349146,128,16228,94322461,CLX5
2025-09-24 19:37:50.920085003+00:00,160,1,432669,A,A,64.82,1,26,8058566349161,128,14617,94322485,CLX5
2025-09-24 19:37:50.920151319+00:00,160,1,432669,A,B,64.81,1,26,8058566349162,128,14932,94322487,CLX5
2025-09-24 19:37:50.920378329+00:00,160,1,432669,C,B,64.81,1,26,8058566349162,128,14837,94322489,CLX5
2025-09-24 19:37:50.920926925+00:00,160,1,432669,A,B,64.81,1,26,8058566349182,128,14657,94322526,CLX5
2025-09-24 19:37:50.921866591+00:00,160,1,432669,C,B,64.8,1,26,8058566346121,128,18166,94322538,CLX5
2025-09-24 19:37:50.924219197+00:00,160,1,432669,T,A,64.81,1,26,8058566349198,0,17364,94322585,CLX5
2025-09-24 19:37:50.924219197+00:00,160,1,432669,F,B,64.81,1,26,8058566345298,0,17364,94322585,CLX5
2025-09-24 19:37:50.924219197+00:00,160,1,432669,C,B,64.81,1,26,8058566345298,128,18976,94322586,CLX5
2025-09-24 19:37:50.924544237+00:00,160,1,432669,A,A,64.82,2,26,8058566349201,128,16699,94322588,CLX5
2025-09-24 19:37:50.924545793+00:00,160,1,432669,A,A,64.82,1,26,8058566349202,128,17918,94322589,CLX5
2025-09-24 19:37:50.924646703+00:00,160,1,432669,A,A,64.85,1,26,8058566349206,128,17298,94322601,CLX5
2025-09-24 19:37:50.924722367+00:00,160,1,432669,C,A,64.82,1,26,8058566349202,128,16793,94322607,CLX5
2025-09-24 19:37:50.924855553+00:00,160,1,432669,A,A,64.82,1,26,8058566349209,128,15579,94322609,CLX5
2025-09-24 19:37:50.925073809+00:00,160,1,432669,A,A,64.82,1,26,8058566349211,128,15667,94322615,CLX5
2025-09-24 19:37:50.925201119+00:00,160,1,432669,A,A,64.82,1,26,8058566349212,128,19238,94322618,CLX5
2025-09-24 19:37:50.925351217+00:00,160,1,432669,C,A,64.82,1,26,8058566349212,128,14473,94322624,CLX5
2025-09-24 19:37:50.926985123+00:00,160,1,432669,C,B,64.81,1,26,8058566349036,128,18109,94322656,CLX5
2025-09-24 19:37:50.985367655+00:00,160,1,432669,C,A,64.85,1,26,8058566349206,128,17876,94322782,CLX5
2025-09-24 19:37:50.985521305+00:00,160,1,432669,C,B,64.81,1,26,8058566349182,128,19404,94322783,CLX5
2025-09-24 19:37:50.985528293+00:00,160,1,432669,C,B,64.81,1,26,8058566349144,128,15395,94322784,CLX5
2025-09-24 19:37:50.985536875+00:00,160,1,432669,C,B,64.81,1,26,8058566349128,128,14255,94322785,CLX5
2025-09-24 19:37:51.011299007+00:00,160,1,432669,C,B,64.78,2,26,8058566346446,128,17912,94322822,CLX5
2025-09-24 19:37:51.093275935+00:00,160,1,432669,C,B,64.79,1,26,8058566349077,128,18739,94322917,CLX5
2025-09-24 19:37:51.268490461+00:00,160,1,432669,A,A,64.82,1,26,8058566349378,128,19082,94322980,CLX5
2025-09-24 19:37:56.072296803+00:00,160,1,432669,M,A,64.94,1,26,8058566125142,128,19731,94323116,CLX5
2025-09-24 19:37:56.461442669+00:00,160,1,432669,A,A,64.82,1,26,8058566349454,128,22009,94323120,CLX5
2025-09-24 19:37:56.461618285+00:00,160,1,432669,C,B,64.81,1,26,8058566349039,128,18980,94323121,CLX5
2025-09-24 19:37:56.461621127+00:00,160,1,432669,C,B,64.81,1,26,8058566349034,128,15649,94323122,CLX5
2025-09-24 19:37:56.462729897+00:00,160,1,432669,A,A,64.85,1,26,8058566349467,128,18261,94323161,CLX5
2025-09-24 19:37:56.525937369+00:00,160,1,432669,C,B,64.81,1,26,8058566349038,128,17867,94323163,CLX5
2025-09-24 19:37:56.525938749+00:00,160,1,432669,C,B,64.8,2,26,8058566349059,128,15043,94323165,CLX5
2025-09-24 19:37:56.525949233+00:00,160,1,432669,C,B,64.81,1,26,8058566348848,128,19150,94323166,CLX5
2025-09-24 19:37:56.525963977+00:00,160,1,432669,A,A,64.82,3,26,8058566349469,128,18355,94323175,CLX5
2025-09-24 19:37:56.525973961+00:00,160,1,432669,C,B,64.81,1,26,8058566349065,128,16741,94323176,CLX5
2025-09-24 19:37:56.525988439+00:00,160,1,432669,A,B,64.8,1,26,8058566349470,128,13826,94323177,CLX5
2025-09-24 19:37:56.526595093+00:00,160,1,432669,A,B,64.81,1,26,8058566349485,128,16375,94323212,CLX5
2025-09-24 19:37:56.526982377+00:00,160,1,432669,C,B,64.81,2,26,8058566348847,128,18760,94323223,CLX5
2025-09-24 19:37:56.611230699+00:00,160,1,432669,A,B,64.78,2,26,8058566349492,128,18404,94323243,CLX5
2025-09-24 19:37:56.623276901+00:00,160,1,432669,C,B,64.54,8,26,8058566349061,128,18312,94323244,CLX5
2025-09-24 19:37:59.709866941+00:00,160,1,432669,M,A,64.95,1,26,8058566131103,128,22314,94323261,CLX5
2025-09-24 19:38:00.025375377+00:00,160,1,432669,A,B,64.81,1,26,8058566349498,128,22043,94323268,CLX5
2025-09-24 19:38:00.178935273+00:00,160,1,432669,A,A,64.82,1,26,8058566349502,128,20629,94323273,CLX5
2025-09-24 19:38:01.285776431+00:00,160,1,432669,A,B,64.81,1,26,8058566349504,128,25824,94323275,CLX5
2025-09-24 19:38:04.290367409+00:00,160,1,432669,C,A,64.98,1,26,8058566344965,128,22573,94323309,CLX5
2025-09-24 19:38:04.305884031+00:00,160,1,432669,A,A,64.97,1,26,8058566349514,128,20559,94323310,CLX5
2025-09-24 19:38:05.091021395+00:00,160,1,432669,C,B,64.81,1,26,8058566349485,128,27614,94323311,CLX5
2025-09-24 19:38:07.121646557+00:00,160,1,432669,C,B,64.81,1,26,8058566347888,128,16656,94323579,CLX5
2025-09-24 19:38:07.121946737+00:00,160,1,432669,C,B,64.81,1,26,8058566347887,128,16691,94323637,CLX5
2025-09-24 19:38:07.121974747+00:00,160,1,432669,A,A,64.82,1,26,8058566349632,128,15126,94323639,CLX5
2025-09-24 19:38:07.121974927+00:00,160,1,432669,A,A,64.82,1,26,8058566349633,128,13809,94323640,CLX5
2025-09-24 19:38:07.121983253+00:00,160,1,432669,A,A,64.82,1,26,8058566349634,128,17944,94323642,CLX5
2025-09-24 19:38:07.122118473+00:00,160,1,432669,T,A,64.81,2,26,8058566349645,0,14341,94323671,CLX5
2025-09-24 19:38:07.122118473+00:00,160,1,432669,F,B,64.81,1,26,8058566340051,0,14341,94323671,CLX5
2025-09-24 19:38:07.122118473+00:00,160,1,432669,F,B,64.81,1,26,8058566347895,0,14341,94323671,CLX5
2025-09-24 19:38:07.122118473+00:00,160,1,432669,C,B,64.81,1,26,8058566340051,0,14341,94323671,CLX5
2025-09-24 19:38:07.122118473+00:00,160,1,432669,C,B,64.81,1,26,8058566347895,128,14341,94323671,CLX5
2025-09-24 19:38:07.122236299+00:00,160,1,432669,T,A,64.81,3,26,8058566349653,0,15250,94323690,CLX5
2025-09-24 19:38:07.122236299+00:00,160,1,432669,F,B,64.81,1,26,8058566337316,0,15250,94323690,CLX5
2025-09-24 19:38:07.122236299+00:00,160,1,432669,F,B,64.81,1,26,8058566349498,0,15250,94323690,CLX5
2025-09-24 19:38:07.122236299+00:00,160,1,432669,F,B,64.81,1,26,8058566349504,0,15250,94323690,CLX5
2025-09-24 19:38:07.122236299+00:00,160,1,432669,C,B,64.81,1,26,8058566337316,0,18279,94323691,CLX5
2025-09-24 19:38:07.122236299+00:00,160,1,432669,C,B,64.81,1,26,8058566349498,0,18279,94323691,CLX5
2025-09-24 19:38:07.122236299+00:00,160,1,432669,C,B,64.81,1,26,8058566349504,128,18279,94323691,CLX5
2025-09-24 19:38:07.122236491+00:00,160,1,432669,A,A,64.81,1,26,8058566349654,128,13597,94323694,CLX5
2025-09-24 19:38:07.122236665+00:00,160,1,432669,A,A,64.81,1,26,8058566349655,128,16016,94323697,CLX5
2025-09-24 19:38:07.122236951+00:00,160,1,432669,A,A,64.85,2,26,8058566349656,128,14356,94323700,CLX5
2025-09-24 19:38:07.122248989+00:00,160,1,432669,A,A,64.82,1,26,8058566349663,128,14803,94323706,CLX5
2025-09-24 19:38:07.122537647+00:00,160,1,432669,A,B,64.54,8,26,8058566349679,128,14865,94323747,CLX5
2025-09-24 19:38:07.125343449+00:00,160,1,432669,A,A,64.82,3,26,8058566349748,128,14852,94324000,CLX5
2025-09-24 19:38:07.126561403+00:00,160,1,432669,C,A,64.81,1,26,8058566349654,128,14821,94324087,CLX5
2025-09-24 19:38:07.126561549+00:00,160,1,432669,C,A,64.81,1,26,8058566349655,128,18225,94324090,CLX5
2025-09-24 19:38:07.126582563+00:00,160,1,432669,A,B,64.8,1,26,8058566349770,128,14643,94324094,CLX5
2025-09-24 19:38:07.127136939+00:00,160,1,432669,M,A,64.81,1,26,8058566349502,128,18041,94324146,CLX5
2025-09-24 19:38:07.127548665+00:00,160,1,432669,A,A,64.81,1,26,8058566349788,128,14722,94324180,CLX5
2025-09-24 19:38:07.127662861+00:00,160,1,432669,A,A,64.81,1,26,8058566349791,128,18152,94324190,CLX5
2025-09-24 19:38:07.127679411+00:00,160,1,432669,A,A,64.81,1,26,8058566349793,128,18413,94324195,CLX5
2025-09-24 19:38:07.127702603+00:00,160,1,432669,C,A,64.85,1,26,8058566312900,128,15320,94324200,CLX5
2025-09-24 19:38:07.127866815+00:00,160,1,432669,M,B,63.63,3,26,8058566221991,128,14113,94324211,CLX5
2025-09-24 19:38:07.127879967+00:00,160,1,432669,M,B,63.62,3,26,8058566332677,128,14848,94324212,CLX5
2025-09-24 19:38:07.127983777+00:00,160,1,432669,C,A,64.82,1,26,8058566347242,128,18721,94324223,CLX5
2025-09-24 19:38:07.127987251+00:00,160,1,432669,C,A,64.82,1,26,8058566347241,128,15903,94324224,CLX5
2025-09-24 19:38:07.128082057+00:00,160,1,432669,M,A,64.83,3,26,8058566331102,128,14404,94324230,CLX5
2025-09-24 19:38:07.128482417+00:00,160,1,432669,A,A,64.81,1,26,8058566349807,128,20466,94324249,CLX5
2025-09-24 19:38:07.128763837+00:00,160,1,432669,A,A,64.81,2,26,8058566349810,128,15027,94324261,CLX5
2025-09-24 19:38:07.132243607+00:00,160,1,432669,C,A,64.81,1,26,8058566349791,128,16401,94324439,CLX5
2025-09-24 19:38:07.132926501+00:00,160,1,432669,C,A,64.81,1,26,8058566349807,128,20423,94324576,CLX5
2025-09-24 19:38:07.133605517+00:00,160,1,432669,C,A,64.81,2,26,8058566349810,128,18999,94324595,CLX5
2025-09-24 19:38:07.133745845+00:00,160,1,432669,A,A,64.82,1,26,8058566349883,128,18010,94324598,CLX5
2025-09-24 19:38:07.133789119+00:00,160,1,432669,A,A,64.82,1,26,8058566349884,128,15028,94324599,CLX5
2025-09-24 19:38:07.134876311+00:00,160,1,432669,A,A,64.82,1,26,8058566349897,128,19161,94324631,CLX5
2025-09-24 19:38:07.135252441+00:00,160,1,432669,A,A,64.81,2,26,8058566349900,128,18117,94324640,CLX5
2025-09-24 19:38:07.137795273+00:00,160,1,432669,C,A,64.81,2,26,8058566349900,128,20852,94324741,CLX5
2025-09-24 19:38:07.139478275+00:00,160,1,432669,T,B,64.81,1,26,8058566349952,0,14853,94324809,CLX5
2025-09-24 19:38:07.139478275+00:00,160,1,432669,F,A,64.81,1,26,8058566349502,0,14853,94324809,CLX5
2025-09-24 19:38:07.139478275+00:00,160,1,432669,C,A,64.81,1,26,8058566349502,128,14757,94324810,CLX5
2025-09-24 19:38:07.139910827+00:00,160,1,432669,T,B,64.81,1,26,8058566349958,0,14560,94324826,CLX5
2025-09-24 19:38:07.139910827+00:00,160,1,432669,F,A,64.81,1,26,8058566349788,0,14560,94324826,CLX5
2025-09-24 19:38:07.139910827+00:00,160,1,432669,C,A,64.81,1,26,8058566349788,128,18486,94324827,CLX5
2025-09-24 19:38:07.140203211+00:00,160,1,432669,A,B,64.8,1,26,8058566349963,128,14881,94324838,CLX5
2025-09-24 19:38:07.140294041+00:00,160,1,432669,A,A,64.81,2,26,8058566349966,128,16991,94324843,CLX5
2025-09-24 19:38:07.140414017+00:00,160,1,432669,C,B,64.8,1,26,8058566349963,128,14921,94324850,CLX5
2025-09-24 19:38:07.146030827+00:00,160,1,432669,C,A,64.81,2,26,8058566349966,128,18291,94325019,CLX5
2025-09-24 19:38:07.146492507+00:00,160,1,432669,C,A,64.82,1,26,8058566349897,128,18164,94325054,CLX5
2025-09-24 19:38:07.146497519+00:00,160,1,432669,C,A,64.82,1,26,8058566349884,128,15585,94325055,CLX5
2025-09-24 19:38:07.146502569+00:00,160,1,432669,C,A,64.82,1,26,8058566349883,128,14821,94325056,CLX5
2025-09-24 19:38:07.146534553+00:00,160,1,432669,T,B,64.81,1,26,8058566350034,0,14329,94325057,CLX5
2025-09-24 19:38:07.146534553+00:00,160,1,432669,F,A,64.81,1,26,8058566349793,0,14329,94325057,CLX5
2025-09-24 19:38:07.146534553+00:00,160,1,432669,C,A,64.81,1,26,8058566349793,128,19505,94325058,CLX5
2025-09-24 19:38:07.149540181+00:00,160,1,432669,A,A,64.81,2,26,8058566350079,128,14470,94325203,CLX5
2025-09-24 19:38:07.150129517+00:00,160,1,432669,C,A,64.81,2,26,8058566350079,128,17067,94325221,CLX5
2025-09-24 19:38:07.150662621+00:00,160,1,432669,C,A,64.83,1,26,8058566345790,128,15217,94325251,CLX5
2025-09-24 19:38:07.150810627+00:00,160,1,432669,C,A,64.82,1,26,8058566349663,128,18048,94325280,CLX5
2025-09-24 19:38:07.155211689+00:00,160,1,432669,M,A,64.81,1,26,8058566349161,128,14781,94325502,CLX5
2025-09-24 19:38:07.156521339+00:00,160,1,432669,T,B,64.81,1,26,8058566350168,0,14640,94325548,CLX5
2025-09-24 19:38:07.156521339+00:00,160,1,432669,F,A,64.81,1,26,8058566349161,0,14640,94325548,CLX5
2025-09-24 19:38:07.156521339+00:00,160,1,432669,C,A,64.81,1,26,8058566349161,128,14503,94325549,CLX5
2025-09-24 19:38:07.156908067+00:00,160,1,432669,M,A,65.98,3,26,8058566321460,128,15592,94325571,CLX5
2025-09-24 19:38:07.157454783+00:00,160,1,432669,M,A,64.84,4,26,8058566331622,128,15024,94325606,CLX5
2025-09-24 19:38:07.160780863+00:00,160,1,432669,M,A,64.93,1,26,8058565075241,128,17402,94325691,CLX5
2025-09-24 19:38:07.161552555+00:00,160,1,432669,M,A,64.94,1,26,8058565075241,128,14094,94325715,CLX5
2025-09-24 19:38:07.164266777+00:00,160,1,432669,A,A,64.82,1,26,8058566350235,128,18425,94325736,CLX5
2025-09-24 19:38:07.166569427+00:00,160,1,432669,A,B,64.81,1,26,8058566350242,128,18247,94325751,CLX5
2025-09-24 19:38:07.167148531+00:00,160,1,432669,M,A,65.97,4,26,8058566331102,128,18583,94325773,CLX5
2025-09-24 19:38:07.167282389+00:00,160,1,432669,C,B,64.81,1,26,8058566350242,128,18629,94325776,CLX5
2025-09-24 19:38:07.178418683+00:00,160,1,432669,A,A,64.82,1,26,8058566350259,128,18554,94325808,CLX5
2025-09-24 19:38:07.178419067+00:00,160,1,432669,A,A,64.82,1,26,8058566350260,128,15185,94325809,CLX5
2025-09-24 19:38:07.211378311+00:00,160,1,432669,C,A,64.87,2,26,8058566347355,128,17908,94326015,CLX5
2025-09-24 19:38:07.217050469+00:00,160,1,432669,C,A,65.9,1,26,8058566347325,128,17436,94326072,CLX5
2025-09-24 19:38:07.223436875+00:00,160,1,432669,C,B,64.54,8,26,8058566349679,128,18076,94326074,CLX5
2025-09-24 19:38:07.311692559+00:00,160,1,432669,A,B,64.76,2,26,8058566350576,128,14452,94326398,CLX5
2025-09-24 19:38:08.030604441+00:00,160,1,432669,A,B,64.78,1,26,8058566350923,128,18032,94327028,CLX5
2025-09-24 19:38:09.136779313+00:00,160,1,432669,A,B,64.78,1,26,8058566351014,128,17805,94327260,CLX5
2025-09-24 19:38:10.047636205+00:00,160,1,432669,C,B,64.8,1,26,8058566348834,128,18743,94327301,CLX5
2025-09-24 19:38:12.365403637+00:00,160,1,432669,A,B,64.81,2,26,8058566351337,128,17161,94328104,CLX5
2025-09-24 19:38:12.366614623+00:00,160,1,432669,A,B,64.81,1,26,8058566351375,128,18562,94328211,CLX5
2025-09-24 19:38:12.366755065+00:00,160,1,432669,M,A,64.93,1,26,8058565075241,128,14983,94328253,CLX5
2025-09-24 19:38:12.366989351+00:00,160,1,432669,A,B,64.81,2,26,8058566351394,128,18396,94328290,CLX5
2025-09-24 19:38:12.367197489+00:00,160,1,432669,A,B,64.8,1,26,8058566351406,128,15057,94328352,CLX5
2025-09-24 19:38:12.368734325+00:00,160,1,432669,C,B,64.81,2,26,8058566351337,128,21082,94328481,CLX5
2025-09-24 19:38:12.368951755+00:00,160,1,432669,A,B,64.54,8,26,8058566351450,128,15482,94328514,CLX5
2025-09-24 19:38:12.368958551+00:00,160,1,432669,A,B,64.81,1,26,8058566351452,128,22500,94328517,CLX5
2025-09-24 19:38:12.368960229+00:00,160,1,432669,M,B,64.8,3,26,8058566332677,128,15158,94328520,CLX5
2025-09-24 19:38:12.369038399+00:00,160,1,432669,A,B,64.81,1,26,8058566351466,128,17048,94328547,CLX5
2025-09-24 19:38:12.369157685+00:00,160,1,432669,A,B,64.81,1,26,8058566351469,128,17207,94328560,CLX5
2025-09-24 19:38:12.370767245+00:00,160,1,432669,C,B,64.81,1,26,8058566351375,128,17474,94328691,CLX5
2025-09-24 19:38:12.371298603+00:00,160,1,432669,M,A,64.94,1,26,8058565075241,128,18779,94328734,CLX5
2025-09-24 19:38:12.371396537+00:00,160,1,432669,C,A,64.85,2,26,8058566349656,128,18592,94328748,CLX5
2025-09-24 19:38:12.371409503+00:00,160,1,432669,A,B,64.81,1,26,8058566351515,128,19358,94328751,CLX5
2025-09-24 19:38:12.371521983+00:00,160,1,432669,C,A,64.82,1,26,8058566349634,128,15348,94328757,CLX5
2025-09-24 19:38:12.371584093+00:00,160,1,432669,A,B,64.81,1,26,8058566351518,128,20356,94328760,CLX5
2025-09-24 19:38:12.371589583+00:00,160,1,432669,C,A,64.82,1,26,8058566349633,128,14307,94328761,CLX5
2025-09-24 19:38:12.371857201+00:00,160,1,432669,A,B,64.8,2,26,8058566351526,128,15025,94328802,CLX5
2025-09-24 19:38:12.371884043+00:00,160,1,432669,A,B,64.81,1,26,8058566351528,128,16447,94328806,CLX5
2025-09-24 19:38:12.374223401+00:00,160,1,432669,A,B,64.81,2,26,8058566351589,128,19546,94328964,CLX5
2025-09-24 19:38:12.374339479+00:00,160,1,432669,C,B,64.81,1,26,8058566351469,128,15938,94328975,CLX5
2025-09-24 19:38:12.374628829+00:00,160,1,432669,C,A,64.82,2,26,8058566349201,128,15270,94329010,CLX5
2025-09-24 19:38:12.374759633+00:00,160,1,432669,A,B,64.81,2,26,8058566351602,128,15926,94329025,CLX5
2025-09-24 19:38:12.375157091+00:00,160,1,432669,C,A,64.82,3,26,8058566349469,128,18603,94329090,CLX5
2025-09-24 19:38:12.375439993+00:00,160,1,432669,A,B,64.81,1,26,8058566351637,128,15466,94329117,CLX5
2025-09-24 19:38:12.376569193+00:00,160,1,432669,C,B,64.8,2,26,8058566351526,128,18218,94329170,CLX5
2025-09-24 19:38:12.377896161+00:00,160,1,432669,C,B,64.8,1,26,8058566351406,128,18224,94329252,CLX5
2025-09-24 19:38:12.378617989+00:00,160,1,432669,A,B,64.81,1,26,8058566351692,128,15496,94329266,CLX5
2025-09-24 19:38:12.378822135+00:00,160,1,432669,A,B,64.81,1,26,8058566351694,128,15487,94329270,CLX5
2025-09-24 19:38:12.379294205+00:00,160,1,432669,C,B,64.81,2,26,8058566351602,128,15735,94329303,CLX5
2025-09-24 19:38:12.379792249+00:00,160,1,432669,C,B,64.81,1,26,8058566351528,128,19382,94329318,CLX5
2025-09-24 19:38:12.380461205+00:00,160,1,432669,A,B,64.81,1,26,8058566351721,128,16315,94329347,CLX5
2025-09-24 19:38:12.382231655+00:00,160,1,432669,C,B,64.81,1,26,8058566351694,128,19331,94329447,CLX5
2025-09-24 19:38:12.382249317+00:00,160,1,432669,C,B,64.81,1,26,8058566351692,128,15979,94329449,CLX5
2025-09-24 19:38:12.383233371+00:00,160,1,432669,A,B,64.81,1,26,8058566351754,128,19589,94329493,CLX5
2025-09-24 19:38:12.385135451+00:00,160,1,432669,C,A,64.82,1,26,8058566349454,128,15147,94329565,CLX5
2025-09-24 19:38:12.386047065+00:00,160,1,432669,A,B,64.8,1,26,8058566351793,128,13738,94329608,CLX5
2025-09-24 19:38:12.387319489+00:00,160,1,432669,A,B,64.8,1,26,8058566351813,128,14949,94329659,CLX5
2025-09-24 19:38:12.390828999+00:00,160,1,432669,A,B,64.81,1,26,8058566351892,128,14829,94329891,CLX5
2025-09-24 19:38:12.391574617+00:00,160,1,432669,C,B,64.81,2,26,8058566351589,128,16247,94330008,CLX5
2025-09-24 19:38:12.391593393+00:00,160,1,432669,A,A,64.82,1,26,8058566351921,128,15377,94330011,CLX5
2025-09-24 19:38:12.391640277+00:00,160,1,432669,C,B,64.81,1,26,8058566351637,128,18499,94330014,CLX5
2025-09-24 19:38:12.392557613+00:00,160,1,432669,M,A,64.83,1,26,8058566349378,128,15814,94330078,CLX5
2025-09-24 19:38:12.392828859+00:00,160,1,432669,C,B,64.81,1,26,8058566351466,128,19591,94330095,CLX5
2025-09-24 19:38:12.392946165+00:00,160,1,432669,C,A,64.82,1,26,8058566351921,128,18545,94330102,CLX5
2025-09-24 19:38:12.394442701+00:00,160,1,432669,A,A,64.82,1,26,8058566351988,128,19212,94330210,CLX5
2025-09-24 19:38:12.395323961+00:00,160,1,432669,C,A,64.82,1,26,8058566351988,128,16025,94330253,CLX5
2025-09-24 19:38:12.396497393+00:00,160,1,432669,A,A,64.82,1,26,8058566352042,128,15506,94330322,CLX5
2025-09-24 19:38:12.396826447+00:00,160,1,432669,C,B,64.81,1,26,8058566351892,128,20026,94330329,CLX5
2025-09-24 19:38:12.396836105+00:00,160,1,432669,C,B,64.81,1,26,8058566351754,128,16504,94330331,CLX5
2025-09-24 19:38:12.396838237+00:00,160,1,432669,C,B,64.81,1,26,8058566351721,128,19204,94330332,CLX5
2025-09-24 19:38:12.405304065+00:00,160,1,432669,A,A,64.82,2,26,8058566352156,128,15223,94330623,CLX5
2025-09-24 19:38:12.405388329+00:00,160,1,432669,A,A,64.82,1,26,8058566352157,128,14911,94330626,CLX5
2025-09-24 19:38:12.407697007+00:00,160,1,432669,M,A,64.82,1,26,8058566349378,128,16329,94330689,CLX5
2025-09-24 19:38:12.411420569+00:00,160,1,432669,A,A,64.87,2,26,8058566352248,128,17911,94330850,CLX5
2025-09-24 19:38:12.417080461+00:00,160,1,432669,A,A,65.9,1,26,8058566352282,128,18297,94330917,CLX5
2025-09-24 19:38:12.423876501+00:00,160,1,432669,C,B,64.54,8,26,8058566351450,128,18462,94330945,CLX5
2025-09-24 19:38:12.460299117+00:00,160,1,432669,C,B,64.81,1,26,8058566351518,128,17729,94331358,CLX5
2025-09-24 19:38:12.460509829+00:00,160,1,432669,A,A,64.85,2,26,8058566352446,128,17294,94331371,CLX5
2025-09-24 19:38:12.511417247+00:00,160,1,432669,C,A,64.87,2,26,8058566352248,128,17743,94331585,CLX5
2025-09-24 19:38:12.511566635+00:00,160,1,432669,C,B,64.8,1,26,8058566351813,128,18222,94331586,CLX5
2025-09-24 19:38:12.511575945+00:00,160,1,432669,C,B,64.8,1,26,8058566351793,128,14658,94331587,CLX5
2025-09-24 19:38:12.517081823+00:00,160,1,432669,C,A,65.9,1,26,8058566352282,128,16337,94331608,CLX5
2025-09-24 19:38:12.577599433+00:00,160,1,432669,A,B,64.81,1,26,8058566352744,128,22051,94331861,CLX5
2025-09-24 19:38:13.635439813+00:00,160,1,432669,M,A,64.95,1,26,8058566157942,128,20387,94332712,CLX5
2025-09-24 19:38:13.751709329+00:00,160,1,432669,C,B,64.81,1,26,8058566352744,128,20458,94332730,CLX5
2025-09-24 19:38:14.666214315+00:00,160,1,432669,A,B,64.81,1,26,8058566353168,128,21074,94332790,CLX5
2025-09-24 19:38:14.666227101+00:00,160,1,432669,A,B,64.81,1,26,8058566353170,128,20308,94332795,CLX5
2025-09-24 19:38:14.666227755+00:00,160,1,432669,A,B,64.81,1,26,8058566353171,128,15159,94332796,CLX5
2025-09-24 19:38:14.666235243+00:00,160,1,432669,A,B,64.81,1,26,8058566353172,128,16390,94332797,CLX5
2025-09-24 19:38:14.666488057+00:00,160,1,432669,C,B,64.81,1,26,8058566353168,128,16613,94332809,CLX5
2025-09-24 19:38:14.666533405+00:00,160,1,432669,C,B,64.81,1,26,8058566353172,128,16431,94332811,CLX5
2025-09-24 19:38:14.666549365+00:00,160,1,432669,C,A,64.85,2,26,8058566352446,128,17972,94332819,CLX5
2025-09-24 19:38:14.666555137+00:00,160,1,432669,A,B,64.81,2,26,8058566353182,128,19752,94332824,CLX5
2025-09-24 19:38:14.666701993+00:00,160,1,432669,A,B,64.81,1,26,8058566353185,128,16042,94332833,CLX5
2025-09-24 19:38:14.666938297+00:00,160,1,432669,C,B,64.81,1,26,8058566353185,128,15930,94332845,CLX5
2025-09-24 19:38:14.667572213+00:00,160,1,432669,C,B,64.78,1,26,8058566351014,128,14763,94332867,CLX5
2025-09-24 19:38:14.667586017+00:00,160,1,432669,C,B,64.78,1,26,8058566350923,128,15553,94332868,CLX5
2025-09-24 19:38:14.668260405+00:00,160,1,432669,C,B,64.81,1,26,8058566353170,128,19825,94332878,CLX5
2025-09-24 19:38:14.668672979+00:00,160,1,432669,A,B,64.81,1,26,8058566353195,128,19657,94332882,CLX5
2025-09-24 19:38:14.668900141+00:00,160,1,432669,C,B,64.81,1,26,8058566353195,128,20248,94332887,CLX5
2025-09-24 19:38:14.680599069+00:00,160,1,432669,C,B,64.81,2,26,8058566353182,128,17650,94332893,CLX5
2025-09-24 19:38:14.711341405+00:00,160,1,432669,A,A,64.85,2,26,8058566353200,128,18329,94332897,CLX5
2025-09-24 19:38:15.923278791+00:00,160,1,432669,A,B,64.81,1,26,8058566353210,128,18602,94332923,CLX5
2025-09-24 19:38:16.006131717+00:00,160,1,432669,A,B,64.81,1,26,8058566353212,128,18482,94332926,CLX5
2025-09-24 19:38:16.962788523+00:00,160,1,432669,A,B,64.81,1,26,8058566353228,128,20256,94332960,CLX5
2025-09-24 19:38:16.962972623+00:00,160,1,432669,C,B,64.81,1,26,8058566353228,128,19436,94332961,CLX5
2025-09-24 19:38:19.128824743+00:00,160,1,432669,A,B,64.81,1,26,8058566353233,128,16528,94332981,CLX5
2025-09-24 19:38:19.420167167+00:00,160,1,432669,M,A,64.93,4,26,8058566144143,128,19376,94332986,CLX5
2025-09-24 19:38:19.707811703+00:00,160,1,432669,A,B,64.81,2,26,8058566353245,128,14893,94333005,CLX5
2025-09-24 19:38:19.707855087+00:00,160,1,432669,A,B,64.81,1,26,8058566353247,128,15668,94333010,CLX5
2025-09-24 19:38:19.708128947+00:00,160,1,432669,C,A,64.82,1,26,8058566349075,128,16342,94333020,CLX5
2025-09-24 19:38:19.747278573+00:00,160,1,432669,C,B,64.81,2,26,8058566353245,128,15571,94333110,CLX5
2025-09-24 19:38:19.747433011+00:00,160,1,432669,C,B,64.81,1,26,8058566353233,128,21355,94333111,CLX5
2025-09-24 19:38:21.679247851+00:00,160,1,432669,A,B,64.8,1,26,8058566353307,128,20245,94333169,CLX5
2025-09-24 19:38:22.247245801+00:00,160,1,432669,A,B,64.81,1,26,8058566353311,128,15844,94333174,CLX5
2025-09-24 19:38:24.154426597+00:00,160,1,432669,A,B,64.81,2,26,8058566353346,128,21929,94333249,CLX5
2025-09-24 19:38:25.977352699+00:00,160,1,432669,C,B,64.81,1,26,8058566353311,128,15825,94333299,CLX5
2025-09-24 19:38:25.977374743+00:00,160,1,432669,C,B,64.81,2,26,8058566353346,128,15757,94333300,CLX5
2025-09-24 19:38:25.977577521+00:00,160,1,432669,A,B,64.81,1,26,8058566353362,128,13604,94333304,CLX5
2025-09-24 19:38:27.230545445+00:00,160,1,432669,C,B,64.81,1,26,8058566353362,128,19073,94333363,CLX5
2025-09-24 19:38:27.230629113+00:00,160,1,432669,C,B,64.81,1,26,8058566353171,128,18953,94333366,CLX5
2025-09-24 19:38:27.231183565+00:00,160,1,432669,C,B,64.81,1,26,8058566353247,128,19218,94333399,CLX5
2025-09-24 19:38:30.717125543+00:00,160,1,432669,C,A,65.7,6,26,8058566342860,128,19335,94333469,CLX5
2025-09-24 19:38:32.119449679+00:00,160,1,432669,A,B,64.81,1,26,8058566353428,128,16429,94333496,CLX5
2025-09-24 19:38:32.119525843+00:00,160,1,432669,C,B,64.81,1,26,8058566353210,128,16595,94333498,CLX5
2025-09-24 19:38:32.502616587+00:00,160,1,432669,C,B,64.81,1,26,8058566353428,128,22318,94333520,CLX5
2025-09-24 19:38:33.195397441+00:00,160,1,432669,T,A,64.81,1,26,8058566353440,0,18823,94333555,CLX5
2025-09-24 19:38:33.195397441+00:00,160,1,432669,F,B,64.81,1,26,8058566351394,0,18823,94333555,CLX5
2025-09-24 19:38:33.195397441+00:00,160,1,432669,M,B,64.81,1,26,8058566351394,128,17904,94333556,CLX5
2025-09-24 19:38:33.198598881+00:00,160,1,432669,A,A,64.82,1,26,8058566353445,128,18763,94333566,CLX5
2025-09-24 19:38:33.198821955+00:00,160,1,432669,T,A,64.81,1,26,8058566353452,0,14925,94333577,CLX5
2025-09-24 19:38:33.198821955+00:00,160,1,432669,F,B,64.81,1,26,8058566351394,0,14925,94333577,CLX5
2025-09-24 19:38:33.198821955+00:00,160,1,432669,C,B,64.81,1,26,8058566351394,128,14925,94333577,CLX5
2025-09-24 19:38:33.199126281+00:00,160,1,432669,T,A,64.81,1,26,8058566353455,0,18198,94333585,CLX5
2025-09-24 19:38:33.199126281+00:00,160,1,432669,F,B,64.81,1,26,8058566351452,0,18198,94333585,CLX5
2025-09-24 19:38:33.199126281+00:00,160,1,432669,C,B,64.81,1,26,8058566351452,128,14508,94333586,CLX5
2025-09-24 19:38:33.199129833+00:00,160,1,432669,T,A,64.81,2,26,8058566353456,0,15260,94333588,CLX5
2025-09-24 19:38:33.199129833+00:00,160,1,432669,F,B,64.81,1,26,8058566351515,0,15260,94333588,CLX5
2025-09-24 19:38:33.199129833+00:00,160,1,432669,F,B,64.81,1,26,8058566353212,0,15260,94333588,CLX5
2025-09-24 19:38:33.199129833+00:00,160,1,432669,C,B,64.81,1,26,8058566351515,0,19049,94333589,CLX5
2025-09-24 19:38:33.199129833+00:00,160,1,432669,C,B,64.81,1,26,8058566353212,128,19049,94333589,CLX5
2025-09-24 19:38:33.199390979+00:00,160,1,432669,A,A,64.82,1,26,8058566353460,128,18406,94333598,CLX5
2025-09-24 19:38:33.199565135+00:00,160,1,432669,A,A,64.81,1,26,8058566353464,128,13897,94333618,CLX5
2025-09-24 19:38:33.199625883+00:00,160,1,432669,C,A,64.82,1,26,8058566353445,128,18097,94333646,CLX5
2025-09-24 19:38:33.199740481+00:00,160,1,432669,A,A,64.82,1,26,8058566353471,128,14927,94333655,CLX5
2025-09-24 19:38:33.199796367+00:00,160,1,432669,M,B,63.62,3,26,8058566332677,128,15220,94333662,CLX5
2025-09-24 19:38:33.199969201+00:00,160,1,432669,A,A,64.82,1,26,8058566353472,128,18154,94333663,CLX5
2025-09-24 19:38:33.200424489+00:00,160,1,432669,M,A,64.83,3,26,8058566321460,128,14456,94333697,CLX5
2025-09-24 19:38:33.200552221+00:00,160,1,432669,C,A,64.82,1,26,8058566350260,128,15256,94333700,CLX5
2025-09-24 19:38:33.200554121+00:00,160,1,432669,C,A,64.82,1,26,8058566350259,128,13725,94333701,CLX5
2025-09-24 19:38:33.200609569+00:00,160,1,432669,C,A,64.84,4,26,8058566331622,128,18145,94333704,CLX5
2025-09-24 19:38:33.200714185+00:00,160,1,432669,A,A,64.82,1,26,8058566353485,128,15115,94333706,CLX5
2025-09-24 19:38:33.201994539+00:00,160,1,432669,M,A,64.93,1,26,8058565075241,128,14590,94333717,CLX5
2025-09-24 19:38:33.202493735+00:00,160,1,432669,M,A,65.98,3,26,8058566321460,128,18284,94333720,CLX5
2025-09-24 19:38:33.202516083+00:00,160,1,432669,M,B,64.8,3,26,8058566221991,128,15340,94333721,CLX5
2025-09-24 19:38:33.202652953+00:00,160,1,432669,T,B,64.81,1,26,8058566353492,0,16533,94333723,CLX5
2025-09-24 19:38:33.202652953+00:00,160,1,432669,F,A,64.81,1,26,8058566353464,0,16533,94333723,CLX5
2025-09-24 19:38:33.202652953+00:00,160,1,432669,C,A,64.81,1,26,8058566353464,128,14465,94333724,CLX5
2025-09-24 19:38:33.202690929+00:00,160,1,432669,M,A,64.94,1,26,8058565075241,128,16339,94333727,CLX5
2025-09-24 19:38:33.202983607+00:00,160,1,432669,A,B,64.81,1,26,8058566353496,128,18381,94333733,CLX5
2025-09-24 19:38:33.202983785+00:00,160,1,432669,A,B,64.81,1,26,8058566353497,128,15230,94333735,CLX5
2025-09-24 19:38:33.203015031+00:00,160,1,432669,A,B,64.81,1,26,8058566353499,128,17061,94333739,CLX5
2025-09-24 19:38:33.203208405+00:00,160,1,432669,M,A,64.84,4,26,8058566331102,128,14479,94333750,CLX5
2025-09-24 19:38:33.203302269+00:00,160,1,432669,C,A,64.82,1,26,8058566353485,128,18977,94333752,CLX5
2025-09-24 19:38:33.203309661+00:00,160,1,432669,C,A,64.82,1,26,8058566353460,128,15013,94333754,CLX5
2025-09-24 19:38:33.203312329+00:00,160,1,432669,C,A,64.82,1,26,8058566353472,128,18495,94333756,CLX5
2025-09-24 19:38:33.203337885+00:00,160,1,432669,C,A,64.82,1,26,8058566353471,128,15098,94333757,CLX5
2025-09-24 19:38:33.203530989+00:00,160,1,432669,A,B,64.81,1,26,8058566353501,128,18281,94333761,CLX5
2025-09-24 19:38:33.203647221+00:00,160,1,432669,C,B,64.81,1,26,8058566353499,128,14503,94333766,CLX5
2025-09-24 19:38:33.210040423+00:00,160,1,432669,A,B,64.81,1,26,8058566353518,128,20254,94333832,CLX5
2025-09-24 19:38:33.210062965+00:00,160,1,432669,A,B,64.81,1,26,8058566353520,128,15056,94333835,CLX5
2025-09-24 19:38:33.210196473+00:00,160,1,432669,A,B,64.81,1,26,8058566353523,128,18690,94333841,CLX5
2025-09-24 19:38:33.217091831+00:00,160,1,432669,A,A,65.7,6,26,8058566353536,128,19005,94333882,CLX5
2025-09-24 19:38:33.235745959+00:00,160,1,432669,T,A,64.81,1,26,8058566353538,0,17924,94333886,CLX5
2025-09-24 19:38:33.235745959+00:00,160,1,432669,F,B,64.81,1,26,8058566353496,0,17924,94333886,CLX5
2025-09-24 19:38:33.235745959+00:00,160,1,432669,C,B,64.81,1,26,8058566353496,128,17078,94333887,CLX5
2025-09-24 19:38:33.236011733+00:00,160,1,432669,C,B,64.81,1,26,8058566353518,128,20831,94333888,CLX5
2025-09-24 19:38:33.236021159+00:00,160,1,432669,C,B,64.81,1,26,8058566353520,128,14419,94333890,CLX5
2025-09-24 19:38:33.236036711+00:00,160,1,432669,A,A,64.82,1,26,8058566353540,128,18111,94333892,CLX5
2025-09-24 19:38:33.236037067+00:00,160,1,432669,C,B,64.81,1,26,8058566353523,128,18302,94333896,CLX5
2025-09-24 19:38:33.236214955+00:00,160,1,432669,A,B,64.81,1,26,8058566353543,128,18348,94333900,CLX5
2025-09-24 19:38:33.236468845+00:00,160,1,432669,C,A,64.82,1,26,8058566353540,128,19825,94333908,CLX5
2025-09-24 19:38:33.236803965+00:00,160,1,432669,A,B,64.81,1,26,8058566353548,128,21147,94333919,CLX5
2025-09-24 19:38:33.236952147+00:00,160,1,432669,A,B,64.81,1,26,8058566353549,128,21775,94333921,CLX5
2025-09-24 19:38:33.239463491+00:00,160,1,432669,A,B,64.81,1,26,8058566353552,128,19350,94333930,CLX5
2025-09-24 19:38:33.239908623+00:00,160,1,432669,A,B,64.78,1,26,8058566353553,128,17735,94333932,CLX5
2025-09-24 19:38:33.351254207+00:00,160,1,432669,A,B,64.81,2,26,8058566353579,128,19797,94333999,CLX5
2025-09-24 19:38:33.360190915+00:00,160,1,432669,A,B,64.81,1,26,8058566353587,128,20388,94334025,CLX5
2025-09-24 19:38:34.195416985+00:00,160,1,432669,T,A,64.81,1,26,8058566353600,0,18277,94334058,CLX5
2025-09-24 19:38:34.195416985+00:00,160,1,432669,F,B,64.81,1,26,8058566353497,0,18277,94334058,CLX5
2025-09-24 19:38:34.195416985+00:00,160,1,432669,C,B,64.81,1,26,8058566353497,128,16067,94334059,CLX5
2025-09-24 19:38:34.195692473+00:00,160,1,432669,C,B,64.81,1,26,8058566353552,128,16043,94334061,CLX5
2025-09-24 19:38:34.196473361+00:00,160,1,432669,C,B,64.81,2,26,8058566353579,128,16540,94334076,CLX5
2025-09-24 19:38:34.196647631+00:00,160,1,432669,A,B,64.81,1,26,8058566353602,128,16567,94334079,CLX5
2025-09-24 19:38:34.200854091+00:00,160,1,432669,A,B,64.81,1,26,8058566353605,128,15991,94334095,CLX5
2025-09-24 19:38:34.207440533+00:00,160,1,432669,C,B,64.81,1,26,8058566353605,128,19738,94334099,CLX5
2025-09-24 19:38:35.195558327+00:00,160,1,432669,T,A,64.81,1,26,8058566353626,0,17995,94334151,CLX5
2025-09-24 19:38:35.195558327+00:00,160,1,432669,F,B,64.81,1,26,8058566353501,0,17995,94334151,CLX5
2025-09-24 19:38:35.195558327+00:00,160,1,432669,C,B,64.81,1,26,8058566353501,128,17090,94334152,CLX5
2025-09-24 19:38:35.569818053+00:00,160,1,432669,C,B,64.81,1,26,8058566353602,128,22090,94334160,CLX5
2025-09-24 19:38:35.743697603+00:00,160,1,432669,A,B,64.81,1,26,8058566353630,128,14695,94334180,CLX5
2025-09-24 19:38:35.743849315+00:00,160,1,432669,A,B,64.81,1,26,8058566353632,128,14793,94334184,CLX5
2025-09-24 19:38:35.744026425+00:00,160,1,432669,A,B,64.81,2,26,8058566353635,128,16405,94334188,CLX5
2025-09-24 19:38:35.801627207+00:00,160,1,432669,A,B,64.81,1,26,8058566353639,128,19451,94334209,CLX5
2025-09-24 19:38:36.195739125+00:00,160,1,432669,T,A,64.81,1,26,8058566353643,0,18744,94334222,CLX5
2025-09-24 19:38:36.195739125+00:00,160,1,432669,F,B,64.81,1,26,8058566353543,0,18744,94334222,CLX5
2025-09-24 19:38:36.195739125+00:00,160,1,432669,C,B,64.81,1,26,8058566353543,128,15701,94334223,CLX5
2025-09-24 19:38:36.196020757+00:00,160,1,432669,C,B,64.81,1,26,8058566353639,128,19351,94334224,CLX5
2025-09-24 19:38:36.196171683+00:00,160,1,432669,C,B,64.81,2,26,8058566353635,128,19743,94334225,CLX5
2025-09-24 19:38:36.197186781+00:00,160,1,432669,A,A,64.82,1,26,8058566353645,128,18566,94334247,CLX5
2025-09-24 19:38:36.197193019+00:00,160,1,432669,C,B,64.81,1,26,8058566353549,128,17001,94334248,CLX5
2025-09-24 19:38:36.348765285+00:00,160,1,432669,C,B,64.81,1,26,8058566353632,128,22778,94334257,CLX5
2025-09-24 19:38:38.077382919+00:00,160,1,432669,T,A,64.81,1,26,8058566353649,0,19170,94334272,CLX5
2025-09-24 19:38:38.077382919+00:00,160,1,432669,F,B,64.81,1,26,8058566353548,0,19170,94334272,CLX5
2025-09-24 19:38:38.077382919+00:00,160,1,432669,C,B,64.81,1,26,8058566353548,128,15540,94334273,CLX5
2025-09-24 19:38:38.077664665+00:00,160,1,432669,A,A,64.82,1,26,8058566353650,128,18310,94334276,CLX5
2025-09-24 19:38:38.077851321+00:00,160,1,432669,A,A,64.82,1,26,8058566353653,128,14588,94334282,CLX5
2025-09-24 19:38:38.078032005+00:00,160,1,432669,A,A,64.82,1,26,8058566353654,128,18442,94334286,CLX5
2025-09-24 19:38:38.078195197+00:00,160,1,432669,A,A,64.82,1,26,8058566353655,128,18078,94334288,CLX5
2025-09-24 19:38:39.003218183+00:00,160,1,432669,C,A,64.82,1,26,8058566353655,128,18111,94334294,CLX5
2025-09-24 19:38:39.003414937+00:00,160,1,432669,C,A,64.82,1,26,8058566353654,128,18767,94334295,CLX5
2025-09-24 19:38:39.003575481+00:00,160,1,432669,C,A,64.82,1,26,8058566353653,128,14972,94334299,CLX5
2025-09-24 19:38:39.062478117+00:00,160,1,432669,C,B,64.61,2,26,8058566285281,128,18280,94334301,CLX5
2025-09-24 19:38:42.154785265+00:00,160,1,432669,A,B,64.81,2,26,8058566353724,128,16617,94334477,CLX5
2025-09-24 19:38:42.155109365+00:00,160,1,432669,A,B,64.81,1,26,8058566353727,128,26513,94334483,CLX5
2025-09-24 19:38:42.165873889+00:00,160,1,432669,C,B,64.81,2,26,8058566353724,128,14633,94334501,CLX5
2025-09-24 19:38:42.166040767+00:00,160,1,432669,C,B,64.81,1,26,8058566353727,128,17163,94334503,CLX5
2025-09-24 19:38:42.629858399+00:00,160,1,432669,C,B,64.81,1,26,8058566353630,128,18352,94335475,CLX5
2025-09-24 19:38:43.134077807+00:00,160,1,432669,T,A,64.81,1,26,8058566354358,0,18245,94336091,CLX5
2025-09-24 19:38:43.134077807+00:00,160,1,432669,F,B,64.81,1,26,8058566353587,0,18245,94336091,CLX5
2025-09-24 19:38:43.134077807+00:00,160,1,432669,C,B,64.81,1,26,8058566353587,128,14486,94336092,CLX5
2025-09-24 19:38:43.134395899+00:00,160,1,432669,C,B,64.8,1,26,8058566340602,128,14128,94336096,CLX5
2025-09-24 19:38:43.134482431+00:00,160,1,432669,M,B,64.79,1,26,8058566335785,128,18123,94336100,CLX5
2025-09-24 19:38:43.134639939+00:00,160,1,432669,A,A,64.82,1,26,8058566354360,128,18787,94336101,CLX5
2025-09-24 19:38:43.134720519+00:00,160,1,432669,A,A,64.82,1,26,8058566354361,128,15006,94336102,CLX5
2025-09-24 19:38:43.134720959+00:00,160,1,432669,M,B,63.63,3,26,8058566221991,128,17997,94336103,CLX5
2025-09-24 19:38:43.134807645+00:00,160,1,432669,A,A,64.82,1,26,8058566354362,128,14202,94336104,CLX5
2025-09-24 19:38:43.134843085+00:00,160,1,432669,A,A,64.82,1,26,8058566354363,128,15815,94336105,CLX5
2025-09-24 19:38:43.134846291+00:00,160,1,432669,A,A,64.82,1,26,8058566354364,128,18147,94336106,CLX5
2025-09-24 19:38:43.135823875+00:00,160,1,432669,M,A,64.93,1,26,8058565075241,128,13180,94336130,CLX5
2025-09-24 19:38:43.427868257+00:00,160,1,432669,A,B,64.78,1,26,8058566354399,128,17706,94336197,CLX5
2025-09-24 19:38:43.427890241+00:00,160,1,432669,C,A,64.82,1,26,8058566354362,128,15076,94336198,CLX5
2025-09-24 19:38:43.427903949+00:00,160,1,432669,C,A,64.82,1,26,8058566354361,128,15018,94336199,CLX5
2025-09-24 19:38:43.427905869+00:00,160,1,432669,C,A,64.82,1,26,8058566354360,128,18102,94336200,CLX5
2025-09-24 19:38:43.778913157+00:00,160,1,432669,C,B,64.54,2,26,8058566286168,128,19269,94336246,CLX5
2025-09-24 19:38:44.534113665+00:00,160,1,432669,A,B,64.79,1,26,8058566354444,128,18752,94336292,CLX5
2025-09-24 19:38:44.534127891+00:00,160,1,432669,A,B,64.78,1,26,8058566354445,128,14562,94336293,CLX5
2025-09-24 19:38:45.839322139+00:00,160,1,432669,M,B,64.75,1,26,8058566197138,128,23419,94336313,CLX5
2025-09-24 19:38:46.071967087+00:00,160,1,432669,A,B,64.8,1,26,8058566354454,128,21489,94336324,CLX5
2025-09-24 19:38:46.280088519+00:00,160,1,432669,C,B,64.8,1,26,8058566353307,128,22621,94336328,CLX5
2025-09-24 19:38:46.725897883+00:00,160,1,432669,C,B,64.5,2,26,8058566285914,128,21920,94336342,CLX5
2025-09-24 19:38:52.277193239+00:00,160,1,432669,C,B,64.79,1,26,8058566354444,128,26795,94336411,CLX5
2025-09-24 19:38:52.277388593+00:00,160,1,432669,T,A,64.8,1,26,8058566354481,0,21051,94336412,CLX5
2025-09-24 19:38:52.277388593+00:00,160,1,432669,F,B,64.8,1,26,8058566248704,0,21051,94336412,CLX5
2025-09-24 19:38:52.277388593+00:00,160,1,432669,C,B,64.8,1,26,8058566248704,128,18673,94336413,CLX5
2025-09-24 19:38:52.277678811+00:00,160,1,432669,A,A,64.82,1,26,8058566354484,128,20606,94336419,CLX5
2025-09-24 19:38:52.277688561+00:00,160,1,432669,A,A,64.81,1,26,8058566354487,128,18505,94336421,CLX5
2025-09-24 19:38:52.277718931+00:00,160,1,432669,A,A,64.81,1,26,8058566354488,128,18250,94336424,CLX5
2025-09-24 19:38:52.278002427+00:00,160,1,432669,A,A,64.82,1,26,8058566354489,128,19478,94336427,CLX5
2025-09-24 19:38:52.278045509+00:00,160,1,432669,C,A,64.81,1,26,8058566354488,128,18344,94336430,CLX5
2025-09-24 19:38:52.278288341+00:00,160,1,432669,M,B,64.78,1,26,8058566335785,128,21370,94336441,CLX5
2025-09-24 19:38:52.278481503+00:00,160,1,432669,M,A,64.83,3,26,8058566321460,128,18001,94336445,CLX5
2025-09-24 19:38:52.278659787+00:00,160,1,432669,C,A,64.82,1,26,8058566354364,128,21005,94336450,CLX5
2025-09-24 19:38:52.278820387+00:00,160,1,432669,M,A,65.97,3,26,8058566331102,128,18461,94336455,CLX5
2025-09-24 19:38:52.278859209+00:00,160,1,432669,A,A,64.81,1,26,8058566354493,128,20993,94336458,CLX5
2025-09-24 19:38:52.279032675+00:00,160,1,432669,T,N,64.81,2,26,0,0,19815,94336461,CLX5
2025-09-24 19:38:52.279032675+00:00,160,1,432669,F,N,64.81,1,26,8058566354487,0,19815,94336461,CLX5
2025-09-24 19:38:52.279032675+00:00,160,1,432669,F,N,64.81,1,26,8058566354493,0,19815,94336461,CLX5
2025-09-24 19:38:52.279032675+00:00,160,1,432669,C,A,64.81,1,26,8058566354487,0,19791,94336462,CLX5
2025-09-24 19:38:52.279032675+00:00,160,1,432669,C,A,64.81,1,26,8058566354493,128,19791,94336462,CLX5
2025-09-24 19:38:52.279041793+00:00,160,1,432669,A,A,64.82,1,26,8058566354495,128,17140,94336465,CLX5
2025-09-24 19:38:52.279336385+00:00,160,1,432669,A,B,64.8,1,26,8058566354499,128,20515,94336472,CLX5
2025-09-24 19:38:52.279416599+00:00,160,1,432669,C,B,64.8,1,26,8058566354499,128,19860,94336482,CLX5
2025-09-24 19:38:52.279480243+00:00,160,1,432669,A,A,64.82,3,26,8058566354507,128,19104,94336493,CLX5
2025-09-24 19:38:52.279493491+00:00,160,1,432669,A,A,64.82,1,26,8058566354509,128,17102,94336495,CLX5
2025-09-24 19:38:52.279650637+00:00,160,1,432669,A,A,64.82,1,26,8058566354514,128,17468,94336504,CLX5
2025-09-24 19:38:52.279684137+00:00,160,1,432669,M,A,64.84,4,26,8058566342145,128,16928,94336506,CLX5
2025-09-24 19:38:52.279846467+00:00,160,1,432669,C,A,64.82,1,26,8058566354489,128,18392,94336509,CLX5
2025-09-24 19:38:52.280011311+00:00,160,1,432669,M,A,64.82,1,26,8058566354507,128,17647,94336515,CLX5
2025-09-24 19:38:52.284456971+00:00,160,1,432669,A,B,64.8,1,26,8058566354571,128,17646,94336816,CLX5
2025-09-24 19:38:52.284745631+00:00,160,1,432669,A,B,64.8,1,26,8058566354574,128,14811,94336821,CLX5
2025-09-24 19:38:52.285114637+00:00,160,1,432669,A,B,64.8,1,26,8058566354582,128,14720,94336843,CLX5
2025-09-24 19:38:52.294043877+00:00,160,1,432669,A,A,65.96,4,26,8058566354590,128,18161,94336863,CLX5
2025-09-24 19:38:52.328890319+00:00,160,1,432669,A,A,64.82,1,26,8058566354651,128,18300,94336988,CLX5
2025-09-24 19:38:52.830298165+00:00,160,1,432669,C,A,64.82,1,26,8058566354514,128,18723,94337152,CLX5
2025-09-24 19:38:52.830479193+00:00,160,1,432669,C,A,64.82,1,26,8058566354509,128,18283,94337153,CLX5
2025-09-24 19:38:53.383362845+00:00,160,1,432669,A,B,64.79,1,26,8058566354883,128,18543,94337562,CLX5
2025-09-24 19:38:53.383396733+00:00,160,1,432669,C,A,64.82,1,26,8058566354495,128,15047,94337563,CLX5
2025-09-24 19:38:54.706996439+00:00,160,1,432669,A,B,64.81,1,26,8058566355165,128,17764,94338308,CLX5
2025-09-24 19:38:54.707255167+00:00,160,1,432669,A,B,64.8,1,26,8058566355166,128,18796,94338312,CLX5
2025-09-24 19:38:54.707299037+00:00,160,1,432669,A,A,64.82,1,26,8058566355169,128,14917,94338317,CLX5
2025-09-24 19:38:54.707408223+00:00,160,1,432669,M,A,64.82,1,26,8058566239191,128,15565,94338321,CLX5
2025-09-24 19:38:54.707508003+00:00,160,1,432669,C,A,64.82,1,26,8058566355169,128,18008,94338323,CLX5
2025-09-24 19:38:54.707538855+00:00,160,1,432669,M,A,65.98,4,26,8058566321460,128,15186,94338324,CLX5
2025-09-24 19:38:54.707566059+00:00,160,1,432669,M,B,64.8,3,26,8058566332677,128,14664,94338325,CLX5
2025-09-24 19:38:54.753415153+00:00,160,1,432669,T,A,64.81,1,26,8058566355204,0,18036,94338431,CLX5
2025-09-24 19:38:54.753415153+00:00,160,1,432669,F,B,64.81,1,26,8058566355165,0,18036,94338431,CLX5
2025-09-24 19:38:54.753415153+00:00,160,1,432669,C,B,64.81,1,26,8058566355165,128,14622,94338432,CLX5
2025-09-24 19:38:54.753728675+00:00,160,1,432669,M,A,65.14,1,26,8058566239191,128,14969,94338436,CLX5
2025-09-24 19:38:54.753876067+00:00,160,1,432669,A,A,64.82,1,26,8058566355205,128,13737,94338441,CLX5
2025-09-24 19:38:54.753910875+00:00,160,1,432669,A,A,64.82,1,26,8058566355206,128,18331,94338446,CLX5
2025-09-24 19:38:54.754045193+00:00,160,1,432669,A,A,64.82,1,26,8058566355207,128,15091,94338447,CLX5
2025-09-24 19:38:54.761194919+00:00,160,1,432669,A,B,64.81,1,26,8058566355224,128,17706,94338507,CLX5
2025-09-24 19:38:54.761283139+00:00,160,1,432669,C,A,64.82,1,26,8058566355207,128,15300,94338511,CLX5
2025-09-24 19:38:54.761289685+00:00,160,1,432669,C,A,64.82,1,26,8058566355206,128,17373,94338512,CLX5
2025-09-24 19:38:54.761377849+00:00,160,1,432669,M,A,64.94,1,26,8058565075241,128,14525,94338513,CLX5
2025-09-24 19:38:54.761436751+00:00,160,1,432669,C,A,64.82,1,26,8058566353645,128,14525,94338513,CLX5
2025-09-24 19:38:54.761552349+00:00,160,1,432669,C,A,64.82,1,26,8058566355205,128,17268,94338519,CLX5
2025-09-24 19:38:54.764881885+00:00,160,1,432669,A,B,64.81,1,26,8058566355227,128,18034,94338520,CLX5
2025-09-24 19:38:54.764882063+00:00,160,1,432669,A,B,64.81,1,26,8058566355228,128,16074,94338522,CLX5
2025-09-24 19:38:54.765046575+00:00,160,1,432669,A,B,64.81,1,26,8058566355229,128,17409,94338526,CLX5
2025-09-24 19:38:54.859504029+00:00,160,1,432669,M,A,64.83,1,26,8058566354507,128,19214,94338700,CLX5
2025-09-24 19:38:55.065338839+00:00,160,1,432669,M,B,64.79,1,26,8058566197138,128,18025,94338801,CLX5
2025-09-24 19:38:57.428337491+00:00,160,1,432669,M,A,64.93,3,26,8058566144143,128,17997,94338911,CLX5
2025-09-24 19:38:57.785213379+00:00,160,1,432669,A,B,64.81,1,26,8058566355494,128,21275,94339173,CLX5
2025-09-24 19:38:57.816289109+00:00,160,1,432669,A,B,64.81,1,26,8058566355579,128,19769,94339386,CLX5
2025-09-24 19:38:57.816289571+00:00,160,1,432669,C,A,64.85,2,26,8058566353200,128,14480,94339388,CLX5
2025-09-24 19:38:57.816290491+00:00,160,1,432669,C,A,64.82,1,26,8058566354484,128,15342,94339394,CLX5
2025-09-24 19:38:57.816294159+00:00,160,1,432669,A,B,64.81,2,26,8058566355583,128,15220,94339396,CLX5
2025-09-24 19:38:57.816308441+00:00,160,1,432669,A,B,64.81,1,26,8058566355585,128,14569,94339401,CLX5
2025-09-24 19:38:57.816422503+00:00,160,1,432669,C,A,64.82,1,26,8058566353650,128,18207,94339408,CLX5
2025-09-24 19:38:57.817039297+00:00,160,1,432669,C,B,64.81,1,26,8058566355585,128,15588,94339426,CLX5
2025-09-24 19:38:57.817516721+00:00,160,1,432669,A,A,65.9,1,26,8058566355594,128,14622,94339451,CLX5
2025-09-24 19:38:57.817521215+00:00,160,1,432669,C,B,64.81,2,26,8058566355583,128,14622,94339451,CLX5
2025-09-24 19:38:57.904363033+00:00,160,1,432669,A,A,64.85,2,26,8058566355753,128,18094,94339935,CLX5
2025-09-24 19:38:57.917267919+00:00,160,1,432669,C,A,65.9,1,26,8058566355594,128,17463,94339986,CLX5
2025-09-24 19:38:57.917397395+00:00,160,1,432669,C,B,64.8,1,26,8058566354582,128,18320,94339988,CLX5
2025-09-24 19:38:57.917562469+00:00,160,1,432669,C,B,64.8,1,26,8058566354574,128,18831,94339989,CLX5
2025-09-24 19:38:58.709233761+00:00,160,1,432669,C,B,64.81,1,26,8058566355579,128,20953,94340397,CLX5
2025-09-24 19:38:58.709444261+00:00,160,1,432669,C,B,64.8,1,26,8058566354571,128,17453,94340398,CLX5
2025-09-24 19:38:58.844345305+00:00,160,1,432669,C,B,64.81,1,26,8058566355494,128,21136,94340411,CLX5
2025-09-24 19:39:00.174667933+00:00,160,1,432669,T,A,64.81,1,26,8058566356117,0,18128,94340602,CLX5
2025-09-24 19:39:00.174667933+00:00,160,1,432669,F,B,64.81,1,26,8058566355224,0,18128,94340602,CLX5
2025-09-24 19:39:00.174667933+00:00,160,1,432669,C,B,64.81,1,26,8058566355224,128,18109,94340603,CLX5
2025-09-24 19:39:00.174955921+00:00,160,1,432669,C,B,64.81,1,26,8058566355228,128,18785,94340605,CLX5
2025-09-24 19:39:00.174956841+00:00,160,1,432669,A,A,64.82,1,26,8058566356118,128,15085,94340607,CLX5
2025-09-24 19:39:00.175128443+00:00,160,1,432669,A,B,64.81,1,26,8058566356120,128,13710,94340612,CLX5
2025-09-24 19:39:00.604934217+00:00,160,1,432669,A,B,64.81,1,26,8058566356126,128,34647,94340645,CLX5
2025-09-24 19:39:00.605148613+00:00,160,1,432669,A,B,64.81,1,26,8058566356127,128,25417,94340646,CLX5
2025-09-24 19:39:01.304591901+00:00,160,1,432669,A,B,64.81,1,26,8058566356130,128,19934,94340650,CLX5
2025-09-24 19:39:02.048908067+00:00,160,1,432669,C,A,65.05,1,26,8058566020533,128,20954,94340652,CLX5
2025-09-24 19:39:03.685146925+00:00,160,1,432669,C,A,65.13,1,26,8058566333583,128,19308,94340666,CLX5
2025-09-24 19:39:03.747565637+00:00,160,1,432669,A,A,65.09,1,26,8058566356134,128,18135,94340667,CLX5
2025-09-24 19:39:04.008615503+00:00,160,1,432669,C,A,64.97,1,26,8058566349514,128,18206,94340692,CLX5
2025-09-24 19:39:04.371632455+00:00,160,1,432669,A,B,64.56,6,26,8058566356144,128,17886,94340703,CLX5
2025-09-24 19:39:04.570714809+00:00,160,1,432669,A,B,64.62,15,26,8058566356146,128,17435,94340706,CLX5
2025-09-24 19:39:04.594193779+00:00,160,1,432669,C,A,65.14,1,26,8058566326983,128,18235,94340707,CLX5
2025-09-24 19:39:04.688000399+00:00,160,1,432669,A,A,65.09,1,26,8058566356147,128,18327,94340708,CLX5
2025-09-24 19:39:05.915687085+00:00,160,1,432669,A,B,64.61,15,26,8058566356153,128,18291,94340721,CLX5
2025-09-24 19:39:06.066863731+00:00,160,1,432669,A,B,64.81,1,26,8058566356157,128,16303,94340750,CLX5
2025-09-24 19:39:06.067082255+00:00,160,1,432669,A,B,64.81,2,26,8058566356161,128,15540,94340759,CLX5
2025-09-24 19:39:06.067107925+00:00,160,1,432669,A,B,64.81,1,26,8058566356162,128,19106,94340763,CLX5
2025-09-24 19:39:06.067937539+00:00,160,1,432669,C,A,64.82,2,26,8058566352156,128,15679,94340806,CLX5
2025-09-24 19:39:06.067937867+00:00,160,1,432669,C,A,64.82,1,26,8058566352157,128,18675,94340807,CLX5
2025-09-24 19:39:06.068265921+00:00,160,1,432669,A,B,64.81,1,26,8058566356181,128,19726,94340822,CLX5
2025-09-24 19:39:06.068267399+00:00,160,1,432669,C,A,64.82,1,26,8058566356118,128,16646,94340828,CLX5
2025-09-24 19:39:06.068267649+00:00,160,1,432669,C,A,64.85,2,26,8058566355753,128,14849,94340830,CLX5
2025-09-24 19:39:06.068271239+00:00,160,1,432669,A,B,64.81,1,26,8058566356185,128,19487,94340832,CLX5
2025-09-24 19:39:06.068430015+00:00,160,1,432669,C,B,64.78,1,26,8058566353553,128,14655,94340849,CLX5
2025-09-24 19:39:06.069162235+00:00,160,1,432669,C,B,64.81,1,26,8058566356185,128,15651,94340879,CLX5
2025-09-24 19:39:06.069559791+00:00,160,1,432669,C,B,64.78,1,26,8058566354445,128,14600,94340884,CLX5
2025-09-24 19:39:06.069740973+00:00,160,1,432669,A,B,64.81,1,26,8058566356197,128,15821,94340886,CLX5
2025-09-24 19:39:06.070925293+00:00,160,1,432669,C,B,64.81,1,26,8058566356197,128,14570,94340933,CLX5
2025-09-24 19:39:06.071285623+00:00,160,1,432669,M,B,64.81,1,26,8058566221991,128,19501,94340946,CLX5
2025-09-24 19:39:06.071396133+00:00,160,1,432669,C,B,64.81,1,26,8058566356162,128,16418,94340947,CLX5
2025-09-24 19:39:06.071662789+00:00,160,1,432669,C,B,64.81,1,26,8058566356157,128,16216,94340953,CLX5
2025-09-24 19:39:06.071860501+00:00,160,1,432669,A,B,64.81,1,26,8058566356221,128,19396,94340972,CLX5
2025-09-24 19:39:06.079242269+00:00,160,1,432669,C,B,64.81,1,26,8058566356221,128,19011,94341024,CLX5
2025-09-24 19:39:06.079381961+00:00,160,1,432669,C,B,64.81,1,26,8058566356181,128,18119,94341025,CLX5
2025-09-24 19:39:06.079383249+00:00,160,1,432669,A,B,64.81,1,26,8058566356243,128,16274,94341026,CLX5
2025-09-24 19:39:06.101170601+00:00,160,1,432669,A,A,64.85,2,26,8058566356249,128,17888,94341041,CLX5
2025-09-24 19:39:06.240037883+00:00,160,1,432669,A,B,64.78,1,26,8058566356258,128,20245,94341063,CLX5
2025-09-24 19:39:09.975824407+00:00,160,1,432669,C,B,64.79,1,26,8058566354883,128,19151,94341131,CLX5
2025-09-24 19:39:10.024304015+00:00,160,1,432669,A,A,64.82,1,26,8058566356287,128,18470,94341132,CLX5
2025-09-24 19:39:10.835454637+00:00,160,1,432669,T,A,64.81,1,26,8058566356290,0,21451,94341154,CLX5
2025-09-24 19:39:10.835454637+00:00,160,1,432669,F,B,64.81,1,26,8058566355227,0,21451,94341154,CLX5
2025-09-24 19:39:10.835454637+00:00,160,1,432669,C,B,64.81,1,26,8058566355227,128,17523,94341155,CLX5
2025-09-24 19:39:10.835745505+00:00,160,1,432669,A,A,64.82,1,26,8058566356291,128,18903,94341156,CLX5
2025-09-24 19:39:10.835776845+00:00,160,1,432669,C,B,64.81,1,26,8058566356243,128,16500,94341163,CLX5
2025-09-24 19:39:10.836437689+00:00,160,1,432669,M,B,63.63,4,26,8058566221991,128,14881,94341171,CLX5
2025-09-24 19:39:11.033763417+00:00,160,1,432669,A,B,64.81,1,26,8058566356300,128,19245,94341182,CLX5
2025-09-24 19:39:11.274582367+00:00,160,1,432669,T,A,64.81,1,26,8058566356310,0,17811,94341214,CLX5
2025-09-24 19:39:11.274582367+00:00,160,1,432669,F,B,64.81,1,26,8058566355229,0,17811,94341214,CLX5
2025-09-24 19:39:11.274582367+00:00,160,1,432669,C,B,64.81,1,26,8058566355229,128,17014,94341215,CLX5
2025-09-24 19:39:11.845570727+00:00,160,1,432669,T,A,64.81,1,26,8058566356312,0,17919,94341224,CLX5
2025-09-24 19:39:11.845570727+00:00,160,1,432669,F,B,64.81,1,26,8058566356120,0,17919,94341224,CLX5
2025-09-24 19:39:11.845570727+00:00,160,1,432669,C,B,64.81,1,26,8058566356120,128,16367,94341225,CLX5
2025-09-24 19:39:11.845861381+00:00,160,1,432669,C,B,64.81,1,26,8058566356300,128,16767,94341227,CLX5
2025-09-24 19:39:12.325905293+00:00,160,1,432669,A,B,64.81,1,26,8058566356316,128,16539,94341241,CLX5
2025-09-24 19:39:12.326218239+00:00,160,1,432669,A,B,64.81,1,26,8058566356317,128,16249,94341243,CLX5
2025-09-24 19:39:12.416699009+00:00,160,1,432669,T,A,64.81,1,26,8058566356322,0,17735,94341256,CLX5
2025-09-24 19:39:12.416699009+00:00,160,1,432669,F,B,64.81,1,26,8058566356126,0,17735,94341256,CLX5
2025-09-24 19:39:12.416699009+00:00,160,1,432669,C,B,64.81,1,26,8058566356126,128,16091,94341257,CLX5
2025-09-24 19:39:12.987785937+00:00,160,1,432669,T,A,64.81,1,26,8058566356325,0,17673,94341266,CLX5
2025-09-24 19:39:12.987785937+00:00,160,1,432669,F,B,64.81,1,26,8058566356127,0,17673,94341266,CLX5
2025-09-24 19:39:12.987785937+00:00,160,1,432669,C,B,64.81,1,26,8058566356127,128,17442,94341267,CLX5
2025-09-24 19:39:13.558886285+00:00,160,1,432669,T,A,64.81,1,26,8058566356328,0,18144,94341277,CLX5
2025-09-24 19:39:13.558886285+00:00,160,1,432669,F,B,64.81,1,26,8058566356130,0,18144,94341277,CLX5
2025-09-24 19:39:13.558886285+00:00,160,1,432669,C,B,64.81,1,26,8058566356130,128,17720,94341278,CLX5
2025-09-24 19:39:14.129986207+00:00,160,1,432669,T,A,64.81,1,26,8058566356337,0,23727,94341307,CLX5
2025-09-24 19:39:14.129986207+00:00,160,1,432669,F,B,64.81,1,26,8058566356161,0,23727,94341307,CLX5
2025-09-24 19:39:14.129986207+00:00,160,1,432669,M,B,64.81,1,26,8058566356161,128,17986,94341308,CLX5
2025-09-24 19:39:14.355106413+00:00,160,1,432669,A,B,64.81,1,26,8058566356356,128,22285,94341385,CLX5
2025-09-24 19:39:14.355106625+00:00,160,1,432669,A,B,64.81,1,26,8058566356357,128,17007,94341386,CLX5
2025-09-24 19:39:14.509431279+00:00,160,1,432669,A,B,64.81,1,26,8058566356397,128,20418,94341520,CLX5
2025-09-24 19:39:14.509447059+00:00,160,1,432669,A,B,64.81,1,26,8058566356398,128,16737,94341522,CLX5
2025-09-24 19:39:14.510592481+00:00,160,1,432669,C,B,64.81,1,26,8058566356398,128,18346,94341643,CLX5
2025-09-24 19:39:14.512986347+00:00,160,1,432669,A,B,64.81,1,26,8058566356476,128,17592,94341761,CLX5
2025-09-24 19:39:14.513058477+00:00,160,1,432669,A,B,64.81,1,26,8058566356480,128,19296,94341768,CLX5
2025-09-24 19:39:14.513063375+00:00,160,1,432669,C,B,64.78,1,26,8058566356258,128,17908,94341770,CLX5
2025-09-24 19:39:14.513480533+00:00,160,1,432669,A,B,64.81,1,26,8058566356492,128,15679,94341799,CLX5
2025-09-24 19:39:14.514953395+00:00,160,1,432669,C,B,64.78,1,26,8058566354399,128,15331,94341854,CLX5
2025-09-24 19:39:14.515002757+00:00,160,1,432669,C,B,64.81,1,26,8058566356492,128,16487,94341855,CLX5
2025-09-24 19:39:14.602477111+00:00,160,1,432669,M,B,64.81,1,26,8058566221991,128,19095,94342425,CLX5
2025-09-24 19:39:14.641163211+00:00,160,1,432669,C,A,64.82,1,26,8058566349211,128,14952,94342504,CLX5
2025-09-24 19:39:14.641180511+00:00,160,1,432669,C,A,64.85,2,26,8058566356249,128,14008,94342513,CLX5
2025-09-24 19:39:14.641183275+00:00,160,1,432669,A,B,64.81,2,26,8058566356716,128,18356,94342518,CLX5
2025-09-24 19:39:14.641190897+00:00,160,1,432669,C,A,64.82,1,26,8058566356291,128,15404,94342519,CLX5
2025-09-24 19:39:14.641191069+00:00,160,1,432669,A,B,64.81,1,26,8058566356717,128,16018,94342520,CLX5
2025-09-24 19:39:14.641191493+00:00,160,1,432669,C,A,64.82,1,26,8058566349632,128,18907,94342521,CLX5
2025-09-24 19:39:14.641233481+00:00,160,1,432669,C,A,64.82,1,26,8058566349209,128,15101,94342528,CLX5
2025-09-24 19:39:14.641607961+00:00,160,1,432669,C,A,64.82,1,26,8058566352042,128,16052,94342535,CLX5
2025-09-24 19:39:14.642026331+00:00,160,1,432669,A,A,64.82,1,26,8058566356729,128,15853,94342568,CLX5
2025-09-24 19:39:14.642126107+00:00,160,1,432669,M,B,64.81,1,26,8058566349770,128,15820,94342569,CLX5
2025-09-24 19:39:14.643725973+00:00,160,1,432669,C,B,64.81,1,26,8058566356717,128,19559,94342602,CLX5
2025-09-24 19:39:14.643727125+00:00,160,1,432669,A,A,64.82,1,26,8058566356740,128,14334,94342603,CLX5
2025-09-24 19:39:14.643730101+00:00,160,1,432669,A,B,64.81,1,26,8058566356741,128,15947,94342604,CLX5
2025-09-24 19:39:14.655115697+00:00,160,1,432669,C,A,64.82,1,26,8058566356740,128,18485,94342621,CLX5
2025-09-24 19:39:14.655131037+00:00,160,1,432669,C,B,64.81,1,26,8058566356741,128,15392,94342622,CLX5
2025-09-24 19:39:14.701097919+00:00,160,1,432669,T,A,64.81,1,26,8058566356773,0,18652,94342662,CLX5
2025-09-24 19:39:14.701097919+00:00,160,1,432669,F,B,64.81,1,26,8058566356161,0,18652,94342662,CLX5
2025-09-24 19:39:14.701097919+00:00,160,1,432669,C,B,64.81,1,26,8058566356161,128,15676,94342663,CLX5
2025-09-24 19:39:14.701408773+00:00,160,1,432669,A,A,64.82,1,26,8058566356776,128,18694,94342666,CLX5
2025-09-24 19:39:14.711544697+00:00,160,1,432669,A,B,64.81,1,26,8058566356779,128,18957,94342680,CLX5
2025-09-24 19:39:14.711653845+00:00,160,1,432669,A,A,64.87,2,26,8058566356780,128,18218,94342681,CLX5
2025-09-24 19:39:14.711691377+00:00,160,1,432669,C,A,64.82,1,26,8058566356776,128,15024,94342682,CLX5
2025-09-24 19:39:14.717345893+00:00,160,1,432669,A,A,65.9,1,26,8058566356783,128,18599,94342692,CLX5
2025-09-24 19:39:14.811978423+00:00,160,1,432669,A,B,64.77,2,26,8058566356820,128,18408,94342759,CLX5
2025-09-24 19:39:15.840045003+00:00,160,1,432669,A,B,64.78,1,26,8058566356890,128,21034,94342903,CLX5
2025-09-24 19:39:16.059468283+00:00,160,1,432669,C,A,64.82,1,26,8058566356729,128,15564,94342915,CLX5
2025-09-24 19:39:16.060415089+00:00,160,1,432669,C,B,64.78,1,26,8058566356890,128,15100,94342925,CLX5
2025-09-24 19:39:19.263873583+00:00,160,1,432669,M,B,64.65,6,26,8058566356144,128,18366,94343099,CLX5
2025-09-24 19:39:19.885943779+00:00,160,1,432669,A,B,64.54,8,26,8058566356965,128,13179,94343105,CLX5
2025-09-24 19:39:19.886399105+00:00,160,1,432669,A,A,64.82,1,26,8058566356968,128,15782,94343111,CLX5
2025-09-24 19:39:19.886429517+00:00,160,1,432669,A,A,64.82,1,26,8058566356969,128,15946,94343113,CLX5
2025-09-24 19:39:19.886554617+00:00,160,1,432669,C,A,64.82,1,26,8058566356968,128,15267,94343166,CLX5
2025-09-24 19:39:19.886847099+00:00,160,1,432669,A,B,64.8,2,26,8058566356976,128,18117,94343173,CLX5
2025-09-24 19:39:19.886852281+00:00,160,1,432669,A,B,64.81,1,26,8058566356977,128,15815,94343175,CLX5
2025-09-24 19:39:19.886854433+00:00,160,1,432669,C,B,64.77,2,26,8058566356820,128,16781,94343176,CLX5
2025-09-24 19:39:19.886895077+00:00,160,1,432669,A,B,64.81,1,26,8058566356978,128,15588,94343177,CLX5
2025-09-24 19:39:19.887675215+00:00,160,1,432669,M,B,64.81,1,26,8058566319851,128,16477,94343190,CLX5
2025-09-24 19:39:19.888232605+00:00,160,1,432669,C,B,64.8,2,26,8058566356976,128,18415,94343198,CLX5
2025-09-24 19:39:19.888246851+00:00,160,1,432669,C,B,64.81,1,26,8058566356978,128,14862,94343200,CLX5
2025-09-24 19:39:19.888513239+00:00,160,1,432669,C,B,64.81,1,26,8058566356977,128,15641,94343207,CLX5
2025-09-24 19:39:19.924345807+00:00,160,1,432669,C,B,64.54,8,26,8058566356965,128,18258,94343211,CLX5
2025-09-24 19:39:20.011620319+00:00,160,1,432669,A,B,64.77,2,26,8058566356984,128,18686,94343213,CLX5
2025-09-24 19:39:20.023497473+00:00,160,1,432669,A,A,64.83,1,26,8058566356987,128,18618,94343216,CLX5
2025-09-24 19:39:20.919030281+00:00,160,1,432669,A,B,64.8,1,26,8058566357018,128,18543,94343259,CLX5
2025-09-24 19:39:22.335816213+00:00,160,1,432669,A,B,64.81,1,26,8058566357038,128,20137,94343298,CLX5
2025-09-24 19:39:22.336037811+00:00,160,1,432669,C,A,64.82,1,26,8058566356969,128,15656,94343301,CLX5
2025-09-24 19:39:26.273762983+00:00,160,1,432669,A,A,64.85,2,26,8058566357121,128,25159,94343517,CLX5
2025-09-24 19:39:26.273809079+00:00,160,1,432669,A,A,64.82,1,26,8058566357126,128,18523,94343527,CLX5
2025-09-24 19:39:26.274004873+00:00,160,1,432669,A,A,64.82,1,26,8058566357127,128,21331,94343529,CLX5
2025-09-24 19:39:26.274298965+00:00,160,1,432669,C,A,64.82,1,26,8058566357127,128,25132,94343553,CLX5
2025-09-24 19:39:26.311944953+00:00,160,1,432669,C,A,64.87,2,26,8058566356780,128,19935,94343559,CLX5
2025-09-24 19:39:26.317539681+00:00,160,1,432669,C,A,65.9,1,26,8058566356783,128,20718,94343560,CLX5
2025-09-24 19:39:26.388207637+00:00,160,1,432669,A,A,64.82,1,26,8058566357134,128,14962,94343578,CLX5
2025-09-24 19:39:26.389543957+00:00,160,1,432669,C,A,64.82,1,26,8058566357134,128,18360,94343587,CLX5
2025-09-24 19:39:26.540322123+00:00,160,1,432669,A,B,64.78,1,26,8058566357138,128,19052,94343598,CLX5
2025-09-24 19:39:29.466379947+00:00,160,1,432669,T,N,64.82,8,26,0,0,18895,94343689,CLX5
2025-09-24 19:39:29.466379947+00:00,160,1,432669,F,N,64.82,1,26,8058566346598,0,18895,94343689,CLX5
2025-09-24 19:39:29.466379947+00:00,160,1,432669,F,N,64.82,1,26,8058566346946,0,18895,94343689,CLX5
2025-09-24 19:39:29.466379947+00:00,160,1,432669,F,N,64.82,2,26,8058566349051,0,18895,94343689,CLX5
2025-09-24 19:39:29.466379947+00:00,160,1,432669,F,N,64.82,2,26,8058566349090,0,18895,94343689,CLX5
2025-09-24 19:39:29.466379947+00:00,160,1,432669,F,N,64.82,2,26,8058566349748,0,18895,94343689,CLX5
2025-09-24 19:39:29.466379947+00:00,160,1,432669,C,A,64.82,1,26,8058566346598,0,16276,94343690,CLX5
2025-09-24 19:39:29.466379947+00:00,160,1,432669,C,A,64.82,1,26,8058566346946,0,16276,94343690,CLX5
2025-09-24 19:39:29.466379947+00:00,160,1,432669,C,A,64.82,2,26,8058566349051,0,16276,94343690,CLX5
2025-09-24 19:39:29.466379947+00:00,160,1,432669,C,A,64.82,2,26,8058566349090,0,16276,94343690,CLX5
2025-09-24 19:39:29.466379947+00:00,160,1,432669,M,A,64.82,1,26,8058566349748,128,16276,94343690,CLX5
2025-09-24 19:39:29.466886401+00:00,160,1,432669,C,A,64.82,1,26,8058566357126,128,20295,94343700,CLX5
2025-09-24 19:39:29.466999503+00:00,160,1,432669,A,B,64.81,1,26,8058566357185,128,14930,94343711,CLX5
2025-09-24 19:39:29.467027863+00:00,160,1,432669,A,B,64.81,2,26,8058566357187,128,18380,94343713,CLX5
2025-09-24 19:39:29.467036219+00:00,160,1,432669,A,B,64.81,2,26,8058566357189,128,13745,94343715,CLX5
2025-09-24 19:39:29.467063879+00:00,160,1,432669,C,A,64.85,1,26,8058566349467,128,14121,94343736,CLX5
2025-09-24 19:39:29.467203477+00:00,160,1,432669,C,B,64.81,1,26,8058566357185,128,14834,94343749,CLX5
2025-09-24 19:39:29.467365823+00:00,160,1,432669,A,A,64.82,1,26,8058566357200,128,18567,94343754,CLX5
2025-09-24 19:39:29.467613781+00:00,160,1,432669,A,B,64.79,1,26,8058566357205,128,18550,94343775,CLX5
2025-09-24 19:39:29.467648587+00:00,160,1,432669,C,A,64.85,2,26,8058566357121,128,18380,94343783,CLX5
2025-09-24 19:39:29.467656941+00:00,160,1,432669,A,A,64.82,1,26,8058566357211,128,19620,94343787,CLX5
2025-09-24 19:39:29.467830289+00:00,160,1,432669,C,B,64.78,1,26,8058566357138,128,14295,94343806,CLX5
2025-09-24 19:39:29.467850583+00:00,160,1,432669,A,B,64.8,2,26,8058566357217,128,17983,94343808,CLX5
2025-09-24 19:39:29.467857457+00:00,160,1,432669,C,B,64.77,2,26,8058566356984,128,14358,94343813,CLX5
2025-09-24 19:39:29.467858723+00:00,160,1,432669,A,B,64.54,8,26,8058566357219,128,16069,94343814,CLX5
2025-09-24 19:39:29.468060985+00:00,160,1,432669,A,B,64.81,1,26,8058566357223,128,15271,94343835,CLX5
2025-09-24 19:39:29.468510363+00:00,160,1,432669,A,A,64.82,1,26,8058566357228,128,19701,94343854,CLX5
2025-09-24 19:39:29.468802515+00:00,160,1,432669,A,A,64.82,1,26,8058566357230,128,16198,94343866,CLX5
2025-09-24 19:39:29.468830373+00:00,160,1,432669,A,A,64.82,2,26,8058566357234,128,18888,94343875,CLX5
2025-09-24 19:39:29.468833983+00:00,160,1,432669,C,B,64.81,2,26,8058566357187,128,15551,94343876,CLX5
2025-09-24 19:39:29.468849919+00:00,160,1,432669,C,B,64.81,2,26,8058566357189,128,15171,94343877,CLX5
2025-09-24 19:39:29.468925275+00:00,160,1,432669,C,A,64.82,1,26,8058566357228,128,16111,94343880,CLX5
2025-09-24 19:39:29.469031869+00:00,160,1,432669,C,B,64.8,2,26,8058566357217,128,16879,94343883,CLX5
2025-09-24 19:39:29.469033653+00:00,160,1,432669,A,A,64.82,1,26,8058566357238,128,16523,94343884,CLX5
2025-09-24 19:39:29.469033831+00:00,160,1,432669,A,A,64.82,1,26,8058566357239,128,18122,94343886,CLX5
2025-09-24 19:39:29.469034009+00:00,160,1,432669,A,A,64.82,1,26,8058566357240,128,15853,94343887,CLX5
2025-09-24 19:39:29.469692377+00:00,160,1,432669,A,A,64.82,1,26,8058566357248,128,15048,94343899,CLX5
2025-09-24 19:39:29.470203171+00:00,160,1,432669,C,A,64.82,1,26,8058566357248,128,17792,94343917,CLX5
2025-09-24 19:39:29.470633865+00:00,160,1,432669,C,B,64.81,1,26,8058566357223,128,14917,94343925,CLX5
2025-09-24 19:39:29.470703059+00:00,160,1,432669,C,A,64.82,2,26,8058566357234,128,18856,94343927,CLX5
2025-09-24 19:39:29.471099059+00:00,160,1,432669,A,A,64.82,1,26,8058566357258,128,15738,94343932,CLX5
2025-09-24 19:39:29.471630109+00:00,160,1,432669,C,A,64.82,1,26,8058566357258,128,14506,94343938,CLX5
2025-09-24 19:39:29.471822483+00:00,160,1,432669,A,A,64.82,1,26,8058566357260,128,18799,94343942,CLX5
2025-09-24 19:39:29.472008773+00:00,160,1,432669,C,A,64.82,1,26,8058566357260,128,16421,94343945,CLX5
2025-09-24 19:39:29.472056445+00:00,160,1,432669,M,A,64.83,1,26,8058566349378,128,15163,94343947,CLX5
2025-09-24 19:39:29.472497451+00:00,160,1,432669,C,A,64.82,1,26,8058566357239,128,16163,94343970,CLX5
2025-09-24 19:39:29.474733403+00:00,160,1,432669,A,B,64.81,2,26,8058566357300,128,14178,94344045,CLX5
2025-09-24 19:39:29.482593173+00:00,160,1,432669,C,B,64.81,2,26,8058566357300,128,15586,94344124,CLX5
2025-09-24 19:39:29.511697187+00:00,160,1,432669,A,A,64.87,2,26,8058566357337,128,18772,94344140,CLX5
2025-09-24 19:39:29.517325361+00:00,160,1,432669,A,A,65.9,1,26,8058566357340,128,19707,94344144,CLX5
2025-09-24 19:39:29.524098629+00:00,160,1,432669,C,B,64.54,8,26,8058566357219,128,18919,94344155,CLX5
2025-09-24 19:39:29.570178631+00:00,160,1,432669,A,A,64.82,1,26,8058566357351,128,16067,94344171,CLX5
2025-09-24 19:39:29.570370297+00:00,160,1,432669,C,B,64.81,1,26,8058566357038,128,15491,94344174,CLX5
2025-09-24 19:39:29.589321147+00:00,160,1,432669,A,A,64.85,2,26,8058566357362,128,18284,94344213,CLX5
2025-09-24 19:39:29.589323989+00:00,160,1,432669,A,A,64.82,2,26,8058566357367,128,15238,94344219,CLX5
2025-09-24 19:39:29.589608271+00:00,160,1,432669,A,A,64.82,3,26,8058566357369,128,15937,94344227,CLX5
2025-09-24 19:39:29.589688545+00:00,160,1,432669,A,A,64.82,1,26,8058566357375,128,19192,94344237,CLX5
2025-09-24 19:39:29.589700139+00:00,160,1,432669,A,A,64.82,2,26,8058566357378,128,18287,94344247,CLX5
2025-09-24 19:39:29.589954931+00:00,160,1,432669,C,B,64.81,1,26,8058566356480,128,20148,94344263,CLX5
2025-09-24 19:39:29.589998245+00:00,160,1,432669,C,A,64.82,2,26,8058566357378,128,14321,94344265,CLX5
2025-09-24 19:39:29.590608297+00:00,160,1,432669,M,B,63.64,4,26,8058566319851,128,14629,94344298,CLX5
2025-09-24 19:39:29.593276097+00:00,160,1,432669,M,A,64.82,1,26,8058566349378,128,19326,94344305,CLX5
2025-09-24 19:39:29.611685473+00:00,160,1,432669,C,A,64.87,2,26,8058566357337,128,18989,94344316,CLX5
2025-09-24 19:39:29.617406437+00:00,160,1,432669,C,A,65.9,1,26,8058566357340,128,18684,94344317,CLX5
2025-09-24 19:39:29.642793899+00:00,160,1,432669,A,A,64.82,1,26,8058566357415,128,18461,94344382,CLX5
2025-09-24 19:39:29.642950909+00:00,160,1,432669,C,B,64.79,1,26,8058566357205,128,19433,94344383,CLX5
2025-09-24 19:39:29.740146123+00:00,160,1,432669,A,B,64.78,1,26,8058566357425,128,17785,94344409,CLX5
2025-09-24 19:39:29.811997207+00:00,160,1,432669,A,B,64.77,2,26,8058566357432,128,18561,94344425,CLX5
2025-09-24 19:39:30.023691043+00:00,160,1,432669,A,A,64.84,1,26,8058566357446,128,18077,94344459,CLX5
2025-09-24 19:39:32.001636549+00:00,160,1,432669,A,A,64.82,1,26,8058566357455,128,20712,94344498,CLX5
2025-09-24 19:39:32.385684713+00:00,160,1,432669,C,A,64.85,2,26,8058566357362,128,16683,94344507,CLX5
2025-09-24 19:39:32.385957571+00:00,160,1,432669,C,B,64.78,1,26,8058566357425,128,21431,94344512,CLX5
2025-09-24 19:39:32.397748195+00:00,160,1,432669,C,B,64.77,2,26,8058566357432,128,20410,94344520,CLX5
2025-09-24 19:39:32.411679273+00:00,160,1,432669,A,A,64.85,2,26,8058566357461,128,20526,94344522,CLX5
2025-09-24 19:39:32.540344239+00:00,160,1,432669,A,B,64.78,1,26,8058566357463,128,20277,94344529,CLX5
2025-09-24 19:39:32.711547673+00:00,160,1,432669,T,B,64.82,1,26,8058566357464,0,22579,94344530,CLX5
2025-09-24 19:39:32.711547673+00:00,160,1,432669,F,A,64.82,1,26,8058566349748,0,22579,94344530,CLX5
2025-09-24 19:39:32.711547673+00:00,160,1,432669,C,A,64.82,1,26,8058566349748,128,17398,94344531,CLX5
2025-09-24 19:39:33.595533795+00:00,160,1,432669,A,B,64.81,1,26,8058566357469,128,25845,94344544,CLX5
2025-09-24 19:39:33.595710869+00:00,160,1,432669,A,B,64.81,1,26,8058566357470,128,22862,94344545,CLX5
2025-09-24 19:39:37.862805025+00:00,160,1,432669,C,A,64.82,3,26,8058566357369,128,19692,94344648,CLX5
2025-09-24 19:39:40.024044219+00:00,160,1,432669,A,A,64.85,1,26,8058566357512,128,21927,94344702,CLX5
2025-09-24 19:39:40.760957669+00:00,160,1,432669,C,A,64.82,1,26,8058566357240,128,15704,94344754,CLX5
2025-09-24 19:39:40.761110859+00:00,160,1,432669,C,A,64.82,1,26,8058566357415,128,19270,94344759,CLX5
2025-09-24 19:39:40.762103783+00:00,160,1,432669,M,A,64.83,1,26,8058566349378,128,20181,94344763,CLX5
2025-09-24 19:39:40.763047997+00:00,160,1,432669,C,A,64.82,1,26,8058566357375,128,15898,94344765,CLX5
2025-09-24 19:39:40.911761851+00:00,160,1,432669,A,B,64.77,2,26,8058566357527,128,18486,94344783,CLX5
2025-09-24 19:39:40.948504347+00:00,160,1,432669,A,B,64.8,1,26,8058566357528,128,18168,94344784,CLX5
2025-09-24 19:39:42.651707889+00:00,160,1,432669,A,A,64.82,1,26,8058566357540,128,19056,94344830,CLX5
2025-09-24 19:39:42.651913879+00:00,160,1,432669,A,A,64.82,1,26,8058566357544,128,19099,94344843,CLX5
2025-09-24 19:39:42.890579603+00:00,160,1,432669,C,B,64.8,1,26,8058566357528,128,19141,94344908,CLX5
2025-09-24 19:39:42.894272963+00:00,160,1,432669,C,B,64.81,1,26,8058566357470,128,20929,94344915,CLX5
2025-09-24 19:39:44.321263711+00:00,160,1,432669,A,B,64.81,4,26,8058566357569,128,25078,94344947,CLX5
2025-09-24 19:39:44.321461327+00:00,160,1,432669,C,A,64.82,1,26,8058566357544,128,21229,94344948,CLX5
2025-09-24 19:39:44.321462753+00:00,160,1,432669,A,B,64.81,1,26,8058566357570,128,14700,94344949,CLX5
2025-09-24 19:39:44.321610045+00:00,160,1,432669,C,A,64.82,1,26,8058566357540,128,14673,94344955,CLX5
2025-09-24 19:39:45.413415487+00:00,160,1,432669,T,A,64.81,1,26,8058566357577,0,18028,94344967,CLX5
2025-09-24 19:39:45.413415487+00:00,160,1,432669,F,B,64.81,1,26,8058566356316,0,18028,94344967,CLX5
2025-09-24 19:39:45.413415487+00:00,160,1,432669,C,B,64.81,1,26,8058566356316,128,16447,94344968,CLX5
2025-09-24 19:39:45.413752319+00:00,160,1,432669,A,A,64.82,1,26,8058566357580,128,16005,94344974,CLX5
2025-09-24 19:39:45.413752509+00:00,160,1,432669,C,B,64.81,1,26,8058566357570,128,19565,94344975,CLX5
2025-09-24 19:39:45.413754007+00:00,160,1,432669,A,A,64.82,1,26,8058566357581,128,14276,94344976,CLX5
2025-09-24 19:39:46.397371377+00:00,160,1,432669,M,A,64.94,1,26,8058566157942,128,20721,94345030,CLX5
2025-09-24 19:39:47.103096869+00:00,160,1,432669,C,A,64.82,1,26,8058566357580,128,18751,94345056,CLX5
2025-09-24 19:39:47.103265551+00:00,160,1,432669,C,A,64.82,1,26,8058566357581,128,15872,94345059,CLX5
2025-09-24 19:39:47.103267127+00:00,160,1,432669,A,B,64.81,1,26,8058566357599,128,18989,94345060,CLX5
2025-09-24 19:39:47.881675811+00:00,160,1,432669,A,A,64.82,1,26,8058566357605,128,23683,94345083,CLX5
2025-09-24 19:39:47.881681417+00:00,160,1,432669,A,A,64.82,1,26,8058566357606,128,18055,94345084,CLX5
2025-09-24 19:39:50.024131683+00:00,160,1,432669,A,A,64.86,1,26,8058566357626,128,19354,94345152,CLX5
2025-09-24 19:39:50.282079135+00:00,160,1,432669,C,A,64.82,1,26,8058566357605,128,15843,94345154,CLX5
2025-09-24 19:39:50.282937395+00:00,160,1,432669,A,A,64.82,2,26,8058566357633,128,19831,94345178,CLX5
2025-09-24 19:39:50.283076645+00:00,160,1,432669,C,B,64.81,1,26,8058566357599,128,19232,94345182,CLX5
2025-09-24 19:39:50.317848615+00:00,160,1,432669,C,B,64.77,2,26,8058566357527,128,18283,94345223,CLX5
2025-09-24 19:39:53.000674857+00:00,160,1,432669,C,A,64.82,1,26,8058566354651,128,24851,94345427,CLX5
2025-09-24 19:39:53.340043521+00:00,160,1,432669,C,A,64.82,1,26,8058566357606,128,16012,94345447,CLX5
2025-09-24 19:39:53.340045461+00:00,160,1,432669,A,B,64.81,1,26,8058566357716,128,18938,94345448,CLX5
2025-09-24 19:39:53.511780501+00:00,160,1,432669,A,B,64.77,2,26,8058566357719,128,18401,94345465,CLX5
2025-09-24 19:39:53.646813713+00:00,160,1,432669,A,A,64.82,1,26,8058566357723,128,15648,94345476,CLX5
2025-09-24 19:39:53.646952965+00:00,160,1,432669,C,B,64.77,2,26,8058566357719,128,14737,94345484,CLX5
2025-09-24 19:39:53.646993975+00:00,160,1,432669,C,B,64.81,1,26,8058566357716,128,19498,94345486,CLX5
2025-09-24 19:39:53.646995491+00:00,160,1,432669,A,A,64.82,1,26,8058566357726,128,16078,94345487,CLX5
2025-09-24 19:39:53.647023425+00:00,160,1,432669,C,A,64.82,1,26,8058566357723,128,16051,94345489,CLX5
2025-09-24 19:39:53.647068199+00:00,160,1,432669,A,A,64.82,1,26,8058566357728,128,15552,94345491,CLX5
2025-09-24 19:39:53.647912923+00:00,160,1,432669,C,A,64.82,1,26,8058566357728,128,16399,94345529,CLX5
2025-09-24 19:39:53.647950957+00:00,160,1,432669,A,B,64.81,1,26,8058566357740,128,16017,94345531,CLX5
2025-09-24 19:39:53.647995595+00:00,160,1,432669,A,A,64.82,1,26,8058566357741,128,18789,94345532,CLX5
2025-09-24 19:39:53.648230765+00:00,160,1,432669,A,B,64.81,1,26,8058566357744,128,15236,94345542,CLX5
2025-09-24 19:39:53.648831335+00:00,160,1,432669,A,B,64.54,8,26,8058566357751,128,18911,94345557,CLX5
2025-09-24 19:39:53.648969393+00:00,160,1,432669,C,B,64.81,1,26,8058566357744,128,18559,94345562,CLX5
2025-09-24 19:39:53.649299545+00:00,160,1,432669,C,B,64.81,1,26,8058566357740,128,18751,94345578,CLX5
2025-09-24 19:39:53.650606545+00:00,160,1,432669,A,A,64.82,3,26,8058566357771,128,18616,94345622,CLX5
2025-09-24 19:39:57.002626109+00:00,160,1,432669,T,B,64.82,1,26,8058566357875,0,17837,94345976,CLX5
2025-09-24 19:39:57.002626109+00:00,160,1,432669,F,A,64.82,1,26,8058566350235,0,17837,94345976,CLX5
2025-09-24 19:39:57.002626109+00:00,160,1,432669,C,A,64.82,1,26,8058566350235,128,16393,94345977,CLX5
2025-09-24 19:39:57.003161537+00:00,160,1,432669,A,B,64.81,1,26,8058566357881,128,15842,94345994,CLX5
2025-09-24 19:39:57.010664525+00:00,160,1,432669,A,A,64.82,1,26,8058566357888,128,20097,94346011,CLX5
2025-09-24 19:39:57.013630833+00:00,160,1,432669,C,B,64.81,1,26,8058566357881,128,16582,94346018,CLX5
2025-09-24 19:39:57.117557981+00:00,160,1,432669,C,A,65.7,6,26,8058566353536,128,18585,94346049,CLX5
2025-09-24 19:39:58.064557563+00:00,160,1,432669,A,B,64.79,1,26,8058566357903,128,16402,94346130,CLX5
2025-09-24 19:39:58.258753925+00:00,160,1,432669,C,B,64.79,1,26,8058566357903,128,18183,94346152,CLX5
2025-09-24 19:39:58.313962567+00:00,160,1,432669,A,B,64.81,1,26,8058566357915,128,15853,94346178,CLX5
2025-09-24 19:39:58.313977867+00:00,160,1,432669,A,B,64.79,1,26,8058566357917,128,14546,94346182,CLX5
2025-09-24 19:39:58.314156921+00:00,160,1,432669,C,A,64.82,1,26,8058566357726,128,15163,94346186,CLX5
2025-09-24 19:39:58.314158417+00:00,160,1,432669,A,B,64.81,1,26,8058566357919,128,14781,94346187,CLX5
2025-09-24 19:39:58.314173489+00:00,160,1,432669,A,B,64.81,1,26,8058566357920,128,18182,94346188,CLX5
2025-09-24 19:39:58.314199445+00:00,160,1,432669,C,A,64.82,3,26,8058566357771,128,14465,94346190,CLX5
2025-09-24 19:39:58.314380033+00:00,160,1,432669,C,B,64.81,1,26,8058566357920,128,17493,94346196,CLX5
2025-09-24 19:39:58.314560909+00:00,160,1,432669,C,A,64.82,1,26,8058566357741,128,18705,94346201,CLX5
2025-09-24 19:39:58.317774579+00:00,160,1,432669,A,A,65.7,6,26,8058566357925,128,18020,94346208,CLX5
2025-09-24 19:39:58.393334495+00:00,160,1,432669,A,A,64.82,1,26,8058566357928,128,15803,94346219,CLX5
2025-09-24 19:39:58.406212903+00:00,160,1,432669,C,B,64.81,1,26,8058566357919,128,18088,94346237,CLX5
2025-09-24 19:39:58.417517441+00:00,160,1,432669,C,A,65.7,6,26,8058566357925,128,18950,94346243,CLX5
2025-09-24 19:39:58.506310895+00:00,160,1,432669,A,A,64.82,3,26,8058566357933,128,19080,94346244,CLX5
2025-09-24 19:40:00.003516463+00:00,160,1,432669,M,B,64.74,17,26,8058566163289,128,17895,94346284,CLX5
2025-09-24 19:40:00.051147833+00:00,160,1,432669,A,B,64.81,1,26,8058566357958,128,18523,94346372,CLX5
2025-09-24 19:40:00.051293171+00:00,160,1,432669,C,A,64.82,1,26,8058566357928,128,14983,94346378,CLX5
2025-09-24 19:40:00.051297569+00:00,160,1,432669,C,A,64.82,2,26,8058566357633,128,15571,94346379,CLX5
2025-09-24 19:40:00.051445037+00:00,160,1,432669,C,A,64.82,3,26,8058566357933,128,19565,94346391,CLX5
2025-09-24 19:40:00.056557693+00:00,160,1,432669,C,A,64.82,1,26,8058566357351,128,15785,94346500,CLX5
2025-09-24 19:40:00.056558001+00:00,160,1,432669,C,A,64.82,2,26,8058566357367,128,19318,94346501,CLX5
2025-09-24 19:40:00.056558193+00:00,160,1,432669,C,A,64.85,2,26,8058566357461,128,14543,94346502,CLX5
2025-09-24 19:40:00.057442661+00:00,160,1,432669,A,A,64.82,2,26,8058566358015,128,19713,94346534,CLX5
2025-09-24 19:40:00.111833957+00:00,160,1,432669,A,A,64.87,2,26,8058566358030,128,18108,94346574,CLX5
2025-09-24 19:40:00.117559893+00:00,160,1,432669,A,A,65.9,1,26,8058566358031,128,17825,94346575,CLX5
2025-09-24 19:40:00.117611251+00:00,160,1,432669,A,A,65.7,6,26,8058566358032,128,14202,94346576,CLX5
2025-09-24 19:40:00.124336463+00:00,160,1,432669,C,B,64.54,8,26,8058566357751,128,18545,94346590,CLX5
2025-09-24 19:40:00.212940421+00:00,160,1,432669,C,A,64.82,2,26,8058566358015,128,17976,94346617,CLX5
2025-09-24 19:40:00.213240985+00:00,160,1,432669,C,A,64.82,1,26,8058566357238,128,15523,94346621,CLX5
2025-09-24 19:40:00.213388913+00:00,160,1,432669,A,B,64.81,2,26,8058566358051,128,19761,94346624,CLX5
2025-09-24 19:40:00.214145531+00:00,160,1,432669,M,B,64.81,1,26,8058566319851,128,18398,94346626,CLX5
2025-09-24 19:40:00.221075485+00:00,160,1,432669,M,A,64.83,1,26,8058566357888,128,22715,94346632,CLX5
2025-09-24 19:40:00.411838461+00:00,160,1,432669,A,B,64.77,2,26,8058566358067,128,18493,94346654,CLX5
2025-09-24 19:40:01.465853197+00:00,160,1,432669,A,B,64.81,2,26,8058566358079,128,23448,94346675,CLX5
2025-09-24 19:40:01.949698323+00:00,160,1,432669,A,B,64.81,1,26,8058566358085,128,18578,94346683,CLX5
2025-09-24 19:40:02.529883071+00:00,160,1,432669,M,A,64.9,3,26,8058566144143,128,30875,94346684,CLX5
2025-09-24 19:40:03.687175747+00:00,160,1,432669,C,A,65.09,1,26,8058566356147,128,24267,94346689,CLX5
2025-09-24 19:40:03.702708745+00:00,160,1,432669,A,A,65.08,1,26,8058566358088,128,20745,94346691,CLX5
2025-09-24 19:40:04.816249145+00:00,160,1,432669,C,A,65.09,1,26,8058566356134,128,21482,94346694,CLX5
2025-09-24 19:40:04.879097265+00:00,160,1,432669,A,A,65.08,1,26,8058566358089,128,24574,94346695,CLX5
2025-09-24 19:40:07.645201137+00:00,160,1,432669,C,A,64.87,1,26,8058566325711,128,19200,94346786,CLX5
2025-09-24 19:40:07.761137007+00:00,160,1,432669,A,A,64.86,1,26,8058566358118,128,18514,94346787,CLX5
2025-09-24 19:40:09.540520899+00:00,160,1,432669,T,B,64.82,1,26,8058566358146,0,18358,94346871,CLX5
2025-09-24 19:40:09.540520899+00:00,160,1,432669,F,A,64.82,1,26,8058566354363,0,18358,94346871,CLX5
2025-09-24 19:40:09.540520899+00:00,160,1,432669,C,A,64.82,1,26,8058566354363,128,18099,94346872,CLX5
2025-09-24 19:40:09.540851143+00:00,160,1,432669,C,A,64.82,1,26,8058566357230,128,21212,94346873,CLX5
2025-09-24 19:40:09.540857019+00:00,160,1,432669,A,B,64.78,1,26,8058566358147,128,13731,94346874,CLX5
2025-09-24 19:40:09.540901023+00:00,160,1,432669,C,A,64.82,1,26,8058566357211,128,17496,94346876,CLX5
2025-09-24 19:40:09.541487713+00:00,160,1,432669,A,B,64.8,2,26,8058566358149,128,14557,94346879,CLX5
2025-09-24 19:40:09.541489669+00:00,160,1,432669,A,B,64.54,8,26,8058566358150,128,14496,94346880,CLX5
2025-09-24 19:40:09.541494853+00:00,160,1,432669,C,B,64.77,2,26,8058566358067,128,14496,94346880,CLX5
2025-09-24 19:40:09.541679339+00:00,160,1,432669,T,B,64.82,3,26,8058566358151,0,18169,94346882,CLX5
2025-09-24 19:40:09.541679339+00:00,160,1,432669,F,A,64.82,1,26,8058566356287,0,18169,94346882,CLX5
2025-09-24 19:40:09.541679339+00:00,160,1,432669,F,A,64.82,1,26,8058566357200,0,18169,94346882,CLX5
2025-09-24 19:40:09.541679339+00:00,160,1,432669,F,A,64.82,1,26,8058566357455,0,18169,94346882,CLX5
2025-09-24 19:40:09.541679339+00:00,160,1,432669,C,A,64.82,1,26,8058566356287,0,14863,94346883,CLX5
2025-09-24 19:40:09.541679339+00:00,160,1,432669,C,A,64.82,1,26,8058566357200,0,14863,94346883,CLX5
2025-09-24 19:40:09.541679339+00:00,160,1,432669,C,A,64.82,1,26,8058566357455,128,14863,94346883,CLX5
2025-09-24 19:40:09.541696619+00:00,160,1,432669,A,B,64.81,1,26,8058566358152,128,14865,94346886,CLX5
2025-09-24 19:40:09.541835715+00:00,160,1,432669,A,B,64.81,1,26,8058566358154,128,13870,94346889,CLX5
2025-09-24 19:40:09.541906311+00:00,160,1,432669,C,A,64.83,1,26,8058566345966,128,17231,94346893,CLX5
2025-09-24 19:40:09.541947205+00:00,160,1,432669,A,B,64.81,1,26,8058566358156,128,15351,94346894,CLX5
2025-09-24 19:40:09.541981437+00:00,160,1,432669,C,B,64.78,1,26,8058566357463,128,15153,94346896,CLX5
2025-09-24 19:40:09.542020125+00:00,160,1,432669,A,B,64.82,1,26,8058566358158,128,14595,94346897,CLX5
2025-09-24 19:40:09.542085017+00:00,160,1,432669,A,B,64.81,1,26,8058566358167,128,18016,94346934,CLX5
2025-09-24 19:40:09.542133839+00:00,160,1,432669,A,B,64.81,3,26,8058566358168,128,18150,94346940,CLX5
2025-09-24 19:40:09.542437513+00:00,160,1,432669,C,B,64.8,1,26,8058566349470,128,14706,94346955,CLX5
2025-09-24 19:40:09.542465737+00:00,160,1,432669,C,B,64.78,1,26,8058566335785,128,15321,94346960,CLX5
2025-09-24 19:40:09.542470553+00:00,160,1,432669,A,B,64.82,1,26,8058566358178,128,14950,94346962,CLX5
2025-09-24 19:40:09.542570121+00:00,160,1,432669,A,A,64.83,1,26,8058566358182,128,15304,94346977,CLX5
2025-09-24 19:40:09.542788051+00:00,160,1,432669,M,B,64.81,1,26,8058566319508,128,17844,94347015,CLX5
2025-09-24 19:40:09.542806291+00:00,160,1,432669,M,B,64.8,1,26,8058566329044,128,15208,94347020,CLX5
2025-09-24 19:40:09.542920025+00:00,160,1,432669,A,B,64.82,1,26,8058566358203,128,14288,94347048,CLX5
2025-09-24 19:40:09.542987127+00:00,160,1,432669,M,A,65.99,4,26,8058566342145,128,15352,94347055,CLX5
2025-09-24 19:40:09.543047527+00:00,160,1,432669,A,B,64.82,2,26,8058566358204,128,14510,94347058,CLX5
2025-09-24 19:40:09.543505043+00:00,160,1,432669,A,B,64.82,2,26,8058566358215,128,20589,94347088,CLX5
2025-09-24 19:40:09.543521037+00:00,160,1,432669,A,B,64.82,2,26,8058566358218,128,17908,94347091,CLX5
2025-09-24 19:40:09.543603785+00:00,160,1,432669,C,A,64.83,1,26,8058566345875,128,13851,94347096,CLX5
2025-09-24 19:40:09.543912891+00:00,160,1,432669,A,B,64.82,2,26,8058566358223,128,16401,94347111,CLX5
2025-09-24 19:40:09.544037435+00:00,160,1,432669,C,A,64.83,2,26,8058566345878,128,18007,94347118,CLX5
2025-09-24 19:40:09.544175959+00:00,160,1,432669,A,B,64.82,1,26,8058566358230,128,15825,94347126,CLX5
2025-09-24 19:40:09.544633301+00:00,160,1,432669,C,A,64.83,1,26,8058566345742,128,14949,94347162,CLX5
2025-09-24 19:40:09.544633455+00:00,160,1,432669,C,A,64.83,1,26,8058566345743,128,17268,94347163,CLX5
2025-09-24 19:40:09.545564403+00:00,160,1,432669,M,A,64.84,1,26,8058566173085,128,13489,94347202,CLX5
2025-09-24 19:40:09.546492931+00:00,160,1,432669,A,B,64.82,1,26,8058566358254,128,15792,94347228,CLX5
2025-09-24 19:40:09.547739493+00:00,160,1,432669,A,A,64.83,1,26,8058566358269,128,16357,94347292,CLX5
2025-09-24 19:40:09.554102323+00:00,160,1,432669,C,A,64.83,1,26,8058566358269,128,15036,94347457,CLX5
2025-09-24 19:40:09.554304585+00:00,160,1,432669,A,A,64.83,1,26,8058566358309,128,18335,94347460,CLX5
2025-09-24 19:40:09.554533881+00:00,160,1,432669,C,A,64.83,1,26,8058566358309,128,15836,94347479,CLX5
2025-09-24 19:40:09.554693311+00:00,160,1,432669,A,A,64.83,1,26,8058566358311,128,14812,94347488,CLX5
2025-09-24 19:40:09.565225909+00:00,160,1,432669,C,B,64.81,1,26,8058566357469,128,15893,94347659,CLX5
2025-09-24 19:40:09.603113593+00:00,160,1,432669,C,A,64.83,1,26,8058566358311,128,18293,94347739,CLX5
2025-09-24 19:40:09.603262233+00:00,160,1,432669,C,B,64.78,1,26,8058566358147,128,18469,94347743,CLX5
2025-09-24 19:40:09.603287979+00:00,160,1,432669,C,B,64.81,1,26,8058566358167,128,14973,94347745,CLX5
2025-09-24 19:40:09.609275141+00:00,160,1,432669,M,B,64.39,4,26,8058559498241,128,18223,94347751,CLX5
2025-09-24 19:40:09.611919689+00:00,160,1,432669,C,B,64.78,2,26,8058566349492,128,15357,94347757,CLX5
2025-09-24 19:40:09.617600315+00:00,160,1,432669,C,B,64.16,2,26,8058566337918,128,17917,94347759,CLX5
2025-09-24 19:40:09.627492755+00:00,160,1,432669,C,B,64.82,1,26,8058566358254,128,20454,94347762,CLX5
2025-09-24 19:40:09.627626669+00:00,160,1,432669,C,B,64.82,2,26,8058566358215,128,19899,94347763,CLX5
2025-09-24 19:40:09.630809601+00:00,160,1,432669,M,B,64.39,4,26,8058559498258,128,17116,94347765,CLX5
2025-09-24 19:40:09.689103337+00:00,160,1,432669,A,B,64.82,1,26,8058566358471,128,18943,94347931,CLX5
2025-09-24 19:40:09.689276917+00:00,160,1,432669,C,B,64.81,1,26,8058566358156,128,14494,94347935,CLX5
2025-09-24 19:40:09.689286515+00:00,160,1,432669,C,B,64.81,1,26,8058566358152,128,17788,94347936,CLX5
2025-09-24 19:40:09.710598767+00:00,160,1,432669,A,B,64.82,1,26,8058566358483,128,19593,94347966,CLX5
2025-09-24 19:40:09.710766317+00:00,160,1,432669,A,A,64.83,1,26,8058566358485,128,19161,94347970,CLX5
2025-09-24 19:40:09.711455701+00:00,160,1,432669,C,A,64.83,1,26,8058566358485,128,18220,94347973,CLX5
2025-09-24 19:40:09.711835363+00:00,160,1,432669,C,A,64.83,1,26,8058566345921,128,17000,94347978,CLX5
2025-09-24 19:40:09.711924255+00:00,160,1,432669,M,A,64.95,1,26,8058565075241,128,15556,94347984,CLX5
2025-09-24 19:40:09.713410981+00:00,160,1,432669,M,A,64.84,1,26,8058566354507,128,14969,94348097,CLX5
2025-09-24 19:40:09.713728267+00:00,160,1,432669,C,A,64.83,2,26,8058566335294,128,14889,94348140,CLX5
2025-09-24 19:40:09.713734603+00:00,160,1,432669,C,A,64.83,1,26,8058566345625,128,14814,94348150,CLX5
2025-09-24 19:40:09.713795193+00:00,160,1,432669,A,B,64.82,1,26,8058566358552,128,17874,94348176,CLX5
2025-09-24 19:40:09.713798055+00:00,160,1,432669,C,A,64.83,1,26,8058566335292,128,18362,94348178,CLX5
2025-09-24 19:40:09.713798785+00:00,160,1,432669,A,B,64.82,1,26,8058566358553,128,15945,94348179,CLX5
2025-09-24 19:40:09.713799399+00:00,160,1,432669,A,B,64.82,1,26,8058566358554,128,15674,94348180,CLX5
2025-09-24 19:40:09.713846437+00:00,160,1,432669,C,B,64.82,1,26,8058566358552,128,19781,94348195,CLX5
2025-09-24 19:40:09.714006713+00:00,160,1,432669,C,B,64.82,1,26,8058566358553,128,17093,94348210,CLX5
2025-09-24 19:40:09.714350339+00:00,160,1,432669,C,B,64.76,2,26,8058566350576,128,18238,94348261,CLX5
2025-09-24 19:40:09.714415883+00:00,160,1,432669,C,A,64.86,2,26,8058566345929,128,14710,94348275,CLX5
2025-09-24 19:40:09.714420031+00:00,160,1,432669,C,A,64.83,1,26,8058566345788,128,15554,94348280,CLX5
2025-09-24 19:40:09.714705543+00:00,160,1,432669,A,B,64.81,2,26,8058566358590,128,14611,94348329,CLX5
2025-09-24 19:40:09.714798217+00:00,160,1,432669,A,B,64.82,1,26,8058566358597,128,18031,94348345,CLX5
2025-09-24 19:40:09.714863935+00:00,160,1,432669,T,B,64.83,1,26,8058566358602,0,14982,94348355,CLX5
2025-09-24 19:40:09.714863935+00:00,160,1,432669,F,A,64.83,1,26,8058566335059,0,14982,94348355,CLX5
2025-09-24 19:40:09.714863935+00:00,160,1,432669,M,A,64.83,1,26,8058566335059,128,19323,94348356,CLX5
2025-09-24 19:40:09.714864289+00:00,160,1,432669,T,B,64.83,1,26,8058566358604,0,14889,94348360,CLX5
2025-09-24 19:40:09.714864289+00:00,160,1,432669,F,A,64.83,1,26,8058566335059,0,14889,94348360,CLX5
2025-09-24 19:40:09.714864289+00:00,160,1,432669,C,A,64.83,1,26,8058566335059,128,14889,94348360,CLX5
2025-09-24 19:40:09.715066409+00:00,160,1,432669,A,B,64.8,1,26,8058566358610,128,14947,94348381,CLX5
2025-09-24 19:40:09.715128939+00:00,160,1,432669,C,A,64.83,1,26,8058566345827,128,14485,94348385,CLX5
2025-09-24 19:40:09.715411935+00:00,160,1,432669,A,B,64.82,1,26,8058566358616,128,15095,94348396,CLX5
2025-09-24 19:40:09.715745885+00:00,160,1,432669,C,B,64.82,1,26,8058566358554,128,14840,94348405,CLX5
2025-09-24 19:40:09.716117927+00:00,160,1,432669,A,B,64.82,1,26,8058566358622,128,15553,94348411,CLX5
2025-09-24 19:40:09.716177945+00:00,160,1,432669,A,B,64.82,1,26,8058566358623,128,13578,94348413,CLX5
2025-09-24 19:40:09.716575251+00:00,160,1,432669,C,B,64.82,1,26,8058566358623,128,17600,94348443,CLX5
2025-09-24 19:40:09.716797001+00:00,160,1,432669,C,B,64.82,1,26,8058566358622,128,17164,94348454,CLX5
2025-09-24 19:40:09.717433339+00:00,160,1,432669,A,B,64.82,2,26,8058566358628,128,17614,94348465,CLX5
2025-09-24 19:40:09.718570485+00:00,160,1,432669,A,B,64.82,1,26,8058566358639,128,18157,94348507,CLX5
2025-09-24 19:40:09.718571617+00:00,160,1,432669,A,B,64.82,1,26,8058566358640,128,14761,94348508,CLX5
2025-09-24 19:40:09.718748249+00:00,160,1,432669,A,B,64.82,1,26,8058566358649,128,14927,94348539,CLX5
2025-09-24 19:40:09.719928383+00:00,160,1,432669,C,B,64.82,1,26,8058566358597,128,15584,94348583,CLX5
2025-09-24 19:40:09.720092497+00:00,160,1,432669,C,B,64.82,1,26,8058566358649,128,13989,94348594,CLX5
2025-09-24 19:40:09.720323427+00:00,160,1,432669,A,A,64.87,1,26,8058566358671,128,17896,94348608,CLX5
2025-09-24 19:40:09.720360537+00:00,160,1,432669,M,B,64.82,2,26,8058566346145,128,16721,94348611,CLX5
2025-09-24 19:40:09.720714627+00:00,160,1,432669,A,A,64.83,1,26,8058566358675,128,16239,94348618,CLX5
2025-09-24 19:40:09.720950777+00:00,160,1,432669,C,B,64.82,1,26,8058566358639,128,14816,94348642,CLX5
2025-09-24 19:40:09.721869379+00:00,160,1,432669,C,B,64.82,1,26,8058566358640,128,15164,94348663,CLX5
2025-09-24 19:40:09.723015759+00:00,160,1,432669,A,A,64.83,1,26,8058566358700,128,16378,94348697,CLX5
2025-09-24 19:40:09.723545811+00:00,160,1,432669,M,A,64.84,1,26,8058566357888,128,19335,94348711,CLX5
2025-09-24 19:40:09.725374759+00:00,160,1,432669,A,A,64.83,2,26,8058566358717,128,15786,94348764,CLX5
2025-09-24 19:40:09.725638939+00:00,160,1,432669,A,A,64.83,1,26,8058566358719,128,15687,94348765,CLX5
2025-09-24 19:40:09.726057195+00:00,160,1,432669,A,B,64.82,1,26,8058566358730,128,15188,94348797,CLX5
2025-09-24 19:40:09.726585689+00:00,160,1,432669,M,B,63.67,4,26,8058566346145,128,15678,94348816,CLX5
2025-09-24 19:40:09.726727379+00:00,160,1,432669,A,B,64.8,1,26,8058566358736,128,14439,94348821,CLX5
2025-09-24 19:40:09.727002945+00:00,160,1,432669,A,B,64.82,1,26,8058566358739,128,15040,94348830,CLX5
2025-09-24 19:40:09.727492445+00:00,160,1,432669,M,A,64.83,1,26,8058566357888,128,16424,94348847,CLX5
2025-09-24 19:40:09.728092497+00:00,160,1,432669,C,A,64.83,1,26,8058566358719,128,15337,94348896,CLX5
2025-09-24 19:40:09.734743159+00:00,160,1,432669,A,B,64.82,1,26,8058566358818,128,18808,94349061,CLX5
2025-09-24 19:40:09.735231817+00:00,160,1,432669,T,B,64.83,1,26,8058566358819,0,17828,94349066,CLX5
2025-09-24 19:40:09.735231817+00:00,160,1,432669,F,A,64.83,1,26,8058566335783,0,17828,94349066,CLX5
2025-09-24 19:40:09.735231817+00:00,160,1,432669,M,A,64.83,2,26,8058566335783,128,16231,94349067,CLX5
2025-09-24 19:40:09.812292245+00:00,160,1,432669,C,B,64.79,2,26,8058566340495,128,17814,94349432,CLX5
2025-09-24 19:40:09.812293109+00:00,160,1,432669,A,A,64.88,2,26,8058566358952,128,14321,94349433,CLX5
2025-09-24 19:40:09.812560323+00:00,160,1,432669,A,A,64.83,1,26,8058566358954,128,14600,94349435,CLX5
2025-09-24 19:40:09.812760857+00:00,160,1,432669,C,A,64.83,1,26,8058566358700,128,19249,94349440,CLX5
2025-09-24 19:40:09.816847109+00:00,160,1,432669,C,A,64.86,1,26,8058566345884,128,18029,94349446,CLX5
2025-09-24 19:40:09.845918313+00:00,160,1,432669,A,A,64.83,1,26,8058566359049,128,15631,94349644,CLX5
2025-09-24 19:40:09.856532777+00:00,160,1,432669,C,A,64.83,1,26,8058566359049,128,18831,94349715,CLX5
2025-09-24 19:40:09.894009925+00:00,160,1,432669,C,B,64.8,1,26,8058566358610,128,18070,94349810,CLX5
2025-09-24 19:40:09.957766107+00:00,160,1,432669,C,A,65.15,1,26,8058566337859,128,18610,94349873,CLX5
2025-09-24 19:40:09.982447041+00:00,160,1,432669,A,A,64.83,1,26,8058566359202,128,19220,94349928,CLX5
2025-09-24 19:40:10.066931359+00:00,160,1,432669,A,A,65.11,1,26,8058566359226,128,17842,94349976,CLX5
2025-09-24 19:40:10.208081783+00:00,160,1,432669,C,B,64.81,2,26,8058566358590,128,14169,94350037,CLX5
2025-09-24 19:40:10.208082147+00:00,160,1,432669,A,A,64.83,1,26,8058566359249,128,18381,94350039,CLX5
2025-09-24 19:40:10.208395999+00:00,160,1,432669,C,B,64.82,1,26,8058566358483,128,17805,94350073,CLX5
2025-09-24 19:40:10.208408843+00:00,160,1,432669,C,B,64.82,2,26,8058566358628,128,15018,94350075,CLX5
2025-09-24 19:40:10.208411205+00:00,160,1,432669,A,A,64.83,1,26,8058566359261,128,15047,94350076,CLX5
2025-09-24 19:40:10.208421245+00:00,160,1,432669,A,A,64.83,2,26,8058566359262,128,15162,94350078,CLX5
2025-09-24 19:40:10.208465153+00:00,160,1,432669,C,B,64.82,1,26,8058566358818,128,15724,94350085,CLX5
2025-09-24 19:40:10.208477019+00:00,160,1,432669,C,B,64.82,1,26,8058566358739,128,13770,94350091,CLX5
2025-09-24 19:40:10.208488847+00:00,160,1,432669,C,B,64.82,1,26,8058566358730,128,19828,94350096,CLX5
2025-09-24 19:40:10.208496505+00:00,160,1,432669,A,A,64.83,2,26,8058566359273,128,15371,94350101,CLX5
2025-09-24 19:40:10.208952657+00:00,160,1,432669,C,A,64.83,2,26,8058566359273,128,15613,94350146,CLX5
2025-09-24 19:40:10.209234501+00:00,160,1,432669,C,B,64.82,1,26,8058566358616,128,18979,94350165,CLX5
2025-09-24 19:40:10.209316385+00:00,160,1,432669,A,A,64.83,1,26,8058566359301,128,18399,94350169,CLX5
2025-09-24 19:40:10.210847441+00:00,160,1,432669,A,A,64.86,2,26,8058566359312,128,14402,94350227,CLX5
2025-09-24 19:40:10.211130379+00:00,160,1,432669,C,B,64.82,2,26,8058566358223,128,14788,94350236,CLX5
2025-09-24 19:40:10.211130647+00:00,160,1,432669,C,B,64.82,1,26,8058566358230,128,16037,94350237,CLX5
2025-09-24 19:40:10.211251315+00:00,160,1,432669,M,A,64.94,1,26,8058565075241,128,14573,94350240,CLX5
2025-09-24 19:40:10.211882775+00:00,160,1,432669,C,A,64.88,2,26,8058566358952,128,13603,94350259,CLX5
2025-09-24 19:40:10.214992135+00:00,160,1,432669,M,A,64.95,1,26,8058565075241,128,14571,94350329,CLX5
2025-09-24 19:40:10.312230911+00:00,160,1,432669,A,B,64.79,2,26,8058566359368,128,17949,94350457,CLX5
2025-09-24 19:40:10.600010125+00:00,160,1,432669,C,B,64.82,1,26,8058566358178,128,19332,94350657,CLX5
2025-09-24 19:40:10.600510339+00:00,160,1,432669,T,A,64.82,1,26,8058566359490,0,17663,94350658,CLX5
2025-09-24 19:40:10.600510339+00:00,160,1,432669,F,B,64.82,1,26,8058566358158,0,17663,94350658,CLX5
2025-09-24 19:40:10.600510339+00:00,160,1,432669,C,B,64.82,1,26,8058566358158,128,16231,94350659,CLX5
2025-09-24 19:40:12.589463389+00:00,160,1,432669,A,B,64.82,2,26,8058566359580,128,20947,94350836,CLX5
2025-09-24 19:40:12.589549575+00:00,160,1,432669,A,B,64.82,1,26,8058566359581,128,16209,94350838,CLX5
2025-09-24 19:40:12.589737803+00:00,160,1,432669,C,A,64.83,1,26,8058566359261,128,15059,94350841,CLX5
2025-09-24 19:40:13.056530953+00:00,160,1,432669,M,B,64.82,4,26,8058566357569,128,24829,94350879,CLX5
2025-09-24 19:40:13.056719815+00:00,160,1,432669,C,A,64.83,1,26,8058566359249,128,18732,94350880,CLX5
2025-09-24 19:40:13.056722273+00:00,160,1,432669,A,B,64.82,1,26,8058566359590,128,15868,94350881,CLX5
2025-09-24 19:40:13.232111317+00:00,160,1,432669,A,A,64.83,1,26,8058566359592,128,18206,94350886,CLX5
2025-09-24 19:40:14.543429801+00:00,160,1,432669,C,A,64.83,2,26,8058566359262,128,14156,94350951,CLX5
2025-09-24 19:40:14.543561585+00:00,160,1,432669,A,B,64.82,1,26,8058566359620,128,15348,94350980,CLX5
2025-09-24 19:40:14.543804645+00:00,160,1,432669,C,A,64.83,2,26,8058566358717,128,15183,94351033,CLX5
2025-09-24 19:40:14.544031951+00:00,160,1,432669,A,B,64.82,2,26,8058566359642,128,17988,94351055,CLX5
2025-09-24 19:40:14.544032127+00:00,160,1,432669,C,A,64.86,2,26,8058566359312,128,14533,94351056,CLX5
2025-09-24 19:40:14.544037589+00:00,160,1,432669,A,B,64.82,1,26,8058566359645,128,14741,94351061,CLX5
2025-09-24 19:40:14.544045999+00:00,160,1,432669,A,B,64.82,1,26,8058566359647,128,14889,94351063,CLX5
2025-09-24 19:40:14.544048993+00:00,160,1,432669,A,B,64.82,1,26,8058566359648,128,14847,94351064,CLX5
2025-09-24 19:40:14.544089581+00:00,160,1,432669,C,A,64.83,1,26,8058566358675,128,15806,94351068,CLX5
2025-09-24 19:40:14.544313077+00:00,160,1,432669,A,B,64.81,2,26,8058566359659,128,14799,94351097,CLX5
2025-09-24 19:40:14.544338593+00:00,160,1,432669,A,B,64.82,1,26,8058566359663,128,19820,94351103,CLX5
2025-09-24 19:40:14.544562341+00:00,160,1,432669,C,A,64.83,1,26,8058566359301,128,19690,94351135,CLX5
2025-09-24 19:40:14.545021161+00:00,160,1,432669,A,B,64.82,1,26,8058566359682,128,15196,94351164,CLX5
2025-09-24 19:40:14.546121119+00:00,160,1,432669,C,B,64.82,1,26,8058566359645,128,19201,94351270,CLX5
2025-09-24 19:40:14.546391943+00:00,160,1,432669,C,B,64.82,1,26,8058566359648,128,14931,94351287,CLX5
2025-09-24 19:40:14.546392691+00:00,160,1,432669,C,B,64.82,1,26,8058566359647,128,18582,94351288,CLX5
2025-09-24 19:40:14.550267981+00:00,160,1,432669,T,B,64.83,3,26,8058566359770,0,14690,94351474,CLX5
2025-09-24 19:40:14.550267981+00:00,160,1,432669,F,A,64.83,2,26,8058566335783,0,14690,94351474,CLX5
2025-09-24 19:40:14.550267981+00:00,160,1,432669,F,A,64.83,1,26,8058566276097,0,14690,94351474,CLX5
2025-09-24 19:40:14.550267981+00:00,160,1,432669,C,A,64.83,2,26,8058566335783,0,16296,94351475,CLX5
2025-09-24 19:40:14.550267981+00:00,160,1,432669,C,A,64.83,1,26,8058566276097,128,16296,94351475,CLX5
2025-09-24 19:40:14.550639371+00:00,160,1,432669,A,B,64.82,1,26,8058566359778,128,19020,94351503,CLX5
2025-09-24 19:40:14.550640581+00:00,160,1,432669,A,B,64.82,1,26,8058566359779,128,15165,94351504,CLX5
2025-09-24 19:40:14.553557529+00:00,160,1,432669,C,B,64.8,1,26,8058566358736,128,14368,94351609,CLX5
2025-09-24 19:40:14.553836721+00:00,160,1,432669,C,B,64.82,1,26,8058566359778,128,18171,94351620,CLX5
2025-09-24 19:40:14.553900809+00:00,160,1,432669,C,B,64.82,1,26,8058566359779,128,15068,94351621,CLX5
2025-09-24 19:40:14.554123711+00:00,160,1,432669,A,B,64.8,1,26,8058566359807,128,14398,94351622,CLX5
2025-09-24 19:40:14.556055643+00:00,160,1,432669,A,A,64.83,1,26,8058566359833,128,15622,94351705,CLX5
2025-09-24 19:40:14.556202807+00:00,160,1,432669,M,A,64.84,1,26,8058566357888,128,19243,94351707,CLX5
2025-09-24 19:40:14.556257121+00:00,160,1,432669,C,A,64.83,1,26,8058566359833,128,15862,94351711,CLX5
2025-09-24 19:40:14.557502627+00:00,160,1,432669,A,A,64.84,1,26,8058566359844,128,17921,94351748,CLX5
2025-09-24 19:40:14.558305419+00:00,160,1,432669,A,A,64.83,1,26,8058566359857,128,16326,94351772,CLX5
2025-09-24 19:40:14.558754335+00:00,160,1,432669,C,A,64.83,1,26,8058566359857,128,15940,94351792,CLX5
2025-09-24 19:40:14.563278155+00:00,160,1,432669,A,A,64.83,1,26,8058566359884,128,16337,94351866,CLX5
2025-09-24 19:40:14.563417637+00:00,160,1,432669,A,B,64.82,1,26,8058566359885,128,17405,94351867,CLX5
2025-09-24 19:40:14.563482069+00:00,160,1,432669,A,B,64.82,1,26,8058566359886,128,15302,94351868,CLX5
2025-09-24 19:40:14.563572131+00:00,160,1,432669,A,B,64.82,1,26,8058566359887,128,18600,94351869,CLX5
2025-09-24 19:40:14.563636429+00:00,160,1,432669,C,B,64.82,1,26,8058566359885,128,18055,94351872,CLX5
2025-09-24 19:40:14.563657721+00:00,160,1,432669,A,B,64.82,1,26,8058566359888,128,15780,94351873,CLX5
2025-09-24 19:40:14.563826807+00:00,160,1,432669,C,A,64.83,1,26,8058566359884,128,19485,94351874,CLX5
2025-09-24 19:40:14.572276451+00:00,160,1,432669,M,A,64.84,1,26,8058566349378,128,20214,94351886,CLX5
2025-09-24 19:40:14.611973389+00:00,160,1,432669,C,B,64.79,2,26,8058566359368,128,17826,94352046,CLX5
2025-09-24 19:40:14.611974271+00:00,160,1,432669,A,A,64.88,2,26,8058566359936,128,14883,94352047,CLX5
2025-09-24 19:40:14.671902737+00:00,160,1,432669,A,A,64.83,1,26,8058566360007,128,14973,94352149,CLX5
2025-09-24 19:40:14.672284687+00:00,160,1,432669,C,A,64.83,1,26,8058566360007,128,16107,94352155,CLX5
2025-09-24 19:40:14.672761939+00:00,160,1,432669,A,A,64.83,1,26,8058566360011,128,19567,94352158,CLX5
2025-09-24 19:40:14.674820395+00:00,160,1,432669,A,B,64.52,1,26,8058566360017,128,17921,94352176,CLX5
2025-09-24 19:40:14.685358425+00:00,160,1,432669,M,A,64.83,1,26,8058566357888,128,16271,94352188,CLX5
2025-09-24 19:40:14.733499553+00:00,160,1,432669,T,A,64.82,1,26,8058566360054,0,17902,94352256,CLX5
2025-09-24 19:40:14.733499553+00:00,160,1,432669,F,B,64.82,1,26,8058566358203,0,17902,94352256,CLX5
2025-09-24 19:40:14.733499553+00:00,160,1,432669,C,B,64.82,1,26,8058566358203,128,14780,94352257,CLX5
2025-09-24 19:40:14.733787983+00:00,160,1,432669,C,B,64.82,2,26,8058566359642,128,18511,94352258,CLX5
2025-09-24 19:40:14.733791457+00:00,160,1,432669,A,A,64.83,2,26,8058566360055,128,16492,94352259,CLX5
2025-09-24 19:40:14.733793417+00:00,160,1,432669,A,A,64.83,1,26,8058566360057,128,14944,94352260,CLX5
2025-09-24 19:40:14.733793877+00:00,160,1,432669,A,A,64.83,1,26,8058566360058,128,18031,94352261,CLX5
2025-09-24 19:40:14.788520467+00:00,160,1,432669,C,A,64.83,1,26,8058566360058,128,19229,94352318,CLX5
2025-09-24 19:40:14.788695563+00:00,160,1,432669,C,B,64.82,1,26,8058566359888,128,18211,94352319,CLX5
2025-09-24 19:40:14.788709961+00:00,160,1,432669,C,B,64.82,1,26,8058566359887,128,14967,94352320,CLX5
2025-09-24 19:40:14.788712191+00:00,160,1,432669,C,B,64.82,1,26,8058566359886,128,15124,94352321,CLX5
2025-09-24 19:40:16.205225735+00:00,160,1,432669,M,A,64.84,1,26,8058566357888,128,20041,94352613,CLX5
2025-09-24 19:40:16.209561497+00:00,160,1,432669,M,A,64.83,1,26,8058566357888,128,19644,94352616,CLX5
2025-09-24 19:40:16.593280127+00:00,160,1,432669,C,A,64.83,1,26,8058566360057,128,19677,94352671,CLX5
2025-09-24 19:40:16.593300727+00:00,160,1,432669,C,A,64.83,1,26,8058566360011,128,16009,94352672,CLX5
2025-09-24 19:40:16.593515221+00:00,160,1,432669,A,A,64.83,1,26,8058566360260,128,21067,94352674,CLX5
2025-09-24 19:40:16.593646369+00:00,160,1,432669,A,A,64.83,1,26,8058566360261,128,19081,94352677,CLX5
2025-09-24 19:40:16.707320351+00:00,160,1,432669,M,A,64.84,1,26,8058566357888,128,19352,94352710,CLX5
2025-09-24 19:40:16.711491347+00:00,160,1,432669,M,A,64.83,1,26,8058566357888,128,20067,94352712,CLX5
2025-09-24 19:40:18.469007057+00:00,160,1,432669,A,B,64.82,2,26,8058566360367,128,20638,94352936,CLX5
2025-09-24 19:40:18.469384051+00:00,160,1,432669,C,A,64.83,1,26,8058566360261,128,21396,94352938,CLX5
2025-09-24 19:40:19.004444803+00:00,160,1,432669,A,A,64.83,1,26,8058566360371,128,15835,94352953,CLX5
2025-09-24 19:40:19.005999455+00:00,160,1,432669,A,B,64.82,11,26,8058566360382,128,18297,94352980,CLX5
2025-09-24 19:40:19.010067775+00:00,160,1,432669,M,A,64.84,1,26,8058566357888,128,19243,94353015,CLX5
2025-09-24 19:40:19.014185417+00:00,160,1,432669,M,A,64.83,1,26,8058566357888,128,20045,94353033,CLX5
2025-09-24 19:40:20.103413167+00:00,160,1,432669,M,A,64.84,1,26,8058566357888,128,22470,94353077,CLX5
2025-09-24 19:40:20.107752617+00:00,160,1,432669,M,A,64.83,1,26,8058566357888,128,19943,94353085,CLX5
2025-09-24 19:40:20.425028505+00:00,160,1,432669,C,A,64.83,1,26,8058566360371,128,18232,94353104,CLX5
2025-09-24 19:40:20.425256765+00:00,160,1,432669,C,A,64.83,1,26,8058566360260,128,19024,94353109,CLX5
2025-09-24 19:40:20.551917107+00:00,160,1,432669,M,A,64.85,1,26,8058566354507,128,15252,94353198,CLX5
2025-09-24 19:40:20.604182135+00:00,160,1,432669,M,A,64.84,1,26,8058566357888,128,19479,94353324,CLX5
2025-09-24 19:40:22.010076775+00:00,160,1,432669,A,A,64.83,4,26,8058566360505,128,19410,94353371,CLX5
2025-09-24 19:40:23.097853279+00:00,160,1,432669,A,A,64.83,1,26,8058566360518,128,20419,94353406,CLX5
2025-09-24 19:40:25.272451065+00:00,160,1,432669,C,A,64.83,4,26,8058566360505,128,20381,94353429,CLX5
2025-09-24 19:40:25.385676417+00:00,160,1,432669,A,A,64.83,1,26,8058566360528,128,19558,94353431,CLX5
2025-09-24 19:40:25.385941941+00:00,160,1,432669,A,A,64.83,1,26,8058566360530,128,19559,94353433,CLX5
2025-09-24 19:40:26.899930747+00:00,160,1,432669,A,A,64.83,1,26,8058566360556,128,19249,94353530,CLX5
2025-09-24 19:40:27.372170255+00:00,160,1,432669,C,A,64.83,1,26,8058566360556,128,18834,94353565,CLX5
2025-09-24 19:40:28.100914287+00:00,160,1,432669,A,A,64.84,1,26,8058566360573,128,20976,94353572,CLX5
2025-09-24 19:40:32.198417827+00:00,160,1,432669,A,A,64.83,1,26,8058566360593,128,20039,94353610,CLX5
2025-09-24 19:40:32.425279989+00:00,160,1,432669,C,A,64.83,1,26,8058566360593,128,20081,94353921,CLX5
2025-09-24 19:40:32.426226775+00:00,160,1,432669,A,B,64.82,1,26,8058566360707,128,18465,94353977,CLX5
2025-09-24 19:40:32.428558861+00:00,160,1,432669,C,B,64.82,1,26,8058566360707,128,14049,94354096,CLX5
2025-09-24 19:40:32.430955431+00:00,160,1,432669,A,B,64.82,1,26,8058566360787,128,15049,94354241,CLX5
2025-09-24 19:40:32.432667863+00:00,160,1,432669,C,B,64.82,1,26,8058566360787,128,15095,94354331,CLX5
2025-09-24 19:40:32.938203365+00:00,160,1,432669,C,B,64.78,1,26,8058566338864,128,18272,94355049,CLX5
2025-09-24 19:40:35.982194431+00:00,160,1,432669,C,A,64.86,1,26,8058566358118,128,18842,94355239,CLX5
2025-09-24 19:40:36.056281563+00:00,160,1,432669,A,A,64.84,1,26,8058566361263,128,18078,94355248,CLX5
2025-09-24 19:40:37.197698863+00:00,160,1,432669,A,A,64.83,1,26,8058566361294,128,14952,94355324,CLX5
2025-09-24 19:40:37.197706273+00:00,160,1,432669,A,A,64.83,1,26,8058566361295,128,19442,94355325,CLX5
2025-09-24 19:40:37.197829609+00:00,160,1,432669,A,A,64.83,2,26,8058566361297,128,15610,94355328,CLX5
2025-09-24 19:40:37.197846735+00:00,160,1,432669,A,A,64.83,1,26,8058566361299,128,14569,94355330,CLX5
2025-09-24 19:40:37.197854223+00:00,160,1,432669,A,A,64.83,1,26,8058566361300,128,14917,94355332,CLX5
2025-09-24 19:40:37.197921841+00:00,160,1,432669,C,B,64.8,1,26,8058566359807,128,14721,94355339,CLX5
2025-09-24 19:40:37.198109205+00:00,160,1,432669,C,B,64.82,1,26,8058566359590,128,15068,94355349,CLX5
2025-09-24 19:40:37.198149655+00:00,160,1,432669,C,B,64.81,2,26,8058566359659,128,14721,94355357,CLX5
2025-09-24 19:40:37.198683451+00:00,160,1,432669,C,B,64.82,1,26,8058566359663,128,15430,94355424,CLX5
2025-09-24 19:40:37.198701211+00:00,160,1,432669,A,B,64.82,1,26,8058566361324,128,18533,94355426,CLX5
2025-09-24 19:40:37.198702669+00:00,160,1,432669,A,A,64.86,2,26,8058566361326,128,15027,94355427,CLX5
2025-09-24 19:40:37.198985511+00:00,160,1,432669,C,B,64.82,1,26,8058566359620,128,16705,94355445,CLX5
2025-09-24 19:40:37.199341789+00:00,160,1,432669,C,A,64.83,1,26,8058566361300,128,14621,94355463,CLX5
2025-09-24 19:40:37.199358801+00:00,160,1,432669,C,A,64.83,1,26,8058566361294,128,14959,94355468,CLX5
2025-09-24 19:40:37.199720801+00:00,160,1,432669,A,A,64.83,1,26,8058566361347,128,15073,94355487,CLX5
2025-09-24 19:40:37.199765115+00:00,160,1,432669,A,A,64.83,1,26,8058566361350,128,18638,94355497,CLX5
2025-09-24 19:40:37.199850203+00:00,160,1,432669,M,A,64.83,1,26,8058566349378,128,19338,94355502,CLX5
2025-09-24 19:40:37.200182713+00:00,160,1,432669,M,A,64.84,3,26,8058566342145,128,14789,94355529,CLX5
2025-09-24 19:40:37.200201281+00:00,160,1,432669,C,A,64.83,1,26,8058566361347,128,18748,94355530,CLX5
2025-09-24 19:40:37.200370463+00:00,160,1,432669,C,A,64.83,1,26,8058566361350,128,19024,94355541,CLX5
2025-09-24 19:40:37.200885307+00:00,160,1,432669,C,A,64.83,1,26,8058566361295,128,15197,94355563,CLX5
2025-09-24 19:40:37.200886133+00:00,160,1,432669,A,A,64.83,1,26,8058566361372,128,19090,94355565,CLX5
2025-09-24 19:40:37.201530629+00:00,160,1,432669,C,A,64.83,1,26,8058566361372,128,16166,94355583,CLX5
2025-09-24 19:40:37.202705943+00:00,160,1,432669,A,A,64.83,1,26,8058566361391,128,18684,94355624,CLX5
2025-09-24 19:40:37.202771221+00:00,160,1,432669,C,A,64.83,1,26,8058566361391,128,15542,94355630,CLX5
2025-09-24 19:40:37.203045691+00:00,160,1,432669,A,A,64.83,1,26,8058566361393,128,15533,94355636,CLX5
2025-09-24 19:40:37.203701517+00:00,160,1,432669,C,A,64.83,1,26,8058566361393,128,17342,94355667,CLX5
2025-09-24 19:40:37.203704933+00:00,160,1,432669,A,A,64.83,1,26,8058566361401,128,15545,94355668,CLX5
2025-09-24 19:40:37.203875039+00:00,160,1,432669,C,A,64.83,1,26,8058566361401,128,15554,94355675,CLX5
2025-09-24 19:40:37.204400229+00:00,160,1,432669,A,A,64.83,1,26,8058566361408,128,18792,94355691,CLX5
2025-09-24 19:40:37.204429279+00:00,160,1,432669,C,A,64.83,1,26,8058566361408,128,15553,94355693,CLX5
2025-09-24 19:40:37.204823707+00:00,160,1,432669,A,A,64.83,1,26,8058566361410,128,15645,94355711,CLX5
2025-09-24 19:40:37.205108639+00:00,160,1,432669,C,A,64.83,1,26,8058566361410,128,19273,94355716,CLX5
2025-09-24 19:40:37.205135979+00:00,160,1,432669,M,A,64.83,1,26,8058566357888,128,16211,94355717,CLX5
2025-09-24 19:40:37.208199109+00:00,160,1,432669,A,B,64.8,1,26,8058566361422,128,13655,94355746,CLX5
2025-09-24 19:40:37.212024021+00:00,160,1,432669,C,A,64.88,2,26,8058566359936,128,18430,94355754,CLX5
2025-09-24 19:40:37.312362423+00:00,160,1,432669,A,B,64.79,2,26,8058566361454,128,17895,94355847,CLX5
2025-09-24 19:40:37.312367763+00:00,160,1,432669,A,B,64.78,2,26,8058566361455,128,14504,94355848,CLX5
2025-09-24 19:40:37.699374281+00:00,160,1,432669,A,A,64.83,1,26,8058566361538,128,20066,94356013,CLX5
2025-09-24 19:40:39.607229981+00:00,160,1,432669,T,B,64.83,13,26,8058566361658,0,18506,94356336,CLX5
2025-09-24 19:40:39.607229981+00:00,160,1,432669,F,A,64.83,1,26,8058566345605,0,18506,94356336,CLX5
2025-09-24 19:40:39.607229981+00:00,160,1,432669,F,A,64.83,1,26,8058566345702,0,18506,94356336,CLX5
2025-09-24 19:40:39.607229981+00:00,160,1,432669,F,A,64.83,1,26,8058566356987,0,18506,94356336,CLX5
2025-09-24 19:40:39.607229981+00:00,160,1,432669,F,A,64.83,1,26,8058566358182,0,18506,94356336,CLX5
2025-09-24 19:40:39.607229981+00:00,160,1,432669,F,A,64.83,1,26,8058566358954,0,18506,94356336,CLX5
2025-09-24 19:40:39.607229981+00:00,160,1,432669,F,A,64.83,1,26,8058566359202,0,18506,94356336,CLX5
2025-09-24 19:40:39.607229981+00:00,160,1,432669,F,A,64.83,1,26,8058566359592,0,18506,94356336,CLX5
2025-09-24 19:40:39.607229981+00:00,160,1,432669,F,A,64.83,2,26,8058566360055,0,18506,94356336,CLX5
2025-09-24 19:40:39.607229981+00:00,160,1,432669,F,A,64.83,1,26,8058566360518,0,18506,94356336,CLX5
2025-09-24 19:40:39.607229981+00:00,160,1,432669,F,A,64.83,1,26,8058566360528,0,18506,94356336,CLX5
2025-09-24 19:40:39.607229981+00:00,160,1,432669,F,A,64.83,1,26,8058566360530,0,18506,94356336,CLX5
2025-09-24 19:40:39.607229981+00:00,160,1,432669,F,A,64.83,1,26,8058566361297,0,18506,94356336,CLX5
2025-09-24 19:40:39.607229981+00:00,160,1,432669,C,A,64.83,1,26,8058566345605,0,16195,94356337,CLX5
2025-09-24 19:40:39.607229981+00:00,160,1,432669,C,A,64.83,1,26,8058566345702,0,16195,94356337,CLX5
2025-09-24 19:40:39.607229981+00:00,160,1,432669,C,A,64.83,1,26,8058566356987,0,16195,94356337,CLX5
2025-09-24 19:40:39.607229981+00:00,160,1,432669,C,A,64.83,1,26,8058566358182,0,16195,94356337,CLX5
2025-09-24 19:40:39.607229981+00:00,160,1,432669,C,A,64.83,1,26,8058566358954,0,16195,94356337,CLX5
2025-09-24 19:40:39.607229981+00:00,160,1,432669,C,A,64.83,1,26,8058566359202,0,16195,94356337,CLX5
2025-09-24 19:40:39.607229981+00:00,160,1,432669,C,A,64.83,1,26,8058566359592,0,16195,94356337,CLX5
2025-09-24 19:40:39.607229981+00:00,160,1,432669,C,A,64.83,2,26,8058566360055,0,16195,94356337,CLX5
2025-09-24 19:40:39.607229981+00:00,160,1,432669,C,A,64.83,1,26,8058566360518,0,16195,94356337,CLX5
2025-09-24 19:40:39.607229981+00:00,160,1,432669,C,A,64.83,1,26,8058566360528,0,16195,94356337,CLX5
2025-09-24 19:40:39.607229981+00:00,160,1,432669,C,A,64.83,1,26,8058566360530,0,16195,94356337,CLX5
2025-09-24 19:40:39.607229981+00:00,160,1,432669,M,A,64.83,1,26,8058566361297,128,16195,94356337,CLX5
2025-09-24 19:40:39.607232515+00:00,160,1,432669,C,B,64.82,1,26,8058566361324,128,18355,94356338,CLX5
2025-09-24 19:40:39.607427597+00:00,160,1,432669,C,B,64.82,2,26,8058566360367,128,17251,94356339,CLX5
2025-09-24 19:40:39.607646659+00:00,160,1,432669,C,A,64.83,1,26,8058566361538,128,21262,94356342,CLX5
2025-09-24 19:40:39.607658467+00:00,160,1,432669,A,A,64.83,1,26,8058566361663,128,18882,94356344,CLX5
2025-09-24 19:40:39.607724973+00:00,160,1,432669,A,B,64.82,1,26,8058566361665,128,15228,94356346,CLX5
2025-09-24 19:40:39.607728717+00:00,160,1,432669,A,B,64.82,1,26,8058566361666,128,14740,94356347,CLX5
2025-09-24 19:40:39.607728891+00:00,160,1,432669,A,B,64.82,1,26,8058566361667,128,17835,94356348,CLX5
2025-09-24 19:40:39.607742233+00:00,160,1,432669,A,B,64.82,1,26,8058566361668,128,14748,94356349,CLX5
2025-09-24 19:40:39.607803209+00:00,160,1,432669,A,A,64.83,2,26,8058566361675,128,16148,94356364,CLX5
2025-09-24 19:40:39.607817147+00:00,160,1,432669,C,B,64.82,1,26,8058566361666,128,15512,94356368,CLX5
2025-09-24 19:40:39.607838209+00:00,160,1,432669,C,B,64.82,1,26,8058566361667,128,15328,94356379,CLX5
2025-09-24 19:40:39.607851265+00:00,160,1,432669,A,A,64.83,1,26,8058566361679,128,16742,94356385,CLX5
2025-09-24 19:40:39.607851533+00:00,160,1,432669,A,A,64.83,1,26,8058566361680,128,16126,94356386,CLX5
2025-09-24 19:40:39.607857735+00:00,160,1,432669,A,A,64.83,2,26,8058566361681,128,19490,94356387,CLX5
2025-09-24 19:40:39.607869369+00:00,160,1,432669,C,B,64.82,1,26,8058566361668,128,17903,94356390,CLX5
2025-09-24 19:40:39.607919191+00:00,160,1,432669,A,A,64.83,1,26,8058566361684,128,18960,94356400,CLX5
2025-09-24 19:40:39.607921019+00:00,160,1,432669,A,A,64.83,1,26,8058566361686,128,16010,94356402,CLX5
2025-09-24 19:40:39.607926545+00:00,160,1,432669,A,A,64.83,1,26,8058566361687,128,15929,94356403,CLX5
2025-09-24 19:40:39.607976559+00:00,160,1,432669,C,A,64.83,1,26,8058566361299,128,16496,94356405,CLX5
2025-09-24 19:40:39.608028051+00:00,160,1,432669,M,A,64.83,1,26,8058566358671,128,15467,94356414,CLX5
2025-09-24 19:40:39.608055909+00:00,160,1,432669,A,A,64.83,1,26,8058566361689,128,16078,94356418,CLX5
2025-09-24 19:40:39.608082269+00:00,160,1,432669,M,B,63.66,4,26,8058566319508,128,18054,94356419,CLX5
2025-09-24 19:40:39.608358507+00:00,160,1,432669,A,B,64.8,1,26,8058566361692,128,17433,94356428,CLX5
2025-09-24 19:40:39.608949207+00:00,160,1,432669,C,A,64.83,2,26,8058566361681,128,19237,94356454,CLX5
2025-09-24 19:40:39.608978755+00:00,160,1,432669,C,B,64.82,1,26,8058566361665,128,14107,94356456,CLX5
2025-09-24 19:40:39.610446741+00:00,160,1,432669,A,B,64.82,1,26,8058566361706,128,14678,94356484,CLX5
2025-09-24 19:40:39.610501343+00:00,160,1,432669,C,B,64.82,1,26,8058566361706,128,14846,94356485,CLX5
2025-09-24 19:40:39.610514917+00:00,160,1,432669,A,B,64.82,1,26,8058566361707,128,18116,94356486,CLX5
2025-09-24 19:40:39.610907827+00:00,160,1,432669,A,B,64.82,1,26,8058566361708,128,15049,94356487,CLX5
2025-09-24 19:40:39.611064339+00:00,160,1,432669,C,B,64.82,1,26,8058566361708,128,17752,94356490,CLX5
2025-09-24 19:40:39.611202533+00:00,160,1,432669,A,B,64.82,1,26,8058566361709,128,18207,94356491,CLX5
2025-09-24 19:40:39.611205953+00:00,160,1,432669,A,B,64.82,1,26,8058566361710,128,13633,94356492,CLX5
2025-09-24 19:40:39.611414455+00:00,160,1,432669,M,A,64.84,1,26,8058566349378,128,19689,94356493,CLX5
2025-09-24 19:40:39.615566617+00:00,160,1,432669,C,B,64.82,1,26,8058566361707,128,14647,94356519,CLX5
2025-09-24 19:40:39.615746111+00:00,160,1,432669,C,B,64.82,1,26,8058566361710,128,18198,94356520,CLX5
2025-09-24 19:40:39.615764581+00:00,160,1,432669,A,B,64.82,1,26,8058566361716,128,14885,94356521,CLX5
2025-09-24 19:40:39.615885975+00:00,160,1,432669,A,B,64.82,1,26,8058566361717,128,18436,94356522,CLX5
2025-09-24 19:40:39.615924873+00:00,160,1,432669,A,B,64.82,1,26,8058566361718,128,14889,94356523,CLX5
2025-09-24 19:40:39.616012959+00:00,160,1,432669,C,B,64.82,1,26,8058566361709,128,20069,94356524,CLX5
2025-09-24 19:40:39.617962537+00:00,160,1,432669,A,A,64.83,1,26,8058566361719,128,19656,94356525,CLX5
2025-09-24 19:40:39.784178857+00:00,160,1,432669,C,B,64.8,1,26,8058566361692,128,17826,94356613,CLX5
2025-09-24 19:40:40.070742571+00:00,160,1,432669,T,B,64.83,3,26,8058566361807,0,18168,94356778,CLX5
2025-09-24 19:40:40.070742571+00:00,160,1,432669,F,A,64.83,1,26,8058566361297,0,18168,94356778,CLX5
2025-09-24 19:40:40.070742571+00:00,160,1,432669,F,A,64.83,1,26,8058566357888,0,18168,94356778,CLX5
2025-09-24 19:40:40.070742571+00:00,160,1,432669,F,A,64.83,1,26,8058566361663,0,18168,94356778,CLX5
2025-09-24 19:40:40.070742571+00:00,160,1,432669,C,A,64.83,1,26,8058566361297,0,15974,94356779,CLX5
2025-09-24 19:40:40.070742571+00:00,160,1,432669,C,A,64.83,1,26,8058566357888,0,15974,94356779,CLX5
2025-09-24 19:40:40.070742571+00:00,160,1,432669,C,A,64.83,1,26,8058566361663,128,15974,94356779,CLX5
2025-09-24 19:40:40.071073105+00:00,160,1,432669,C,A,64.83,1,26,8058566361689,128,19456,94356780,CLX5
2025-09-24 19:40:40.071075005+00:00,160,1,432669,C,A,64.83,1,26,8058566361686,128,16376,94356783,CLX5
2025-09-24 19:40:40.071109639+00:00,160,1,432669,A,A,64.83,1,26,8058566361810,128,18987,94356784,CLX5
2025-09-24 19:40:40.071113365+00:00,160,1,432669,A,B,64.82,1,26,8058566361811,128,15605,94356785,CLX5
2025-09-24 19:40:40.078566477+00:00,160,1,432669,A,A,64.83,1,26,8058566361816,128,19384,94356809,CLX5
2025-09-24 19:40:40.081274055+00:00,160,1,432669,A,A,64.83,1,26,8058566361818,128,18769,94356811,CLX5
2025-09-24 19:40:40.128291667+00:00,160,1,432669,C,B,64.82,1,26,8058566361718,128,18402,94356828,CLX5
2025-09-24 19:40:40.128310635+00:00,160,1,432669,C,B,64.82,1,26,8058566361717,128,14699,94356829,CLX5
2025-09-24 19:40:40.128461869+00:00,160,1,432669,C,B,64.82,1,26,8058566361716,128,18410,94356830,CLX5
2025-09-24 19:40:40.169411491+00:00,160,1,432669,C,A,65.45,10,26,8058565931419,128,18419,94356835,CLX5
2025-09-24 19:40:40.235486741+00:00,160,1,432669,A,A,64.83,2,26,8058566361834,128,19586,94356849,CLX5
2025-09-24 19:40:40.235643501+00:00,160,1,432669,A,A,64.83,1,26,8058566361835,128,19162,94356850,CLX5
2025-09-24 19:40:40.619340163+00:00,160,1,432669,C,A,64.83,1,26,8058566361835,128,14980,94356911,CLX5
2025-09-24 19:40:40.619341449+00:00,160,1,432669,A,B,64.82,1,26,8058566361866,128,18578,94356912,CLX5
2025-09-24 19:40:40.619383919+00:00,160,1,432669,C,A,64.83,2,26,8058566361834,128,16240,94356913,CLX5
2025-09-24 19:40:40.619567501+00:00,160,1,432669,C,B,64.82,1,26,8058566361866,128,14913,94356926,CLX5
2025-09-24 19:40:40.619579061+00:00,160,1,432669,C,A,64.86,2,26,8058566361326,128,13632,94356928,CLX5
2025-09-24 19:40:40.619747867+00:00,160,1,432669,C,A,64.83,1,26,8058566361719,128,15911,94356939,CLX5
2025-09-24 19:40:40.619748433+00:00,160,1,432669,C,A,64.83,1,26,8058566361818,128,14706,94356940,CLX5
2025-09-24 19:40:40.619928713+00:00,160,1,432669,A,B,64.82,1,26,8058566361873,128,17144,94356944,CLX5
2025-09-24 19:40:40.627045955+00:00,160,1,432669,M,A,64.84,1,26,8058566361816,128,20291,94356957,CLX5
2025-09-24 19:40:40.627227867+00:00,160,1,432669,A,B,64.82,1,26,8058566361878,128,18248,94356958,CLX5
2025-09-24 19:40:40.627361359+00:00,160,1,432669,C,B,64.82,1,26,8058566361873,128,19223,94356959,CLX5
2025-09-24 19:40:40.627381057+00:00,160,1,432669,A,B,64.82,1,26,8058566361879,128,14721,94356960,CLX5
2025-09-24 19:40:40.627509711+00:00,160,1,432669,A,B,64.82,1,26,8058566361880,128,18291,94356961,CLX5
2025-09-24 19:40:40.712045309+00:00,160,1,432669,A,A,64.88,2,26,8058566361892,128,18845,94356987,CLX5
2025-09-24 19:40:41.234465375+00:00,160,1,432669,C,B,64.82,1,26,8058566361880,128,18444,94357072,CLX5
2025-09-24 19:40:41.234472653+00:00,160,1,432669,C,B,64.82,1,26,8058566361879,128,16029,94357073,CLX5
2025-09-24 19:40:41.234646023+00:00,160,1,432669,C,B,64.82,1,26,8058566361878,128,18105,94357074,CLX5
2025-09-24 19:40:41.234652685+00:00,160,1,432669,A,A,64.83,2,26,8058566361940,128,16454,94357075,CLX5
2025-09-24 19:40:41.234875547+00:00,160,1,432669,A,A,64.83,1,26,8058566361941,128,19135,94357076,CLX5
2025-09-24 19:40:41.235012629+00:00,160,1,432669,A,A,64.83,1,26,8058566361942,128,19210,94357077,CLX5
2025-09-24 19:40:42.144224093+00:00,160,1,432669,A,A,64.83,2,26,8058566361955,128,23128,94357094,CLX5
2025-09-24 19:40:43.202567681+00:00,160,1,432669,A,A,64.83,2,26,8058566361982,128,21527,94357186,CLX5
2025-09-24 19:40:43.306022931+00:00,160,1,432669,C,A,64.83,2,26,8058566361982,128,21214,94357202,CLX5
2025-09-24 19:40:43.306182573+00:00,160,1,432669,C,A,64.83,1,26,8058566361941,128,21260,94357203,CLX5
2025-09-24 19:40:43.306312205+00:00,160,1,432669,A,B,64.82,1,26,8058566361986,128,20674,94357204,CLX5
2025-09-24 19:40:43.306450841+00:00,160,1,432669,C,B,64.82,1,26,8058566361986,128,21331,94357205,CLX5
2025-09-24 19:40:44.740929047+00:00,160,1,432669,C,A,64.83,1,26,8058566361942,128,21585,94357225,CLX5
2025-09-24 19:40:44.741000525+00:00,160,1,432669,A,A,64.83,1,26,8058566361992,128,18316,94357226,CLX5
2025-09-24 19:40:45.350189859+00:00,160,1,432669,C,A,64.83,2,26,8058566361955,128,24872,94357243,CLX5
2025-09-24 19:40:45.350198691+00:00,160,1,432669,C,A,64.83,2,26,8058566361940,128,18141,94357244,CLX5
2025-09-24 19:40:45.350341799+00:00,160,1,432669,C,A,64.83,1,26,8058566361810,128,22536,94357245,CLX5
2025-09-24 19:40:47.171803045+00:00,160,1,432669,M,B,64.82,1,26,8058566130074,128,24411,94357257,CLX5
2025-09-24 19:40:47.172018787+00:00,160,1,432669,A,B,64.82,1,26,8058566361998,128,22289,94357258,CLX5
2025-09-24 19:40:47.318419871+00:00,160,1,432669,A,B,64.82,1,26,8058566362000,128,23689,94357274,CLX5
2025-09-24 19:40:47.318578593+00:00,160,1,432669,C,B,64.82,1,26,8058566361998,128,20815,94357275,CLX5
2025-09-24 19:40:47.318600535+00:00,160,1,432669,A,B,64.82,1,26,8058566362001,128,17537,94357276,CLX5
2025-09-24 19:40:47.318737617+00:00,160,1,432669,A,B,64.82,1,26,8058566362002,128,20602,94357277,CLX5
2025-09-24 19:40:47.318865369+00:00,160,1,432669,C,A,64.83,1,26,8058566361680,128,22055,94357278,CLX5
2025-09-24 19:40:47.319071031+00:00,160,1,432669,C,A,64.83,1,26,8058566361687,128,17685,94357285,CLX5
2025-09-24 19:40:47.406417269+00:00,160,1,432669,T,B,64.83,6,26,8058566362009,0,21296,94357301,CLX5
2025-09-24 19:40:47.406417269+00:00,160,1,432669,F,A,64.83,2,26,8058566361675,0,21296,94357301,CLX5
2025-09-24 19:40:47.406417269+00:00,160,1,432669,F,A,64.83,1,26,8058566361679,0,21296,94357301,CLX5
2025-09-24 19:40:47.406417269+00:00,160,1,432669,F,A,64.83,1,26,8058566361684,0,21296,94357301,CLX5
2025-09-24 19:40:47.406417269+00:00,160,1,432669,F,A,64.83,1,26,8058566358671,0,21296,94357301,CLX5
2025-09-24 19:40:47.406417269+00:00,160,1,432669,F,A,64.83,1,26,8058566361992,0,21296,94357301,CLX5
2025-09-24 19:40:47.406417269+00:00,160,1,432669,A,B,64.83,2,26,8058566362009,0,19367,94357302,CLX5
2025-09-24 19:40:47.406417269+00:00,160,1,432669,C,A,64.83,2,26,8058566361675,0,19367,94357302,CLX5
2025-09-24 19:40:47.406417269+00:00,160,1,432669,C,A,64.83,1,26,8058566361679,0,19367,94357302,CLX5
2025-09-24 19:40:47.406417269+00:00,160,1,432669,C,A,64.83,1,26,8058566361684,0,19367,94357302,CLX5
2025-09-24 19:40:47.406417269+00:00,160,1,432669,C,A,64.83,1,26,8058566358671,0,19367,94357302,CLX5
2025-09-24 19:40:47.406417269+00:00,160,1,432669,C,A,64.83,1,26,8058566361992,128,19367,94357302,CLX5
2025-09-24 19:40:47.406753043+00:00,160,1,432669,A,B,64.82,1,26,8058566362014,128,18037,94357311,CLX5
2025-09-24 19:40:47.406772109+00:00,160,1,432669,C,B,64.82,1,26,8058566362014,128,22607,94357313,CLX5
2025-09-24 19:40:47.406910283+00:00,160,1,432669,C,B,64.8,1,26,8058566361422,128,18078,94357340,CLX5
2025-09-24 19:40:47.406919731+00:00,160,1,432669,A,B,64.82,3,26,8058566362025,128,15377,94357343,CLX5
2025-09-24 19:40:47.406930731+00:00,160,1,432669,A,A,64.84,1,26,8058566362027,128,18427,94357346,CLX5
2025-09-24 19:40:47.407263739+00:00,160,1,432669,M,B,64.81,1,26,8058566319508,128,14904,94357367,CLX5
2025-09-24 19:40:47.407376305+00:00,160,1,432669,C,A,64.84,1,26,8058566362027,128,15069,94357370,CLX5
2025-09-24 19:40:47.407383295+00:00,160,1,432669,A,B,64.8,1,26,8058566362033,128,18591,94357372,CLX5
2025-09-24 19:40:47.407398443+00:00,160,1,432669,A,B,64.83,1,26,8058566362034,128,14449,94357373,CLX5
2025-09-24 19:40:47.407472955+00:00,160,1,432669,A,B,64.81,2,26,8058566362037,128,18489,94357383,CLX5
2025-09-24 19:40:47.407481057+00:00,160,1,432669,C,B,64.78,2,26,8058566361455,128,13633,94357385,CLX5
2025-09-24 19:40:47.407751841+00:00,160,1,432669,A,B,64.83,1,26,8058566362048,128,20617,94357407,CLX5
2025-09-24 19:40:47.407956733+00:00,160,1,432669,M,B,64.82,4,26,8058566346145,128,14653,94357419,CLX5
2025-09-24 19:40:47.407993883+00:00,160,1,432669,M,A,65.99,4,26,8058566342145,128,15018,94357422,CLX5
2025-09-24 19:40:47.408221529+00:00,160,1,432669,M,A,64.85,1,26,8058566173085,128,15033,94357428,CLX5
2025-09-24 19:40:47.408522629+00:00,160,1,432669,A,A,64.84,1,26,8058566362053,128,14074,94357437,CLX5
2025-09-24 19:40:47.409441251+00:00,160,1,432669,C,B,64.83,1,26,8058566362048,128,18786,94357445,CLX5
2025-09-24 19:40:47.409841225+00:00,160,1,432669,M,B,64.82,1,26,8058566349770,128,14972,94357452,CLX5
2025-09-24 19:40:47.410526695+00:00,160,1,432669,A,B,64.81,1,26,8058566362058,128,17362,94357468,CLX5
2025-09-24 19:40:47.412086855+00:00,160,1,432669,C,B,64.79,2,26,8058566361454,128,18178,94357550,CLX5
2025-09-24 19:40:47.412581541+00:00,160,1,432669,M,B,64.49,10,26,8058566151203,128,14734,94357582,CLX5
2025-09-24 19:40:47.425221073+00:00,160,1,432669,T,A,64.83,1,26,8058566362121,0,14543,94357693,CLX5
2025-09-24 19:40:47.425221073+00:00,160,1,432669,F,B,64.83,1,26,8058566362009,0,14543,94357693,CLX5
2025-09-24 19:40:47.425221073+00:00,160,1,432669,M,B,64.83,1,26,8058566362009,128,18507,94357694,CLX5
2025-09-24 19:40:47.425538685+00:00,160,1,432669,T,A,64.83,2,26,8058566362122,0,18030,94357699,CLX5
2025-09-24 19:40:47.425538685+00:00,160,1,432669,F,B,64.83,1,26,8058566362034,0,18030,94357699,CLX5
2025-09-24 19:40:47.425538685+00:00,160,1,432669,F,B,64.83,1,26,8058566362009,0,18030,94357699,CLX5
2025-09-24 19:40:47.425538685+00:00,160,1,432669,C,B,64.83,1,26,8058566362034,0,16523,94357700,CLX5
2025-09-24 19:40:47.425538685+00:00,160,1,432669,M,B,64.83,2,26,8058566362009,128,16523,94357700,CLX5
2025-09-24 19:40:47.425603501+00:00,160,1,432669,C,A,64.84,1,26,8058566362053,128,16523,94357700,CLX5
2025-09-24 19:40:47.425652151+00:00,160,1,432669,T,A,64.83,1,26,8058566362126,0,14610,94357704,CLX5
2025-09-24 19:40:47.425652151+00:00,160,1,432669,F,B,64.83,1,26,8058566362009,0,14610,94357704,CLX5
2025-09-24 19:40:47.425652151+00:00,160,1,432669,M,B,64.83,1,26,8058566362009,128,18022,94357705,CLX5
2025-09-24 19:40:47.425652977+00:00,160,1,432669,T,A,64.83,2,26,8058566362127,0,14699,94357707,CLX5
2025-09-24 19:40:47.425652977+00:00,160,1,432669,F,B,64.83,2,26,8058566362009,0,14699,94357707,CLX5
2025-09-24 19:40:47.425652977+00:00,160,1,432669,M,B,64.83,1,26,8058566362009,128,16699,94357708,CLX5
2025-09-24 19:40:47.425829649+00:00,160,1,432669,T,A,64.83,1,26,8058566362130,0,14839,94357718,CLX5
2025-09-24 19:40:47.425829649+00:00,160,1,432669,F,B,64.83,1,26,8058566362009,0,14839,94357718,CLX5
2025-09-24 19:40:47.425829649+00:00,160,1,432669,M,B,64.83,2,26,8058566362009,128,14582,94357719,CLX5
2025-09-24 19:40:47.425860367+00:00,160,1,432669,A,B,64.83,2,26,8058566362134,128,14428,94357729,CLX5
2025-09-24 19:40:47.426005377+00:00,160,1,432669,A,A,64.84,1,26,8058566362138,128,14991,94357737,CLX5
2025-09-24 19:40:47.426030049+00:00,160,1,432669,C,B,64.82,4,26,8058566346145,128,14666,94357738,CLX5
2025-09-24 19:40:47.426158585+00:00,160,1,432669,A,A,64.87,2,26,8058566362141,128,18268,94357749,CLX5
2025-09-24 19:40:47.426254237+00:00,160,1,432669,A,A,64.88,2,26,8058566362143,128,14173,94357755,CLX5
2025-09-24 19:40:47.426259825+00:00,160,1,432669,C,A,64.84,1,26,8058566362138,128,18410,94357757,CLX5
2025-09-24 19:40:47.426304079+00:00,160,1,432669,C,B,64.81,2,26,8058566362037,128,14560,94357760,CLX5
2025-09-24 19:40:47.426445653+00:00,160,1,432669,C,A,64.84,1,26,8058566359844,128,15197,94357763,CLX5
2025-09-24 19:40:47.426486241+00:00,160,1,432669,A,B,64.83,1,26,8058566362146,128,16969,94357764,CLX5
2025-09-24 19:40:47.427159593+00:00,160,1,432669,A,A,64.84,1,26,8058566362151,128,13627,94357775,CLX5
2025-09-24 19:40:47.427265283+00:00,160,1,432669,C,B,64.81,1,26,8058566362058,128,14400,94357784,CLX5
2025-09-24 19:40:47.430007133+00:00,160,1,432669,T,A,64.83,1,26,8058566362156,0,17064,94357791,CLX5
2025-09-24 19:40:47.430007133+00:00,160,1,432669,F,B,64.83,1,26,8058566362009,0,17064,94357791,CLX5
2025-09-24 19:40:47.430007133+00:00,160,1,432669,M,B,64.83,1,26,8058566362009,128,17064,94357791,CLX5
2025-09-24 19:40:47.430265939+00:00,160,1,432669,C,B,64.83,1,26,8058566362146,128,21071,94357793,CLX5
2025-09-24 19:40:47.432622039+00:00,160,1,432669,T,A,64.83,1,26,8058566362161,0,16215,94357801,CLX5
2025-09-24 19:40:47.432622039+00:00,160,1,432669,F,B,64.83,1,26,8058566362009,0,16215,94357801,CLX5
2025-09-24 19:40:47.432622039+00:00,160,1,432669,M,B,64.83,2,26,8058566362009,128,16215,94357801,CLX5
2025-09-24 19:40:47.432909681+00:00,160,1,432669,C,B,64.83,2,26,8058566362134,128,18249,94357803,CLX5
2025-09-24 19:40:47.441315897+00:00,160,1,432669,T,A,64.83,1,26,8058566362168,0,16565,94357821,CLX5
2025-09-24 19:40:47.441315897+00:00,160,1,432669,F,B,64.83,1,26,8058566362009,0,16565,94357821,CLX5
2025-09-24 19:40:47.441315897+00:00,160,1,432669,M,B,64.83,1,26,8058566362009,128,16565,94357821,CLX5
2025-09-24 19:40:47.441638979+00:00,160,1,432669,T,A,64.83,1,26,8058566362169,0,17954,94357824,CLX5
2025-09-24 19:40:47.441638979+00:00,160,1,432669,F,B,64.83,1,26,8058566362009,0,17954,94357824,CLX5
2025-09-24 19:40:47.441638979+00:00,160,1,432669,M,B,64.83,2,26,8058566362009,128,14370,94357825,CLX5
2025-09-24 19:40:47.441641667+00:00,160,1,432669,T,A,64.83,2,26,8058566362170,0,15145,94357827,CLX5
2025-09-24 19:40:47.441641667+00:00,160,1,432669,F,B,64.83,2,26,8058566362009,0,15145,94357827,CLX5
2025-09-24 19:40:47.441641667+00:00,160,1,432669,M,B,64.83,2,26,8058566362009,128,15145,94357827,CLX5
2025-09-24 19:40:47.441656757+00:00,160,1,432669,A,B,64.82,1,26,8058566362171,128,15390,94357828,CLX5
2025-09-24 19:40:47.441871557+00:00,160,1,432669,A,B,64.82,1,26,8058566362172,128,18117,94357829,CLX5
2025-09-24 19:40:47.441919863+00:00,160,1,432669,C,A,64.84,1,26,8058566362151,128,15742,94357830,CLX5
2025-09-24 19:40:47.442049113+00:00,160,1,432669,A,A,64.84,1,26,8058566362174,128,15231,94357832,CLX5
2025-09-24 19:40:47.442218641+00:00,160,1,432669,A,B,64.83,1,26,8058566362176,128,17974,94357837,CLX5
2025-09-24 19:40:47.442662005+00:00,160,1,432669,C,B,64.82,1,26,8058566362172,128,19065,94357848,CLX5
2025-09-24 19:40:47.445616025+00:00,160,1,432669,T,A,64.83,1,26,8058566362185,0,16401,94357866,CLX5
2025-09-24 19:40:47.445616025+00:00,160,1,432669,F,B,64.83,1,26,8058566362009,0,16401,94357866,CLX5
2025-09-24 19:40:47.445616025+00:00,160,1,432669,M,B,64.83,1,26,8058566362009,128,16401,94357866,CLX5
2025-09-24 19:40:47.445868131+00:00,160,1,432669,C,B,64.83,1,26,8058566362176,128,18218,94357869,CLX5
2025-09-24 19:40:47.445902075+00:00,160,1,432669,T,A,64.83,1,26,8058566362186,0,17838,94357872,CLX5
2025-09-24 19:40:47.445902075+00:00,160,1,432669,F,B,64.83,1,26,8058566362009,0,17838,94357872,CLX5
2025-09-24 19:40:47.445902075+00:00,160,1,432669,C,B,64.83,1,26,8058566362009,128,14536,94357873,CLX5
2025-09-24 19:40:47.446127013+00:00,160,1,432669,A,B,64.82,1,26,8058566362187,128,17836,94357879,CLX5
2025-09-24 19:40:47.446134673+00:00,160,1,432669,C,B,64.82,1,26,8058566362171,128,14993,94357881,CLX5
2025-09-24 19:40:47.455718179+00:00,160,1,432669,A,A,64.84,1,26,8058566362196,128,18755,94357907,CLX5
2025-09-24 19:40:47.455719349+00:00,160,1,432669,A,A,64.83,2,26,8058566362197,128,14547,94357908,CLX5
2025-09-24 19:40:47.455856951+00:00,160,1,432669,A,A,64.83,2,26,8058566362198,128,14534,94357912,CLX5
2025-09-24 19:40:47.455913069+00:00,160,1,432669,A,A,64.83,1,26,8058566362203,128,15846,94357920,CLX5
2025-09-24 19:40:47.456053261+00:00,160,1,432669,M,A,64.83,2,26,8058566362143,128,17797,94357924,CLX5
2025-09-24 19:40:47.456145245+00:00,160,1,432669,A,B,64.8,1,26,8058566362206,128,14817,94357926,CLX5
2025-09-24 19:40:47.456419735+00:00,160,1,432669,T,B,64.83,2,26,8058566362210,0,17923,94357930,CLX5
2025-09-24 19:40:47.456419735+00:00,160,1,432669,F,A,64.83,2,26,8058566362197,0,17923,94357930,CLX5
2025-09-24 19:40:47.456419735+00:00,160,1,432669,C,A,64.83,2,26,8058566362197,128,18779,94357931,CLX5
2025-09-24 19:40:47.456697663+00:00,160,1,432669,C,A,64.84,1,26,8058566362174,128,17850,94357938,CLX5
2025-09-24 19:40:47.456712733+00:00,160,1,432669,C,B,64.82,1,26,8058566362187,128,13708,94357940,CLX5
2025-09-24 19:40:47.457567135+00:00,160,1,432669,T,B,64.83,2,26,8058566362214,0,17779,94357942,CLX5
2025-09-24 19:40:47.457567135+00:00,160,1,432669,F,A,64.83,2,26,8058566362198,0,17779,94357942,CLX5
2025-09-24 19:40:47.457567135+00:00,160,1,432669,C,A,64.83,2,26,8058566362198,128,15345,94357943,CLX5
2025-09-24 19:40:47.457823941+00:00,160,1,432669,T,B,64.83,3,26,8058566362215,0,18416,94357949,CLX5
2025-09-24 19:40:47.457823941+00:00,160,1,432669,F,A,64.83,1,26,8058566362203,0,18416,94357949,CLX5
2025-09-24 19:40:47.457823941+00:00,160,1,432669,F,A,64.83,2,26,8058566362143,0,18416,94357949,CLX5
2025-09-24 19:40:47.457823941+00:00,160,1,432669,C,A,64.83,1,26,8058566362203,0,14786,94357950,CLX5
2025-09-24 19:40:47.457823941+00:00,160,1,432669,C,A,64.83,2,26,8058566362143,128,14786,94357950,CLX5
2025-09-24 19:40:47.457974655+00:00,160,1,432669,A,B,64.82,1,26,8058566362220,128,18356,94357958,CLX5
2025-09-24 19:40:47.458142667+00:00,160,1,432669,A,A,64.84,1,26,8058566362221,128,15198,94357959,CLX5
2025-09-24 19:40:47.464799935+00:00,160,1,432669,A,B,64.82,1,26,8058566362234,128,18461,94357999,CLX5
2025-09-24 19:40:47.468319215+00:00,160,1,432669,T,A,64.82,1,26,8058566362236,0,18050,94358002,CLX5
2025-09-24 19:40:47.468319215+00:00,160,1,432669,F,B,64.82,1,26,8058566358204,0,18050,94358002,CLX5
2025-09-24 19:40:47.468319215+00:00,160,1,432669,M,B,64.82,1,26,8058566358204,128,15132,94358003,CLX5
2025-09-24 19:40:47.469850501+00:00,160,1,432669,A,A,64.83,1,26,8058566362240,128,18008,94358007,CLX5
2025-09-24 19:40:47.470210833+00:00,160,1,432669,M,A,64.83,2,26,8058566362141,128,17489,94358012,CLX5
2025-09-24 19:40:47.512109219+00:00,160,1,432669,A,B,64.81,2,26,8058566362253,128,19029,94358043,CLX5
2025-09-24 19:40:47.512264619+00:00,160,1,432669,C,B,64.82,1,26,8058566362234,128,18017,94358044,CLX5
2025-09-24 19:40:47.515280535+00:00,160,1,432669,C,B,64.82,1,26,8058566358471,128,18421,94358048,CLX5
2025-09-24 19:40:47.515979117+00:00,160,1,432669,C,B,64.81,2,26,8058566362253,128,18342,94358049,CLX5
2025-09-24 19:40:47.584224713+00:00,160,1,432669,C,B,64.8,1,26,8058566362033,128,22318,94358107,CLX5
2025-09-24 19:40:47.612068555+00:00,160,1,432669,A,B,64.79,2,26,8058566362305,128,22453,94358120,CLX5
2025-09-24 19:40:47.632881855+00:00,160,1,432669,A,B,64.82,4,26,8058566362312,128,20750,94358127,CLX5
2025-09-24 19:40:47.642665457+00:00,160,1,432669,T,A,64.82,1,26,8058566362314,0,18375,94358130,CLX5
2025-09-24 19:40:47.642665457+00:00,160,1,432669,F,B,64.82,1,26,8058566358204,0,18375,94358130,CLX5
2025-09-24 19:40:47.642665457+00:00,160,1,432669,C,B,64.82,1,26,8058566358204,128,14900,94358131,CLX5
2025-09-24 19:40:47.712054017+00:00,160,1,432669,A,B,64.78,2,26,8058566362327,128,18766,94358159,CLX5
2025-09-24 19:40:48.574316193+00:00,160,1,432669,C,A,64.84,1,26,8058566362221,128,18289,94358216,CLX5
2025-09-24 19:40:48.868565903+00:00,160,1,432669,T,B,64.83,2,26,8058566362395,0,17878,94358306,CLX5
2025-09-24 19:40:48.868565903+00:00,160,1,432669,F,A,64.83,1,26,8058566362240,0,17878,94358306,CLX5
2025-09-24 19:40:48.868565903+00:00,160,1,432669,F,A,64.83,1,26,8058566362141,0,17878,94358306,CLX5
2025-09-24 19:40:48.868565903+00:00,160,1,432669,C,A,64.83,1,26,8058566362240,0,14704,94358307,CLX5
2025-09-24 19:40:48.868565903+00:00,160,1,432669,M,A,64.83,1,26,8058566362141,128,14704,94358307,CLX5
2025-09-24 19:40:48.868945777+00:00,160,1,432669,T,B,64.83,1,26,8058566362403,0,15109,94358331,CLX5
2025-09-24 19:40:48.868945777+00:00,160,1,432669,F,A,64.83,1,26,8058566362141,0,15109,94358331,CLX5
2025-09-24 19:40:48.868945777+00:00,160,1,432669,C,A,64.83,1,26,8058566362141,128,14999,94358332,CLX5
2025-09-24 19:40:48.869316301+00:00,160,1,432669,C,A,64.84,1,26,8058566362196,128,17009,94358351,CLX5
2025-09-24 19:40:48.869343795+00:00,160,1,432669,A,A,64.84,1,26,8058566362410,128,13953,94358359,CLX5
2025-09-24 19:40:48.869442325+00:00,160,1,432669,A,B,64.8,1,26,8058566362411,128,14544,94358361,CLX5
2025-09-24 19:40:48.870257407+00:00,160,1,432669,A,B,64.81,2,26,8058566362417,128,14641,94358382,CLX5
2025-09-24 19:40:48.870263645+00:00,160,1,432669,C,B,64.78,2,26,8058566362327,128,14855,94358385,CLX5
2025-09-24 19:40:48.870421597+00:00,160,1,432669,A,B,64.82,1,26,8058566362421,128,16076,94358389,CLX5
2025-09-24 19:40:48.878491461+00:00,160,1,432669,A,B,64.83,2,26,8058566362429,128,14643,94358431,CLX5
2025-09-24 19:40:48.878621727+00:00,160,1,432669,A,B,64.83,1,26,8058566362433,128,17370,94358443,CLX5
2025-09-24 19:40:48.878669573+00:00,160,1,432669,A,B,64.83,1,26,8058566362439,128,20483,94358455,CLX5
2025-09-24 19:40:48.878723407+00:00,160,1,432669,A,B,64.83,2,26,8058566362441,128,20342,94358459,CLX5
2025-09-24 19:40:48.878758869+00:00,160,1,432669,A,B,64.83,2,26,8058566362445,128,16065,94358470,CLX5
2025-09-24 19:40:48.878760871+00:00,160,1,432669,A,B,64.83,2,26,8058566362448,128,15357,94358473,CLX5
2025-09-24 19:40:48.878761497+00:00,160,1,432669,A,B,64.82,2,26,8058566362449,128,14770,94358474,CLX5
2025-09-24 19:40:48.878769447+00:00,160,1,432669,C,A,64.84,2,26,8058566329004,128,15034,94358478,CLX5
2025-09-24 19:40:48.878878631+00:00,160,1,432669,A,B,64.82,2,26,8058566362456,128,14740,94358493,CLX5
2025-09-24 19:40:48.879029901+00:00,160,1,432669,C,B,64.8,1,26,8058566362206,128,17191,94358533,CLX5
2025-09-24 19:40:48.879058663+00:00,160,1,432669,A,B,64.83,1,26,8058566362474,128,15422,94358535,CLX5
2025-09-24 19:40:48.879066535+00:00,160,1,432669,C,B,64.81,1,26,8058566358154,128,15747,94358538,CLX5
2025-09-24 19:40:48.879071563+00:00,160,1,432669,A,B,64.83,1,26,8058566362476,128,15782,94358542,CLX5
2025-09-24 19:40:48.879173493+00:00,160,1,432669,A,B,64.83,1,26,8058566362483,128,15291,94358552,CLX5
2025-09-24 19:40:48.879755419+00:00,160,1,432669,A,B,64.83,2,26,8058566362492,128,18395,94358577,CLX5
2025-09-24 19:40:48.879858747+00:00,160,1,432669,M,B,64.82,4,26,8058566345944,128,14738,94358583,CLX5
2025-09-24 19:40:48.880625543+00:00,160,1,432669,C,B,64.83,2,26,8058566362492,128,18574,94358628,CLX5
2025-09-24 19:40:48.881715499+00:00,160,1,432669,C,B,64.83,1,26,8058566362476,128,18805,94358703,CLX5
2025-09-24 19:40:48.885048703+00:00,160,1,432669,C,B,64.83,2,26,8058566362441,128,18868,94358832,CLX5
2025-09-24 19:40:48.891520775+00:00,160,1,432669,C,B,64.83,1,26,8058566362474,128,19368,94358949,CLX5
2025-09-24 19:40:48.891529049+00:00,160,1,432669,A,B,64.81,1,26,8058566362586,128,14495,94358951,CLX5
2025-09-24 19:40:48.892146571+00:00,160,1,432669,C,A,64.84,1,26,8058566362410,128,17265,94358971,CLX5
2025-09-24 19:40:48.892373311+00:00,160,1,432669,A,B,64.83,1,26,8058566362608,128,15448,94358982,CLX5
2025-09-24 19:40:48.892393991+00:00,160,1,432669,A,B,64.83,1,26,8058566362613,128,17332,94358990,CLX5
2025-09-24 19:40:48.892407103+00:00,160,1,432669,A,B,64.83,1,26,8058566362615,128,15253,94358994,CLX5
2025-09-24 19:40:48.892507881+00:00,160,1,432669,M,A,64.96,1,26,8058565075241,128,14692,94359000,CLX5
2025-09-24 19:40:48.892681211+00:00,160,1,432669,C,A,64.84,2,26,8058566328837,128,14928,94359009,CLX5
2025-09-24 19:40:48.893020535+00:00,160,1,432669,A,B,64.83,1,26,8058566362629,128,15004,94359041,CLX5
2025-09-24 19:40:48.893119411+00:00,160,1,432669,C,B,64.83,1,26,8058566362615,128,15038,94359046,CLX5
2025-09-24 19:40:48.894293363+00:00,160,1,432669,A,B,64.83,1,26,8058566362652,128,15319,94359182,CLX5
2025-09-24 19:40:48.894488503+00:00,160,1,432669,C,B,64.83,1,26,8058566362652,128,15223,94359193,CLX5
2025-09-24 19:40:48.895147957+00:00,160,1,432669,A,A,64.84,1,26,8058566362661,128,14891,94359217,CLX5
2025-09-24 19:40:48.895501085+00:00,160,1,432669,A,B,64.83,1,26,8058566362663,128,15398,94359228,CLX5
2025-09-24 19:40:48.895936023+00:00,160,1,432669,C,B,64.83,1,26,8058566362663,128,18800,94359242,CLX5
2025-09-24 19:40:48.896386781+00:00,160,1,432669,A,B,64.83,2,26,8058566362687,128,14892,94359321,CLX5
2025-09-24 19:40:48.897262129+00:00,160,1,432669,M,A,64.95,1,26,8058565075241,128,15128,94359384,CLX5
2025-09-24 19:40:48.898217439+00:00,160,1,432669,M,A,64.86,1,26,8058566354507,128,14448,94359456,CLX5
2025-09-24 19:40:48.899155241+00:00,160,1,432669,M,A,64.96,1,26,8058565075241,128,14743,94359495,CLX5
2025-09-24 19:40:48.899336395+00:00,160,1,432669,C,B,64.83,1,26,8058566362613,128,15158,94359510,CLX5
2025-09-24 19:40:48.899614081+00:00,160,1,432669,C,B,64.83,1,26,8058566362629,128,14554,94359517,CLX5
2025-09-24 19:40:48.899702475+00:00,160,1,432669,C,B,64.83,2,26,8058566362687,128,14178,94359519,CLX5
2025-09-24 19:40:48.899948913+00:00,160,1,432669,M,A,64.95,1,26,8058565075241,128,15125,94359524,CLX5
2025-09-24 19:40:48.900636015+00:00,160,1,432669,M,A,64.96,1,26,8058565075241,128,14263,94359556,CLX5
2025-09-24 19:40:48.907235685+00:00,160,1,432669,A,A,64.84,1,26,8058566362808,128,15531,94359870,CLX5
2025-09-24 19:40:48.907526091+00:00,160,1,432669,C,B,64.83,1,26,8058566362608,128,15042,94359874,CLX5
2025-09-24 19:40:48.908882165+00:00,160,1,432669,C,B,64.83,1,26,8058566362439,128,15791,94359924,CLX5
2025-09-24 19:40:48.909084199+00:00,160,1,432669,A,A,64.84,1,26,8058566362827,128,16044,94359934,CLX5
2025-09-24 19:40:48.910069327+00:00,160,1,432669,M,A,64.95,1,26,8058565075241,128,16019,94360047,CLX5
2025-09-24 19:40:48.910743293+00:00,160,1,432669,A,A,64.84,1,26,8058566362865,128,15463,94360072,CLX5
2025-09-24 19:40:48.912159441+00:00,160,1,432669,C,B,64.79,2,26,8058566362305,128,14895,94360137,CLX5
2025-09-24 19:40:48.912185035+00:00,160,1,432669,M,A,64.96,1,26,8058565075241,128,14093,94360141,CLX5
2025-09-24 19:40:48.913108053+00:00,160,1,432669,A,B,64.83,1,26,8058566362898,128,20105,94360185,CLX5
2025-09-24 19:40:48.921071713+00:00,160,1,432669,M,A,64.95,1,26,8058565075241,128,14113,94360346,CLX5
2025-09-24 19:40:48.926649293+00:00,160,1,432669,M,A,64.96,1,26,8058565075241,128,14147,94360386,CLX5
2025-09-24 19:40:48.930723639+00:00,160,1,432669,A,B,64.83,1,26,8058566362944,128,19199,94360403,CLX5
2025-09-24 19:40:48.951132685+00:00,160,1,432669,C,B,64.82,4,26,8058566362312,128,18159,94360484,CLX5
2025-09-24 19:40:49.007379435+00:00,160,1,432669,C,B,64.83,2,26,8058566362445,128,17710,94360719,CLX5
2025-09-24 19:40:49.008141843+00:00,160,1,432669,M,A,64.95,1,26,8058565075241,128,15266,94360761,CLX5
2025-09-24 19:40:49.008478001+00:00,160,1,432669,C,B,64.83,1,26,8058566362944,128,15863,94360773,CLX5
2025-09-24 19:40:49.018613811+00:00,160,1,432669,A,B,64.83,1,26,8058566363077,128,18410,94360844,CLX5
2025-09-24 19:40:49.018780977+00:00,160,1,432669,M,A,64.96,1,26,8058565075241,128,16144,94360855,CLX5
2025-09-24 19:40:49.068899675+00:00,160,1,432669,A,B,64.83,4,26,8058566363202,128,19349,94361071,CLX5
2025-09-24 19:40:49.069039443+00:00,160,1,432669,A,B,64.83,2,26,8058566363203,128,19086,94361072,CLX5
2025-09-24 19:40:49.069041305+00:00,160,1,432669,A,B,64.83,1,26,8058566363204,128,15026,94361073,CLX5
2025-09-24 19:40:49.069045145+00:00,160,1,432669,A,B,64.83,1,26,8058566363205,128,15161,94361074,CLX5
2025-09-24 19:40:49.165637101+00:00,160,1,432669,C,B,64.83,1,26,8058566363205,128,18297,94361254,CLX5
2025-09-24 19:40:49.165761895+00:00,160,1,432669,C,B,64.83,2,26,8058566363203,128,18771,94361255,CLX5
2025-09-24 19:40:49.165771743+00:00,160,1,432669,C,B,64.83,1,26,8058566363204,128,15075,94361256,CLX5
2025-09-24 19:40:49.190999489+00:00,160,1,432669,M,A,64.95,1,26,8058565075241,128,17855,94361307,CLX5
2025-09-24 19:40:49.203526513+00:00,160,1,432669,M,A,64.96,1,26,8058565075241,128,14054,94361333,CLX5
2025-09-24 19:40:49.530673127+00:00,160,1,432669,C,B,64.82,1,26,8058566362002,128,19590,94361544,CLX5
2025-09-24 19:40:49.530687699+00:00,160,1,432669,C,B,64.82,1,26,8058566362001,128,14883,94361545,CLX5
2025-09-24 19:40:49.530707839+00:00,160,1,432669,A,A,64.86,1,26,8058566363455,128,14719,94361546,CLX5
2025-09-24 19:40:49.605764795+00:00,160,1,432669,C,B,64.82,1,26,8058566362000,128,18643,94361556,CLX5
2025-09-24 19:40:49.900008937+00:00,160,1,432669,C,B,64.83,1,26,8058566362483,128,19710,94361594,CLX5
2025-09-24 19:40:50.008576593+00:00,160,1,432669,A,B,64.8,5,26,8058566363486,128,19192,94361614,CLX5
2025-09-24 19:40:50.008756105+00:00,160,1,432669,C,B,64.81,1,26,8058566362586,128,17968,94361615,CLX5
2025-09-24 19:40:51.189515679+00:00,160,1,432669,M,B,64.83,11,26,8058566360382,128,18348,94361864,CLX5
2025-09-24 19:40:51.401848309+00:00,160,1,432669,M,B,64.81,1,26,8058566197138,128,18798,94361896,CLX5
2025-09-24 19:40:51.872724449+00:00,160,1,432669,A,B,64.83,1,26,8058566363626,128,18176,94361917,CLX5
2025-09-24 19:40:51.875136189+00:00,160,1,432669,A,B,64.83,1,26,8058566363628,128,18229,94361919,CLX5
2025-09-24 19:40:53.292146815+00:00,160,1,432669,A,A,65.97,1,26,8058566363632,128,20420,94361954,CLX5
2025-09-24 19:40:53.797648645+00:00,160,1,432669,A,A,64.84,1,26,8058566363633,128,22062,94361956,CLX5
2025-09-24 19:40:53.797860239+00:00,160,1,432669,C,B,64.83,1,26,8058566363628,128,21880,94361957,CLX5
2025-09-24 19:40:54.372713885+00:00,160,1,432669,A,B,64.83,1,26,8058566363638,128,17447,94361973,CLX5
2025-09-24 19:40:55.138157267+00:00,160,1,432669,A,B,64.83,1,26,8058566363652,128,16202,94362037,CLX5
2025-09-24 19:40:55.138786521+00:00,160,1,432669,C,B,64.83,1,26,8058566363652,128,14791,94362104,CLX5
2025-09-24 19:40:55.154750539+00:00,160,1,432669,C,B,64.83,1,26,8058566363638,128,14712,94362566,CLX5
2025-09-24 19:40:55.737948561+00:00,160,1,432669,A,B,64.83,1,26,8058566363934,128,13905,94362904,CLX5
2025-09-24 19:40:55.738131949+00:00,160,1,432669,A,B,64.83,1,26,8058566363936,128,18286,94362906,CLX5
2025-09-24 19:40:58.888710397+00:00,160,1,432669,C,B,64.76,2,26,8058564529110,128,18132,94363267,CLX5
2025-09-24 19:41:00.092663039+00:00,160,1,432669,C,B,64.83,1,26,8058566363936,128,18943,94363465,CLX5
2025-09-24 19:41:00.092684791+00:00,160,1,432669,C,B,64.83,1,26,8058566363934,128,14754,94363466,CLX5
2025-09-24 19:41:00.592307173+00:00,160,1,432669,C,A,64.86,1,26,8058566363455,128,18222,94363538,CLX5
2025-09-24 19:41:00.838673299+00:00,160,1,432669,A,B,64.83,1,26,8058566364185,128,17654,94363542,CLX5
2025-09-24 19:41:01.678017091+00:00,160,1,432669,A,B,64.82,1,26,8058566364191,128,19332,94363565,CLX5
2025-09-24 19:41:02.265494401+00:00,160,1,432669,C,B,64.83,1,26,8058566364185,128,15219,94363646,CLX5
2025-09-24 19:41:02.265996555+00:00,160,1,432669,C,A,64.84,2,26,8058566324579,128,19478,94363698,CLX5
2025-09-24 19:41:02.265998877+00:00,160,1,432669,C,A,64.87,2,26,8058566358030,128,13695,94363704,CLX5
2025-09-24 19:41:02.266000067+00:00,160,1,432669,C,A,64.84,1,26,8058566319356,128,15119,94363705,CLX5
2025-09-24 19:41:02.266012565+00:00,160,1,432669,C,A,64.84,2,26,8058566307859,128,14922,94363709,CLX5
2025-09-24 19:41:02.266021263+00:00,160,1,432669,C,A,64.84,1,26,8058566307923,128,15191,94363713,CLX5
2025-09-24 19:41:02.266022377+00:00,160,1,432669,A,B,64.83,1,26,8058566364234,128,22009,94363718,CLX5
2025-09-24 19:41:02.266030883+00:00,160,1,432669,A,B,64.83,1,26,8058566364236,128,15131,94363720,CLX5
2025-09-24 19:41:02.266061351+00:00,160,1,432669,A,B,64.83,1,26,8058566364240,128,15831,94363731,CLX5
2025-09-24 19:41:02.266105549+00:00,160,1,432669,C,A,64.84,1,26,8058566362661,128,16240,94363740,CLX5
2025-09-24 19:41:02.266198281+00:00,160,1,432669,C,A,64.84,1,26,8058566319355,128,14720,94363752,CLX5
2025-09-24 19:41:02.266209875+00:00,160,1,432669,T,B,64.84,1,26,8058566364249,0,18362,94363754,CLX5
2025-09-24 19:41:02.266209875+00:00,160,1,432669,F,A,64.84,1,26,8058566274106,0,18362,94363754,CLX5
2025-09-24 19:41:02.266209875+00:00,160,1,432669,C,A,64.84,1,26,8058566274106,128,15346,94363755,CLX5
2025-09-24 19:41:02.266383207+00:00,160,1,432669,C,B,64.83,1,26,8058566364240,128,14850,94363768,CLX5
2025-09-24 19:41:02.266426903+00:00,160,1,432669,A,B,64.81,1,26,8058566364251,128,14884,94363772,CLX5
2025-09-24 19:41:02.266632431+00:00,160,1,432669,A,B,64.83,1,26,8058566364265,128,14628,94363802,CLX5
2025-09-24 19:41:02.267168317+00:00,160,1,432669,A,B,64.82,2,26,8058566364279,128,15187,94363834,CLX5
2025-09-24 19:41:02.267497161+00:00,160,1,432669,A,B,64.83,2,26,8058566364287,128,14729,94363845,CLX5
2025-09-24 19:41:02.267499675+00:00,160,1,432669,C,A,64.84,3,26,8058566307931,128,15320,94363846,CLX5
2025-09-24 19:41:02.267958709+00:00,160,1,432669,C,A,64.84,1,26,8058566274281,128,14093,94363870,CLX5
2025-09-24 19:41:02.268131079+00:00,160,1,432669,C,A,64.87,1,26,8058566329645,128,14368,94363876,CLX5
2025-09-24 19:41:02.268146285+00:00,160,1,432669,T,N,64.84,1,26,0,0,14652,94363877,CLX5
2025-09-24 19:41:02.268146285+00:00,160,1,432669,F,N,64.84,1,26,8058566307934,0,14652,94363877,CLX5
2025-09-24 19:41:02.268146285+00:00,160,1,432669,C,A,64.84,1,26,8058566307934,128,20711,94363878,CLX5
2025-09-24 19:41:02.268341405+00:00,160,1,432669,A,A,64.84,1,26,8058566364299,128,16133,94363882,CLX5
2025-09-24 19:41:02.268476163+00:00,160,1,432669,A,B,64.83,1,26,8058566364302,128,15114,94363887,CLX5
2025-09-24 19:41:02.268570815+00:00,160,1,432669,A,B,64.83,1,26,8058566364303,128,15152,94363892,CLX5
2025-09-24 19:41:02.268922755+00:00,160,1,432669,A,A,64.84,2,26,8058566364306,128,14108,94363902,CLX5
2025-09-24 19:41:02.268995347+00:00,160,1,432669,C,B,64.83,1,26,8058566364302,128,14947,94363904,CLX5
2025-09-24 19:41:02.269541429+00:00,160,1,432669,T,N,64.84,1,26,0,0,13473,94363911,CLX5
2025-09-24 19:41:02.269541429+00:00,160,1,432669,F,N,64.84,1,26,8058566329855,0,13473,94363911,CLX5
2025-09-24 19:41:02.269541429+00:00,160,1,432669,C,A,64.84,1,26,8058566329855,128,16168,94363912,CLX5
2025-09-24 19:41:02.269556211+00:00,160,1,432669,C,B,64.82,2,26,8058566364279,128,18668,94363913,CLX5
2025-09-24 19:41:02.272213931+00:00,160,1,432669,M,A,64.85,1,26,8058566349378,128,16029,94363991,CLX5
2025-09-24 19:41:02.273323239+00:00,160,1,432669,A,B,64.81,1,26,8058566364346,128,14788,94364038,CLX5
2025-09-24 19:41:02.273898425+00:00,160,1,432669,C,B,64.83,1,26,8058566364234,128,14871,94364044,CLX5
2025-09-24 19:41:02.274603093+00:00,160,1,432669,M,A,64.85,1,26,8058566361816,128,15536,94364076,CLX5
2025-09-24 19:41:02.276026155+00:00,160,1,432669,A,A,64.84,1,26,8058566364362,128,15073,94364096,CLX5
2025-09-24 19:41:02.277109177+00:00,160,1,432669,A,A,64.84,1,26,8058566364368,128,15153,94364118,CLX5
2025-09-24 19:41:02.277292683+00:00,160,1,432669,A,A,64.84,3,26,8058566364370,128,18992,94364123,CLX5
2025-09-24 19:41:02.277330831+00:00,160,1,432669,A,A,64.84,2,26,8058566364372,128,14919,94364126,CLX5
2025-09-24 19:41:02.278375669+00:00,160,1,432669,C,B,64.83,1,26,8058566364303,128,14621,94364175,CLX5
2025-09-24 19:41:02.278685947+00:00,160,1,432669,A,A,64.84,1,26,8058566364389,128,18290,94364193,CLX5
2025-09-24 19:41:02.278694107+00:00,160,1,432669,C,B,64.83,2,26,8058566364287,128,14745,94364195,CLX5
2025-09-24 19:41:02.278757465+00:00,160,1,432669,A,A,64.84,2,26,8058566364393,128,15030,94364199,CLX5
2025-09-24 19:41:02.278958497+00:00,160,1,432669,A,A,64.87,1,26,8058566364396,128,14443,94364205,CLX5
2025-09-24 19:41:02.279090147+00:00,160,1,432669,C,B,64.83,1,26,8058566364265,128,18410,94364212,CLX5
2025-09-24 19:41:02.279096617+00:00,160,1,432669,C,A,64.84,2,26,8058566364393,128,15118,94364213,CLX5
2025-09-24 19:41:02.279566669+00:00,160,1,432669,M,A,64.95,1,26,8058565075241,128,17115,94364234,CLX5
2025-09-24 19:41:02.279765381+00:00,160,1,432669,A,A,64.84,1,26,8058566364411,128,15080,94364246,CLX5
2025-09-24 19:41:02.279929705+00:00,160,1,432669,T,A,64.83,1,26,8058566364417,0,14875,94364263,CLX5
2025-09-24 19:41:02.279929705+00:00,160,1,432669,F,B,64.83,1,26,8058566362429,0,14875,94364263,CLX5
2025-09-24 19:41:02.279929705+00:00,160,1,432669,M,B,64.83,1,26,8058566362429,128,19022,94364264,CLX5
2025-09-24 19:41:02.280019653+00:00,160,1,432669,A,A,64.84,2,26,8058566364420,128,15362,94364270,CLX5
2025-09-24 19:41:02.280036897+00:00,160,1,432669,C,B,64.83,1,26,8058566362433,128,17568,94364275,CLX5
2025-09-24 19:41:02.280046917+00:00,160,1,432669,C,B,64.83,2,26,8058566362448,128,14898,94364277,CLX5
2025-09-24 19:41:02.280470853+00:00,160,1,432669,C,B,64.83,1,26,8058566362429,128,16810,94364308,CLX5
2025-09-24 19:41:02.280505277+00:00,160,1,432669,C,B,64.83,1,26,8058566363077,128,18638,94364311,CLX5
2025-09-24 19:41:02.281030951+00:00,160,1,432669,A,A,64.87,2,26,8058566364431,128,14723,94364329,CLX5
2025-09-24 19:41:02.283612719+00:00,160,1,432669,M,A,64.84,1,26,8058566361816,128,16589,94364400,CLX5
2025-09-24 19:41:02.287711679+00:00,160,1,432669,M,A,64.84,1,26,8058566349378,128,19092,94364420,CLX5
2025-09-24 19:41:02.292361657+00:00,160,1,432669,A,A,64.87,2,26,8058566364454,128,17938,94364426,CLX5
2025-09-24 19:41:02.292740763+00:00,160,1,432669,C,B,64.83,1,26,8058566364236,128,14747,94364438,CLX5
2025-09-24 19:41:02.295497589+00:00,160,1,432669,T,B,64.84,2,26,8058566364467,0,17899,94364491,CLX5
2025-09-24 19:41:02.295497589+00:00,160,1,432669,F,A,64.84,1,26,8058566357446,0,17899,94364491,CLX5
2025-09-24 19:41:02.295497589+00:00,160,1,432669,F,A,64.84,1,26,8058566360573,0,17899,94364491,CLX5
2025-09-24 19:41:02.295497589+00:00,160,1,432669,C,A,64.84,1,26,8058566357446,0,15430,94364492,CLX5
2025-09-24 19:41:02.295497589+00:00,160,1,432669,C,A,64.84,1,26,8058566360573,128,15430,94364492,CLX5
2025-09-24 19:41:02.295828159+00:00,160,1,432669,A,B,64.83,1,26,8058566364471,128,14683,94364501,CLX5
2025-09-24 19:41:02.295835417+00:00,160,1,432669,C,A,64.84,2,26,8058566364420,128,19220,94364504,CLX5
2025-09-24 19:41:02.314409215+00:00,160,1,432669,C,B,64.74,2,26,8058566262123,128,19526,94364595,CLX5
2025-09-24 19:41:02.337440499+00:00,160,1,432669,M,A,64.96,1,26,8058565075241,128,14679,94364648,CLX5
2025-09-24 19:41:02.444300179+00:00,160,1,432669,C,B,64.81,1,26,8058566364251,128,18729,94364820,CLX5
2025-09-24 19:41:02.577417889+00:00,160,1,432669,A,A,64.84,1,26,8058566364660,128,19172,94364900,CLX5
2025-09-24 19:41:03.399922837+00:00,160,1,432669,C,A,65.08,1,26,8058566358089,128,18271,94365019,CLX5
2025-09-24 19:41:03.415431029+00:00,160,1,432669,A,A,65.07,1,26,8058566364716,128,18973,94365020,CLX5
2025-09-24 19:41:03.572908315+00:00,160,1,432669,T,B,64.84,1,26,8058566364719,0,18221,94365026,CLX5
2025-09-24 19:41:03.572908315+00:00,160,1,432669,F,A,64.84,1,26,8058566361263,0,18221,94365026,CLX5
2025-09-24 19:41:03.572908315+00:00,160,1,432669,C,A,64.84,1,26,8058566361263,128,16444,94365027,CLX5
2025-09-24 19:41:03.588663793+00:00,160,1,432669,C,A,65.08,1,26,8058566358088,128,18270,94365034,CLX5
2025-09-24 19:41:03.620050279+00:00,160,1,432669,A,A,65.07,1,26,8058566364722,128,18224,94365035,CLX5
2025-09-24 19:41:03.806496035+00:00,160,1,432669,C,B,64.6,2,26,8058564984683,128,18591,94365043,CLX5
2025-09-24 19:41:04.336590919+00:00,160,1,432669,T,A,64.83,1,26,8058566364741,0,16893,94365083,CLX5
2025-09-24 19:41:04.336590919+00:00,160,1,432669,F,B,64.83,1,26,8058566362898,0,16893,94365083,CLX5
2025-09-24 19:41:04.336590919+00:00,160,1,432669,C,B,64.83,1,26,8058566362898,128,16893,94365083,CLX5
2025-09-24 19:41:04.336968929+00:00,160,1,432669,A,A,64.84,2,26,8058566364745,128,14844,94365096,CLX5
2025-09-24 19:41:04.336969109+00:00,160,1,432669,A,A,64.84,1,26,8058566364746,128,14129,94365097,CLX5
2025-09-24 19:41:04.336984999+00:00,160,1,432669,C,B,64.81,1,26,8058566364346,128,14678,94365099,CLX5
2025-09-24 19:41:04.336997901+00:00,160,1,432669,A,A,64.84,2,26,8058566364747,128,15491,94365100,CLX5
2025-09-24 19:41:04.337314573+00:00,160,1,432669,C,A,64.84,2,26,8058566364747,128,19134,94365109,CLX5
2025-09-24 19:41:04.337718675+00:00,160,1,432669,C,B,64.83,1,26,8058566364471,128,15198,94365136,CLX5
2025-09-24 19:41:04.338063665+00:00,160,1,432669,M,A,64.95,1,26,8058565075241,128,14744,94365152,CLX5
2025-09-24 19:41:04.347785693+00:00,160,1,432669,A,B,64.83,1,26,8058566364779,128,18835,94365228,CLX5
2025-09-24 19:41:04.348932133+00:00,160,1,432669,A,B,64.83,1,26,8058566364784,128,18436,94365249,CLX5
2025-09-24 19:41:04.403740953+00:00,160,1,432669,C,A,65.11,1,26,8058566359226,128,17759,94365281,CLX5
2025-09-24 19:41:04.408162863+00:00,160,1,432669,M,A,64.96,1,26,8058565075241,128,15742,94365290,CLX5
2025-09-24 19:41:04.481832181+00:00,160,1,432669,A,A,65.1,1,26,8058566364828,128,14338,94365348,CLX5
2025-09-24 19:41:04.529146381+00:00,160,1,432669,C,A,65.24,1,26,8058566280143,128,18118,94365368,CLX5
2025-09-24 19:41:04.576458699+00:00,160,1,432669,A,A,65.1,1,26,8058566364843,128,18370,94365378,CLX5
2025-09-24 19:41:07.019861661+00:00,160,1,432669,T,B,64.84,1,26,8058566365217,0,17912,94366315,CLX5
2025-09-24 19:41:07.019861661+00:00,160,1,432669,F,A,64.84,1,26,8058566362808,0,17912,94366315,CLX5
2025-09-24 19:41:07.019861661+00:00,160,1,432669,C,A,64.84,1,26,8058566362808,128,15812,94366316,CLX5
2025-09-24 19:41:08.131418059+00:00,160,1,432669,A,B,64.72,1,26,8058566365291,128,18967,94366495,CLX5
2025-09-24 19:41:09.170234667+00:00,160,1,432669,A,B,64.75,1,26,8058566365346,128,18815,94366609,CLX5
2025-09-24 19:41:09.434325869+00:00,160,1,432669,T,A,64.83,1,26,8058566365361,0,16249,94366640,CLX5
2025-09-24 19:41:09.434325869+00:00,160,1,432669,F,B,64.83,1,26,8058566363202,0,16249,94366640,CLX5
2025-09-24 19:41:09.434325869+00:00,160,1,432669,M,B,64.83,3,26,8058566363202,128,16249,94366640,CLX5
2025-09-24 19:41:09.440640971+00:00,160,1,432669,T,A,64.83,1,26,8058566365380,0,16200,94366701,CLX5
2025-09-24 19:41:09.440640971+00:00,160,1,432669,F,B,64.83,1,26,8058566363202,0,16200,94366701,CLX5
2025-09-24 19:41:09.440640971+00:00,160,1,432669,M,B,64.83,2,26,8058566363202,128,18542,94366702,CLX5
2025-09-24 19:41:09.440948197+00:00,160,1,432669,A,A,64.84,2,26,8058566365382,128,15147,94366704,CLX5
2025-09-24 19:41:09.441018119+00:00,160,1,432669,C,B,64.83,1,26,8058566364784,128,14962,94366706,CLX5
2025-09-24 19:41:09.441186035+00:00,160,1,432669,M,A,64.84,2,26,8058566364431,128,18170,94366707,CLX5
2025-09-24 19:41:09.441186785+00:00,160,1,432669,A,B,64.83,1,26,8058566365384,128,14995,94366708,CLX5
2025-09-24 19:41:09.449020039+00:00,160,1,432669,C,A,64.84,2,26,8058566365382,128,18694,94366722,CLX5
2025-09-24 19:41:09.453902077+00:00,160,1,432669,T,A,64.83,1,26,8058566365390,0,15996,94366725,CLX5
2025-09-24 19:41:09.453902077+00:00,160,1,432669,F,B,64.83,1,26,8058566363202,0,15996,94366725,CLX5
2025-09-24 19:41:09.453902077+00:00,160,1,432669,M,B,64.83,1,26,8058566363202,128,15996,94366725,CLX5
2025-09-24 19:41:09.454231821+00:00,160,1,432669,A,A,64.84,2,26,8058566365394,128,18351,94366732,CLX5
2025-09-24 19:41:09.460770305+00:00,160,1,432669,T,A,64.83,1,26,8058566365398,0,16735,94366738,CLX5
2025-09-24 19:41:09.460770305+00:00,160,1,432669,F,B,64.83,1,26,8058566363202,0,16735,94366738,CLX5
2025-09-24 19:41:09.460770305+00:00,160,1,432669,C,B,64.83,1,26,8058566363202,128,16735,94366738,CLX5
2025-09-24 19:41:09.464457291+00:00,160,1,432669,T,A,64.83,1,26,8058566365403,0,18279,94366752,CLX5
2025-09-24 19:41:09.464457291+00:00,160,1,432669,F,B,64.83,1,26,8058566360382,0,18279,94366752,CLX5
2025-09-24 19:41:09.464457291+00:00,160,1,432669,M,B,64.83,10,26,8058566360382,128,15620,94366753,CLX5
2025-09-24 19:41:09.464712927+00:00,160,1,432669,T,A,64.83,13,26,8058566365404,0,18578,94366754,CLX5
2025-09-24 19:41:09.464712927+00:00,160,1,432669,F,B,64.83,10,26,8058566360382,0,18578,94366754,CLX5
2025-09-24 19:41:09.464712927+00:00,160,1,432669,F,B,64.83,1,26,8058566363626,0,18578,94366754,CLX5
2025-09-24 19:41:09.464712927+00:00,160,1,432669,F,B,64.83,1,26,8058566364779,0,18578,94366754,CLX5
2025-09-24 19:41:09.464712927+00:00,160,1,432669,F,B,64.83,1,26,8058566365384,0,18578,94366754,CLX5
2025-09-24 19:41:09.464712927+00:00,160,1,432669,C,B,64.83,10,26,8058566360382,0,14868,94366755,CLX5
2025-09-24 19:41:09.464712927+00:00,160,1,432669,C,B,64.83,1,26,8058566363626,0,14868,94366755,CLX5
2025-09-24 19:41:09.464712927+00:00,160,1,432669,C,B,64.83,1,26,8058566364779,0,14868,94366755,CLX5
2025-09-24 19:41:09.464712927+00:00,160,1,432669,C,B,64.83,1,26,8058566365384,128,14868,94366755,CLX5
2025-09-24 19:41:09.464978375+00:00,160,1,432669,T,A,64.83,1,26,8058566365405,128,17870,94366759,CLX5
2025-09-24 19:41:09.464995019+00:00,160,1,432669,C,B,64.82,1,26,8058566362421,128,14707,94366771,CLX5
2025-09-24 19:41:09.465005971+00:00,160,1,432669,A,A,64.83,2,26,8058566365417,128,13990,94366799,CLX5
2025-09-24 19:41:09.465029829+00:00,160,1,432669,A,B,64.82,1,26,8058566365422,128,18009,94366814,CLX5
2025-09-24 19:41:09.465044533+00:00,160,1,432669,A,A,64.84,3,26,8058566365423,128,14777,94366815,CLX5
2025-09-24 19:41:09.465256053+00:00,160,1,432669,C,A,64.84,1,26,8058566362827,128,14788,94366828,CLX5
2025-09-24 19:41:09.465259911+00:00,160,1,432669,A,A,64.84,2,26,8058566365428,128,15202,94366829,CLX5
2025-09-24 19:41:09.465313439+00:00,160,1,432669,M,A,64.83,2,26,8058566362865,128,14572,94366831,CLX5
2025-09-24 19:41:09.465343139+00:00,160,1,432669,A,A,64.83,3,26,8058566365429,128,17459,94366841,CLX5
2025-09-24 19:41:09.465402637+00:00,160,1,432669,A,A,64.83,2,26,8058566365432,128,15897,94366847,CLX5
2025-09-24 19:41:09.465492029+00:00,160,1,432669,M,B,63.67,4,26,8058566345944,128,14598,94366854,CLX5
2025-09-24 19:41:09.465650267+00:00,160,1,432669,A,A,64.83,1,26,8058566365436,128,15992,94366866,CLX5
2025-09-24 19:41:09.465951943+00:00,160,1,432669,M,A,64.95,1,26,8058565075241,128,14432,94366896,CLX5
2025-09-24 19:41:09.466002629+00:00,160,1,432669,A,A,64.84,1,26,8058566365445,128,14659,94366899,CLX5
2025-09-24 19:41:09.466148275+00:00,160,1,432669,A,A,64.83,1,26,8058566365448,128,18949,94366909,CLX5
2025-09-24 19:41:09.466158315+00:00,160,1,432669,A,A,64.83,1,26,8058566365450,128,15639,94366913,CLX5
2025-09-24 19:41:09.466165823+00:00,160,1,432669,C,A,64.83,2,26,8058566365432,128,17828,94366916,CLX5
2025-09-24 19:41:09.466286183+00:00,160,1,432669,M,A,64.83,1,26,8058566357626,128,16071,94366935,CLX5
2025-09-24 19:41:09.466377205+00:00,160,1,432669,C,B,64.82,2,26,8058566362449,128,14535,94366937,CLX5
2025-09-24 19:41:09.466401839+00:00,160,1,432669,C,A,64.84,1,26,8058566363633,128,15100,94366940,CLX5
2025-09-24 19:41:09.466977467+00:00,160,1,432669,A,A,64.83,1,26,8058566365462,128,15694,94366962,CLX5
2025-09-24 19:41:09.467628795+00:00,160,1,432669,C,A,64.83,1,26,8058566365448,128,15719,94366994,CLX5
2025-09-24 19:41:09.467699431+00:00,160,1,432669,A,B,64.82,1,26,8058566365470,128,15198,94367000,CLX5
2025-09-24 19:41:09.469302925+00:00,160,1,432669,A,B,64.82,1,26,8058566365480,128,14959,94367041,CLX5
2025-09-24 19:41:09.470618797+00:00,160,1,432669,A,B,64.82,1,26,8058566365490,128,14672,94367080,CLX5
2025-09-24 19:41:09.473363353+00:00,160,1,432669,T,A,64.82,1,26,8058566365517,0,16934,94367182,CLX5
2025-09-24 19:41:09.473363353+00:00,160,1,432669,F,B,64.82,1,26,8058566358218,0,16934,94367182,CLX5
2025-09-24 19:41:09.473363353+00:00,160,1,432669,M,B,64.82,1,26,8058566358218,128,16934,94367182,CLX5
2025-09-24 19:41:09.473688395+00:00,160,1,432669,A,A,64.83,2,26,8058566365518,128,15605,94367192,CLX5
2025-09-24 19:41:09.473793567+00:00,160,1,432669,C,B,64.82,1,26,8058566365490,128,14994,94367204,CLX5
2025-09-24 19:41:09.474924361+00:00,160,1,432669,C,B,64.82,1,26,8058566365470,128,15451,94367266,CLX5
2025-09-24 19:41:09.475222791+00:00,160,1,432669,C,A,64.83,2,26,8058566365518,128,14913,94367282,CLX5
2025-09-24 19:41:09.478517695+00:00,160,1,432669,A,B,63.68,4,26,8058566365565,128,13959,94367361,CLX5
2025-09-24 19:41:09.483275857+00:00,160,1,432669,C,B,64.81,2,26,8058566362417,128,13699,94367594,CLX5
2025-09-24 19:41:09.483291773+00:00,160,1,432669,C,B,64.82,1,26,8058566365480,128,15080,94367598,CLX5
2025-09-24 19:41:09.485944215+00:00,160,1,432669,T,A,64.82,1,26,8058566365636,0,18122,94367619,CLX5
2025-09-24 19:41:09.485944215+00:00,160,1,432669,F,B,64.82,1,26,8058566358218,0,18122,94367619,CLX5
2025-09-24 19:41:09.485944215+00:00,160,1,432669,C,B,64.82,1,26,8058566358218,128,15883,94367620,CLX5
2025-09-24 19:41:09.486216381+00:00,160,1,432669,A,A,64.83,1,26,8058566365637,128,18808,94367626,CLX5
2025-09-24 19:41:09.486216561+00:00,160,1,432669,A,A,64.83,2,26,8058566365638,128,15483,94367627,CLX5
2025-09-24 19:41:09.486221277+00:00,160,1,432669,A,A,64.83,1,26,8058566365639,128,15894,94367628,CLX5
2025-09-24 19:41:09.497839915+00:00,160,1,432669,T,A,64.82,1,26,8058566365669,0,18599,94367733,CLX5
2025-09-24 19:41:09.497839915+00:00,160,1,432669,F,B,64.82,1,26,8058566359580,0,18599,94367733,CLX5
2025-09-24 19:41:09.497839915+00:00,160,1,432669,M,B,64.82,1,26,8058566359580,128,16000,94367734,CLX5
2025-09-24 19:41:09.498713187+00:00,160,1,432669,A,A,64.83,1,26,8058566365672,128,17878,94367738,CLX5
2025-09-24 19:41:09.501637045+00:00,160,1,432669,A,B,64.82,1,26,8058566365673,128,18327,94367741,CLX5
2025-09-24 19:41:09.501986643+00:00,160,1,432669,C,A,64.83,1,26,8058566365637,128,19258,94367744,CLX5
2025-09-24 19:41:09.502120825+00:00,160,1,432669,C,A,64.83,2,26,8058566365638,128,19134,94367746,CLX5
2025-09-24 19:41:09.506057457+00:00,160,1,432669,T,A,64.82,1,26,8058566365679,0,19346,94367758,CLX5
2025-09-24 19:41:09.506057457+00:00,160,1,432669,F,B,64.82,1,26,8058566359580,0,19346,94367758,CLX5
2025-09-24 19:41:09.506057457+00:00,160,1,432669,C,B,64.82,1,26,8058566359580,128,15368,94367759,CLX5
2025-09-24 19:41:09.506350667+00:00,160,1,432669,A,A,64.83,1,26,8058566365680,128,19051,94367760,CLX5
2025-09-24 19:41:09.506445531+00:00,160,1,432669,A,A,64.83,2,26,8058566365685,128,15510,94367765,CLX5
2025-09-24 19:41:09.506521423+00:00,160,1,432669,M,A,64.84,4,26,8058566342145,128,14415,94367766,CLX5
2025-09-24 19:41:09.510378169+00:00,160,1,432669,T,A,64.82,1,26,8058566365688,0,17928,94367773,CLX5
2025-09-24 19:41:09.510378169+00:00,160,1,432669,F,B,64.82,1,26,8058566359581,0,17928,94367773,CLX5
2025-09-24 19:41:09.510378169+00:00,160,1,432669,C,B,64.82,1,26,8058566359581,128,15745,94367774,CLX5
2025-09-24 19:41:09.510661437+00:00,160,1,432669,C,B,64.82,2,26,8058566362456,128,15220,94367776,CLX5
2025-09-24 19:41:09.511905327+00:00,160,1,432669,A,B,64.82,2,26,8058566365694,128,15231,94367787,CLX5
2025-09-24 19:41:09.512118957+00:00,160,1,432669,C,A,64.83,2,26,8058566365685,128,15889,94367798,CLX5
2025-09-24 19:41:09.512211151+00:00,160,1,432669,A,B,64.79,2,26,8058566365698,128,17890,94367800,CLX5
2025-09-24 19:41:09.512700767+00:00,160,1,432669,C,A,64.83,1,26,8058566365680,128,19275,94367806,CLX5
2025-09-24 19:41:09.514955649+00:00,160,1,432669,A,A,64.83,1,26,8058566365708,128,15426,94367817,CLX5
2025-09-24 19:41:09.514956763+00:00,160,1,432669,A,A,64.83,1,26,8058566365709,128,15512,94367818,CLX5
2025-09-24 19:41:09.515233673+00:00,160,1,432669,C,A,64.84,1,26,8058566365445,128,18416,94367820,CLX5
2025-09-24 19:41:09.516836399+00:00,160,1,432669,A,A,64.83,1,26,8058566365712,128,18744,94367825,CLX5
2025-09-24 19:41:09.522202429+00:00,160,1,432669,T,A,64.82,1,26,8058566365721,0,16811,94367854,CLX5
2025-09-24 19:41:09.522202429+00:00,160,1,432669,F,B,64.82,1,26,8058566357569,0,16811,94367854,CLX5
2025-09-24 19:41:09.522202429+00:00,160,1,432669,M,B,64.82,3,26,8058566357569,128,15990,94367855,CLX5
2025-09-24 19:41:09.522395129+00:00,160,1,432669,A,B,64.81,1,26,8058566365723,128,14550,94367861,CLX5
2025-09-24 19:41:09.522553849+00:00,160,1,432669,A,B,64.82,3,26,8058566365725,128,14619,94367865,CLX5
2025-09-24 19:41:09.527622157+00:00,160,1,432669,T,A,64.82,1,26,8058566365728,0,17070,94367876,CLX5
2025-09-24 19:41:09.527622157+00:00,160,1,432669,F,B,64.82,1,26,8058566357569,0,17070,94367876,CLX5
2025-09-24 19:41:09.527622157+00:00,160,1,432669,M,B,64.82,2,26,8058566357569,128,15518,94367877,CLX5
2025-09-24 19:41:09.527917883+00:00,160,1,432669,C,A,64.83,1,26,8058566365709,128,15470,94367879,CLX5
2025-09-24 19:41:09.527966073+00:00,160,1,432669,A,B,64.82,1,26,8058566365730,128,14906,94367880,CLX5
2025-09-24 19:41:09.528124329+00:00,160,1,432669,C,A,64.83,1,26,8058566365708,128,16443,94367884,CLX5
2025-09-24 19:41:09.536249199+00:00,160,1,432669,T,A,64.82,1,26,8058566365735,0,17693,94367898,CLX5
2025-09-24 19:41:09.536249199+00:00,160,1,432669,F,B,64.82,1,26,8058566357569,0,17693,94367898,CLX5
2025-09-24 19:41:09.536249199+00:00,160,1,432669,M,B,64.82,1,26,8058566357569,128,15508,94367899,CLX5
2025-09-24 19:41:09.536473331+00:00,160,1,432669,A,A,64.83,1,26,8058566365736,128,19123,94367901,CLX5
2025-09-24 19:41:09.536646623+00:00,160,1,432669,T,A,64.82,1,26,8058566365741,0,13798,94367908,CLX5
2025-09-24 19:41:09.536646623+00:00,160,1,432669,F,B,64.82,1,26,8058566357569,0,13798,94367908,CLX5
2025-09-24 19:41:09.536646623+00:00,160,1,432669,C,B,64.82,1,26,8058566357569,128,13798,94367908,CLX5
2025-09-24 19:41:09.536995663+00:00,160,1,432669,A,A,64.83,1,26,8058566365742,128,18954,94367910,CLX5
2025-09-24 19:41:09.537044201+00:00,160,1,432669,A,A,64.83,2,26,8058566365745,128,19734,94367914,CLX5
2025-09-24 19:41:09.544548303+00:00,160,1,432669,C,A,64.83,2,26,8058566365745,128,18879,94367942,CLX5
2025-09-24 19:41:09.547441079+00:00,160,1,432669,C,A,64.83,1,26,8058566365742,128,18784,94367947,CLX5
2025-09-24 19:41:09.550030123+00:00,160,1,432669,T,A,64.82,1,26,8058566365755,0,17851,94367949,CLX5
2025-09-24 19:41:09.550030123+00:00,160,1,432669,F,B,64.82,1,26,8058566359682,0,17851,94367949,CLX5
2025-09-24 19:41:09.550030123+00:00,160,1,432669,C,B,64.82,1,26,8058566359682,128,15657,94367950,CLX5
2025-09-24 19:41:09.550872657+00:00,160,1,432669,A,A,64.86,2,26,8058566365758,128,18366,94367953,CLX5
2025-09-24 19:41:09.550915299+00:00,160,1,432669,A,A,64.83,2,26,8058566365765,128,16540,94367960,CLX5
2025-09-24 19:41:09.553191359+00:00,160,1,432669,T,A,64.82,1,26,8058566365771,0,15479,94367973,CLX5
2025-09-24 19:41:09.553191359+00:00,160,1,432669,F,B,64.82,1,26,8058566361811,0,15479,94367973,CLX5
2025-09-24 19:41:09.553191359+00:00,160,1,432669,C,B,64.82,1,26,8058566361811,128,15479,94367973,CLX5
2025-09-24 19:41:09.553495531+00:00,160,1,432669,A,A,64.83,2,26,8058566365775,128,15507,94367979,CLX5
2025-09-24 19:41:09.553497335+00:00,160,1,432669,A,A,64.83,1,26,8058566365778,128,19044,94367985,CLX5
2025-09-24 19:41:09.553499199+00:00,160,1,432669,C,B,64.82,1,26,8058566365422,128,14917,94367986,CLX5
2025-09-24 19:41:09.553524907+00:00,160,1,432669,C,B,64.82,3,26,8058566365725,128,14372,94367996,CLX5
2025-09-24 19:41:09.554031493+00:00,160,1,432669,C,A,64.83,1,26,8058566365778,128,14887,94368005,CLX5
2025-09-24 19:41:09.554046065+00:00,160,1,432669,M,A,64.83,1,26,8058566361816,128,16280,94368006,CLX5
2025-09-24 19:41:09.554200929+00:00,160,1,432669,A,A,64.83,1,26,8058566365783,128,18097,94368007,CLX5
2025-09-24 19:41:09.555288329+00:00,160,1,432669,A,B,64.82,3,26,8058566365788,128,14988,94368015,CLX5
2025-09-24 19:41:09.555429231+00:00,160,1,432669,A,B,64.82,1,26,8058566365789,128,20318,94368016,CLX5
2025-09-24 19:41:09.555565047+00:00,160,1,432669,A,B,64.82,1,26,8058566365790,128,17628,94368019,CLX5
2025-09-24 19:41:09.555979459+00:00,160,1,432669,C,A,64.83,2,26,8058566365765,128,18622,94368020,CLX5
2025-09-24 19:41:09.561748441+00:00,160,1,432669,T,A,64.82,1,26,8058566365795,0,17679,94368029,CLX5
2025-09-24 19:41:09.561748441+00:00,160,1,432669,F,B,64.82,1,26,8058566130074,0,17679,94368029,CLX5
2025-09-24 19:41:09.561748441+00:00,160,1,432669,C,B,64.82,1,26,8058566130074,128,15692,94368030,CLX5
2025-09-24 19:41:09.575164271+00:00,160,1,432669,T,A,64.82,1,26,8058566365801,0,17700,94368041,CLX5
2025-09-24 19:41:09.575164271+00:00,160,1,432669,F,B,64.82,1,26,8058566362025,0,17700,94368041,CLX5
2025-09-24 19:41:09.575164271+00:00,160,1,432669,M,B,64.82,2,26,8058566362025,128,15336,94368042,CLX5
2025-09-24 19:41:09.575481595+00:00,160,1,432669,A,A,64.83,3,26,8058566365804,128,14928,94368047,CLX5
2025-09-24 19:41:09.577474659+00:00,160,1,432669,A,A,64.83,1,26,8058566365806,128,18395,94368054,CLX5
2025-09-24 19:41:09.586315735+00:00,160,1,432669,T,A,64.82,1,26,8058566365819,0,17762,94368073,CLX5
2025-09-24 19:41:09.586315735+00:00,160,1,432669,F,B,64.82,1,26,8058566362025,0,17762,94368073,CLX5
2025-09-24 19:41:09.586315735+00:00,160,1,432669,M,B,64.82,1,26,8058566362025,128,15835,94368074,CLX5
2025-09-24 19:41:09.586594507+00:00,160,1,432669,C,B,64.82,1,26,8058566362025,128,15089,94368080,CLX5
2025-09-24 19:41:09.612208537+00:00,160,1,432669,C,A,64.88,2,26,8058566361892,128,17565,94368150,CLX5
2025-09-24 19:41:09.854880109+00:00,160,1,432669,M,A,65.99,4,26,8058566342145,128,17090,94368398,CLX5
2025-09-24 19:41:09.861133177+00:00,160,1,432669,A,B,64.82,1,26,8058566365967,128,15041,94368414,CLX5
2025-09-24 19:41:09.861297329+00:00,160,1,432669,C,B,64.82,1,26,8058566365967,128,15262,94368422,CLX5
2025-09-24 19:41:09.861526183+00:00,160,1,432669,A,B,64.82,2,26,8058566365972,128,15437,94368435,CLX5
2025-09-24 19:41:09.870976677+00:00,160,1,432669,T,A,64.82,1,26,8058566365977,0,18229,94368461,CLX5
2025-09-24 19:41:09.870976677+00:00,160,1,432669,F,B,64.82,1,26,8058566349770,0,18229,94368461,CLX5
2025-09-24 19:41:09.870976677+00:00,160,1,432669,C,B,64.82,1,26,8058566349770,128,15797,94368462,CLX5
2025-09-24 19:41:09.871290431+00:00,160,1,432669,C,B,64.82,2,26,8058566365972,128,14956,94368469,CLX5
2025-09-24 19:41:09.871329499+00:00,160,1,432669,A,B,64.81,1,26,8058566365981,128,14504,94368470,CLX5
2025-09-24 19:41:09.907395609+00:00,160,1,432669,A,B,64.82,1,26,8058566366017,128,15043,94368542,CLX5
2025-09-24 19:41:09.907399833+00:00,160,1,432669,A,B,64.82,1,26,8058566366018,128,18156,94368543,CLX5
2025-09-24 19:41:09.907886837+00:00,160,1,432669,C,B,64.82,1,26,8058566366018,128,18270,94368574,CLX5
2025-09-24 19:41:10.023809537+00:00,160,1,432669,A,A,64.86,1,26,8058566366055,128,18212,94368652,CLX5
2025-09-24 19:41:10.492937841+00:00,160,1,432669,C,A,64.83,1,26,8058566365672,128,18506,94368737,CLX5
2025-09-24 19:41:10.600404831+00:00,160,1,432669,C,B,64.81,1,26,8058566365723,128,18752,94368777,CLX5
2025-09-24 19:41:10.600411857+00:00,160,1,432669,A,B,64.82,1,26,8058566366123,128,15334,94368778,CLX5
2025-09-24 19:41:10.600582843+00:00,160,1,432669,A,B,64.82,1,26,8058566366124,128,18374,94368779,CLX5
2025-09-24 19:41:10.600587549+00:00,160,1,432669,C,A,64.83,2,26,8058566365775,128,14943,94368780,CLX5
2025-09-24 19:41:10.600598567+00:00,160,1,432669,C,A,64.83,1,26,8058566365783,128,14761,94368781,CLX5
2025-09-24 19:41:10.600853533+00:00,160,1,432669,A,B,64.82,1,26,8058566366126,128,18215,94368785,CLX5
2025-09-24 19:41:10.664705749+00:00,160,1,432669,C,B,63.64,2,26,8058562072296,128,20245,94368795,CLX5
2025-09-24 19:41:10.664916481+00:00,160,1,432669,C,B,64.1,2,26,8058561842297,128,17559,94368796,CLX5
2025-09-24 19:41:10.665165319+00:00,160,1,432669,C,B,64.47,2,26,8058562455486,128,17487,94368797,CLX5
2025-09-24 19:41:10.665510923+00:00,160,1,432669,C,B,64.31,2,26,8058563779693,128,17900,94368798,CLX5
2025-09-24 19:41:15.014374399+00:00,160,1,432669,C,B,64.8,1,26,8058566362411,128,20264,94368920,CLX5
2025-09-24 19:41:15.016480855+00:00,160,1,432669,C,B,64.82,1,26,8058566366123,128,18473,94368922,CLX5
2025-09-24 19:41:15.213558699+00:00,160,1,432669,A,B,64.82,1,26,8058566366186,128,19042,94368928,CLX5
2025-09-24 19:41:15.213703155+00:00,160,1,432669,C,A,64.83,1,26,8058566365736,128,18408,94368929,CLX5
2025-09-24 19:41:15.213845017+00:00,160,1,432669,C,B,64.82,1,26,8058566366186,128,18579,94368931,CLX5
2025-09-24 19:41:15.723966569+00:00,160,1,432669,C,B,64.81,1,26,8058566358085,128,20918,94368932,CLX5
2025-09-24 19:41:16.725715969+00:00,160,1,432669,M,B,64.8,1,26,8058566365346,128,20034,94368979,CLX5
2025-09-24 19:41:18.826828861+00:00,160,1,432669,A,B,64.76,1,26,8058566366211,128,19010,94368996,CLX5
2025-09-24 19:41:20.024388381+00:00,160,1,432669,A,A,64.87,1,26,8058566366218,128,18321,94369012,CLX5
2025-09-24 19:41:20.155903057+00:00,160,1,432669,C,B,64.82,1,26,8058566364191,128,18914,94369013,CLX5
2025-09-24 19:41:21.187824781+00:00,160,1,432669,A,B,64.82,1,26,8058566366225,128,21792,94369057,CLX5
2025-09-24 19:41:21.976732807+00:00,160,1,432669,M,B,64.81,1,26,8058566365346,128,23785,94369060,CLX5
2025-09-24 19:41:24.064456857+00:00,160,1,432669,C,B,64.81,1,26,8058566365346,128,23467,94369065,CLX5
2025-09-24 19:41:26.563296573+00:00,160,1,432669,A,A,64.83,1,26,8058566366236,128,20841,94369103,CLX5
2025-09-24 19:41:26.581013513+00:00,160,1,432669,C,B,64.82,1,26,8058566366017,128,21196,94369105,CLX5
2025-09-24 19:41:26.676281973+00:00,160,1,432669,A,B,64.82,1,26,8058566366238,128,20664,94369107,CLX5
2025-09-24 19:41:29.389925337+00:00,160,1,432669,A,B,64.82,2,26,8058566366244,128,24989,94369132,CLX5
2025-09-24 19:41:30.124425921+00:00,160,1,432669,A,A,64.83,2,26,8058566366280,128,17970,94369231,CLX5
2025-09-24 19:41:30.125778673+00:00,160,1,432669,C,B,64.82,1,26,8058566366126,128,14796,94369335,CLX5
2025-09-24 19:41:31.156660761+00:00,160,1,432669,C,A,64.83,2,26,8058566366280,128,18343,94369656,CLX5
2025-09-24 19:41:31.456181289+00:00,160,1,432669,M,B,64.42,1,26,8058566360017,128,18323,94369667,CLX5
2025-09-24 19:41:38.633050337+00:00,160,1,432669,A,B,64.51,1,26,8058566367011,128,22280,94371112,CLX5
2025-09-24 19:41:43.423302243+00:00,160,1,432669,C,B,64.8,1,26,8058566357018,128,21286,94371164,CLX5
2025-09-24 19:41:43.569684207+00:00,160,1,432669,A,B,64.81,1,26,8058566367028,128,23333,94371166,CLX5
2025-09-24 19:41:47.027727885+00:00,160,1,432669,T,A,64.82,59,26,8058566367036,0,24045,94371200,CLX5
2025-09-24 19:41:47.027727885+00:00,160,1,432669,F,B,64.82,1,26,8058566362220,0,24045,94371200,CLX5
2025-09-24 19:41:47.027727885+00:00,160,1,432669,F,B,64.82,1,26,8058566365673,0,24045,94371200,CLX5
2025-09-24 19:41:47.027727885+00:00,160,1,432669,F,B,64.82,2,26,8058566365694,0,24045,94371200,CLX5
2025-09-24 19:41:47.027727885+00:00,160,1,432669,F,B,64.82,1,26,8058566365730,0,24045,94371200,CLX5
2025-09-24 19:41:47.027727885+00:00,160,1,432669,F,B,64.82,3,26,8058566365788,0,24045,94371200,CLX5
2025-09-24 19:41:47.027727885+00:00,160,1,432669,F,B,64.82,1,26,8058566365789,0,24045,94371200,CLX5
2025-09-24 19:41:47.027727885+00:00,160,1,432669,F,B,64.82,1,26,8058566365790,0,24045,94371200,CLX5
2025-09-24 19:41:47.027727885+00:00,160,1,432669,F,B,64.82,1,26,8058566366124,0,24045,94371200,CLX5
2025-09-24 19:41:47.027727885+00:00,160,1,432669,F,B,64.82,1,26,8058566366225,0,24045,94371200,CLX5
2025-09-24 19:41:47.027727885+00:00,160,1,432669,F,B,64.82,1,26,8058566366238,0,24045,94371200,CLX5
2025-09-24 19:41:47.027727885+00:00,160,1,432669,F,B,64.82,2,26,8058566366244,0,24045,94371200,CLX5
2025-09-24 19:41:47.027727885+00:00,160,1,432669,C,B,64.82,1,26,8058566362220,0,31109,94371201,CLX5
2025-09-24 19:41:47.027727885+00:00,160,1,432669,C,B,64.82,1,26,8058566365673,0,31109,94371201,CLX5
2025-09-24 19:41:47.027727885+00:00,160,1,432669,C,B,64.82,2,26,8058566365694,0,31109,94371201,CLX5
2025-09-24 19:41:47.027727885+00:00,160,1,432669,C,B,64.82,1,26,8058566365730,0,31109,94371201,CLX5
2025-09-24 19:41:47.027727885+00:00,160,1,432669,C,B,64.82,3,26,8058566365788,0,31109,94371201,CLX5
2025-09-24 19:41:47.027727885+00:00,160,1,432669,C,B,64.82,1,26,8058566365789,0,31109,94371201,CLX5
2025-09-24 19:41:47.027727885+00:00,160,1,432669,C,B,64.82,1,26,8058566365790,0,31109,94371201,CLX5
2025-09-24 19:41:47.027727885+00:00,160,1,432669,C,B,64.82,1,26,8058566366124,0,31109,94371201,CLX5
2025-09-24 19:41:47.027727885+00:00,160,1,432669,C,B,64.82,1,26,8058566366225,0,31109,94371201,CLX5
2025-09-24 19:41:47.027727885+00:00,160,1,432669,C,B,64.82,1,26,8058566366238,0,31109,94371201,CLX5
2025-09-24 19:41:47.027727885+00:00,160,1,432669,C,B,64.82,2,26,8058566366244,0,31109,94371201,CLX5
2025-09-24 19:41:47.027727885+00:00,160,1,432669,A,A,64.82,1,26,8058566367036,128,31109,94371201,CLX5
2025-09-24 19:41:47.028635505+00:00,160,1,432669,A,A,64.83,2,26,8058566367038,128,20939,94371211,CLX5
2025-09-24 19:41:47.028673181+00:00,160,1,432669,A,A,64.82,2,26,8058566367045,128,17871,94371218,CLX5
2025-09-24 19:41:47.028673509+00:00,160,1,432669,A,A,64.82,1,26,8058566367047,128,19474,94371220,CLX5
2025-09-24 19:41:47.028699669+00:00,160,1,432669,A,A,64.82,1,26,8058566367054,128,21778,94371237,CLX5
