ts_event,rtype,publisher_id,instrument_id,action,side,price,size,channel_id,order_id,flags,ts_in_delta,sequence,symbol
2025-09-24 19:33:18.083158183+00:00,160,1,432669,A,B,64.81,2,26,8058566328169,128,14679,94262852,CLX5
2025-09-24 19:33:18.083164193+00:00,160,1,432669,C,A,64.83,1,26,8058566328167,128,19788,94262854,CLX5
2025-09-24 19:33:18.083168705+00:00,160,1,432669,C,B,64.78,2,26,8058566327965,128,13776,94262856,CLX5
2025-09-24 19:33:18.083173621+00:00,160,1,432669,C,A,64.83,1,26,8058566327725,128,18077,94262857,CLX5
2025-09-24 19:33:18.083634169+00:00,160,1,432669,C,B,64.81,2,26,8058566328169,128,15091,94262874,CLX5
2025-09-24 19:33:18.083639889+00:00,160,1,432669,A,A,64.83,1,26,8058566328179,128,16731,94262878,CLX5
2025-09-24 19:33:18.083647243+00:00,160,1,432669,A,A,64.83,1,26,8058566328181,128,19087,94262879,CLX5
2025-09-24 19:33:18.083959845+00:00,160,1,432669,C,A,64.83,1,26,8058566328179,128,16461,94262895,CLX5
2025-09-24 19:33:18.084069413+00:00,160,1,432669,C,B,64.82,1,26,8058566328168,128,19220,94262899,CLX5
2025-09-24 19:33:18.084774579+00:00,160,1,432669,C,A,64.83,1,26,8058566328181,128,15249,94262916,CLX5
2025-09-24 19:33:18.084847671+00:00,160,1,432669,A,B,64.82,1,26,8058566328188,128,19200,94262920,CLX5
2025-09-24 19:33:18.085139479+00:00,160,1,432669,A,A,64.83,1,26,8058566328193,128,14117,94262934,CLX5
2025-09-24 19:33:18.085141879+00:00,160,1,432669,C,B,64.82,1,26,8058566328188,128,18867,94262937,CLX5
2025-09-24 19:33:18.085207021+00:00,160,1,432669,C,A,64.83,1,26,8058566328193,128,16307,94262945,CLX5
2025-09-24 19:33:18.085455361+00:00,160,1,432669,A,A,64.83,1,26,8058566328205,128,14428,94262977,CLX5
2025-09-24 19:33:18.085526919+00:00,160,1,432669,C,A,64.83,1,26,8058566328205,128,19611,94262981,CLX5
2025-09-24 19:33:18.085826253+00:00,160,1,432669,A,A,64.83,1,26,8058566328211,128,16719,94262991,CLX5
2025-09-24 19:33:18.086382989+00:00,160,1,432669,A,B,64.82,1,26,8058566328227,128,18151,94263020,CLX5
2025-09-24 19:33:18.086383181+00:00,160,1,432669,C,A,64.83,1,26,8058566328211,128,16289,94263021,CLX5
2025-09-24 19:33:18.086572197+00:00,160,1,432669,C,B,64.82,1,26,8058566328227,128,18938,94263029,CLX5
2025-09-24 19:33:18.087116627+00:00,160,1,432669,A,B,64.82,1,26,8058566328243,128,15196,94263092,CLX5
2025-09-24 19:33:18.087155525+00:00,160,1,432669,C,B,64.82,1,26,8058566328243,128,18982,94263093,CLX5
2025-09-24 19:33:18.088297815+00:00,160,1,432669,A,A,64.83,1,26,8058566328251,128,15514,94263126,CLX5
2025-09-24 19:33:18.210002325+00:00,160,1,432669,A,B,64.78,2,26,8058566328312,128,18069,94263238,CLX5
2025-09-24 19:33:18.561205947+00:00,160,1,432669,A,A,64.83,1,26,8058566328399,128,16077,94263371,CLX5
2025-09-24 19:33:18.945355781+00:00,160,1,432669,A,B,64.8,1,26,8058566328479,128,18526,94263578,CLX5
2025-09-24 19:33:19.145376553+00:00,160,1,432669,C,A,64.83,1,26,8058566328251,128,15952,94263657,CLX5
2025-09-24 19:33:19.145789297+00:00,160,1,432669,A,B,64.82,1,26,8058566328518,128,15877,94263680,CLX5
2025-09-24 19:33:19.146885913+00:00,160,1,432669,C,A,64.83,2,26,8058566328147,128,20021,94263693,CLX5
2025-09-24 19:33:19.241831987+00:00,160,1,432669,A,A,64.83,1,26,8058566328537,128,20097,94263727,CLX5
2025-09-24 19:33:19.241841009+00:00,160,1,432669,A,A,64.83,1,26,8058566328538,128,16252,94263728,CLX5
2025-09-24 19:33:19.241854123+00:00,160,1,432669,C,B,64.82,1,26,8058566328518,128,15222,94263730,CLX5
2025-09-24 19:33:19.242089869+00:00,160,1,432669,C,A,64.83,1,26,8058566328538,128,16554,94263732,CLX5
2025-09-24 19:33:19.242091405+00:00,160,1,432669,A,B,64.82,1,26,8058566328540,128,15284,94263733,CLX5
2025-09-24 19:33:19.252250965+00:00,160,1,432669,C,A,64.83,1,26,8058566328537,128,20016,94263745,CLX5
2025-09-24 19:33:19.252395647+00:00,160,1,432669,C,A,64.83,1,26,8058566328399,128,15939,94263748,CLX5
2025-09-24 19:33:19.252397011+00:00,160,1,432669,C,B,64.82,1,26,8058566328540,128,15956,94263750,CLX5
2025-09-24 19:33:19.252708307+00:00,160,1,432669,C,A,64.83,1,26,8058566326138,128,20643,94263752,CLX5
2025-09-24 19:33:20.215928735+00:00,160,1,432669,A,A,64.83,1,26,8058566328620,128,21150,94263898,CLX5
2025-09-24 19:33:20.216126889+00:00,160,1,432669,A,A,64.83,1,26,8058566328621,128,20678,94263899,CLX5
2025-09-24 19:33:21.480268585+00:00,160,1,432669,A,B,64.81,2,26,8058566328625,128,20031,94263925,CLX5
2025-09-24 19:33:21.480277647+00:00,160,1,432669,C,B,64.78,2,26,8058566328312,128,17078,94263943,CLX5
2025-09-24 19:33:21.480283023+00:00,160,1,432669,C,A,64.83,1,26,8058566328620,128,19991,94263946,CLX5
2025-09-24 19:33:21.480297057+00:00,160,1,432669,A,B,64.82,1,26,8058566328636,128,15005,94263948,CLX5
2025-09-24 19:33:21.480301781+00:00,160,1,432669,C,A,64.83,1,26,8058566328621,128,21520,94263949,CLX5
2025-09-24 19:33:21.480308903+00:00,160,1,432669,A,B,64.82,1,26,8058566328637,128,15145,94263950,CLX5
2025-09-24 19:33:21.480313127+00:00,160,1,432669,C,B,64.81,1,26,8058566327572,128,14819,94263951,CLX5
2025-09-24 19:33:21.481352241+00:00,160,1,432669,C,B,64.82,1,26,8058566328637,128,18382,94263987,CLX5
2025-09-24 19:33:21.510014755+00:00,160,1,432669,C,B,64.79,2,26,8058566325603,128,18584,94264113,CLX5
2025-09-24 19:33:21.546609491+00:00,160,1,432669,A,B,64.82,1,26,8058566328682,128,18756,94264146,CLX5
2025-09-24 19:33:22.400537799+00:00,160,1,432669,A,B,64.82,1,26,8058566328730,128,15341,94264237,CLX5
2025-09-24 19:33:22.400692791+00:00,160,1,432669,C,B,64.82,1,26,8058566328730,128,15713,94264241,CLX5
2025-09-24 19:33:22.400896611+00:00,160,1,432669,A,B,64.82,1,26,8058566328734,128,18301,94264262,CLX5
2025-09-24 19:33:22.508515141+00:00,160,1,432669,C,A,64.83,1,26,8058566324724,128,14782,94264279,CLX5
2025-09-24 19:33:22.508520459+00:00,160,1,432669,C,B,64.82,1,26,8058566328734,128,18604,94264281,CLX5
2025-09-24 19:33:22.510110207+00:00,160,1,432669,A,B,64.82,1,26,8058566328742,128,18605,94264296,CLX5
2025-09-24 19:33:22.895461345+00:00,160,1,432669,T,B,64.83,3,26,8058566328745,0,20249,94264311,CLX5
2025-09-24 19:33:22.895461345+00:00,160,1,432669,F,A,64.83,1,26,8058566325778,0,20249,94264311,CLX5
2025-09-24 19:33:22.895461345+00:00,160,1,432669,F,A,64.83,1,26,8058566325831,0,20249,94264311,CLX5
2025-09-24 19:33:22.895461345+00:00,160,1,432669,F,A,64.83,1,26,8058566326935,0,20249,94264311,CLX5
2025-09-24 19:33:22.895461345+00:00,160,1,432669,C,A,64.83,1,26,8058566325778,0,14989,94264312,CLX5
2025-09-24 19:33:22.895461345+00:00,160,1,432669,C,A,64.83,1,26,8058566325831,0,14989,94264312,CLX5
2025-09-24 19:33:22.895461345+00:00,160,1,432669,C,A,64.83,1,26,8058566326935,128,14989,94264312,CLX5
2025-09-24 19:33:22.895462459+00:00,160,1,432669,A,B,64.83,1,26,8058566328746,128,17680,94264315,CLX5
2025-09-24 19:33:22.895463317+00:00,160,1,432669,A,B,64.82,2,26,8058566328750,128,15568,94264324,CLX5
2025-09-24 19:33:22.895463853+00:00,160,1,432669,A,B,64.83,2,26,8058566328753,128,17436,94264326,CLX5
2025-09-24 19:33:22.895464027+00:00,160,1,432669,A,B,64.83,3,26,8058566328754,128,15518,94264328,CLX5
2025-09-24 19:33:22.895464207+00:00,160,1,432669,A,B,64.83,1,26,8058566328755,128,17335,94264330,CLX5
2025-09-24 19:33:22.895464383+00:00,160,1,432669,C,A,64.84,2,26,8058566322040,128,19345,94264331,CLX5
2025-09-24 19:33:22.895467893+00:00,160,1,432669,A,B,64.82,1,26,8058566328758,128,14958,94264332,CLX5
2025-09-24 19:33:22.895473539+00:00,160,1,432669,C,A,64.87,2,26,8058566314496,128,14713,94264347,CLX5
2025-09-24 19:33:22.895476283+00:00,160,1,432669,A,B,64.83,1,26,8058566328765,128,19652,94264355,CLX5
2025-09-24 19:33:22.895478767+00:00,160,1,432669,A,B,64.83,1,26,8058566328769,128,16669,94264366,CLX5
2025-09-24 19:33:22.895497977+00:00,160,1,432669,C,A,64.84,1,26,8058566319377,128,19076,94264395,CLX5
2025-09-24 19:33:22.895498331+00:00,160,1,432669,T,A,64.83,2,26,8058566328779,0,15174,94264399,CLX5
2025-09-24 19:33:22.895498331+00:00,160,1,432669,F,B,64.83,1,26,8058566328746,0,15174,94264399,CLX5
2025-09-24 19:33:22.895498331+00:00,160,1,432669,F,B,64.83,1,26,8058566328753,0,15174,94264399,CLX5
2025-09-24 19:33:22.895498331+00:00,160,1,432669,C,B,64.83,1,26,8058566328746,0,15174,94264399,CLX5
2025-09-24 19:33:22.895498331+00:00,160,1,432669,M,B,64.83,1,26,8058566328753,128,15174,94264399,CLX5
2025-09-24 19:33:22.895514393+00:00,160,1,432669,C,B,64.82,1,26,8058566328636,128,15199,94264404,CLX5
2025-09-24 19:33:22.895524531+00:00,160,1,432669,A,B,64.81,1,26,8058566328781,128,14996,94264405,CLX5
2025-09-24 19:33:22.895529139+00:00,160,1,432669,A,B,64.83,1,26,8058566328782,128,17349,94264407,CLX5
2025-09-24 19:33:22.895560933+00:00,160,1,432669,A,B,64.83,2,26,8058566328784,128,14184,94264408,CLX5
2025-09-24 19:33:22.895633525+00:00,160,1,432669,C,B,64.83,1,26,8058566328753,128,16058,94264412,CLX5
2025-09-24 19:33:22.895633677+00:00,160,1,432669,C,B,64.83,1,26,8058566328755,128,18459,94264413,CLX5
2025-09-24 19:33:22.895964173+00:00,160,1,432669,C,B,64.83,1,26,8058566328782,128,15112,94264428,CLX5
2025-09-24 19:33:22.895990071+00:00,160,1,432669,T,A,64.83,1,26,8058566328792,0,14861,94264431,CLX5
2025-09-24 19:33:22.895990071+00:00,160,1,432669,F,B,64.83,1,26,8058566328754,0,14861,94264431,CLX5
2025-09-24 19:33:22.895990071+00:00,160,1,432669,M,B,64.83,2,26,8058566328754,128,17731,94264432,CLX5
2025-09-24 19:33:22.895997923+00:00,160,1,432669,T,A,64.83,1,26,8058566328793,0,14475,94264433,CLX5
2025-09-24 19:33:22.895997923+00:00,160,1,432669,F,B,64.83,1,26,8058566328754,0,14475,94264433,CLX5
2025-09-24 19:33:22.895997923+00:00,160,1,432669,M,B,64.83,1,26,8058566328754,128,14475,94264433,CLX5
2025-09-24 19:33:22.896026107+00:00,160,1,432669,A,A,64.84,1,26,8058566328796,128,15230,94264439,CLX5
2025-09-24 19:33:22.896065007+00:00,160,1,432669,C,B,64.83,1,26,8058566328754,128,14841,94264458,CLX5
2025-09-24 19:33:22.896150807+00:00,160,1,432669,A,B,64.83,1,26,8058566328807,128,15185,94264470,CLX5
2025-09-24 19:33:22.896191317+00:00,160,1,432669,C,A,64.84,3,26,8058566288785,128,14307,94264478,CLX5
2025-09-24 19:33:22.896214759+00:00,160,1,432669,T,A,64.83,2,26,8058566328808,0,14663,94264479,CLX5
2025-09-24 19:33:22.896214759+00:00,160,1,432669,F,B,64.83,1,26,8058566328765,0,14663,94264479,CLX5
2025-09-24 19:33:22.896214759+00:00,160,1,432669,F,B,64.83,1,26,8058566328769,0,14663,94264479,CLX5
2025-09-24 19:33:22.896214759+00:00,160,1,432669,C,B,64.83,1,26,8058566328765,0,18624,94264480,CLX5
2025-09-24 19:33:22.896214759+00:00,160,1,432669,C,B,64.83,1,26,8058566328769,128,18624,94264480,CLX5
2025-09-24 19:33:22.896383039+00:00,160,1,432669,C,B,64.82,1,26,8058566326782,128,15030,94264487,CLX5
2025-09-24 19:33:22.896457495+00:00,160,1,432669,A,B,64.8,1,26,8058566328813,128,17178,94264489,CLX5
2025-09-24 19:33:22.896872753+00:00,160,1,432669,A,A,64.84,1,26,8058566328816,128,16067,94264519,CLX5
2025-09-24 19:33:22.897001177+00:00,160,1,432669,T,A,64.83,2,26,8058566328817,0,14744,94264523,CLX5
2025-09-24 19:33:22.897001177+00:00,160,1,432669,F,B,64.83,2,26,8058566328784,0,14744,94264523,CLX5
2025-09-24 19:33:22.897001177+00:00,160,1,432669,C,B,64.83,2,26,8058566328784,128,17459,94264524,CLX5
2025-09-24 19:33:22.897463395+00:00,160,1,432669,T,A,64.83,1,26,8058566328830,0,18186,94264560,CLX5
2025-09-24 19:33:22.897463395+00:00,160,1,432669,F,B,64.83,1,26,8058566328807,0,18186,94264560,CLX5
2025-09-24 19:33:22.897463395+00:00,160,1,432669,C,B,64.83,1,26,8058566328807,0,18186,94264560,CLX5
2025-09-24 19:33:22.897463395+00:00,160,1,432669,A,A,64.83,1,26,8058566328830,128,18186,94264560,CLX5
2025-09-24 19:33:22.897856921+00:00,160,1,432669,A,A,64.84,2,26,8058566328837,128,17180,94264582,CLX5
2025-09-24 19:33:22.898068765+00:00,160,1,432669,A,B,64.82,1,26,8058566328846,128,15067,94264596,CLX5
2025-09-24 19:33:22.898583955+00:00,160,1,432669,A,A,64.83,1,26,8058566328848,128,17099,94264604,CLX5
2025-09-24 19:33:22.898647023+00:00,160,1,432669,C,A,64.83,1,26,8058566328848,128,14750,94264607,CLX5
2025-09-24 19:33:22.898729101+00:00,160,1,432669,C,A,64.84,1,26,8058566319360,128,14987,94264613,CLX5
2025-09-24 19:33:22.898734917+00:00,160,1,432669,A,B,64.82,2,26,8058566328851,128,16107,94264617,CLX5
2025-09-24 19:33:22.898765425+00:00,160,1,432669,T,B,64.83,1,26,8058566328855,0,18610,94264628,CLX5
2025-09-24 19:33:22.898765425+00:00,160,1,432669,F,A,64.83,1,26,8058566328830,0,18610,94264628,CLX5
2025-09-24 19:33:22.898765425+00:00,160,1,432669,C,A,64.83,1,26,8058566328830,128,18610,94264628,CLX5
2025-09-24 19:33:22.898904811+00:00,160,1,432669,A,B,64.83,1,26,8058566328858,128,15187,94264635,CLX5
2025-09-24 19:33:22.899333067+00:00,160,1,432669,C,A,64.84,1,26,8058566328796,128,14406,94264654,CLX5
2025-09-24 19:33:22.899335179+00:00,160,1,432669,T,A,64.83,1,26,8058566328862,0,15360,94264655,CLX5
2025-09-24 19:33:22.899335179+00:00,160,1,432669,F,B,64.83,1,26,8058566328858,0,15360,94264655,CLX5
2025-09-24 19:33:22.899335179+00:00,160,1,432669,C,B,64.83,1,26,8058566328858,128,18649,94264656,CLX5
2025-09-24 19:33:22.899665271+00:00,160,1,432669,C,B,64.82,2,26,8058566328851,128,19559,94264678,CLX5
2025-09-24 19:33:22.899947247+00:00,160,1,432669,A,B,64.82,1,26,8058566328867,128,16788,94264681,CLX5
2025-09-24 19:33:22.900169131+00:00,160,1,432669,A,A,64.84,1,26,8058566328868,128,15126,94264682,CLX5
2025-09-24 19:33:22.900796485+00:00,160,1,432669,A,B,64.83,1,26,8058566328877,128,17255,94264704,CLX5
2025-09-24 19:33:22.900874395+00:00,160,1,432669,A,B,64.83,2,26,8058566328880,128,17818,94264711,CLX5
2025-09-24 19:33:22.900889523+00:00,160,1,432669,C,A,64.84,2,26,8058566319357,128,17103,94264714,CLX5
2025-09-24 19:33:22.900903461+00:00,160,1,432669,C,A,64.84,1,26,8058566328868,128,15667,94264716,CLX5
2025-09-24 19:33:22.900950653+00:00,160,1,432669,M,A,64.96,1,26,8058565075241,128,14863,94264719,CLX5
2025-09-24 19:33:22.901153089+00:00,160,1,432669,A,A,64.84,1,26,8058566328883,128,15617,94264726,CLX5
2025-09-24 19:33:22.901420669+00:00,160,1,432669,T,A,64.83,1,26,8058566328887,0,15622,94264734,CLX5
2025-09-24 19:33:22.901420669+00:00,160,1,432669,F,B,64.83,1,26,8058566328877,0,15622,94264734,CLX5
2025-09-24 19:33:22.901420669+00:00,160,1,432669,C,B,64.83,1,26,8058566328877,128,15622,94264734,CLX5
2025-09-24 19:33:22.901515377+00:00,160,1,432669,A,B,64.83,1,26,8058566328898,128,17405,94264752,CLX5
2025-09-24 19:33:22.901515553+00:00,160,1,432669,A,B,64.83,1,26,8058566328899,128,16574,94264754,CLX5
2025-09-24 19:33:22.901569423+00:00,160,1,432669,C,A,64.84,1,26,8058566328816,128,15470,94264759,CLX5
2025-09-24 19:33:22.901569711+00:00,160,1,432669,C,A,64.84,1,26,8058566328883,128,15092,94264760,CLX5
2025-09-24 19:33:22.901824005+00:00,160,1,432669,A,B,64.83,2,26,8058566328901,128,18665,94264765,CLX5
2025-09-24 19:33:22.902973687+00:00,160,1,432669,A,B,64.83,1,26,8058566328911,128,19132,94264811,CLX5
2025-09-24 19:33:22.903006479+00:00,160,1,432669,M,A,64.95,1,26,8058565075241,128,14448,94264821,CLX5
2025-09-24 19:33:22.903011143+00:00,160,1,432669,A,B,64.82,3,26,8058566328914,128,15375,94264822,CLX5
2025-09-24 19:33:22.903155637+00:00,160,1,432669,A,A,64.84,1,26,8058566328916,128,15022,94264825,CLX5
2025-09-24 19:33:22.903191597+00:00,160,1,432669,A,A,64.84,1,26,8058566328917,128,15185,94264828,CLX5
2025-09-24 19:33:22.903789785+00:00,160,1,432669,A,B,64.82,1,26,8058566328926,128,18216,94264854,CLX5
2025-09-24 19:33:22.903978627+00:00,160,1,432669,A,A,64.84,2,26,8058566328931,128,14726,94264859,CLX5
2025-09-24 19:33:22.904645759+00:00,160,1,432669,C,A,64.84,2,26,8058566328931,128,15373,94264898,CLX5
2025-09-24 19:33:22.905063879+00:00,160,1,432669,C,B,64.83,2,26,8058566328901,128,18268,94264913,CLX5
2025-09-24 19:33:22.905203169+00:00,160,1,432669,C,B,64.83,1,26,8058566328911,128,14114,94264919,CLX5
2025-09-24 19:33:22.905220025+00:00,160,1,432669,A,A,64.84,2,26,8058566328949,128,18650,94264921,CLX5
2025-09-24 19:33:22.905226093+00:00,160,1,432669,C,B,64.83,2,26,8058566328880,128,14988,94264922,CLX5
2025-09-24 19:33:22.907104767+00:00,160,1,432669,C,A,64.84,2,26,8058566328949,128,15154,94264963,CLX5
2025-09-24 19:33:22.907748651+00:00,160,1,432669,A,A,64.84,1,26,8058566328962,128,15573,94264969,CLX5
2025-09-24 19:33:22.908826357+00:00,160,1,432669,A,B,64.83,2,26,8058566328966,128,14754,94264987,CLX5
2025-09-24 19:33:22.909997985+00:00,160,1,432669,A,B,64.83,1,26,8058566328977,128,14405,94265044,CLX5
2025-09-24 19:33:22.909998773+00:00,160,1,432669,A,B,64.83,1,26,8058566328978,128,20147,94265046,CLX5
2025-09-24 19:33:22.918626085+00:00,160,1,432669,M,B,64.82,4,26,8058566319851,128,17678,94265141,CLX5
2025-09-24 19:33:22.918630077+00:00,160,1,432669,C,B,64.82,1,26,8058566328926,128,15039,94265142,CLX5
2025-09-24 19:33:22.932795541+00:00,160,1,432669,T,A,64.83,1,26,8058566328997,0,18045,94265160,CLX5
2025-09-24 19:33:22.932795541+00:00,160,1,432669,F,B,64.83,1,26,8058566328898,0,18045,94265160,CLX5
2025-09-24 19:33:22.932795541+00:00,160,1,432669,C,B,64.83,1,26,8058566328898,128,18997,94265161,CLX5
2025-09-24 19:33:22.933061603+00:00,160,1,432669,C,B,64.83,1,26,8058566328978,128,17376,94265162,CLX5
2025-09-24 19:33:22.933083087+00:00,160,1,432669,T,A,64.83,4,26,8058566328998,0,19944,94265164,CLX5
2025-09-24 19:33:22.933083087+00:00,160,1,432669,F,B,64.83,1,26,8058566328899,0,19944,94265164,CLX5
2025-09-24 19:33:22.933083087+00:00,160,1,432669,F,B,64.83,2,26,8058566328966,0,19944,94265164,CLX5
2025-09-24 19:33:22.933083087+00:00,160,1,432669,F,B,64.83,1,26,8058566328977,0,19944,94265164,CLX5
2025-09-24 19:33:22.933083087+00:00,160,1,432669,C,B,64.83,1,26,8058566328899,0,15042,94265165,CLX5
2025-09-24 19:33:22.933083087+00:00,160,1,432669,C,B,64.83,2,26,8058566328966,0,15042,94265165,CLX5
2025-09-24 19:33:22.933083087+00:00,160,1,432669,C,B,64.83,1,26,8058566328977,128,15042,94265165,CLX5
2025-09-24 19:33:22.933085409+00:00,160,1,432669,A,B,64.83,1,26,8058566328999,128,16144,94265168,CLX5
2025-09-24 19:33:22.933365947+00:00,160,1,432669,A,A,64.84,2,26,8058566329004,128,15319,94265174,CLX5
2025-09-24 19:33:22.933392863+00:00,160,1,432669,C,B,64.83,1,26,8058566328999,128,16010,94265184,CLX5
2025-09-24 19:33:22.933407627+00:00,160,1,432669,A,A,64.83,1,26,8058566329010,128,14805,94265190,CLX5
2025-09-24 19:33:22.933565253+00:00,160,1,432669,A,A,64.83,1,26,8058566329013,128,17571,94265201,CLX5
2025-09-24 19:33:22.933583127+00:00,160,1,432669,M,B,63.67,4,26,8058566319851,128,15236,94265206,CLX5
2025-09-24 19:33:22.934219657+00:00,160,1,432669,C,B,64.82,1,26,8058566328867,128,16212,94265220,CLX5
2025-09-24 19:33:22.934409383+00:00,160,1,432669,A,A,64.87,2,26,8058566329019,128,14927,94265224,CLX5
2025-09-24 19:33:22.934513595+00:00,160,1,432669,C,B,64.82,1,26,8058566328846,128,14261,94265234,CLX5
2025-09-24 19:33:22.934998433+00:00,160,1,432669,A,A,64.83,1,26,8058566329031,128,14902,94265253,CLX5
2025-09-24 19:33:22.938863931+00:00,160,1,432669,A,B,63.68,4,26,8058566329044,128,18571,94265321,CLX5
2025-09-24 19:33:22.940795981+00:00,160,1,432669,M,A,64.83,1,26,8058566328962,128,19133,94265324,CLX5
2025-09-24 19:33:23.071859863+00:00,160,1,432669,C,B,64.8,1,26,8058566328813,128,18923,94265472,CLX5
2025-09-24 19:33:23.110058059+00:00,160,1,432669,A,B,64.78,2,26,8058566329100,128,18424,94265485,CLX5
2025-09-24 19:33:23.382581593+00:00,160,1,432669,A,A,64.83,2,26,8058566329144,128,21404,94265581,CLX5
2025-09-24 19:33:23.391835737+00:00,160,1,432669,A,A,64.83,1,26,8058566329148,128,20575,94265596,CLX5
2025-09-24 19:33:23.391998237+00:00,160,1,432669,C,B,64.82,1,26,8058566328682,128,18751,94265597,CLX5
2025-09-24 19:33:23.392498089+00:00,160,1,432669,A,B,64.82,1,26,8058566329149,128,14283,94265600,CLX5
2025-09-24 19:33:24.173081785+00:00,160,1,432669,C,A,64.83,1,26,8058566329148,128,20074,94265639,CLX5
2025-09-24 19:33:24.173246457+00:00,160,1,432669,C,B,64.81,1,26,8058566328781,128,18097,94265640,CLX5
2025-09-24 19:33:24.173250815+00:00,160,1,432669,C,A,64.83,2,26,8058566329144,128,18035,94265642,CLX5
2025-09-24 19:33:29.488036293+00:00,160,1,432669,C,A,64.83,1,26,8058566329010,128,22967,94265705,CLX5
2025-09-24 19:33:29.488036447+00:00,160,1,432669,C,A,64.83,1,26,8058566329013,128,20774,94265707,CLX5
2025-09-24 19:33:29.488571931+00:00,160,1,432669,C,B,64.82,1,26,8058566329149,128,18316,94265723,CLX5
2025-09-24 19:33:29.539026595+00:00,160,1,432669,T,B,64.83,1,26,8058566329192,0,18967,94265745,CLX5
2025-09-24 19:33:29.539026595+00:00,160,1,432669,F,A,64.83,1,26,8058566329031,0,18967,94265745,CLX5
2025-09-24 19:33:29.539026595+00:00,160,1,432669,C,A,64.83,1,26,8058566329031,128,16152,94265746,CLX5
2025-09-24 19:33:29.539379879+00:00,160,1,432669,T,B,64.83,1,26,8058566329195,0,14108,94265758,CLX5
2025-09-24 19:33:29.539379879+00:00,160,1,432669,F,A,64.83,1,26,8058566328962,0,14108,94265758,CLX5
2025-09-24 19:33:29.539379879+00:00,160,1,432669,C,A,64.83,1,26,8058566328962,128,14108,94265758,CLX5
2025-09-24 19:33:29.540400679+00:00,160,1,432669,M,B,64.83,1,26,8058566324408,128,18675,94265848,CLX5
2025-09-24 19:33:29.541291749+00:00,160,1,432669,A,B,64.83,1,26,8058566329219,128,14686,94265881,CLX5
2025-09-24 19:33:29.542016843+00:00,160,1,432669,A,B,64.8,1,26,8058566329225,128,14726,94265908,CLX5
2025-09-24 19:33:29.547889019+00:00,160,1,432669,T,A,64.83,1,26,8058566329239,0,17983,94265945,CLX5
2025-09-24 19:33:29.547889019+00:00,160,1,432669,F,B,64.83,1,26,8058566324408,0,17983,94265945,CLX5
2025-09-24 19:33:29.547889019+00:00,160,1,432669,C,B,64.83,1,26,8058566324408,128,15052,94265946,CLX5
2025-09-24 19:33:29.548134019+00:00,160,1,432669,T,A,64.83,1,26,8058566329240,0,16865,94265949,CLX5
2025-09-24 19:33:29.548134019+00:00,160,1,432669,F,B,64.83,1,26,8058566329219,0,16865,94265949,CLX5
2025-09-24 19:33:29.548134019+00:00,160,1,432669,C,B,64.83,1,26,8058566329219,128,17279,94265950,CLX5
2025-09-24 19:33:29.548368211+00:00,160,1,432669,A,A,64.83,1,26,8058566329246,128,17206,94265962,CLX5
2025-09-24 19:33:29.548368441+00:00,160,1,432669,A,A,64.83,2,26,8058566329247,128,14730,94265966,CLX5
2025-09-24 19:33:29.555042125+00:00,160,1,432669,A,A,64.84,1,26,8058566329260,128,18458,94266033,CLX5
2025-09-24 19:33:29.581525129+00:00,160,1,432669,A,A,64.83,1,26,8058566329264,128,17903,94266046,CLX5
2025-09-24 19:33:29.640388699+00:00,160,1,432669,M,A,64.83,1,26,8058566329260,128,18299,94266099,CLX5
2025-09-24 19:33:29.673868507+00:00,160,1,432669,A,A,64.83,1,26,8058566329288,128,21291,94266114,CLX5
2025-09-24 19:33:29.674032565+00:00,160,1,432669,A,A,64.83,1,26,8058566329289,128,18822,94266116,CLX5
2025-09-24 19:33:29.674035023+00:00,160,1,432669,A,A,64.83,1,26,8058566329290,128,16683,94266117,CLX5
2025-09-24 19:33:29.721897187+00:00,160,1,432669,C,B,64.8,1,26,8058566329225,128,18520,94266135,CLX5
2025-09-24 19:33:29.819486637+00:00,160,1,432669,C,A,64.83,1,26,8058566329288,128,19968,94266143,CLX5
2025-09-24 19:33:29.819652671+00:00,160,1,432669,C,A,64.83,1,26,8058566329289,128,16994,94266146,CLX5
2025-09-24 19:33:29.819670391+00:00,160,1,432669,C,A,64.83,1,26,8058566329290,128,20424,94266147,CLX5
2025-09-24 19:33:33.842432475+00:00,160,1,432669,C,A,65.32,1,26,8058562216742,128,20671,94266397,CLX5
2025-09-24 19:33:34.716325459+00:00,160,1,432669,C,B,64.72,1,26,8058566325952,128,18354,94266429,CLX5
2025-09-24 19:33:37.933717771+00:00,160,1,432669,A,A,64.83,1,26,8058566329398,128,25180,94266456,CLX5
2025-09-24 19:33:37.957199835+00:00,160,1,432669,A,A,64.83,1,26,8058566329401,128,22821,94266463,CLX5
2025-09-24 19:33:37.957435079+00:00,160,1,432669,C,B,64.82,2,26,8058566327630,128,14584,94266481,CLX5
2025-09-24 19:33:37.960024509+00:00,160,1,432669,M,A,64.84,1,26,8058566329260,128,16586,94266509,CLX5
2025-09-24 19:33:37.963924837+00:00,160,1,432669,M,A,64.83,1,26,8058566329260,128,19599,94266515,CLX5
2025-09-24 19:33:38.039036167+00:00,160,1,432669,A,A,64.83,1,26,8058566329421,128,19768,94266536,CLX5
2025-09-24 19:33:38.039049759+00:00,160,1,432669,A,A,64.83,1,26,8058566329423,128,14876,94266540,CLX5
2025-09-24 19:33:38.039064101+00:00,160,1,432669,C,B,64.82,1,26,8058566328742,128,18284,94266544,CLX5
2025-09-24 19:33:38.039090463+00:00,160,1,432669,C,A,64.83,1,26,8058566329423,128,20070,94266547,CLX5
2025-09-24 19:33:38.039246609+00:00,160,1,432669,A,A,64.83,1,26,8058566329426,128,19837,94266562,CLX5
2025-09-24 19:33:38.039259241+00:00,160,1,432669,C,B,64.82,1,26,8058566328758,128,14119,94266563,CLX5
2025-09-24 19:33:38.039428347+00:00,160,1,432669,C,B,64.82,2,26,8058566327423,128,17985,94266568,CLX5
2025-09-24 19:33:38.039503417+00:00,160,1,432669,A,B,64.82,1,26,8058566329427,128,15427,94266570,CLX5
2025-09-24 19:33:38.041775041+00:00,160,1,432669,C,A,64.83,1,26,8058566329426,128,16931,94266597,CLX5
2025-09-24 19:33:38.138395183+00:00,160,1,432669,C,A,64.83,1,26,8058566329421,128,16285,94266644,CLX5
2025-09-24 19:33:38.138582799+00:00,160,1,432669,C,A,64.83,1,26,8058566329401,128,15315,94266649,CLX5
2025-09-24 19:33:38.138677547+00:00,160,1,432669,C,B,64.78,2,26,8058566329100,128,17752,94266651,CLX5
2025-09-24 19:33:38.138994467+00:00,160,1,432669,A,A,64.83,2,26,8058566329446,128,15181,94266658,CLX5
2025-09-24 19:33:38.142076679+00:00,160,1,432669,A,A,64.83,2,26,8058566329470,128,17464,94266709,CLX5
2025-09-24 19:33:38.142220943+00:00,160,1,432669,A,A,64.83,1,26,8058566329471,128,15740,94266714,CLX5
2025-09-24 19:33:38.142529165+00:00,160,1,432669,C,A,64.83,1,26,8058566329471,128,19507,94266720,CLX5
2025-09-24 19:33:38.187804369+00:00,160,1,432669,A,B,64.82,1,26,8058566329521,128,18828,94266852,CLX5
2025-09-24 19:33:38.187807459+00:00,160,1,432669,C,A,64.87,1,26,8058566307943,128,14600,94266874,CLX5
2025-09-24 19:33:38.187807785+00:00,160,1,432669,C,A,64.88,1,26,8058566302457,128,13802,94266876,CLX5
2025-09-24 19:33:38.187808921+00:00,160,1,432669,A,B,64.82,1,26,8058566329527,128,14445,94266880,CLX5
2025-09-24 19:33:38.187809157+00:00,160,1,432669,T,B,64.83,8,26,8058566329528,0,14822,94266881,CLX5
2025-09-24 19:33:38.187809157+00:00,160,1,432669,F,A,64.83,1,26,8058566329246,0,14822,94266881,CLX5
2025-09-24 19:33:38.187809157+00:00,160,1,432669,F,A,64.83,2,26,8058566329247,0,14822,94266881,CLX5
2025-09-24 19:33:38.187809157+00:00,160,1,432669,F,A,64.83,1,26,8058566329264,0,14822,94266881,CLX5
2025-09-24 19:33:38.187809157+00:00,160,1,432669,F,A,64.83,1,26,8058566329398,0,14822,94266881,CLX5
2025-09-24 19:33:38.187809157+00:00,160,1,432669,F,A,64.83,1,26,8058566329260,0,14822,94266881,CLX5
2025-09-24 19:33:38.187809157+00:00,160,1,432669,F,A,64.83,2,26,8058566329446,0,14822,94266881,CLX5
2025-09-24 19:33:38.187809157+00:00,160,1,432669,C,A,64.83,1,26,8058566329246,0,18382,94266882,CLX5
2025-09-24 19:33:38.187809157+00:00,160,1,432669,C,A,64.83,2,26,8058566329247,0,18382,94266882,CLX5
2025-09-24 19:33:38.187809157+00:00,160,1,432669,C,A,64.83,1,26,8058566329264,0,18382,94266882,CLX5
2025-09-24 19:33:38.187809157+00:00,160,1,432669,C,A,64.83,1,26,8058566329398,0,18382,94266882,CLX5
2025-09-24 19:33:38.187809157+00:00,160,1,432669,C,A,64.83,1,26,8058566329260,0,18382,94266882,CLX5
2025-09-24 19:33:38.187809157+00:00,160,1,432669,C,A,64.83,2,26,8058566329446,128,18382,94266882,CLX5
2025-09-24 19:33:38.187809791+00:00,160,1,432669,C,A,64.83,2,26,8058566329470,128,16993,94266885,CLX5
2025-09-24 19:33:38.187811923+00:00,160,1,432669,A,B,64.82,2,26,8058566329531,128,15505,94266891,CLX5
2025-09-24 19:33:38.187817279+00:00,160,1,432669,C,A,64.84,1,26,8058566328917,128,15649,94266894,CLX5
2025-09-24 19:33:38.187863835+00:00,160,1,432669,A,B,64.83,2,26,8058566329540,128,18555,94266919,CLX5
2025-09-24 19:33:38.188117651+00:00,160,1,432669,A,B,64.82,1,26,8058566329541,128,15051,94266922,CLX5
2025-09-24 19:33:38.188375167+00:00,160,1,432669,A,B,64.83,1,26,8058566329553,128,18332,94266961,CLX5
2025-09-24 19:33:38.188927757+00:00,160,1,432669,C,B,64.82,1,26,8058566329541,128,15379,94266993,CLX5
2025-09-24 19:33:38.188948877+00:00,160,1,432669,C,B,64.82,1,26,8058566329521,128,15203,94266998,CLX5
2025-09-24 19:33:38.189005687+00:00,160,1,432669,C,B,64.82,1,26,8058566329427,128,19883,94267001,CLX5
2025-09-24 19:33:38.189007743+00:00,160,1,432669,A,A,64.84,1,26,8058566329566,128,15239,94267003,CLX5
2025-09-24 19:33:38.189159933+00:00,160,1,432669,T,A,64.83,2,26,8058566329568,0,15117,94267018,CLX5
2025-09-24 19:33:38.189159933+00:00,160,1,432669,F,B,64.83,2,26,8058566329540,0,15117,94267018,CLX5
2025-09-24 19:33:38.189159933+00:00,160,1,432669,C,B,64.83,2,26,8058566329540,128,18819,94267019,CLX5
2025-09-24 19:33:38.189257369+00:00,160,1,432669,A,B,64.82,1,26,8058566329572,128,16184,94267042,CLX5
2025-09-24 19:33:38.189376501+00:00,160,1,432669,T,A,64.83,1,26,8058566329577,0,15010,94267056,CLX5
2025-09-24 19:33:38.189376501+00:00,160,1,432669,F,B,64.83,1,26,8058566329553,0,15010,94267056,CLX5
2025-09-24 19:33:38.189376501+00:00,160,1,432669,C,B,64.83,1,26,8058566329553,0,18905,94267057,CLX5
2025-09-24 19:33:38.189376501+00:00,160,1,432669,A,A,64.83,1,26,8058566329577,128,18905,94267057,CLX5
2025-09-24 19:33:38.189687891+00:00,160,1,432669,A,B,64.82,1,26,8058566329584,128,15036,94267100,CLX5
2025-09-24 19:33:38.189777571+00:00,160,1,432669,T,B,64.83,1,26,8058566329588,0,15106,94267106,CLX5
2025-09-24 19:33:38.189777571+00:00,160,1,432669,F,A,64.83,1,26,8058566329577,0,15106,94267106,CLX5
2025-09-24 19:33:38.189777571+00:00,160,1,432669,C,A,64.83,1,26,8058566329577,128,15106,94267106,CLX5
2025-09-24 19:33:38.190803055+00:00,160,1,432669,A,A,64.83,1,26,8058566329597,128,14759,94267153,CLX5
2025-09-24 19:33:38.191016971+00:00,160,1,432669,A,A,64.83,2,26,8058566329604,128,14909,94267169,CLX5
2025-09-24 19:33:38.191078159+00:00,160,1,432669,A,B,64.82,1,26,8058566329607,128,18148,94267177,CLX5
2025-09-24 19:33:38.191116019+00:00,160,1,432669,C,B,64.82,1,26,8058566329527,128,19719,94267182,CLX5
2025-09-24 19:33:38.191419175+00:00,160,1,432669,A,A,64.83,2,26,8058566329617,128,22625,94267198,CLX5
2025-09-24 19:33:38.191517053+00:00,160,1,432669,A,A,64.87,1,26,8058566329627,128,14679,94267212,CLX5
2025-09-24 19:33:38.191523675+00:00,160,1,432669,A,A,64.83,1,26,8058566329630,128,19017,94267214,CLX5
2025-09-24 19:33:38.191540705+00:00,160,1,432669,C,B,64.82,2,26,8058566329531,128,15097,94267216,CLX5
2025-09-24 19:33:38.191714421+00:00,160,1,432669,A,B,64.8,1,26,8058566329635,128,17987,94267226,CLX5
2025-09-24 19:33:38.192160147+00:00,160,1,432669,A,A,64.83,1,26,8058566329642,128,16471,94267242,CLX5
2025-09-24 19:33:38.192166349+00:00,160,1,432669,A,A,64.88,1,26,8058566329644,128,15737,94267245,CLX5
2025-09-24 19:33:38.192167961+00:00,160,1,432669,A,A,64.87,1,26,8058566329645,128,14604,94267247,CLX5
2025-09-24 19:33:38.192169997+00:00,160,1,432669,A,A,64.83,1,26,8058566329646,128,19822,94267248,CLX5
2025-09-24 19:33:38.192181419+00:00,160,1,432669,A,B,64.82,1,26,8058566329647,128,14469,94267249,CLX5
2025-09-24 19:33:38.192269697+00:00,160,1,432669,C,B,64.82,1,26,8058566329607,128,15427,94267253,CLX5
2025-09-24 19:33:38.192282215+00:00,160,1,432669,C,B,64.82,1,26,8058566329584,128,18084,94267255,CLX5
2025-09-24 19:33:38.192286767+00:00,160,1,432669,C,B,64.82,1,26,8058566329572,128,15372,94267256,CLX5
2025-09-24 19:33:38.193100581+00:00,160,1,432669,C,B,64.82,1,26,8058566329647,128,15563,94267277,CLX5
2025-09-24 19:33:38.193323501+00:00,160,1,432669,C,A,64.83,1,26,8058566329642,128,19771,94267286,CLX5
2025-09-24 19:33:38.193843067+00:00,160,1,432669,A,B,64.82,1,26,8058566329666,128,15785,94267301,CLX5
2025-09-24 19:33:38.193870697+00:00,160,1,432669,A,B,64.82,1,26,8058566329667,128,15747,94267304,CLX5
2025-09-24 19:33:38.193944267+00:00,160,1,432669,C,B,64.82,1,26,8058566329666,128,18935,94267310,CLX5
2025-09-24 19:33:38.194128789+00:00,160,1,432669,A,B,64.82,1,26,8058566329671,128,17343,94267314,CLX5
2025-09-24 19:33:38.194254141+00:00,160,1,432669,C,A,64.83,1,26,8058566329646,128,16959,94267316,CLX5
2025-09-24 19:33:38.194317497+00:00,160,1,432669,C,B,64.82,1,26,8058566329671,128,15375,94267318,CLX5
2025-09-24 19:33:38.194496799+00:00,160,1,432669,A,B,64.82,1,26,8058566329673,128,16568,94267324,CLX5
2025-09-24 19:33:38.194554031+00:00,160,1,432669,C,B,64.82,1,26,8058566329673,128,14911,94267326,CLX5
2025-09-24 19:33:38.195242093+00:00,160,1,432669,A,B,64.82,1,26,8058566329685,128,18853,94267363,CLX5
2025-09-24 19:33:38.195535819+00:00,160,1,432669,A,A,64.83,1,26,8058566329687,128,16868,94267368,CLX5
2025-09-24 19:33:38.195697937+00:00,160,1,432669,A,B,64.82,1,26,8058566329688,128,18799,94267370,CLX5
2025-09-24 19:33:38.195957817+00:00,160,1,432669,C,B,64.82,1,26,8058566329688,128,15194,94267376,CLX5
2025-09-24 19:33:38.196504821+00:00,160,1,432669,A,B,64.82,1,26,8058566329691,128,16240,94267380,CLX5
2025-09-24 19:33:38.196893179+00:00,160,1,432669,A,B,64.82,2,26,8058566329693,128,14764,94267386,CLX5
2025-09-24 19:33:38.197520089+00:00,160,1,432669,C,A,64.83,2,26,8058566329617,128,17364,94267393,CLX5
2025-09-24 19:33:38.198652859+00:00,160,1,432669,C,B,64.82,1,26,8058566329691,128,15061,94267403,CLX5
2025-09-24 19:33:38.200093793+00:00,160,1,432669,C,B,64.82,1,26,8058566329685,128,15693,94267438,CLX5
2025-09-24 19:33:38.200245871+00:00,160,1,432669,A,B,64.82,1,26,8058566329709,128,15210,94267452,CLX5
2025-09-24 19:33:38.265367191+00:00,160,1,432669,C,A,64.87,1,26,8058566329627,128,18356,94267516,CLX5
2025-09-24 19:33:38.371945511+00:00,160,1,432669,C,B,64.8,1,26,8058566329635,128,18384,94267614,CLX5
2025-09-24 19:33:38.749934215+00:00,160,1,432669,C,B,64.82,1,26,8058566329709,128,18332,94267681,CLX5
2025-09-24 19:33:39.027774145+00:00,160,1,432669,T,B,64.83,3,26,8058566326500,0,19100,94267730,CLX5
2025-09-24 19:33:39.027774145+00:00,160,1,432669,F,B,64.83,3,26,8058566326500,0,19100,94267730,CLX5
2025-09-24 19:33:39.027774145+00:00,160,1,432669,F,A,64.83,1,26,8058566329597,0,19100,94267730,CLX5
2025-09-24 19:33:39.027774145+00:00,160,1,432669,F,A,64.83,2,26,8058566329604,0,19100,94267730,CLX5
2025-09-24 19:33:39.027774145+00:00,160,1,432669,C,B,64.82,3,26,8058566326500,0,15123,94267731,CLX5
2025-09-24 19:33:39.027774145+00:00,160,1,432669,C,A,64.83,1,26,8058566329597,0,15123,94267731,CLX5
2025-09-24 19:33:39.027774145+00:00,160,1,432669,C,A,64.83,2,26,8058566329604,128,15123,94267731,CLX5
2025-09-24 19:33:39.028119749+00:00,160,1,432669,C,A,64.84,1,26,8058566328916,128,15736,94267737,CLX5
2025-09-24 19:33:39.028121459+00:00,160,1,432669,C,A,64.84,1,26,8058566329566,128,14936,94267738,CLX5
2025-09-24 19:33:39.028123225+00:00,160,1,432669,A,B,64.82,1,26,8058566329823,128,15286,94267739,CLX5
2025-09-24 19:33:39.028125125+00:00,160,1,432669,A,B,64.82,1,26,8058566329824,128,19148,94267740,CLX5
2025-09-24 19:33:39.028126967+00:00,160,1,432669,A,B,64.82,1,26,8058566329826,128,14350,94267742,CLX5
2025-09-24 19:33:39.028138143+00:00,160,1,432669,T,B,64.83,1,26,8058566329827,0,14657,94267743,CLX5
2025-09-24 19:33:39.028138143+00:00,160,1,432669,F,A,64.83,1,26,8058566329630,0,14657,94267743,CLX5
2025-09-24 19:33:39.028138143+00:00,160,1,432669,C,A,64.83,1,26,8058566329630,128,22033,94267744,CLX5
2025-09-24 19:33:39.028175197+00:00,160,1,432669,C,B,64.82,1,26,8058566329823,128,19276,94267755,CLX5
2025-09-24 19:33:39.028514195+00:00,160,1,432669,T,B,64.83,1,26,8058566329832,0,14154,94267759,CLX5
2025-09-24 19:33:39.028514195+00:00,160,1,432669,F,A,64.83,1,26,8058566329687,0,14154,94267759,CLX5
2025-09-24 19:33:39.028514195+00:00,160,1,432669,C,A,64.83,1,26,8058566329687,128,14154,94267759,CLX5
2025-09-24 19:33:39.028784827+00:00,160,1,432669,A,B,64.82,1,26,8058566329835,128,15776,94267771,CLX5
2025-09-24 19:33:39.028834879+00:00,160,1,432669,C,B,64.82,1,26,8058566329835,128,20105,94267772,CLX5
2025-09-24 19:33:39.028874237+00:00,160,1,432669,A,A,64.84,1,26,8058566329839,128,15424,94267782,CLX5
2025-09-24 19:33:39.028974975+00:00,160,1,432669,A,B,64.82,1,26,8058566329844,128,14894,94267794,CLX5
2025-09-24 19:33:39.029133233+00:00,160,1,432669,A,B,64.82,1,26,8058566329848,128,16463,94267806,CLX5
2025-09-24 19:33:39.029170249+00:00,160,1,432669,A,B,64.82,1,26,8058566329849,128,15230,94267808,CLX5
2025-09-24 19:33:39.029331215+00:00,160,1,432669,A,B,64.82,1,26,8058566329852,128,17326,94267811,CLX5
2025-09-24 19:33:39.029541177+00:00,160,1,432669,C,B,64.82,1,26,8058566329852,128,15031,94267813,CLX5
2025-09-24 19:33:39.029889335+00:00,160,1,432669,A,A,64.84,1,26,8058566329855,128,18802,94267831,CLX5
2025-09-24 19:33:39.030270785+00:00,160,1,432669,A,B,64.82,1,26,8058566329857,128,15021,94267839,CLX5
2025-09-24 19:33:39.037208839+00:00,160,1,432669,A,A,64.83,1,26,8058566329869,128,18259,94267892,CLX5
2025-09-24 19:33:39.040462577+00:00,160,1,432669,M,A,64.84,1,26,8058566329869,128,19661,94267899,CLX5
2025-09-24 19:33:39.140220071+00:00,160,1,432669,M,A,64.83,1,26,8058566329869,128,18651,94267943,CLX5
2025-09-24 19:33:39.140453841+00:00,160,1,432669,C,B,64.82,1,26,8058566329849,128,15193,94267950,CLX5
2025-09-24 19:33:39.140631105+00:00,160,1,432669,C,B,64.82,1,26,8058566329848,128,18742,94267952,CLX5
2025-09-24 19:33:39.140778287+00:00,160,1,432669,C,B,64.82,1,26,8058566329844,128,17286,94267953,CLX5
2025-09-24 19:33:39.210097963+00:00,160,1,432669,A,B,64.78,2,26,8058566329888,128,18006,94267957,CLX5
2025-09-24 19:33:43.533133043+00:00,160,1,432669,A,B,64.82,1,26,8058566330172,128,18253,94268725,CLX5
2025-09-24 19:33:44.397165875+00:00,160,1,432669,C,B,64.82,1,26,8058566329857,128,15185,94268768,CLX5
2025-09-24 19:33:44.397492625+00:00,160,1,432669,A,B,64.82,1,26,8058566330188,128,14922,94268777,CLX5
2025-09-24 19:33:48.334870041+00:00,160,1,432669,T,A,64.82,2,26,8058566330210,0,17735,94268839,CLX5
2025-09-24 19:33:48.334870041+00:00,160,1,432669,F,B,64.82,1,26,8058566323034,0,17735,94268839,CLX5
2025-09-24 19:33:48.334870041+00:00,160,1,432669,F,B,64.82,1,26,8058566323035,0,17735,94268839,CLX5
2025-09-24 19:33:48.334870041+00:00,160,1,432669,C,B,64.82,1,26,8058566323034,0,16889,94268840,CLX5
2025-09-24 19:33:48.334870041+00:00,160,1,432669,C,B,64.82,1,26,8058566323035,128,16889,94268840,CLX5
2025-09-24 19:33:48.335198865+00:00,160,1,432669,A,A,64.83,1,26,8058566330213,128,16991,94268844,CLX5
2025-09-24 19:33:48.335565357+00:00,160,1,432669,C,A,64.83,1,26,8058566330213,128,18513,94268870,CLX5
2025-09-24 19:33:56.766140039+00:00,160,1,432669,C,B,64.82,1,26,8058566329826,128,19458,94269012,CLX5
2025-09-24 19:33:56.766140693+00:00,160,1,432669,A,A,64.83,1,26,8058566330278,128,23594,94269017,CLX5
2025-09-24 19:33:56.766141881+00:00,160,1,432669,A,A,64.83,1,26,8058566330283,128,18162,94269026,CLX5
2025-09-24 19:33:56.766142207+00:00,160,1,432669,A,A,64.83,1,26,8058566330284,128,20673,94269030,CLX5
2025-09-24 19:33:56.766144251+00:00,160,1,432669,A,A,64.83,1,26,8058566330285,128,19946,94269032,CLX5
2025-09-24 19:33:56.766153735+00:00,160,1,432669,A,A,64.83,2,26,8058566330291,128,22184,94269040,CLX5
2025-09-24 19:33:56.766157705+00:00,160,1,432669,C,B,64.81,2,26,8058566328625,128,25502,94269063,CLX5
2025-09-24 19:33:56.766158181+00:00,160,1,432669,C,B,64.8,2,26,8058566323254,128,18368,94269066,CLX5
2025-09-24 19:33:56.766164313+00:00,160,1,432669,A,A,64.83,2,26,8058566330305,128,23870,94269095,CLX5
2025-09-24 19:33:56.766168231+00:00,160,1,432669,C,B,64.82,1,26,8058566330188,128,22358,94269101,CLX5
2025-09-24 19:33:56.766176275+00:00,160,1,432669,A,A,64.83,1,26,8058566330307,128,19657,94269105,CLX5
2025-09-24 19:33:56.766216497+00:00,160,1,432669,A,A,64.83,1,26,8058566330308,128,20056,94269108,CLX5
2025-09-24 19:33:56.766242971+00:00,160,1,432669,T,A,64.82,1,26,8058566330310,0,16780,94269113,CLX5
2025-09-24 19:33:56.766242971+00:00,160,1,432669,F,B,64.82,1,26,8058566323716,0,16780,94269113,CLX5
2025-09-24 19:33:56.766242971+00:00,160,1,432669,C,B,64.82,1,26,8058566323061,0,16780,94269113,CLX5
2025-09-24 19:33:56.766242971+00:00,160,1,432669,M,B,64.82,1,26,8058566323716,128,16780,94269113,CLX5
2025-09-24 19:33:56.766283175+00:00,160,1,432669,T,A,64.82,1,26,8058566330311,0,18133,94269116,CLX5
2025-09-24 19:33:56.766283175+00:00,160,1,432669,F,B,64.82,1,26,8058566323716,0,18133,94269116,CLX5
2025-09-24 19:33:56.766283175+00:00,160,1,432669,C,B,64.82,1,26,8058566323716,128,18133,94269116,CLX5
2025-09-24 19:33:56.766338257+00:00,160,1,432669,T,A,64.82,17,26,8058566330313,0,27425,94269122,CLX5
2025-09-24 19:33:56.766338257+00:00,160,1,432669,F,B,64.82,1,26,8058566323717,0,27425,94269122,CLX5
2025-09-24 19:33:56.766338257+00:00,160,1,432669,F,B,64.82,1,26,8058566321508,0,27425,94269122,CLX5
2025-09-24 19:33:56.766338257+00:00,160,1,432669,F,B,64.82,1,26,8058566311303,0,27425,94269122,CLX5
2025-09-24 19:33:56.766338257+00:00,160,1,432669,F,B,64.82,1,26,8058566327178,0,27425,94269122,CLX5
2025-09-24 19:33:56.766338257+00:00,160,1,432669,F,B,64.82,1,26,8058566327347,0,27425,94269122,CLX5
2025-09-24 19:33:56.766338257+00:00,160,1,432669,F,B,64.82,2,26,8058566328750,0,27425,94269122,CLX5
2025-09-24 19:33:56.766338257+00:00,160,1,432669,F,B,64.82,3,26,8058566328914,0,27425,94269122,CLX5
2025-09-24 19:33:56.766338257+00:00,160,1,432669,F,B,64.82,1,26,8058566329667,0,27425,94269122,CLX5
2025-09-24 19:33:56.766338257+00:00,160,1,432669,F,B,64.82,2,26,8058566329693,0,27425,94269122,CLX5
2025-09-24 19:33:56.766338257+00:00,160,1,432669,F,B,64.82,1,26,8058566330172,0,27425,94269122,CLX5
2025-09-24 19:33:56.766338257+00:00,160,1,432669,C,B,64.82,1,26,8058566323717,0,27425,94269122,CLX5
2025-09-24 19:33:56.766338257+00:00,160,1,432669,C,B,64.82,1,26,8058566321508,0,27425,94269122,CLX5
2025-09-24 19:33:56.766338257+00:00,160,1,432669,C,B,64.82,1,26,8058566311303,0,27425,94269122,CLX5
2025-09-24 19:33:56.766338257+00:00,160,1,432669,C,B,64.82,1,26,8058566327178,0,27425,94269122,CLX5
2025-09-24 19:33:56.766338257+00:00,160,1,432669,C,B,64.82,1,26,8058566327347,0,27425,94269122,CLX5
2025-09-24 19:33:56.766338257+00:00,160,1,432669,C,B,64.82,2,26,8058566328750,0,27425,94269122,CLX5
2025-09-24 19:33:56.766338257+00:00,160,1,432669,C,B,64.82,3,26,8058566328914,0,27425,94269122,CLX5
2025-09-24 19:33:56.766338257+00:00,160,1,432669,C,B,64.82,1,26,8058566329667,0,27425,94269122,CLX5
2025-09-24 19:33:56.766338257+00:00,160,1,432669,C,B,64.82,2,26,8058566329693,0,27425,94269122,CLX5
2025-09-24 19:33:56.766338257+00:00,160,1,432669,C,B,64.82,1,26,8058566330172,0,27425,94269122,CLX5
2025-09-24 19:33:56.766338257+00:00,160,1,432669,C,B,64.82,1,26,8058566329824,128,27425,94269122,CLX5
2025-09-24 19:33:56.766345505+00:00,160,1,432669,A,A,64.82,1,26,8058566330319,128,20283,94269135,CLX5
2025-09-24 19:33:56.766359741+00:00,160,1,432669,C,B,64.78,2,26,8058566329888,128,18717,94269158,CLX5
2025-09-24 19:33:56.766364831+00:00,160,1,432669,A,A,64.83,1,26,8058566330339,128,20044,94269165,CLX5
2025-09-24 19:33:56.766366385+00:00,160,1,432669,A,A,64.82,1,26,8058566330341,128,17898,94269169,CLX5
2025-09-24 19:33:56.766416393+00:00,160,1,432669,A,A,64.82,1,26,8058566330348,128,17981,94269196,CLX5
2025-09-24 19:33:56.766416927+00:00,160,1,432669,A,A,64.82,1,26,8058566330351,128,15909,94269203,CLX5
2025-09-24 19:33:56.766425767+00:00,160,1,432669,C,B,64.81,1,26,8058566312880,128,14808,94269239,CLX5
2025-09-24 19:33:56.766437451+00:00,160,1,432669,A,A,64.82,2,26,8058566330387,128,20726,94269301,CLX5
2025-09-24 19:33:56.766437629+00:00,160,1,432669,C,B,64.81,2,26,8058566312876,128,14240,94269302,CLX5
2025-09-24 19:33:56.766446271+00:00,160,1,432669,C,B,64.81,2,26,8058566312883,128,17026,94269317,CLX5
2025-09-24 19:33:56.766446427+00:00,160,1,432669,C,B,64.81,1,26,8058566312885,128,14867,94269318,CLX5
2025-09-24 19:33:56.766476089+00:00,160,1,432669,A,A,64.82,2,26,8058566330422,128,16608,94269337,CLX5
2025-09-24 19:33:56.766525257+00:00,160,1,432669,A,A,64.83,2,26,8058566330477,128,19158,94269408,CLX5
2025-09-24 19:33:56.766649343+00:00,160,1,432669,A,A,64.82,1,26,8058566330533,128,18210,94269509,CLX5
2025-09-24 19:33:56.766653797+00:00,160,1,432669,C,B,64.81,1,26,8058566320736,128,14290,94269511,CLX5
2025-09-24 19:33:56.766660095+00:00,160,1,432669,A,A,64.82,3,26,8058566330536,128,19449,94269513,CLX5
2025-09-24 19:33:56.766720245+00:00,160,1,432669,C,B,64.81,2,26,8058566320855,128,15031,94269573,CLX5
2025-09-24 19:33:56.766795467+00:00,160,1,432669,A,A,64.83,1,26,8058566330575,128,18320,94269599,CLX5
2025-09-24 19:33:56.766842467+00:00,160,1,432669,A,A,64.83,2,26,8058566330578,128,18804,94269604,CLX5
2025-09-24 19:33:56.766842773+00:00,160,1,432669,C,B,64.81,2,26,8058566298574,128,15309,94269605,CLX5
2025-09-24 19:33:56.766861475+00:00,160,1,432669,A,A,64.86,1,26,8058566330580,128,14900,94269608,CLX5
2025-09-24 19:33:56.766864891+00:00,160,1,432669,T,A,64.81,3,26,8058566330581,0,14769,94269610,CLX5
2025-09-24 19:33:56.766864891+00:00,160,1,432669,F,B,64.81,3,26,8058566288724,0,14769,94269610,CLX5
2025-09-24 19:33:56.766864891+00:00,160,1,432669,C,B,64.81,3,26,8058566288724,0,17457,94269611,CLX5
2025-09-24 19:33:56.766864891+00:00,160,1,432669,C,B,64.81,1,26,8058566288514,0,17457,94269611,CLX5
2025-09-24 19:33:56.766864891+00:00,160,1,432669,C,B,64.81,1,26,8058566288515,128,17457,94269611,CLX5
2025-09-24 19:33:56.766901965+00:00,160,1,432669,C,B,64.81,2,26,8058566321424,128,18685,94269620,CLX5
2025-09-24 19:33:56.767015875+00:00,160,1,432669,A,A,64.85,1,26,8058566330617,128,14960,94269646,CLX5
2025-09-24 19:33:56.767244669+00:00,160,1,432669,A,A,64.82,2,26,8058566330633,128,15510,94269683,CLX5
2025-09-24 19:33:56.767797509+00:00,160,1,432669,A,A,64.82,1,26,8058566330658,128,15152,94269736,CLX5
2025-09-24 19:33:56.767805093+00:00,160,1,432669,C,A,64.84,1,26,8058566329839,128,14859,94269737,CLX5
2025-09-24 19:33:56.767859579+00:00,160,1,432669,A,A,64.82,1,26,8058566330662,128,15436,94269746,CLX5
2025-09-24 19:33:56.768110357+00:00,160,1,432669,C,B,64.81,1,26,8058566321434,128,21837,94269764,CLX5
2025-09-24 19:33:56.768226381+00:00,160,1,432669,A,B,64.81,1,26,8058566330679,128,18567,94269774,CLX5
2025-09-24 19:33:56.768308687+00:00,160,1,432669,A,A,64.83,3,26,8058566330683,128,15324,94269794,CLX5
2025-09-24 19:33:56.769687389+00:00,160,1,432669,A,A,64.82,1,26,8058566330715,128,16965,94269877,CLX5
2025-09-24 19:33:56.769698071+00:00,160,1,432669,C,B,64.79,1,26,8058566323125,128,17059,94269882,CLX5
2025-09-24 19:33:56.769728099+00:00,160,1,432669,A,A,64.83,1,26,8058566330721,128,15375,94269883,CLX5
2025-09-24 19:33:56.769781819+00:00,160,1,432669,M,A,64.83,1,26,8058566325943,128,14102,94269890,CLX5
2025-09-24 19:33:56.769906017+00:00,160,1,432669,A,A,64.83,1,26,8058566330731,128,15001,94269896,CLX5
2025-09-24 19:33:56.770027337+00:00,160,1,432669,A,A,64.82,1,26,8058566330743,128,14338,94269910,CLX5
2025-09-24 19:33:56.770033981+00:00,160,1,432669,A,B,64.81,1,26,8058566330745,128,18554,94269918,CLX5
2025-09-24 19:33:56.770109085+00:00,160,1,432669,M,B,63.66,4,26,8058566319508,128,16968,94269927,CLX5
2025-09-24 19:33:56.770314709+00:00,160,1,432669,M,A,64.84,3,26,8058566275421,128,14942,94269981,CLX5
2025-09-24 19:33:56.770426467+00:00,160,1,432669,C,B,64.78,1,26,8058566323114,128,14669,94269997,CLX5
2025-09-24 19:33:56.770426615+00:00,160,1,432669,C,B,64.77,1,26,8058566320901,128,18657,94269998,CLX5
2025-09-24 19:33:56.770427273+00:00,160,1,432669,C,B,64.72,2,26,8058566321275,128,14927,94270000,CLX5
2025-09-24 19:33:56.770758977+00:00,160,1,432669,C,A,64.84,3,26,8058566275421,128,16333,94270036,CLX5
2025-09-24 19:33:56.771321513+00:00,160,1,432669,M,A,64.84,3,26,8058566321460,128,13805,94270058,CLX5
2025-09-24 19:33:56.771704519+00:00,160,1,432669,M,A,64.83,1,26,8058566173085,128,15605,94270090,CLX5
2025-09-24 19:33:56.771994117+00:00,160,1,432669,A,A,64.86,2,26,8058566330777,128,15022,94270096,CLX5
2025-09-24 19:33:56.772128013+00:00,160,1,432669,M,A,64.94,1,26,8058565075241,128,14641,94270102,CLX5
2025-09-24 19:33:56.773027377+00:00,160,1,432669,M,A,64.84,1,26,8058566329869,128,15307,94270165,CLX5
2025-09-24 19:33:56.774404187+00:00,160,1,432669,C,A,64.82,2,26,8058566330422,128,15445,94270221,CLX5
2025-09-24 19:33:56.775591541+00:00,160,1,432669,M,A,64.84,1,26,8058566282798,128,15119,94270301,CLX5
2025-09-24 19:33:56.776245711+00:00,160,1,432669,C,A,64.82,1,26,8058566330658,128,18782,94270342,CLX5
2025-09-24 19:33:56.777204153+00:00,160,1,432669,A,B,64.81,1,26,8058566330853,128,18985,94270406,CLX5
2025-09-24 19:33:56.778043253+00:00,160,1,432669,C,B,64.81,1,26,8058566330745,128,14761,94270459,CLX5
2025-09-24 19:33:56.778418461+00:00,160,1,432669,T,A,64.81,1,26,8058566330875,0,15019,94270489,CLX5
2025-09-24 19:33:56.778418461+00:00,160,1,432669,F,B,64.81,1,26,8058566304545,0,15019,94270489,CLX5
2025-09-24 19:33:56.778418461+00:00,160,1,432669,C,B,64.81,1,26,8058566304545,128,17966,94270490,CLX5
2025-09-24 19:33:56.779197141+00:00,160,1,432669,A,B,64.81,1,26,8058566330880,128,18931,94270512,CLX5
2025-09-24 19:33:56.779200751+00:00,160,1,432669,A,B,64.81,1,26,8058566330881,128,15186,94270514,CLX5
2025-09-24 19:33:56.779277681+00:00,160,1,432669,A,B,64.81,1,26,8058566330884,128,19373,94270521,CLX5
2025-09-24 19:33:56.779508627+00:00,160,1,432669,A,B,64.81,1,26,8058566330886,128,16504,94270544,CLX5
2025-09-24 19:33:56.779535947+00:00,160,1,432669,A,B,64.81,2,26,8058566330888,128,16384,94270547,CLX5
2025-09-24 19:33:56.779607867+00:00,160,1,432669,T,A,64.81,2,26,8058566330890,0,15224,94270552,CLX5
2025-09-24 19:33:56.779607867+00:00,160,1,432669,F,B,64.81,1,26,8058566330679,0,15224,94270552,CLX5
2025-09-24 19:33:56.779607867+00:00,160,1,432669,F,B,64.81,1,26,8058566330853,0,15224,94270552,CLX5
2025-09-24 19:33:56.779607867+00:00,160,1,432669,C,B,64.81,1,26,8058566330679,0,16282,94270553,CLX5
2025-09-24 19:33:56.779607867+00:00,160,1,432669,C,B,64.81,1,26,8058566330853,128,16282,94270553,CLX5
2025-09-24 19:33:56.780387391+00:00,160,1,432669,A,A,64.84,1,26,8058566330904,128,14716,94270602,CLX5
2025-09-24 19:33:56.780390443+00:00,160,1,432669,C,A,64.9,1,26,8058566307915,128,18280,94270603,CLX5
2025-09-24 19:33:56.781061705+00:00,160,1,432669,A,B,64.81,1,26,8058566330941,128,16991,94270678,CLX5
2025-09-24 19:33:56.782024447+00:00,160,1,432669,A,B,64.81,1,26,8058566330949,128,19768,94270784,CLX5
2025-09-24 19:33:56.782184125+00:00,160,1,432669,C,A,64.82,1,26,8058566330715,128,19373,94270805,CLX5
2025-09-24 19:33:56.783146119+00:00,160,1,432669,C,B,64.81,2,26,8058566330888,128,16332,94270861,CLX5
2025-09-24 19:33:56.783158099+00:00,160,1,432669,M,A,64.82,1,26,8058566239191,128,15255,94270863,CLX5
2025-09-24 19:33:56.784502021+00:00,160,1,432669,A,B,64.77,1,26,8058566330971,128,15263,94270902,CLX5
2025-09-24 19:33:56.784631019+00:00,160,1,432669,A,B,64.79,1,26,8058566330981,128,14900,94270922,CLX5
2025-09-24 19:33:56.786939603+00:00,160,1,432669,C,A,64.85,1,26,8058566324295,128,18218,94270975,CLX5
2025-09-24 19:33:56.787736003+00:00,160,1,432669,M,A,64.82,1,26,8058566329869,128,19287,94270988,CLX5
2025-09-24 19:33:56.787988759+00:00,160,1,432669,A,A,64.82,1,26,8058566330998,128,19203,94270994,CLX5
2025-09-24 19:33:56.789574417+00:00,160,1,432669,C,A,64.83,1,26,8058566330731,128,14877,94271025,CLX5
2025-09-24 19:33:56.789877897+00:00,160,1,432669,C,B,64.81,1,26,8058566330884,128,16197,94271047,CLX5
2025-09-24 19:33:56.790570085+00:00,160,1,432669,A,B,64.8,1,26,8058566331010,128,13874,94271073,CLX5
2025-09-24 19:33:56.792424493+00:00,160,1,432669,A,B,64.81,1,26,8058566331027,128,19304,94271113,CLX5
2025-09-24 19:33:56.793455871+00:00,160,1,432669,A,B,64.81,1,26,8058566331052,128,16063,94271232,CLX5
2025-09-24 19:33:56.793675951+00:00,160,1,432669,M,A,65.14,1,26,8058566239191,128,15685,94271241,CLX5
2025-09-24 19:33:56.793890545+00:00,160,1,432669,C,B,64.81,1,26,8058566331052,128,16164,94271258,CLX5
2025-09-24 19:33:56.793893363+00:00,160,1,432669,C,B,64.77,1,26,8058566330971,128,14837,94271270,CLX5
2025-09-24 19:33:56.794206213+00:00,160,1,432669,C,B,64.81,1,26,8058566330886,128,16813,94271393,CLX5
2025-09-24 19:33:56.794909959+00:00,160,1,432669,A,A,65.96,4,26,8058566331102,128,14724,94271427,CLX5
2025-09-24 19:33:56.795426703+00:00,160,1,432669,A,B,64.81,2,26,8058566331113,128,17052,94271443,CLX5
2025-09-24 19:33:56.795472051+00:00,160,1,432669,C,A,64.82,1,26,8058566330998,128,15465,94271451,CLX5
2025-09-24 19:33:56.795486605+00:00,160,1,432669,C,A,64.82,1,26,8058566330319,128,15792,94271452,CLX5
2025-09-24 19:33:56.795492345+00:00,160,1,432669,A,B,64.81,1,26,8058566331115,128,19697,94271453,CLX5
2025-09-24 19:33:56.795517919+00:00,160,1,432669,A,B,64.81,2,26,8058566331118,128,19581,94271460,CLX5
2025-09-24 19:33:56.798752035+00:00,160,1,432669,A,B,64.81,1,26,8058566331152,128,14270,94271578,CLX5
2025-09-24 19:33:56.799105989+00:00,160,1,432669,T,B,64.82,1,26,8058566331161,0,14781,94271595,CLX5
2025-09-24 19:33:56.799105989+00:00,160,1,432669,F,A,64.82,1,26,8058566330341,0,14781,94271595,CLX5
2025-09-24 19:33:56.799105989+00:00,160,1,432669,C,A,64.82,1,26,8058566330341,128,16041,94271596,CLX5
2025-09-24 19:33:56.799117107+00:00,160,1,432669,A,B,64.81,1,26,8058566331163,128,18882,94271630,CLX5
2025-09-24 19:33:56.799702335+00:00,160,1,432669,C,B,64.81,2,26,8058566331118,128,19255,94271664,CLX5
2025-09-24 19:33:56.799864241+00:00,160,1,432669,A,A,65.0,1,26,8058566331179,128,14777,94271666,CLX5
2025-09-24 19:33:56.801067799+00:00,160,1,432669,C,A,64.82,1,26,8058566330533,128,19364,94271692,CLX5
2025-09-24 19:33:56.801069161+00:00,160,1,432669,A,B,64.81,2,26,8058566331188,128,15321,94271693,CLX5
2025-09-24 19:33:56.801071543+00:00,160,1,432669,C,A,64.82,1,26,8058566330743,128,15729,94271694,CLX5
2025-09-24 19:33:56.801385641+00:00,160,1,432669,A,B,64.81,2,26,8058566331191,128,18610,94271700,CLX5
2025-09-24 19:33:56.803845511+00:00,160,1,432669,A,B,64.81,1,26,8058566331211,128,18353,94271795,CLX5
2025-09-24 19:33:56.804375141+00:00,160,1,432669,C,B,64.81,1,26,8058566330949,128,15031,94271822,CLX5
2025-09-24 19:33:56.804381439+00:00,160,1,432669,C,B,64.81,1,26,8058566330941,128,15253,94271824,CLX5
2025-09-24 19:33:56.805337729+00:00,160,1,432669,A,B,64.77,1,26,8058566331225,128,15307,94271855,CLX5
2025-09-24 19:33:56.807449711+00:00,160,1,432669,C,B,64.81,1,26,8058566331115,128,15459,94271954,CLX5
2025-09-24 19:33:56.807464303+00:00,160,1,432669,A,A,64.82,1,26,8058566331242,128,15934,94271955,CLX5
2025-09-24 19:33:56.807713681+00:00,160,1,432669,A,B,64.81,1,26,8058566331247,128,15486,94271967,CLX5
2025-09-24 19:33:56.808239027+00:00,160,1,432669,C,A,64.82,1,26,8058566331242,128,20337,94272007,CLX5
2025-09-24 19:33:56.809985037+00:00,160,1,432669,A,A,64.82,1,26,8058566331280,128,19483,94272084,CLX5
2025-09-24 19:33:56.810604037+00:00,160,1,432669,C,A,64.87,2,26,8058566329019,128,14770,94272108,CLX5
2025-09-24 19:33:56.810604555+00:00,160,1,432669,C,A,64.88,2,26,8058566323777,128,14826,94272109,CLX5
2025-09-24 19:33:56.811272935+00:00,160,1,432669,C,A,64.82,1,26,8058566331280,128,15431,94272136,CLX5
2025-09-24 19:33:56.812445871+00:00,160,1,432669,C,A,64.82,2,26,8058566330387,128,16155,94272163,CLX5
2025-09-24 19:33:56.812478393+00:00,160,1,432669,C,A,64.82,1,26,8058566330348,128,16198,94272169,CLX5
2025-09-24 19:33:56.812478545+00:00,160,1,432669,C,A,64.82,1,26,8058566330351,128,16138,94272170,CLX5
2025-09-24 19:33:56.812490949+00:00,160,1,432669,C,A,64.82,2,26,8058566330633,128,20635,94272171,CLX5
2025-09-24 19:33:56.812495095+00:00,160,1,432669,A,B,64.81,2,26,8058566331315,128,15350,94272173,CLX5
2025-09-24 19:33:56.813025051+00:00,160,1,432669,C,A,64.82,1,26,8058566330662,128,17089,94272211,CLX5
2025-09-24 19:33:56.813222225+00:00,160,1,432669,T,B,64.82,4,26,8058566331329,0,15112,94272227,CLX5
2025-09-24 19:33:56.813222225+00:00,160,1,432669,F,A,64.82,3,26,8058566330536,0,15112,94272227,CLX5
2025-09-24 19:33:56.813222225+00:00,160,1,432669,F,A,64.82,1,26,8058566329869,0,15112,94272227,CLX5
2025-09-24 19:33:56.813222225+00:00,160,1,432669,C,A,64.82,3,26,8058566330536,0,19529,94272228,CLX5
2025-09-24 19:33:56.813222225+00:00,160,1,432669,C,A,64.82,1,26,8058566329869,128,19529,94272228,CLX5
2025-09-24 19:33:56.813223147+00:00,160,1,432669,A,B,64.82,1,26,8058566331330,128,15025,94272231,CLX5
2025-09-24 19:33:56.813249199+00:00,160,1,432669,T,A,64.82,1,26,8058566331331,0,15225,94272235,CLX5
2025-09-24 19:33:56.813249199+00:00,160,1,432669,F,B,64.82,1,26,8058566331330,0,15225,94272235,CLX5
2025-09-24 19:33:56.813249199+00:00,160,1,432669,C,B,64.82,1,26,8058566331330,128,15225,94272235,CLX5
2025-09-24 19:33:56.813568239+00:00,160,1,432669,A,A,64.82,1,26,8058566331341,128,18630,94272261,CLX5
2025-09-24 19:33:56.813613485+00:00,160,1,432669,A,B,64.81,2,26,8058566331351,128,17058,94272290,CLX5
2025-09-24 19:33:56.813988789+00:00,160,1,432669,T,B,64.82,1,26,8058566331354,0,14776,94272306,CLX5
2025-09-24 19:33:56.813988789+00:00,160,1,432669,F,A,64.82,1,26,8058566331341,0,14776,94272306,CLX5
2025-09-24 19:33:56.813988789+00:00,160,1,432669,C,A,64.82,1,26,8058566331341,128,14738,94272307,CLX5
2025-09-24 19:33:56.814616085+00:00,160,1,432669,A,B,64.82,1,26,8058566331363,128,15168,94272347,CLX5
2025-09-24 19:33:56.814881933+00:00,160,1,432669,T,N,64.82,1,26,0,0,15128,94272367,CLX5
2025-09-24 19:33:56.814881933+00:00,160,1,432669,F,N,64.82,1,26,8058566331363,0,15128,94272367,CLX5
2025-09-24 19:33:56.814881933+00:00,160,1,432669,C,B,64.82,1,26,8058566331363,128,18156,94272368,CLX5
2025-09-24 19:33:56.815371071+00:00,160,1,432669,A,B,64.82,1,26,8058566331378,128,14968,94272392,CLX5
2025-09-24 19:33:56.815991857+00:00,160,1,432669,M,A,64.83,3,26,8058566282770,128,15477,94272436,CLX5
2025-09-24 19:33:56.816084283+00:00,160,1,432669,C,A,65.9,1,26,8058566302406,128,17860,94272440,CLX5
2025-09-24 19:33:56.816161731+00:00,160,1,432669,A,B,64.78,1,26,8058566331393,128,18363,94272459,CLX5
2025-09-24 19:33:56.822863483+00:00,160,1,432669,A,B,64.81,1,26,8058566331492,128,15136,94272764,CLX5
2025-09-24 19:33:56.824339417+00:00,160,1,432669,M,A,65.97,4,26,8058566282770,128,19141,94272794,CLX5
2025-09-24 19:33:56.824356525+00:00,160,1,432669,A,B,64.82,1,26,8058566331498,128,18200,94272796,CLX5
2025-09-24 19:33:56.824356701+00:00,160,1,432669,C,A,64.83,1,26,8058566330575,128,16348,94272798,CLX5
2025-09-24 19:33:56.824366143+00:00,160,1,432669,C,A,64.84,1,26,8058566330904,128,18027,94272807,CLX5
2025-09-24 19:33:56.824419441+00:00,160,1,432669,A,B,64.82,1,26,8058566331502,128,14861,94272811,CLX5
2025-09-24 19:33:56.824530009+00:00,160,1,432669,C,B,64.82,1,26,8058566331502,128,18294,94272824,CLX5
2025-09-24 19:33:56.824550993+00:00,160,1,432669,A,B,64.81,3,26,8058566331508,128,14996,94272830,CLX5
2025-09-24 19:33:56.824563415+00:00,160,1,432669,C,B,64.82,1,26,8058566331498,128,14765,94272832,CLX5
2025-09-24 19:33:56.824876841+00:00,160,1,432669,A,B,64.82,1,26,8058566331511,128,17843,94272845,CLX5
2025-09-24 19:33:56.825441737+00:00,160,1,432669,C,B,64.82,1,26,8058566331511,128,17927,94272860,CLX5
2025-09-24 19:33:56.825757967+00:00,160,1,432669,A,B,64.81,1,26,8058566331521,128,14808,94272876,CLX5
2025-09-24 19:33:56.825945313+00:00,160,1,432669,A,B,64.82,1,26,8058566331522,128,20119,94272878,CLX5
2025-09-24 19:33:56.826012451+00:00,160,1,432669,A,B,64.82,1,26,8058566331524,128,14745,94272886,CLX5
2025-09-24 19:33:56.826286923+00:00,160,1,432669,A,B,64.81,1,26,8058566331529,128,15054,94272894,CLX5
2025-09-24 19:33:56.826514739+00:00,160,1,432669,C,B,64.82,1,26,8058566331522,128,14810,94272906,CLX5
2025-09-24 19:33:56.826517639+00:00,160,1,432669,T,A,64.82,1,26,8058566331533,0,15332,94272909,CLX5
2025-09-24 19:33:56.826517639+00:00,160,1,432669,F,B,64.82,1,26,8058566331378,0,15332,94272909,CLX5
2025-09-24 19:33:56.826517639+00:00,160,1,432669,C,B,64.82,1,26,8058566331378,128,15332,94272909,CLX5
2025-09-24 19:33:56.826885013+00:00,160,1,432669,C,B,64.82,1,26,8058566331524,128,18703,94272919,CLX5
2025-09-24 19:33:56.826887049+00:00,160,1,432669,A,B,64.82,1,26,8058566331536,128,14310,94272922,CLX5
2025-09-24 19:33:56.827331835+00:00,160,1,432669,A,B,64.82,1,26,8058566331545,128,17873,94272946,CLX5
2025-09-24 19:33:56.827339229+00:00,160,1,432669,A,B,64.82,1,26,8058566331546,128,17025,94272948,CLX5
2025-09-24 19:33:56.828028037+00:00,160,1,432669,C,B,64.82,1,26,8058566331545,128,15181,94272968,CLX5
2025-09-24 19:33:56.829126573+00:00,160,1,432669,A,B,64.82,1,26,8058566331564,128,19109,94273007,CLX5
2025-09-24 19:33:56.829405153+00:00,160,1,432669,A,B,64.82,1,26,8058566331565,128,22897,94273013,CLX5
2025-09-24 19:33:56.829405537+00:00,160,1,432669,A,B,64.82,1,26,8058566331566,128,17376,94273014,CLX5
2025-09-24 19:33:56.829405729+00:00,160,1,432669,A,B,64.82,1,26,8058566331567,128,16660,94273015,CLX5
2025-09-24 19:33:56.829534997+00:00,160,1,432669,A,B,64.82,1,26,8058566331568,128,16129,94273019,CLX5
2025-09-24 19:33:56.829548053+00:00,160,1,432669,A,B,64.82,2,26,8058566331569,128,19531,94273021,CLX5
2025-09-24 19:33:56.829830625+00:00,160,1,432669,A,B,64.82,1,26,8058566331576,128,16194,94273051,CLX5
2025-09-24 19:33:56.832326323+00:00,160,1,432669,A,B,64.72,2,26,8058566331591,128,15001,94273120,CLX5
2025-09-24 19:33:56.833683799+00:00,160,1,432669,M,A,64.95,1,26,8058565075241,128,17107,94273179,CLX5
2025-09-24 19:33:56.834489013+00:00,160,1,432669,M,B,64.81,1,26,8058566331010,128,18442,94273199,CLX5
2025-09-24 19:33:56.834830449+00:00,160,1,432669,T,A,64.82,1,26,8058566331616,0,14669,94273212,CLX5
2025-09-24 19:33:56.834830449+00:00,160,1,432669,F,B,64.82,1,26,8058566331536,0,14669,94273212,CLX5
2025-09-24 19:33:56.834830449+00:00,160,1,432669,C,B,64.82,1,26,8058566331536,128,16519,94273213,CLX5
2025-09-24 19:33:56.835380409+00:00,160,1,432669,A,B,64.82,1,26,8058566331617,128,19734,94273215,CLX5
2025-09-24 19:33:56.835716683+00:00,160,1,432669,A,A,65.95,3,26,8058566331622,128,15567,94273230,CLX5
2025-09-24 19:33:56.836305865+00:00,160,1,432669,T,A,64.82,1,26,8058566331628,0,14915,94273242,CLX5
2025-09-24 19:33:56.836305865+00:00,160,1,432669,F,B,64.82,1,26,8058566331546,0,14915,94273242,CLX5
2025-09-24 19:33:56.836305865+00:00,160,1,432669,C,B,64.82,1,26,8058566331546,128,20127,94273243,CLX5
2025-09-24 19:33:56.836475433+00:00,160,1,432669,C,B,64.82,1,26,8058566331568,128,15847,94273246,CLX5
2025-09-24 19:33:56.836550579+00:00,160,1,432669,C,B,64.82,1,26,8058566331576,128,16204,94273251,CLX5
2025-09-24 19:33:56.836724139+00:00,160,1,432669,C,B,64.82,1,26,8058566331565,128,16299,94273259,CLX5
2025-09-24 19:33:56.836909411+00:00,160,1,432669,A,B,64.82,1,26,8058566331631,128,19351,94273260,CLX5
2025-09-24 19:33:56.837229807+00:00,160,1,432669,C,B,64.82,1,26,8058566331564,128,19554,94273266,CLX5
2025-09-24 19:33:56.837881771+00:00,160,1,432669,A,B,64.82,1,26,8058566331650,128,16067,94273285,CLX5
2025-09-24 19:33:56.838242831+00:00,160,1,432669,C,B,64.82,2,26,8058566331569,128,16899,94273301,CLX5
2025-09-24 19:33:56.838369891+00:00,160,1,432669,C,B,64.82,1,26,8058566331617,128,20569,94273303,CLX5
2025-09-24 19:33:56.838451123+00:00,160,1,432669,A,B,64.82,2,26,8058566331661,128,15853,94273314,CLX5
2025-09-24 19:33:56.838462661+00:00,160,1,432669,C,B,64.82,1,26,8058566331631,128,19688,94273321,CLX5
2025-09-24 19:33:56.839746413+00:00,160,1,432669,T,A,64.82,1,26,8058566331683,0,14787,94273379,CLX5
2025-09-24 19:33:56.839746413+00:00,160,1,432669,F,B,64.82,1,26,8058566331566,0,14787,94273379,CLX5
2025-09-24 19:33:56.839746413+00:00,160,1,432669,C,B,64.82,1,26,8058566331566,128,14787,94273379,CLX5
2025-09-24 19:33:56.839980449+00:00,160,1,432669,C,B,64.82,1,26,8058566331567,128,17997,94273397,CLX5
2025-09-24 19:33:56.841460685+00:00,160,1,432669,T,A,64.82,3,26,8058566331707,0,15852,94273466,CLX5
2025-09-24 19:33:56.841460685+00:00,160,1,432669,F,B,64.82,1,26,8058566331650,0,15852,94273466,CLX5
2025-09-24 19:33:56.841460685+00:00,160,1,432669,F,B,64.82,2,26,8058566331661,0,15852,94273466,CLX5
2025-09-24 19:33:56.841460685+00:00,160,1,432669,C,B,64.82,1,26,8058566331650,0,15852,94273466,CLX5
2025-09-24 19:33:56.841460685+00:00,160,1,432669,C,B,64.82,2,26,8058566331661,128,15852,94273466,CLX5
2025-09-24 19:33:56.843412835+00:00,160,1,432669,M,A,64.84,1,26,8058566173085,128,17610,94273536,CLX5
2025-09-24 19:33:56.846926723+00:00,160,1,432669,A,A,64.84,1,26,8058566331778,128,15223,94273642,CLX5
2025-09-24 19:33:56.848093859+00:00,160,1,432669,C,A,64.84,1,26,8058566331778,128,15193,94273665,CLX5
2025-09-24 19:33:56.849404911+00:00,160,1,432669,A,A,64.82,1,26,8058566331801,128,18728,94273713,CLX5
2025-09-24 19:33:56.850655505+00:00,160,1,432669,C,B,64.81,2,26,8058566331315,128,14584,94273758,CLX5
2025-09-24 19:33:56.850934527+00:00,160,1,432669,A,A,64.82,2,26,8058566331821,128,14842,94273771,CLX5
2025-09-24 19:33:56.858152217+00:00,160,1,432669,T,B,64.82,1,26,8058566331861,0,17860,94273878,CLX5
2025-09-24 19:33:56.858152217+00:00,160,1,432669,F,A,64.82,1,26,8058566331801,0,17860,94273878,CLX5
2025-09-24 19:33:56.858152217+00:00,160,1,432669,C,A,64.82,1,26,8058566331801,128,15103,94273879,CLX5
2025-09-24 19:33:56.858400579+00:00,160,1,432669,T,B,64.82,2,26,8058566331864,0,18226,94273888,CLX5
2025-09-24 19:33:56.858400579+00:00,160,1,432669,F,A,64.82,2,26,8058566331821,0,18226,94273888,CLX5
2025-09-24 19:33:56.858400579+00:00,160,1,432669,C,A,64.82,2,26,8058566331821,128,15112,94273889,CLX5
2025-09-24 19:33:56.858735373+00:00,160,1,432669,A,B,64.82,1,26,8058566331867,128,17830,94273900,CLX5
2025-09-24 19:33:56.858992947+00:00,160,1,432669,A,B,64.82,1,26,8058566331871,128,15053,94273916,CLX5
2025-09-24 19:33:56.859001357+00:00,160,1,432669,T,A,64.82,1,26,8058566331872,0,14897,94273919,CLX5
2025-09-24 19:33:56.859001357+00:00,160,1,432669,F,B,64.82,1,26,8058566331867,0,14897,94273919,CLX5
2025-09-24 19:33:56.859001357+00:00,160,1,432669,C,B,64.82,1,26,8058566331867,128,14897,94273919,CLX5
2025-09-24 19:33:56.859047857+00:00,160,1,432669,T,A,64.82,1,26,8058566331874,0,15539,94273922,CLX5
2025-09-24 19:33:56.859047857+00:00,160,1,432669,F,B,64.82,1,26,8058566331871,0,15539,94273922,CLX5
2025-09-24 19:33:56.859047857+00:00,160,1,432669,C,B,64.82,1,26,8058566331871,128,14713,94273923,CLX5
2025-09-24 19:33:56.865748307+00:00,160,1,432669,A,A,64.82,1,26,8058566331891,128,18521,94273960,CLX5
2025-09-24 19:33:56.866343825+00:00,160,1,432669,A,A,64.82,2,26,8058566331892,128,16716,94273966,CLX5
2025-09-24 19:33:56.868741893+00:00,160,1,432669,A,B,64.79,1,26,8058566331895,128,17751,94273974,CLX5
2025-09-24 19:33:56.884233537+00:00,160,1,432669,A,B,64.81,1,26,8058566331914,128,17579,94274024,CLX5
2025-09-24 19:33:56.884765911+00:00,160,1,432669,M,A,64.83,1,26,8058566331891,128,18407,94274025,CLX5
2025-09-24 19:33:56.884854841+00:00,160,1,432669,A,B,64.8,2,26,8058566331915,128,14184,94274028,CLX5
2025-09-24 19:33:56.884858931+00:00,160,1,432669,A,B,64.79,2,26,8058566331916,128,17576,94274029,CLX5
2025-09-24 19:33:56.910266323+00:00,160,1,432669,A,A,64.87,2,26,8058566331963,128,15027,94274091,CLX5
2025-09-24 19:33:56.915828239+00:00,160,1,432669,A,A,65.9,1,26,8058566331990,128,18183,94274122,CLX5
2025-09-24 19:33:56.931180689+00:00,160,1,432669,A,B,64.8,1,26,8058566332034,128,14805,94274176,CLX5
2025-09-24 19:33:57.010247581+00:00,160,1,432669,A,B,64.77,2,26,8058566332230,128,18378,94274462,CLX5
2025-09-24 19:33:57.032522881+00:00,160,1,432669,C,A,64.82,2,26,8058566331892,128,18269,94274529,CLX5
2025-09-24 19:33:57.032881713+00:00,160,1,432669,C,A,64.85,1,26,8058566330617,128,14807,94274538,CLX5
2025-09-24 19:33:57.087596841+00:00,160,1,432669,C,B,64.8,1,26,8058566332034,128,18048,94274709,CLX5
2025-09-24 19:33:57.166289965+00:00,160,1,432669,A,A,64.83,1,26,8058566332416,128,17267,94274774,CLX5
2025-09-24 19:33:57.166455597+00:00,160,1,432669,C,B,64.81,1,26,8058566331914,128,19178,94274775,CLX5
2025-09-24 19:33:57.991134503+00:00,160,1,432669,A,B,64.82,1,26,8058566332654,128,18070,94275226,CLX5
2025-09-24 19:33:57.991135329+00:00,160,1,432669,A,B,64.82,1,26,8058566332656,128,15349,94275229,CLX5
2025-09-24 19:33:57.991159711+00:00,160,1,432669,A,B,64.82,1,26,8058566332658,128,15152,94275239,CLX5
2025-09-24 19:33:57.991202065+00:00,160,1,432669,A,B,64.81,2,26,8058566332659,128,14620,94275241,CLX5
2025-09-24 19:33:57.991394845+00:00,160,1,432669,C,B,64.81,1,26,8058566331492,128,17389,94275245,CLX5
2025-09-24 19:33:57.991409127+00:00,160,1,432669,C,B,64.82,1,26,8058566332656,128,14844,94275247,CLX5
2025-09-24 19:33:57.991440211+00:00,160,1,432669,A,B,64.82,1,26,8058566332662,128,14072,94275251,CLX5
2025-09-24 19:33:57.991790941+00:00,160,1,432669,A,B,64.81,1,26,8058566332666,128,15361,94275266,CLX5
2025-09-24 19:33:57.991829723+00:00,160,1,432669,A,B,64.82,2,26,8058566332667,128,18272,94275267,CLX5
2025-09-24 19:33:57.992198443+00:00,160,1,432669,M,B,64.81,3,26,8058566319508,128,15450,94275274,CLX5
2025-09-24 19:33:57.993114397+00:00,160,1,432669,T,A,64.82,5,26,8058566332669,0,18235,94275276,CLX5
2025-09-24 19:33:57.993114397+00:00,160,1,432669,F,B,64.82,1,26,8058566332654,0,18235,94275276,CLX5
2025-09-24 19:33:57.993114397+00:00,160,1,432669,F,B,64.82,1,26,8058566332658,0,18235,94275276,CLX5
2025-09-24 19:33:57.993114397+00:00,160,1,432669,F,B,64.82,1,26,8058566332662,0,18235,94275276,CLX5
2025-09-24 19:33:57.993114397+00:00,160,1,432669,F,B,64.82,2,26,8058566332667,0,18235,94275276,CLX5
2025-09-24 19:33:57.993114397+00:00,160,1,432669,C,B,64.82,1,26,8058566332654,0,14831,94275277,CLX5
2025-09-24 19:33:57.993114397+00:00,160,1,432669,C,B,64.82,1,26,8058566332658,0,14831,94275277,CLX5
2025-09-24 19:33:57.993114397+00:00,160,1,432669,C,B,64.82,1,26,8058566332662,0,14831,94275277,CLX5
2025-09-24 19:33:57.993114397+00:00,160,1,432669,C,B,64.82,2,26,8058566332667,128,14831,94275277,CLX5
2025-09-24 19:33:57.993446925+00:00,160,1,432669,A,A,64.82,1,26,8058566332672,128,18016,94275287,CLX5
2025-09-24 19:33:57.993468045+00:00,160,1,432669,C,B,64.81,2,26,8058566332659,128,19047,94275292,CLX5
2025-09-24 19:33:57.993702023+00:00,160,1,432669,M,B,63.66,4,26,8058566319508,128,17653,94275298,CLX5
2025-09-24 19:33:58.002230865+00:00,160,1,432669,M,B,64.81,3,26,8058566319851,128,18904,94275313,CLX5
2025-09-24 19:33:58.008337885+00:00,160,1,432669,A,B,63.67,4,26,8058566332677,128,18387,94275314,CLX5
2025-09-24 19:33:58.037421453+00:00,160,1,432669,A,B,64.8,1,26,8058566332682,128,20781,94275327,CLX5
2025-09-24 19:33:59.406771827+00:00,160,1,432669,A,B,64.81,1,26,8058566332855,128,19084,94275674,CLX5
2025-09-24 19:33:59.406953317+00:00,160,1,432669,C,A,64.82,1,26,8058566332672,128,16839,94275677,CLX5
2025-09-24 19:33:59.407186837+00:00,160,1,432669,A,B,64.82,1,26,8058566332859,128,15868,94275689,CLX5
2025-09-24 19:33:59.407674745+00:00,160,1,432669,M,A,65.98,4,26,8058566321460,128,15068,94275703,CLX5
2025-09-24 19:33:59.407687013+00:00,160,1,432669,M,A,65.99,4,26,8058566282798,128,15061,94275705,CLX5
2025-09-24 19:33:59.448159825+00:00,160,1,432669,T,A,64.82,1,26,8058566332870,0,18422,94275726,CLX5
2025-09-24 19:33:59.448159825+00:00,160,1,432669,F,B,64.82,1,26,8058566332859,0,18422,94275726,CLX5
2025-09-24 19:33:59.448159825+00:00,160,1,432669,C,B,64.82,1,26,8058566332859,128,14778,94275727,CLX5
2025-09-24 19:33:59.448476305+00:00,160,1,432669,C,B,64.8,1,26,8058566332682,128,15074,94275738,CLX5
2025-09-24 19:33:59.448585815+00:00,160,1,432669,A,A,64.83,1,26,8058566332875,128,15143,94275743,CLX5
2025-09-24 19:33:59.448701799+00:00,160,1,432669,A,A,64.83,1,26,8058566332876,128,15542,94275745,CLX5
2025-09-24 19:33:59.448796587+00:00,160,1,432669,A,A,64.83,1,26,8058566332877,128,14261,94275747,CLX5
2025-09-24 19:33:59.449204029+00:00,160,1,432669,M,B,63.65,4,26,8058566319851,128,18446,94275761,CLX5
2025-09-24 19:33:59.461808907+00:00,160,1,432669,A,A,64.83,1,26,8058566332889,128,18429,94275798,CLX5
2025-09-24 19:33:59.461991433+00:00,160,1,432669,C,A,64.83,1,26,8058566332877,128,15381,94275801,CLX5
2025-09-24 19:33:59.461996349+00:00,160,1,432669,C,A,64.83,1,26,8058566332876,128,14966,94275802,CLX5
2025-09-24 19:33:59.462001301+00:00,160,1,432669,C,A,64.83,1,26,8058566332875,128,18387,94275803,CLX5
2025-09-24 19:33:59.507368921+00:00,160,1,432669,A,B,64.82,2,26,8058566332898,128,14637,94275821,CLX5
2025-09-24 19:34:00.249681311+00:00,160,1,432669,C,B,64.81,1,26,8058566332666,128,19092,94276162,CLX5
2025-09-24 19:34:00.249692139+00:00,160,1,432669,C,B,64.81,1,26,8058566331529,128,14985,94276163,CLX5
2025-09-24 19:34:00.249857253+00:00,160,1,432669,C,B,64.81,1,26,8058566331521,128,18400,94276164,CLX5
2025-09-24 19:34:01.475591553+00:00,160,1,432669,T,A,64.82,1,26,8058566333069,0,18680,94276331,CLX5
2025-09-24 19:34:01.475591553+00:00,160,1,432669,F,B,64.82,1,26,8058566332898,0,18680,94276331,CLX5
2025-09-24 19:34:01.475591553+00:00,160,1,432669,M,B,64.82,1,26,8058566332898,128,15027,94276332,CLX5
2025-09-24 19:34:01.475869133+00:00,160,1,432669,T,A,64.82,1,26,8058566333071,0,18288,94276336,CLX5
2025-09-24 19:34:01.475869133+00:00,160,1,432669,F,B,64.82,1,26,8058566332898,0,18288,94276336,CLX5
2025-09-24 19:34:01.475869133+00:00,160,1,432669,C,B,64.82,1,26,8058566332898,128,14648,94276337,CLX5
2025-09-24 19:34:01.476145565+00:00,160,1,432669,A,B,64.81,2,26,8058566333074,128,16771,94276344,CLX5
2025-09-24 19:34:01.972976929+00:00,160,1,432669,A,B,64.82,1,26,8058566333099,128,19025,94276413,CLX5
2025-09-24 19:34:01.972995015+00:00,160,1,432669,A,B,64.82,2,26,8058566333100,128,17203,94276415,CLX5
2025-09-24 19:34:01.973012773+00:00,160,1,432669,A,B,64.82,2,26,8058566333101,128,17536,94276418,CLX5
2025-09-24 19:34:01.973245677+00:00,160,1,432669,A,B,64.82,1,26,8058566333103,128,16429,94276425,CLX5
2025-09-24 19:34:01.973301855+00:00,160,1,432669,A,B,64.82,1,26,8058566333104,128,18527,94276427,CLX5
2025-09-24 19:34:02.095254069+00:00,160,1,432669,C,B,64.82,2,26,8058566333101,128,21072,94276489,CLX5
2025-09-24 19:34:02.096947973+00:00,160,1,432669,M,B,64.81,3,26,8058566319851,128,18486,94276492,CLX5
2025-09-24 19:34:02.677267871+00:00,160,1,432669,A,B,64.82,2,26,8058566333154,128,21271,94276568,CLX5
2025-09-24 19:34:02.677931913+00:00,160,1,432669,A,B,64.82,1,26,8058566333156,128,19539,94276574,CLX5
2025-09-24 19:34:02.678064541+00:00,160,1,432669,A,B,64.82,1,26,8058566333157,128,19278,94276578,CLX5
2025-09-24 19:34:02.678076311+00:00,160,1,432669,A,B,64.82,1,26,8058566333158,128,14873,94276579,CLX5
2025-09-24 19:34:02.678538491+00:00,160,1,432669,A,B,64.82,1,26,8058566333166,128,15012,94276602,CLX5
2025-09-24 19:34:02.678580999+00:00,160,1,432669,C,A,64.83,2,26,8058566330477,128,19057,94276617,CLX5
2025-09-24 19:34:02.678696289+00:00,160,1,432669,A,B,64.82,1,26,8058566333171,128,19085,94276622,CLX5
2025-09-24 19:34:02.678798179+00:00,160,1,432669,A,B,64.82,1,26,8058566333177,128,15397,94276636,CLX5
2025-09-24 19:34:02.678957321+00:00,160,1,432669,C,B,64.82,1,26,8058566333171,128,15735,94276645,CLX5
2025-09-24 19:34:02.810530251+00:00,160,1,432669,A,B,64.78,2,26,8058566333334,128,18175,94277223,CLX5
2025-09-24 19:34:03.002396737+00:00,160,1,432669,C,B,64.82,1,26,8058566333104,128,18643,94277315,CLX5
2025-09-24 19:34:03.002558491+00:00,160,1,432669,C,B,64.82,1,26,8058566333157,128,19173,94277316,CLX5
2025-09-24 19:34:03.002565421+00:00,160,1,432669,C,B,64.82,1,26,8058566333166,128,16026,94277317,CLX5
2025-09-24 19:34:03.181671057+00:00,160,1,432669,T,A,64.82,1,26,8058566333398,0,18772,94277369,CLX5
2025-09-24 19:34:03.181671057+00:00,160,1,432669,F,B,64.82,1,26,8058566333099,0,18772,94277369,CLX5
2025-09-24 19:34:03.181671057+00:00,160,1,432669,C,B,64.82,1,26,8058566333099,128,15962,94277370,CLX5
2025-09-24 19:34:04.104065155+00:00,160,1,432669,T,A,64.82,1,26,8058566333465,0,18478,94277508,CLX5
2025-09-24 19:34:04.104065155+00:00,160,1,432669,F,B,64.82,1,26,8058566333100,0,18478,94277508,CLX5
2025-09-24 19:34:04.104065155+00:00,160,1,432669,M,B,64.82,1,26,8058566333100,128,20094,94277509,CLX5
2025-09-24 19:34:04.432234133+00:00,160,1,432669,C,B,64.78,2,26,8058566333334,128,14960,94277773,CLX5
2025-09-24 19:34:04.434982377+00:00,160,1,432669,A,B,64.82,1,26,8058566333549,128,19429,94277826,CLX5
2025-09-24 19:34:04.435153039+00:00,160,1,432669,T,A,64.82,1,26,8058566333552,0,18141,94277829,CLX5
2025-09-24 19:34:04.435153039+00:00,160,1,432669,F,B,64.82,1,26,8058566333100,0,18141,94277829,CLX5
2025-09-24 19:34:04.435153039+00:00,160,1,432669,C,B,64.82,1,26,8058566333100,128,16306,94277830,CLX5
2025-09-24 19:34:04.438670783+00:00,160,1,432669,A,B,64.82,1,26,8058566333563,128,18068,94277865,CLX5
2025-09-24 19:34:04.450403367+00:00,160,1,432669,C,A,65.03,1,26,8058566324730,128,19236,94277898,CLX5
2025-09-24 19:34:04.452795389+00:00,160,1,432669,C,B,64.82,1,26,8058566333549,128,19774,94277905,CLX5
2025-09-24 19:34:04.452796061+00:00,160,1,432669,C,B,64.82,1,26,8058566333563,128,15171,94277906,CLX5
2025-09-24 19:34:04.544457197+00:00,160,1,432669,A,A,65.01,1,26,8058566333574,128,18163,94277930,CLX5
2025-09-24 19:34:04.858497097+00:00,160,1,432669,C,A,65.21,1,26,8058566277403,128,17782,94277946,CLX5
2025-09-24 19:34:04.968541231+00:00,160,1,432669,A,A,65.13,1,26,8058566333583,128,18994,94277947,CLX5
2025-09-24 19:34:05.634942641+00:00,160,1,432669,A,B,64.82,1,26,8058566333591,128,14939,94277995,CLX5
2025-09-24 19:34:05.634947783+00:00,160,1,432669,A,B,64.82,2,26,8058566333592,128,16244,94277997,CLX5
2025-09-24 19:34:05.635004209+00:00,160,1,432669,A,B,64.82,2,26,8058566333598,128,15007,94278007,CLX5
2025-09-24 19:34:05.635192975+00:00,160,1,432669,A,B,64.82,2,26,8058566333599,128,15481,94278008,CLX5
2025-09-24 19:34:05.635202097+00:00,160,1,432669,C,A,64.86,2,26,8058566330777,128,19086,94278010,CLX5
2025-09-24 19:34:05.635288125+00:00,160,1,432669,C,B,64.82,2,26,8058566333598,128,20705,94278027,CLX5
2025-09-24 19:34:05.636104763+00:00,160,1,432669,C,B,64.82,2,26,8058566333599,128,16087,94278062,CLX5
2025-09-24 19:34:05.668565041+00:00,160,1,432669,A,A,64.86,2,26,8058566333636,128,18073,94278183,CLX5
2025-09-24 19:34:05.668720669+00:00,160,1,432669,C,B,64.82,2,26,8058566333592,128,19671,94278184,CLX5
2025-09-24 19:34:05.694538481+00:00,160,1,432669,C,A,64.86,2,26,8058566333636,128,19022,94278190,CLX5
2025-09-24 19:34:05.694668477+00:00,160,1,432669,A,B,64.82,1,26,8058566333637,128,16355,94278195,CLX5
2025-09-24 19:34:05.694668689+00:00,160,1,432669,A,B,64.82,1,26,8058566333638,128,16333,94278196,CLX5
2025-09-24 19:34:05.710238357+00:00,160,1,432669,A,A,64.88,2,26,8058566333657,128,18032,94278268,CLX5
2025-09-24 19:34:05.780507259+00:00,160,1,432669,C,B,64.79,1,26,8058566330981,128,18024,94278338,CLX5
2025-09-24 19:34:05.810557217+00:00,160,1,432669,A,B,64.78,2,26,8058566333689,128,18301,94278360,CLX5
2025-09-24 19:34:06.087234337+00:00,160,1,432669,C,B,64.78,2,26,8058566333689,128,14616,94278481,CLX5
2025-09-24 19:34:06.779998239+00:00,160,1,432669,A,B,64.82,1,26,8058566333799,128,19518,94278728,CLX5
2025-09-24 19:34:06.874358277+00:00,160,1,432669,C,B,64.82,1,26,8058566333799,128,16874,94278877,CLX5
2025-09-24 19:34:06.874917527+00:00,160,1,432669,C,A,64.83,1,26,8058566330308,128,18652,94278933,CLX5
2025-09-24 19:34:06.875775039+00:00,160,1,432669,A,B,64.82,1,26,8058566333874,128,16813,94279029,CLX5
2025-09-24 19:34:06.876417001+00:00,160,1,432669,A,B,64.82,1,26,8058566333888,128,15820,94279073,CLX5
2025-09-24 19:34:06.876517891+00:00,160,1,432669,A,B,64.82,1,26,8058566333889,128,18634,94279076,CLX5
2025-09-24 19:34:06.876626097+00:00,160,1,432669,C,A,64.83,1,26,8058566330283,128,18478,94279088,CLX5
2025-09-24 19:34:06.876626397+00:00,160,1,432669,C,A,64.83,1,26,8058566330284,128,15135,94279090,CLX5
2025-09-24 19:34:06.876626723+00:00,160,1,432669,A,B,64.82,2,26,8058566333896,128,15028,94279093,CLX5
2025-09-24 19:34:06.876653477+00:00,160,1,432669,A,B,64.82,2,26,8058566333900,128,15359,94279099,CLX5
2025-09-24 19:34:06.876743693+00:00,160,1,432669,C,A,64.83,2,26,8058566330305,128,15147,94279105,CLX5
2025-09-24 19:34:06.876807951+00:00,160,1,432669,A,B,64.81,2,26,8058566333906,128,15152,94279115,CLX5
2025-09-24 19:34:06.876810851+00:00,160,1,432669,C,A,64.83,1,26,8058566330339,128,18495,94279121,CLX5
2025-09-24 19:34:06.876816765+00:00,160,1,432669,C,A,64.83,1,26,8058566330307,128,15383,94279124,CLX5
2025-09-24 19:34:06.876861115+00:00,160,1,432669,C,A,64.83,2,26,8058566330578,128,19413,94279137,CLX5
2025-09-24 19:34:06.878671307+00:00,160,1,432669,C,A,64.83,1,26,8058566330721,128,19512,94279234,CLX5
2025-09-24 19:34:06.878903579+00:00,160,1,432669,C,B,64.82,2,26,8058566333900,128,18484,94279238,CLX5
2025-09-24 19:34:06.879203815+00:00,160,1,432669,A,B,64.82,1,26,8058566333949,128,17610,94279251,CLX5
2025-09-24 19:34:06.879878973+00:00,160,1,432669,C,A,64.86,1,26,8058566330580,128,19336,94279281,CLX5
2025-09-24 19:34:06.880345243+00:00,160,1,432669,M,A,64.84,1,26,8058566325943,128,16715,94279309,CLX5
2025-09-24 19:34:06.880727537+00:00,160,1,432669,C,A,64.83,1,26,8058566330285,128,17256,94279322,CLX5
2025-09-24 19:34:06.881345633+00:00,160,1,432669,C,A,64.83,1,26,8058566330278,128,16153,94279394,CLX5
2025-09-24 19:34:06.882067349+00:00,160,1,432669,C,A,64.83,3,26,8058566330683,128,18205,94279438,CLX5
2025-09-24 19:34:06.886495077+00:00,160,1,432669,A,B,64.82,2,26,8058566334061,128,14904,94279672,CLX5
2025-09-24 19:34:06.889048259+00:00,160,1,432669,C,B,64.82,2,26,8058566334061,128,18496,94279745,CLX5
2025-09-24 19:34:06.891075785+00:00,160,1,432669,A,A,64.83,2,26,8058566334104,128,16815,94279844,CLX5
2025-09-24 19:34:06.891093199+00:00,160,1,432669,A,A,64.83,1,26,8058566334105,128,20632,94279845,CLX5
2025-09-24 19:34:06.891093391+00:00,160,1,432669,A,A,64.83,1,26,8058566334106,128,15357,94279846,CLX5
2025-09-24 19:34:06.891746737+00:00,160,1,432669,A,A,64.83,1,26,8058566334112,128,19637,94279891,CLX5
2025-09-24 19:34:06.891871897+00:00,160,1,432669,C,B,64.82,2,26,8058566333896,128,18513,94279895,CLX5
2025-09-24 19:34:06.892516259+00:00,160,1,432669,C,B,64.81,2,26,8058566333906,128,15651,94279919,CLX5
2025-09-24 19:34:06.892522327+00:00,160,1,432669,A,A,64.83,1,26,8058566334123,128,19195,94279926,CLX5
2025-09-24 19:34:06.981500803+00:00,160,1,432669,M,A,64.83,1,26,8058566325943,128,20021,94280425,CLX5
2025-09-24 19:34:06.981683501+00:00,160,1,432669,C,A,64.83,1,26,8058566334123,128,15631,94280428,CLX5
2025-09-24 19:34:07.010275495+00:00,160,1,432669,A,B,64.78,2,26,8058566334354,128,18469,94280598,CLX5
2025-09-24 19:34:07.188513985+00:00,160,1,432669,C,A,64.83,1,26,8058566334112,128,19480,94281157,CLX5
2025-09-24 19:34:07.188514253+00:00,160,1,432669,C,A,64.83,1,26,8058566334106,128,16264,94281158,CLX5
2025-09-24 19:34:07.188550041+00:00,160,1,432669,C,A,64.83,1,26,8058566334105,128,20022,94281160,CLX5
2025-09-24 19:34:07.188848071+00:00,160,1,432669,M,A,64.84,1,26,8058566325943,128,18903,94281170,CLX5
2025-09-24 19:34:07.521004893+00:00,160,1,432669,A,B,64.82,2,26,8058566334745,128,19094,94281394,CLX5
2025-09-24 19:34:10.006885953+00:00,160,1,432669,C,A,64.83,2,26,8058566334104,128,20771,94282037,CLX5
2025-09-24 19:34:10.007413449+00:00,160,1,432669,A,B,64.81,2,26,8058566335033,128,14611,94282050,CLX5
2025-09-24 19:34:10.007781055+00:00,160,1,432669,C,A,64.83,2,26,8058566330291,128,19091,94282096,CLX5
2025-09-24 19:34:10.009137705+00:00,160,1,432669,A,A,64.83,1,26,8058566335056,128,18052,94282122,CLX5
2025-09-24 19:34:10.009137887+00:00,160,1,432669,A,A,64.83,1,26,8058566335057,128,14137,94282124,CLX5
2025-09-24 19:34:10.009218669+00:00,160,1,432669,A,A,64.83,2,26,8058566335059,128,15719,94282128,CLX5
2025-09-24 19:34:10.009273157+00:00,160,1,432669,A,A,64.83,1,26,8058566335060,128,20692,94282134,CLX5
2025-09-24 19:34:10.010237339+00:00,160,1,432669,C,B,64.79,2,26,8058566331916,128,18356,94282261,CLX5
2025-09-24 19:34:10.012060989+00:00,160,1,432669,C,B,64.82,2,26,8058566334745,128,15651,94282355,CLX5
2025-09-24 19:34:10.012396205+00:00,160,1,432669,A,A,64.83,1,26,8058566335100,128,16660,94282366,CLX5
2025-09-24 19:34:10.013457075+00:00,160,1,432669,C,A,64.83,1,26,8058566335100,128,16274,94282430,CLX5
2025-09-24 19:34:10.075618787+00:00,160,1,432669,C,B,64.82,1,26,8058566333889,128,18580,94282955,CLX5
2025-09-24 19:34:10.075619229+00:00,160,1,432669,C,B,64.81,2,26,8058566335033,128,15194,94282956,CLX5
2025-09-24 19:34:10.075628213+00:00,160,1,432669,A,A,64.83,1,26,8058566335292,128,15578,94282960,CLX5
2025-09-24 19:34:10.075630423+00:00,160,1,432669,C,B,64.82,1,26,8058566333874,128,15112,94282962,CLX5
2025-09-24 19:34:10.075633455+00:00,160,1,432669,A,A,64.83,2,26,8058566335294,128,17339,94282968,CLX5
2025-09-24 19:34:10.075634357+00:00,160,1,432669,A,A,64.83,1,26,8058566335295,128,15546,94282969,CLX5
2025-09-24 19:34:10.075639849+00:00,160,1,432669,A,A,64.83,1,26,8058566335296,128,14869,94282972,CLX5
2025-09-24 19:34:10.075678937+00:00,160,1,432669,A,A,64.83,2,26,8058566335297,128,14380,94282977,CLX5
2025-09-24 19:34:10.076022391+00:00,160,1,432669,M,A,64.83,1,26,8058566325943,128,15862,94282989,CLX5
2025-09-24 19:34:10.076045277+00:00,160,1,432669,C,A,64.83,2,26,8058566335297,128,15358,94282991,CLX5
2025-09-24 19:34:10.076067165+00:00,160,1,432669,C,A,64.83,1,26,8058566335296,128,15515,94282992,CLX5
2025-09-24 19:34:10.076157873+00:00,160,1,432669,A,A,64.83,1,26,8058566335300,128,14447,94282996,CLX5
2025-09-24 19:34:10.076440243+00:00,160,1,432669,C,A,64.83,1,26,8058566335300,128,18958,94282998,CLX5
2025-09-24 19:34:10.076442661+00:00,160,1,432669,C,B,64.82,1,26,8058566333888,128,14735,94282999,CLX5
2025-09-24 19:34:10.076451531+00:00,160,1,432669,C,B,64.82,1,26,8058566333949,128,15833,94283000,CLX5
2025-09-24 19:34:10.076899563+00:00,160,1,432669,C,A,64.83,1,26,8058566335295,128,19009,94283012,CLX5
2025-09-24 19:34:10.076931933+00:00,160,1,432669,A,A,64.83,1,26,8058566335303,128,15238,94283013,CLX5
2025-09-24 19:34:10.077240903+00:00,160,1,432669,C,A,64.83,1,26,8058566335303,128,15190,94283029,CLX5
2025-09-24 19:34:10.077244763+00:00,160,1,432669,A,A,64.83,1,26,8058566335312,128,18492,94283030,CLX5
2025-09-24 19:34:10.077271989+00:00,160,1,432669,C,A,64.83,1,26,8058566335312,128,15414,94283031,CLX5
2025-09-24 19:34:10.077620779+00:00,160,1,432669,A,A,64.83,1,26,8058566335313,128,15777,94283032,CLX5
2025-09-24 19:34:10.077654993+00:00,160,1,432669,C,A,64.83,1,26,8058566335313,128,18212,94283033,CLX5
2025-09-24 19:34:10.101000721+00:00,160,1,432669,A,A,64.83,1,26,8058566335319,128,18309,94283042,CLX5
2025-09-24 19:34:10.101005213+00:00,160,1,432669,A,A,64.83,1,26,8058566335320,128,15344,94283043,CLX5
2025-09-24 19:34:10.110289175+00:00,160,1,432669,A,B,64.79,2,26,8058566335327,128,18072,94283061,CLX5
2025-09-24 19:34:10.121029873+00:00,160,1,432669,C,A,64.83,1,26,8058566335320,128,18675,94283102,CLX5
2025-09-24 19:34:10.121155991+00:00,160,1,432669,C,A,64.83,1,26,8058566335319,128,18549,94283108,CLX5
2025-09-24 19:34:10.160563961+00:00,160,1,432669,A,A,64.83,1,26,8058566335361,128,18995,94283139,CLX5
2025-09-24 19:34:10.160905437+00:00,160,1,432669,A,A,64.83,1,26,8058566335362,128,15178,94283145,CLX5
2025-09-24 19:34:10.702471621+00:00,160,1,432669,C,A,64.83,1,26,8058566335361,128,15449,94283251,CLX5
2025-09-24 19:34:10.702478935+00:00,160,1,432669,A,B,64.82,2,26,8058566335423,128,19021,94283252,CLX5
2025-09-24 19:34:10.702497539+00:00,160,1,432669,C,A,64.83,1,26,8058566335362,128,15325,94283253,CLX5
2025-09-24 19:34:10.861780607+00:00,160,1,432669,A,A,64.83,1,26,8058566335436,128,19366,94283289,CLX5
2025-09-24 19:34:11.954597043+00:00,160,1,432669,A,B,64.81,2,26,8058566335478,128,25969,94283381,CLX5
2025-09-24 19:34:11.954602937+00:00,160,1,432669,A,B,64.82,1,26,8058566335479,128,19803,94283385,CLX5
2025-09-24 19:34:11.954901465+00:00,160,1,432669,C,A,64.83,1,26,8058566335060,128,20773,94283390,CLX5
2025-09-24 19:34:11.954911025+00:00,160,1,432669,A,B,64.82,1,26,8058566335482,128,18351,94283391,CLX5
2025-09-24 19:34:12.010230007+00:00,160,1,432669,C,B,64.79,2,26,8058566335327,128,18942,94283403,CLX5
2025-09-24 19:34:12.518568655+00:00,160,1,432669,C,B,64.82,1,26,8058566335482,128,18697,94283476,CLX5
2025-09-24 19:34:17.233218373+00:00,160,1,432669,T,A,64.82,1,26,8058566335601,0,17816,94283686,CLX5
2025-09-24 19:34:17.233218373+00:00,160,1,432669,F,B,64.82,1,26,8058566333103,0,17816,94283686,CLX5
2025-09-24 19:34:17.233218373+00:00,160,1,432669,C,B,64.82,1,26,8058566333103,128,15520,94283687,CLX5
2025-09-24 19:34:17.677176887+00:00,160,1,432669,T,A,64.82,1,26,8058566335628,0,18749,94283744,CLX5
2025-09-24 19:34:17.677176887+00:00,160,1,432669,F,B,64.82,1,26,8058566333154,0,18749,94283744,CLX5
2025-09-24 19:34:17.677176887+00:00,160,1,432669,M,B,64.82,1,26,8058566333154,128,15682,94283745,CLX5
2025-09-24 19:34:17.678009439+00:00,160,1,432669,A,B,64.82,1,26,8058566335630,128,17958,94283751,CLX5
2025-09-24 19:34:17.678127109+00:00,160,1,432669,A,A,64.83,1,26,8058566335631,128,17902,94283752,CLX5
2025-09-24 19:34:17.687617541+00:00,160,1,432669,A,B,64.82,1,26,8058566335632,128,18728,94283753,CLX5
2025-09-24 19:34:18.121323937+00:00,160,1,432669,T,A,64.82,1,26,8058566335649,0,17785,94283786,CLX5
2025-09-24 19:34:18.121323937+00:00,160,1,432669,F,B,64.82,1,26,8058566333154,0,17785,94283786,CLX5
2025-09-24 19:34:18.121323937+00:00,160,1,432669,C,B,64.82,1,26,8058566333154,128,17016,94283787,CLX5
2025-09-24 19:34:18.121695231+00:00,160,1,432669,C,B,64.82,1,26,8058566335630,128,14788,94283792,CLX5
2025-09-24 19:34:18.224676397+00:00,160,1,432669,A,B,64.82,1,26,8058566335656,128,18335,94283805,CLX5
2025-09-24 19:34:18.565485731+00:00,160,1,432669,T,A,64.82,1,26,8058566335671,0,17898,94283836,CLX5
2025-09-24 19:34:18.565485731+00:00,160,1,432669,F,B,64.82,1,26,8058566333156,0,17898,94283836,CLX5
2025-09-24 19:34:18.565485731+00:00,160,1,432669,C,B,64.82,1,26,8058566333156,128,17045,94283837,CLX5
2025-09-24 19:34:18.575905401+00:00,160,1,432669,A,B,64.82,1,26,8058566335674,128,19458,94283842,CLX5
2025-09-24 19:34:18.576165393+00:00,160,1,432669,A,B,64.82,1,26,8058566335675,128,18692,94283844,CLX5
2025-09-24 19:34:18.576307507+00:00,160,1,432669,C,B,64.82,1,26,8058566335675,128,15077,94283849,CLX5
2025-09-24 19:34:19.009609755+00:00,160,1,432669,T,A,64.82,1,26,8058566335696,0,18039,94283888,CLX5
2025-09-24 19:34:19.009609755+00:00,160,1,432669,F,B,64.82,1,26,8058566333158,0,18039,94283888,CLX5
2025-09-24 19:34:19.009609755+00:00,160,1,432669,C,B,64.82,1,26,8058566333158,128,17685,94283889,CLX5
2025-09-24 19:34:19.009914563+00:00,160,1,432669,A,A,64.83,1,26,8058566335697,128,19359,94283890,CLX5
2025-09-24 19:34:19.009933473+00:00,160,1,432669,A,A,64.83,1,26,8058566335699,128,15325,94283892,CLX5
2025-09-24 19:34:19.010030391+00:00,160,1,432669,A,B,64.82,1,26,8058566335701,128,16475,94283895,CLX5
2025-09-24 19:34:19.010212187+00:00,160,1,432669,C,A,64.83,1,26,8058566335697,128,18387,94283897,CLX5
2025-09-24 19:34:19.453759641+00:00,160,1,432669,T,A,64.82,1,26,8058566335719,0,18245,94283935,CLX5
2025-09-24 19:34:19.453759641+00:00,160,1,432669,F,B,64.82,1,26,8058566333177,0,18245,94283935,CLX5
2025-09-24 19:34:19.453759641+00:00,160,1,432669,C,B,64.82,1,26,8058566333177,128,16093,94283936,CLX5
2025-09-24 19:34:19.454037261+00:00,160,1,432669,A,A,64.83,1,26,8058566335720,128,18635,94283937,CLX5
2025-09-24 19:34:19.454055081+00:00,160,1,432669,C,B,64.82,1,26,8058566335701,128,17079,94283938,CLX5
2025-09-24 19:34:19.454217831+00:00,160,1,432669,C,B,64.82,1,26,8058566335632,128,16341,94283943,CLX5
2025-09-24 19:34:19.454218195+00:00,160,1,432669,C,B,64.82,1,26,8058566335656,128,19744,94283944,CLX5
2025-09-24 19:34:19.454218521+00:00,160,1,432669,C,B,64.82,1,26,8058566335674,128,16252,94283945,CLX5
2025-09-24 19:34:19.454281611+00:00,160,1,432669,A,B,64.82,1,26,8058566335723,128,16227,94283946,CLX5
2025-09-24 19:34:19.454423089+00:00,160,1,432669,A,B,64.82,1,26,8058566335725,128,16649,94283951,CLX5
2025-09-24 19:34:19.454651195+00:00,160,1,432669,C,B,64.82,1,26,8058566335725,128,20992,94283955,CLX5
2025-09-24 19:34:19.454653325+00:00,160,1,432669,A,A,64.83,1,26,8058566335726,128,14183,94283956,CLX5
2025-09-24 19:34:19.454934151+00:00,160,1,432669,A,B,64.82,1,26,8058566335727,128,19407,94283957,CLX5
2025-09-24 19:34:19.897959311+00:00,160,1,432669,T,A,64.82,1,26,8058566335742,0,17601,94283994,CLX5
2025-09-24 19:34:19.897959311+00:00,160,1,432669,F,B,64.82,1,26,8058566333591,0,17601,94283994,CLX5
2025-09-24 19:34:19.897959311+00:00,160,1,432669,C,B,64.82,1,26,8058566333591,128,17621,94283995,CLX5
2025-09-24 19:34:19.898281357+00:00,160,1,432669,C,B,64.82,1,26,8058566335727,128,16066,94284002,CLX5
2025-09-24 19:34:19.898630629+00:00,160,1,432669,A,A,64.83,1,26,8058566335746,128,17566,94284003,CLX5
2025-09-24 19:34:20.342085967+00:00,160,1,432669,T,A,64.82,1,26,8058566335762,0,17980,94284035,CLX5
2025-09-24 19:34:20.342085967+00:00,160,1,432669,F,B,64.82,1,26,8058566333637,0,17980,94284035,CLX5
2025-09-24 19:34:20.342085967+00:00,160,1,432669,C,B,64.82,1,26,8058566333637,128,16933,94284036,CLX5
2025-09-24 19:34:20.342362607+00:00,160,1,432669,C,B,64.82,1,26,8058566335479,128,22525,94284044,CLX5
2025-09-24 19:34:20.342373897+00:00,160,1,432669,C,B,64.82,1,26,8058566335723,128,17482,94284045,CLX5
2025-09-24 19:34:20.342451383+00:00,160,1,432669,T,A,64.82,4,26,8058566335765,0,16376,94284057,CLX5
2025-09-24 19:34:20.342451383+00:00,160,1,432669,F,B,64.82,1,26,8058566333638,0,16376,94284057,CLX5
2025-09-24 19:34:20.342451383+00:00,160,1,432669,F,B,64.82,2,26,8058566335423,0,16376,94284057,CLX5
2025-09-24 19:34:20.342451383+00:00,160,1,432669,C,B,64.82,1,26,8058566333638,0,16376,94284057,CLX5
2025-09-24 19:34:20.342451383+00:00,160,1,432669,C,B,64.82,2,26,8058566335423,128,16376,94284057,CLX5
2025-09-24 19:34:20.342882755+00:00,160,1,432669,A,A,64.83,1,26,8058566335771,128,17774,94284076,CLX5
2025-09-24 19:34:20.343019795+00:00,160,1,432669,A,A,64.83,1,26,8058566335775,128,14642,94284088,CLX5
2025-09-24 19:34:20.343025017+00:00,160,1,432669,A,A,64.86,1,26,8058566335777,128,16849,94284090,CLX5
2025-09-24 19:34:20.343029951+00:00,160,1,432669,C,B,64.81,2,26,8058566333074,128,18737,94284099,CLX5
2025-09-24 19:34:20.343099125+00:00,160,1,432669,A,A,64.83,3,26,8058566335783,128,15100,94284107,CLX5
2025-09-24 19:34:20.343167973+00:00,160,1,432669,A,A,64.83,2,26,8058566335784,128,15069,94284109,CLX5
2025-09-24 19:34:20.343181797+00:00,160,1,432669,A,B,64.81,5,26,8058566335785,128,14988,94284110,CLX5
2025-09-24 19:34:20.343283897+00:00,160,1,432669,C,A,64.83,1,26,8058566335775,128,15197,94284115,CLX5
2025-09-24 19:34:20.343313599+00:00,160,1,432669,A,A,64.83,1,26,8058566335786,128,15139,94284120,CLX5
2025-09-24 19:34:20.343430771+00:00,160,1,432669,A,A,64.83,1,26,8058566335787,128,15258,94284126,CLX5
2025-09-24 19:34:20.343612895+00:00,160,1,432669,A,A,64.83,1,26,8058566335789,128,18387,94284133,CLX5
2025-09-24 19:34:20.343707239+00:00,160,1,432669,C,A,64.83,1,26,8058566335787,128,14968,94284157,CLX5
2025-09-24 19:34:20.343719219+00:00,160,1,432669,A,A,64.83,1,26,8058566335799,128,14930,94284163,CLX5
2025-09-24 19:34:20.343851423+00:00,160,1,432669,C,A,64.83,2,26,8058566335784,128,15611,94284173,CLX5
2025-09-24 19:34:20.343928681+00:00,160,1,432669,M,B,63.65,4,26,8058566319851,128,15162,94284180,CLX5
2025-09-24 19:34:20.344531919+00:00,160,1,432669,A,A,64.82,2,26,8058566335813,128,18459,94284207,CLX5
2025-09-24 19:34:20.344754833+00:00,160,1,432669,A,A,64.82,1,26,8058566335826,128,15005,94284234,CLX5
2025-09-24 19:34:20.344938825+00:00,160,1,432669,C,B,64.81,2,26,8058566335478,128,14945,94284251,CLX5
2025-09-24 19:34:20.344940093+00:00,160,1,432669,A,A,64.82,2,26,8058566335833,128,21873,94284252,CLX5
2025-09-24 19:34:20.344949079+00:00,160,1,432669,C,B,64.78,2,26,8058566334354,128,15932,94284264,CLX5
2025-09-24 19:34:20.345178777+00:00,160,1,432669,A,A,64.86,2,26,8058566335838,128,14986,94284276,CLX5
2025-09-24 19:34:20.345827651+00:00,160,1,432669,M,B,64.81,4,26,8058566335785,128,15094,94284339,CLX5
2025-09-24 19:34:20.347098423+00:00,160,1,432669,M,A,64.84,4,26,8058566282798,128,15129,94284402,CLX5
2025-09-24 19:34:20.347230553+00:00,160,1,432669,C,A,64.83,1,26,8058566335726,128,14965,94284409,CLX5
2025-09-24 19:34:20.347231473+00:00,160,1,432669,C,A,64.83,1,26,8058566335631,128,18557,94284410,CLX5
2025-09-24 19:34:20.347707805+00:00,160,1,432669,A,A,64.82,1,26,8058566335879,128,17669,94284440,CLX5
2025-09-24 19:34:20.347764135+00:00,160,1,432669,A,A,64.82,1,26,8058566335881,128,17223,94284453,CLX5
2025-09-24 19:34:20.347909127+00:00,160,1,432669,M,A,64.94,1,26,8058565075241,128,14751,94284464,CLX5
2025-09-24 19:34:20.348732253+00:00,160,1,432669,M,B,64.8,4,26,8058566335785,128,18219,94284508,CLX5
2025-09-24 19:34:20.353871635+00:00,160,1,432669,A,A,64.82,3,26,8058566335916,128,17143,94284627,CLX5
2025-09-24 19:34:20.354998241+00:00,160,1,432669,C,A,64.82,1,26,8058566335879,128,15992,94284659,CLX5
2025-09-24 19:34:20.356252349+00:00,160,1,432669,A,A,64.82,1,26,8058566335929,128,19674,94284672,CLX5
2025-09-24 19:34:20.372136693+00:00,160,1,432669,C,A,64.83,1,26,8058566335799,128,18739,94284744,CLX5
2025-09-24 19:34:20.372144659+00:00,160,1,432669,C,A,64.83,1,26,8058566335789,128,14879,94284745,CLX5
2025-09-24 19:34:20.372153991+00:00,160,1,432669,C,A,64.83,1,26,8058566335786,128,15087,94284746,CLX5
2025-09-24 19:34:20.397448837+00:00,160,1,432669,A,A,64.82,2,26,8058566335960,128,19555,94284772,CLX5
2025-09-24 19:34:20.410356275+00:00,160,1,432669,C,A,64.88,2,26,8058566333657,128,17970,94284788,CLX5
2025-09-24 19:34:20.410356925+00:00,160,1,432669,A,B,64.79,2,26,8058566335966,128,14539,94284789,CLX5
2025-09-24 19:34:20.662352243+00:00,160,1,432669,C,A,64.83,1,26,8058566335436,128,18461,94284971,CLX5
2025-09-24 19:34:20.662911397+00:00,160,1,432669,A,A,64.82,1,26,8058566336044,128,19246,94284972,CLX5
2025-09-24 19:34:20.786244013+00:00,160,1,432669,T,A,64.81,1,26,8058566336045,0,17926,94284981,CLX5
2025-09-24 19:34:20.786244013+00:00,160,1,432669,F,B,64.81,1,26,8058566330880,0,17926,94284981,CLX5
2025-09-24 19:34:20.786244013+00:00,160,1,432669,C,B,64.81,1,26,8058566330880,128,14840,94284982,CLX5
2025-09-24 19:34:20.786563045+00:00,160,1,432669,C,B,64.81,2,26,8058566331188,128,15116,94284985,CLX5
2025-09-24 19:34:20.786563851+00:00,160,1,432669,C,B,64.81,1,26,8058566331211,128,16755,94284988,CLX5
2025-09-24 19:34:20.787430521+00:00,160,1,432669,C,B,64.79,1,26,8058566331895,128,20728,94285003,CLX5
2025-09-24 19:34:20.787667055+00:00,160,1,432669,A,A,64.85,1,26,8058566336056,128,15812,94285013,CLX5
2025-09-24 19:34:20.816171595+00:00,160,1,432669,A,B,64.16,2,26,8058566336059,128,18187,94285021,CLX5
2025-09-24 19:34:24.736508645+00:00,160,1,432669,A,B,64.81,1,26,8058566336108,128,18583,94285157,CLX5
2025-09-24 19:34:27.115915389+00:00,160,1,432669,C,B,64.16,2,26,8058566336059,128,18260,94285263,CLX5
2025-09-24 19:34:28.463360087+00:00,160,1,432669,M,A,64.83,1,26,8058566276097,128,19388,94285278,CLX5
2025-09-24 19:34:29.214518393+00:00,160,1,432669,A,A,64.82,1,26,8058566336144,128,19432,94285307,CLX5
2025-09-24 19:34:29.215015591+00:00,160,1,432669,M,A,64.82,1,26,8058566325943,128,16390,94285339,CLX5
2025-09-24 19:34:29.215582581+00:00,160,1,432669,C,A,64.82,1,26,8058566336144,128,14433,94285365,CLX5
2025-09-24 19:34:29.215875235+00:00,160,1,432669,A,B,64.16,2,26,8058566336172,128,17770,94285371,CLX5
2025-09-24 19:34:29.216167617+00:00,160,1,432669,A,A,64.82,1,26,8058566336174,128,14717,94285375,CLX5
2025-09-24 19:34:29.221164735+00:00,160,1,432669,A,A,64.82,1,26,8058566336248,128,18308,94285624,CLX5
2025-09-24 19:34:29.221415571+00:00,160,1,432669,C,A,64.82,1,26,8058566336248,128,18875,94285632,CLX5
2025-09-24 19:34:29.221605145+00:00,160,1,432669,A,A,64.82,1,26,8058566336253,128,19112,94285636,CLX5
2025-09-24 19:34:29.221926557+00:00,160,1,432669,C,A,64.82,1,26,8058566336253,128,15109,94285671,CLX5
2025-09-24 19:34:29.223849027+00:00,160,1,432669,M,A,64.82,1,26,8058566331891,128,19752,94285799,CLX5
2025-09-24 19:34:29.224376101+00:00,160,1,432669,A,A,64.82,1,26,8058566336312,128,14616,94285837,CLX5
2025-09-24 19:34:29.225406557+00:00,160,1,432669,C,B,64.81,2,26,8058566331191,128,18593,94285945,CLX5
2025-09-24 19:34:29.237161431+00:00,160,1,432669,C,A,64.82,1,26,8058566336312,128,14343,94286205,CLX5
2025-09-24 19:34:29.353446171+00:00,160,1,432669,C,A,64.82,1,26,8058566336174,128,19075,94286557,CLX5
2025-09-24 19:34:29.353609671+00:00,160,1,432669,A,A,64.82,1,26,8058566336566,128,18516,94286558,CLX5
2025-09-24 19:34:29.361178611+00:00,160,1,432669,C,A,64.82,1,26,8058566336566,128,15172,94286583,CLX5
2025-09-24 19:34:29.361368431+00:00,160,1,432669,A,A,64.82,1,26,8058566336590,128,15544,94286588,CLX5
2025-09-24 19:34:29.565315565+00:00,160,1,432669,A,A,64.82,1,26,8058566336693,128,18740,94286771,CLX5
2025-09-24 19:34:30.766820167+00:00,160,1,432669,A,B,64.78,1,26,8058566336849,128,21178,94287050,CLX5
2025-09-24 19:34:32.274591031+00:00,160,1,432669,C,B,64.81,2,26,8058566331351,128,22245,94287071,CLX5
2025-09-24 19:34:32.275443127+00:00,160,1,432669,C,B,64.77,2,26,8058566332230,128,22031,94287077,CLX5
2025-09-24 19:34:32.900840161+00:00,160,1,432669,C,B,64.81,1,26,8058566336108,128,21343,94287105,CLX5
2025-09-24 19:34:33.358874625+00:00,160,1,432669,C,A,64.82,1,26,8058566336590,128,16926,94287182,CLX5
2025-09-24 19:34:33.359230999+00:00,160,1,432669,A,A,64.82,1,26,8058566336891,128,17414,94287210,CLX5
2025-09-24 19:34:33.359963217+00:00,160,1,432669,A,B,64.81,1,26,8058566336898,128,18885,94287233,CLX5
2025-09-24 19:34:33.510310037+00:00,160,1,432669,A,B,64.77,2,26,8058566336922,128,18567,94287298,CLX5
2025-09-24 19:34:35.503726417+00:00,160,1,432669,C,A,64.82,1,26,8058566336891,128,18525,94287337,CLX5
2025-09-24 19:34:35.503900843+00:00,160,1,432669,C,A,64.82,1,26,8058566325943,128,15165,94287341,CLX5
2025-09-24 19:34:40.842802501+00:00,160,1,432669,M,B,62.11,10,26,8058561691831,128,23342,94287894,CLX5
2025-09-24 19:34:46.945564221+00:00,160,1,432669,A,B,64.81,1,26,8058566337228,128,15109,94288152,CLX5
2025-09-24 19:34:46.945568253+00:00,160,1,432669,A,A,64.82,1,26,8058566337229,128,18408,94288153,CLX5
2025-09-24 19:34:46.945798603+00:00,160,1,432669,C,A,64.82,1,26,8058566337229,128,18303,94288159,CLX5
2025-09-24 19:34:46.953927791+00:00,160,1,432669,M,A,64.83,1,26,8058566331891,128,20139,94288161,CLX5
2025-09-24 19:34:50.047105353+00:00,160,1,432669,C,B,64.81,1,26,8058566337228,128,15334,94288183,CLX5
2025-09-24 19:34:50.047110171+00:00,160,1,432669,A,A,64.82,1,26,8058566337236,128,18618,94288189,CLX5
2025-09-24 19:34:50.047496249+00:00,160,1,432669,C,B,64.77,2,26,8058566336922,128,13995,94288219,CLX5
2025-09-24 19:34:50.210394037+00:00,160,1,432669,A,B,64.77,2,26,8058566337262,128,18914,94288267,CLX5
2025-09-24 19:34:50.576966635+00:00,160,1,432669,A,A,64.82,1,26,8058566337265,128,19132,94288271,CLX5
2025-09-24 19:34:56.471437373+00:00,160,1,432669,T,A,64.81,1,26,8058566337281,0,24242,94288314,CLX5
2025-09-24 19:34:56.471437373+00:00,160,1,432669,F,B,64.81,1,26,8058566330881,0,24242,94288314,CLX5
2025-09-24 19:34:56.471437373+00:00,160,1,432669,C,B,64.81,1,26,8058566330881,128,19623,94288315,CLX5
2025-09-24 19:34:56.471804539+00:00,160,1,432669,C,B,64.81,1,26,8058566336898,128,19417,94288317,CLX5
2025-09-24 19:34:56.471853995+00:00,160,1,432669,A,B,64.81,1,26,8058566337284,128,21405,94288320,CLX5
2025-09-24 19:34:56.471875057+00:00,160,1,432669,C,B,64.81,1,26,8058566337284,128,18977,94288321,CLX5
2025-09-24 19:34:56.472074401+00:00,160,1,432669,A,B,64.81,1,26,8058566337285,128,22438,94288323,CLX5
2025-09-24 19:34:56.472447135+00:00,160,1,432669,C,B,64.77,2,26,8058566337262,128,22559,94288324,CLX5
2025-09-24 19:34:56.497339143+00:00,160,1,432669,A,B,64.47,1,26,8058566337289,128,22412,94288329,CLX5
2025-09-24 19:34:56.610404799+00:00,160,1,432669,A,B,64.77,2,26,8058566337292,128,20545,94288334,CLX5
2025-09-24 19:34:56.675605411+00:00,160,1,432669,C,B,64.78,1,26,8058566336849,128,18369,94288336,CLX5
2025-09-24 19:34:59.614050051+00:00,160,1,432669,T,A,64.81,17,26,8058566337308,0,18969,94288374,CLX5
2025-09-24 19:34:59.614050051+00:00,160,1,432669,F,B,64.81,1,26,8058566331027,0,18969,94288374,CLX5
2025-09-24 19:34:59.614050051+00:00,160,1,432669,F,B,64.81,2,26,8058566331113,0,18969,94288374,CLX5
2025-09-24 19:34:59.614050051+00:00,160,1,432669,F,B,64.81,1,26,8058566331152,0,18969,94288374,CLX5
2025-09-24 19:34:59.614050051+00:00,160,1,432669,F,B,64.81,1,26,8058566331247,0,18969,94288374,CLX5
2025-09-24 19:34:59.614050051+00:00,160,1,432669,F,B,64.81,3,26,8058566331508,0,18969,94288374,CLX5
2025-09-24 19:34:59.614050051+00:00,160,1,432669,F,B,64.81,1,26,8058566331010,0,18969,94288374,CLX5
2025-09-24 19:34:59.614050051+00:00,160,1,432669,F,B,64.81,1,26,8058566332855,0,18969,94288374,CLX5
2025-09-24 19:34:59.614050051+00:00,160,1,432669,F,B,64.81,1,26,8058566337285,0,18969,94288374,CLX5
2025-09-24 19:34:59.614050051+00:00,160,1,432669,F,B,64.81,1,26,8058566331163,0,18969,94288374,CLX5
2025-09-24 19:34:59.614050051+00:00,160,1,432669,C,B,64.81,1,26,8058566331027,0,16448,94288375,CLX5
2025-09-24 19:34:59.614050051+00:00,160,1,432669,C,B,64.81,2,26,8058566331113,0,16448,94288375,CLX5
2025-09-24 19:34:59.614050051+00:00,160,1,432669,C,B,64.81,1,26,8058566331152,0,16448,94288375,CLX5
2025-09-24 19:34:59.614050051+00:00,160,1,432669,C,B,64.81,1,26,8058566331247,0,16448,94288375,CLX5
2025-09-24 19:34:59.614050051+00:00,160,1,432669,C,B,64.81,3,26,8058566331508,0,16448,94288375,CLX5
2025-09-24 19:34:59.614050051+00:00,160,1,432669,C,B,64.81,1,26,8058566331010,0,16448,94288375,CLX5
2025-09-24 19:34:59.614050051+00:00,160,1,432669,C,B,64.81,1,26,8058566332855,0,16448,94288375,CLX5
2025-09-24 19:34:59.614050051+00:00,160,1,432669,C,B,64.81,1,26,8058566337285,0,16448,94288375,CLX5
2025-09-24 19:34:59.614050051+00:00,160,1,432669,C,B,64.81,1,26,8058566331163,128,16448,94288375,CLX5
2025-09-24 19:34:59.614606347+00:00,160,1,432669,A,A,64.82,1,26,8058566337314,128,17175,94288386,CLX5
2025-09-24 19:34:59.614685311+00:00,160,1,432669,A,A,64.82,1,26,8058566337315,128,15425,94288390,CLX5
2025-09-24 19:34:59.614691803+00:00,160,1,432669,A,B,64.8,1,26,8058566337316,128,15228,94288392,CLX5
2025-09-24 19:34:59.614729951+00:00,160,1,432669,A,A,64.82,2,26,8058566337318,128,14537,94288394,CLX5
2025-09-24 19:34:59.614737169+00:00,160,1,432669,A,B,64.8,1,26,8058566337322,128,18006,94288400,CLX5
2025-09-24 19:34:59.614748305+00:00,160,1,432669,A,B,64.8,1,26,8058566337327,128,15177,94288409,CLX5
2025-09-24 19:34:59.614788893+00:00,160,1,432669,A,A,64.82,1,26,8058566337337,128,17002,94288440,CLX5
2025-09-24 19:34:59.614828979+00:00,160,1,432669,M,A,64.82,1,26,8058566173085,128,15620,94288445,CLX5
2025-09-24 19:34:59.614846777+00:00,160,1,432669,A,A,64.82,3,26,8058566337340,128,17343,94288447,CLX5
2025-09-24 19:34:59.615142847+00:00,160,1,432669,C,B,64.77,2,26,8058566337292,128,18363,94288475,CLX5
2025-09-24 19:34:59.615309841+00:00,160,1,432669,A,B,64.81,1,26,8058566337348,128,18263,94288485,CLX5
2025-09-24 19:34:59.615674165+00:00,160,1,432669,C,B,64.8,2,26,8058566331915,128,23257,94288539,CLX5
2025-09-24 19:34:59.615681807+00:00,160,1,432669,A,A,64.85,2,26,8058566337368,128,14700,94288541,CLX5
2025-09-24 19:34:59.615979797+00:00,160,1,432669,M,B,64.46,10,26,8058566151203,128,14960,94288575,CLX5
2025-09-24 19:34:59.616088805+00:00,160,1,432669,C,A,65.9,1,26,8058566331990,128,14706,94288583,CLX5
2025-09-24 19:34:59.616171941+00:00,160,1,432669,C,A,64.82,1,26,8058566337315,128,18055,94288599,CLX5
2025-09-24 19:34:59.616292019+00:00,160,1,432669,C,A,64.82,2,26,8058566337318,128,15780,94288611,CLX5
2025-09-24 19:34:59.616354179+00:00,160,1,432669,C,B,64.81,1,26,8058566337348,128,15238,94288622,CLX5
2025-09-24 19:34:59.617276545+00:00,160,1,432669,A,B,64.81,1,26,8058566337390,128,15205,94288669,CLX5
2025-09-24 19:34:59.617279789+00:00,160,1,432669,C,B,64.8,1,26,8058566337322,128,14989,94288672,CLX5
2025-09-24 19:34:59.617396887+00:00,160,1,432669,A,B,64.81,1,26,8058566337392,128,17010,94288676,CLX5
2025-09-24 19:34:59.618107561+00:00,160,1,432669,C,A,64.85,2,26,8058566337368,128,14265,94288715,CLX5
2025-09-24 19:34:59.618110345+00:00,160,1,432669,A,B,64.81,2,26,8058566337397,128,14576,94288719,CLX5
2025-09-24 19:34:59.618110845+00:00,160,1,432669,A,B,64.81,2,26,8058566337398,128,14923,94288721,CLX5
2025-09-24 19:34:59.618151507+00:00,160,1,432669,A,B,64.81,2,26,8058566337402,128,16886,94288727,CLX5
2025-09-24 19:34:59.618310113+00:00,160,1,432669,A,B,64.81,1,26,8058566337404,128,18746,94288740,CLX5
2025-09-24 19:34:59.618449231+00:00,160,1,432669,A,B,64.81,1,26,8058566337411,128,16503,94288767,CLX5
2025-09-24 19:34:59.619468533+00:00,160,1,432669,M,A,64.83,1,26,8058566173085,128,15011,94288830,CLX5
2025-09-24 19:34:59.619528223+00:00,160,1,432669,A,B,64.81,1,26,8058566337425,128,17452,94288839,CLX5
2025-09-24 19:34:59.619533483+00:00,160,1,432669,A,B,64.81,1,26,8058566337426,128,15596,94288840,CLX5
2025-09-24 19:34:59.619897671+00:00,160,1,432669,A,B,64.8,1,26,8058566337428,128,14922,94288865,CLX5
2025-09-24 19:34:59.619899131+00:00,160,1,432669,A,B,64.8,2,26,8058566337429,128,14902,94288866,CLX5
2025-09-24 19:34:59.619899309+00:00,160,1,432669,A,B,64.8,2,26,8058566337430,128,18303,94288867,CLX5
2025-09-24 19:34:59.620647647+00:00,160,1,432669,A,B,64.81,3,26,8058566337434,128,19318,94288955,CLX5
2025-09-24 19:34:59.621634427+00:00,160,1,432669,C,B,64.81,2,26,8058566337402,128,18522,94289009,CLX5
2025-09-24 19:34:59.622067291+00:00,160,1,432669,A,B,64.81,1,26,8058566337448,128,15689,94289031,CLX5
2025-09-24 19:34:59.622688959+00:00,160,1,432669,C,B,64.81,1,26,8058566337404,128,18043,94289055,CLX5
2025-09-24 19:34:59.623408525+00:00,160,1,432669,M,A,64.82,1,26,8058566331891,128,18593,94289060,CLX5
2025-09-24 19:34:59.623519515+00:00,160,1,432669,C,B,64.81,1,26,8058566337448,128,14975,94289061,CLX5
2025-09-24 19:34:59.623826701+00:00,160,1,432669,A,B,64.81,1,26,8058566337458,128,15256,94289075,CLX5
2025-09-24 19:34:59.624136403+00:00,160,1,432669,C,B,64.81,1,26,8058566337458,128,18764,94289077,CLX5
2025-09-24 19:34:59.625768657+00:00,160,1,432669,C,A,64.82,1,26,8058566337337,128,19343,94289190,CLX5
2025-09-24 19:34:59.627603481+00:00,160,1,432669,M,A,64.83,1,26,8058566331891,128,14282,94289270,CLX5
2025-09-24 19:34:59.628087531+00:00,160,1,432669,C,B,64.81,1,26,8058566337426,128,17991,94289296,CLX5
2025-09-24 19:34:59.628303443+00:00,160,1,432669,A,B,64.81,1,26,8058566337515,128,15121,94289297,CLX5
2025-09-24 19:34:59.629632201+00:00,160,1,432669,C,B,64.81,1,26,8058566337515,128,18446,94289370,CLX5
2025-09-24 19:34:59.630166549+00:00,160,1,432669,C,A,64.82,1,26,8058566337314,128,18009,94289376,CLX5
2025-09-24 19:34:59.630289021+00:00,160,1,432669,A,B,64.81,1,26,8058566337533,128,15342,94289379,CLX5
2025-09-24 19:34:59.630885097+00:00,160,1,432669,C,B,64.81,1,26,8058566337533,128,16481,94289396,CLX5
2025-09-24 19:34:59.647409329+00:00,160,1,432669,A,B,64.8,2,26,8058566337562,128,15181,94289497,CLX5
2025-09-24 19:34:59.678668813+00:00,160,1,432669,A,B,64.81,2,26,8058566337592,128,18828,94289553,CLX5
2025-09-24 19:34:59.716128301+00:00,160,1,432669,A,A,65.9,1,26,8058566337606,128,18040,94289581,CLX5
2025-09-24 19:34:59.810822401+00:00,160,1,432669,A,B,64.77,2,26,8058566337653,128,18519,94289675,CLX5
2025-09-24 19:35:00.525468713+00:00,160,1,432669,C,A,64.83,1,26,8058566332889,128,18324,94289849,CLX5
2025-09-24 19:35:00.543478401+00:00,160,1,432669,A,A,64.82,1,26,8058566337750,128,18897,94289856,CLX5
2025-09-24 19:35:00.700008789+00:00,160,1,432669,C,B,64.81,1,26,8058566337392,128,19445,94289891,CLX5
2025-09-24 19:35:01.840568197+00:00,160,1,432669,A,A,64.82,1,26,8058566337813,128,18151,94290018,CLX5
2025-09-24 19:35:02.649784529+00:00,160,1,432669,A,B,64.81,1,26,8058566337821,128,26280,94290028,CLX5
2025-09-24 19:35:04.974191647+00:00,160,1,432669,C,A,65.23,1,26,8058566285568,128,21796,94290039,CLX5
2025-09-24 19:35:05.017238843+00:00,160,1,432669,A,B,64.81,1,26,8058566337834,128,19279,94290079,CLX5
2025-09-24 19:35:05.017517683+00:00,160,1,432669,C,A,64.82,1,26,8058566335881,128,18392,94290084,CLX5
2025-09-24 19:35:05.068045707+00:00,160,1,432669,A,A,65.15,1,26,8058566337859,128,19032,94290184,CLX5
2025-09-24 19:35:05.116061293+00:00,160,1,432669,C,B,64.16,2,26,8058566336172,128,19108,94290198,CLX5
2025-09-24 19:35:08.011474651+00:00,160,1,432669,C,B,64.81,1,26,8058566337834,128,18703,94290330,CLX5
2025-09-24 19:35:08.016038099+00:00,160,1,432669,A,B,64.16,2,26,8058566337918,128,18003,94290331,CLX5
2025-09-24 19:35:08.207162827+00:00,160,1,432669,A,A,64.82,1,26,8058566337921,128,14398,94290334,CLX5
2025-09-24 19:35:08.207177535+00:00,160,1,432669,A,A,64.82,1,26,8058566337923,128,16545,94290337,CLX5
2025-09-24 19:35:08.207177713+00:00,160,1,432669,C,B,64.81,2,26,8058566337592,128,15165,94290339,CLX5
2025-09-24 19:35:08.207178285+00:00,160,1,432669,C,B,64.77,2,26,8058566337653,128,18708,94290340,CLX5
2025-09-24 19:35:08.207178669+00:00,160,1,432669,C,B,64.81,1,26,8058566337411,128,15637,94290341,CLX5
2025-09-24 19:35:08.207401051+00:00,160,1,432669,C,A,64.82,1,26,8058566337921,128,14164,94290352,CLX5
2025-09-24 19:35:08.207442521+00:00,160,1,432669,C,A,64.82,1,26,8058566337923,128,15022,94290356,CLX5
2025-09-24 19:35:08.207607519+00:00,160,1,432669,A,B,64.81,1,26,8058566337930,128,14311,94290362,CLX5
2025-09-24 19:35:08.275749231+00:00,160,1,432669,C,B,64.8,2,26,8058566337562,128,14807,94290471,CLX5
2025-09-24 19:35:08.275749557+00:00,160,1,432669,A,A,64.82,1,26,8058566337963,128,15205,94290472,CLX5
2025-09-24 19:35:08.275754837+00:00,160,1,432669,A,A,64.82,1,26,8058566337964,128,19172,94290474,CLX5
2025-09-24 19:35:08.275757641+00:00,160,1,432669,C,B,64.81,1,26,8058566337930,128,14860,94290475,CLX5
2025-09-24 19:35:08.276059161+00:00,160,1,432669,A,A,64.82,1,26,8058566337966,128,16988,94290486,CLX5
2025-09-24 19:35:08.276139127+00:00,160,1,432669,C,A,64.82,1,26,8058566337964,128,17843,94290489,CLX5
2025-09-24 19:35:08.276401619+00:00,160,1,432669,C,A,64.82,1,26,8058566337963,128,15240,94290519,CLX5
2025-09-24 19:35:08.310824221+00:00,160,1,432669,A,B,64.78,2,26,8058566337984,128,18401,94290548,CLX5
2025-09-24 19:35:08.321893205+00:00,160,1,432669,C,B,64.54,8,26,8058566321866,128,18102,94290554,CLX5
2025-09-24 19:35:08.410491557+00:00,160,1,432669,A,B,64.77,2,26,8058566337995,128,18891,94290582,CLX5
2025-09-24 19:35:08.495841221+00:00,160,1,432669,T,A,64.81,15,26,8058566338000,0,20016,94290590,CLX5
2025-09-24 19:35:08.495841221+00:00,160,1,432669,F,B,64.81,1,26,8058566337390,0,20016,94290590,CLX5
2025-09-24 19:35:08.495841221+00:00,160,1,432669,F,B,64.81,2,26,8058566337397,0,20016,94290590,CLX5
2025-09-24 19:35:08.495841221+00:00,160,1,432669,F,B,64.81,2,26,8058566337398,0,20016,94290590,CLX5
2025-09-24 19:35:08.495841221+00:00,160,1,432669,F,B,64.81,1,26,8058566337425,0,20016,94290590,CLX5
2025-09-24 19:35:08.495841221+00:00,160,1,432669,F,B,64.81,3,26,8058566337434,0,20016,94290590,CLX5
2025-09-24 19:35:08.495841221+00:00,160,1,432669,F,B,64.81,1,26,8058566337821,0,20016,94290590,CLX5
2025-09-24 19:35:08.495841221+00:00,160,1,432669,C,B,64.81,1,26,8058566337390,0,20318,94290591,CLX5
2025-09-24 19:35:08.495841221+00:00,160,1,432669,C,B,64.81,2,26,8058566337397,0,20318,94290591,CLX5
2025-09-24 19:35:08.495841221+00:00,160,1,432669,C,B,64.81,2,26,8058566337398,0,20318,94290591,CLX5
2025-09-24 19:35:08.495841221+00:00,160,1,432669,C,B,64.81,1,26,8058566337425,0,20318,94290591,CLX5
2025-09-24 19:35:08.495841221+00:00,160,1,432669,C,B,64.81,3,26,8058566337434,0,20318,94290591,CLX5
2025-09-24 19:35:08.495841221+00:00,160,1,432669,C,B,64.81,1,26,8058566337821,0,20318,94290591,CLX5
2025-09-24 19:35:08.495841221+00:00,160,1,432669,A,A,64.81,15,26,8058566338000,128,20318,94290591,CLX5
2025-09-24 19:35:08.496367545+00:00,160,1,432669,A,A,64.82,1,26,8058566338002,128,18989,94290601,CLX5
2025-09-24 19:35:08.496376089+00:00,160,1,432669,A,A,64.82,1,26,8058566338004,128,15574,94290603,CLX5
2025-09-24 19:35:08.496454269+00:00,160,1,432669,C,B,64.8,1,26,8058566337327,128,16561,94290611,CLX5
2025-09-24 19:35:08.496614427+00:00,160,1,432669,A,A,64.82,1,26,8058566338016,128,14316,94290629,CLX5
2025-09-24 19:35:08.496629037+00:00,160,1,432669,C,B,64.8,1,26,8058566337428,128,18631,94290642,CLX5
2025-09-24 19:35:08.496631611+00:00,160,1,432669,A,A,64.82,2,26,8058566338023,128,18826,94290646,CLX5
2025-09-24 19:35:08.496709981+00:00,160,1,432669,A,A,64.81,2,26,8058566338026,128,15160,94290656,CLX5
2025-09-24 19:35:08.496757807+00:00,160,1,432669,A,B,64.8,1,26,8058566338030,128,15007,94290660,CLX5
2025-09-24 19:35:08.496772647+00:00,160,1,432669,A,A,64.81,1,26,8058566338032,128,15346,94290664,CLX5
2025-09-24 19:35:08.496783437+00:00,160,1,432669,A,A,64.81,1,26,8058566338033,128,15335,94290667,CLX5
2025-09-24 19:35:08.496812177+00:00,160,1,432669,A,A,64.81,1,26,8058566338036,128,18634,94290674,CLX5
2025-09-24 19:35:08.496996049+00:00,160,1,432669,C,A,64.81,1,26,8058566338033,128,15468,94290691,CLX5
2025-09-24 19:35:08.497034197+00:00,160,1,432669,M,A,64.83,3,26,8058566321460,128,14808,94290704,CLX5
2025-09-24 19:35:08.497136433+00:00,160,1,432669,C,A,64.82,2,26,8058566335960,128,15037,94290710,CLX5
2025-09-24 19:35:08.497138181+00:00,160,1,432669,C,A,64.82,1,26,8058566337265,128,15175,94290711,CLX5
2025-09-24 19:35:08.497327389+00:00,160,1,432669,C,A,64.84,4,26,8058566282798,128,15098,94290756,CLX5
2025-09-24 19:35:08.497436171+00:00,160,1,432669,C,B,64.8,2,26,8058566337430,128,18659,94290765,CLX5
2025-09-24 19:35:08.497469061+00:00,160,1,432669,C,B,64.78,1,26,8058566331393,128,14888,94290779,CLX5
2025-09-24 19:35:08.497778933+00:00,160,1,432669,C,B,64.77,2,26,8058566337995,128,19341,94290805,CLX5
2025-09-24 19:35:08.497819983+00:00,160,1,432669,C,B,64.8,2,26,8058566337429,128,14197,94290818,CLX5
2025-09-24 19:35:08.497845073+00:00,160,1,432669,A,A,64.85,2,26,8058566338063,128,14706,94290827,CLX5
2025-09-24 19:35:08.498467011+00:00,160,1,432669,A,A,64.81,1,26,8058566338085,128,15219,94290882,CLX5
2025-09-24 19:35:08.499266617+00:00,160,1,432669,A,A,64.82,1,26,8058566338093,128,13961,94290919,CLX5
2025-09-24 19:35:08.499304459+00:00,160,1,432669,A,A,64.82,1,26,8058566338095,128,18355,94290921,CLX5
2025-09-24 19:35:08.499559173+00:00,160,1,432669,M,A,64.93,1,26,8058565075241,128,14198,94290934,CLX5
2025-09-24 19:35:08.499885559+00:00,160,1,432669,M,B,64.79,4,26,8058566335785,128,15097,94290947,CLX5
2025-09-24 19:35:08.499955771+00:00,160,1,432669,T,B,64.81,1,26,8058566338099,0,14462,94290952,CLX5
2025-09-24 19:35:08.499955771+00:00,160,1,432669,F,A,64.81,1,26,8058566338000,0,14462,94290952,CLX5
2025-09-24 19:35:08.499955771+00:00,160,1,432669,M,A,64.81,14,26,8058566338000,128,15196,94290953,CLX5
2025-09-24 19:35:08.502548309+00:00,160,1,432669,M,A,64.94,1,26,8058565075241,128,14709,94291095,CLX5
2025-09-24 19:35:08.503459731+00:00,160,1,432669,M,A,64.93,1,26,8058565075241,128,14692,94291136,CLX5
2025-09-24 19:35:08.504099639+00:00,160,1,432669,C,A,64.81,1,26,8058566338085,128,18782,94291167,CLX5
2025-09-24 19:35:08.504293859+00:00,160,1,432669,A,A,64.81,1,26,8058566338157,128,15009,94291175,CLX5
2025-09-24 19:35:08.504885539+00:00,160,1,432669,M,A,64.82,1,26,8058566331891,128,18209,94291191,CLX5
2025-09-24 19:35:08.505224903+00:00,160,1,432669,C,A,64.81,1,26,8058566338157,128,17340,94291202,CLX5
2025-09-24 19:35:08.505732719+00:00,160,1,432669,A,A,64.81,1,26,8058566338171,128,15076,94291224,CLX5
2025-09-24 19:35:08.506408435+00:00,160,1,432669,C,A,64.81,1,26,8058566338171,128,18158,94291258,CLX5
2025-09-24 19:35:08.509609413+00:00,160,1,432669,C,B,64.8,1,26,8058566338030,128,15686,94291326,CLX5
2025-09-24 19:35:08.509648829+00:00,160,1,432669,C,A,64.82,1,26,8058566338095,128,15099,94291330,CLX5
2025-09-24 19:35:08.509662671+00:00,160,1,432669,C,A,64.82,1,26,8058566338093,128,17314,94291332,CLX5
2025-09-24 19:35:08.510550709+00:00,160,1,432669,C,A,64.87,2,26,8058566331963,128,14574,94291350,CLX5
2025-09-24 19:35:08.511537699+00:00,160,1,432669,M,A,64.94,1,26,8058565075241,128,17597,94291357,CLX5
2025-09-24 19:35:08.516113529+00:00,160,1,432669,C,A,65.9,1,26,8058566337606,128,14612,94291467,CLX5
2025-09-24 19:35:08.516156323+00:00,160,1,432669,C,A,65.7,6,26,8058566287517,128,14630,94291468,CLX5
2025-09-24 19:35:08.547368869+00:00,160,1,432669,A,A,64.81,2,26,8058566338260,128,18438,94291541,CLX5
2025-09-24 19:35:08.547371863+00:00,160,1,432669,A,A,64.81,1,26,8058566338261,128,14917,94291542,CLX5
2025-09-24 19:35:08.579332559+00:00,160,1,432669,C,A,64.82,1,26,8058566336044,128,18366,94291642,CLX5
2025-09-24 19:35:08.579865661+00:00,160,1,432669,A,A,64.81,1,26,8058566338293,128,18334,94291643,CLX5
2025-09-24 19:35:08.581212579+00:00,160,1,432669,M,A,64.93,1,26,8058565075241,128,13693,94291680,CLX5
2025-09-24 19:35:08.584185529+00:00,160,1,432669,M,A,64.94,1,26,8058565075241,128,14553,94291772,CLX5
2025-09-24 19:35:08.608984289+00:00,160,1,432669,T,B,64.81,3,26,8058566338375,0,18068,94291921,CLX5
2025-09-24 19:35:08.608984289+00:00,160,1,432669,F,A,64.81,3,26,8058566338000,0,18068,94291921,CLX5
2025-09-24 19:35:08.608984289+00:00,160,1,432669,M,A,64.81,11,26,8058566338000,128,19214,94291922,CLX5
2025-09-24 19:35:08.609023741+00:00,160,1,432669,T,B,64.81,1,26,8058566338377,0,14385,94291925,CLX5
2025-09-24 19:35:08.609023741+00:00,160,1,432669,F,A,64.81,1,26,8058566338000,0,14385,94291925,CLX5
2025-09-24 19:35:08.609023741+00:00,160,1,432669,M,A,64.81,10,26,8058566338000,128,14385,94291925,CLX5
2025-09-24 19:35:08.609338819+00:00,160,1,432669,M,A,64.93,1,26,8058565075241,128,14246,94291935,CLX5
2025-09-24 19:35:08.609489685+00:00,160,1,432669,T,B,64.81,15,26,8058566338384,0,17378,94291947,CLX5
2025-09-24 19:35:08.609489685+00:00,160,1,432669,F,A,64.81,10,26,8058566338000,0,17378,94291947,CLX5
2025-09-24 19:35:08.609489685+00:00,160,1,432669,F,A,64.81,2,26,8058566338026,0,17378,94291947,CLX5
2025-09-24 19:35:08.609489685+00:00,160,1,432669,F,A,64.81,1,26,8058566338032,0,17378,94291947,CLX5
2025-09-24 19:35:08.609489685+00:00,160,1,432669,F,A,64.81,1,26,8058566338036,0,17378,94291947,CLX5
2025-09-24 19:35:08.609489685+00:00,160,1,432669,F,A,64.81,1,26,8058566338260,0,17378,94291947,CLX5
2025-09-24 19:35:08.609489685+00:00,160,1,432669,C,A,64.81,10,26,8058566338000,0,14553,94291948,CLX5
2025-09-24 19:35:08.609489685+00:00,160,1,432669,C,A,64.81,2,26,8058566338026,0,14553,94291948,CLX5
2025-09-24 19:35:08.609489685+00:00,160,1,432669,C,A,64.81,1,26,8058566338032,0,14553,94291948,CLX5
2025-09-24 19:35:08.609489685+00:00,160,1,432669,C,A,64.81,1,26,8058566338036,0,14553,94291948,CLX5
2025-09-24 19:35:08.609489685+00:00,160,1,432669,M,A,64.81,1,26,8058566338260,128,14553,94291948,CLX5
2025-09-24 19:35:08.609494641+00:00,160,1,432669,T,B,64.81,3,26,8058566338385,0,18591,94291949,CLX5
2025-09-24 19:35:08.609494641+00:00,160,1,432669,F,A,64.81,1,26,8058566338260,0,18591,94291949,CLX5
2025-09-24 19:35:08.609494641+00:00,160,1,432669,F,A,64.81,1,26,8058566338261,0,18591,94291949,CLX5
2025-09-24 19:35:08.609494641+00:00,160,1,432669,F,A,64.81,1,26,8058566338293,0,18591,94291949,CLX5
2025-09-24 19:35:08.609494641+00:00,160,1,432669,C,A,64.81,1,26,8058566338260,0,14807,94291950,CLX5
2025-09-24 19:35:08.609494641+00:00,160,1,432669,C,A,64.81,1,26,8058566338261,0,14807,94291950,CLX5
2025-09-24 19:35:08.609494641+00:00,160,1,432669,C,A,64.81,1,26,8058566338293,128,14807,94291950,CLX5
2025-09-24 19:35:08.609922077+00:00,160,1,432669,A,B,64.8,1,26,8058566338390,128,15058,94291965,CLX5
2025-09-24 19:35:08.609926907+00:00,160,1,432669,A,B,64.8,1,26,8058566338394,128,14775,94291973,CLX5
2025-09-24 19:35:08.609976175+00:00,160,1,432669,A,B,64.8,1,26,8058566338398,128,14883,94291978,CLX5
2025-09-24 19:35:08.609978891+00:00,160,1,432669,A,B,64.8,1,26,8058566338409,128,16100,94292006,CLX5
2025-09-24 19:35:08.609979065+00:00,160,1,432669,A,A,64.81,1,26,8058566338410,128,14730,94292007,CLX5
2025-09-24 19:35:08.609979247+00:00,160,1,432669,A,A,64.81,1,26,8058566338411,128,17816,94292010,CLX5
2025-09-24 19:35:08.610071919+00:00,160,1,432669,A,A,64.81,1,26,8058566338426,128,14551,94292032,CLX5
2025-09-24 19:35:08.610237013+00:00,160,1,432669,C,B,64.8,1,26,8058566338394,128,14927,94292044,CLX5
2025-09-24 19:35:08.610299103+00:00,160,1,432669,M,A,64.84,4,26,8058566282770,128,14545,94292050,CLX5
2025-09-24 19:35:08.610437029+00:00,160,1,432669,A,A,64.81,2,26,8058566338435,128,14955,94292053,CLX5
2025-09-24 19:35:08.610551475+00:00,160,1,432669,A,B,64.78,1,26,8058566338439,128,13563,94292062,CLX5
2025-09-24 19:35:08.610706913+00:00,160,1,432669,T,B,64.81,2,26,8058566338453,0,14950,94292086,CLX5
2025-09-24 19:35:08.610706913+00:00,160,1,432669,F,A,64.81,1,26,8058566338410,0,14950,94292086,CLX5
2025-09-24 19:35:08.610706913+00:00,160,1,432669,F,A,64.81,1,26,8058566338411,0,14950,94292086,CLX5
2025-09-24 19:35:08.610706913+00:00,160,1,432669,C,A,64.81,1,26,8058566338410,0,18190,94292087,CLX5
2025-09-24 19:35:08.610706913+00:00,160,1,432669,C,A,64.81,1,26,8058566338411,128,18190,94292087,CLX5
2025-09-24 19:35:08.610856339+00:00,160,1,432669,C,A,64.81,2,26,8058566338435,128,17977,94292102,CLX5
2025-09-24 19:35:08.611412155+00:00,160,1,432669,C,B,64.8,1,26,8058566338398,128,14926,94292133,CLX5
2025-09-24 19:35:08.611697763+00:00,160,1,432669,C,A,64.81,1,26,8058566338426,128,14927,94292148,CLX5
2025-09-24 19:35:08.611782027+00:00,160,1,432669,A,B,64.8,1,26,8058566338483,128,14904,94292154,CLX5
2025-09-24 19:35:08.611845883+00:00,160,1,432669,C,A,64.84,4,26,8058566282770,128,14472,94292156,CLX5
2025-09-24 19:35:08.612091977+00:00,160,1,432669,A,B,64.8,1,26,8058566338488,128,14759,94292163,CLX5
2025-09-24 19:35:08.612214389+00:00,160,1,432669,A,B,64.81,2,26,8058566338492,128,17939,94292168,CLX5
2025-09-24 19:35:08.613837047+00:00,160,1,432669,C,B,64.8,1,26,8058566338483,128,17300,94292209,CLX5
2025-09-24 19:35:08.614223275+00:00,160,1,432669,A,B,64.8,1,26,8058566338508,128,14793,94292217,CLX5
2025-09-24 19:35:08.614465627+00:00,160,1,432669,C,B,64.8,1,26,8058566338508,128,18264,94292220,CLX5
2025-09-24 19:35:08.615147695+00:00,160,1,432669,M,A,64.84,4,26,8058566331102,128,15372,94292251,CLX5
2025-09-24 19:35:08.615446109+00:00,160,1,432669,M,A,65.97,4,26,8058566321460,128,13868,94292276,CLX5
2025-09-24 19:35:08.616207047+00:00,160,1,432669,A,A,65.7,6,26,8058566338533,128,14967,94292301,CLX5
2025-09-24 19:35:08.618817001+00:00,160,1,432669,C,B,64.81,2,26,8058566338492,128,15269,94292431,CLX5
2025-09-24 19:35:08.619149783+00:00,160,1,432669,A,A,64.81,1,26,8058566338579,128,16634,94292451,CLX5
2025-09-24 19:35:08.619149971+00:00,160,1,432669,A,A,64.81,1,26,8058566338580,128,14518,94292455,CLX5
2025-09-24 19:35:08.620221647+00:00,160,1,432669,A,A,64.81,1,26,8058566338600,128,14574,94292520,CLX5
2025-09-24 19:35:08.620223069+00:00,160,1,432669,C,B,64.8,1,26,8058566338409,128,17432,94292522,CLX5
2025-09-24 19:35:08.620223837+00:00,160,1,432669,M,A,64.94,1,26,8058565075241,128,14334,94292524,CLX5
2025-09-24 19:35:08.620416173+00:00,160,1,432669,M,A,65.96,3,26,8058566331102,128,15118,94292535,CLX5
2025-09-24 19:35:08.620593421+00:00,160,1,432669,M,A,64.83,3,26,8058566331622,128,14932,94292542,CLX5
2025-09-24 19:35:08.621229239+00:00,160,1,432669,C,A,64.81,1,26,8058566338600,128,18499,94292577,CLX5
2025-09-24 19:35:08.626224243+00:00,160,1,432669,A,A,65.95,3,26,8058566338645,128,17602,94292665,CLX5
2025-09-24 19:35:08.644528295+00:00,160,1,432669,C,A,64.82,1,26,8058566337750,128,18142,94292693,CLX5
2025-09-24 19:35:08.661943749+00:00,160,1,432669,A,A,64.82,1,26,8058566338676,128,18445,94292714,CLX5
2025-09-24 19:35:08.716201383+00:00,160,1,432669,C,A,65.7,6,26,8058566338533,128,14143,94292812,CLX5
2025-09-24 19:35:08.810885865+00:00,160,1,432669,A,B,64.76,2,26,8058566338861,128,18562,94293033,CLX5
2025-09-24 19:35:08.831931151+00:00,160,1,432669,A,B,64.78,1,26,8058566338864,128,18756,94293043,CLX5
2025-09-24 19:35:09.938053427+00:00,160,1,432669,A,B,64.78,1,26,8058566338999,128,18535,94293314,CLX5
2025-09-24 19:35:12.469384201+00:00,160,1,432669,C,A,64.82,1,26,8058566336693,128,18568,94293619,CLX5
2025-09-24 19:35:12.469555015+00:00,160,1,432669,C,A,64.81,1,26,8058566338580,128,18188,94293620,CLX5
2025-09-24 19:35:12.469722663+00:00,160,1,432669,C,A,64.81,1,26,8058566338579,128,14823,94293626,CLX5
2025-09-24 19:35:12.469903057+00:00,160,1,432669,A,B,64.8,1,26,8058566339145,128,18260,94293630,CLX5
2025-09-24 19:35:12.470334251+00:00,160,1,432669,A,B,64.81,1,26,8058566339150,128,16266,94293642,CLX5
2025-09-24 19:35:12.470383499+00:00,160,1,432669,A,B,64.8,2,26,8058566339151,128,15021,94293648,CLX5
2025-09-24 19:35:12.470465575+00:00,160,1,432669,C,A,64.82,1,26,8058566338016,128,15779,94293660,CLX5
2025-09-24 19:35:12.470559477+00:00,160,1,432669,C,B,64.8,1,26,8058566339145,128,17496,94293686,CLX5
2025-09-24 19:35:12.470759053+00:00,160,1,432669,C,B,64.81,1,26,8058566339150,128,14934,94293707,CLX5
2025-09-24 19:35:12.470804325+00:00,160,1,432669,A,B,64.81,1,26,8058566339168,128,14668,94293714,CLX5
2025-09-24 19:35:12.470936203+00:00,160,1,432669,M,A,65.98,4,26,8058566331622,128,17612,94293731,CLX5
2025-09-24 19:35:12.471252547+00:00,160,1,432669,C,B,64.81,1,26,8058566339168,128,14793,94293788,CLX5
2025-09-24 19:35:12.471510353+00:00,160,1,432669,A,B,64.8,1,26,8058566339196,128,14682,94293819,CLX5
2025-09-24 19:35:12.471915611+00:00,160,1,432669,C,B,64.8,1,26,8058566339196,128,18383,94293833,CLX5
2025-09-24 19:35:12.473370445+00:00,160,1,432669,A,B,64.8,1,26,8058566339205,128,17500,94293865,CLX5
2025-09-24 19:35:12.473512517+00:00,160,1,432669,C,B,64.8,1,26,8058566339205,128,15072,94293885,CLX5
2025-09-24 19:35:12.473614619+00:00,160,1,432669,M,A,64.84,4,26,8058566321460,128,14625,94293888,CLX5
2025-09-24 19:35:12.505494025+00:00,160,1,432669,M,A,64.93,1,26,8058565075241,128,17686,94294038,CLX5
2025-09-24 19:35:12.507475935+00:00,160,1,432669,M,A,64.94,1,26,8058565075241,128,17790,94294062,CLX5
2025-09-24 19:35:12.516226949+00:00,160,1,432669,A,A,65.7,6,26,8058566339267,128,18127,94294092,CLX5
2025-09-24 19:35:14.426758613+00:00,160,1,432669,A,B,64.81,1,26,8058566339421,128,18584,94294428,CLX5
2025-09-24 19:35:14.427411153+00:00,160,1,432669,C,A,64.82,2,26,8058566338023,128,19039,94294438,CLX5
2025-09-24 19:35:14.479709301+00:00,160,1,432669,T,A,64.81,1,26,8058566339432,0,19312,94294467,CLX5
2025-09-24 19:35:14.479709301+00:00,160,1,432669,F,B,64.81,1,26,8058566339421,0,19312,94294467,CLX5
2025-09-24 19:35:14.479709301+00:00,160,1,432669,C,B,64.81,1,26,8058566339421,128,14528,94294468,CLX5
2025-09-24 19:35:14.479975997+00:00,160,1,432669,A,A,64.82,2,26,8058566339433,128,18160,94294471,CLX5
2025-09-24 19:35:14.479983117+00:00,160,1,432669,A,A,64.82,1,26,8058566339434,128,14957,94294475,CLX5
2025-09-24 19:35:14.480146963+00:00,160,1,432669,A,A,64.82,1,26,8058566339438,128,15200,94294483,CLX5
2025-09-24 19:35:14.480185515+00:00,160,1,432669,C,A,64.82,1,26,8058566339434,128,14916,94294484,CLX5
2025-09-24 19:35:14.480218557+00:00,160,1,432669,A,A,64.82,1,26,8058566339439,128,15124,94294485,CLX5
2025-09-24 19:35:14.480381173+00:00,160,1,432669,A,A,64.82,1,26,8058566339440,128,18153,94294486,CLX5
2025-09-24 19:35:14.515089153+00:00,160,1,432669,A,A,64.82,1,26,8058566339448,128,18721,94294518,CLX5
2025-09-24 19:35:14.515271007+00:00,160,1,432669,C,A,64.82,1,26,8058566339440,128,18672,94294519,CLX5
2025-09-24 19:35:14.515280647+00:00,160,1,432669,C,A,64.82,1,26,8058566339439,128,15177,94294520,CLX5
2025-09-24 19:35:14.515285465+00:00,160,1,432669,C,A,64.82,1,26,8058566339438,128,14963,94294521,CLX5
2025-09-24 19:35:14.517337913+00:00,160,1,432669,A,A,64.81,2,26,8058566339451,128,19006,94294523,CLX5
2025-09-24 19:35:14.517481907+00:00,160,1,432669,A,A,64.81,1,26,8058566339454,128,15334,94294532,CLX5
2025-09-24 19:35:14.517632081+00:00,160,1,432669,C,B,64.8,2,26,8058566339151,128,14209,94294542,CLX5
2025-09-24 19:35:14.517843271+00:00,160,1,432669,M,A,64.83,3,26,8058566331622,128,18239,94294552,CLX5
2025-09-24 19:35:14.616216123+00:00,160,1,432669,C,A,65.7,6,26,8058566339267,128,18342,94294660,CLX5
2025-09-24 19:35:15.380241673+00:00,160,1,432669,A,B,64.8,1,26,8058566339497,128,18906,94294677,CLX5
2025-09-24 19:35:15.380414791+00:00,160,1,432669,C,A,64.81,1,26,8058566339454,128,18517,94294678,CLX5
2025-09-24 19:35:16.222086497+00:00,160,1,432669,A,A,64.81,1,26,8058566339505,128,18825,94294703,CLX5
2025-09-24 19:35:18.787380159+00:00,160,1,432669,A,B,64.78,1,26,8058566339518,128,17759,94294743,CLX5
2025-09-24 19:35:19.984090837+00:00,160,1,432669,C,A,64.81,1,26,8058566339505,128,20334,94294753,CLX5
2025-09-24 19:35:20.085212277+00:00,160,1,432669,A,A,64.82,1,26,8058566339533,128,18204,94294800,CLX5
2025-09-24 19:35:20.085468873+00:00,160,1,432669,A,A,64.82,1,26,8058566339534,128,18307,94294801,CLX5
2025-09-24 19:35:20.563635989+00:00,160,1,432669,A,A,64.81,1,26,8058566339546,128,14668,94294832,CLX5
2025-09-24 19:35:20.624191981+00:00,160,1,432669,M,A,64.93,1,26,8058565075241,128,16587,94294862,CLX5
2025-09-24 19:35:20.624981987+00:00,160,1,432669,M,A,64.94,1,26,8058565075241,128,14707,94294886,CLX5
2025-09-24 19:35:20.632243837+00:00,160,1,432669,M,A,64.93,1,26,8058565075241,128,16176,94294920,CLX5
2025-09-24 19:35:20.633055251+00:00,160,1,432669,M,A,64.94,1,26,8058565075241,128,17664,94294930,CLX5
2025-09-24 19:35:20.654488935+00:00,160,1,432669,M,A,64.93,1,26,8058565075241,128,18034,94294970,CLX5
2025-09-24 19:35:20.751096365+00:00,160,1,432669,M,A,64.94,1,26,8058565075241,128,16107,94295071,CLX5
2025-09-24 19:35:22.402368501+00:00,160,1,432669,A,B,64.71,1,26,8058566339705,128,18173,94295303,CLX5
2025-09-24 19:35:30.158845271+00:00,160,1,432669,M,A,64.93,1,26,8058565075241,128,14188,94295581,CLX5
2025-09-24 19:35:30.160074475+00:00,160,1,432669,A,A,64.81,2,26,8058566339790,128,17871,94295605,CLX5
2025-09-24 19:35:30.160181837+00:00,160,1,432669,A,A,64.81,2,26,8058566339797,128,21795,94295623,CLX5
2025-09-24 19:35:30.160506899+00:00,160,1,432669,C,A,64.81,2,26,8058566339797,128,16881,94295634,CLX5
2025-09-24 19:35:30.160514155+00:00,160,1,432669,A,A,64.81,1,26,8058566339800,128,18377,94295636,CLX5
2025-09-24 19:35:30.160939531+00:00,160,1,432669,A,A,64.81,1,26,8058566339806,128,14601,94295654,CLX5
2025-09-24 19:35:30.161265611+00:00,160,1,432669,C,B,64.76,2,26,8058566338861,128,18451,94295665,CLX5
2025-09-24 19:35:30.233435573+00:00,160,1,432669,M,A,64.94,1,26,8058565075241,128,15403,94296097,CLX5
2025-09-24 19:35:30.233689981+00:00,160,1,432669,C,A,64.81,2,26,8058566339790,128,18410,94296108,CLX5
2025-09-24 19:35:30.625130127+00:00,160,1,432669,C,A,64.82,1,26,8058566339533,128,18607,94296282,CLX5
2025-09-24 19:35:31.350766097+00:00,160,1,432669,C,A,64.82,1,26,8058566339534,128,17958,94296333,CLX5
2025-09-24 19:35:34.071306905+00:00,160,1,432669,A,B,64.79,1,26,8058566340051,128,20531,94296452,CLX5
2025-09-24 19:35:34.492297199+00:00,160,1,432669,A,A,64.81,1,26,8058566340057,128,18997,94296463,CLX5
2025-09-24 19:35:34.492323675+00:00,160,1,432669,A,A,64.81,2,26,8058566340065,128,22081,94296479,CLX5
2025-09-24 19:35:34.492491839+00:00,160,1,432669,A,A,64.81,1,26,8058566340088,128,16684,94296536,CLX5
2025-09-24 19:35:34.492619917+00:00,160,1,432669,C,B,64.78,1,26,8058566338439,128,14896,94296597,CLX5
2025-09-24 19:35:34.492673021+00:00,160,1,432669,C,B,64.8,1,26,8058566338488,128,18160,94296604,CLX5
2025-09-24 19:35:34.492673351+00:00,160,1,432669,A,A,64.81,1,26,8058566340100,128,16140,94296605,CLX5
2025-09-24 19:35:34.492791405+00:00,160,1,432669,A,A,64.81,1,26,8058566340105,128,16250,94296624,CLX5
2025-09-24 19:35:34.492798987+00:00,160,1,432669,C,B,64.8,1,26,8058566338390,128,18067,94296626,CLX5
2025-09-24 19:35:34.492802635+00:00,160,1,432669,A,A,64.81,1,26,8058566340109,128,15862,94296628,CLX5
2025-09-24 19:35:34.492803307+00:00,160,1,432669,A,A,64.81,2,26,8058566340110,128,15705,94296630,CLX5
2025-09-24 19:35:34.492833393+00:00,160,1,432669,C,B,64.8,1,26,8058566249950,128,15224,94296635,CLX5
2025-09-24 19:35:34.492842991+00:00,160,1,432669,A,A,64.81,2,26,8058566340113,128,15262,94296642,CLX5
2025-09-24 19:35:34.493080407+00:00,160,1,432669,A,B,64.54,8,26,8058566340123,128,15161,94296685,CLX5
2025-09-24 19:35:34.493147663+00:00,160,1,432669,C,B,64.79,2,26,8058566335966,128,15335,94296696,CLX5
2025-09-24 19:35:34.493324775+00:00,160,1,432669,C,B,64.8,2,26,8058566256559,128,14727,94296729,CLX5
2025-09-24 19:35:34.494071969+00:00,160,1,432669,M,A,64.93,1,26,8058565075241,128,15101,94296819,CLX5
2025-09-24 19:35:34.494092569+00:00,160,1,432669,A,A,64.84,2,26,8058566340173,128,15090,94296823,CLX5
2025-09-24 19:35:34.495429079+00:00,160,1,432669,C,A,64.81,2,26,8058566340113,128,14282,94296968,CLX5
2025-09-24 19:35:34.495496163+00:00,160,1,432669,C,B,64.78,1,26,8058566339518,128,15093,94296970,CLX5
2025-09-24 19:35:34.495669723+00:00,160,1,432669,A,B,64.8,1,26,8058566340206,128,14150,94296982,CLX5
2025-09-24 19:35:34.495718775+00:00,160,1,432669,A,B,64.8,1,26,8058566340208,128,15258,94296984,CLX5
2025-09-24 19:35:34.495736555+00:00,160,1,432669,C,B,64.8,3,26,8058566250421,128,15745,94296986,CLX5
2025-09-24 19:35:34.496189635+00:00,160,1,432669,C,B,64.8,1,26,8058566340206,128,14900,94297058,CLX5
2025-09-24 19:35:34.496767529+00:00,160,1,432669,M,B,63.64,3,26,8058566221991,128,14583,94297072,CLX5
2025-09-24 19:35:34.496934773+00:00,160,1,432669,M,B,64.8,2,26,8058566211150,128,16877,94297082,CLX5
2025-09-24 19:35:34.497756229+00:00,160,1,432669,C,B,64.8,2,26,8058566211150,128,19400,94297119,CLX5
2025-09-24 19:35:34.499586637+00:00,160,1,432669,C,A,64.84,2,26,8058566340173,128,18209,94297212,CLX5
2025-09-24 19:35:34.499933145+00:00,160,1,432669,C,A,64.81,2,26,8058566340110,128,18872,94297228,CLX5
2025-09-24 19:35:34.500418151+00:00,160,1,432669,A,B,64.8,1,26,8058566340266,128,14954,94297248,CLX5
2025-09-24 19:35:34.500686479+00:00,160,1,432669,M,A,64.81,1,26,8058566331891,128,19030,94297258,CLX5
2025-09-24 19:35:34.502181863+00:00,160,1,432669,C,A,64.81,1,26,8058566340105,128,18735,94297303,CLX5
2025-09-24 19:35:34.511552049+00:00,160,1,432669,A,B,64.78,1,26,8058566340353,128,14677,94297597,CLX5
2025-09-24 19:35:34.514959013+00:00,160,1,432669,M,A,64.82,1,26,8058566331891,128,19516,94297647,CLX5
2025-09-24 19:35:34.542201115+00:00,160,1,432669,A,B,64.79,2,26,8058566340373,128,18256,94297708,CLX5
2025-09-24 19:35:34.542395661+00:00,160,1,432669,C,A,64.81,1,26,8058566340088,128,17887,94297719,CLX5
2025-09-24 19:35:34.569425731+00:00,160,1,432669,A,A,64.81,2,26,8058566340395,128,19428,94297770,CLX5
2025-09-24 19:35:34.569426665+00:00,160,1,432669,C,B,64.79,2,26,8058566340373,128,18846,94297772,CLX5
2025-09-24 19:35:34.569431273+00:00,160,1,432669,A,A,64.81,1,26,8058566340397,128,14246,94297775,CLX5
2025-09-24 19:35:34.569432523+00:00,160,1,432669,C,B,64.8,1,26,8058566340208,128,18270,94297777,CLX5
2025-09-24 19:35:34.569849337+00:00,160,1,432669,C,A,64.81,1,26,8058566340397,128,14462,94297793,CLX5
2025-09-24 19:35:34.570282027+00:00,160,1,432669,A,B,64.8,1,26,8058566340404,128,19477,94297806,CLX5
2025-09-24 19:35:34.572552327+00:00,160,1,432669,A,A,64.81,1,26,8058566340408,128,15291,94297813,CLX5
2025-09-24 19:35:34.572553883+00:00,160,1,432669,C,B,64.8,1,26,8058566340404,128,15104,94297814,CLX5
2025-09-24 19:35:34.572711335+00:00,160,1,432669,C,A,64.81,1,26,8058566340408,128,18503,94297821,CLX5
2025-09-24 19:35:34.572749617+00:00,160,1,432669,A,B,64.8,1,26,8058566340410,128,15574,94297822,CLX5
2025-09-24 19:35:34.610665967+00:00,160,1,432669,A,B,64.77,2,26,8058566340445,128,18329,94297886,CLX5
2025-09-24 19:35:34.622125979+00:00,160,1,432669,C,B,64.54,8,26,8058566340123,128,18603,94297903,CLX5
2025-09-24 19:35:34.643702737+00:00,160,1,432669,A,B,64.4,2,26,8058566340482,128,18429,94297934,CLX5
2025-09-24 19:35:34.646997387+00:00,160,1,432669,C,A,64.81,2,26,8058566340395,128,16206,94297971,CLX5
2025-09-24 19:35:34.647326155+00:00,160,1,432669,C,A,64.81,1,26,8058566340057,128,15685,94297984,CLX5
2025-09-24 19:35:34.647710195+00:00,160,1,432669,A,B,64.79,2,26,8058566340495,128,13952,94297996,CLX5
2025-09-24 19:35:34.647829193+00:00,160,1,432669,A,B,64.8,1,26,8058566340503,128,15646,94298010,CLX5
2025-09-24 19:35:34.647926705+00:00,160,1,432669,C,B,64.8,1,26,8058566340503,128,14897,94298018,CLX5
2025-09-24 19:35:34.710660705+00:00,160,1,432669,C,B,64.77,2,26,8058566340445,128,18488,94298227,CLX5
2025-09-24 19:35:34.724633521+00:00,160,1,432669,C,A,64.81,1,26,8058566340109,128,16846,94298236,CLX5
2025-09-24 19:35:34.724633669+00:00,160,1,432669,A,B,64.8,1,26,8058566340602,128,15375,94298238,CLX5
2025-09-24 19:35:34.724639723+00:00,160,1,432669,C,A,64.81,1,26,8058566339546,128,20462,94298239,CLX5
2025-09-24 19:35:34.724651395+00:00,160,1,432669,A,B,64.8,1,26,8058566340603,128,15591,94298241,CLX5
2025-09-24 19:35:34.724655043+00:00,160,1,432669,A,B,64.8,1,26,8058566340604,128,17071,94298242,CLX5
2025-09-24 19:35:34.724664375+00:00,160,1,432669,C,A,64.81,2,26,8058566340065,128,16106,94298243,CLX5
2025-09-24 19:35:34.724722989+00:00,160,1,432669,A,B,64.8,2,26,8058566340607,128,14693,94298246,CLX5
2025-09-24 19:35:34.724819063+00:00,160,1,432669,M,A,64.94,1,26,8058565075241,128,14485,94298253,CLX5
2025-09-24 19:35:34.724871707+00:00,160,1,432669,C,B,64.8,1,26,8058566340603,128,15020,94298254,CLX5
2025-09-24 19:35:34.724913867+00:00,160,1,432669,C,A,64.81,1,26,8058566340100,128,22058,94298255,CLX5
2025-09-24 19:35:34.725038163+00:00,160,1,432669,C,B,64.8,2,26,8058566340607,128,17168,94298270,CLX5
2025-09-24 19:35:34.725925931+00:00,160,1,432669,A,A,64.81,1,26,8058566340624,128,20510,94298309,CLX5
2025-09-24 19:35:34.745980945+00:00,160,1,432669,T,B,64.81,4,26,8058566340666,0,18321,94298454,CLX5
2025-09-24 19:35:34.745980945+00:00,160,1,432669,F,A,64.81,2,26,8058566339451,0,18321,94298454,CLX5
2025-09-24 19:35:34.745980945+00:00,160,1,432669,F,A,64.81,1,26,8058566339800,0,18321,94298454,CLX5
2025-09-24 19:35:34.745980945+00:00,160,1,432669,F,A,64.81,1,26,8058566339806,0,18321,94298454,CLX5
2025-09-24 19:35:34.745980945+00:00,160,1,432669,C,A,64.81,2,26,8058566339451,0,15224,94298455,CLX5
2025-09-24 19:35:34.745980945+00:00,160,1,432669,C,A,64.81,1,26,8058566339800,0,15224,94298455,CLX5
2025-09-24 19:35:34.745980945+00:00,160,1,432669,C,A,64.81,1,26,8058566339806,128,15224,94298455,CLX5
2025-09-24 19:35:34.746336455+00:00,160,1,432669,A,A,64.81,1,26,8058566340671,128,17903,94298469,CLX5
2025-09-24 19:35:34.746336635+00:00,160,1,432669,A,A,64.81,1,26,8058566340672,128,17049,94298471,CLX5
2025-09-24 19:35:34.746351181+00:00,160,1,432669,A,B,64.8,2,26,8058566340678,128,19033,94298484,CLX5
2025-09-24 19:35:34.746383321+00:00,160,1,432669,M,A,64.93,1,26,8058565075241,128,14858,94298494,CLX5
2025-09-24 19:35:34.746389311+00:00,160,1,432669,A,B,64.8,2,26,8058566340680,128,14978,94298497,CLX5
2025-09-24 19:35:34.746407185+00:00,160,1,432669,T,N,64.81,1,26,0,0,14695,94298499,CLX5
2025-09-24 19:35:34.746407185+00:00,160,1,432669,F,N,64.81,1,26,8058566340624,0,14695,94298499,CLX5
2025-09-24 19:35:34.746407185+00:00,160,1,432669,C,A,64.81,1,26,8058566340624,128,17947,94298500,CLX5
2025-09-24 19:35:34.746421143+00:00,160,1,432669,T,N,64.81,1,26,0,0,14849,94298504,CLX5
2025-09-24 19:35:34.746421143+00:00,160,1,432669,F,N,64.81,1,26,8058566340671,0,14849,94298504,CLX5
2025-09-24 19:35:34.746421143+00:00,160,1,432669,C,A,64.81,1,26,8058566340671,128,18637,94298505,CLX5
2025-09-24 19:35:34.746704561+00:00,160,1,432669,C,B,64.8,2,26,8058566340678,128,16240,94298515,CLX5
2025-09-24 19:35:34.747150749+00:00,160,1,432669,C,A,64.81,1,26,8058566340672,128,18237,94298528,CLX5
2025-09-24 19:35:34.747974699+00:00,160,1,432669,A,A,64.82,1,26,8058566340698,128,13809,94298553,CLX5
2025-09-24 19:35:34.748005361+00:00,160,1,432669,A,B,64.8,1,26,8058566340700,128,18219,94298558,CLX5
2025-09-24 19:35:34.748202287+00:00,160,1,432669,A,A,64.81,1,26,8058566340703,128,14610,94298571,CLX5
2025-09-24 19:35:34.748883473+00:00,160,1,432669,C,B,64.8,1,26,8058566340700,128,18137,94298600,CLX5
2025-09-24 19:35:34.749762583+00:00,160,1,432669,A,A,64.81,1,26,8058566340712,128,18229,94298618,CLX5
2025-09-24 19:35:34.749762763+00:00,160,1,432669,A,A,64.81,1,26,8058566340713,128,16047,94298620,CLX5
2025-09-24 19:35:34.751682287+00:00,160,1,432669,A,A,64.81,1,26,8058566340741,128,17846,94298717,CLX5
2025-09-24 19:35:34.854356919+00:00,160,1,432669,C,A,64.81,1,26,8058566340741,128,14596,94298896,CLX5
2025-09-24 19:35:35.118606687+00:00,160,1,432669,M,A,64.94,1,26,8058565075241,128,17614,94299034,CLX5
2025-09-24 19:35:35.136103913+00:00,160,1,432669,T,B,64.81,3,26,8058566340881,0,17725,94299128,CLX5
2025-09-24 19:35:35.136103913+00:00,160,1,432669,F,A,64.81,1,26,8058566340703,0,17725,94299128,CLX5
2025-09-24 19:35:35.136103913+00:00,160,1,432669,F,A,64.81,1,26,8058566340712,0,17725,94299128,CLX5
2025-09-24 19:35:35.136103913+00:00,160,1,432669,F,A,64.81,1,26,8058566340713,0,17725,94299128,CLX5
2025-09-24 19:35:35.136103913+00:00,160,1,432669,C,A,64.81,1,26,8058566340703,0,14554,94299129,CLX5
2025-09-24 19:35:35.136103913+00:00,160,1,432669,C,A,64.81,1,26,8058566340712,0,14554,94299129,CLX5
2025-09-24 19:35:35.136103913+00:00,160,1,432669,C,A,64.81,1,26,8058566340713,128,14554,94299129,CLX5
2025-09-24 19:35:35.136431393+00:00,160,1,432669,M,A,64.93,1,26,8058565075241,128,13882,94299154,CLX5
2025-09-24 19:35:35.136524125+00:00,160,1,432669,A,B,64.8,2,26,8058566340892,128,14103,94299166,CLX5
2025-09-24 19:35:35.136605433+00:00,160,1,432669,A,B,64.8,1,26,8058566340896,128,18585,94299174,CLX5
2025-09-24 19:35:35.136605609+00:00,160,1,432669,A,B,64.8,1,26,8058566340897,128,15007,94299175,CLX5
2025-09-24 19:35:35.136619927+00:00,160,1,432669,C,A,64.82,2,26,8058566339433,128,14870,94299176,CLX5
2025-09-24 19:35:35.137313593+00:00,160,1,432669,C,A,64.82,1,26,8058566340698,128,14757,94299216,CLX5
2025-09-24 19:35:35.137500843+00:00,160,1,432669,A,B,64.8,3,26,8058566340905,128,15143,94299218,CLX5
2025-09-24 19:35:35.137534805+00:00,160,1,432669,A,A,64.82,2,26,8058566340906,128,18062,94299219,CLX5
2025-09-24 19:35:35.224138941+00:00,160,1,432669,C,B,64.8,2,26,8058566340892,128,15083,94299421,CLX5
2025-09-24 19:35:35.465290459+00:00,160,1,432669,M,A,64.94,1,26,8058565075241,128,14832,94299580,CLX5
2025-09-24 19:35:35.516247949+00:00,160,1,432669,A,A,65.7,6,26,8058566341057,128,18291,94299657,CLX5
2025-09-24 19:35:37.609360191+00:00,160,1,432669,A,B,64.54,8,26,8058566341136,128,18945,94299947,CLX5
2025-09-24 19:35:37.611194671+00:00,160,1,432669,M,A,64.93,1,26,8058565075241,128,14256,94300003,CLX5
2025-09-24 19:35:37.616304409+00:00,160,1,432669,C,A,65.7,6,26,8058566341057,128,17905,94300033,CLX5
2025-09-24 19:35:39.547830035+00:00,160,1,432669,M,B,64.75,1,26,8058566197138,128,18046,94300099,CLX5
2025-09-24 19:35:42.388976019+00:00,160,1,432669,M,A,64.94,1,26,8058565075241,128,15451,94300285,CLX5
2025-09-24 19:35:42.390790397+00:00,160,1,432669,A,B,64.81,1,26,8058566341228,128,18114,94300291,CLX5
2025-09-24 19:35:42.391039447+00:00,160,1,432669,C,A,64.82,2,26,8058566340906,128,15683,94300309,CLX5
2025-09-24 19:35:42.391078421+00:00,160,1,432669,A,B,64.81,1,26,8058566341232,128,14854,94300315,CLX5
2025-09-24 19:35:42.391333751+00:00,160,1,432669,M,A,65.97,4,26,8058566331622,128,15775,94300330,CLX5
2025-09-24 19:35:42.391355427+00:00,160,1,432669,M,B,64.8,3,26,8058566221991,128,14095,94300335,CLX5
2025-09-24 19:35:42.391732939+00:00,160,1,432669,A,B,64.81,1,26,8058566341236,128,14694,94300344,CLX5
2025-09-24 19:35:42.392185751+00:00,160,1,432669,M,B,64.8,1,26,8058566340051,128,18552,94300354,CLX5
2025-09-24 19:35:42.392348847+00:00,160,1,432669,A,B,64.79,1,26,8058566341239,128,18918,94300355,CLX5
2025-09-24 19:35:42.416266309+00:00,160,1,432669,A,A,65.7,6,26,8058566341243,128,18236,94300369,CLX5
2025-09-24 19:35:42.428440741+00:00,160,1,432669,T,A,64.81,1,26,8058566341246,0,18672,94300376,CLX5
2025-09-24 19:35:42.428440741+00:00,160,1,432669,F,B,64.81,1,26,8058566341228,0,18672,94300376,CLX5
2025-09-24 19:35:42.428440741+00:00,160,1,432669,C,B,64.81,1,26,8058566341228,128,14520,94300377,CLX5
2025-09-24 19:35:42.428727135+00:00,160,1,432669,C,B,64.81,1,26,8058566341236,128,17908,94300384,CLX5
2025-09-24 19:35:42.428744453+00:00,160,1,432669,A,A,64.82,2,26,8058566341247,128,15222,94300386,CLX5
2025-09-24 19:35:42.428777783+00:00,160,1,432669,M,A,64.82,1,26,8058566239191,128,15125,94300388,CLX5
2025-09-24 19:35:42.430299009+00:00,160,1,432669,M,A,64.93,1,26,8058565075241,128,14583,94300419,CLX5
2025-09-24 19:35:42.516250545+00:00,160,1,432669,C,A,65.7,6,26,8058566341243,128,18225,94300453,CLX5
2025-09-24 19:35:42.537627227+00:00,160,1,432669,M,A,65.14,1,26,8058566239191,128,18732,94300460,CLX5
2025-09-24 19:35:42.684165989+00:00,160,1,432669,M,A,64.94,1,26,8058565075241,128,16443,94300484,CLX5
2025-09-24 19:35:42.684338379+00:00,160,1,432669,M,A,64.82,1,26,8058566239191,128,15097,94300486,CLX5
2025-09-24 19:35:42.716235623+00:00,160,1,432669,A,A,65.7,6,26,8058566341282,128,19045,94300505,CLX5
2025-09-24 19:35:42.853881455+00:00,160,1,432669,A,B,64.81,1,26,8058566341287,128,19174,94300522,CLX5
2025-09-24 19:35:42.854088403+00:00,160,1,432669,M,A,65.14,1,26,8058566239191,128,15674,94300544,CLX5
2025-09-24 19:35:42.854162357+00:00,160,1,432669,C,A,64.82,2,26,8058566341247,128,15109,94300560,CLX5
2025-09-24 19:35:42.854171189+00:00,160,1,432669,A,B,64.81,1,26,8058566341296,128,14736,94300565,CLX5
2025-09-24 19:35:42.854821811+00:00,160,1,432669,A,B,64.81,1,26,8058566341305,128,18381,94300596,CLX5
2025-09-24 19:35:42.871787871+00:00,160,1,432669,A,B,64.81,1,26,8058566341357,128,18040,94300784,CLX5
2025-09-24 19:35:42.872007239+00:00,160,1,432669,A,B,64.81,2,26,8058566341365,128,14672,94300803,CLX5
2025-09-24 19:35:42.872147181+00:00,160,1,432669,A,B,64.81,2,26,8058566341366,128,16395,94300806,CLX5
2025-09-24 19:35:42.873718193+00:00,160,1,432669,C,B,64.81,2,26,8058566341366,128,16446,94300864,CLX5
2025-09-24 19:35:42.874344217+00:00,160,1,432669,C,B,64.81,2,26,8058566341365,128,15481,94300871,CLX5
2025-09-24 19:35:42.877323465+00:00,160,1,432669,C,A,64.82,1,26,8058566338676,128,18386,94300883,CLX5
2025-09-24 19:35:42.890092363+00:00,160,1,432669,C,B,64.81,1,26,8058566341287,128,18155,94300916,CLX5
2025-09-24 19:35:42.890141589+00:00,160,1,432669,A,A,64.82,2,26,8058566341386,128,13832,94300920,CLX5
2025-09-24 19:35:42.890328031+00:00,160,1,432669,C,B,64.81,1,26,8058566341357,128,15221,94300925,CLX5
2025-09-24 19:35:42.890438773+00:00,160,1,432669,C,B,64.81,1,26,8058566341305,128,15013,94300938,CLX5
2025-09-24 19:35:42.891782061+00:00,160,1,432669,M,A,64.93,1,26,8058565075241,128,14702,94300997,CLX5
2025-09-24 19:35:42.892027253+00:00,160,1,432669,A,B,64.81,1,26,8058566341409,128,14558,94301005,CLX5
2025-09-24 19:35:42.892097907+00:00,160,1,432669,A,B,64.81,2,26,8058566341410,128,16957,94301011,CLX5
2025-09-24 19:35:42.892273137+00:00,160,1,432669,C,A,64.82,2,26,8058566341386,128,15250,94301016,CLX5
2025-09-24 19:35:42.894102239+00:00,160,1,432669,M,A,64.94,1,26,8058565075241,128,18209,94301103,CLX5
2025-09-24 19:35:42.894165559+00:00,160,1,432669,C,B,64.81,1,26,8058566341409,128,17388,94301105,CLX5
2025-09-24 19:35:42.894930185+00:00,160,1,432669,A,A,64.82,1,26,8058566341439,128,15225,94301123,CLX5
2025-09-24 19:35:42.960823501+00:00,160,1,432669,M,A,64.93,1,26,8058565075241,128,17876,94301229,CLX5
2025-09-24 19:35:42.961195619+00:00,160,1,432669,A,B,64.81,1,26,8058566341496,128,21396,94301243,CLX5
2025-09-24 19:35:42.961201571+00:00,160,1,432669,A,B,64.81,1,26,8058566341497,128,17434,94301244,CLX5
2025-09-24 19:35:42.961516879+00:00,160,1,432669,M,A,64.94,1,26,8058565075241,128,14754,94301252,CLX5
2025-09-24 19:35:42.962459595+00:00,160,1,432669,A,B,64.81,2,26,8058566341513,128,17244,94301308,CLX5
2025-09-24 19:35:43.400009255+00:00,160,1,432669,C,B,64.81,1,26,8058566341232,128,19376,94301587,CLX5
2025-09-24 19:35:43.600109335+00:00,160,1,432669,T,A,64.81,1,26,8058566341645,0,18311,94301626,CLX5
2025-09-24 19:35:43.600109335+00:00,160,1,432669,F,B,64.81,1,26,8058566341296,0,18311,94301626,CLX5
2025-09-24 19:35:43.600109335+00:00,160,1,432669,C,B,64.81,1,26,8058566341296,128,17436,94301627,CLX5
2025-09-24 19:35:43.600413833+00:00,160,1,432669,C,B,64.81,2,26,8058566341513,128,15878,94301631,CLX5
2025-09-24 19:35:43.900145273+00:00,160,1,432669,A,B,64.81,1,26,8058566341665,128,22342,94301700,CLX5
2025-09-24 19:35:44.178052783+00:00,160,1,432669,C,B,64.81,1,26,8058566341497,128,21203,94301715,CLX5
2025-09-24 19:35:44.178251397+00:00,160,1,432669,T,A,64.81,1,26,8058566341678,0,18645,94301718,CLX5
2025-09-24 19:35:44.178251397+00:00,160,1,432669,F,B,64.81,1,26,8058566341410,0,18645,94301718,CLX5
2025-09-24 19:35:44.178251397+00:00,160,1,432669,M,B,64.81,1,26,8058566341410,128,14634,94301719,CLX5
2025-09-24 19:35:44.178516883+00:00,160,1,432669,A,A,64.82,2,26,8058566341681,128,14985,94301730,CLX5
2025-09-24 19:35:44.178727249+00:00,160,1,432669,C,B,64.81,1,26,8058566341496,128,14743,94301740,CLX5
2025-09-24 19:35:44.179668909+00:00,160,1,432669,C,A,64.82,2,26,8058566341681,128,15965,94301763,CLX5
2025-09-24 19:35:44.179817761+00:00,160,1,432669,A,B,64.81,1,26,8058566341690,128,18375,94301764,CLX5
2025-09-24 19:35:44.179960047+00:00,160,1,432669,A,B,64.81,1,26,8058566341691,128,21219,94301767,CLX5
2025-09-24 19:35:45.046542773+00:00,160,1,432669,A,A,64.82,2,26,8058566341710,128,15226,94301836,CLX5
2025-09-24 19:35:45.046711593+00:00,160,1,432669,C,B,64.81,1,26,8058566341691,128,18027,94301837,CLX5
2025-09-24 19:35:45.046736415+00:00,160,1,432669,T,A,64.81,1,26,8058566341711,0,17917,94301839,CLX5
2025-09-24 19:35:45.046736415+00:00,160,1,432669,F,B,64.81,1,26,8058566341410,0,17917,94301839,CLX5
2025-09-24 19:35:45.046736415+00:00,160,1,432669,C,B,64.81,1,26,8058566341410,128,14528,94301840,CLX5
2025-09-24 19:35:45.046974755+00:00,160,1,432669,C,B,64.81,1,26,8058566341690,128,18204,94301847,CLX5
2025-09-24 19:35:45.048038541+00:00,160,1,432669,C,A,64.82,2,26,8058566341710,128,18421,94301875,CLX5
2025-09-24 19:35:45.081767919+00:00,160,1,432669,C,A,64.84,1,26,8058566316078,128,18233,94301879,CLX5
2025-09-24 19:35:45.106544331+00:00,160,1,432669,A,B,64.81,2,26,8058566341721,128,14774,94301884,CLX5
2025-09-24 19:35:45.106571671+00:00,160,1,432669,A,B,64.81,1,26,8058566341722,128,16024,94301886,CLX5
2025-09-24 19:35:45.107306057+00:00,160,1,432669,A,B,64.81,1,26,8058566341723,128,22830,94301890,CLX5
2025-09-24 19:35:45.107449015+00:00,160,1,432669,A,B,64.81,1,26,8058566341724,128,19249,94301891,CLX5
2025-09-24 19:35:45.157031537+00:00,160,1,432669,A,A,64.82,1,26,8058566341727,128,18794,94301897,CLX5
2025-09-24 19:35:45.157179313+00:00,160,1,432669,C,B,64.81,1,26,8058566341722,128,20502,94301898,CLX5
2025-09-24 19:35:45.390073297+00:00,160,1,432669,M,B,64.79,1,26,8058566197138,128,17705,94301910,CLX5
2025-09-24 19:35:45.672949723+00:00,160,1,432669,C,B,64.81,1,26,8058566341723,128,23078,94301916,CLX5
2025-09-24 19:35:45.672966081+00:00,160,1,432669,C,B,64.81,1,26,8058566341724,128,19392,94301920,CLX5
2025-09-24 19:35:45.673032739+00:00,160,1,432669,A,A,64.82,2,26,8058566341732,128,18133,94301937,CLX5
2025-09-24 19:35:45.673107403+00:00,160,1,432669,C,B,64.81,2,26,8058566341721,128,20152,94301939,CLX5
2025-09-24 19:35:45.673592009+00:00,160,1,432669,C,A,64.82,2,26,8058566341732,128,14560,94301969,CLX5
2025-09-24 19:35:45.674855487+00:00,160,1,432669,M,A,64.93,1,26,8058565075241,128,15135,94302000,CLX5
2025-09-24 19:35:45.677031059+00:00,160,1,432669,A,B,64.81,1,26,8058566341766,128,14766,94302088,CLX5
2025-09-24 19:35:45.677031235+00:00,160,1,432669,A,B,64.81,1,26,8058566341767,128,18281,94302091,CLX5
2025-09-24 19:35:45.677061547+00:00,160,1,432669,M,A,64.94,1,26,8058565075241,128,13656,94302095,CLX5
2025-09-24 19:35:45.677361285+00:00,160,1,432669,A,B,64.81,1,26,8058566341769,128,18663,94302111,CLX5
2025-09-24 19:35:45.706814397+00:00,160,1,432669,C,B,64.81,1,26,8058566341769,128,17855,94302135,CLX5
2025-09-24 19:35:45.706959349+00:00,160,1,432669,C,B,64.81,1,26,8058566341767,128,18122,94302138,CLX5
2025-09-24 19:35:46.789302705+00:00,160,1,432669,T,A,64.81,1,26,8058566341821,0,18321,94302243,CLX5
2025-09-24 19:35:46.789302705+00:00,160,1,432669,F,B,64.81,1,26,8058566341665,0,18321,94302243,CLX5
2025-09-24 19:35:46.789302705+00:00,160,1,432669,C,B,64.81,1,26,8058566341665,128,16792,94302244,CLX5
2025-09-24 19:35:46.789599159+00:00,160,1,432669,C,B,64.81,1,26,8058566341766,128,18604,94302247,CLX5
2025-09-24 19:35:46.789797023+00:00,160,1,432669,C,B,64.79,1,26,8058566341239,128,15193,94302253,CLX5
2025-09-24 19:35:46.789996503+00:00,160,1,432669,A,A,64.82,2,26,8058566341826,128,19118,94302260,CLX5
2025-09-24 19:35:46.790039913+00:00,160,1,432669,M,B,63.64,3,26,8058566221991,128,15690,94302261,CLX5
2025-09-24 19:35:46.790165667+00:00,160,1,432669,A,A,64.82,1,26,8058566341828,128,14939,94302268,CLX5
2025-09-24 19:35:46.790205871+00:00,160,1,432669,A,A,64.82,1,26,8058566341829,128,18024,94302269,CLX5
2025-09-24 19:35:46.790430615+00:00,160,1,432669,A,A,64.82,1,26,8058566341830,128,15217,94302279,CLX5
2025-09-24 19:35:46.816612999+00:00,160,1,432669,C,A,65.7,6,26,8058566341282,128,18680,94302294,CLX5
2025-09-24 19:35:46.816741289+00:00,160,1,432669,C,A,64.82,1,26,8058566341830,128,19144,94302295,CLX5
2025-09-24 19:35:46.816750927+00:00,160,1,432669,C,A,64.82,1,26,8058566341829,128,15121,94302296,CLX5
2025-09-24 19:35:46.816752731+00:00,160,1,432669,C,A,64.82,1,26,8058566341828,128,15626,94302297,CLX5
2025-09-24 19:35:47.966741107+00:00,160,1,432669,C,A,64.82,2,26,8058566341826,128,18027,94302332,CLX5
2025-09-24 19:35:47.966756581+00:00,160,1,432669,A,B,64.8,2,26,8058566341844,128,14818,94302333,CLX5
2025-09-24 19:35:47.967042033+00:00,160,1,432669,C,B,64.8,2,26,8058566341844,128,18136,94302334,CLX5
2025-09-24 19:35:47.967086979+00:00,160,1,432669,A,A,64.82,2,26,8058566341845,128,15224,94302335,CLX5
2025-09-24 19:35:47.967113187+00:00,160,1,432669,M,B,64.8,3,26,8058566221991,128,13898,94302336,CLX5
2025-09-24 19:35:47.989271621+00:00,160,1,432669,C,A,64.82,1,26,8058566341439,128,19229,94302340,CLX5
2025-09-24 19:35:48.006890491+00:00,160,1,432669,T,A,64.81,1,26,8058566341850,128,18851,94302346,CLX5
2025-09-24 19:35:48.016867139+00:00,160,1,432669,T,A,64.81,1,26,8058566341852,0,18774,94302355,CLX5
2025-09-24 19:35:48.016867139+00:00,160,1,432669,A,A,64.81,1,26,8058566341852,128,14699,94302356,CLX5
2025-09-24 19:35:48.017541643+00:00,160,1,432669,M,A,65.98,3,26,8058566321460,128,14863,94302382,CLX5
2025-09-24 19:35:48.201445321+00:00,160,1,432669,M,A,64.83,3,26,8058566321460,128,17783,94302407,CLX5
2025-09-24 19:35:54.297185753+00:00,160,1,432669,C,B,64.67,1,26,8058564139889,128,18952,94303077,CLX5
2025-09-24 19:35:55.378005547+00:00,160,1,432669,C,A,64.82,1,26,8058566339448,128,21330,94303084,CLX5
2025-09-24 19:35:55.378193295+00:00,160,1,432669,T,B,64.81,1,26,8058566342099,0,18042,94303085,CLX5
2025-09-24 19:35:55.378193295+00:00,160,1,432669,F,A,64.81,1,26,8058566341852,0,18042,94303085,CLX5
2025-09-24 19:35:55.378193295+00:00,160,1,432669,C,A,64.81,1,26,8058566341852,128,16980,94303086,CLX5
2025-09-24 19:35:55.378829999+00:00,160,1,432669,M,A,64.84,4,26,8058566331622,128,19022,94303110,CLX5
2025-09-24 19:35:55.379045431+00:00,160,1,432669,A,B,64.8,1,26,8058566342106,128,18839,94303121,CLX5
2025-09-24 19:35:55.379166097+00:00,160,1,432669,A,B,64.8,1,26,8058566342108,128,15181,94303123,CLX5
2025-09-24 19:35:55.379401557+00:00,160,1,432669,A,B,64.8,1,26,8058566342109,128,18135,94303125,CLX5
2025-09-24 19:35:55.416340363+00:00,160,1,432669,A,A,65.7,6,26,8058566342111,128,18727,94303134,CLX5
2025-09-24 19:35:55.451767389+00:00,160,1,432669,C,B,64.8,1,26,8058566342109,128,15061,94303157,CLX5
2025-09-24 19:35:55.451779389+00:00,160,1,432669,C,B,64.8,1,26,8058566342108,128,18686,94303158,CLX5
2025-09-24 19:35:55.451924935+00:00,160,1,432669,C,B,64.8,1,26,8058566342106,128,18083,94303159,CLX5
2025-09-24 19:35:55.616307317+00:00,160,1,432669,C,A,65.7,6,26,8058566342111,128,18844,94303164,CLX5
2025-09-24 19:35:57.423333575+00:00,160,1,432669,A,A,64.82,1,26,8058566342118,128,18445,94303170,CLX5
2025-09-24 19:35:58.961285303+00:00,160,1,432669,A,A,64.81,1,26,8058566342123,128,18884,94303188,CLX5
2025-09-24 19:35:58.961519225+00:00,160,1,432669,A,A,64.82,1,26,8058566342124,128,18748,94303191,CLX5
2025-09-24 19:35:58.962129315+00:00,160,1,432669,A,A,64.81,1,26,8058566342126,128,18191,94303199,CLX5
2025-09-24 19:35:58.962129493+00:00,160,1,432669,A,A,64.81,1,26,8058566342127,128,15246,94303201,CLX5
2025-09-24 19:35:58.962170365+00:00,160,1,432669,M,A,65.97,3,26,8058566331622,128,14580,94303206,CLX5
2025-09-24 19:35:58.962430569+00:00,160,1,432669,C,A,64.81,1,26,8058566342127,128,13607,94303219,CLX5
2025-09-24 19:35:58.962588733+00:00,160,1,432669,C,A,64.81,1,26,8058566342126,128,17977,94303223,CLX5
2025-09-24 19:35:58.962624653+00:00,160,1,432669,C,A,64.81,1,26,8058566342123,128,15337,94303225,CLX5
2025-09-24 19:35:58.963300831+00:00,160,1,432669,M,A,64.84,4,26,8058566331102,128,18712,94303233,CLX5
2025-09-24 19:35:58.963601105+00:00,160,1,432669,M,A,64.93,1,26,8058565075241,128,17146,94303244,CLX5
2025-09-24 19:35:58.963629749+00:00,160,1,432669,M,B,63.64,3,26,8058566221991,128,18267,94303247,CLX5
2025-09-24 19:35:58.978081949+00:00,160,1,432669,A,A,65.96,4,26,8058566342145,128,18303,94303275,CLX5
2025-09-24 19:35:59.064787687+00:00,160,1,432669,M,A,64.94,1,26,8058565075241,128,14885,94303300,CLX5
2025-09-24 19:35:59.715514123+00:00,160,1,432669,A,B,64.78,1,26,8058566342164,128,20242,94303346,CLX5
2025-09-24 19:35:59.779890343+00:00,160,1,432669,M,B,64.75,1,26,8058566197138,128,18800,94303347,CLX5
2025-09-24 19:36:00.024788961+00:00,160,1,432669,A,B,64.8,1,26,8058566342166,128,18883,94303350,CLX5
2025-09-24 19:36:00.024959045+00:00,160,1,432669,C,A,64.82,1,26,8058566342124,128,18535,94303351,CLX5
2025-09-24 19:36:02.690834215+00:00,160,1,432669,A,A,64.82,1,26,8058566342307,128,22338,94303694,CLX5
2025-09-24 19:36:03.046763243+00:00,160,1,432669,A,B,64.81,1,26,8058566342310,128,22080,94303700,CLX5
2025-09-24 19:36:03.046768657+00:00,160,1,432669,C,A,64.82,1,26,8058566342307,128,17680,94303702,CLX5
2025-09-24 19:36:03.047055071+00:00,160,1,432669,A,B,64.81,1,26,8058566342313,128,17159,94303709,CLX5
2025-09-24 19:36:03.047079375+00:00,160,1,432669,C,A,64.82,2,26,8058566341845,128,16404,94303711,CLX5
2025-09-24 19:36:03.047101263+00:00,160,1,432669,A,B,64.81,1,26,8058566342315,128,17329,94303714,CLX5
2025-09-24 19:36:03.047355807+00:00,160,1,432669,M,A,65.98,4,26,8058566321460,128,18447,94303727,CLX5
2025-09-24 19:36:03.047460173+00:00,160,1,432669,C,B,64.8,1,26,8058566342166,128,15142,94303728,CLX5
2025-09-24 19:36:03.047544053+00:00,160,1,432669,M,B,64.8,3,26,8058566221991,128,14828,94303729,CLX5
2025-09-24 19:36:03.047707265+00:00,160,1,432669,A,B,64.8,1,26,8058566342317,128,17970,94303731,CLX5
2025-09-24 19:36:03.048175859+00:00,160,1,432669,A,B,64.81,1,26,8058566342318,128,22921,94303732,CLX5
2025-09-24 19:36:03.080346191+00:00,160,1,432669,T,A,64.81,1,26,8058566342330,0,18720,94303762,CLX5
2025-09-24 19:36:03.080346191+00:00,160,1,432669,F,B,64.81,1,26,8058566342310,0,18720,94303762,CLX5
2025-09-24 19:36:03.080346191+00:00,160,1,432669,C,B,64.81,1,26,8058566342310,128,14749,94303763,CLX5
2025-09-24 19:36:03.080669409+00:00,160,1,432669,A,A,64.82,2,26,8058566342331,128,18668,94303765,CLX5
2025-09-24 19:36:03.728236491+00:00,160,1,432669,A,B,64.81,1,26,8058566342375,128,21838,94303904,CLX5
2025-09-24 19:36:03.728437985+00:00,160,1,432669,C,A,64.82,2,26,8058566342331,128,18956,94303905,CLX5
2025-09-24 19:36:03.728470009+00:00,160,1,432669,C,B,64.8,1,26,8058566342317,128,15007,94303906,CLX5
2025-09-24 19:36:04.089366839+00:00,160,1,432669,T,A,64.81,3,26,8058566342386,0,19649,94303921,CLX5
2025-09-24 19:36:04.089366839+00:00,160,1,432669,F,B,64.81,1,26,8058566342315,0,19649,94303921,CLX5
2025-09-24 19:36:04.089366839+00:00,160,1,432669,F,B,64.81,1,26,8058566342318,0,19649,94303921,CLX5
2025-09-24 19:36:04.089366839+00:00,160,1,432669,F,B,64.81,1,26,8058566342375,0,19649,94303921,CLX5
2025-09-24 19:36:04.089366839+00:00,160,1,432669,C,B,64.81,1,26,8058566342315,0,14807,94303922,CLX5
2025-09-24 19:36:04.089366839+00:00,160,1,432669,C,B,64.81,1,26,8058566342318,0,14807,94303922,CLX5
2025-09-24 19:36:04.089366839+00:00,160,1,432669,C,B,64.81,1,26,8058566342375,0,14807,94303922,CLX5
2025-09-24 19:36:04.089366839+00:00,160,1,432669,C,B,64.81,1,26,8058566342313,128,14807,94303922,CLX5
2025-09-24 19:36:04.089392201+00:00,160,1,432669,A,A,64.82,1,26,8058566342390,128,18064,94303931,CLX5
2025-09-24 19:36:04.089397713+00:00,160,1,432669,A,A,64.81,2,26,8058566342398,128,18014,94303949,CLX5
2025-09-24 19:36:04.089421077+00:00,160,1,432669,A,A,64.81,1,26,8058566342403,128,18004,94303963,CLX5
2025-09-24 19:36:04.089473759+00:00,160,1,432669,A,A,64.82,2,26,8058566342405,128,14319,94303971,CLX5
2025-09-24 19:36:04.089487373+00:00,160,1,432669,A,A,64.81,2,26,8058566342407,128,14529,94303972,CLX5
2025-09-24 19:36:04.089771729+00:00,160,1,432669,C,A,64.81,1,26,8058566342403,128,21500,94303998,CLX5
2025-09-24 19:36:04.089915147+00:00,160,1,432669,M,A,64.93,1,26,8058565075241,128,14708,94304014,CLX5
2025-09-24 19:36:04.090053075+00:00,160,1,432669,M,B,63.64,3,26,8058566221991,128,18648,94304018,CLX5
2025-09-24 19:36:04.090169287+00:00,160,1,432669,A,A,64.82,1,26,8058566342425,128,14176,94304022,CLX5
2025-09-24 19:36:04.090333977+00:00,160,1,432669,C,A,64.81,2,26,8058566342407,128,14706,94304034,CLX5
2025-09-24 19:36:04.090565441+00:00,160,1,432669,T,B,64.81,1,26,8058566342430,0,16817,94304057,CLX5
2025-09-24 19:36:04.090565441+00:00,160,1,432669,F,A,64.81,1,26,8058566342398,0,16817,94304057,CLX5
2025-09-24 19:36:04.090565441+00:00,160,1,432669,M,A,64.81,1,26,8058566342398,128,14538,94304058,CLX5
2025-09-24 19:36:04.090565623+00:00,160,1,432669,T,B,64.81,1,26,8058566342431,0,14637,94304061,CLX5
2025-09-24 19:36:04.090565623+00:00,160,1,432669,F,A,64.81,1,26,8058566342398,0,14637,94304061,CLX5
2025-09-24 19:36:04.090565623+00:00,160,1,432669,C,A,64.81,1,26,8058566342398,128,14637,94304061,CLX5
2025-09-24 19:36:04.090879771+00:00,160,1,432669,M,A,64.83,3,26,8058566321460,128,14041,94304084,CLX5
2025-09-24 19:36:04.091034081+00:00,160,1,432669,C,A,64.82,1,26,8058566342390,128,15119,94304091,CLX5
2025-09-24 19:36:04.091754465+00:00,160,1,432669,A,B,64.81,1,26,8058566342454,128,14504,94304121,CLX5
2025-09-24 19:36:04.091880259+00:00,160,1,432669,A,B,64.81,1,26,8058566342459,128,14739,94304130,CLX5
2025-09-24 19:36:04.091897459+00:00,160,1,432669,M,A,64.94,1,26,8058565075241,128,14868,94304134,CLX5
2025-09-24 19:36:04.092032621+00:00,160,1,432669,A,B,64.81,1,26,8058566342461,128,14733,94304137,CLX5
2025-09-24 19:36:04.093308561+00:00,160,1,432669,A,B,64.77,1,26,8058566342468,128,18150,94304156,CLX5
2025-09-24 19:36:04.093379751+00:00,160,1,432669,C,A,64.82,2,26,8058566342405,128,15155,94304161,CLX5
2025-09-24 19:36:04.094878495+00:00,160,1,432669,A,B,64.81,1,26,8058566342476,128,24074,94304187,CLX5
2025-09-24 19:36:04.095107847+00:00,160,1,432669,M,A,65.98,4,26,8058566321460,128,14666,94304200,CLX5
2025-09-24 19:36:04.165367839+00:00,160,1,432669,C,B,64.77,1,26,8058566342468,128,16662,94304400,CLX5
2025-09-24 19:36:04.178419115+00:00,160,1,432669,C,B,64.81,1,26,8058566342476,128,24365,94304405,CLX5
2025-09-24 19:36:04.280255609+00:00,160,1,432669,C,B,64.8,1,26,8058566339497,128,18627,94304451,CLX5
2025-09-24 19:36:04.652892087+00:00,160,1,432669,C,A,65.01,1,26,8058566333574,128,17935,94304649,CLX5
2025-09-24 19:36:04.746674153+00:00,160,1,432669,A,A,64.99,1,26,8058566342642,128,18361,94304683,CLX5
2025-09-24 19:36:05.788006095+00:00,160,1,432669,M,B,64.79,1,26,8058566197138,128,18334,94304852,CLX5
2025-09-24 19:36:06.008485079+00:00,160,1,432669,T,A,64.81,1,26,8058566342710,0,19217,94304855,CLX5
2025-09-24 19:36:06.008485079+00:00,160,1,432669,F,B,64.81,1,26,8058566342454,0,19217,94304855,CLX5
2025-09-24 19:36:06.008485079+00:00,160,1,432669,C,B,64.81,1,26,8058566342454,128,16403,94304856,CLX5
2025-09-24 19:36:07.250079341+00:00,160,1,432669,T,A,64.81,1,26,8058566342718,0,20092,94304868,CLX5
2025-09-24 19:36:07.250079341+00:00,160,1,432669,F,B,64.81,1,26,8058566342459,0,20092,94304868,CLX5
2025-09-24 19:36:07.250079341+00:00,160,1,432669,C,B,64.81,1,26,8058566342459,128,14554,94304869,CLX5
2025-09-24 19:36:07.284193145+00:00,160,1,432669,T,A,64.81,1,26,8058566342719,0,19186,94304872,CLX5
2025-09-24 19:36:07.284193145+00:00,160,1,432669,F,B,64.81,1,26,8058566342461,0,19186,94304872,CLX5
2025-09-24 19:36:07.284193145+00:00,160,1,432669,C,B,64.81,1,26,8058566342461,128,16755,94304873,CLX5
2025-09-24 19:36:07.284887809+00:00,160,1,432669,A,A,64.82,2,26,8058566342729,128,18278,94304895,CLX5
2025-09-24 19:36:07.404463379+00:00,160,1,432669,A,B,64.81,1,26,8058566342739,128,18142,94304923,CLX5
2025-09-24 19:36:07.404717305+00:00,160,1,432669,C,A,64.82,2,26,8058566342729,128,16817,94304928,CLX5
2025-09-24 19:36:08.638723793+00:00,160,1,432669,A,B,64.8,1,26,8058566342783,128,22417,94305058,CLX5
2025-09-24 19:36:08.639041769+00:00,160,1,432669,M,B,64.8,3,26,8058566221991,128,20293,94305059,CLX5
2025-09-24 19:36:10.059998673+00:00,160,1,432669,A,B,64.81,1,26,8058566342788,128,16564,94305076,CLX5
2025-09-24 19:36:10.060269533+00:00,160,1,432669,A,B,64.81,1,26,8058566342790,128,21218,94305083,CLX5
2025-09-24 19:36:10.060324463+00:00,160,1,432669,A,B,64.81,2,26,8058566342791,128,17702,94305089,CLX5
2025-09-24 19:36:10.060367949+00:00,160,1,432669,T,A,64.81,1,26,8058566342792,0,17654,94305091,CLX5
2025-09-24 19:36:10.060367949+00:00,160,1,432669,F,B,64.81,1,26,8058566342739,0,17654,94305091,CLX5
2025-09-24 19:36:10.060367949+00:00,160,1,432669,C,B,64.81,1,26,8058566342739,128,17654,94305091,CLX5
2025-09-24 19:36:10.116501223+00:00,160,1,432669,A,A,65.7,6,26,8058566342860,128,18114,94305310,CLX5
2025-09-24 19:36:11.593774185+00:00,160,1,432669,T,A,64.81,1,26,8058566342912,0,17788,94305461,CLX5
2025-09-24 19:36:11.593774185+00:00,160,1,432669,F,B,64.81,1,26,8058566342788,0,17788,94305461,CLX5
2025-09-24 19:36:11.593774185+00:00,160,1,432669,C,B,64.81,1,26,8058566342788,128,14702,94305462,CLX5
2025-09-24 19:36:11.783082635+00:00,160,1,432669,A,B,64.81,2,26,8058566342945,128,17582,94305568,CLX5
2025-09-24 19:36:12.064154937+00:00,160,1,432669,C,B,64.81,2,26,8058566342945,128,22261,94305646,CLX5
2025-09-24 19:36:12.724923683+00:00,160,1,432669,A,B,64.76,35,26,8058566342993,128,18594,94305668,CLX5
2025-09-24 19:36:12.725092713+00:00,160,1,432669,A,B,64.81,2,26,8058566342994,128,22698,94305669,CLX5
2025-09-24 19:36:12.725109781+00:00,160,1,432669,A,B,64.81,2,26,8058566342995,128,16503,94305670,CLX5
2025-09-24 19:36:12.725243561+00:00,160,1,432669,A,B,64.81,1,26,8058566342996,128,19282,94305671,CLX5
2025-09-24 19:36:12.725273357+00:00,160,1,432669,C,A,64.82,1,26,8058566338004,128,15060,94305674,CLX5
2025-09-24 19:36:12.725275161+00:00,160,1,432669,A,B,64.81,1,26,8058566342997,128,18828,94305676,CLX5
2025-09-24 19:36:12.725376169+00:00,160,1,432669,A,B,64.81,1,26,8058566342999,128,15857,94305680,CLX5
2025-09-24 19:36:12.726255125+00:00,160,1,432669,C,A,64.82,1,26,8058566338002,128,19432,94305758,CLX5
2025-09-24 19:36:12.726258331+00:00,160,1,432669,A,B,64.81,1,26,8058566343019,128,15505,94305759,CLX5
2025-09-24 19:36:12.726258987+00:00,160,1,432669,A,B,64.81,1,26,8058566343021,128,15298,94305762,CLX5
2025-09-24 19:36:12.726259271+00:00,160,1,432669,A,B,64.81,1,26,8058566343022,128,15153,94305764,CLX5
2025-09-24 19:36:12.726260367+00:00,160,1,432669,C,A,64.85,2,26,8058566338063,128,14809,94305765,CLX5
2025-09-24 19:36:12.726280103+00:00,160,1,432669,A,B,64.81,1,26,8058566343024,128,15152,94305769,CLX5
2025-09-24 19:36:12.726430951+00:00,160,1,432669,A,B,64.81,2,26,8058566343029,128,15600,94305786,CLX5
2025-09-24 19:36:12.726602937+00:00,160,1,432669,A,B,64.8,2,26,8058566343037,128,18348,94305813,CLX5
2025-09-24 19:36:12.726608679+00:00,160,1,432669,C,A,64.82,3,26,8058566335916,128,18798,94305818,CLX5
2025-09-24 19:36:12.727207191+00:00,160,1,432669,C,B,64.81,1,26,8058566343019,128,15433,94305836,CLX5
2025-09-24 19:36:12.727223799+00:00,160,1,432669,C,B,64.81,1,26,8058566343022,128,18459,94305840,CLX5
2025-09-24 19:36:12.727273371+00:00,160,1,432669,C,B,64.8,2,26,8058566343037,128,16057,94305841,CLX5
2025-09-24 19:36:12.727360363+00:00,160,1,432669,A,A,64.82,1,26,8058566343048,128,15330,94305848,CLX5
2025-09-24 19:36:12.727379447+00:00,160,1,432669,A,B,64.81,1,26,8058566343049,128,19366,94305850,CLX5
2025-09-24 19:36:12.727384267+00:00,160,1,432669,C,A,64.82,1,26,8058566343048,128,15388,94305851,CLX5
2025-09-24 19:36:12.727474483+00:00,160,1,432669,C,A,64.82,1,26,8058566337966,128,18057,94305853,CLX5
2025-09-24 19:36:12.727593709+00:00,160,1,432669,A,B,64.81,1,26,8058566343050,128,14902,94305855,CLX5
2025-09-24 19:36:12.727629363+00:00,160,1,432669,C,B,64.81,1,26,8058566343050,128,18276,94305856,CLX5
2025-09-24 19:36:12.727781975+00:00,160,1,432669,A,A,64.82,1,26,8058566343051,128,15324,94305857,CLX5
2025-09-24 19:36:12.727815653+00:00,160,1,432669,C,A,64.82,1,26,8058566343051,128,15074,94305859,CLX5
2025-09-24 19:36:12.728814889+00:00,160,1,432669,T,B,64.82,3,26,8058566343060,0,14754,94305897,CLX5
2025-09-24 19:36:12.728814889+00:00,160,1,432669,F,A,64.82,2,26,8058566335813,0,14754,94305897,CLX5
2025-09-24 19:36:12.728814889+00:00,160,1,432669,F,A,64.82,1,26,8058566335826,0,14754,94305897,CLX5
2025-09-24 19:36:12.728814889+00:00,160,1,432669,C,A,64.82,2,26,8058566335813,0,14754,94305897,CLX5
2025-09-24 19:36:12.728814889+00:00,160,1,432669,C,A,64.82,1,26,8058566335826,128,14754,94305897,CLX5
2025-09-24 19:36:12.729005173+00:00,160,1,432669,M,B,64.81,2,26,8058566319851,128,15007,94305918,CLX5
2025-09-24 19:36:12.729092525+00:00,160,1,432669,C,A,64.82,2,26,8058566335833,128,16161,94305924,CLX5
2025-09-24 19:36:12.729101591+00:00,160,1,432669,A,B,64.81,1,26,8058566343069,128,15131,94305938,CLX5
2025-09-24 19:36:12.729104241+00:00,160,1,432669,A,B,64.81,1,26,8058566343070,128,18666,94305940,CLX5
2025-09-24 19:36:12.729505177+00:00,160,1,432669,A,A,64.83,1,26,8058566343075,128,16787,94305961,CLX5
2025-09-24 19:36:12.729747357+00:00,160,1,432669,C,A,64.85,1,26,8058566336056,128,14592,94305965,CLX5
2025-09-24 19:36:12.730504379+00:00,160,1,432669,C,B,64.81,1,26,8058566343070,128,14609,94306012,CLX5
2025-09-24 19:36:12.731364693+00:00,160,1,432669,C,B,64.81,1,26,8058566343069,128,19138,94306070,CLX5
2025-09-24 19:36:12.733851137+00:00,160,1,432669,M,A,64.83,1,26,8058566331891,128,17258,94306205,CLX5
2025-09-24 19:36:12.741954233+00:00,160,1,432669,A,B,64.81,1,26,8058566343148,128,17875,94306336,CLX5
2025-09-24 19:36:12.742112031+00:00,160,1,432669,A,B,64.81,1,26,8058566343150,128,14712,94306339,CLX5
2025-09-24 19:36:12.776404253+00:00,160,1,432669,C,B,64.71,1,26,8058566339705,128,19591,94306368,CLX5
2025-09-24 19:36:12.777039401+00:00,160,1,432669,A,B,64.8,2,26,8058566343166,128,18849,94306369,CLX5
2025-09-24 19:36:12.791829277+00:00,160,1,432669,C,B,64.8,2,26,8058566343166,128,15014,94306427,CLX5
2025-09-24 19:36:12.792004103+00:00,160,1,432669,A,B,64.81,1,26,8058566343184,128,14743,94306437,CLX5
2025-09-24 19:36:12.811172903+00:00,160,1,432669,A,A,64.87,2,26,8058566343201,128,18634,94306464,CLX5
2025-09-24 19:36:12.816720921+00:00,160,1,432669,A,A,65.9,1,26,8058566343202,128,17827,94306465,CLX5
2025-09-24 19:36:12.910840391+00:00,160,1,432669,A,B,64.77,2,26,8058566343229,128,18886,94306534,CLX5
2025-09-24 19:36:12.927025911+00:00,160,1,432669,A,B,64.8,2,26,8058566343232,128,18141,94306539,CLX5
2025-09-24 19:36:12.927030441+00:00,160,1,432669,C,B,64.77,2,26,8058566343229,128,13809,94306542,CLX5
2025-09-24 19:36:12.927251999+00:00,160,1,432669,C,B,64.81,1,26,8058566343184,128,14914,94306547,CLX5
2025-09-24 19:36:13.010812031+00:00,160,1,432669,C,B,64.78,2,26,8058566337984,128,18475,94306573,CLX5
2025-09-24 19:36:13.010985901+00:00,160,1,432669,C,B,64.78,1,26,8058566342164,128,17698,94306574,CLX5
2025-09-24 19:36:13.542564217+00:00,160,1,432669,C,B,64.81,1,26,8058566343150,128,17872,94306586,CLX5
2025-09-24 19:36:13.542571935+00:00,160,1,432669,C,B,64.81,1,26,8058566343148,128,14921,94306587,CLX5
2025-09-24 19:36:17.527125383+00:00,160,1,432669,M,A,64.95,1,26,8058565075241,128,14879,94306759,CLX5
2025-09-24 19:36:17.527747917+00:00,160,1,432669,M,B,64.79,3,26,8058566335785,128,14832,94306778,CLX5
2025-09-24 19:36:17.638270451+00:00,160,1,432669,M,A,64.94,1,26,8058565075241,128,14176,94306804,CLX5
2025-09-24 19:36:18.046090371+00:00,160,1,432669,M,A,64.95,1,26,8058565075241,128,18689,94307149,CLX5
2025-09-24 19:36:18.048466421+00:00,160,1,432669,C,A,64.82,3,26,8058566337340,128,20413,94307269,CLX5
2025-09-24 19:36:18.056008653+00:00,160,1,432669,M,A,64.94,1,26,8058565075241,128,16231,94307523,CLX5
2025-09-24 19:36:18.056902701+00:00,160,1,432669,M,B,64.81,1,26,8058566337316,128,15834,94307574,CLX5
2025-09-24 19:36:18.058095007+00:00,160,1,432669,M,A,64.95,1,26,8058565075241,128,15610,94307631,CLX5
2025-09-24 19:36:18.077509901+00:00,160,1,432669,M,A,64.94,1,26,8058565075241,128,14258,94307866,CLX5
2025-09-24 19:36:18.079660551+00:00,160,1,432669,M,A,64.82,1,26,8058566331891,128,21158,94307890,CLX5
2025-09-24 19:36:18.083181465+00:00,160,1,432669,A,A,64.82,1,26,8058566343791,128,20417,94307922,CLX5
2025-09-24 19:36:18.083785719+00:00,160,1,432669,C,A,64.82,1,26,8058566343791,128,19367,94307938,CLX5
2025-09-24 19:36:18.162994955+00:00,160,1,432669,M,A,64.83,1,26,8058566331891,128,20804,94308024,CLX5
2025-09-24 19:36:22.496647629+00:00,160,1,432669,A,A,64.82,1,26,8058566343993,128,21375,94308303,CLX5
2025-09-24 19:36:24.051123009+00:00,160,1,432669,C,B,64.78,1,26,8058566338999,128,21764,94308342,CLX5
2025-09-24 19:36:29.718392195+00:00,160,1,432669,A,A,64.82,2,26,8058566344015,128,22495,94308425,CLX5
2025-09-24 19:36:29.718460371+00:00,160,1,432669,A,A,64.82,1,26,8058566344016,128,16097,94308426,CLX5
2025-09-24 19:36:29.718717005+00:00,160,1,432669,A,A,64.82,1,26,8058566344020,128,15790,94308435,CLX5
2025-09-24 19:36:29.757577089+00:00,160,1,432669,M,B,64.71,35,26,8058566342993,128,19423,94308448,CLX5
2025-09-24 19:36:29.759047381+00:00,160,1,432669,C,A,64.82,1,26,8058566344020,128,19384,94308451,CLX5
2025-09-24 19:36:31.100962975+00:00,160,1,432669,A,A,64.85,1,26,8058566344029,128,14515,94308463,CLX5
2025-09-24 19:36:31.100964665+00:00,160,1,432669,C,B,64.81,1,26,8058566343049,128,18298,94308464,CLX5
2025-09-24 19:36:31.100978085+00:00,160,1,432669,A,A,64.82,1,26,8058566344031,128,16247,94308466,CLX5
2025-09-24 19:36:31.101205153+00:00,160,1,432669,A,A,64.82,1,26,8058566344032,128,17874,94308480,CLX5
2025-09-24 19:36:31.101207669+00:00,160,1,432669,A,A,64.82,2,26,8058566344033,128,15560,94308482,CLX5
2025-09-24 19:36:31.101546535+00:00,160,1,432669,A,A,64.82,1,26,8058566344036,128,15730,94308491,CLX5
2025-09-24 19:36:31.101552447+00:00,160,1,432669,A,A,64.82,1,26,8058566344038,128,15775,94308494,CLX5
2025-09-24 19:36:31.101552811+00:00,160,1,432669,C,B,64.8,2,26,8058566343232,128,14857,94308496,CLX5
2025-09-24 19:36:31.101554747+00:00,160,1,432669,C,B,64.81,2,26,8058566343029,128,14992,94308498,CLX5
2025-09-24 19:36:31.101578577+00:00,160,1,432669,C,B,64.81,1,26,8058566343021,128,15053,94308508,CLX5
2025-09-24 19:36:31.101602519+00:00,160,1,432669,C,B,64.81,2,26,8058566342994,128,16148,94308512,CLX5
2025-09-24 19:36:31.101623695+00:00,160,1,432669,C,B,64.81,1,26,8058566342999,128,15448,94308514,CLX5
2025-09-24 19:36:31.101844601+00:00,160,1,432669,M,B,63.65,4,26,8058566319851,128,15862,94308524,CLX5
2025-09-24 19:36:31.102521121+00:00,160,1,432669,C,B,64.81,1,26,8058566342996,128,17956,94308553,CLX5
2025-09-24 19:36:31.103831215+00:00,160,1,432669,A,A,64.82,1,26,8058566344068,128,18241,94308586,CLX5
2025-09-24 19:36:31.109061505+00:00,160,1,432669,M,A,64.82,1,26,8058566331891,128,20280,94308600,CLX5
2025-09-24 19:36:31.210855509+00:00,160,1,432669,A,B,64.78,2,26,8058566344082,128,17903,94308616,CLX5
2025-09-24 19:36:31.210861155+00:00,160,1,432669,A,B,64.77,2,26,8058566344083,128,14498,94308617,CLX5
2025-09-24 19:36:33.475878575+00:00,160,1,432669,C,A,64.94,1,26,8058565474962,128,505238,94308654,CLX5
2025-09-24 19:36:34.208659605+00:00,160,1,432669,C,B,64.81,1,26,8058566342997,128,17111,94308775,CLX5
2025-09-24 19:36:37.543102277+00:00,160,1,432669,C,A,64.82,1,26,8058566344036,128,17415,94309516,CLX5
2025-09-24 19:36:39.790673047+00:00,160,1,432669,C,A,64.82,1,26,8058566337813,128,19004,94310003,CLX5
2025-09-24 19:36:39.923533855+00:00,160,1,432669,T,A,64.81,1,26,8058566344629,0,17538,94310007,CLX5
2025-09-24 19:36:39.923533855+00:00,160,1,432669,F,B,64.81,1,26,8058566342790,0,17538,94310007,CLX5
2025-09-24 19:36:39.923533855+00:00,160,1,432669,C,B,64.81,1,26,8058566342790,128,15911,94310008,CLX5
2025-09-24 19:36:49.837225371+00:00,160,1,432669,A,B,64.8,2,26,8058566344822,128,19678,94310563,CLX5
2025-09-24 19:36:49.837236005+00:00,160,1,432669,C,B,64.77,2,26,8058566344083,128,15128,94310565,CLX5
2025-09-24 19:36:49.837254725+00:00,160,1,432669,C,A,64.82,2,26,8058566344033,128,17243,94310570,CLX5
2025-09-24 19:36:49.837261503+00:00,160,1,432669,A,B,64.81,2,26,8058566344827,128,20471,94310573,CLX5
2025-09-24 19:36:49.837274943+00:00,160,1,432669,A,B,64.81,1,26,8058566344829,128,19389,94310577,CLX5
2025-09-24 19:36:49.837613135+00:00,160,1,432669,A,B,64.81,1,26,8058566344836,128,18286,94310592,CLX5
2025-09-24 19:36:49.837616149+00:00,160,1,432669,C,B,64.81,2,26,8058566344827,128,16062,94310593,CLX5
2025-09-24 19:36:49.837731479+00:00,160,1,432669,A,B,64.81,1,26,8058566344837,128,16027,94310600,CLX5
2025-09-24 19:36:49.838149253+00:00,160,1,432669,A,B,64.81,1,26,8058566344842,128,14077,94310619,CLX5
2025-09-24 19:36:49.838262007+00:00,160,1,432669,C,A,64.82,1,26,8058566344038,128,16195,94310623,CLX5
2025-09-24 19:36:49.838703839+00:00,160,1,432669,C,A,64.82,1,26,8058566344068,128,16424,94310640,CLX5
2025-09-24 19:36:49.904997183+00:00,160,1,432669,C,B,64.8,2,26,8058566344822,128,15514,94310718,CLX5
2025-09-24 19:36:49.904998839+00:00,160,1,432669,C,B,64.81,1,26,8058566344842,128,15061,94310721,CLX5
2025-09-24 19:36:49.905038257+00:00,160,1,432669,C,B,64.81,1,26,8058566344829,128,17981,94310733,CLX5
2025-09-24 19:36:49.905074025+00:00,160,1,432669,A,A,64.82,2,26,8058566344866,128,15805,94310741,CLX5
2025-09-24 19:36:49.905529101+00:00,160,1,432669,C,A,64.82,2,26,8058566344866,128,14704,94310750,CLX5
2025-09-24 19:36:49.905729041+00:00,160,1,432669,A,A,64.82,1,26,8058566344870,128,16070,94310756,CLX5
2025-09-24 19:36:49.910978415+00:00,160,1,432669,C,B,64.78,2,26,8058566344082,128,19258,94310758,CLX5
2025-09-24 19:36:49.991510877+00:00,160,1,432669,A,B,64.8,2,26,8058566344884,128,15244,94310783,CLX5
2025-09-24 19:36:50.241429303+00:00,160,1,432669,C,B,64.8,2,26,8058566344884,128,19518,94310807,CLX5
2025-09-24 19:36:50.241604783+00:00,160,1,432669,T,A,64.81,1,26,8058566344899,0,17170,94310815,CLX5
2025-09-24 19:36:50.241604783+00:00,160,1,432669,F,B,64.81,1,26,8058566342791,0,17170,94310815,CLX5
2025-09-24 19:36:50.241604783+00:00,160,1,432669,M,B,64.81,1,26,8058566342791,128,16335,94310816,CLX5
2025-09-24 19:36:50.241895843+00:00,160,1,432669,A,A,64.82,2,26,8058566344901,128,19202,94310819,CLX5
2025-09-24 19:36:50.241902659+00:00,160,1,432669,A,A,64.82,1,26,8058566344902,128,15086,94310820,CLX5
2025-09-24 19:36:50.241932071+00:00,160,1,432669,A,A,64.82,2,26,8058566344903,128,15157,94310821,CLX5
2025-09-24 19:36:50.241934567+00:00,160,1,432669,A,B,64.81,1,26,8058566344904,128,19890,94310822,CLX5
2025-09-24 19:36:50.242266771+00:00,160,1,432669,C,A,64.82,2,26,8058566344903,128,15261,94310834,CLX5
2025-09-24 19:36:50.311280143+00:00,160,1,432669,A,B,64.78,2,26,8058566344917,128,18239,94310859,CLX5
2025-09-24 19:36:50.339442785+00:00,160,1,432669,A,B,64.81,1,26,8058566344919,128,19632,94310866,CLX5
2025-09-24 19:36:50.410946437+00:00,160,1,432669,A,B,64.77,2,26,8058566344921,128,18950,94310872,CLX5
2025-09-24 19:36:51.356299291+00:00,160,1,432669,C,A,64.82,1,26,8058566344902,128,19362,94310904,CLX5
2025-09-24 19:36:51.356529991+00:00,160,1,432669,A,B,64.81,1,26,8058566344937,128,26968,94310909,CLX5
2025-09-24 19:36:51.356682297+00:00,160,1,432669,C,B,64.81,1,26,8058566344937,128,18525,94310911,CLX5
2025-09-24 19:37:00.158751029+00:00,160,1,432669,A,A,64.82,1,26,8058566344953,128,18812,94310984,CLX5
2025-09-24 19:37:00.173519189+00:00,160,1,432669,M,A,64.83,1,26,8058566331891,128,18436,94310988,CLX5
2025-09-24 19:37:00.339610795+00:00,160,1,432669,A,B,64.8,1,26,8058566344955,128,18079,94310993,CLX5
2025-09-24 19:37:00.506604279+00:00,160,1,432669,M,B,64.74,35,26,8058566342993,128,18392,94310994,CLX5
2025-09-24 19:37:02.417822017+00:00,160,1,432669,A,B,64.81,2,26,8058566344960,128,20541,94311008,CLX5
2025-09-24 19:37:02.418270837+00:00,160,1,432669,C,A,64.82,1,26,8058566344870,128,19762,94311014,CLX5
2025-09-24 19:37:02.418275367+00:00,160,1,432669,A,B,64.81,1,26,8058566344963,128,15842,94311015,CLX5
2025-09-24 19:37:02.418439385+00:00,160,1,432669,C,B,64.81,1,26,8058566344963,128,19579,94311016,CLX5
2025-09-24 19:37:03.736359365+00:00,160,1,432669,C,B,64.8,1,26,8058566271014,128,19256,94311022,CLX5
2025-09-24 19:37:03.858476749+00:00,160,1,432669,C,A,64.99,1,26,8058566342642,128,18674,94311023,CLX5
2025-09-24 19:37:03.936539143+00:00,160,1,432669,A,A,64.98,1,26,8058566344965,128,18664,94311024,CLX5
2025-09-24 19:37:04.462637115+00:00,160,1,432669,C,A,64.82,2,26,8058566344901,128,16646,94311079,CLX5
2025-09-24 19:37:04.463282381+00:00,160,1,432669,A,B,64.81,1,26,8058566344991,128,15903,94311126,CLX5
2025-09-24 19:37:04.468667589+00:00,160,1,432669,C,A,64.82,1,26,8058566344032,128,19517,94311222,CLX5
2025-09-24 19:37:04.468831531+00:00,160,1,432669,C,A,64.85,1,26,8058566344029,128,14580,94311224,CLX5
2025-09-24 19:37:04.468884991+00:00,160,1,432669,A,B,64.8,2,26,8058566345015,128,18075,94311228,CLX5
2025-09-24 19:37:04.468893485+00:00,160,1,432669,C,B,64.77,2,26,8058566344921,128,14652,94311232,CLX5
2025-09-24 19:37:04.469055545+00:00,160,1,432669,C,A,64.82,2,26,8058566344015,128,14678,94311238,CLX5
2025-09-24 19:37:04.469056103+00:00,160,1,432669,C,A,64.82,1,26,8058566344016,128,18471,94311239,CLX5
2025-09-24 19:37:04.471181123+00:00,160,1,432669,M,B,64.81,1,26,8058566319851,128,17568,94311330,CLX5
2025-09-24 19:37:04.471451487+00:00,160,1,432669,C,B,64.81,1,26,8058566344991,128,17628,94311358,CLX5
2025-09-24 19:37:04.472475529+00:00,160,1,432669,A,B,64.81,1,26,8058566345085,128,18279,94311477,CLX5
2025-09-24 19:37:04.473718887+00:00,160,1,432669,M,A,64.95,1,26,8058565075241,128,16260,94311529,CLX5
2025-09-24 19:37:04.475683247+00:00,160,1,432669,C,B,64.81,1,26,8058566345085,128,18559,94311651,CLX5
2025-09-24 19:37:04.511034533+00:00,160,1,432669,C,B,64.78,2,26,8058566344917,128,19759,94311827,CLX5
2025-09-24 19:37:04.571847543+00:00,160,1,432669,C,A,64.82,1,26,8058566344031,128,19841,94311876,CLX5
2025-09-24 19:37:04.634791813+00:00,160,1,432669,A,A,64.82,1,26,8058566345250,128,16724,94311940,CLX5
2025-09-24 19:37:04.635170995+00:00,160,1,432669,C,A,64.82,1,26,8058566345250,128,16378,94311945,CLX5
2025-09-24 19:37:04.789435575+00:00,160,1,432669,A,A,64.82,1,26,8058566345297,128,20774,94312015,CLX5
2025-09-24 19:37:04.827003077+00:00,160,1,432669,A,B,64.81,1,26,8058566345298,128,18844,94312016,CLX5
2025-09-24 19:37:04.827173737+00:00,160,1,432669,C,A,64.82,1,26,8058566345297,128,16587,94312018,CLX5
2025-09-24 19:37:06.000337829+00:00,160,1,432669,A,A,64.82,1,26,8058566345380,128,19880,94312134,CLX5
2025-09-24 19:37:06.000516821+00:00,160,1,432669,C,A,64.82,1,26,8058566345380,128,16388,94312139,CLX5
2025-09-24 19:37:08.730253705+00:00,160,1,432669,T,N,64.82,1,26,0,0,18203,94312158,CLX5
2025-09-24 19:37:08.730253705+00:00,160,1,432669,F,N,64.82,1,26,8058566335929,0,18203,94312158,CLX5
2025-09-24 19:37:08.730253705+00:00,160,1,432669,C,A,64.82,1,26,8058566335929,128,17326,94312159,CLX5
2025-09-24 19:37:08.730254639+00:00,160,1,432669,T,B,64.82,2,26,8058566345389,0,18217,94312164,CLX5
2025-09-24 19:37:08.730254639+00:00,160,1,432669,F,A,64.82,1,26,8058566337236,0,18217,94312164,CLX5
2025-09-24 19:37:08.730254639+00:00,160,1,432669,F,A,64.82,1,26,8058566341727,0,18217,94312164,CLX5
2025-09-24 19:37:08.730254639+00:00,160,1,432669,C,A,64.82,1,26,8058566337236,0,17456,94312165,CLX5
2025-09-24 19:37:08.730254639+00:00,160,1,432669,C,A,64.82,1,26,8058566341727,128,17456,94312165,CLX5
2025-09-24 19:37:08.730254927+00:00,160,1,432669,T,B,64.82,4,26,8058566345390,0,18063,94312166,CLX5
2025-09-24 19:37:08.730254927+00:00,160,1,432669,F,A,64.82,1,26,8058566342118,0,18063,94312166,CLX5
2025-09-24 19:37:08.730254927+00:00,160,1,432669,F,A,64.82,1,26,8058566342425,0,18063,94312166,CLX5
2025-09-24 19:37:08.730254927+00:00,160,1,432669,F,A,64.82,1,26,8058566343993,0,18063,94312166,CLX5
2025-09-24 19:37:08.730254927+00:00,160,1,432669,F,A,64.82,1,26,8058566344953,0,18063,94312166,CLX5
2025-09-24 19:37:08.730254927+00:00,160,1,432669,C,A,64.82,1,26,8058566342118,0,14775,94312167,CLX5
2025-09-24 19:37:08.730254927+00:00,160,1,432669,C,A,64.82,1,26,8058566342425,0,14775,94312167,CLX5
2025-09-24 19:37:08.730254927+00:00,160,1,432669,C,A,64.82,1,26,8058566343993,0,14775,94312167,CLX5
2025-09-24 19:37:08.730254927+00:00,160,1,432669,C,A,64.82,1,26,8058566344953,128,14775,94312167,CLX5
2025-09-24 19:37:08.730255119+00:00,160,1,432669,A,B,64.82,2,26,8058566345391,128,18143,94312170,CLX5
2025-09-24 19:37:08.730255827+00:00,160,1,432669,A,B,64.81,2,26,8058566345393,128,19225,94312172,CLX5
2025-09-24 19:37:08.730263507+00:00,160,1,432669,A,B,64.81,1,26,8058566345401,128,16850,94312182,CLX5
2025-09-24 19:37:08.730307841+00:00,160,1,432669,C,A,64.83,1,26,8058566335771,128,15750,94312251,CLX5
2025-09-24 19:37:08.730333603+00:00,160,1,432669,A,B,64.81,1,26,8058566345421,128,15121,94312259,CLX5
2025-09-24 19:37:08.730408619+00:00,160,1,432669,A,B,64.82,2,26,8058566345427,128,18368,94312268,CLX5
2025-09-24 19:37:08.730434803+00:00,160,1,432669,C,A,64.83,1,26,8058566335056,128,21781,94312278,CLX5
2025-09-24 19:37:08.730434955+00:00,160,1,432669,C,A,64.83,1,26,8058566335057,128,15633,94312279,CLX5
2025-09-24 19:37:08.730537365+00:00,160,1,432669,A,B,64.82,1,26,8058566345446,128,24046,94312297,CLX5
2025-09-24 19:37:08.730655381+00:00,160,1,432669,A,B,64.82,1,26,8058566345447,128,16989,94312298,CLX5
2025-09-24 19:37:08.730661181+00:00,160,1,432669,C,B,64.81,1,26,8058566345421,128,14941,94312299,CLX5
2025-09-24 19:37:08.730731007+00:00,160,1,432669,A,B,64.82,1,26,8058566345451,128,16620,94312303,CLX5
2025-09-24 19:37:08.730736135+00:00,160,1,432669,A,B,64.82,2,26,8058566345454,128,16542,94312305,CLX5
2025-09-24 19:37:08.730743141+00:00,160,1,432669,C,A,64.83,1,26,8058566335720,128,14418,94312306,CLX5
2025-09-24 19:37:08.730762015+00:00,160,1,432669,C,A,64.83,1,26,8058566335699,128,14898,94312309,CLX5
2025-09-24 19:37:08.730796131+00:00,160,1,432669,C,A,64.83,1,26,8058566343075,128,19864,94312314,CLX5
2025-09-24 19:37:08.731001523+00:00,160,1,432669,M,A,64.94,1,26,8058565075241,128,18612,94312346,CLX5
2025-09-24 19:37:08.731113511+00:00,160,1,432669,A,B,64.82,1,26,8058566345478,128,14947,94312362,CLX5
2025-09-24 19:37:08.731126587+00:00,160,1,432669,C,A,64.86,2,26,8058566335838,128,14704,94312368,CLX5
2025-09-24 19:37:08.731166251+00:00,160,1,432669,A,B,64.82,2,26,8058566345482,128,15817,94312370,CLX5
2025-09-24 19:37:08.731175641+00:00,160,1,432669,A,B,64.82,2,26,8058566345487,128,15715,94312374,CLX5
2025-09-24 19:37:08.731203191+00:00,160,1,432669,A,B,64.82,1,26,8058566345493,128,16962,94312378,CLX5
2025-09-24 19:37:08.731212945+00:00,160,1,432669,A,B,64.81,1,26,8058566345497,128,14476,94312387,CLX5
2025-09-24 19:37:08.731371913+00:00,160,1,432669,A,A,64.83,1,26,8058566345503,128,13861,94312409,CLX5
2025-09-24 19:37:08.731382513+00:00,160,1,432669,A,B,64.82,1,26,8058566345507,128,15377,94312421,CLX5
2025-09-24 19:37:08.731417647+00:00,160,1,432669,A,A,64.83,1,26,8058566345514,128,19590,94312434,CLX5
2025-09-24 19:37:08.731420161+00:00,160,1,432669,A,B,64.81,3,26,8058566345515,128,15283,94312435,CLX5
2025-09-24 19:37:08.731519959+00:00,160,1,432669,A,B,64.79,1,26,8058566345526,128,14920,94312466,CLX5
2025-09-24 19:37:08.731524125+00:00,160,1,432669,A,B,64.82,1,26,8058566345528,128,15407,94312471,CLX5
2025-09-24 19:37:08.731528733+00:00,160,1,432669,A,A,64.83,1,26,8058566345529,128,15149,94312472,CLX5
2025-09-24 19:37:08.731604551+00:00,160,1,432669,C,A,64.83,1,26,8058566345529,128,15734,94312481,CLX5
2025-09-24 19:37:08.731670845+00:00,160,1,432669,M,A,65.99,4,26,8058566331102,128,19015,94312483,CLX5
2025-09-24 19:37:08.731855175+00:00,160,1,432669,T,A,64.82,1,26,8058566345538,0,14711,94312502,CLX5
2025-09-24 19:37:08.731855175+00:00,160,1,432669,F,B,64.82,1,26,8058566345391,0,14711,94312502,CLX5
2025-09-24 19:37:08.731855175+00:00,160,1,432669,M,B,64.82,1,26,8058566345391,128,15919,94312503,CLX5
2025-09-24 19:37:08.731862761+00:00,160,1,432669,M,B,64.81,1,26,8058566319508,128,18694,94312504,CLX5
2025-09-24 19:37:08.731875067+00:00,160,1,432669,C,A,64.83,1,26,8058566345514,128,15747,94312505,CLX5
2025-09-24 19:37:08.732009653+00:00,160,1,432669,M,B,64.8,1,26,8058566332677,128,14809,94312517,CLX5
2025-09-24 19:37:08.732147233+00:00,160,1,432669,M,B,64.82,1,26,8058566344955,128,15146,94312521,CLX5
2025-09-24 19:37:08.732289365+00:00,160,1,432669,A,B,64.82,3,26,8058566345544,128,14140,94312529,CLX5
2025-09-24 19:37:08.732575085+00:00,160,1,432669,M,B,64.81,1,26,8058566340051,128,18687,94312559,CLX5
2025-09-24 19:37:08.732659909+00:00,160,1,432669,A,B,64.82,1,26,8058566345553,128,23179,94312569,CLX5
2025-09-24 19:37:08.732678877+00:00,160,1,432669,A,B,64.82,1,26,8058566345555,128,15114,94312573,CLX5
2025-09-24 19:37:08.733166669+00:00,160,1,432669,M,A,64.84,1,26,8058566173085,128,18855,94312589,CLX5
2025-09-24 19:37:08.733811493+00:00,160,1,432669,A,B,64.81,2,26,8058566345566,128,14993,94312613,CLX5
2025-09-24 19:37:08.733867517+00:00,160,1,432669,C,B,64.82,2,26,8058566345487,128,15126,94312618,CLX5
2025-09-24 19:37:08.734115609+00:00,160,1,432669,M,A,64.95,1,26,8058565075241,128,14798,94312642,CLX5
2025-09-24 19:37:08.734215385+00:00,160,1,432669,A,B,64.81,1,26,8058566345576,128,14858,94312646,CLX5
2025-09-24 19:37:08.734541905+00:00,160,1,432669,C,A,64.83,1,26,8058566345503,128,15921,94312654,CLX5
2025-09-24 19:37:08.734690027+00:00,160,1,432669,C,A,64.83,1,26,8058566335746,128,19478,94312657,CLX5
2025-09-24 19:37:08.734786195+00:00,160,1,432669,A,A,64.83,1,26,8058566345586,128,15579,94312670,CLX5
2025-09-24 19:37:08.735349539+00:00,160,1,432669,A,A,64.83,1,26,8058566345595,128,16030,94312698,CLX5
2025-09-24 19:37:08.735594691+00:00,160,1,432669,A,A,64.83,1,26,8058566345599,128,18508,94312718,CLX5
2025-09-24 19:37:08.735609911+00:00,160,1,432669,C,B,64.82,1,26,8058566345447,128,15231,94312721,CLX5
2025-09-24 19:37:08.735731811+00:00,160,1,432669,A,B,64.82,1,26,8058566345602,128,16348,94312732,CLX5
2025-09-24 19:37:08.735771727+00:00,160,1,432669,A,A,64.83,1,26,8058566345604,128,18852,94312739,CLX5
2025-09-24 19:37:08.735775047+00:00,160,1,432669,A,A,64.83,1,26,8058566345605,128,15560,94312742,CLX5
2025-09-24 19:37:08.735964985+00:00,160,1,432669,A,A,64.83,1,26,8058566345612,128,15215,94312763,CLX5
2025-09-24 19:37:08.736099015+00:00,160,1,432669,C,A,64.86,1,26,8058566335777,128,14631,94312764,CLX5
2025-09-24 19:37:08.736808941+00:00,160,1,432669,C,A,64.83,1,26,8058566345604,128,15351,94312850,CLX5
2025-09-24 19:37:08.737258565+00:00,160,1,432669,A,A,64.83,1,26,8058566345625,128,15681,94312877,CLX5
2025-09-24 19:37:08.737612023+00:00,160,1,432669,C,B,64.82,1,26,8058566345493,128,18351,94312915,CLX5
2025-09-24 19:37:08.737731385+00:00,160,1,432669,A,B,64.82,1,26,8058566345648,128,18577,94312944,CLX5
2025-09-24 19:37:08.737732843+00:00,160,1,432669,C,A,64.83,1,26,8058566345599,128,15105,94312945,CLX5
2025-09-24 19:37:08.738006643+00:00,160,1,432669,A,B,64.82,1,26,8058566345652,128,15505,94312955,CLX5
2025-09-24 19:37:08.738789199+00:00,160,1,432669,C,B,64.82,2,26,8058566345482,128,14956,94313035,CLX5
2025-09-24 19:37:08.738869777+00:00,160,1,432669,A,A,64.83,2,26,8058566345667,128,18711,94313038,CLX5
2025-09-24 19:37:08.739203747+00:00,160,1,432669,C,B,64.82,1,26,8058566345652,128,14099,94313058,CLX5
2025-09-24 19:37:08.739361547+00:00,160,1,432669,C,B,64.82,1,26,8058566345553,128,14743,94313069,CLX5
2025-09-24 19:37:08.739921373+00:00,160,1,432669,C,B,64.82,1,26,8058566345602,128,14904,94313104,CLX5
2025-09-24 19:37:08.740576085+00:00,160,1,432669,C,A,64.83,1,26,8058566345595,128,15008,94313131,CLX5
2025-09-24 19:37:08.741125371+00:00,160,1,432669,A,A,64.83,1,26,8058566345701,128,15139,94313157,CLX5
2025-09-24 19:37:08.741397577+00:00,160,1,432669,A,A,64.83,1,26,8058566345702,128,18653,94313168,CLX5
2025-09-24 19:37:08.741495089+00:00,160,1,432669,M,B,64.81,1,26,8058566329044,128,14174,94313173,CLX5
2025-09-24 19:37:08.742200581+00:00,160,1,432669,C,A,64.83,2,26,8058566345667,128,18688,94313239,CLX5
2025-09-24 19:37:08.742678679+00:00,160,1,432669,A,A,64.83,1,26,8058566345712,128,18419,94313252,CLX5
2025-09-24 19:37:08.743517567+00:00,160,1,432669,A,A,64.83,1,26,8058566345716,128,15139,94313273,CLX5
2025-09-24 19:37:08.743726357+00:00,160,1,432669,C,A,64.83,1,26,8058566345701,128,18718,94313276,CLX5
2025-09-24 19:37:08.744244889+00:00,160,1,432669,C,B,64.81,1,26,8058566345576,128,18304,94313290,CLX5
2025-09-24 19:37:08.744727517+00:00,160,1,432669,C,A,64.83,1,26,8058566345716,128,18620,94313302,CLX5
2025-09-24 19:37:08.745479413+00:00,160,1,432669,C,B,64.81,2,26,8058566345566,128,18009,94313341,CLX5
2025-09-24 19:37:08.745511139+00:00,160,1,432669,C,B,64.82,2,26,8058566345427,128,17762,94313351,CLX5
2025-09-24 19:37:08.745517697+00:00,160,1,432669,C,B,64.82,3,26,8058566345544,128,16400,94313354,CLX5
2025-09-24 19:37:08.745542311+00:00,160,1,432669,A,A,64.83,1,26,8058566345735,128,15107,94313358,CLX5
2025-09-24 19:37:08.745592535+00:00,160,1,432669,A,A,64.83,2,26,8058566345738,128,18617,94313365,CLX5
2025-09-24 19:37:08.745620545+00:00,160,1,432669,A,A,64.83,1,26,8058566345742,128,18859,94313373,CLX5
2025-09-24 19:37:08.745620737+00:00,160,1,432669,A,A,64.83,1,26,8058566345743,128,14334,94313374,CLX5
2025-09-24 19:37:08.745748681+00:00,160,1,432669,A,A,64.83,1,26,8058566345746,128,18662,94313382,CLX5
2025-09-24 19:37:08.745765115+00:00,160,1,432669,C,B,64.82,1,26,8058566345391,128,15079,94313384,CLX5
2025-09-24 19:37:08.746369639+00:00,160,1,432669,C,A,64.83,2,26,8058566345738,128,18152,94313458,CLX5
2025-09-24 19:37:08.748249217+00:00,160,1,432669,C,A,64.83,1,26,8058566345746,128,14253,94313569,CLX5
2025-09-24 19:37:08.749341399+00:00,160,1,432669,C,A,64.83,1,26,8058566345712,128,19231,94313617,CLX5
2025-09-24 19:37:08.749344145+00:00,160,1,432669,C,A,64.83,1,26,8058566345735,128,15220,94313618,CLX5
2025-09-24 19:37:08.749736269+00:00,160,1,432669,A,A,64.83,1,26,8058566345788,128,15003,94313622,CLX5
2025-09-24 19:37:08.749929007+00:00,160,1,432669,A,A,64.83,1,26,8058566345790,128,17468,94313630,CLX5
2025-09-24 19:37:08.750290797+00:00,160,1,432669,C,B,64.82,1,26,8058566345648,128,14552,94313663,CLX5
2025-09-24 19:37:08.750407105+00:00,160,1,432669,C,B,64.82,1,26,8058566345478,128,17127,94313669,CLX5
2025-09-24 19:37:08.751225067+00:00,160,1,432669,A,A,64.83,2,26,8058566345824,128,15381,94313714,CLX5
2025-09-24 19:37:08.751910015+00:00,160,1,432669,A,A,64.83,1,26,8058566345827,128,17235,94313718,CLX5
2025-09-24 19:37:08.752989873+00:00,160,1,432669,C,A,64.83,2,26,8058566345824,128,15318,94313760,CLX5
2025-09-24 19:37:08.752990755+00:00,160,1,432669,A,A,64.83,2,26,8058566345835,128,18826,94313761,CLX5
2025-09-24 19:37:08.753995235+00:00,160,1,432669,C,A,64.83,2,26,8058566345835,128,15050,94313798,CLX5
2025-09-24 19:37:08.755031049+00:00,160,1,432669,A,A,64.83,2,26,8058566345856,128,18345,94313895,CLX5
2025-09-24 19:37:08.755822381+00:00,160,1,432669,C,A,64.83,2,26,8058566345856,128,14089,94313920,CLX5
2025-09-24 19:37:08.756105741+00:00,160,1,432669,C,B,64.82,1,26,8058566345507,128,18884,94313932,CLX5
2025-09-24 19:37:08.756133907+00:00,160,1,432669,C,B,64.82,2,26,8058566345454,128,16917,94313937,CLX5
2025-09-24 19:37:08.756134053+00:00,160,1,432669,C,B,64.82,1,26,8058566345446,128,16992,94313938,CLX5
2025-09-24 19:37:08.756135653+00:00,160,1,432669,T,A,64.82,4,26,8058566345868,0,16955,94313939,CLX5
2025-09-24 19:37:08.756135653+00:00,160,1,432669,F,B,64.82,1,26,8058566345451,0,16955,94313939,CLX5
2025-09-24 19:37:08.756135653+00:00,160,1,432669,F,B,64.82,1,26,8058566345528,0,16955,94313939,CLX5
2025-09-24 19:37:08.756135653+00:00,160,1,432669,F,B,64.82,1,26,8058566344955,0,16955,94313939,CLX5
2025-09-24 19:37:08.756135653+00:00,160,1,432669,F,B,64.82,1,26,8058566345555,0,16955,94313939,CLX5
2025-09-24 19:37:08.756135653+00:00,160,1,432669,C,B,64.82,1,26,8058566345451,0,15103,94313940,CLX5
2025-09-24 19:37:08.756135653+00:00,160,1,432669,C,B,64.82,1,26,8058566345528,0,15103,94313940,CLX5
2025-09-24 19:37:08.756135653+00:00,160,1,432669,C,B,64.82,1,26,8058566344955,0,15103,94313940,CLX5
2025-09-24 19:37:08.756135653+00:00,160,1,432669,C,B,64.82,1,26,8058566345555,128,15103,94313940,CLX5
2025-09-24 19:37:08.756135845+00:00,160,1,432669,A,A,64.82,2,26,8058566345869,128,18048,94313943,CLX5
2025-09-24 19:37:08.756171787+00:00,160,1,432669,A,A,64.83,1,26,8058566345875,128,18432,94313961,CLX5
2025-09-24 19:37:08.756193711+00:00,160,1,432669,A,A,64.83,2,26,8058566345878,128,18377,94313970,CLX5
2025-09-24 19:37:08.756388161+00:00,160,1,432669,A,A,64.86,1,26,8058566345884,128,14726,94313986,CLX5
2025-09-24 19:37:08.756424081+00:00,160,1,432669,M,A,64.84,1,26,8058566332416,128,18453,94313990,CLX5
