ts_event,rtype,publisher_id,instrument_id,action,side,price,size,channel_id,order_id,flags,ts_in_delta,sequence,symbol
2025-09-24 19:30:00.000860311+00:00,160,1,432669,A,A,64.83,1,26,8058566314544,128,17528,94225061,CLX5
2025-09-24 19:30:00.001394777+00:00,160,1,432669,C,A,64.83,1,26,8058566314535,128,17697,94225065,CLX5
2025-09-24 19:30:00.061472325+00:00,160,1,432669,C,B,64.79,1,26,8058566226379,128,21053,94225124,CLX5
2025-09-24 19:30:00.061473053+00:00,160,1,432669,C,B,64.8,1,26,8058566253567,128,17668,94225125,CLX5
2025-09-24 19:30:00.093437495+00:00,160,1,432669,C,A,64.83,1,26,8058566314534,128,18699,94225162,CLX5
2025-09-24 19:30:00.093784155+00:00,160,1,432669,A,B,64.82,1,26,8058566314579,128,15148,94225181,CLX5
2025-09-24 19:30:00.125953257+00:00,160,1,432669,C,A,64.86,1,26,8058566175788,128,18262,94225208,CLX5
2025-09-24 19:30:00.398580505+00:00,160,1,432669,C,A,64.83,2,26,8058566314531,128,16291,94225265,CLX5
2025-09-24 19:30:00.398599399+00:00,160,1,432669,C,A,64.83,2,26,8058566314530,128,14788,94225266,CLX5
2025-09-24 19:30:00.399976013+00:00,160,1,432669,C,A,64.83,1,26,8058566314503,128,16415,94225293,CLX5
2025-09-24 19:30:00.400141223+00:00,160,1,432669,T,B,64.83,6,26,8058566314620,0,18442,94225298,CLX5
2025-09-24 19:30:00.400141223+00:00,160,1,432669,F,A,64.83,1,26,8058566308744,0,18442,94225298,CLX5
2025-09-24 19:30:00.400141223+00:00,160,1,432669,F,A,64.83,2,26,8058566308768,0,18442,94225298,CLX5
2025-09-24 19:30:00.400141223+00:00,160,1,432669,F,A,64.83,1,26,8058566311024,0,18442,94225298,CLX5
2025-09-24 19:30:00.400141223+00:00,160,1,432669,F,A,64.83,1,26,8058566313468,0,18442,94225298,CLX5
2025-09-24 19:30:00.400141223+00:00,160,1,432669,F,A,64.83,1,26,8058566314544,0,18442,94225298,CLX5
2025-09-24 19:30:00.400141223+00:00,160,1,432669,C,A,64.83,1,26,8058566308744,0,15030,94225299,CLX5
2025-09-24 19:30:00.400141223+00:00,160,1,432669,C,A,64.83,2,26,8058566308768,0,15030,94225299,CLX5
2025-09-24 19:30:00.400141223+00:00,160,1,432669,C,A,64.83,1,26,8058566311024,0,15030,94225299,CLX5
2025-09-24 19:30:00.400141223+00:00,160,1,432669,C,A,64.83,1,26,8058566313468,0,15030,94225299,CLX5
2025-09-24 19:30:00.400141223+00:00,160,1,432669,C,A,64.83,1,26,8058566314544,128,15030,94225299,CLX5
2025-09-24 19:30:00.400153319+00:00,160,1,432669,A,B,64.83,3,26,8058566314621,128,16510,94225302,CLX5
2025-09-24 19:30:00.400477971+00:00,160,1,432669,A,B,64.82,2,26,8058566314622,128,15238,94225306,CLX5
2025-09-24 19:30:00.400484563+00:00,160,1,432669,A,B,64.82,1,26,8058566314624,128,15142,94225309,CLX5
2025-09-24 19:30:00.400522039+00:00,160,1,432669,C,A,65.05,1,26,8058565884948,128,17488,94225313,CLX5
2025-09-24 19:30:00.400522481+00:00,160,1,432669,C,A,65.03,1,26,8058565958174,128,17488,94225313,CLX5
2025-09-24 19:30:00.400522885+00:00,160,1,432669,C,A,65.02,1,26,8058565971028,128,17488,94225313,CLX5
2025-09-24 19:30:00.400523209+00:00,160,1,432669,C,A,65.01,1,26,8058565978397,128,15461,94225314,CLX5
2025-09-24 19:30:00.400523537+00:00,160,1,432669,C,A,65.0,1,26,8058565986118,128,15461,94225314,CLX5
2025-09-24 19:30:00.400523863+00:00,160,1,432669,C,A,64.99,1,26,8058566056746,128,15461,94225314,CLX5
2025-09-24 19:30:00.400524151+00:00,160,1,432669,C,A,64.98,1,26,8058566058624,128,15461,94225314,CLX5
2025-09-24 19:30:00.400524479+00:00,160,1,432669,C,A,64.94,1,26,8058566099503,128,15461,94225314,CLX5
2025-09-24 19:30:00.400524765+00:00,160,1,432669,C,A,64.93,1,26,8058566106311,128,14820,94225315,CLX5
2025-09-24 19:30:00.400525111+00:00,160,1,432669,C,A,64.92,1,26,8058566107908,128,14663,94225316,CLX5
2025-09-24 19:30:00.400525379+00:00,160,1,432669,C,A,64.91,1,26,8058566108705,128,15033,94225317,CLX5
2025-09-24 19:30:00.400525649+00:00,160,1,432669,C,A,64.89,1,26,8058566173002,128,16997,94225318,CLX5
2025-09-24 19:30:00.400525879+00:00,160,1,432669,C,A,64.88,1,26,8058566173150,128,15056,94225319,CLX5
2025-09-24 19:30:00.400526025+00:00,160,1,432669,C,A,64.86,1,26,8058566175980,128,14702,94225320,CLX5
2025-09-24 19:30:00.400526263+00:00,160,1,432669,C,A,64.85,1,26,8058566273445,128,14936,94225321,CLX5
2025-09-24 19:30:00.400526493+00:00,160,1,432669,C,A,64.84,1,26,8058566274081,128,15684,94225322,CLX5
2025-09-24 19:30:00.400569155+00:00,160,1,432669,A,A,64.84,1,26,8058566314633,128,18331,94225336,CLX5
2025-09-24 19:30:00.400587451+00:00,160,1,432669,A,A,64.84,1,26,8058566314639,128,18642,94225356,CLX5
2025-09-24 19:30:00.400611643+00:00,160,1,432669,A,A,64.84,1,26,8058566314641,128,17860,94225359,CLX5
2025-09-24 19:30:00.400614887+00:00,160,1,432669,M,B,64.82,1,26,8058566311303,128,18451,94225364,CLX5
2025-09-24 19:30:00.400626829+00:00,160,1,432669,C,A,64.85,1,26,8058566313455,128,18766,94225370,CLX5
2025-09-24 19:30:00.400634277+00:00,160,1,432669,A,B,64.82,3,26,8058566314643,128,15218,94225371,CLX5
2025-09-24 19:30:00.400640921+00:00,160,1,432669,C,A,64.85,1,26,8058566313240,128,18171,94225373,CLX5
2025-09-24 19:30:00.400642399+00:00,160,1,432669,C,A,64.85,1,26,8058566311241,128,15215,94225374,CLX5
2025-09-24 19:30:00.400680529+00:00,160,1,432669,A,B,64.83,1,26,8058566314644,128,18845,94225375,CLX5
2025-09-24 19:30:00.400722919+00:00,160,1,432669,A,B,64.83,1,26,8058566314645,128,20600,94225376,CLX5
2025-09-24 19:30:00.400985489+00:00,160,1,432669,M,B,64.82,3,26,8058566311409,128,14400,94225382,CLX5
2025-09-24 19:30:00.401298643+00:00,160,1,432669,A,B,64.8,1,26,8058566314647,128,18131,94225389,CLX5
2025-09-24 19:30:00.401678269+00:00,160,1,432669,C,B,64.78,1,26,8058566287073,128,14898,94225417,CLX5
2025-09-24 19:30:00.403177857+00:00,160,1,432669,M,A,64.85,1,26,8058566173085,128,15075,94225489,CLX5
2025-09-24 19:30:00.404368897+00:00,160,1,432669,C,A,64.84,1,26,8058566314641,128,15342,94225543,CLX5
2025-09-24 19:30:00.404766703+00:00,160,1,432669,A,A,64.84,1,26,8058566314689,128,15317,94225555,CLX5
2025-09-24 19:30:00.404808405+00:00,160,1,432669,A,B,64.83,1,26,8058566314690,128,20056,94225558,CLX5
2025-09-24 19:30:00.410209565+00:00,160,1,432669,T,A,64.83,6,26,8058566314695,0,18162,94225587,CLX5
2025-09-24 19:30:00.410209565+00:00,160,1,432669,F,B,64.83,3,26,8058566314621,0,18162,94225587,CLX5
2025-09-24 19:30:00.410209565+00:00,160,1,432669,F,B,64.83,1,26,8058566314644,0,18162,94225587,CLX5
2025-09-24 19:30:00.410209565+00:00,160,1,432669,F,B,64.83,1,26,8058566314645,0,18162,94225587,CLX5
2025-09-24 19:30:00.410209565+00:00,160,1,432669,F,B,64.83,1,26,8058566314690,0,18162,94225587,CLX5
2025-09-24 19:30:00.410209565+00:00,160,1,432669,C,B,64.83,3,26,8058566314621,0,14895,94225588,CLX5
2025-09-24 19:30:00.410209565+00:00,160,1,432669,C,B,64.83,1,26,8058566314644,0,14895,94225588,CLX5
2025-09-24 19:30:00.410209565+00:00,160,1,432669,C,B,64.83,1,26,8058566314645,0,14895,94225588,CLX5
2025-09-24 19:30:00.410209565+00:00,160,1,432669,C,B,64.83,1,26,8058566314690,128,14895,94225588,CLX5
2025-09-24 19:30:00.410521073+00:00,160,1,432669,C,A,64.84,1,26,8058566314689,128,18762,94225592,CLX5
2025-09-24 19:30:00.410522069+00:00,160,1,432669,A,A,64.83,2,26,8058566314696,128,17093,94225594,CLX5
2025-09-24 19:30:00.410581271+00:00,160,1,432669,C,B,64.81,1,26,8058566313373,128,14884,94225615,CLX5
2025-09-24 19:30:00.410671921+00:00,160,1,432669,A,A,64.84,1,26,8058566314709,128,17862,94225627,CLX5
2025-09-24 19:30:00.410701201+00:00,160,1,432669,A,A,64.84,1,26,8058566314710,128,18899,94225628,CLX5
2025-09-24 19:30:00.410721571+00:00,160,1,432669,C,A,64.84,1,26,8058566314709,128,15330,94225629,CLX5
2025-09-24 19:30:00.410740329+00:00,160,1,432669,A,A,64.84,1,26,8058566314711,128,14986,94225630,CLX5
2025-09-24 19:30:00.410783373+00:00,160,1,432669,M,B,63.67,4,26,8058566311409,128,18470,94225633,CLX5
2025-09-24 19:30:00.411223245+00:00,160,1,432669,C,B,64.81,1,26,8058566312861,128,14937,94225651,CLX5
2025-09-24 19:30:00.411522059+00:00,160,1,432669,A,A,64.83,1,26,8058566314722,128,14588,94225654,CLX5
2025-09-24 19:30:00.411639307+00:00,160,1,432669,A,A,64.84,1,26,8058566314723,128,15573,94225658,CLX5
2025-09-24 19:30:00.412135413+00:00,160,1,432669,A,A,64.83,2,26,8058566314726,128,18069,94225670,CLX5
2025-09-24 19:30:00.412171817+00:00,160,1,432669,A,A,64.83,1,26,8058566314728,128,16937,94225675,CLX5
2025-09-24 19:30:00.457666111+00:00,160,1,432669,A,A,64.83,1,26,8058566314750,128,19714,94225710,CLX5
2025-09-24 19:30:00.457862229+00:00,160,1,432669,C,A,64.84,1,26,8058566314723,128,18915,94225711,CLX5
2025-09-24 19:30:00.457864841+00:00,160,1,432669,C,A,64.84,1,26,8058566314711,128,15373,94225712,CLX5
2025-09-24 19:30:00.457870581+00:00,160,1,432669,C,A,64.84,1,26,8058566314710,128,15383,94225713,CLX5
2025-09-24 19:30:00.458311799+00:00,160,1,432669,C,A,64.84,1,26,8058566314639,128,18354,94225718,CLX5
2025-09-24 19:30:00.545829295+00:00,160,1,432669,M,B,64.37,4,26,8058559498241,128,18301,94225736,CLX5
2025-09-24 19:30:00.567889583+00:00,160,1,432669,M,B,64.37,4,26,8058559498258,128,18395,94225744,CLX5
2025-09-24 19:30:00.580800899+00:00,160,1,432669,C,B,64.8,1,26,8058566314647,128,18532,94225748,CLX5
2025-09-24 19:30:00.853205783+00:00,160,1,432669,A,A,64.83,3,26,8058566314782,128,19780,94225781,CLX5
2025-09-24 19:30:00.855478847+00:00,160,1,432669,C,B,64.82,1,26,8058566314624,128,18885,94225802,CLX5
2025-09-24 19:30:00.855602719+00:00,160,1,432669,A,A,64.83,1,26,8058566314797,128,15440,94225826,CLX5
2025-09-24 19:30:00.855990925+00:00,160,1,432669,C,A,64.83,1,26,8058566314797,128,18727,94225841,CLX5
2025-09-24 19:30:00.856398255+00:00,160,1,432669,A,A,64.86,1,26,8058566314803,128,13814,94225845,CLX5
2025-09-24 19:30:00.926263687+00:00,160,1,432669,A,A,64.83,2,26,8058566314816,128,18960,94225877,CLX5
2025-09-24 19:30:00.998056981+00:00,160,1,432669,A,A,64.83,1,26,8058566314818,128,19138,94225912,CLX5
2025-09-24 19:30:00.998062607+00:00,160,1,432669,C,B,64.81,2,26,8058566313321,128,19724,94225916,CLX5
2025-09-24 19:30:00.998063471+00:00,160,1,432669,C,B,64.82,2,26,8058566314622,128,14862,94225922,CLX5
2025-09-24 19:30:00.998066851+00:00,160,1,432669,C,B,64.82,1,26,8058566314579,128,19848,94225926,CLX5
2025-09-24 19:30:00.998078869+00:00,160,1,432669,A,A,64.83,1,26,8058566314820,128,15355,94225929,CLX5
2025-09-24 19:30:00.998224917+00:00,160,1,432669,C,A,64.83,1,26,8058566314820,128,17861,94225941,CLX5
2025-09-24 19:30:00.998243405+00:00,160,1,432669,C,B,64.82,3,26,8058566314643,128,15839,94225942,CLX5
2025-09-24 19:30:00.998401741+00:00,160,1,432669,A,A,64.83,1,26,8058566314826,128,15776,94225951,CLX5
2025-09-24 19:30:00.998452197+00:00,160,1,432669,C,A,64.83,1,26,8058566314826,128,15555,94225957,CLX5
2025-09-24 19:30:00.998584171+00:00,160,1,432669,C,B,64.82,1,26,8058566314389,128,15194,94225973,CLX5
2025-09-24 19:30:00.998781769+00:00,160,1,432669,A,A,64.83,1,26,8058566314832,128,18784,94225980,CLX5
2025-09-24 19:30:00.998789159+00:00,160,1,432669,A,A,64.83,1,26,8058566314833,128,15911,94225982,CLX5
2025-09-24 19:30:00.998930139+00:00,160,1,432669,C,B,64.82,1,26,8058566313063,128,15482,94225993,CLX5
2025-09-24 19:30:00.999264531+00:00,160,1,432669,C,A,64.83,1,26,8058566314833,128,15408,94226000,CLX5
2025-09-24 19:30:00.999538157+00:00,160,1,432669,A,A,64.83,1,26,8058566314835,128,15178,94226003,CLX5
2025-09-24 19:30:00.999757777+00:00,160,1,432669,C,B,64.82,1,26,8058566314167,128,15276,94226025,CLX5
2025-09-24 19:30:01.000048607+00:00,160,1,432669,A,B,64.82,1,26,8058566314839,128,15288,94226036,CLX5
2025-09-24 19:30:01.000204003+00:00,160,1,432669,A,A,64.83,1,26,8058566314841,128,14764,94226039,CLX5
2025-09-24 19:30:01.000825213+00:00,160,1,432669,A,B,64.82,1,26,8058566314852,128,15160,94226052,CLX5
2025-09-24 19:30:01.003866837+00:00,160,1,432669,A,B,64.82,1,26,8058566314853,128,19257,94226065,CLX5
2025-09-24 19:30:01.024092071+00:00,160,1,432669,C,B,64.82,1,26,8058566314852,128,18842,94226082,CLX5
2025-09-24 19:30:01.024221415+00:00,160,1,432669,M,A,64.94,1,26,8058565075241,128,14894,94226085,CLX5
2025-09-24 19:30:01.026182495+00:00,160,1,432669,M,A,64.95,1,26,8058565075241,128,18598,94226131,CLX5
2025-09-24 19:30:01.109114159+00:00,160,1,432669,A,B,64.79,2,26,8058566314879,128,18113,94226160,CLX5
2025-09-24 19:30:01.209105749+00:00,160,1,432669,A,B,64.78,2,26,8058566314889,128,19915,94226178,CLX5
2025-09-24 19:30:01.428712711+00:00,160,1,432669,C,A,64.83,1,26,8058566314750,128,19424,94226201,CLX5
2025-09-24 19:30:01.428872449+00:00,160,1,432669,A,B,64.82,1,26,8058566314905,128,19012,94226202,CLX5
2025-09-24 19:30:01.428896965+00:00,160,1,432669,C,B,64.81,1,26,8058566305478,128,15269,94226204,CLX5
2025-09-24 19:30:01.520251767+00:00,160,1,432669,A,B,64.81,2,26,8058566314917,128,14201,94226237,CLX5
2025-09-24 19:30:01.520252517+00:00,160,1,432669,A,B,64.82,2,26,8058566314921,128,15835,94226243,CLX5
2025-09-24 19:30:01.520256521+00:00,160,1,432669,C,A,64.83,1,26,8058566314835,128,15656,94226258,CLX5
2025-09-24 19:30:01.520257787+00:00,160,1,432669,A,B,64.82,1,26,8058566314930,128,15752,94226261,CLX5
2025-09-24 19:30:01.520260877+00:00,160,1,432669,C,B,64.78,2,26,8058566314889,128,14398,94226265,CLX5
2025-09-24 19:30:01.520262395+00:00,160,1,432669,C,A,64.83,1,26,8058566314818,128,21996,94226267,CLX5
2025-09-24 19:30:01.520287201+00:00,160,1,432669,C,A,64.83,1,26,8058566314841,128,15919,94226272,CLX5
2025-09-24 19:30:01.520306361+00:00,160,1,432669,C,A,64.83,2,26,8058566314816,128,15816,94226273,CLX5
2025-09-24 19:30:01.520813257+00:00,160,1,432669,C,A,64.83,1,26,8058566314832,128,16313,94226305,CLX5
2025-09-24 19:30:01.520910061+00:00,160,1,432669,C,A,64.86,1,26,8058566314803,128,14948,94226314,CLX5
2025-09-24 19:30:01.521103337+00:00,160,1,432669,A,B,64.82,1,26,8058566314950,128,18808,94226317,CLX5
2025-09-24 19:30:01.570616551+00:00,160,1,432669,A,B,64.82,5,26,8058566314979,128,16695,94226457,CLX5
2025-09-24 19:30:01.570820793+00:00,160,1,432669,C,A,64.83,1,26,8058566314728,128,19086,94226464,CLX5
2025-09-24 19:30:01.595505643+00:00,160,1,432669,C,A,64.83,2,26,8058566314726,128,20253,94226492,CLX5
2025-09-24 19:30:01.609133719+00:00,160,1,432669,C,B,64.79,2,26,8058566314879,128,19097,94226499,CLX5
2025-09-24 19:30:01.709117843+00:00,160,1,432669,A,B,64.8,2,26,8058566314994,128,18388,94226522,CLX5
2025-09-24 19:30:01.709121643+00:00,160,1,432669,A,B,64.79,2,26,8058566314995,128,15047,94226523,CLX5
2025-09-24 19:30:01.989038983+00:00,160,1,432669,T,B,64.83,6,26,8058566315004,0,18677,94226565,CLX5
2025-09-24 19:30:01.989038983+00:00,160,1,432669,F,A,64.83,2,26,8058566314696,0,18677,94226565,CLX5
2025-09-24 19:30:01.989038983+00:00,160,1,432669,F,A,64.83,1,26,8058566314722,0,18677,94226565,CLX5
2025-09-24 19:30:01.989038983+00:00,160,1,432669,F,A,64.83,3,26,8058566314782,0,18677,94226565,CLX5
2025-09-24 19:30:01.989038983+00:00,160,1,432669,C,A,64.83,2,26,8058566314696,0,14729,94226566,CLX5
2025-09-24 19:30:01.989038983+00:00,160,1,432669,C,A,64.83,1,26,8058566314722,0,14729,94226566,CLX5
2025-09-24 19:30:01.989038983+00:00,160,1,432669,C,A,64.83,3,26,8058566314782,128,14729,94226566,CLX5
2025-09-24 19:30:01.989510781+00:00,160,1,432669,A,A,64.84,1,26,8058566315040,128,17112,94226680,CLX5
2025-09-24 19:30:01.989676893+00:00,160,1,432669,A,A,64.84,1,26,8058566315047,128,16068,94226693,CLX5
2025-09-24 19:30:01.989678831+00:00,160,1,432669,C,A,64.84,1,26,8058566314633,128,17600,94226694,CLX5
2025-09-24 19:30:01.989680309+00:00,160,1,432669,A,B,64.83,1,26,8058566315049,128,15019,94226696,CLX5
2025-09-24 19:30:01.989682979+00:00,160,1,432669,C,A,64.84,1,26,8058566315040,128,14906,94226699,CLX5
2025-09-24 19:30:01.990074353+00:00,160,1,432669,A,B,64.83,1,26,8058566315054,128,14792,94226713,CLX5
2025-09-24 19:30:01.990086833+00:00,160,1,432669,A,B,64.8,1,26,8058566315055,128,15597,94226718,CLX5
2025-09-24 19:30:01.990581979+00:00,160,1,432669,A,B,64.83,2,26,8058566315063,128,14858,94226792,CLX5
2025-09-24 19:30:01.990663443+00:00,160,1,432669,A,B,64.83,2,26,8058566315072,128,17830,94226809,CLX5
2025-09-24 19:30:01.992375909+00:00,160,1,432669,A,A,64.84,1,26,8058566315091,128,15276,94226878,CLX5
2025-09-24 19:30:01.992439325+00:00,160,1,432669,C,A,64.84,1,26,8058566315047,128,19253,94226880,CLX5
2025-09-24 19:30:01.992828837+00:00,160,1,432669,A,A,64.84,1,26,8058566315093,128,15261,94226882,CLX5
2025-09-24 19:30:01.993073167+00:00,160,1,432669,M,B,64.82,3,26,8058566311409,128,16564,94226883,CLX5
2025-09-24 19:30:01.993193947+00:00,160,1,432669,A,B,64.83,1,26,8058566315094,128,17064,94226893,CLX5
2025-09-24 19:30:01.993741199+00:00,160,1,432669,M,B,64.82,4,26,8058566314979,128,19057,94226951,CLX5
2025-09-24 19:30:01.994019741+00:00,160,1,432669,C,B,64.83,2,26,8058566315072,128,20656,94226958,CLX5
2025-09-24 19:30:01.994179823+00:00,160,1,432669,C,B,64.83,2,26,8058566315063,128,15272,94226971,CLX5
2025-09-24 19:30:01.994252301+00:00,160,1,432669,C,B,64.83,1,26,8058566315054,128,17072,94226979,CLX5
2025-09-24 19:30:01.994868461+00:00,160,1,432669,M,B,64.82,2,26,8058566314979,128,15543,94227013,CLX5
2025-09-24 19:30:01.995116741+00:00,160,1,432669,A,A,64.84,1,26,8058566315118,128,19024,94227015,CLX5
2025-09-24 19:30:01.995276709+00:00,160,1,432669,C,B,64.82,2,26,8058566314979,128,15628,94227017,CLX5
2025-09-24 19:30:01.996057499+00:00,160,1,432669,T,A,64.83,2,26,8058566315122,0,14803,94227026,CLX5
2025-09-24 19:30:01.996057499+00:00,160,1,432669,F,B,64.83,1,26,8058566315049,0,14803,94227026,CLX5
2025-09-24 19:30:01.996057499+00:00,160,1,432669,F,B,64.83,1,26,8058566315094,0,14803,94227026,CLX5
2025-09-24 19:30:01.996057499+00:00,160,1,432669,C,B,64.83,1,26,8058566315049,0,18792,94227027,CLX5
2025-09-24 19:30:01.996057499+00:00,160,1,432669,C,B,64.83,1,26,8058566315094,128,18792,94227027,CLX5
2025-09-24 19:30:01.996058557+00:00,160,1,432669,A,A,64.83,1,26,8058566315123,128,18920,94227029,CLX5
2025-09-24 19:30:01.996884869+00:00,160,1,432669,M,A,64.85,1,26,8058566305433,128,15606,94227052,CLX5
2025-09-24 19:30:01.998271511+00:00,160,1,432669,A,B,64.82,1,26,8058566315140,128,16846,94227072,CLX5
2025-09-24 19:30:01.998525359+00:00,160,1,432669,C,B,64.82,1,26,8058566314853,128,15172,94227088,CLX5
2025-09-24 19:30:01.998569921+00:00,160,1,432669,A,A,64.83,1,26,8058566315148,128,14810,94227089,CLX5
2025-09-24 19:30:01.998586701+00:00,160,1,432669,C,B,64.82,1,26,8058566314930,128,15269,94227092,CLX5
2025-09-24 19:30:01.998588265+00:00,160,1,432669,A,A,64.83,2,26,8058566315151,128,14056,94227097,CLX5
2025-09-24 19:30:01.998588583+00:00,160,1,432669,C,B,64.82,1,26,8058566315140,128,15152,94227099,CLX5
2025-09-24 19:30:01.998606747+00:00,160,1,432669,A,A,64.83,1,26,8058566315154,128,17019,94227102,CLX5
2025-09-24 19:30:01.998641785+00:00,160,1,432669,A,A,64.83,2,26,8058566315156,128,20083,94227104,CLX5
2025-09-24 19:30:01.998641959+00:00,160,1,432669,A,A,64.83,1,26,8058566315157,128,16745,94227105,CLX5
2025-09-24 19:30:01.998716489+00:00,160,1,432669,M,B,63.67,4,26,8058566311409,128,15950,94227109,CLX5
2025-09-24 19:30:02.000081375+00:00,160,1,432669,C,B,64.82,2,26,8058566314921,128,15624,94227145,CLX5
2025-09-24 19:30:02.006982915+00:00,160,1,432669,M,A,64.84,1,26,8058566305433,128,18580,94227215,CLX5
2025-09-24 19:30:02.048374791+00:00,160,1,432669,A,B,64.82,5,26,8058566315208,128,18773,94227254,CLX5
2025-09-24 19:30:02.048525369+00:00,160,1,432669,C,A,64.83,2,26,8058566315156,128,19932,94227255,CLX5
2025-09-24 19:30:02.048525667+00:00,160,1,432669,C,A,64.83,1,26,8058566315157,128,15444,94227258,CLX5
2025-09-24 19:30:02.048530765+00:00,160,1,432669,C,A,64.84,1,26,8058566315118,128,18744,94227259,CLX5
2025-09-24 19:30:02.170807581+00:00,160,1,432669,C,B,64.8,1,26,8058566315055,128,19416,94227364,CLX5
2025-09-24 19:30:04.437985893+00:00,160,1,432669,C,A,65.06,1,26,8058566310050,128,23267,94227584,CLX5
2025-09-24 19:30:04.547585373+00:00,160,1,432669,A,A,65.05,1,26,8058566315368,128,24132,94227586,CLX5
2025-09-24 19:30:05.511573591+00:00,160,1,432669,C,A,64.97,1,26,8058566060211,128,20633,94227591,CLX5
2025-09-24 19:30:11.344915535+00:00,160,1,432669,T,A,64.82,1,26,8058566315605,0,18462,94228164,CLX5
2025-09-24 19:30:11.344915535+00:00,160,1,432669,F,B,64.82,1,26,8058566312886,0,18462,94228164,CLX5
2025-09-24 19:30:11.344915535+00:00,160,1,432669,M,B,64.82,2,26,8058566312886,128,15642,94228165,CLX5
2025-09-24 19:30:11.345289727+00:00,160,1,432669,T,B,64.83,5,26,8058566315609,0,17271,94228169,CLX5
2025-09-24 19:30:11.345289727+00:00,160,1,432669,F,A,64.83,1,26,8058566315123,0,17271,94228169,CLX5
2025-09-24 19:30:11.345289727+00:00,160,1,432669,F,A,64.83,1,26,8058566315148,0,17271,94228169,CLX5
2025-09-24 19:30:11.345289727+00:00,160,1,432669,F,A,64.83,2,26,8058566315151,0,17271,94228169,CLX5
2025-09-24 19:30:11.345289727+00:00,160,1,432669,F,A,64.83,1,26,8058566315154,0,17271,94228169,CLX5
2025-09-24 19:30:11.345289727+00:00,160,1,432669,C,A,64.83,1,26,8058566315123,0,15268,94228170,CLX5
2025-09-24 19:30:11.345289727+00:00,160,1,432669,C,A,64.83,1,26,8058566315148,0,15268,94228170,CLX5
2025-09-24 19:30:11.345289727+00:00,160,1,432669,C,A,64.83,2,26,8058566315151,0,15268,94228170,CLX5
2025-09-24 19:30:11.345289727+00:00,160,1,432669,C,A,64.83,1,26,8058566315154,128,15268,94228170,CLX5
2025-09-24 19:30:11.345300899+00:00,160,1,432669,A,B,64.83,2,26,8058566315610,128,17521,94228173,CLX5
2025-09-24 19:30:11.345639399+00:00,160,1,432669,A,B,64.82,2,26,8058566315615,128,15632,94228190,CLX5
2025-09-24 19:30:11.345665491+00:00,160,1,432669,A,B,64.82,1,26,8058566315620,128,15812,94228202,CLX5
2025-09-24 19:30:11.345669083+00:00,160,1,432669,A,A,64.84,1,26,8058566315621,128,15744,94228203,CLX5
2025-09-24 19:30:11.345712415+00:00,160,1,432669,A,B,64.83,2,26,8058566315625,128,14878,94228214,CLX5
2025-09-24 19:30:11.345726027+00:00,160,1,432669,A,B,64.83,1,26,8058566315626,128,17306,94228222,CLX5
2025-09-24 19:30:11.345763599+00:00,160,1,432669,A,B,64.82,3,26,8058566315628,128,15081,94228230,CLX5
2025-09-24 19:30:11.345784681+00:00,160,1,432669,A,B,64.83,2,26,8058566315630,128,17189,94228236,CLX5
2025-09-24 19:30:11.345784857+00:00,160,1,432669,A,B,64.83,1,26,8058566315631,128,19409,94228237,CLX5
2025-09-24 19:30:11.345818393+00:00,160,1,432669,A,B,64.83,1,26,8058566315632,128,19333,94228241,CLX5
2025-09-24 19:30:11.345942247+00:00,160,1,432669,C,A,64.84,1,26,8058566308520,128,15090,94228246,CLX5
2025-09-24 19:30:11.347058333+00:00,160,1,432669,M,B,64.82,3,26,8058566311409,128,15672,94228289,CLX5
2025-09-24 19:30:11.347763287+00:00,160,1,432669,A,B,64.83,1,26,8058566315658,128,19582,94228324,CLX5
2025-09-24 19:30:11.347779357+00:00,160,1,432669,M,B,64.82,4,26,8058566315208,128,15345,94228325,CLX5
2025-09-24 19:30:11.347812149+00:00,160,1,432669,M,B,64.82,3,26,8058566315208,128,14285,94228326,CLX5
2025-09-24 19:30:11.347900715+00:00,160,1,432669,M,B,64.82,2,26,8058566315208,128,18396,94228328,CLX5
2025-09-24 19:30:11.349191685+00:00,160,1,432669,A,B,64.82,1,26,8058566315665,128,17625,94228369,CLX5
2025-09-24 19:30:11.349237975+00:00,160,1,432669,A,B,64.82,1,26,8058566315666,128,19059,94228375,CLX5
2025-09-24 19:30:11.349265735+00:00,160,1,432669,A,B,64.82,1,26,8058566315667,128,15187,94228376,CLX5
2025-09-24 19:30:11.349752685+00:00,160,1,432669,M,B,64.82,1,26,8058566315208,128,15202,94228382,CLX5
2025-09-24 19:30:11.350671805+00:00,160,1,432669,A,B,64.8,1,26,8058566315674,128,18315,94228400,CLX5
2025-09-24 19:30:11.351820395+00:00,160,1,432669,A,B,64.83,1,26,8058566315677,128,15710,94228416,CLX5
2025-09-24 19:30:11.352872567+00:00,160,1,432669,C,B,64.82,1,26,8058566315208,128,18406,94228440,CLX5
2025-09-24 19:30:11.358220549+00:00,160,1,432669,M,A,64.85,1,26,8058566305433,128,18947,94228454,CLX5
2025-09-24 19:30:11.358364387+00:00,160,1,432669,C,A,64.84,1,26,8058566315621,128,14463,94228458,CLX5
2025-09-24 19:30:11.358370973+00:00,160,1,432669,C,B,64.83,1,26,8058566315658,128,14987,94228460,CLX5
2025-09-24 19:30:11.375423527+00:00,160,1,432669,A,A,64.85,1,26,8058566315687,128,21093,94228485,CLX5
2025-09-24 19:30:11.375575659+00:00,160,1,432669,C,B,64.83,1,26,8058566315677,128,19595,94228486,CLX5
2025-09-24 19:30:11.375730733+00:00,160,1,432669,C,B,64.82,1,26,8058566315667,128,15286,94228488,CLX5
2025-09-24 19:30:11.375743711+00:00,160,1,432669,C,B,64.82,1,26,8058566315666,128,15363,94228491,CLX5
2025-09-24 19:30:11.375747841+00:00,160,1,432669,C,B,64.82,1,26,8058566315665,128,14511,94228492,CLX5
2025-09-24 19:30:11.378000477+00:00,160,1,432669,T,A,64.83,1,26,8058566315688,0,18968,94228493,CLX5
2025-09-24 19:30:11.378000477+00:00,160,1,432669,F,B,64.83,1,26,8058566315610,0,18968,94228493,CLX5
2025-09-24 19:30:11.378000477+00:00,160,1,432669,M,B,64.83,1,26,8058566315610,128,16221,94228494,CLX5
2025-09-24 19:30:11.378298849+00:00,160,1,432669,A,A,64.84,1,26,8058566315689,128,15411,94228496,CLX5
2025-09-24 19:30:11.440910343+00:00,160,1,432669,M,A,64.84,1,26,8058566305433,128,19405,94228532,CLX5
2025-09-24 19:30:11.441056851+00:00,160,1,432669,C,A,64.84,1,26,8058566315689,128,15136,94228536,CLX5
2025-09-24 19:30:12.379732257+00:00,160,1,432669,A,A,64.84,1,26,8058566315833,128,18608,94228933,CLX5
2025-09-24 19:30:12.379874253+00:00,160,1,432669,C,B,64.83,1,26,8058566315631,128,16187,94228936,CLX5
2025-09-24 19:30:12.379906393+00:00,160,1,432669,A,A,64.84,1,26,8058566315834,128,18184,94228937,CLX5
2025-09-24 19:30:12.380046181+00:00,160,1,432669,C,B,64.83,2,26,8058566315625,128,20467,94228938,CLX5
2025-09-24 19:30:12.380046489+00:00,160,1,432669,C,B,64.83,2,26,8058566315630,128,13977,94228939,CLX5
2025-09-24 19:30:12.380081259+00:00,160,1,432669,A,A,64.84,1,26,8058566315835,128,15752,94228941,CLX5
2025-09-24 19:30:12.400009653+00:00,160,1,432669,C,B,64.83,1,26,8058566315632,128,19615,94228953,CLX5
2025-09-24 19:30:12.417761345+00:00,160,1,432669,T,A,64.83,2,26,8058566315841,0,19067,94228966,CLX5
2025-09-24 19:30:12.417761345+00:00,160,1,432669,F,B,64.83,1,26,8058566315610,0,19067,94228966,CLX5
2025-09-24 19:30:12.417761345+00:00,160,1,432669,F,B,64.83,1,26,8058566315626,0,19067,94228966,CLX5
2025-09-24 19:30:12.417761345+00:00,160,1,432669,C,B,64.83,1,26,8058566315610,0,15132,94228967,CLX5
2025-09-24 19:30:12.417761345+00:00,160,1,432669,C,B,64.83,1,26,8058566315626,128,15132,94228967,CLX5
2025-09-24 19:30:12.418339603+00:00,160,1,432669,M,B,63.67,4,26,8058566311409,128,15700,94228998,CLX5
2025-09-24 19:30:12.418517177+00:00,160,1,432669,C,B,64.8,1,26,8058566315674,128,17349,94229007,CLX5
2025-09-24 19:30:12.426480909+00:00,160,1,432669,A,A,64.83,3,26,8058566315883,128,18449,94229113,CLX5
2025-09-24 19:30:12.426705675+00:00,160,1,432669,A,A,64.84,1,26,8058566315884,128,18319,94229117,CLX5
2025-09-24 19:30:12.426715503+00:00,160,1,432669,A,A,64.83,1,26,8058566315889,128,22674,94229124,CLX5
2025-09-24 19:30:12.437533037+00:00,160,1,432669,M,B,64.82,1,26,8058566314284,128,18058,94229185,CLX5
2025-09-24 19:30:12.437720383+00:00,160,1,432669,C,A,64.84,1,26,8058566315835,128,15091,94229187,CLX5
2025-09-24 19:30:12.437731729+00:00,160,1,432669,C,A,64.84,1,26,8058566315834,128,17250,94229188,CLX5
2025-09-24 19:30:12.437735837+00:00,160,1,432669,C,A,64.84,1,26,8058566315833,128,15089,94229189,CLX5
2025-09-24 19:30:13.344934115+00:00,160,1,432669,T,A,64.82,1,26,8058566316000,0,19190,94229380,CLX5
2025-09-24 19:30:13.344934115+00:00,160,1,432669,F,B,64.82,1,26,8058566312886,0,19190,94229380,CLX5
2025-09-24 19:30:13.344934115+00:00,160,1,432669,M,B,64.82,1,26,8058566312886,128,15553,94229381,CLX5
2025-09-24 19:30:16.285865443+00:00,160,1,432669,T,B,64.83,2,26,8058566316025,0,30218,94229430,CLX5
2025-09-24 19:30:16.285865443+00:00,160,1,432669,F,A,64.83,2,26,8058566315883,0,30218,94229430,CLX5
2025-09-24 19:30:16.285865443+00:00,160,1,432669,M,A,64.83,1,26,8058566315883,128,17154,94229431,CLX5
2025-09-24 19:30:16.286205099+00:00,160,1,432669,T,B,64.83,2,26,8058566316030,0,18009,94229442,CLX5
2025-09-24 19:30:16.286205099+00:00,160,1,432669,F,A,64.83,1,26,8058566315883,0,18009,94229442,CLX5
2025-09-24 19:30:16.286205099+00:00,160,1,432669,F,A,64.83,1,26,8058566315889,0,18009,94229442,CLX5
2025-09-24 19:30:16.286205099+00:00,160,1,432669,C,A,64.83,1,26,8058566315883,0,18009,94229442,CLX5
2025-09-24 19:30:16.286205099+00:00,160,1,432669,C,A,64.83,1,26,8058566315889,128,18009,94229442,CLX5
2025-09-24 19:30:16.286627765+00:00,160,1,432669,A,A,64.84,1,26,8058566316031,128,17653,94229451,CLX5
2025-09-24 19:30:16.286665111+00:00,160,1,432669,A,B,64.82,1,26,8058566316035,128,17971,94229464,CLX5
2025-09-24 19:30:16.741276793+00:00,160,1,432669,M,A,64.98,1,26,8058566157942,128,18144,94229534,CLX5
2025-09-24 19:30:17.199058545+00:00,160,1,432669,A,A,64.84,1,26,8058566316078,128,19354,94229566,CLX5
2025-09-24 19:30:18.148699065+00:00,160,1,432669,C,A,64.85,1,26,8058566315687,128,17877,94229661,CLX5
2025-09-24 19:30:18.162002195+00:00,160,1,432669,A,A,64.84,1,26,8058566316117,128,18580,94229678,CLX5
2025-09-24 19:30:18.162164485+00:00,160,1,432669,C,A,64.84,1,26,8058566316031,128,18707,94229679,CLX5
2025-09-24 19:30:19.837502365+00:00,160,1,432669,A,A,64.83,2,26,8058566316187,128,18053,94229828,CLX5
2025-09-24 19:30:19.837721525+00:00,160,1,432669,A,A,64.83,1,26,8058566316189,128,14899,94229837,CLX5
2025-09-24 19:30:19.837866499+00:00,160,1,432669,C,A,64.84,1,26,8058566316117,128,15724,94229847,CLX5
2025-09-24 19:30:19.838199851+00:00,160,1,432669,A,A,64.84,1,26,8058566316194,128,15108,94229852,CLX5
2025-09-24 19:30:19.888333355+00:00,160,1,432669,A,A,64.83,1,26,8058566316199,128,18299,94229864,CLX5
2025-09-24 19:30:19.888509371+00:00,160,1,432669,T,B,64.83,4,26,8058566316200,0,17487,94229866,CLX5
2025-09-24 19:30:19.888509371+00:00,160,1,432669,F,A,64.83,2,26,8058566316187,0,17487,94229866,CLX5
2025-09-24 19:30:19.888509371+00:00,160,1,432669,F,A,64.83,1,26,8058566316189,0,17487,94229866,CLX5
2025-09-24 19:30:19.888509371+00:00,160,1,432669,F,A,64.83,1,26,8058566316199,0,17487,94229866,CLX5
2025-09-24 19:30:19.888509371+00:00,160,1,432669,C,A,64.83,2,26,8058566316187,0,14732,94229867,CLX5
2025-09-24 19:30:19.888509371+00:00,160,1,432669,C,A,64.83,1,26,8058566316189,0,14732,94229867,CLX5
2025-09-24 19:30:19.888509371+00:00,160,1,432669,C,A,64.83,1,26,8058566316199,128,14732,94229867,CLX5
2025-09-24 19:30:19.888519355+00:00,160,1,432669,A,B,64.83,1,26,8058566316201,128,18306,94229870,CLX5
2025-09-24 19:30:19.888537633+00:00,160,1,432669,C,A,64.84,1,26,8058566316194,128,19329,94229872,CLX5
2025-09-24 19:30:19.888878841+00:00,160,1,432669,A,A,64.84,1,26,8058566316205,128,16034,94229884,CLX5
2025-09-24 19:30:19.889468581+00:00,160,1,432669,A,B,64.8,1,26,8058566316211,128,15339,94229921,CLX5
2025-09-24 19:30:21.275960883+00:00,160,1,432669,M,B,64.82,3,26,8058566311409,128,21306,94230276,CLX5
2025-09-24 19:30:21.331750457+00:00,160,1,432669,T,A,64.83,1,26,8058566316343,0,19092,94230277,CLX5
2025-09-24 19:30:21.331750457+00:00,160,1,432669,F,B,64.83,1,26,8058566316201,0,19092,94230277,CLX5
2025-09-24 19:30:21.331750457+00:00,160,1,432669,C,B,64.83,1,26,8058566316201,128,14871,94230278,CLX5
2025-09-24 19:30:21.332074441+00:00,160,1,432669,C,A,64.84,1,26,8058566316205,128,18575,94230287,CLX5
2025-09-24 19:30:21.332281715+00:00,160,1,432669,M,B,63.67,4,26,8058566311409,128,14584,94230295,CLX5
2025-09-24 19:30:21.332291967+00:00,160,1,432669,A,A,64.84,1,26,8058566316347,128,18603,94230296,CLX5
2025-09-24 19:30:21.332320613+00:00,160,1,432669,A,A,64.84,1,26,8058566316348,128,15156,94230297,CLX5
2025-09-24 19:30:21.332383911+00:00,160,1,432669,A,A,64.84,1,26,8058566316349,128,15364,94230301,CLX5
2025-09-24 19:30:21.332504215+00:00,160,1,432669,A,A,64.84,1,26,8058566316350,128,14403,94230302,CLX5
2025-09-24 19:30:21.332574715+00:00,160,1,432669,C,A,64.84,1,26,8058566316350,128,16048,94230303,CLX5
2025-09-24 19:30:21.332585887+00:00,160,1,432669,C,B,64.8,1,26,8058566316211,128,18119,94230304,CLX5
2025-09-24 19:30:21.782172409+00:00,160,1,432669,C,A,64.84,1,26,8058566316349,128,20495,94230334,CLX5
2025-09-24 19:30:21.782185215+00:00,160,1,432669,C,A,64.84,1,26,8058566316348,128,15954,94230335,CLX5
2025-09-24 19:30:21.782195715+00:00,160,1,432669,C,A,64.84,1,26,8058566316347,128,15415,94230336,CLX5
2025-09-24 19:30:22.403122069+00:00,160,1,432669,A,A,64.84,1,26,8058566316388,128,17892,94230413,CLX5
2025-09-24 19:30:24.859102505+00:00,160,1,432669,C,A,64.84,1,26,8058566316388,128,16265,94230694,CLX5
2025-09-24 19:30:24.859417101+00:00,160,1,432669,A,A,64.84,1,26,8058566316473,128,15658,94230703,CLX5
2025-09-24 19:30:24.859617117+00:00,160,1,432669,C,A,64.84,1,26,8058566316473,128,18734,94230708,CLX5
2025-09-24 19:30:26.085376981+00:00,160,1,432669,A,A,64.84,1,26,8058566316525,128,19154,94230849,CLX5
2025-09-24 19:30:26.548911745+00:00,160,1,432669,A,B,64.83,1,26,8058566316563,128,14288,94230963,CLX5
2025-09-24 19:30:26.549751747+00:00,160,1,432669,C,A,64.84,1,26,8058566315093,128,18901,94231077,CLX5
2025-09-24 19:30:26.549847723+00:00,160,1,432669,A,B,64.83,1,26,8058566316595,128,18424,94231083,CLX5
2025-09-24 19:30:26.550275577+00:00,160,1,432669,A,B,64.8,1,26,8058566316599,128,15206,94231111,CLX5
2025-09-24 19:30:26.554982479+00:00,160,1,432669,A,A,64.84,1,26,8058566316632,128,15525,94231274,CLX5
2025-09-24 19:30:26.555320749+00:00,160,1,432669,C,A,64.84,1,26,8058566316525,128,15690,94231290,CLX5
2025-09-24 19:30:26.558515853+00:00,160,1,432669,M,A,64.85,1,26,8058566305433,128,16903,94231310,CLX5
2025-09-24 19:30:26.558648449+00:00,160,1,432669,A,A,64.84,1,26,8058566316638,128,15071,94231318,CLX5
2025-09-24 19:30:26.558900393+00:00,160,1,432669,C,A,64.84,1,26,8058566316638,128,18674,94231319,CLX5
2025-09-24 19:30:26.605007351+00:00,160,1,432669,T,A,64.83,2,26,8058566316656,0,17915,94231354,CLX5
2025-09-24 19:30:26.605007351+00:00,160,1,432669,F,B,64.83,1,26,8058566316563,0,17915,94231354,CLX5
2025-09-24 19:30:26.605007351+00:00,160,1,432669,F,B,64.83,1,26,8058566316595,0,17915,94231354,CLX5
2025-09-24 19:30:26.605007351+00:00,160,1,432669,C,B,64.83,1,26,8058566316563,0,15160,94231355,CLX5
2025-09-24 19:30:26.605007351+00:00,160,1,432669,C,B,64.83,1,26,8058566316595,128,15160,94231355,CLX5
2025-09-24 19:30:26.605268729+00:00,160,1,432669,A,A,64.84,1,26,8058566316659,128,16068,94231360,CLX5
2025-09-24 19:30:26.605402105+00:00,160,1,432669,A,A,64.84,1,26,8058566316661,128,18880,94231366,CLX5
2025-09-24 19:30:26.605454809+00:00,160,1,432669,A,A,64.84,1,26,8058566316662,128,15304,94231367,CLX5
2025-09-24 19:30:26.605625583+00:00,160,1,432669,C,A,64.84,1,26,8058566316659,128,19313,94231370,CLX5
2025-09-24 19:30:26.605647971+00:00,160,1,432669,A,A,64.84,1,26,8058566316665,128,15381,94231372,CLX5
2025-09-24 19:30:26.611007663+00:00,160,1,432669,C,A,64.84,1,26,8058566316665,128,18582,94231384,CLX5
2025-09-24 19:30:26.611017819+00:00,160,1,432669,C,A,64.84,1,26,8058566316662,128,14568,94231385,CLX5
2025-09-24 19:30:26.611022485+00:00,160,1,432669,C,A,64.84,1,26,8058566316661,128,15611,94231386,CLX5
2025-09-24 19:30:26.611190555+00:00,160,1,432669,A,A,64.84,1,26,8058566316669,128,19006,94231387,CLX5
2025-09-24 19:30:26.730941647+00:00,160,1,432669,C,B,64.8,1,26,8058566316599,128,19268,94231483,CLX5
2025-09-24 19:30:31.742717865+00:00,160,1,432669,M,A,64.84,1,26,8058566305433,128,19346,94232040,CLX5
2025-09-24 19:30:32.242934813+00:00,160,1,432669,M,A,64.85,1,26,8058566305433,128,18665,94232086,CLX5
2025-09-24 19:30:34.352561815+00:00,160,1,432669,T,B,64.84,1,26,8058566317039,0,21344,94232193,CLX5
2025-09-24 19:30:34.352561815+00:00,160,1,432669,F,A,64.84,1,26,8058566274047,0,21344,94232193,CLX5
2025-09-24 19:30:34.352561815+00:00,160,1,432669,C,A,64.84,1,26,8058566274047,128,18157,94232194,CLX5
2025-09-24 19:30:34.352881711+00:00,160,1,432669,A,B,64.83,2,26,8058566317040,128,24452,94232195,CLX5
2025-09-24 19:30:34.352888449+00:00,160,1,432669,C,A,64.84,1,26,8058566316669,128,22207,94232206,CLX5
2025-09-24 19:30:34.352911315+00:00,160,1,432669,C,B,64.83,2,26,8058566317040,128,19567,94232210,CLX5
2025-09-24 19:30:34.353178837+00:00,160,1,432669,A,A,64.84,1,26,8058566317050,128,15363,94232229,CLX5
2025-09-24 19:30:34.353194773+00:00,160,1,432669,A,A,64.84,1,26,8058566317051,128,17367,94232232,CLX5
2025-09-24 19:30:34.353203431+00:00,160,1,432669,A,B,64.83,1,26,8058566317052,128,15216,94232234,CLX5
2025-09-24 19:30:34.353257323+00:00,160,1,432669,T,A,64.83,1,26,8058566317053,0,18451,94232237,CLX5
2025-09-24 19:30:34.353257323+00:00,160,1,432669,F,B,64.83,1,26,8058566317052,0,18451,94232237,CLX5
2025-09-24 19:30:34.353257323+00:00,160,1,432669,C,B,64.83,1,26,8058566317052,128,18451,94232237,CLX5
2025-09-24 19:30:34.353257515+00:00,160,1,432669,A,A,64.83,2,26,8058566317054,128,18697,94232240,CLX5
2025-09-24 19:30:34.353257695+00:00,160,1,432669,A,A,64.83,1,26,8058566317055,128,15093,94232243,CLX5
2025-09-24 19:30:34.353626773+00:00,160,1,432669,A,A,64.83,2,26,8058566317060,128,18376,94232264,CLX5
2025-09-24 19:30:34.353693797+00:00,160,1,432669,A,B,64.8,1,26,8058566317062,128,17381,94232269,CLX5
2025-09-24 19:30:34.353983435+00:00,160,1,432669,C,B,64.82,1,26,8058566315620,128,15864,94232277,CLX5
2025-09-24 19:30:34.354009525+00:00,160,1,432669,A,A,64.83,1,26,8058566317067,128,19709,94232279,CLX5
2025-09-24 19:30:34.354553247+00:00,160,1,432669,T,B,64.83,5,26,8058566317077,0,15212,94232300,CLX5
2025-09-24 19:30:34.354553247+00:00,160,1,432669,F,A,64.83,2,26,8058566317054,0,15212,94232300,CLX5
2025-09-24 19:30:34.354553247+00:00,160,1,432669,F,A,64.83,1,26,8058566317055,0,15212,94232300,CLX5
2025-09-24 19:30:34.354553247+00:00,160,1,432669,F,A,64.83,2,26,8058566317060,0,15212,94232300,CLX5
2025-09-24 19:30:34.354553247+00:00,160,1,432669,C,A,64.83,2,26,8058566317054,0,15263,94232301,CLX5
2025-09-24 19:30:34.354553247+00:00,160,1,432669,C,A,64.83,1,26,8058566317055,0,15263,94232301,CLX5
2025-09-24 19:30:34.354553247+00:00,160,1,432669,C,A,64.83,2,26,8058566317060,128,15263,94232301,CLX5
2025-09-24 19:30:34.354565303+00:00,160,1,432669,T,B,64.83,1,26,8058566317078,0,15080,94232307,CLX5
2025-09-24 19:30:34.354565303+00:00,160,1,432669,F,A,64.83,1,26,8058566317067,0,15080,94232307,CLX5
2025-09-24 19:30:34.354565303+00:00,160,1,432669,A,B,64.83,1,26,8058566317078,0,15080,94232307,CLX5
2025-09-24 19:30:34.354565303+00:00,160,1,432669,C,A,64.83,1,26,8058566317067,128,15080,94232307,CLX5
2025-09-24 19:30:34.354577225+00:00,160,1,432669,T,A,64.83,1,26,8058566317079,0,15111,94232315,CLX5
2025-09-24 19:30:34.354577225+00:00,160,1,432669,F,B,64.83,1,26,8058566317078,0,15111,94232315,CLX5
2025-09-24 19:30:34.354577225+00:00,160,1,432669,C,B,64.83,1,26,8058566317078,0,15111,94232315,CLX5
2025-09-24 19:30:34.354577225+00:00,160,1,432669,A,A,64.83,1,26,8058566317079,128,15111,94232315,CLX5
2025-09-24 19:30:34.355479989+00:00,160,1,432669,A,B,64.82,1,26,8058566317092,128,15110,94232367,CLX5
2025-09-24 19:30:34.355488515+00:00,160,1,432669,T,B,64.83,1,26,8058566317094,0,15295,94232370,CLX5
2025-09-24 19:30:34.355488515+00:00,160,1,432669,F,A,64.83,1,26,8058566317079,0,15295,94232370,CLX5
2025-09-24 19:30:34.355488515+00:00,160,1,432669,C,A,64.83,1,26,8058566317079,128,18636,94232371,CLX5
2025-09-24 19:30:34.355612407+00:00,160,1,432669,A,B,64.83,1,26,8058566317099,128,16335,94232387,CLX5
2025-09-24 19:30:34.355620259+00:00,160,1,432669,C,B,64.82,1,26,8058566317092,128,15743,94232392,CLX5
2025-09-24 19:30:34.355768437+00:00,160,1,432669,T,A,64.83,1,26,8058566317105,0,14612,94232405,CLX5
2025-09-24 19:30:34.355768437+00:00,160,1,432669,F,B,64.83,1,26,8058566317099,0,14612,94232405,CLX5
2025-09-24 19:30:34.355768437+00:00,160,1,432669,C,B,64.83,1,26,8058566317099,128,18553,94232406,CLX5
2025-09-24 19:30:34.356145569+00:00,160,1,432669,A,B,64.82,1,26,8058566317107,128,14873,94232411,CLX5
2025-09-24 19:30:34.356268135+00:00,160,1,432669,A,A,64.83,1,26,8058566317112,128,14900,94232428,CLX5
2025-09-24 19:30:34.356549441+00:00,160,1,432669,T,B,64.83,1,26,8058566317113,0,14843,94232434,CLX5
2025-09-24 19:30:34.356549441+00:00,160,1,432669,F,A,64.83,1,26,8058566317112,0,14843,94232434,CLX5
2025-09-24 19:30:34.356549441+00:00,160,1,432669,C,A,64.83,1,26,8058566317112,128,19733,94232435,CLX5
2025-09-24 19:30:34.357618719+00:00,160,1,432669,A,B,64.82,1,26,8058566317120,128,14449,94232459,CLX5
2025-09-24 19:30:34.474947355+00:00,160,1,432669,M,A,64.84,1,26,8058566305433,128,18784,94232537,CLX5
2025-09-24 19:30:34.475133509+00:00,160,1,432669,C,B,64.82,1,26,8058566317120,128,14279,94232547,CLX5
2025-09-24 19:30:34.475496181+00:00,160,1,432669,C,B,64.82,1,26,8058566317107,128,15152,94232549,CLX5
2025-09-24 19:30:34.530989433+00:00,160,1,432669,C,B,64.8,1,26,8058566317062,128,20988,94232564,CLX5
2025-09-24 19:30:34.664047861+00:00,160,1,432669,A,A,64.84,1,26,8058566317159,128,18363,94232595,CLX5
2025-09-24 19:30:34.668204035+00:00,160,1,432669,T,A,64.82,1,26,8058566317160,0,18374,94232596,CLX5
2025-09-24 19:30:34.668204035+00:00,160,1,432669,F,B,64.82,1,26,8058566312886,0,18374,94232596,CLX5
2025-09-24 19:30:34.668204035+00:00,160,1,432669,C,B,64.82,1,26,8058566312886,128,15157,94232597,CLX5
2025-09-24 19:30:34.668483209+00:00,160,1,432669,A,A,64.83,2,26,8058566317162,128,18082,94232602,CLX5
2025-09-24 19:30:34.668486167+00:00,160,1,432669,A,A,64.83,2,26,8058566317163,128,15061,94232605,CLX5
2025-09-24 19:30:34.668771869+00:00,160,1,432669,A,A,64.83,1,26,8058566317168,128,21374,94232613,CLX5
2025-09-24 19:30:34.668810613+00:00,160,1,432669,C,A,64.83,2,26,8058566317162,128,18787,94232616,CLX5
2025-09-24 19:30:34.670471551+00:00,160,1,432669,A,A,64.83,1,26,8058566317181,128,21681,94232650,CLX5
2025-09-24 19:30:35.012777673+00:00,160,1,432669,C,A,64.83,1,26,8058566317181,128,20425,94232711,CLX5
2025-09-24 19:30:35.013741873+00:00,160,1,432669,A,B,64.82,1,26,8058566317207,128,18271,94232723,CLX5
2025-09-24 19:30:35.013916623+00:00,160,1,432669,C,A,64.83,1,26,8058566317168,128,21523,94232725,CLX5
2025-09-24 19:30:35.792971665+00:00,160,1,432669,A,A,64.83,1,26,8058566317233,128,17935,94232801,CLX5
2025-09-24 19:30:35.792978729+00:00,160,1,432669,C,B,64.8,2,26,8058566314994,128,14125,94232803,CLX5
2025-09-24 19:30:35.793021813+00:00,160,1,432669,A,A,64.83,2,26,8058566317236,128,14833,94232816,CLX5
2025-09-24 19:30:35.793096729+00:00,160,1,432669,A,A,64.83,1,26,8058566317237,128,15718,94232818,CLX5
2025-09-24 19:30:35.793345549+00:00,160,1,432669,C,A,64.83,2,26,8058566317236,128,28341,94232820,CLX5
2025-09-24 19:30:35.909236227+00:00,160,1,432669,A,B,64.8,2,26,8058566317244,128,19600,94232844,CLX5
2025-09-24 19:30:40.215027601+00:00,160,1,432669,T,B,64.83,4,26,8058566317319,0,22552,94233005,CLX5
2025-09-24 19:30:40.215027601+00:00,160,1,432669,F,A,64.83,2,26,8058566317163,0,22552,94233005,CLX5
2025-09-24 19:30:40.215027601+00:00,160,1,432669,F,A,64.83,1,26,8058566317233,0,22552,94233005,CLX5
2025-09-24 19:30:40.215027601+00:00,160,1,432669,F,A,64.83,1,26,8058566317237,0,22552,94233005,CLX5
2025-09-24 19:30:40.215027601+00:00,160,1,432669,A,B,64.83,1,26,8058566317319,0,18558,94233006,CLX5
2025-09-24 19:30:40.215027601+00:00,160,1,432669,C,A,64.83,2,26,8058566317163,0,18558,94233006,CLX5
2025-09-24 19:30:40.215027601+00:00,160,1,432669,C,A,64.83,1,26,8058566317233,0,18558,94233006,CLX5
2025-09-24 19:30:40.215027601+00:00,160,1,432669,C,A,64.83,1,26,8058566317237,128,18558,94233006,CLX5
2025-09-24 19:30:40.215364969+00:00,160,1,432669,C,A,64.84,1,26,8058566317051,128,23066,94233011,CLX5
2025-09-24 19:30:40.215431147+00:00,160,1,432669,A,B,64.82,1,26,8058566317325,128,18595,94233018,CLX5
2025-09-24 19:30:40.215531809+00:00,160,1,432669,A,A,64.84,1,26,8058566317329,128,15334,94233038,CLX5
2025-09-24 19:30:40.216071441+00:00,160,1,432669,A,B,64.8,1,26,8058566317334,128,14830,94233053,CLX5
2025-09-24 19:30:40.223683751+00:00,160,1,432669,M,A,64.85,1,26,8058566305433,128,18750,94233140,CLX5
2025-09-24 19:30:40.223877549+00:00,160,1,432669,A,A,64.84,1,26,8058566317358,128,15834,94233145,CLX5
2025-09-24 19:30:40.224031063+00:00,160,1,432669,A,A,64.84,1,26,8058566317359,128,18728,94233148,CLX5
2025-09-24 19:30:40.224187999+00:00,160,1,432669,A,A,64.84,1,26,8058566317360,128,19542,94233150,CLX5
2025-09-24 19:30:40.250747799+00:00,160,1,432669,T,A,64.83,1,26,8058566317365,0,20121,94233160,CLX5
2025-09-24 19:30:40.250747799+00:00,160,1,432669,F,B,64.83,1,26,8058566317319,0,20121,94233160,CLX5
2025-09-24 19:30:40.250747799+00:00,160,1,432669,C,B,64.83,1,26,8058566317319,128,15268,94233161,CLX5
2025-09-24 19:30:40.251011865+00:00,160,1,432669,C,A,64.84,1,26,8058566317329,128,18331,94233170,CLX5
2025-09-24 19:30:40.251212171+00:00,160,1,432669,C,B,64.82,1,26,8058566317325,128,16226,94233174,CLX5
2025-09-24 19:30:40.258672731+00:00,160,1,432669,M,A,64.84,1,26,8058566305433,128,19287,94233184,CLX5
2025-09-24 19:30:40.258846963+00:00,160,1,432669,C,A,64.84,1,26,8058566317360,128,18355,94233185,CLX5
2025-09-24 19:30:40.258853297+00:00,160,1,432669,C,A,64.84,1,26,8058566317359,128,14960,94233186,CLX5
2025-09-24 19:30:40.258864069+00:00,160,1,432669,C,A,64.84,1,26,8058566317358,128,15396,94233187,CLX5
2025-09-24 19:30:40.259073475+00:00,160,1,432669,A,A,64.84,1,26,8058566317370,128,14274,94233192,CLX5
2025-09-24 19:30:40.259221845+00:00,160,1,432669,C,A,64.84,1,26,8058566317370,128,18422,94233193,CLX5
2025-09-24 19:30:40.315972029+00:00,160,1,432669,A,A,64.84,1,26,8058566317376,128,18546,94233209,CLX5
2025-09-24 19:30:40.401023607+00:00,160,1,432669,C,B,64.8,1,26,8058566317334,128,18227,94233228,CLX5
2025-09-24 19:30:44.709674249+00:00,160,1,432669,A,A,64.89,2,26,8058566317481,128,26222,94233446,CLX5
2025-09-24 19:30:45.016880903+00:00,160,1,432669,C,A,64.84,1,26,8058566317376,128,21578,94233463,CLX5
2025-09-24 19:30:45.750889213+00:00,160,1,432669,A,A,64.83,2,26,8058566317514,128,13889,94233533,CLX5
2025-09-24 19:30:45.751074985+00:00,160,1,432669,A,A,64.83,2,26,8058566317579,128,18500,94233672,CLX5
2025-09-24 19:30:45.751276441+00:00,160,1,432669,A,A,64.83,2,26,8058566317601,128,16915,94233720,CLX5
2025-09-24 19:30:45.751875933+00:00,160,1,432669,C,B,64.8,2,26,8058566317244,128,14801,94233809,CLX5
2025-09-24 19:30:45.751893137+00:00,160,1,432669,A,A,64.83,1,26,8058566317631,128,16920,94233815,CLX5
2025-09-24 19:30:45.752273873+00:00,160,1,432669,A,A,64.83,1,26,8058566317639,128,16998,94233842,CLX5
2025-09-24 19:30:45.752431941+00:00,160,1,432669,A,A,64.83,1,26,8058566317644,128,20342,94233882,CLX5
2025-09-24 19:30:45.752529241+00:00,160,1,432669,A,A,64.83,1,26,8058566317646,128,16014,94233902,CLX5
2025-09-24 19:30:45.752534177+00:00,160,1,432669,C,B,64.79,2,26,8058566314995,128,15047,94233905,CLX5
2025-09-24 19:30:45.753051767+00:00,160,1,432669,C,B,64.81,2,26,8058566314917,128,17581,94233958,CLX5
2025-09-24 19:30:45.753052517+00:00,160,1,432669,C,B,64.82,1,26,8058566316035,128,15318,94233959,CLX5
2025-09-24 19:30:45.753052813+00:00,160,1,432669,C,B,64.82,1,26,8058566317207,128,15445,94233962,CLX5
2025-09-24 19:30:45.753052965+00:00,160,1,432669,A,A,64.83,2,26,8058566317660,128,16046,94233964,CLX5
2025-09-24 19:30:45.753053291+00:00,160,1,432669,A,A,64.83,2,26,8058566317661,128,18730,94233966,CLX5
2025-09-24 19:30:45.753053467+00:00,160,1,432669,A,A,64.83,1,26,8058566317662,128,15352,94233967,CLX5
2025-09-24 19:30:45.753166923+00:00,160,1,432669,C,B,64.82,2,26,8058566315615,128,15424,94233991,CLX5
2025-09-24 19:30:45.753277013+00:00,160,1,432669,A,A,64.83,1,26,8058566317666,128,14490,94234006,CLX5
2025-09-24 19:30:45.753279603+00:00,160,1,432669,A,A,64.83,1,26,8058566317667,128,15791,94234007,CLX5
2025-09-24 19:30:45.754296083+00:00,160,1,432669,A,A,64.83,1,26,8058566317696,128,16146,94234104,CLX5
2025-09-24 19:30:45.754477305+00:00,160,1,432669,A,A,64.86,1,26,8058566317700,128,14108,94234120,CLX5
2025-09-24 19:30:45.754761373+00:00,160,1,432669,T,B,64.83,4,26,8058566317705,0,18328,94234132,CLX5
2025-09-24 19:30:45.754761373+00:00,160,1,432669,F,A,64.83,2,26,8058566317514,0,18328,94234132,CLX5
2025-09-24 19:30:45.754761373+00:00,160,1,432669,F,A,64.83,2,26,8058566317579,0,18328,94234132,CLX5
2025-09-24 19:30:45.754761373+00:00,160,1,432669,C,A,64.83,2,26,8058566317514,0,16877,94234133,CLX5
2025-09-24 19:30:45.754761373+00:00,160,1,432669,C,A,64.83,2,26,8058566317579,128,16877,94234133,CLX5
2025-09-24 19:30:45.754772663+00:00,160,1,432669,T,B,64.83,1,26,8058566317706,0,14279,94234134,CLX5
2025-09-24 19:30:45.754772663+00:00,160,1,432669,F,A,64.83,1,26,8058566317601,0,14279,94234134,CLX5
2025-09-24 19:30:45.754772663+00:00,160,1,432669,M,A,64.83,1,26,8058566317601,128,14279,94234134,CLX5
2025-09-24 19:30:45.754824865+00:00,160,1,432669,C,A,64.83,2,26,8058566317660,128,15634,94234138,CLX5
2025-09-24 19:30:45.754825019+00:00,160,1,432669,C,A,64.83,1,26,8058566317662,128,16012,94234139,CLX5
2025-09-24 19:30:45.755656113+00:00,160,1,432669,M,A,64.94,1,26,8058565075241,128,14546,94234191,CLX5
2025-09-24 19:30:45.756128623+00:00,160,1,432669,C,A,64.83,1,26,8058566317601,128,16321,94234213,CLX5
2025-09-24 19:30:45.756190905+00:00,160,1,432669,C,A,64.83,1,26,8058566317639,128,16102,94234218,CLX5
2025-09-24 19:30:45.757133873+00:00,160,1,432669,C,A,64.83,2,26,8058566317661,128,15396,94234275,CLX5
2025-09-24 19:30:45.757785507+00:00,160,1,432669,A,B,64.82,2,26,8058566317765,128,15175,94234317,CLX5
2025-09-24 19:30:45.757913817+00:00,160,1,432669,A,B,64.82,2,26,8058566317770,128,18419,94234334,CLX5
2025-09-24 19:30:45.758296247+00:00,160,1,432669,C,A,64.83,1,26,8058566317666,128,16947,94234359,CLX5
2025-09-24 19:30:45.758890365+00:00,160,1,432669,A,B,64.82,2,26,8058566317788,128,14995,94234378,CLX5
2025-09-24 19:30:45.758937863+00:00,160,1,432669,C,A,64.83,1,26,8058566317667,128,17204,94234380,CLX5
2025-09-24 19:30:45.758938687+00:00,160,1,432669,A,B,64.82,1,26,8058566317789,128,15104,94234381,CLX5
2025-09-24 19:30:45.758941299+00:00,160,1,432669,T,B,64.83,2,26,8058566317790,0,15223,94234382,CLX5
2025-09-24 19:30:45.758941299+00:00,160,1,432669,F,A,64.83,1,26,8058566317631,0,15223,94234382,CLX5
2025-09-24 19:30:45.758941299+00:00,160,1,432669,F,A,64.83,1,26,8058566317644,0,15223,94234382,CLX5
2025-09-24 19:30:45.758941299+00:00,160,1,432669,C,A,64.83,1,26,8058566317631,0,18250,94234383,CLX5
2025-09-24 19:30:45.758941299+00:00,160,1,432669,C,A,64.83,1,26,8058566317644,128,18250,94234383,CLX5
2025-09-24 19:30:45.758962573+00:00,160,1,432669,T,B,64.83,2,26,8058566317794,0,17000,94234387,CLX5
2025-09-24 19:30:45.758962573+00:00,160,1,432669,F,A,64.83,1,26,8058566317646,0,17000,94234387,CLX5
2025-09-24 19:30:45.758962573+00:00,160,1,432669,F,A,64.83,1,26,8058566317696,0,17000,94234387,CLX5
2025-09-24 19:30:45.758962573+00:00,160,1,432669,C,A,64.83,1,26,8058566317646,0,15005,94234388,CLX5
2025-09-24 19:30:45.758962573+00:00,160,1,432669,C,A,64.83,1,26,8058566317696,128,15005,94234388,CLX5
2025-09-24 19:30:45.758962765+00:00,160,1,432669,A,B,64.83,2,26,8058566317795,128,17214,94234391,CLX5
2025-09-24 19:30:45.758962939+00:00,160,1,432669,A,B,64.83,1,26,8058566317796,128,16076,94234393,CLX5
2025-09-24 19:30:45.759126341+00:00,160,1,432669,M,A,64.84,3,26,8058566291196,128,15012,94234403,CLX5
2025-09-24 19:30:45.760400243+00:00,160,1,432669,M,A,64.95,1,26,8058565075241,128,14467,94234477,CLX5
2025-09-24 19:30:45.760426929+00:00,160,1,432669,M,B,63.66,4,26,8058566280404,128,15377,94234478,CLX5
2025-09-24 19:30:45.761173699+00:00,160,1,432669,C,B,64.82,1,26,8058566314950,128,15186,94234529,CLX5
2025-09-24 19:30:45.762101499+00:00,160,1,432669,A,B,64.82,2,26,8058566317866,128,14253,94234571,CLX5
2025-09-24 19:30:45.762158557+00:00,160,1,432669,A,B,64.83,1,26,8058566317869,128,21537,94234576,CLX5
2025-09-24 19:30:45.762237121+00:00,160,1,432669,A,B,64.83,1,26,8058566317871,128,17257,94234580,CLX5
2025-09-24 19:30:45.762996565+00:00,160,1,432669,A,B,64.83,3,26,8058566317882,128,19138,94234592,CLX5
2025-09-24 19:30:45.765297411+00:00,160,1,432669,C,A,64.84,3,26,8058566291196,128,15164,94234710,CLX5
2025-09-24 19:30:45.766320013+00:00,160,1,432669,C,B,64.83,3,26,8058566317882,128,16945,94234765,CLX5
2025-09-24 19:30:45.766350617+00:00,160,1,432669,T,A,64.83,1,26,8058566317951,0,14838,94234767,CLX5
2025-09-24 19:30:45.766350617+00:00,160,1,432669,F,B,64.83,1,26,8058566317795,0,14838,94234767,CLX5
2025-09-24 19:30:45.766350617+00:00,160,1,432669,M,B,64.83,1,26,8058566317795,128,20315,94234768,CLX5
2025-09-24 19:30:45.768750321+00:00,160,1,432669,A,A,64.84,1,26,8058566317974,128,15307,94234843,CLX5
2025-09-24 19:30:45.769217147+00:00,160,1,432669,M,B,64.82,3,26,8058566311409,128,15389,94234862,CLX5
2025-09-24 19:30:45.770177795+00:00,160,1,432669,C,A,64.84,1,26,8058566317974,128,14865,94234881,CLX5
2025-09-24 19:30:45.770904235+00:00,160,1,432669,M,B,64.81,3,26,8058566291224,128,14714,94234904,CLX5
2025-09-24 19:30:45.772435557+00:00,160,1,432669,A,B,64.82,1,26,8058566317999,128,15140,94234934,CLX5
2025-09-24 19:30:45.778876471+00:00,160,1,432669,A,A,64.84,1,26,8058566318116,128,18137,94235215,CLX5
2025-09-24 19:30:45.783146555+00:00,160,1,432669,C,A,64.84,1,26,8058566318116,128,15403,94235388,CLX5
2025-09-24 19:30:45.786195053+00:00,160,1,432669,A,B,64.83,1,26,8058566318242,128,20198,94235513,CLX5
2025-09-24 19:30:45.787674463+00:00,160,1,432669,C,A,64.84,1,26,8058566317050,128,15131,94235571,CLX5
2025-09-24 19:30:45.788485187+00:00,160,1,432669,C,A,64.84,2,26,8058566307924,128,15054,94235632,CLX5
2025-09-24 19:30:45.789246145+00:00,160,1,432669,A,B,64.83,2,26,8058566318303,128,16847,94235697,CLX5
2025-09-24 19:30:45.789578713+00:00,160,1,432669,C,A,64.84,1,26,8058566315884,128,19396,94235709,CLX5
2025-09-24 19:30:45.789821045+00:00,160,1,432669,A,B,64.83,2,26,8058566318310,128,17279,94235719,CLX5
2025-09-24 19:30:45.789822773+00:00,160,1,432669,C,A,64.84,1,26,8058566316632,128,15384,94235723,CLX5
2025-09-24 19:30:45.790262127+00:00,160,1,432669,C,A,64.84,1,26,8058566307926,128,15137,94235743,CLX5
2025-09-24 19:30:45.790401511+00:00,160,1,432669,A,B,64.83,1,26,8058566318320,128,15616,94235745,CLX5
2025-09-24 19:30:45.790405295+00:00,160,1,432669,A,A,64.84,1,26,8058566318321,128,18505,94235748,CLX5
2025-09-24 19:30:45.790414779+00:00,160,1,432669,A,B,64.83,1,26,8058566318322,128,14587,94235752,CLX5
2025-09-24 19:30:45.790698197+00:00,160,1,432669,A,B,64.83,1,26,8058566318327,128,15452,94235762,CLX5
2025-09-24 19:30:45.791252649+00:00,160,1,432669,C,B,64.83,1,26,8058566318322,128,15406,94235785,CLX5
2025-09-24 19:30:45.791253243+00:00,160,1,432669,A,B,64.81,2,26,8058566318334,128,18109,94235786,CLX5
2025-09-24 19:30:45.794987017+00:00,160,1,432669,M,A,64.85,1,26,8058566305433,128,19067,94235870,CLX5
2025-09-24 19:30:45.859588177+00:00,160,1,432669,C,A,64.84,1,26,8058566318321,128,18922,94236116,CLX5
2025-09-24 19:30:45.860225129+00:00,160,1,432669,C,A,64.84,1,26,8058566315091,128,18706,94236125,CLX5
2025-09-24 19:30:45.866180993+00:00,160,1,432669,A,B,64.83,1,26,8058566318496,128,19240,94236180,CLX5
2025-09-24 19:30:45.866301277+00:00,160,1,432669,C,B,64.83,1,26,8058566318496,128,18931,94236181,CLX5
2025-09-24 19:30:45.866328269+00:00,160,1,432669,C,A,64.84,1,26,8058566307925,128,15475,94236182,CLX5
2025-09-24 19:30:45.866437935+00:00,160,1,432669,A,A,64.84,1,26,8058566318497,128,18832,94236183,CLX5
2025-09-24 19:30:45.931051975+00:00,160,1,432669,C,A,64.86,1,26,8058566317700,128,18347,94236387,CLX5
2025-09-24 19:30:48.050076459+00:00,160,1,432669,C,B,64.83,1,26,8058566318320,128,19614,94237068,CLX5
2025-09-24 19:30:48.050281755+00:00,160,1,432669,A,B,64.83,1,26,8058566318949,128,18882,94237069,CLX5
2025-09-24 19:30:48.050420065+00:00,160,1,432669,C,A,64.84,1,26,8058566318497,128,19584,94237070,CLX5
2025-09-24 19:30:48.209303005+00:00,160,1,432669,A,B,64.79,2,26,8058566318951,128,18954,94237073,CLX5
2025-09-24 19:30:48.389115229+00:00,160,1,432669,T,A,64.83,1,26,8058566318952,0,20754,94237074,CLX5
2025-09-24 19:30:48.389115229+00:00,160,1,432669,F,B,64.83,1,26,8058566317795,0,20754,94237074,CLX5
2025-09-24 19:30:48.389115229+00:00,160,1,432669,C,B,64.83,1,26,8058566317795,128,15949,94237075,CLX5
2025-09-24 19:30:48.389445745+00:00,160,1,432669,C,B,64.83,2,26,8058566318310,128,20417,94237076,CLX5
2025-09-24 19:30:48.389452099+00:00,160,1,432669,A,A,64.84,1,26,8058566318953,128,15698,94237077,CLX5
2025-09-24 19:30:48.389467495+00:00,160,1,432669,C,B,64.83,1,26,8058566318949,128,16904,94237078,CLX5
2025-09-24 19:30:48.389586761+00:00,160,1,432669,A,B,64.83,1,26,8058566318954,128,16619,94237081,CLX5
2025-09-24 19:30:48.389629653+00:00,160,1,432669,A,B,64.83,1,26,8058566318955,128,16136,94237083,CLX5
2025-09-24 19:30:48.389714801+00:00,160,1,432669,T,A,64.83,3,26,8058566318956,0,17977,94237084,CLX5
2025-09-24 19:30:48.389714801+00:00,160,1,432669,F,B,64.83,1,26,8058566317796,0,17977,94237084,CLX5
2025-09-24 19:30:48.389714801+00:00,160,1,432669,F,B,64.83,1,26,8058566317869,0,17977,94237084,CLX5
2025-09-24 19:30:48.389714801+00:00,160,1,432669,F,B,64.83,1,26,8058566317871,0,17977,94237084,CLX5
2025-09-24 19:30:48.389714801+00:00,160,1,432669,C,B,64.83,1,26,8058566317796,0,17662,94237085,CLX5
2025-09-24 19:30:48.389714801+00:00,160,1,432669,C,B,64.83,1,26,8058566317869,0,17662,94237085,CLX5
2025-09-24 19:30:48.389714801+00:00,160,1,432669,C,B,64.83,1,26,8058566317871,128,17662,94237085,CLX5
2025-09-24 19:30:48.389987237+00:00,160,1,432669,C,B,64.83,1,26,8058566318955,128,20821,94237086,CLX5
2025-09-24 19:30:48.390004899+00:00,160,1,432669,A,A,64.84,1,26,8058566318957,128,14992,94237087,CLX5
2025-09-24 19:30:48.390009797+00:00,160,1,432669,C,B,64.83,1,26,8058566318954,128,17254,94237088,CLX5
2025-09-24 19:30:48.390206337+00:00,160,1,432669,C,A,64.84,1,26,8058566318957,128,18614,94237093,CLX5
2025-09-24 19:30:48.390333953+00:00,160,1,432669,A,B,64.83,1,26,8058566318958,128,21491,94237094,CLX5
2025-09-24 19:30:48.390561099+00:00,160,1,432669,C,B,64.79,2,26,8058566318951,128,18347,94237095,CLX5
2025-09-24 19:30:48.391909553+00:00,160,1,432669,A,A,64.84,1,26,8058566318959,128,19620,94237096,CLX5
2025-09-24 19:30:48.392053143+00:00,160,1,432669,C,A,64.84,1,26,8058566318959,128,18548,94237097,CLX5
2025-09-24 19:30:48.850939383+00:00,160,1,432669,A,B,64.83,1,26,8058566319024,128,20783,94237260,CLX5
2025-09-24 19:30:48.850939559+00:00,160,1,432669,A,B,64.83,1,26,8058566319025,128,15121,94237261,CLX5
2025-09-24 19:30:48.851135101+00:00,160,1,432669,A,B,64.83,1,26,8058566319028,128,16153,94237272,CLX5
2025-09-24 19:30:48.852078411+00:00,160,1,432669,A,B,64.83,1,26,8058566319037,128,14943,94237317,CLX5
2025-09-24 19:30:50.032046661+00:00,160,1,432669,M,A,64.84,1,26,8058566305433,128,22104,94237514,CLX5
2025-09-24 19:30:50.032235275+00:00,160,1,432669,C,B,64.83,1,26,8058566319037,128,19512,94237515,CLX5
2025-09-24 19:30:50.032394205+00:00,160,1,432669,C,B,64.83,1,26,8058566319028,128,19415,94237517,CLX5
2025-09-24 19:30:53.953166935+00:00,160,1,432669,A,A,64.84,1,26,8058566319282,128,22166,94237812,CLX5
2025-09-24 19:30:53.953180221+00:00,160,1,432669,A,A,64.84,1,26,8058566319284,128,23496,94237816,CLX5
2025-09-24 19:30:53.953191047+00:00,160,1,432669,C,B,64.83,1,26,8058566319024,128,20922,94237818,CLX5
2025-09-24 19:30:53.953191203+00:00,160,1,432669,C,B,64.83,1,26,8058566319025,128,23451,94237819,CLX5
2025-09-24 19:30:53.953192751+00:00,160,1,432669,C,B,64.81,2,26,8058566318334,128,14857,94237826,CLX5
2025-09-24 19:30:53.953472353+00:00,160,1,432669,C,A,64.84,1,26,8058566319284,128,18374,94237830,CLX5
2025-09-24 19:30:53.990313513+00:00,160,1,432669,A,B,64.81,2,26,8058566319302,128,15027,94237883,CLX5
2025-09-24 19:30:54.457330113+00:00,160,1,432669,T,B,64.84,4,26,8058566319345,0,18467,94237980,CLX5
2025-09-24 19:30:54.457330113+00:00,160,1,432669,F,A,64.84,1,26,8058566274057,0,18467,94237980,CLX5
2025-09-24 19:30:54.457330113+00:00,160,1,432669,F,A,64.84,1,26,8058566274071,0,18467,94237980,CLX5
2025-09-24 19:30:54.457330113+00:00,160,1,432669,F,A,64.84,2,26,8058566274087,0,18467,94237980,CLX5
2025-09-24 19:30:54.457330113+00:00,160,1,432669,C,A,64.84,1,26,8058566274057,0,15967,94237981,CLX5
2025-09-24 19:30:54.457330113+00:00,160,1,432669,C,A,64.84,1,26,8058566274071,0,15967,94237981,CLX5
2025-09-24 19:30:54.457330113+00:00,160,1,432669,C,A,64.84,2,26,8058566274087,128,15967,94237981,CLX5
2025-09-24 19:30:54.457662035+00:00,160,1,432669,A,B,64.83,1,26,8058566319347,128,16054,94237984,CLX5
2025-09-24 19:30:54.457673375+00:00,160,1,432669,C,A,64.84,1,26,8058566318953,128,15840,94237986,CLX5
2025-09-24 19:30:54.457673527+00:00,160,1,432669,A,B,64.83,1,26,8058566319348,128,20107,94237987,CLX5
2025-09-24 19:30:54.457673703+00:00,160,1,432669,A,B,64.83,2,26,8058566319349,128,15144,94237988,CLX5
2025-09-24 19:30:54.457677351+00:00,160,1,432669,A,B,64.83,1,26,8058566319351,128,15903,94237990,CLX5
2025-09-24 19:30:54.457677887+00:00,160,1,432669,C,A,64.84,1,26,8058566319282,128,18310,94237991,CLX5
2025-09-24 19:30:54.457679673+00:00,160,1,432669,A,B,64.83,1,26,8058566319352,128,15726,94237992,CLX5
2025-09-24 19:30:54.457691289+00:00,160,1,432669,A,B,64.83,1,26,8058566319353,128,15728,94237993,CLX5
2025-09-24 19:30:54.457761921+00:00,160,1,432669,A,B,64.83,2,26,8058566319354,128,18574,94237995,CLX5
2025-09-24 19:30:54.457954297+00:00,160,1,432669,A,A,64.84,1,26,8058566319355,128,15477,94237998,CLX5
2025-09-24 19:30:54.458028003+00:00,160,1,432669,C,B,64.83,1,26,8058566319352,128,15309,94237999,CLX5
2025-09-24 19:30:54.458037469+00:00,160,1,432669,C,B,64.83,2,26,8058566319354,128,18543,94238000,CLX5
2025-09-24 19:30:54.458153047+00:00,160,1,432669,C,B,64.83,1,26,8058566319353,128,15711,94238001,CLX5
2025-09-24 19:30:54.458335709+00:00,160,1,432669,A,A,64.84,1,26,8058566319356,128,15514,94238005,CLX5
2025-09-24 19:30:54.458343041+00:00,160,1,432669,A,A,64.84,2,26,8058566319357,128,15713,94238006,CLX5
2025-09-24 19:30:54.458370111+00:00,160,1,432669,A,A,64.84,1,26,8058566319358,128,15936,94238007,CLX5
2025-09-24 19:30:54.458370361+00:00,160,1,432669,A,B,64.83,1,26,8058566319359,128,20938,94238008,CLX5
2025-09-24 19:30:54.458428881+00:00,160,1,432669,C,A,64.84,1,26,8058566319358,128,15640,94238009,CLX5
2025-09-24 19:30:54.458459927+00:00,160,1,432669,A,A,64.84,1,26,8058566319360,128,15650,94238012,CLX5
2025-09-24 19:30:54.458566771+00:00,160,1,432669,A,A,64.84,1,26,8058566319361,128,19120,94238013,CLX5
2025-09-24 19:30:55.167788907+00:00,160,1,432669,C,B,64.83,1,26,8058566319359,128,15348,94238051,CLX5
2025-09-24 19:30:55.167953729+00:00,160,1,432669,C,B,64.83,1,26,8058566319351,128,19485,94238053,CLX5
2025-09-24 19:30:55.167984507+00:00,160,1,432669,C,A,64.84,1,26,8058566319361,128,15777,94238054,CLX5
2025-09-24 19:30:55.637730687+00:00,160,1,432669,A,A,64.85,1,26,8058566319376,128,14886,94238095,CLX5
2025-09-24 19:30:55.638719347+00:00,160,1,432669,C,B,64.83,1,26,8058566319347,128,16203,94238103,CLX5
2025-09-24 19:30:55.638770841+00:00,160,1,432669,C,B,64.83,1,26,8058566319348,128,19266,94238104,CLX5
2025-09-24 19:30:55.638908401+00:00,160,1,432669,A,A,64.84,1,26,8058566319377,128,18634,94238105,CLX5
2025-09-24 19:30:55.639147987+00:00,160,1,432669,C,B,64.83,2,26,8058566319349,128,21265,94238109,CLX5
2025-09-24 19:30:55.639415431+00:00,160,1,432669,A,A,64.84,1,26,8058566319383,128,15297,94238135,CLX5
2025-09-24 19:30:55.639760517+00:00,160,1,432669,C,A,64.84,1,26,8058566319383,128,15743,94238141,CLX5
2025-09-24 19:30:55.639922771+00:00,160,1,432669,A,A,64.84,1,26,8058566319390,128,15699,94238153,CLX5
2025-09-24 19:30:55.641202855+00:00,160,1,432669,T,A,64.83,1,26,8058566305433,0,18453,94238217,CLX5
2025-09-24 19:30:55.641202855+00:00,160,1,432669,F,A,64.83,1,26,8058566305433,0,18453,94238217,CLX5
2025-09-24 19:30:55.641202855+00:00,160,1,432669,F,B,64.83,1,26,8058566318242,0,18453,94238217,CLX5
2025-09-24 19:30:55.641202855+00:00,160,1,432669,C,B,64.83,1,26,8058566318242,0,15180,94238218,CLX5
2025-09-24 19:30:55.641202855+00:00,160,1,432669,C,A,64.84,1,26,8058566305433,128,15180,94238218,CLX5
2025-09-24 19:30:55.641454593+00:00,160,1,432669,C,B,64.83,2,26,8058566318303,128,18309,94238226,CLX5
2025-09-24 19:30:55.641487519+00:00,160,1,432669,T,A,64.83,2,26,8058566319415,0,15227,94238234,CLX5
2025-09-24 19:30:55.641487519+00:00,160,1,432669,F,B,64.83,1,26,8058566318327,0,15227,94238234,CLX5
2025-09-24 19:30:55.641487519+00:00,160,1,432669,F,B,64.83,1,26,8058566318958,0,15227,94238234,CLX5
2025-09-24 19:30:55.641487519+00:00,160,1,432669,C,B,64.83,1,26,8058566318327,0,15541,94238235,CLX5
2025-09-24 19:30:55.641487519+00:00,160,1,432669,C,B,64.83,1,26,8058566318958,128,15541,94238235,CLX5
2025-09-24 19:30:55.641909193+00:00,160,1,432669,A,A,64.84,2,26,8058566319423,128,15169,94238251,CLX5
2025-09-24 19:30:55.641968075+00:00,160,1,432669,A,A,64.84,2,26,8058566319432,128,15847,94238276,CLX5
2025-09-24 19:30:55.642113873+00:00,160,1,432669,C,B,64.82,3,26,8058566311409,128,19143,94238288,CLX5
2025-09-24 19:30:55.643016501+00:00,160,1,432669,C,B,64.82,2,26,8058566317866,128,18150,94238325,CLX5
2025-09-24 19:30:55.647121685+00:00,160,1,432669,A,A,64.83,1,26,8058566319448,128,18182,94238350,CLX5
2025-09-24 19:30:55.649459259+00:00,160,1,432669,T,B,64.83,1,26,8058566319450,0,18214,94238355,CLX5
2025-09-24 19:30:55.649459259+00:00,160,1,432669,F,A,64.83,1,26,8058566319448,0,18214,94238355,CLX5
2025-09-24 19:30:55.649459259+00:00,160,1,432669,C,A,64.83,1,26,8058566319448,128,15237,94238356,CLX5
2025-09-24 19:30:55.649742811+00:00,160,1,432669,A,B,64.83,1,26,8058566319451,128,15109,94238362,CLX5
2025-09-24 19:30:55.653268235+00:00,160,1,432669,A,B,64.83,1,26,8058566319466,128,14117,94238418,CLX5
2025-09-24 19:30:55.654141585+00:00,160,1,432669,T,A,64.83,1,26,8058566319475,0,18469,94238465,CLX5
2025-09-24 19:30:55.654141585+00:00,160,1,432669,F,B,64.83,1,26,8058566319451,0,18469,94238465,CLX5
2025-09-24 19:30:55.654141585+00:00,160,1,432669,C,B,64.83,1,26,8058566319451,128,14889,94238466,CLX5
2025-09-24 19:30:55.657484485+00:00,160,1,432669,A,B,64.83,1,26,8058566319482,128,14808,94238515,CLX5
2025-09-24 19:30:55.658954181+00:00,160,1,432669,A,A,64.84,1,26,8058566319483,128,19189,94238523,CLX5
2025-09-24 19:30:55.686992835+00:00,160,1,432669,T,A,64.83,1,26,8058566319488,0,18641,94238531,CLX5
2025-09-24 19:30:55.686992835+00:00,160,1,432669,F,B,64.83,1,26,8058566319466,0,18641,94238531,CLX5
2025-09-24 19:30:55.686992835+00:00,160,1,432669,C,B,64.83,1,26,8058566319466,128,14998,94238532,CLX5
2025-09-24 19:30:55.687251601+00:00,160,1,432669,C,B,64.83,1,26,8058566319482,128,17781,94238535,CLX5
2025-09-24 19:30:55.687446069+00:00,160,1,432669,A,A,64.84,1,26,8058566319490,128,15417,94238539,CLX5
2025-09-24 19:30:55.687606689+00:00,160,1,432669,A,A,64.84,1,26,8058566319491,128,18596,94238540,CLX5
2025-09-24 19:30:55.687754619+00:00,160,1,432669,A,A,64.84,1,26,8058566319492,128,18239,94238541,CLX5
2025-09-24 19:30:55.691332785+00:00,160,1,432669,M,A,64.83,1,26,8058566319483,128,18684,94238547,CLX5
2025-09-24 19:30:55.694647595+00:00,160,1,432669,A,B,63.68,4,26,8058566319508,128,14944,94238594,CLX5
2025-09-24 19:30:55.709349539+00:00,160,1,432669,C,A,64.84,1,26,8058566319492,128,18852,94238602,CLX5
2025-09-24 19:30:55.709361787+00:00,160,1,432669,C,A,64.84,1,26,8058566319491,128,15188,94238603,CLX5
2025-09-24 19:30:55.709366511+00:00,160,1,432669,C,A,64.84,1,26,8058566319490,128,15304,94238604,CLX5
2025-09-24 19:30:57.354646367+00:00,160,1,432669,T,B,64.83,1,26,8058566319640,0,19954,94238893,CLX5
2025-09-24 19:30:57.354646367+00:00,160,1,432669,F,A,64.83,1,26,8058566319483,0,19954,94238893,CLX5
2025-09-24 19:30:57.354646367+00:00,160,1,432669,C,A,64.83,1,26,8058566319483,128,15251,94238894,CLX5
2025-09-24 19:30:57.355927181+00:00,160,1,432669,A,B,64.82,1,26,8058566319652,128,15424,94238947,CLX5
2025-09-24 19:30:57.356293559+00:00,160,1,432669,A,B,64.82,1,26,8058566319654,128,18543,94238956,CLX5
2025-09-24 19:30:57.356469075+00:00,160,1,432669,A,B,64.82,1,26,8058566319657,128,14454,94238965,CLX5
2025-09-24 19:30:57.361690805+00:00,160,1,432669,A,A,64.83,1,26,8058566319663,128,18901,94238983,CLX5
2025-09-24 19:30:57.363882331+00:00,160,1,432669,T,B,64.83,1,26,8058566319667,0,18559,94238991,CLX5
2025-09-24 19:30:57.363882331+00:00,160,1,432669,F,A,64.83,1,26,8058566319663,0,18559,94238991,CLX5
2025-09-24 19:30:57.363882331+00:00,160,1,432669,C,A,64.83,1,26,8058566319663,128,14974,94238992,CLX5
2025-09-24 19:30:57.368438653+00:00,160,1,432669,A,A,64.83,1,26,8058566319669,128,17309,94238998,CLX5
2025-09-24 19:30:57.370259541+00:00,160,1,432669,T,B,64.83,1,26,8058566319671,0,18640,94239003,CLX5
2025-09-24 19:30:57.370259541+00:00,160,1,432669,F,A,64.83,1,26,8058566319669,0,18640,94239003,CLX5
2025-09-24 19:30:57.370259541+00:00,160,1,432669,C,A,64.83,1,26,8058566319669,128,14928,94239004,CLX5
2025-09-24 19:30:57.373558991+00:00,160,1,432669,A,B,64.83,2,26,8058566319675,128,13988,94239021,CLX5
2025-09-24 19:30:57.373575619+00:00,160,1,432669,A,B,64.83,2,26,8058566319676,128,17679,94239024,CLX5
2025-09-24 19:30:57.373916269+00:00,160,1,432669,A,B,64.83,1,26,8058566319680,128,17735,94239043,CLX5
2025-09-24 19:30:57.375002537+00:00,160,1,432669,T,A,64.83,1,26,8058566319682,0,18112,94239074,CLX5
2025-09-24 19:30:57.375002537+00:00,160,1,432669,F,B,64.83,1,26,8058566319675,0,18112,94239074,CLX5
2025-09-24 19:30:57.375002537+00:00,160,1,432669,M,B,64.83,1,26,8058566319675,128,18815,94239075,CLX5
2025-09-24 19:30:57.375223961+00:00,160,1,432669,C,B,64.83,1,26,8058566319675,128,14993,94239079,CLX5
2025-09-24 19:30:57.375425995+00:00,160,1,432669,T,A,64.83,1,26,8058566319685,0,18686,94239087,CLX5
2025-09-24 19:30:57.375425995+00:00,160,1,432669,F,B,64.83,1,26,8058566319676,0,18686,94239087,CLX5
2025-09-24 19:30:57.375425995+00:00,160,1,432669,M,B,64.83,1,26,8058566319676,128,15056,94239088,CLX5
2025-09-24 19:30:57.375655271+00:00,160,1,432669,T,A,64.83,1,26,8058566319686,0,17912,94239091,CLX5
2025-09-24 19:30:57.375655271+00:00,160,1,432669,F,B,64.83,1,26,8058566319680,0,17912,94239091,CLX5
2025-09-24 19:30:57.375655271+00:00,160,1,432669,C,B,64.83,1,26,8058566319680,0,15110,94239092,CLX5
2025-09-24 19:30:57.375655271+00:00,160,1,432669,C,B,64.83,1,26,8058566319676,128,15110,94239092,CLX5
2025-09-24 19:30:57.379779211+00:00,160,1,432669,A,A,64.84,1,26,8058566319697,128,18287,94239121,CLX5
2025-09-24 19:30:57.379937853+00:00,160,1,432669,C,B,64.82,1,26,8058566319657,128,18591,94239122,CLX5
2025-09-24 19:30:57.379952079+00:00,160,1,432669,C,B,64.82,1,26,8058566319654,128,15319,94239123,CLX5
2025-09-24 19:30:57.379959491+00:00,160,1,432669,A,A,64.84,1,26,8058566319698,128,14238,94239124,CLX5
2025-09-24 19:30:57.380091119+00:00,160,1,432669,C,B,64.82,1,26,8058566319652,128,18502,94239125,CLX5
2025-09-24 19:30:57.381902713+00:00,160,1,432669,M,A,64.83,1,26,8058566319697,128,17961,94239133,CLX5
2025-09-24 19:30:57.382081803+00:00,160,1,432669,A,A,64.83,1,26,8058566319702,128,15035,94239137,CLX5
2025-09-24 19:30:57.382105513+00:00,160,1,432669,A,A,64.84,1,26,8058566319703,128,17010,94239142,CLX5
2025-09-24 19:30:58.464385695+00:00,160,1,432669,A,A,64.83,1,26,8058566319805,128,13852,94239371,CLX5
2025-09-24 19:30:58.464686737+00:00,160,1,432669,T,B,64.83,3,26,8058566319809,0,17559,94239384,CLX5
2025-09-24 19:30:58.464686737+00:00,160,1,432669,F,A,64.83,1,26,8058566319697,0,17559,94239384,CLX5
2025-09-24 19:30:58.464686737+00:00,160,1,432669,F,A,64.83,1,26,8058566319702,0,17559,94239384,CLX5
2025-09-24 19:30:58.464686737+00:00,160,1,432669,F,A,64.83,1,26,8058566319805,0,17559,94239384,CLX5
2025-09-24 19:30:58.464686737+00:00,160,1,432669,C,A,64.83,1,26,8058566319697,0,17559,94239384,CLX5
2025-09-24 19:30:58.464686737+00:00,160,1,432669,C,A,64.83,1,26,8058566319702,0,17559,94239384,CLX5
2025-09-24 19:30:58.464686737+00:00,160,1,432669,C,A,64.83,1,26,8058566319805,128,17559,94239384,CLX5
2025-09-24 19:30:58.464698217+00:00,160,1,432669,A,B,64.83,1,26,8058566319810,128,15329,94239388,CLX5
2025-09-24 19:30:58.464726805+00:00,160,1,432669,C,A,64.84,1,26,8058566319703,128,17268,94239390,CLX5
2025-09-24 19:30:58.464739343+00:00,160,1,432669,C,A,64.84,1,26,8058566319698,128,15281,94239391,CLX5
2025-09-24 19:30:58.465037179+00:00,160,1,432669,C,B,64.82,1,26,8058566317789,128,14110,94239416,CLX5
2025-09-24 19:30:58.465041365+00:00,160,1,432669,T,A,64.83,1,26,8058566319818,0,14969,94239418,CLX5
2025-09-24 19:30:58.465041365+00:00,160,1,432669,F,B,64.83,1,26,8058566319810,0,14969,94239418,CLX5
2025-09-24 19:30:58.465041365+00:00,160,1,432669,C,B,64.83,1,26,8058566319810,128,18155,94239419,CLX5
2025-09-24 19:30:58.465425999+00:00,160,1,432669,M,B,64.82,3,26,8058566280404,128,15353,94239428,CLX5
2025-09-24 19:30:58.465640993+00:00,160,1,432669,A,B,64.82,1,26,8058566319820,128,18964,94239437,CLX5
2025-09-24 19:30:58.465792415+00:00,160,1,432669,A,B,64.82,1,26,8058566319823,128,15977,94239442,CLX5
2025-09-24 19:30:58.465936101+00:00,160,1,432669,M,B,63.67,4,26,8058566280404,128,18584,94239443,CLX5
2025-09-24 19:30:58.465937907+00:00,160,1,432669,A,B,64.82,1,26,8058566319824,128,15425,94239444,CLX5
2025-09-24 19:30:58.470650127+00:00,160,1,432669,A,A,64.83,1,26,8058566319829,128,18258,94239463,CLX5
2025-09-24 19:30:58.473420605+00:00,160,1,432669,T,B,64.83,1,26,8058566319831,0,18746,94239467,CLX5
2025-09-24 19:30:58.473420605+00:00,160,1,432669,F,A,64.83,1,26,8058566319829,0,18746,94239467,CLX5
2025-09-24 19:30:58.473420605+00:00,160,1,432669,C,A,64.83,1,26,8058566319829,128,15046,94239468,CLX5
2025-09-24 19:30:58.473436251+00:00,160,1,432669,A,B,64.82,1,26,8058566319832,128,14899,94239472,CLX5
2025-09-24 19:30:58.473806813+00:00,160,1,432669,A,B,64.83,1,26,8058566319837,128,15267,94239482,CLX5
2025-09-24 19:30:58.474113367+00:00,160,1,432669,C,B,64.82,1,26,8058566319832,128,14548,94239490,CLX5
2025-09-24 19:30:58.474588739+00:00,160,1,432669,M,B,64.82,3,26,8058566319508,128,15138,94239503,CLX5
2025-09-24 19:30:58.478143231+00:00,160,1,432669,T,A,64.83,1,26,8058566319845,0,18551,94239517,CLX5
2025-09-24 19:30:58.478143231+00:00,160,1,432669,F,B,64.83,1,26,8058566319837,0,18551,94239517,CLX5
2025-09-24 19:30:58.478143231+00:00,160,1,432669,C,B,64.83,1,26,8058566319837,128,15106,94239518,CLX5
2025-09-24 19:30:58.478574119+00:00,160,1,432669,M,B,63.66,4,26,8058566319508,128,14645,94239527,CLX5
2025-09-24 19:30:58.478780817+00:00,160,1,432669,C,B,64.82,1,26,8058566319824,128,18976,94239529,CLX5
2025-09-24 19:30:58.478792681+00:00,160,1,432669,C,B,64.82,1,26,8058566319823,128,15812,94239530,CLX5
2025-09-24 19:30:58.478799381+00:00,160,1,432669,A,A,64.84,1,26,8058566319849,128,14949,94239531,CLX5
2025-09-24 19:30:58.478936827+00:00,160,1,432669,A,A,64.84,1,26,8058566319850,128,18751,94239532,CLX5
2025-09-24 19:30:58.481922067+00:00,160,1,432669,A,B,63.68,4,26,8058566319851,128,18938,94239539,CLX5
2025-09-24 19:30:58.486295075+00:00,160,1,432669,A,A,64.84,1,26,8058566319856,128,18799,94239566,CLX5
2025-09-24 19:30:58.486460957+00:00,160,1,432669,A,B,64.82,1,26,8058566319857,128,18990,94239567,CLX5
2025-09-24 19:30:58.486469807+00:00,160,1,432669,C,A,64.84,1,26,8058566319850,128,15073,94239568,CLX5
2025-09-24 19:30:58.486478677+00:00,160,1,432669,C,A,64.84,1,26,8058566319849,128,14957,94239569,CLX5
2025-09-24 19:30:58.486621077+00:00,160,1,432669,A,B,64.82,1,26,8058566319858,128,19155,94239570,CLX5
2025-09-24 19:30:58.539721347+00:00,160,1,432669,M,A,64.83,1,26,8058566319856,128,18752,94239593,CLX5
2025-09-24 19:30:58.838643737+00:00,160,1,432669,C,B,64.82,1,26,8058566319858,128,18445,94239680,CLX5
2025-09-24 19:30:58.838656005+00:00,160,1,432669,C,B,64.82,1,26,8058566319857,128,15425,94239681,CLX5
2025-09-24 19:30:58.838658521+00:00,160,1,432669,C,B,64.82,1,26,8058566319820,128,15385,94239682,CLX5
2025-09-24 19:30:59.398960427+00:00,160,1,432669,A,A,64.83,2,26,8058566319927,128,15108,94239742,CLX5
2025-09-24 19:30:59.399015895+00:00,160,1,432669,A,A,64.83,2,26,8058566319928,128,14986,94239746,CLX5
2025-09-24 19:30:59.399016075+00:00,160,1,432669,A,A,64.83,1,26,8058566319929,128,21273,94239748,CLX5
2025-09-24 19:30:59.399020599+00:00,160,1,432669,A,A,64.83,2,26,8058566319930,128,17233,94239749,CLX5
2025-09-24 19:30:59.399185249+00:00,160,1,432669,A,A,64.83,1,26,8058566319932,128,16413,94239753,CLX5
2025-09-24 19:30:59.399191451+00:00,160,1,432669,C,B,64.82,2,26,8058566317788,128,15257,94239754,CLX5
2025-09-24 19:30:59.399435071+00:00,160,1,432669,A,A,64.83,1,26,8058566319933,128,19433,94239759,CLX5
2025-09-24 19:30:59.399755529+00:00,160,1,432669,C,B,64.82,2,26,8058566317770,128,16052,94239768,CLX5
2025-09-24 19:30:59.400465449+00:00,160,1,432669,A,A,64.86,1,26,8058566319952,128,15216,94239813,CLX5
2025-09-24 19:30:59.469152419+00:00,160,1,432669,A,A,64.83,1,26,8058566319972,128,16887,94239920,CLX5
2025-09-24 19:30:59.469161843+00:00,160,1,432669,A,A,64.83,2,26,8058566319973,128,15201,94239924,CLX5
2025-09-24 19:30:59.469164817+00:00,160,1,432669,C,B,64.81,2,26,8058566319302,128,14871,94239926,CLX5
2025-09-24 19:30:59.469165687+00:00,160,1,432669,A,A,64.83,1,26,8058566319974,128,15064,94239930,CLX5
2025-09-24 19:30:59.469169295+00:00,160,1,432669,A,A,64.83,2,26,8058566319976,128,15893,94239936,CLX5
2025-09-24 19:30:59.469172291+00:00,160,1,432669,C,B,64.82,2,26,8058566317765,128,19003,94239937,CLX5
2025-09-24 19:30:59.469517201+00:00,160,1,432669,C,B,64.82,3,26,8058566315628,128,15818,94239994,CLX5
2025-09-24 19:30:59.470263607+00:00,160,1,432669,C,B,64.82,1,26,8058566317999,128,15499,94240029,CLX5
2025-09-24 19:30:59.470294709+00:00,160,1,432669,M,A,64.94,1,26,8058565075241,128,15060,94240031,CLX5
2025-09-24 19:30:59.470602645+00:00,160,1,432669,C,B,64.82,1,26,8058566313296,128,15520,94240047,CLX5
2025-09-24 19:30:59.470847703+00:00,160,1,432669,A,A,64.83,1,26,8058566319992,128,18901,94240058,CLX5
2025-09-24 19:30:59.470849489+00:00,160,1,432669,C,B,64.82,1,26,8058566314905,128,16504,94240059,CLX5
2025-09-24 19:30:59.470850545+00:00,160,1,432669,C,B,64.79,1,26,8058566312959,128,14800,94240060,CLX5
2025-09-24 19:30:59.471700107+00:00,160,1,432669,A,A,64.83,1,26,8058566319995,128,15700,94240104,CLX5
2025-09-24 19:30:59.473859129+00:00,160,1,432669,C,B,64.82,2,26,8058566312953,128,16529,94240192,CLX5
2025-09-24 19:30:59.473915305+00:00,160,1,432669,A,A,64.83,2,26,8058566320018,128,15101,94240201,CLX5
2025-09-24 19:30:59.473938095+00:00,160,1,432669,M,B,64.8,1,26,8058566311303,128,16396,94240210,CLX5
2025-09-24 19:30:59.475313677+00:00,160,1,432669,C,B,64.82,1,26,8058566312891,128,17094,94240267,CLX5
2025-09-24 19:30:59.475522199+00:00,160,1,432669,A,A,64.86,2,26,8058566320040,128,15219,94240277,CLX5
2025-09-24 19:30:59.475840999+00:00,160,1,432669,C,B,64.82,3,26,8058566313288,128,15726,94240304,CLX5
2025-09-24 19:30:59.475851175+00:00,160,1,432669,A,B,64.79,1,26,8058566320052,128,15719,94240312,CLX5
2025-09-24 19:30:59.476077303+00:00,160,1,432669,M,B,64.81,1,26,8058566311303,128,19503,94240334,CLX5
2025-09-24 19:30:59.476237309+00:00,160,1,432669,C,B,64.82,1,26,8058566314163,128,18423,94240340,CLX5
2025-09-24 19:30:59.476663511+00:00,160,1,432669,M,A,64.84,1,26,8058566173085,128,15306,94240351,CLX5
2025-09-24 19:30:59.479177197+00:00,160,1,432669,C,A,64.84,1,26,8058566319390,128,14204,94240441,CLX5
2025-09-24 19:30:59.509402925+00:00,160,1,432669,C,A,64.88,2,26,8058566313101,128,18234,94240559,CLX5
2025-09-24 19:30:59.509403539+00:00,160,1,432669,A,B,64.79,2,26,8058566320130,128,14928,94240560,CLX5
2025-09-24 19:30:59.658776677+00:00,160,1,432669,A,B,64.82,2,26,8058566320217,128,18861,94240733,CLX5
2025-09-24 19:31:00.240421081+00:00,160,1,432669,A,B,64.82,1,26,8058566320267,128,18557,94240853,CLX5
2025-09-24 19:31:00.614666819+00:00,160,1,432669,T,A,64.82,1,26,8058566320272,0,29808,94240863,CLX5
2025-09-24 19:31:00.614666819+00:00,160,1,432669,F,B,64.82,1,26,8058566314839,0,29808,94240863,CLX5
2025-09-24 19:31:00.614666819+00:00,160,1,432669,C,B,64.82,1,26,8058566314839,128,27240,94240864,CLX5
2025-09-24 19:31:04.110602635+00:00,160,1,432669,T,A,64.82,1,26,8058566320426,0,21561,94241330,CLX5
2025-09-24 19:31:04.110602635+00:00,160,1,432669,F,B,64.82,1,26,8058566314284,0,21561,94241330,CLX5
2025-09-24 19:31:04.110602635+00:00,160,1,432669,C,B,64.82,1,26,8058566314284,128,15113,94241331,CLX5
2025-09-24 19:31:04.636080813+00:00,160,1,432669,C,A,65.05,1,26,8058566315368,128,21575,94241335,CLX5
2025-09-24 19:31:04.729895097+00:00,160,1,432669,A,A,65.04,1,26,8058566320427,128,18654,94241336,CLX5
2025-09-24 19:31:07.568020899+00:00,160,1,432669,A,B,64.82,2,26,8058566320436,128,20779,94241362,CLX5
2025-09-24 19:31:07.568196783+00:00,160,1,432669,A,B,64.82,2,26,8058566320438,128,24556,94241366,CLX5
2025-09-24 19:31:07.568342371+00:00,160,1,432669,C,A,64.83,2,26,8058566320018,128,22697,94241369,CLX5
2025-09-24 19:31:07.569165189+00:00,160,1,432669,C,A,64.83,1,26,8058566319992,128,18045,94241424,CLX5
2025-09-24 19:31:07.569174769+00:00,160,1,432669,A,B,64.82,1,26,8058566320455,128,20008,94241442,CLX5
2025-09-24 19:31:07.569950049+00:00,160,1,432669,C,B,64.82,1,26,8058566320455,128,15453,94241469,CLX5
2025-09-24 19:31:07.571171405+00:00,160,1,432669,C,B,64.82,2,26,8058566320438,128,17016,94241497,CLX5
2025-09-24 19:31:07.578347567+00:00,160,1,432669,A,B,64.82,1,26,8058566320468,128,16080,94241513,CLX5
2025-09-24 19:31:07.579759473+00:00,160,1,432669,C,B,64.82,1,26,8058566320468,128,20209,94241543,CLX5
2025-09-24 19:31:07.587196093+00:00,160,1,432669,A,A,64.83,1,26,8058566320480,128,19323,94241571,CLX5
2025-09-24 19:31:07.748813051+00:00,160,1,432669,A,B,64.82,1,26,8058566320502,128,16828,94241620,CLX5
2025-09-24 19:31:10.507189327+00:00,160,1,432669,T,A,64.82,1,26,8058566320525,0,19152,94241665,CLX5
2025-09-24 19:31:10.507189327+00:00,160,1,432669,F,B,64.82,1,26,8058566320217,0,19152,94241665,CLX5
2025-09-24 19:31:10.507189327+00:00,160,1,432669,M,B,64.82,1,26,8058566320217,128,17398,94241666,CLX5
2025-09-24 19:31:10.507581411+00:00,160,1,432669,C,B,64.82,1,26,8058566320502,128,20976,94241673,CLX5
2025-09-24 19:31:10.507935541+00:00,160,1,432669,C,B,64.82,1,26,8058566320217,128,14814,94241675,CLX5
2025-09-24 19:31:10.988307401+00:00,160,1,432669,C,B,64.81,4,26,8058566306863,128,18934,94241765,CLX5
2025-09-24 19:31:11.321858055+00:00,160,1,432669,A,B,64.82,2,26,8058566320558,128,21789,94241769,CLX5
2025-09-24 19:31:11.321858235+00:00,160,1,432669,A,B,64.82,1,26,8058566320559,128,17645,94241771,CLX5
2025-09-24 19:31:11.321894611+00:00,160,1,432669,A,B,64.82,2,26,8058566320560,128,16279,94241773,CLX5
2025-09-24 19:31:11.322084201+00:00,160,1,432669,A,B,64.82,1,26,8058566320562,128,15470,94241781,CLX5
2025-09-24 19:31:11.325366123+00:00,160,1,432669,C,A,64.83,1,26,8058566320480,128,19490,94241799,CLX5
2025-09-24 19:31:12.645224575+00:00,160,1,432669,A,A,64.83,1,26,8058566320580,128,18427,94241829,CLX5
2025-09-24 19:31:12.645400363+00:00,160,1,432669,C,B,64.82,2,26,8058566320560,128,19326,94241830,CLX5
2025-09-24 19:31:12.645448515+00:00,160,1,432669,C,B,64.82,1,26,8058566320562,128,16937,94241831,CLX5
2025-09-24 19:31:12.645583811+00:00,160,1,432669,C,B,64.82,2,26,8058566320436,128,21774,94241832,CLX5
2025-09-24 19:31:13.471040395+00:00,160,1,432669,C,A,64.84,1,26,8058566317159,128,22021,94241843,CLX5
2025-09-24 19:31:16.376961839+00:00,160,1,432669,T,A,64.82,1,26,8058566320602,0,18324,94241910,CLX5
2025-09-24 19:31:16.376961839+00:00,160,1,432669,F,B,64.82,1,26,8058566320267,0,18324,94241910,CLX5
2025-09-24 19:31:16.376961839+00:00,160,1,432669,C,B,64.82,1,26,8058566320267,128,16250,94241911,CLX5
2025-09-24 19:31:16.586003471+00:00,160,1,432669,T,A,64.82,1,26,8058566320607,0,19107,94241926,CLX5
2025-09-24 19:31:16.586003471+00:00,160,1,432669,F,B,64.82,1,26,8058566320558,0,19107,94241926,CLX5
2025-09-24 19:31:16.586003471+00:00,160,1,432669,M,B,64.82,1,26,8058566320558,128,16197,94241927,CLX5
2025-09-24 19:31:16.586298293+00:00,160,1,432669,A,A,64.83,2,26,8058566320608,128,20144,94241930,CLX5
2025-09-24 19:31:16.586305973+00:00,160,1,432669,A,A,64.83,1,26,8058566320609,128,14735,94241931,CLX5
2025-09-24 19:31:16.586318567+00:00,160,1,432669,A,A,64.83,1,26,8058566320610,128,15999,94241932,CLX5
2025-09-24 19:31:16.672749125+00:00,160,1,432669,A,B,64.82,1,26,8058566320612,128,18312,94241940,CLX5
2025-09-24 19:31:16.672935837+00:00,160,1,432669,C,A,64.83,1,26,8058566320610,128,15326,94241945,CLX5
2025-09-24 19:31:17.560932723+00:00,160,1,432669,A,A,64.83,1,26,8058566320622,128,19106,94241978,CLX5
2025-09-24 19:31:21.500102713+00:00,160,1,432669,T,A,64.82,1,26,8058566320634,0,24305,94242003,CLX5
2025-09-24 19:31:21.500102713+00:00,160,1,432669,F,B,64.82,1,26,8058566320558,0,24305,94242003,CLX5
2025-09-24 19:31:21.500102713+00:00,160,1,432669,C,B,64.82,1,26,8058566320558,128,18508,94242004,CLX5
2025-09-24 19:31:21.500407365+00:00,160,1,432669,C,B,64.82,1,26,8058566320559,128,22722,94242007,CLX5
2025-09-24 19:31:21.500407517+00:00,160,1,432669,C,B,64.82,1,26,8058566320612,128,18636,94242009,CLX5
2025-09-24 19:31:21.500616943+00:00,160,1,432669,A,B,64.81,2,26,8058566320639,128,18054,94242019,CLX5
2025-09-24 19:31:21.500628789+00:00,160,1,432669,A,A,64.83,3,26,8058566320640,128,18139,94242020,CLX5
2025-09-24 19:31:21.500663999+00:00,160,1,432669,A,A,64.83,1,26,8058566320641,128,22711,94242021,CLX5
2025-09-24 19:31:21.500840843+00:00,160,1,432669,C,A,64.83,1,26,8058566320609,128,18178,94242022,CLX5
2025-09-24 19:31:21.500869393+00:00,160,1,432669,A,A,64.83,1,26,8058566320642,128,16749,94242023,CLX5
2025-09-24 19:31:21.500905851+00:00,160,1,432669,A,A,64.83,1,26,8058566320643,128,21175,94242024,CLX5
2025-09-24 19:31:21.500918215+00:00,160,1,432669,M,B,63.65,4,26,8058566291224,128,17382,94242025,CLX5
2025-09-24 19:31:21.501076647+00:00,160,1,432669,A,B,64.81,1,26,8058566320645,128,19701,94242027,CLX5
2025-09-24 19:31:21.501114699+00:00,160,1,432669,C,B,64.79,1,26,8058566320052,128,17452,94242028,CLX5
2025-09-24 19:31:21.501259767+00:00,160,1,432669,A,A,64.83,1,26,8058566320647,128,17526,94242033,CLX5
2025-09-24 19:31:21.509429277+00:00,160,1,432669,A,B,64.77,2,26,8058566320648,128,21652,94242040,CLX5
2025-09-24 19:31:21.515009029+00:00,160,1,432669,C,A,64.83,1,26,8058566320643,128,21313,94242041,CLX5
2025-09-24 19:31:21.515015807+00:00,160,1,432669,C,A,64.83,1,26,8058566320642,128,18497,94242042,CLX5
2025-09-24 19:31:21.515026099+00:00,160,1,432669,C,A,64.83,1,26,8058566320641,128,17286,94242043,CLX5
2025-09-24 19:31:21.515208665+00:00,160,1,432669,C,B,64.81,1,26,8058566320645,128,17772,94242046,CLX5
2025-09-24 19:31:21.515347339+00:00,160,1,432669,A,B,64.81,1,26,8058566320650,128,21345,94242047,CLX5
2025-09-24 19:31:21.569460001+00:00,160,1,432669,C,B,64.8,5,26,8058566286350,128,21489,94242050,CLX5
2025-09-24 19:31:21.773408461+00:00,160,1,432669,C,B,64.81,1,26,8058566320650,128,20730,94242053,CLX5
2025-09-24 19:31:21.773576607+00:00,160,1,432669,A,B,64.81,1,26,8058566320653,128,20952,94242054,CLX5
2025-09-24 19:31:23.141978327+00:00,160,1,432669,T,A,64.81,5,26,8058566320655,0,23230,94242068,CLX5
2025-09-24 19:31:23.141978327+00:00,160,1,432669,F,B,64.81,1,26,8058566288068,0,23230,94242068,CLX5
2025-09-24 19:31:23.141978327+00:00,160,1,432669,F,B,64.81,2,26,8058566288099,0,23230,94242068,CLX5
2025-09-24 19:31:23.141978327+00:00,160,1,432669,F,B,64.81,1,26,8058566288142,0,23230,94242068,CLX5
2025-09-24 19:31:23.141978327+00:00,160,1,432669,F,B,64.81,1,26,8058566288513,0,23230,94242068,CLX5
2025-09-24 19:31:23.141978327+00:00,160,1,432669,C,B,64.81,1,26,8058566288068,0,18609,94242069,CLX5
2025-09-24 19:31:23.141978327+00:00,160,1,432669,C,B,64.81,2,26,8058566288099,0,18609,94242069,CLX5
2025-09-24 19:31:23.141978327+00:00,160,1,432669,C,B,64.81,1,26,8058566288142,0,18609,94242069,CLX5
2025-09-24 19:31:23.141978327+00:00,160,1,432669,C,B,64.81,1,26,8058566288513,128,18609,94242069,CLX5
2025-09-24 19:31:23.142326273+00:00,160,1,432669,A,A,64.82,2,26,8058566320657,128,20660,94242072,CLX5
2025-09-24 19:31:23.142346413+00:00,160,1,432669,C,B,64.81,1,26,8058566320653,128,17652,94242090,CLX5
2025-09-24 19:31:23.142348065+00:00,160,1,432669,C,A,64.82,2,26,8058566320657,128,20804,94242091,CLX5
2025-09-24 19:31:23.142431773+00:00,160,1,432669,A,B,64.81,1,26,8058566320663,128,21010,94242097,CLX5
2025-09-24 19:31:23.142535179+00:00,160,1,432669,C,B,64.81,1,26,8058566320663,128,17478,94242105,CLX5
2025-09-24 19:31:23.142871701+00:00,160,1,432669,A,B,64.81,1,26,8058566320665,128,17825,94242123,CLX5
2025-09-24 19:31:23.142892205+00:00,160,1,432669,C,A,64.83,1,26,8058566320580,128,17316,94242124,CLX5
2025-09-24 19:31:23.142954779+00:00,160,1,432669,M,A,64.84,4,26,8058566275421,128,17730,94242129,CLX5
2025-09-24 19:31:23.143092071+00:00,160,1,432669,A,A,64.82,1,26,8058566320669,128,18700,94242137,CLX5
2025-09-24 19:31:23.144217371+00:00,160,1,432669,M,B,64.81,2,26,8058566291224,128,17718,94242165,CLX5
2025-09-24 19:31:23.144290635+00:00,160,1,432669,C,A,64.83,1,26,8058566320647,128,15100,94242166,CLX5
2025-09-24 19:31:23.144577491+00:00,160,1,432669,A,A,64.83,1,26,8058566320675,128,15152,94242173,CLX5
2025-09-24 19:31:23.174330765+00:00,160,1,432669,C,A,64.83,1,26,8058566320675,128,18554,94242186,CLX5
2025-09-24 19:31:23.193126947+00:00,160,1,432669,A,A,64.82,1,26,8058566320677,128,18277,94242187,CLX5
2025-09-24 19:31:23.194522111+00:00,160,1,432669,A,A,64.82,1,26,8058566320680,128,18350,94242196,CLX5
2025-09-24 19:31:23.194677259+00:00,160,1,432669,A,A,64.82,1,26,8058566320681,128,18271,94242199,CLX5
2025-09-24 19:31:23.194822999+00:00,160,1,432669,T,B,64.82,4,26,8058566320683,0,18546,94242204,CLX5
2025-09-24 19:31:23.194822999+00:00,160,1,432669,F,A,64.82,1,26,8058566320669,0,18546,94242204,CLX5
2025-09-24 19:31:23.194822999+00:00,160,1,432669,F,A,64.82,1,26,8058566320677,0,18546,94242204,CLX5
2025-09-24 19:31:23.194822999+00:00,160,1,432669,F,A,64.82,1,26,8058566320680,0,18546,94242204,CLX5
2025-09-24 19:31:23.194822999+00:00,160,1,432669,F,A,64.82,1,26,8058566320681,0,18546,94242204,CLX5
2025-09-24 19:31:23.194822999+00:00,160,1,432669,C,A,64.82,1,26,8058566320669,0,15447,94242205,CLX5
2025-09-24 19:31:23.194822999+00:00,160,1,432669,C,A,64.82,1,26,8058566320677,0,15447,94242205,CLX5
2025-09-24 19:31:23.194822999+00:00,160,1,432669,C,A,64.82,1,26,8058566320680,0,15447,94242205,CLX5
2025-09-24 19:31:23.194822999+00:00,160,1,432669,C,A,64.82,1,26,8058566320681,128,15447,94242205,CLX5
2025-09-24 19:31:23.194833865+00:00,160,1,432669,A,B,64.82,1,26,8058566320684,128,14733,94242209,CLX5
2025-09-24 19:31:23.195153321+00:00,160,1,432669,A,B,64.81,1,26,8058566320687,128,15537,94242215,CLX5
2025-09-24 19:31:23.195168227+00:00,160,1,432669,A,B,64.81,1,26,8058566320689,128,15571,94242216,CLX5
2025-09-24 19:31:23.195169757+00:00,160,1,432669,A,B,64.82,2,26,8058566320690,128,20018,94242217,CLX5
2025-09-24 19:31:23.195238565+00:00,160,1,432669,A,B,64.81,2,26,8058566320694,128,19133,94242237,CLX5
2025-09-24 19:31:23.195391813+00:00,160,1,432669,M,B,63.65,4,26,8058566291224,128,15717,94242240,CLX5
2025-09-24 19:31:23.195598683+00:00,160,1,432669,M,A,65.98,4,26,8058566275421,128,19109,94242242,CLX5
2025-09-24 19:31:23.195770997+00:00,160,1,432669,A,B,64.79,1,26,8058566320697,128,14958,94242252,CLX5
2025-09-24 19:31:23.195924147+00:00,160,1,432669,A,B,64.81,1,26,8058566320698,128,15217,94242260,CLX5
2025-09-24 19:31:23.209817807+00:00,160,1,432669,C,B,64.81,1,26,8058566320698,128,18183,94242272,CLX5
2025-09-24 19:31:23.209831591+00:00,160,1,432669,A,A,64.83,1,26,8058566320699,128,15709,94242273,CLX5
2025-09-24 19:31:23.209984303+00:00,160,1,432669,A,A,64.83,1,26,8058566320700,128,18698,94242274,CLX5
2025-09-24 19:31:23.210011871+00:00,160,1,432669,A,A,64.83,1,26,8058566320701,128,15434,94242275,CLX5
2025-09-24 19:31:24.280440171+00:00,160,1,432669,C,A,64.83,1,26,8058566320701,128,18495,94242306,CLX5
2025-09-24 19:31:24.280446411+00:00,160,1,432669,C,A,64.83,1,26,8058566320700,128,15385,94242307,CLX5
2025-09-24 19:31:24.833566971+00:00,160,1,432669,C,A,64.83,1,26,8058566320699,128,20112,94242319,CLX5
2025-09-24 19:31:24.920274725+00:00,160,1,432669,A,A,64.83,1,26,8058566320718,128,15306,94242341,CLX5
2025-09-24 19:31:24.920453661+00:00,160,1,432669,C,B,64.81,1,26,8058566320689,128,15712,94242348,CLX5
2025-09-24 19:31:24.920857783+00:00,160,1,432669,C,B,64.82,2,26,8058566320690,128,18082,94242360,CLX5
2025-09-24 19:31:24.968307953+00:00,160,1,432669,T,A,64.82,1,26,8058566320724,0,20941,94242370,CLX5
2025-09-24 19:31:24.968307953+00:00,160,1,432669,F,B,64.82,1,26,8058566320684,0,20941,94242370,CLX5
2025-09-24 19:31:24.968307953+00:00,160,1,432669,C,B,64.82,1,26,8058566320684,128,14898,94242371,CLX5
2025-09-24 19:31:24.968629519+00:00,160,1,432669,C,B,64.81,1,26,8058566320687,128,15228,94242383,CLX5
2025-09-24 19:31:24.968797321+00:00,160,1,432669,A,A,64.83,1,26,8058566320733,128,15428,94242406,CLX5
2025-09-24 19:31:24.968993829+00:00,160,1,432669,A,B,64.81,1,26,8058566320736,128,15316,94242423,CLX5
2025-09-24 19:31:24.969019839+00:00,160,1,432669,A,A,64.83,1,26,8058566320737,128,14249,94242425,CLX5
2025-09-24 19:31:24.969085077+00:00,160,1,432669,A,A,64.83,1,26,8058566320738,128,15388,94242428,CLX5
2025-09-24 19:31:24.969130387+00:00,160,1,432669,A,A,64.83,1,26,8058566320740,128,15127,94242433,CLX5
2025-09-24 19:31:24.969132383+00:00,160,1,432669,C,B,64.79,1,26,8058566320697,128,15024,94242434,CLX5
2025-09-24 19:31:25.036340785+00:00,160,1,432669,C,A,64.83,1,26,8058566320740,128,18277,94242450,CLX5
2025-09-24 19:31:25.036348617+00:00,160,1,432669,C,A,64.83,1,26,8058566320737,128,15092,94242451,CLX5
2025-09-24 19:31:25.036357219+00:00,160,1,432669,C,A,64.83,1,26,8058566320733,128,14995,94242452,CLX5
2025-09-24 19:31:26.601811361+00:00,160,1,432669,A,A,64.82,3,26,8058566320762,128,18155,94242496,CLX5
2025-09-24 19:31:26.601912023+00:00,160,1,432669,C,B,64.81,1,26,8058566320665,128,18660,94242550,CLX5
2025-09-24 19:31:26.602047529+00:00,160,1,432669,A,A,64.82,2,26,8058566320770,128,22911,94242557,CLX5
2025-09-24 19:31:26.602048681+00:00,160,1,432669,C,B,64.78,1,26,8058566302456,128,18354,94242560,CLX5
2025-09-24 19:31:26.602048829+00:00,160,1,432669,C,B,64.8,2,26,8058566302528,128,15069,94242561,CLX5
2025-09-24 19:31:26.602048979+00:00,160,1,432669,C,B,64.77,1,26,8058566302713,128,15228,94242562,CLX5
2025-09-24 19:31:26.602049603+00:00,160,1,432669,C,B,64.79,2,26,8058566320130,128,15441,94242568,CLX5
2025-09-24 19:31:26.602073735+00:00,160,1,432669,A,A,64.82,1,26,8058566320777,128,17041,94242580,CLX5
2025-09-24 19:31:26.602075639+00:00,160,1,432669,A,A,64.82,2,26,8058566320778,128,19904,94242581,CLX5
2025-09-24 19:31:26.602082915+00:00,160,1,432669,C,B,64.81,2,26,8058566320694,128,15378,94242586,CLX5
2025-09-24 19:31:26.602086829+00:00,160,1,432669,A,A,64.82,2,26,8058566320780,128,16282,94242587,CLX5
2025-09-24 19:31:26.602087011+00:00,160,1,432669,A,A,64.82,1,26,8058566320781,128,18520,94242588,CLX5
2025-09-24 19:31:26.602108737+00:00,160,1,432669,A,A,64.82,1,26,8058566320783,128,15756,94242596,CLX5
2025-09-24 19:31:26.602133925+00:00,160,1,432669,A,A,64.82,1,26,8058566320785,128,15371,94242602,CLX5
2025-09-24 19:31:26.602355159+00:00,160,1,432669,M,A,64.84,4,26,8058566275421,128,15353,94242612,CLX5
2025-09-24 19:31:26.602491547+00:00,160,1,432669,C,A,64.83,1,26,8058566320738,128,15059,94242617,CLX5
2025-09-24 19:31:26.602700493+00:00,160,1,432669,A,A,64.82,2,26,8058566320792,128,18540,94242624,CLX5
2025-09-24 19:31:26.602700877+00:00,160,1,432669,C,A,64.82,2,26,8058566320778,128,15723,94242625,CLX5
2025-09-24 19:31:26.603482053+00:00,160,1,432669,C,B,64.77,2,26,8058566320648,128,14731,94242658,CLX5
2025-09-24 19:31:26.603483089+00:00,160,1,432669,C,B,64.72,2,26,8058566302431,128,18141,94242659,CLX5
2025-09-24 19:31:26.603507145+00:00,160,1,432669,C,A,64.82,1,26,8058566320781,128,15727,94242660,CLX5
2025-09-24 19:31:26.603513655+00:00,160,1,432669,C,A,64.82,2,26,8058566320780,128,16098,94242661,CLX5
2025-09-24 19:31:26.603850601+00:00,160,1,432669,C,A,64.82,2,26,8058566320792,128,16554,94242688,CLX5
2025-09-24 19:31:26.603851699+00:00,160,1,432669,C,B,64.81,2,26,8058566320639,128,15977,94242690,CLX5
2025-09-24 19:31:26.604286939+00:00,160,1,432669,C,B,64.76,1,26,8058566305832,128,18571,94242715,CLX5
2025-09-24 19:31:26.604814647+00:00,160,1,432669,C,A,64.82,1,26,8058566320785,128,16642,94242734,CLX5
2025-09-24 19:31:26.605081765+00:00,160,1,432669,A,B,64.81,2,26,8058566320831,128,16721,94242745,CLX5
2025-09-24 19:31:26.605417711+00:00,160,1,432669,A,B,64.81,1,26,8058566320834,128,14396,94242751,CLX5
2025-09-24 19:31:26.605423413+00:00,160,1,432669,T,B,64.82,7,26,8058566320835,0,14858,94242752,CLX5
2025-09-24 19:31:26.605423413+00:00,160,1,432669,F,A,64.82,3,26,8058566320762,0,14858,94242752,CLX5
2025-09-24 19:31:26.605423413+00:00,160,1,432669,F,A,64.82,2,26,8058566320770,0,14858,94242752,CLX5
2025-09-24 19:31:26.605423413+00:00,160,1,432669,F,A,64.82,1,26,8058566320777,0,14858,94242752,CLX5
2025-09-24 19:31:26.605423413+00:00,160,1,432669,F,A,64.82,1,26,8058566320783,0,14858,94242752,CLX5
2025-09-24 19:31:26.605423413+00:00,160,1,432669,C,A,64.82,3,26,8058566320762,0,19121,94242753,CLX5
2025-09-24 19:31:26.605423413+00:00,160,1,432669,C,A,64.82,2,26,8058566320770,0,19121,94242753,CLX5
2025-09-24 19:31:26.605423413+00:00,160,1,432669,C,A,64.82,1,26,8058566320777,0,19121,94242753,CLX5
2025-09-24 19:31:26.605423413+00:00,160,1,432669,C,A,64.82,1,26,8058566320783,128,19121,94242753,CLX5
2025-09-24 19:31:26.605433743+00:00,160,1,432669,A,B,64.82,3,26,8058566320836,128,14900,94242757,CLX5
2025-09-24 19:31:26.605599295+00:00,160,1,432669,C,B,64.81,1,26,8058566320834,128,14926,94242764,CLX5
2025-09-24 19:31:26.605601849+00:00,160,1,432669,C,B,64.81,2,26,8058566320831,128,19511,94242766,CLX5
2025-09-24 19:31:26.605804131+00:00,160,1,432669,A,B,64.81,2,26,8058566320840,128,16061,94242783,CLX5
2025-09-24 19:31:26.605851497+00:00,160,1,432669,A,B,64.81,1,26,8058566320842,128,14949,94242786,CLX5
2025-09-24 19:31:26.607052669+00:00,160,1,432669,A,B,64.81,1,26,8058566320845,128,15418,94242807,CLX5
2025-09-24 19:31:26.607053901+00:00,160,1,432669,A,B,64.82,2,26,8058566320846,128,14854,94242808,CLX5
2025-09-24 19:31:26.607077383+00:00,160,1,432669,A,B,64.82,1,26,8058566320850,128,17376,94242817,CLX5
2025-09-24 19:31:26.607147747+00:00,160,1,432669,C,A,64.83,1,26,8058566320718,128,18654,94242824,CLX5
2025-09-24 19:31:26.607178927+00:00,160,1,432669,A,B,64.82,3,26,8058566320851,128,16374,94242825,CLX5
2025-09-24 19:31:26.607179105+00:00,160,1,432669,A,B,64.82,2,26,8058566320852,128,15196,94242826,CLX5
2025-09-24 19:31:26.607205171+00:00,160,1,432669,A,B,64.81,2,26,8058566320855,128,17464,94242831,CLX5
2025-09-24 19:31:26.607271505+00:00,160,1,432669,A,B,64.81,1,26,8058566320856,128,15351,94242832,CLX5
2025-09-24 19:31:26.607332595+00:00,160,1,432669,A,B,64.81,1,26,8058566320857,128,14280,94242834,CLX5
2025-09-24 19:31:26.607655661+00:00,160,1,432669,C,B,64.82,2,26,8058566320852,128,16473,94242841,CLX5
2025-09-24 19:31:26.607693579+00:00,160,1,432669,C,B,64.82,3,26,8058566320851,128,16778,94242845,CLX5
2025-09-24 19:31:26.609850161+00:00,160,1,432669,C,A,64.85,1,26,8058566319376,128,15203,94242919,CLX5
2025-09-24 19:31:26.616904583+00:00,160,1,432669,A,A,64.83,1,26,8058566320899,128,18925,94242998,CLX5
2025-09-24 19:31:26.617047731+00:00,160,1,432669,A,B,64.77,1,26,8058566320901,128,14801,94243003,CLX5
2025-09-24 19:31:26.617068813+00:00,160,1,432669,A,A,64.83,1,26,8058566320902,128,18517,94243005,CLX5
2025-09-24 19:31:26.617276241+00:00,160,1,432669,A,A,64.83,1,26,8058566320903,128,17447,94243008,CLX5
2025-09-24 19:31:26.617420445+00:00,160,1,432669,C,B,64.81,1,26,8058566320857,128,19005,94243009,CLX5
2025-09-24 19:31:26.617431313+00:00,160,1,432669,C,B,64.81,1,26,8058566320856,128,15595,94243010,CLX5
2025-09-24 19:31:26.646568121+00:00,160,1,432669,A,B,64.72,2,26,8058566320913,128,18108,94243036,CLX5
2025-09-24 19:31:26.663496955+00:00,160,1,432669,A,B,64.8,2,26,8058566320918,128,18738,94243043,CLX5
2025-09-24 19:31:26.663501101+00:00,160,1,432669,A,B,64.79,2,26,8058566320919,128,14808,94243044,CLX5
2025-09-24 19:31:26.749733215+00:00,160,1,432669,A,B,64.78,1,26,8058566320930,128,19077,94243065,CLX5
2025-09-24 19:31:27.045917593+00:00,160,1,432669,C,A,64.83,1,26,8058566320903,128,19534,94243129,CLX5
2025-09-24 19:31:27.045927731+00:00,160,1,432669,C,A,64.83,1,26,8058566320902,128,15291,94243130,CLX5
2025-09-24 19:31:27.045934219+00:00,160,1,432669,C,A,64.83,1,26,8058566320899,128,15134,94243131,CLX5
2025-09-24 19:31:27.046071801+00:00,160,1,432669,A,B,64.79,1,26,8058566320981,128,14781,94243134,CLX5
2025-09-24 19:31:27.630814845+00:00,160,1,432669,C,B,64.82,2,26,8058566320846,128,19417,94243185,CLX5
2025-09-24 19:31:27.630824959+00:00,160,1,432669,T,A,64.82,4,26,8058566321021,0,18420,94243245,CLX5
2025-09-24 19:31:27.630824959+00:00,160,1,432669,F,B,64.82,3,26,8058566320836,0,18420,94243245,CLX5
2025-09-24 19:31:27.630824959+00:00,160,1,432669,F,B,64.82,1,26,8058566320850,0,18420,94243245,CLX5
2025-09-24 19:31:27.630824959+00:00,160,1,432669,C,B,64.82,3,26,8058566320836,0,15742,94243246,CLX5
2025-09-24 19:31:27.630824959+00:00,160,1,432669,C,B,64.82,1,26,8058566320850,128,15742,94243246,CLX5
2025-09-24 19:31:27.631878535+00:00,160,1,432669,A,A,64.83,1,26,8058566321026,128,18864,94243268,CLX5
2025-09-24 19:31:27.632259447+00:00,160,1,432669,A,A,64.83,1,26,8058566321035,128,17789,94243298,CLX5
2025-09-24 19:31:27.632352793+00:00,160,1,432669,A,A,64.83,1,26,8058566321036,128,16142,94243300,CLX5
2025-09-24 19:31:27.632383627+00:00,160,1,432669,C,B,64.79,1,26,8058566320981,128,18756,94243303,CLX5
2025-09-24 19:31:27.632545379+00:00,160,1,432669,A,A,64.83,1,26,8058566321040,128,14552,94243311,CLX5
2025-09-24 19:31:27.632616569+00:00,160,1,432669,A,A,64.82,2,26,8058566321041,128,14884,94243314,CLX5
2025-09-24 19:31:27.632652723+00:00,160,1,432669,A,A,64.83,1,26,8058566321042,128,15134,94243317,CLX5
2025-09-24 19:31:27.632678277+00:00,160,1,432669,A,A,64.82,1,26,8058566321043,128,15107,94243319,CLX5
2025-09-24 19:31:27.632766189+00:00,160,1,432669,C,B,64.81,1,26,8058566320845,128,14989,94243321,CLX5
2025-09-24 19:31:27.633279383+00:00,160,1,432669,A,A,64.82,2,26,8058566321045,128,22686,94243333,CLX5
2025-09-24 19:31:27.682572211+00:00,160,1,432669,C,A,64.83,1,26,8058566321036,128,18248,94243367,CLX5
2025-09-24 19:31:27.682729279+00:00,160,1,432669,C,B,64.81,2,26,8058566320840,128,18491,94243368,CLX5
2025-09-24 19:31:27.682763069+00:00,160,1,432669,C,A,64.83,1,26,8058566321042,128,15051,94243369,CLX5
2025-09-24 19:31:27.682772379+00:00,160,1,432669,C,A,64.83,1,26,8058566321040,128,15172,94243370,CLX5
2025-09-24 19:31:27.682776969+00:00,160,1,432669,C,A,64.83,1,26,8058566321035,128,14849,94243371,CLX5
2025-09-24 19:31:27.709474313+00:00,160,1,432669,A,B,64.77,2,26,8058566321063,128,18604,94243375,CLX5
2025-09-24 19:31:27.719952443+00:00,160,1,432669,M,B,64.54,1,26,8058566301815,128,18367,94243376,CLX5
2025-09-24 19:31:27.993779177+00:00,160,1,432669,A,A,64.82,1,26,8058566321103,128,23141,94243428,CLX5
2025-09-24 19:31:30.001285211+00:00,160,1,432669,A,B,64.76,1,26,8058566321133,128,21906,94243474,CLX5
2025-09-24 19:31:30.697810361+00:00,160,1,432669,T,B,64.82,7,26,8058566321144,0,22425,94243497,CLX5
2025-09-24 19:31:30.697810361+00:00,160,1,432669,F,A,64.82,2,26,8058566321041,0,22425,94243497,CLX5
2025-09-24 19:31:30.697810361+00:00,160,1,432669,F,A,64.82,1,26,8058566321043,0,22425,94243497,CLX5
2025-09-24 19:31:30.697810361+00:00,160,1,432669,F,A,64.82,2,26,8058566321045,0,22425,94243497,CLX5
2025-09-24 19:31:30.697810361+00:00,160,1,432669,F,A,64.82,1,26,8058566321103,0,22425,94243497,CLX5
2025-09-24 19:31:30.697810361+00:00,160,1,432669,C,A,64.82,2,26,8058566321041,0,20216,94243498,CLX5
2025-09-24 19:31:30.697810361+00:00,160,1,432669,C,A,64.82,1,26,8058566321043,0,20216,94243498,CLX5
2025-09-24 19:31:30.697810361+00:00,160,1,432669,C,A,64.82,2,26,8058566321045,0,20216,94243498,CLX5
2025-09-24 19:31:30.697810361+00:00,160,1,432669,C,A,64.82,1,26,8058566321103,128,20216,94243498,CLX5
2025-09-24 19:31:30.698132465+00:00,160,1,432669,A,B,64.81,1,26,8058566321155,128,18996,94243531,CLX5
2025-09-24 19:31:30.698135985+00:00,160,1,432669,C,A,64.86,1,26,8058566319952,128,15214,94243548,CLX5
2025-09-24 19:31:30.698142775+00:00,160,1,432669,C,A,64.83,1,26,8058566321026,128,14977,94243593,CLX5
2025-09-24 19:31:30.698144331+00:00,160,1,432669,A,B,64.81,2,26,8058566321160,128,15508,94243598,CLX5
2025-09-24 19:31:30.698431377+00:00,160,1,432669,A,B,64.82,1,26,8058566321171,128,15437,94243638,CLX5
2025-09-24 19:31:30.698482409+00:00,160,1,432669,C,A,64.83,2,26,8058566319973,128,18859,94243658,CLX5
2025-09-24 19:31:30.698997465+00:00,160,1,432669,A,B,64.81,1,26,8058566321180,128,18717,94243677,CLX5
2025-09-24 19:31:30.699105881+00:00,160,1,432669,A,B,64.81,1,26,8058566321182,128,14931,94243686,CLX5
2025-09-24 19:31:30.700290449+00:00,160,1,432669,A,B,64.54,8,26,8058566321185,128,14533,94243702,CLX5
2025-09-24 19:31:30.700706093+00:00,160,1,432669,A,A,64.83,1,26,8058566321192,128,15355,94243739,CLX5
2025-09-24 19:31:30.700742495+00:00,160,1,432669,A,B,64.82,1,26,8058566321193,128,18517,94243740,CLX5
2025-09-24 19:31:30.700819503+00:00,160,1,432669,C,B,64.8,2,26,8058566320918,128,14429,94243743,CLX5
2025-09-24 19:31:30.700820415+00:00,160,1,432669,C,B,64.79,2,26,8058566320919,128,18690,94243748,CLX5
2025-09-24 19:31:30.700820809+00:00,160,1,432669,C,B,64.77,2,26,8058566321063,128,15104,94243750,CLX5
2025-09-24 19:31:30.700822019+00:00,160,1,432669,C,B,64.72,2,26,8058566320913,128,14531,94243751,CLX5
2025-09-24 19:31:30.700833479+00:00,160,1,432669,T,A,64.82,2,26,8058566321194,0,15229,94243752,CLX5
2025-09-24 19:31:30.700833479+00:00,160,1,432669,F,B,64.82,1,26,8058566321171,0,15229,94243752,CLX5
2025-09-24 19:31:30.700833479+00:00,160,1,432669,F,B,64.82,1,26,8058566321193,0,15229,94243752,CLX5
2025-09-24 19:31:30.700833479+00:00,160,1,432669,C,B,64.82,1,26,8058566321171,0,15229,94243752,CLX5
2025-09-24 19:31:30.700833479+00:00,160,1,432669,C,B,64.82,1,26,8058566321193,128,15229,94243752,CLX5
2025-09-24 19:31:30.700833659+00:00,160,1,432669,A,A,64.82,2,26,8058566321195,128,14946,94243755,CLX5
2025-09-24 19:31:30.700833835+00:00,160,1,432669,A,A,64.82,1,26,8058566321196,128,18337,94243759,CLX5
2025-09-24 19:31:30.701000417+00:00,160,1,432669,M,A,65.98,4,26,8058566275421,128,18657,94243767,CLX5
2025-09-24 19:31:30.701251579+00:00,160,1,432669,A,B,64.79,1,26,8058566321200,128,18180,94243778,CLX5
2025-09-24 19:31:30.701843519+00:00,160,1,432669,A,A,64.82,1,26,8058566321216,128,18211,94243861,CLX5
2025-09-24 19:31:30.702340689+00:00,160,1,432669,A,A,64.82,1,26,8058566321224,128,18635,94243893,CLX5
2025-09-24 19:31:30.702432845+00:00,160,1,432669,M,B,64.81,3,26,8058566291224,128,16734,94243896,CLX5
2025-09-24 19:31:30.702452967+00:00,160,1,432669,A,B,64.8,1,26,8058566321226,128,15118,94243897,CLX5
2025-09-24 19:31:30.702686389+00:00,160,1,432669,A,A,64.86,1,26,8058566321231,128,16954,94243909,CLX5
2025-09-24 19:31:30.702699367+00:00,160,1,432669,C,B,64.81,2,26,8058566321160,128,15262,94243910,CLX5
2025-09-24 19:31:30.702781445+00:00,160,1,432669,A,A,64.82,2,26,8058566321232,128,17132,94243911,CLX5
2025-09-24 19:31:30.702782789+00:00,160,1,432669,A,A,64.82,2,26,8058566321233,128,19608,94243912,CLX5
2025-09-24 19:31:30.702798627+00:00,160,1,432669,A,A,64.82,2,26,8058566321234,128,16472,94243913,CLX5
2025-09-24 19:31:30.702803927+00:00,160,1,432669,C,B,64.81,1,26,8058566321182,128,14296,94243915,CLX5
2025-09-24 19:31:30.702814025+00:00,160,1,432669,C,B,64.81,1,26,8058566321180,128,15542,94243918,CLX5
2025-09-24 19:31:30.702825873+00:00,160,1,432669,C,B,64.81,1,26,8058566321155,128,15429,94243921,CLX5
2025-09-24 19:31:30.702901229+00:00,160,1,432669,C,B,64.81,3,26,8058566291224,128,19505,94243924,CLX5
2025-09-24 19:31:30.703232971+00:00,160,1,432669,M,A,64.84,4,26,8058566288785,128,18490,94243933,CLX5
2025-09-24 19:31:30.704893831+00:00,160,1,432669,C,A,64.82,2,26,8058566321234,128,16630,94243959,CLX5
2025-09-24 19:31:30.705080967+00:00,160,1,432669,C,A,64.82,2,26,8058566321232,128,17076,94243963,CLX5
2025-09-24 19:31:30.705114833+00:00,160,1,432669,C,A,64.82,2,26,8058566321233,128,18777,94243964,CLX5
2025-09-24 19:31:30.705278737+00:00,160,1,432669,C,A,64.82,1,26,8058566321224,128,25076,94243968,CLX5
2025-09-24 19:31:30.705798055+00:00,160,1,432669,A,A,64.82,1,26,8058566321253,128,18158,94243981,CLX5
2025-09-24 19:31:30.706670023+00:00,160,1,432669,A,A,64.82,2,26,8058566321260,128,16847,94244010,CLX5
2025-09-24 19:31:30.707178589+00:00,160,1,432669,C,A,64.82,2,26,8058566321260,128,20176,94244017,CLX5
2025-09-24 19:31:30.719995463+00:00,160,1,432669,C,B,64.54,8,26,8058566321185,128,18990,94244047,CLX5
2025-09-24 19:31:30.720124807+00:00,160,1,432669,C,B,64.8,1,26,8058566321226,128,18315,94244048,CLX5
2025-09-24 19:31:30.752053577+00:00,160,1,432669,A,B,64.72,2,26,8058566321275,128,17952,94244068,CLX5
2025-09-24 19:31:30.762030319+00:00,160,1,432669,A,B,64.8,2,26,8058566321278,128,14950,94244071,CLX5
2025-09-24 19:31:30.762034563+00:00,160,1,432669,A,B,64.79,2,26,8058566321279,128,14677,94244072,CLX5
2025-09-24 19:31:30.809826133+00:00,160,1,432669,A,B,64.77,2,26,8058566321294,128,18932,94244102,CLX5
2025-09-24 19:31:30.881288587+00:00,160,1,432669,C,B,64.79,1,26,8058566321200,128,19724,94244122,CLX5
2025-09-24 19:31:35.419135989+00:00,160,1,432669,A,B,64.81,2,26,8058566321424,128,21618,94244319,CLX5
2025-09-24 19:31:35.419164807+00:00,160,1,432669,C,A,64.82,1,26,8058566321253,128,18999,94244323,CLX5
2025-09-24 19:31:35.419411247+00:00,160,1,432669,T,B,64.82,4,26,8058566321427,0,22785,94244332,CLX5
2025-09-24 19:31:35.419411247+00:00,160,1,432669,F,A,64.82,2,26,8058566321195,0,22785,94244332,CLX5
2025-09-24 19:31:35.419411247+00:00,160,1,432669,F,A,64.82,1,26,8058566321196,0,22785,94244332,CLX5
2025-09-24 19:31:35.419411247+00:00,160,1,432669,F,A,64.82,1,26,8058566321216,0,22785,94244332,CLX5
2025-09-24 19:31:35.419411247+00:00,160,1,432669,C,A,64.82,2,26,8058566321195,0,19248,94244333,CLX5
2025-09-24 19:31:35.419411247+00:00,160,1,432669,C,A,64.82,1,26,8058566321196,0,19248,94244333,CLX5
2025-09-24 19:31:35.419411247+00:00,160,1,432669,C,A,64.82,1,26,8058566321216,128,19248,94244333,CLX5
2025-09-24 19:31:35.419421961+00:00,160,1,432669,A,B,64.82,1,26,8058566321428,128,20070,94244336,CLX5
2025-09-24 19:31:35.419749593+00:00,160,1,432669,A,B,64.81,1,26,8058566321434,128,15115,94244347,CLX5
2025-09-24 19:31:35.419807343+00:00,160,1,432669,A,B,64.82,2,26,8058566321442,128,14036,94244377,CLX5
2025-09-24 19:31:35.419820093+00:00,160,1,432669,C,A,64.83,1,26,8058566321192,128,19183,94244380,CLX5
2025-09-24 19:31:35.419917817+00:00,160,1,432669,A,B,64.82,1,26,8058566321444,128,14569,94244389,CLX5
2025-09-24 19:31:35.420140585+00:00,160,1,432669,M,A,65.99,4,26,8058566288785,128,15111,94244407,CLX5
2025-09-24 19:31:35.420169537+00:00,160,1,432669,A,B,64.82,2,26,8058566321446,128,15543,94244410,CLX5
2025-09-24 19:31:35.420399099+00:00,160,1,432669,C,B,64.82,2,26,8058566321446,128,18827,94244429,CLX5
2025-09-24 19:31:35.420425327+00:00,160,1,432669,A,B,64.79,1,26,8058566321452,128,18001,94244430,CLX5
2025-09-24 19:31:35.420605799+00:00,160,1,432669,M,B,64.81,3,26,8058566319508,128,15070,94244442,CLX5
2025-09-24 19:31:35.424563665+00:00,160,1,432669,A,A,65.97,4,26,8058566321460,128,18024,94244480,CLX5
2025-09-24 19:31:35.592112641+00:00,160,1,432669,A,B,64.81,2,26,8058566321508,128,19077,94244577,CLX5
2025-09-24 19:31:36.500008981+00:00,160,1,432669,C,B,64.82,1,26,8058566321444,128,20785,94244618,CLX5
2025-09-24 19:31:36.626384355+00:00,160,1,432669,T,A,64.82,1,26,8058566321532,0,18340,94244627,CLX5
2025-09-24 19:31:36.626384355+00:00,160,1,432669,F,B,64.82,1,26,8058566321428,0,18340,94244627,CLX5
2025-09-24 19:31:36.626384355+00:00,160,1,432669,C,B,64.82,1,26,8058566321428,128,16679,94244628,CLX5
2025-09-24 19:31:36.626691715+00:00,160,1,432669,C,B,64.82,2,26,8058566321442,128,14925,94244632,CLX5
2025-09-24 19:31:36.627073201+00:00,160,1,432669,M,B,63.66,4,26,8058566319508,128,18940,94244636,CLX5
2025-09-24 19:31:36.627349227+00:00,160,1,432669,C,B,64.79,1,26,8058566321452,128,18528,94244637,CLX5
2025-09-24 19:31:36.627351897+00:00,160,1,432669,A,A,64.83,1,26,8058566321534,128,15042,94244638,CLX5
2025-09-24 19:31:36.627503395+00:00,160,1,432669,A,A,64.83,1,26,8058566321535,128,19463,94244639,CLX5
2025-09-24 19:31:36.627664573+00:00,160,1,432669,A,A,64.83,1,26,8058566321537,128,17637,94244641,CLX5
2025-09-24 19:31:37.001372289+00:00,160,1,432669,C,A,64.83,1,26,8058566321537,128,19449,94244643,CLX5
2025-09-24 19:31:37.001383923+00:00,160,1,432669,C,A,64.83,1,26,8058566321535,128,15373,94244644,CLX5
2025-09-24 19:31:37.001389511+00:00,160,1,432669,C,A,64.83,1,26,8058566321534,128,15177,94244645,CLX5
2025-09-24 19:31:37.201187533+00:00,160,1,432669,A,A,64.83,1,26,8058566321539,128,19413,94244646,CLX5
2025-09-24 19:31:42.815459287+00:00,160,1,432669,A,B,64.82,2,26,8058566321575,128,18181,94244761,CLX5
2025-09-24 19:31:42.815551213+00:00,160,1,432669,A,B,64.82,2,26,8058566321577,128,17590,94244766,CLX5
2025-09-24 19:31:42.815672379+00:00,160,1,432669,A,B,64.82,1,26,8058566321578,128,15058,94244771,CLX5
2025-09-24 19:31:42.815734641+00:00,160,1,432669,A,B,64.82,1,26,8058566321579,128,17020,94244776,CLX5
2025-09-24 19:31:42.816203697+00:00,160,1,432669,A,B,64.79,1,26,8058566321584,128,16193,94244798,CLX5
2025-09-24 19:31:42.898025343+00:00,160,1,432669,M,B,64.81,3,26,8058566319508,128,18787,94244898,CLX5
2025-09-24 19:31:43.900008501+00:00,160,1,432669,C,B,64.82,1,26,8058566321579,128,17366,94244953,CLX5
2025-09-24 19:31:45.017632845+00:00,160,1,432669,A,B,64.82,2,26,8058566321643,128,19829,94244989,CLX5
2025-09-24 19:31:45.017774571+00:00,160,1,432669,A,B,64.82,1,26,8058566321644,128,16206,94244992,CLX5
2025-09-24 19:31:45.017819959+00:00,160,1,432669,A,B,64.82,1,26,8058566321647,128,16158,94245002,CLX5
2025-09-24 19:31:45.018784657+00:00,160,1,432669,C,B,64.82,2,26,8058566321643,128,14160,94245034,CLX5
2025-09-24 19:31:45.018955299+00:00,160,1,432669,C,B,64.82,1,26,8058566321647,128,16608,94245039,CLX5
2025-09-24 19:31:45.020831633+00:00,160,1,432669,A,B,64.82,1,26,8058566321662,128,16294,94245063,CLX5
2025-09-24 19:31:45.020832171+00:00,160,1,432669,A,B,64.82,1,26,8058566321663,128,16250,94245064,CLX5
2025-09-24 19:31:45.020833919+00:00,160,1,432669,A,B,64.82,1,26,8058566321664,128,19791,94245065,CLX5
2025-09-24 19:31:45.020840733+00:00,160,1,432669,A,B,64.82,1,26,8058566321666,128,16055,94245067,CLX5
2025-09-24 19:31:45.020848413+00:00,160,1,432669,A,B,64.82,3,26,8058566321668,128,15388,94245070,CLX5
2025-09-24 19:31:45.020851485+00:00,160,1,432669,C,A,64.86,2,26,8058566320040,128,14695,94245073,CLX5
2025-09-24 19:31:45.020852925+00:00,160,1,432669,C,A,64.83,2,26,8058566320608,128,18284,94245074,CLX5
2025-09-24 19:31:45.020898695+00:00,160,1,432669,A,B,64.82,2,26,8058566321672,128,14458,94245080,CLX5
2025-09-24 19:31:45.021214445+00:00,160,1,432669,C,B,64.82,2,26,8058566321672,128,15925,94245090,CLX5
2025-09-24 19:31:45.021370919+00:00,160,1,432669,C,B,64.82,3,26,8058566321668,128,15298,94245107,CLX5
2025-09-24 19:31:45.021406227+00:00,160,1,432669,M,A,64.95,1,26,8058565075241,128,15008,94245108,CLX5
2025-09-24 19:31:45.021825151+00:00,160,1,432669,C,B,64.82,1,26,8058566321664,128,16136,94245122,CLX5
2025-09-24 19:31:45.021970893+00:00,160,1,432669,C,B,64.82,1,26,8058566321662,128,19712,94245125,CLX5
2025-09-24 19:31:45.022190549+00:00,160,1,432669,M,A,64.94,1,26,8058565075241,128,14882,94245129,CLX5
2025-09-24 19:31:45.022409957+00:00,160,1,432669,M,B,64.81,1,26,8058566321508,128,15093,94245150,CLX5
2025-09-24 19:31:45.030870083+00:00,160,1,432669,C,B,64.82,1,26,8058566321666,128,19440,94245187,CLX5
2025-09-24 19:31:45.031617469+00:00,160,1,432669,C,B,64.82,1,26,8058566321644,128,19679,94245194,CLX5
2025-09-24 19:31:45.031625763+00:00,160,1,432669,C,B,64.82,1,26,8058566321663,128,17076,94245195,CLX5
2025-09-24 19:31:45.093732219+00:00,160,1,432669,A,B,64.82,1,26,8058566321696,128,16913,94245216,CLX5
2025-09-24 19:31:45.093736271+00:00,160,1,432669,A,B,64.82,3,26,8058566321697,128,19569,94245217,CLX5
2025-09-24 19:31:45.093933293+00:00,160,1,432669,A,B,64.82,1,26,8058566321698,128,19290,94245218,CLX5
2025-09-24 19:31:45.094210489+00:00,160,1,432669,A,B,64.82,1,26,8058566321699,128,19349,94245219,CLX5
2025-09-24 19:31:45.094220395+00:00,160,1,432669,A,B,64.82,1,26,8058566321701,128,14194,94245221,CLX5
2025-09-24 19:31:45.094221817+00:00,160,1,432669,A,B,64.82,1,26,8058566321704,128,16689,94245226,CLX5
2025-09-24 19:31:45.094226809+00:00,160,1,432669,A,B,64.82,1,26,8058566321705,128,15452,94245228,CLX5
2025-09-24 19:31:45.094341369+00:00,160,1,432669,M,A,64.95,1,26,8058565075241,128,15052,94245234,CLX5
2025-09-24 19:31:45.098593311+00:00,160,1,432669,A,B,64.81,1,26,8058566321713,128,18461,94245257,CLX5
2025-09-24 19:31:45.125616253+00:00,160,1,432669,C,A,64.83,1,26,8058566319974,128,18449,94245265,CLX5
2025-09-24 19:31:45.182127061+00:00,160,1,432669,C,B,64.82,1,26,8058566321701,128,18822,94245285,CLX5
2025-09-24 19:31:45.182150215+00:00,160,1,432669,C,B,64.82,1,26,8058566321705,128,15482,94245286,CLX5
2025-09-24 19:31:45.209567411+00:00,160,1,432669,A,A,64.88,2,26,8058566321732,128,19097,94245302,CLX5
2025-09-24 19:31:45.309883007+00:00,160,1,432669,A,B,64.78,2,26,8058566321739,128,17938,94245314,CLX5
2025-09-24 19:31:45.890491993+00:00,160,1,432669,A,B,64.82,1,26,8058566321757,128,15407,94245368,CLX5
2025-09-24 19:31:46.468557783+00:00,160,1,432669,C,B,64.82,1,26,8058566321757,128,18723,94245457,CLX5
2025-09-24 19:31:47.071351759+00:00,160,1,432669,A,B,64.82,1,26,8058566321794,128,14679,94245497,CLX5
2025-09-24 19:31:47.071472579+00:00,160,1,432669,C,B,64.82,1,26,8058566321794,128,15780,94245501,CLX5
2025-09-24 19:31:47.071757437+00:00,160,1,432669,A,B,64.82,1,26,8058566321798,128,15349,94245512,CLX5
2025-09-24 19:31:47.071775637+00:00,160,1,432669,C,B,64.82,1,26,8058566321798,128,15560,94245515,CLX5
2025-09-24 19:31:47.128874265+00:00,160,1,432669,A,B,64.82,1,26,8058566321802,128,18842,94245533,CLX5
2025-09-24 19:31:47.129023461+00:00,160,1,432669,A,B,64.82,1,26,8058566321823,128,15638,94245582,CLX5
2025-09-24 19:31:47.129455865+00:00,160,1,432669,C,A,64.83,2,26,8058566319976,128,14835,94245620,CLX5
2025-09-24 19:31:47.130019399+00:00,160,1,432669,C,A,64.83,2,26,8058566319930,128,18488,94245696,CLX5
2025-09-24 19:31:47.130026387+00:00,160,1,432669,A,B,64.82,2,26,8058566321854,128,19535,94245700,CLX5
2025-09-24 19:31:47.130113033+00:00,160,1,432669,C,A,64.83,1,26,8058566319995,128,14583,94245709,CLX5
2025-09-24 19:31:47.130409819+00:00,160,1,432669,A,B,64.81,2,26,8058566321863,128,18532,94245737,CLX5
2025-09-24 19:31:47.130415207+00:00,160,1,432669,A,B,64.54,8,26,8058566321866,128,15247,94245744,CLX5
2025-09-24 19:31:47.130417703+00:00,160,1,432669,C,B,64.78,2,26,8058566321739,128,15247,94245744,CLX5
2025-09-24 19:31:47.130432699+00:00,160,1,432669,A,B,64.82,1,26,8058566321868,128,15162,94245749,CLX5
2025-09-24 19:31:47.130545397+00:00,160,1,432669,A,B,64.82,1,26,8058566321871,128,18948,94245761,CLX5
2025-09-24 19:31:47.130820983+00:00,160,1,432669,C,A,64.83,1,26,8058566319932,128,19324,94245797,CLX5
2025-09-24 19:31:47.130823439+00:00,160,1,432669,C,A,64.83,1,26,8058566319933,128,19160,94245800,CLX5
2025-09-24 19:31:47.130827643+00:00,160,1,432669,C,A,64.83,1,26,8058566319972,128,16209,94245801,CLX5
2025-09-24 19:31:47.130937741+00:00,160,1,432669,A,B,64.82,1,26,8058566321888,128,15293,94245816,CLX5
2025-09-24 19:31:47.131102615+00:00,160,1,432669,C,B,64.82,2,26,8058566321854,128,18734,94245839,CLX5
2025-09-24 19:31:47.132208717+00:00,160,1,432669,C,A,64.86,1,26,8058566321231,128,18869,94245900,CLX5
2025-09-24 19:31:47.132213881+00:00,160,1,432669,T,B,64.83,11,26,8058566321904,0,14112,94245901,CLX5
2025-09-24 19:31:47.132213881+00:00,160,1,432669,F,A,64.83,1,26,8058566319856,0,14112,94245901,CLX5
2025-09-24 19:31:47.132213881+00:00,160,1,432669,F,A,64.83,2,26,8058566319927,0,14112,94245901,CLX5
2025-09-24 19:31:47.132213881+00:00,160,1,432669,F,A,64.83,2,26,8058566319928,0,14112,94245901,CLX5
2025-09-24 19:31:47.132213881+00:00,160,1,432669,F,A,64.83,1,26,8058566319929,0,14112,94245901,CLX5
2025-09-24 19:31:47.132213881+00:00,160,1,432669,F,A,64.83,1,26,8058566320622,0,14112,94245901,CLX5
2025-09-24 19:31:47.132213881+00:00,160,1,432669,F,A,64.83,3,26,8058566320640,0,14112,94245901,CLX5
2025-09-24 19:31:47.132213881+00:00,160,1,432669,F,A,64.83,1,26,8058566321539,0,14112,94245901,CLX5
2025-09-24 19:31:47.132213881+00:00,160,1,432669,C,A,64.83,1,26,8058566319856,0,15277,94245902,CLX5
2025-09-24 19:31:47.132213881+00:00,160,1,432669,C,A,64.83,2,26,8058566319927,0,15277,94245902,CLX5
2025-09-24 19:31:47.132213881+00:00,160,1,432669,C,A,64.83,2,26,8058566319928,0,15277,94245902,CLX5
2025-09-24 19:31:47.132213881+00:00,160,1,432669,C,A,64.83,1,26,8058566319929,0,15277,94245902,CLX5
2025-09-24 19:31:47.132213881+00:00,160,1,432669,C,A,64.83,1,26,8058566320622,0,15277,94245902,CLX5
2025-09-24 19:31:47.132213881+00:00,160,1,432669,C,A,64.83,3,26,8058566320640,0,15277,94245902,CLX5
2025-09-24 19:31:47.132213881+00:00,160,1,432669,C,A,64.83,1,26,8058566321539,128,15277,94245902,CLX5
2025-09-24 19:31:47.132224785+00:00,160,1,432669,A,B,64.83,3,26,8058566321905,128,14863,94245906,CLX5
2025-09-24 19:31:47.132270789+00:00,160,1,432669,T,A,64.83,1,26,8058566321906,0,15705,94245911,CLX5
2025-09-24 19:31:47.132270789+00:00,160,1,432669,F,B,64.83,1,26,8058566321905,0,15705,94245911,CLX5
2025-09-24 19:31:47.132270789+00:00,160,1,432669,M,B,64.83,2,26,8058566321905,128,19008,94245912,CLX5
2025-09-24 19:31:47.132682243+00:00,160,1,432669,T,A,64.83,1,26,8058566321909,0,14911,94245927,CLX5
2025-09-24 19:31:47.132682243+00:00,160,1,432669,F,B,64.83,1,26,8058566321905,0,14911,94245927,CLX5
2025-09-24 19:31:47.132682243+00:00,160,1,432669,M,B,64.83,1,26,8058566321905,128,18561,94245928,CLX5
2025-09-24 19:31:47.133461749+00:00,160,1,432669,A,B,64.82,2,26,8058566321912,128,18992,94245942,CLX5
2025-09-24 19:31:47.133590233+00:00,160,1,432669,T,A,64.83,1,26,8058566321922,0,15121,94245964,CLX5
2025-09-24 19:31:47.133590233+00:00,160,1,432669,F,B,64.83,1,26,8058566321905,0,15121,94245964,CLX5
2025-09-24 19:31:47.133590233+00:00,160,1,432669,C,B,64.83,1,26,8058566321905,128,15121,94245964,CLX5
2025-09-24 19:31:47.134432201+00:00,160,1,432669,M,B,64.82,3,26,8058566280404,128,15847,94245991,CLX5
2025-09-24 19:31:47.135930339+00:00,160,1,432669,A,B,64.83,1,26,8058566321965,128,18713,94246104,CLX5
2025-09-24 19:31:47.135930933+00:00,160,1,432669,A,B,64.83,3,26,8058566321967,128,15441,94246108,CLX5
2025-09-24 19:31:47.135944739+00:00,160,1,432669,A,B,64.83,1,26,8058566321971,128,21947,94246125,CLX5
2025-09-24 19:31:47.135949939+00:00,160,1,432669,A,B,64.82,2,26,8058566321973,128,14328,94246132,CLX5
2025-09-24 19:31:47.135957947+00:00,160,1,432669,A,A,64.84,1,26,8058566321976,128,15283,94246141,CLX5
2025-09-24 19:31:47.136046519+00:00,160,1,432669,A,B,64.83,3,26,8058566321978,128,15314,94246150,CLX5
2025-09-24 19:31:47.136046695+00:00,160,1,432669,A,B,64.83,2,26,8058566321979,128,16541,94246152,CLX5
2025-09-24 19:31:47.136046875+00:00,160,1,432669,C,A,64.84,2,26,8058566319423,128,14302,94246153,CLX5
2025-09-24 19:31:47.136047991+00:00,160,1,432669,C,A,64.84,2,26,8058566319432,128,15339,94246157,CLX5
2025-09-24 19:31:47.136062121+00:00,160,1,432669,A,B,64.83,1,26,8058566321983,128,14629,94246167,CLX5
2025-09-24 19:31:47.136073717+00:00,160,1,432669,C,B,64.81,1,26,8058566321713,128,14711,94246172,CLX5
2025-09-24 19:31:47.136375987+00:00,160,1,432669,T,A,64.83,1,26,8058566321992,0,15055,94246195,CLX5
2025-09-24 19:31:47.136375987+00:00,160,1,432669,F,B,64.83,1,26,8058566321965,0,15055,94246195,CLX5
2025-09-24 19:31:47.136375987+00:00,160,1,432669,C,B,64.83,1,26,8058566321965,128,18260,94246196,CLX5
2025-09-24 19:31:47.136378831+00:00,160,1,432669,T,A,64.83,1,26,8058566321993,0,15426,94246197,CLX5
2025-09-24 19:31:47.136378831+00:00,160,1,432669,F,B,64.83,1,26,8058566321967,0,15426,94246197,CLX5
2025-09-24 19:31:47.136378831+00:00,160,1,432669,M,B,64.83,2,26,8058566321967,128,16195,94246198,CLX5
2025-09-24 19:31:47.136574161+00:00,160,1,432669,T,A,64.83,1,26,8058566321994,0,14973,94246222,CLX5
2025-09-24 19:31:47.136574161+00:00,160,1,432669,F,B,64.83,1,26,8058566321967,0,14973,94246222,CLX5
2025-09-24 19:31:47.136574161+00:00,160,1,432669,M,B,64.83,1,26,8058566321967,128,19631,94246223,CLX5
2025-09-24 19:31:47.136605629+00:00,160,1,432669,A,B,64.8,1,26,8058566321995,128,14680,94246227,CLX5
2025-09-24 19:31:47.137051435+00:00,160,1,432669,C,B,64.83,2,26,8058566321979,128,17338,94246241,CLX5
2025-09-24 19:31:47.137084305+00:00,160,1,432669,C,B,64.82,1,26,8058566321868,128,16797,94246255,CLX5
2025-09-24 19:31:47.137173657+00:00,160,1,432669,C,B,64.83,1,26,8058566321967,128,20742,94246260,CLX5
2025-09-24 19:31:47.137332049+00:00,160,1,432669,C,B,64.82,3,26,8058566280404,128,15298,94246263,CLX5
2025-09-24 19:31:47.137574781+00:00,160,1,432669,C,B,64.83,3,26,8058566321978,128,15978,94246268,CLX5
2025-09-24 19:31:47.137668091+00:00,160,1,432669,T,A,64.83,2,26,8058566322018,0,15852,94246278,CLX5
2025-09-24 19:31:47.137668091+00:00,160,1,432669,F,B,64.83,1,26,8058566321971,0,15852,94246278,CLX5
2025-09-24 19:31:47.137668091+00:00,160,1,432669,F,B,64.83,1,26,8058566321983,0,15852,94246278,CLX5
2025-09-24 19:31:47.137668091+00:00,160,1,432669,C,B,64.83,1,26,8058566321971,0,15852,94246278,CLX5
2025-09-24 19:31:47.137668091+00:00,160,1,432669,C,B,64.83,1,26,8058566321983,128,15852,94246278,CLX5
2025-09-24 19:31:47.137694855+00:00,160,1,432669,C,B,64.82,2,26,8058566321973,128,19122,94246284,CLX5
2025-09-24 19:31:47.138083255+00:00,160,1,432669,M,A,64.85,1,26,8058566173085,128,15915,94246321,CLX5
2025-09-24 19:31:47.139443801+00:00,160,1,432669,A,A,64.84,2,26,8058566322040,128,17859,94246404,CLX5
2025-09-24 19:31:47.139931615+00:00,160,1,432669,M,B,64.82,1,26,8058566311303,128,15367,94246434,CLX5
2025-09-24 19:31:47.140181261+00:00,160,1,432669,A,A,64.84,1,26,8058566322055,128,15281,94246457,CLX5
2025-09-24 19:31:47.140181437+00:00,160,1,432669,A,A,64.84,1,26,8058566322056,128,16257,94246458,CLX5
2025-09-24 19:31:47.140418217+00:00,160,1,432669,A,A,64.83,1,26,8058566322062,128,18517,94246472,CLX5
2025-09-24 19:31:47.140792619+00:00,160,1,432669,C,B,64.81,1,26,8058566320842,128,15189,94246502,CLX5
2025-09-24 19:31:47.141822309+00:00,160,1,432669,A,A,64.83,3,26,8058566322092,128,14925,94246570,CLX5
2025-09-24 19:31:47.142894583+00:00,160,1,432669,A,A,64.83,1,26,8058566322115,128,17156,94246663,CLX5
2025-09-24 19:31:47.142897807+00:00,160,1,432669,A,A,64.83,1,26,8058566322118,128,18956,94246664,CLX5
2025-09-24 19:31:47.143179765+00:00,160,1,432669,A,A,64.83,2,26,8058566322124,128,16426,94246681,CLX5
2025-09-24 19:31:47.143441777+00:00,160,1,432669,A,B,64.82,2,26,8058566322126,128,19246,94246691,CLX5
2025-09-24 19:31:47.143541811+00:00,160,1,432669,A,B,64.82,1,26,8058566322127,128,15292,94246696,CLX5
2025-09-24 19:31:47.143638377+00:00,160,1,432669,M,A,64.84,1,26,8058566322062,128,16922,94246697,CLX5
2025-09-24 19:31:47.143871473+00:00,160,1,432669,A,B,64.82,1,26,8058566322132,128,15250,94246713,CLX5
2025-09-24 19:31:47.144261253+00:00,160,1,432669,C,B,64.82,1,26,8058566321888,128,15188,94246757,CLX5
2025-09-24 19:31:47.144449559+00:00,160,1,432669,A,A,64.83,1,26,8058566322139,128,19933,94246762,CLX5
2025-09-24 19:31:47.145129651+00:00,160,1,432669,A,B,64.82,1,26,8058566322143,128,18551,94246795,CLX5
2025-09-24 19:31:47.146470115+00:00,160,1,432669,C,B,64.82,2,26,8058566321912,128,18191,94246856,CLX5
2025-09-24 19:31:47.146472343+00:00,160,1,432669,A,A,64.83,3,26,8058566322156,128,16266,94246858,CLX5
2025-09-24 19:31:47.146487241+00:00,160,1,432669,C,B,64.82,2,26,8058566322126,128,18663,94246860,CLX5
2025-09-24 19:31:47.146495421+00:00,160,1,432669,A,A,64.83,1,26,8058566322158,128,15263,94246861,CLX5
2025-09-24 19:31:47.146633961+00:00,160,1,432669,M,A,64.83,1,26,8058566322062,128,19075,94246865,CLX5
2025-09-24 19:31:47.147337133+00:00,160,1,432669,A,B,64.82,2,26,8058566322165,128,16246,94246919,CLX5
2025-09-24 19:31:47.148270019+00:00,160,1,432669,C,B,64.82,2,26,8058566322165,128,14265,94246961,CLX5
2025-09-24 19:31:47.148285415+00:00,160,1,432669,C,B,64.82,1,26,8058566322143,128,19418,94246963,CLX5
2025-09-24 19:31:47.148298989+00:00,160,1,432669,C,B,64.82,1,26,8058566322132,128,15162,94246964,CLX5
2025-09-24 19:31:47.148301619+00:00,160,1,432669,C,B,64.82,1,26,8058566322127,128,15269,94246965,CLX5
2025-09-24 19:31:47.154627491+00:00,160,1,432669,C,A,64.83,1,26,8058566322158,128,19300,94247156,CLX5
2025-09-24 19:31:47.163982893+00:00,160,1,432669,A,A,64.83,1,26,8058566322274,128,18880,94247315,CLX5
2025-09-24 19:31:47.164026263+00:00,160,1,432669,A,A,64.83,1,26,8058566322275,128,15502,94247316,CLX5
2025-09-24 19:31:47.164153957+00:00,160,1,432669,C,A,64.84,1,26,8058566321976,128,15392,94247324,CLX5
2025-09-24 19:31:47.164173463+00:00,160,1,432669,C,B,64.82,1,26,8058566321802,128,15403,94247326,CLX5
2025-09-24 19:31:47.164301063+00:00,160,1,432669,C,A,64.83,1,26,8058566322275,128,18650,94247327,CLX5
2025-09-24 19:31:47.164372119+00:00,160,1,432669,C,A,64.83,1,26,8058566322274,128,15765,94247328,CLX5
2025-09-24 19:31:47.164851193+00:00,160,1,432669,C,B,64.81,2,26,8058566321863,128,18397,94247335,CLX5
2025-09-24 19:31:47.164852077+00:00,160,1,432669,C,B,64.77,2,26,8058566321294,128,15410,94247337,CLX5
2025-09-24 19:31:47.164862291+00:00,160,1,432669,A,A,64.83,1,26,8058566322282,128,15503,94247342,CLX5
2025-09-24 19:31:47.164902419+00:00,160,1,432669,A,A,64.83,2,26,8058566322283,128,16029,94247346,CLX5
2025-09-24 19:31:47.165063151+00:00,160,1,432669,A,A,64.86,1,26,8058566322286,128,14906,94247358,CLX5
2025-09-24 19:31:47.165128161+00:00,160,1,432669,A,A,64.83,1,26,8058566322287,128,18883,94247361,CLX5
2025-09-24 19:31:47.165337875+00:00,160,1,432669,C,A,64.83,1,26,8058566322282,128,14007,94247369,CLX5
2025-09-24 19:31:47.165494767+00:00,160,1,432669,C,A,64.83,2,26,8058566322283,128,14344,94247375,CLX5
2025-09-24 19:31:47.165545069+00:00,160,1,432669,A,A,64.83,1,26,8058566322289,128,15407,94247377,CLX5
2025-09-24 19:31:47.165680963+00:00,160,1,432669,C,A,64.83,1,26,8058566322289,128,15400,94247383,CLX5
2025-09-24 19:31:47.223269667+00:00,160,1,432669,M,A,64.94,1,26,8058565075241,128,15345,94247567,CLX5
2025-09-24 19:31:47.223856009+00:00,160,1,432669,A,A,64.83,2,26,8058566322384,128,18747,94247579,CLX5
2025-09-24 19:31:47.223999407+00:00,160,1,432669,A,A,64.83,1,26,8058566322385,128,15370,94247585,CLX5
2025-09-24 19:31:47.224046005+00:00,160,1,432669,M,A,64.95,1,26,8058565075241,128,14677,94247587,CLX5
2025-09-24 19:31:47.224130039+00:00,160,1,432669,C,A,64.83,1,26,8058566322385,128,18366,94247588,CLX5
2025-09-24 19:31:47.224785671+00:00,160,1,432669,A,B,64.81,2,26,8058566322388,128,18525,94247595,CLX5
2025-09-24 19:31:47.225998385+00:00,160,1,432669,C,A,64.83,2,26,8058566322384,128,18452,94247613,CLX5
2025-09-24 19:31:47.227428185+00:00,160,1,432669,C,B,64.81,2,26,8058566322388,128,18342,94247618,CLX5
2025-09-24 19:31:47.227435577+00:00,160,1,432669,A,A,64.83,1,26,8058566322394,128,15301,94247620,CLX5
2025-09-24 19:31:47.227484113+00:00,160,1,432669,A,A,64.83,2,26,8058566322395,128,17283,94247622,CLX5
2025-09-24 19:31:47.227675853+00:00,160,1,432669,C,A,64.83,1,26,8058566322394,128,18571,94247623,CLX5
2025-09-24 19:31:47.230883401+00:00,160,1,432669,A,A,64.83,1,26,8058566322403,128,19227,94247638,CLX5
2025-09-24 19:31:47.321369643+00:00,160,1,432669,C,B,64.8,1,26,8058566321995,128,19005,94247788,CLX5
2025-09-24 19:31:47.509613311+00:00,160,1,432669,A,B,64.78,2,26,8058566322627,128,18463,94247974,CLX5
2025-09-24 19:31:48.088532141+00:00,160,1,432669,A,B,64.81,2,26,8058566322745,128,19423,94248172,CLX5
2025-09-24 19:31:48.088536883+00:00,160,1,432669,C,A,64.83,1,26,8058566322287,128,15252,94248174,CLX5
2025-09-24 19:31:48.088538881+00:00,160,1,432669,C,B,64.78,2,26,8058566322627,128,17257,94248176,CLX5
2025-09-24 19:31:48.088548155+00:00,160,1,432669,C,A,64.83,1,26,8058566322403,128,15786,94248177,CLX5
2025-09-24 19:31:48.088565435+00:00,160,1,432669,C,A,64.83,2,26,8058566322395,128,15328,94248178,CLX5
2025-09-24 19:31:48.088773319+00:00,160,1,432669,C,B,64.81,2,26,8058566322745,128,15189,94248191,CLX5
2025-09-24 19:31:48.088783419+00:00,160,1,432669,A,A,64.83,1,26,8058566322751,128,15710,94248194,CLX5
2025-09-24 19:31:48.088823949+00:00,160,1,432669,C,A,64.83,1,26,8058566322139,128,15584,94248195,CLX5
2025-09-24 19:31:48.088825199+00:00,160,1,432669,C,A,64.83,1,26,8058566322751,128,16049,94248196,CLX5
2025-09-24 19:31:48.088949089+00:00,160,1,432669,A,A,64.83,2,26,8058566322755,128,15493,94248207,CLX5
2025-09-24 19:31:48.089122265+00:00,160,1,432669,A,A,64.83,1,26,8058566322756,128,16984,94248214,CLX5
2025-09-24 19:31:48.089122977+00:00,160,1,432669,A,A,64.83,1,26,8058566322757,128,15506,94248216,CLX5
2025-09-24 19:31:48.089287303+00:00,160,1,432669,A,A,64.83,1,26,8058566322758,128,19931,94248217,CLX5
2025-09-24 19:31:48.209591789+00:00,160,1,432669,A,B,64.78,2,26,8058566322764,128,18263,94248250,CLX5
2025-09-24 19:31:50.549106865+00:00,160,1,432669,A,B,64.81,2,26,8058566322824,128,20182,94248368,CLX5
2025-09-24 19:31:50.549113297+00:00,160,1,432669,C,A,64.83,1,26,8058566322757,128,15198,94248371,CLX5
2025-09-24 19:31:50.549116773+00:00,160,1,432669,C,B,64.78,2,26,8058566322764,128,14930,94248375,CLX5
2025-09-24 19:31:50.549152349+00:00,160,1,432669,C,A,64.83,2,26,8058566322755,128,15637,94248378,CLX5
2025-09-24 19:31:50.549155899+00:00,160,1,432669,C,A,64.83,1,26,8058566322756,128,15681,94248379,CLX5
2025-09-24 19:31:50.601248617+00:00,160,1,432669,C,A,64.86,1,26,8058566322286,128,14956,94248433,CLX5
2025-09-24 19:31:50.602287847+00:00,160,1,432669,C,A,64.83,1,26,8058566322758,128,16837,94248458,CLX5
2025-09-24 19:31:50.609607909+00:00,160,1,432669,C,B,64.79,2,26,8058566321279,128,18107,94248484,CLX5
2025-09-24 19:31:52.031546779+00:00,160,1,432669,A,A,64.83,2,26,8058566322947,128,18734,94248675,CLX5
2025-09-24 19:31:52.031611711+00:00,160,1,432669,C,B,64.79,1,26,8058566321584,128,16024,94248685,CLX5
2025-09-24 19:31:52.031612009+00:00,160,1,432669,C,B,64.78,1,26,8058566320930,128,14965,94248687,CLX5
2025-09-24 19:31:52.031640683+00:00,160,1,432669,A,A,64.83,1,26,8058566322958,128,15355,94248694,CLX5
2025-09-24 19:31:52.031710049+00:00,160,1,432669,A,A,64.83,1,26,8058566322962,128,15316,94248701,CLX5
2025-09-24 19:31:52.031789373+00:00,160,1,432669,A,A,64.83,1,26,8058566322966,128,16132,94248707,CLX5
2025-09-24 19:31:52.031790667+00:00,160,1,432669,A,A,64.83,2,26,8058566322971,128,18844,94248713,CLX5
2025-09-24 19:31:52.031791741+00:00,160,1,432669,C,B,64.81,2,26,8058566322824,128,15262,94248715,CLX5
2025-09-24 19:31:52.031793941+00:00,160,1,432669,C,B,64.8,2,26,8058566321278,128,14787,94248729,CLX5
2025-09-24 19:31:52.031795431+00:00,160,1,432669,C,B,64.82,3,26,8058566321697,128,16325,94248739,CLX5
2025-09-24 19:31:52.031802483+00:00,160,1,432669,A,A,64.83,2,26,8058566322975,128,15744,94248787,CLX5
2025-09-24 19:31:52.031808367+00:00,160,1,432669,C,B,64.82,1,26,8058566321698,128,14637,94248795,CLX5
2025-09-24 19:31:52.031837263+00:00,160,1,432669,C,B,64.82,2,26,8058566321577,128,16337,94248799,CLX5
2025-09-24 19:31:52.031837415+00:00,160,1,432669,C,B,64.82,1,26,8058566321578,128,16227,94248800,CLX5
2025-09-24 19:31:52.031837587+00:00,160,1,432669,A,A,64.83,2,26,8058566322979,128,19221,94248801,CLX5
2025-09-24 19:31:52.031837779+00:00,160,1,432669,A,A,64.83,1,26,8058566322980,128,15529,94248802,CLX5
2025-09-24 19:31:52.031839585+00:00,160,1,432669,A,A,64.83,1,26,8058566322981,128,15525,94248804,CLX5
2025-09-24 19:31:52.031842331+00:00,160,1,432669,A,A,64.83,1,26,8058566322982,128,18291,94248806,CLX5
2025-09-24 19:31:52.031896529+00:00,160,1,432669,A,A,64.83,1,26,8058566322983,128,15678,94248817,CLX5
2025-09-24 19:31:52.032056325+00:00,160,1,432669,C,A,64.83,1,26,8058566322958,128,15410,94248823,CLX5
2025-09-24 19:31:52.032229923+00:00,160,1,432669,C,B,64.82,1,26,8058566321704,128,16587,94248838,CLX5
2025-09-24 19:31:52.032280571+00:00,160,1,432669,C,B,64.82,2,26,8058566321575,128,17468,94248845,CLX5
2025-09-24 19:31:52.032309407+00:00,160,1,432669,C,B,64.82,1,26,8058566321699,128,17049,94248857,CLX5
2025-09-24 19:31:52.033069119+00:00,160,1,432669,C,A,64.83,2,26,8058566322975,128,16089,94248914,CLX5
2025-09-24 19:31:52.033106057+00:00,160,1,432669,A,A,64.86,1,26,8058566322999,128,14798,94248916,CLX5
2025-09-24 19:31:52.033225015+00:00,160,1,432669,A,B,64.82,1,26,8058566323002,128,17853,94248925,CLX5
2025-09-24 19:31:52.033543511+00:00,160,1,432669,C,A,64.83,1,26,8058566322962,128,15096,94248941,CLX5
2025-09-24 19:31:52.033572769+00:00,160,1,432669,C,A,64.83,2,26,8058566322979,128,15169,94248945,CLX5
2025-09-24 19:31:52.033999413+00:00,160,1,432669,A,A,64.86,2,26,8058566323015,128,15725,94248965,CLX5
2025-09-24 19:31:52.034117487+00:00,160,1,432669,C,B,64.82,1,26,8058566321871,128,15780,94248974,CLX5
2025-09-24 19:31:52.034134171+00:00,160,1,432669,M,A,64.94,1,26,8058565075241,128,16239,94248975,CLX5
2025-09-24 19:31:52.034301127+00:00,160,1,432669,A,B,64.82,1,26,8058566323022,128,16092,94248983,CLX5
2025-09-24 19:31:52.034303315+00:00,160,1,432669,A,B,64.82,2,26,8058566323023,128,15791,94248985,CLX5
2025-09-24 19:31:52.034305811+00:00,160,1,432669,C,A,64.83,1,26,8058566322981,128,18941,94248986,CLX5
2025-09-24 19:31:52.034305967+00:00,160,1,432669,A,B,64.82,2,26,8058566323024,128,16905,94248987,CLX5
2025-09-24 19:31:52.034307175+00:00,160,1,432669,C,A,64.83,1,26,8058566322983,128,14585,94248988,CLX5
2025-09-24 19:31:52.034309095+00:00,160,1,432669,C,A,64.83,1,26,8058566322982,128,18737,94248989,CLX5
2025-09-24 19:31:52.034310419+00:00,160,1,432669,C,A,64.83,1,26,8058566322980,128,15865,94248990,CLX5
2025-09-24 19:31:52.034316409+00:00,160,1,432669,A,B,64.82,1,26,8058566323025,128,14772,94248991,CLX5
2025-09-24 19:31:52.034318771+00:00,160,1,432669,A,A,64.83,1,26,8058566323026,128,15406,94248992,CLX5
2025-09-24 19:31:52.035010997+00:00,160,1,432669,A,B,64.82,2,26,8058566323034,128,14578,94249013,CLX5
2025-09-24 19:31:52.035011189+00:00,160,1,432669,A,B,64.82,1,26,8058566323035,128,15205,94249014,CLX5
2025-09-24 19:31:52.035056307+00:00,160,1,432669,C,A,64.86,2,26,8058566323015,128,15036,94249015,CLX5
2025-09-24 19:31:52.035202989+00:00,160,1,432669,T,A,64.82,1,26,8058566323036,0,14702,94249027,CLX5
2025-09-24 19:31:52.035202989+00:00,160,1,432669,F,B,64.82,1,26,8058566321696,0,14702,94249027,CLX5
2025-09-24 19:31:52.035202989+00:00,160,1,432669,C,B,64.82,1,26,8058566321696,128,15789,94249028,CLX5
2025-09-24 19:31:52.035353683+00:00,160,1,432669,A,A,64.83,1,26,8058566323037,128,15495,94249034,CLX5
2025-09-24 19:31:52.035380023+00:00,160,1,432669,M,B,64.8,1,26,8058566311303,128,18439,94249036,CLX5
2025-09-24 19:31:52.035435183+00:00,160,1,432669,C,A,64.83,1,26,8058566323037,128,16103,94249037,CLX5
2025-09-24 19:31:52.035701053+00:00,160,1,432669,A,A,64.83,1,26,8058566323040,128,15486,94249046,CLX5
2025-09-24 19:31:52.035702705+00:00,160,1,432669,M,A,64.95,1,26,8058565075241,128,14557,94249047,CLX5
2025-09-24 19:31:52.035704433+00:00,160,1,432669,A,A,64.83,1,26,8058566323041,128,18329,94249048,CLX5
2025-09-24 19:31:52.035776371+00:00,160,1,432669,A,A,64.83,1,26,8058566323044,128,18014,94249053,CLX5
2025-09-24 19:31:52.036440431+00:00,160,1,432669,M,B,64.81,1,26,8058566311303,128,14875,94249087,CLX5
2025-09-24 19:31:52.036592337+00:00,160,1,432669,C,A,64.83,1,26,8058566323044,128,18474,94249092,CLX5
2025-09-24 19:31:52.036666195+00:00,160,1,432669,C,A,64.83,1,26,8058566323041,128,15125,94249095,CLX5
2025-09-24 19:31:52.036793869+00:00,160,1,432669,M,A,64.84,1,26,8058566173085,128,15730,94249096,CLX5
2025-09-24 19:31:52.036953241+00:00,160,1,432669,A,A,64.83,1,26,8058566323054,128,18361,94249097,CLX5
2025-09-24 19:31:52.037723417+00:00,160,1,432669,C,A,64.83,1,26,8058566323040,128,14733,94249115,CLX5
2025-09-24 19:31:52.037724145+00:00,160,1,432669,C,A,64.83,1,26,8058566323054,128,15495,94249116,CLX5
2025-09-24 19:31:52.037976133+00:00,160,1,432669,A,B,64.82,1,26,8058566323061,128,15335,94249121,CLX5
2025-09-24 19:31:52.038030775+00:00,160,1,432669,A,A,64.83,1,26,8058566323063,128,17490,94249127,CLX5
2025-09-24 19:31:52.038080673+00:00,160,1,432669,A,A,64.83,1,26,8058566323065,128,15486,94249130,CLX5
2025-09-24 19:31:52.038083821+00:00,160,1,432669,A,A,64.83,1,26,8058566323066,128,18769,94249132,CLX5
2025-09-24 19:31:52.038112677+00:00,160,1,432669,C,B,64.82,1,26,8058566323025,128,15571,94249134,CLX5
2025-09-24 19:31:52.038151287+00:00,160,1,432669,M,A,64.94,1,26,8058565075241,128,14546,94249135,CLX5
2025-09-24 19:31:52.038184251+00:00,160,1,432669,C,A,64.83,1,26,8058566323026,128,18626,94249137,CLX5
2025-09-24 19:31:52.039401363+00:00,160,1,432669,C,A,64.83,1,26,8058566323065,128,15037,94249161,CLX5
2025-09-24 19:31:52.040080803+00:00,160,1,432669,A,A,64.83,1,26,8058566323079,128,17654,94249176,CLX5
2025-09-24 19:31:52.040740043+00:00,160,1,432669,C,A,64.83,1,26,8058566323066,128,19087,94249186,CLX5
2025-09-24 19:31:52.040740217+00:00,160,1,432669,C,A,64.83,1,26,8058566323063,128,15412,94249187,CLX5
2025-09-24 19:31:52.040804957+00:00,160,1,432669,C,A,64.83,1,26,8058566323079,128,18721,94249189,CLX5
2025-09-24 19:31:52.040923741+00:00,160,1,432669,A,A,64.83,1,26,8058566323088,128,17136,94249193,CLX5
2025-09-24 19:31:52.041038265+00:00,160,1,432669,C,A,64.83,1,26,8058566323088,128,15322,94249195,CLX5
2025-09-24 19:31:52.041038411+00:00,160,1,432669,A,A,64.83,1,26,8058566323089,128,15387,94249196,CLX5
2025-09-24 19:31:52.041168971+00:00,160,1,432669,A,A,64.83,1,26,8058566323091,128,15708,94249202,CLX5
2025-09-24 19:31:52.041272129+00:00,160,1,432669,C,A,64.83,1,26,8058566323091,128,15257,94249205,CLX5
2025-09-24 19:31:52.041272859+00:00,160,1,432669,C,A,64.83,1,26,8058566323089,128,18584,94249206,CLX5
2025-09-24 19:31:52.041494513+00:00,160,1,432669,A,A,64.83,1,26,8058566323092,128,15633,94249207,CLX5
2025-09-24 19:31:52.041497833+00:00,160,1,432669,A,A,64.83,1,26,8058566323093,128,15380,94249208,CLX5
2025-09-24 19:31:52.041512617+00:00,160,1,432669,C,A,64.83,1,26,8058566323093,128,15838,94249214,CLX5
2025-09-24 19:31:52.041809187+00:00,160,1,432669,C,A,64.83,1,26,8058566323092,128,14801,94249252,CLX5
2025-09-24 19:31:52.041812123+00:00,160,1,432669,A,A,64.83,1,26,8058566323104,128,15381,94249253,CLX5
2025-09-24 19:31:52.042028941+00:00,160,1,432669,A,A,64.83,1,26,8058566323108,128,15371,94249262,CLX5
2025-09-24 19:31:52.042032511+00:00,160,1,432669,C,A,64.83,1,26,8058566323104,128,15413,94249264,CLX5
2025-09-24 19:31:52.042066301+00:00,160,1,432669,C,A,64.83,2,26,8058566322971,128,14284,94249267,CLX5
2025-09-24 19:31:52.042108311+00:00,160,1,432669,A,A,64.83,1,26,8058566323112,128,15559,94249270,CLX5
2025-09-24 19:31:52.042115529+00:00,160,1,432669,C,A,64.83,1,26,8058566322966,128,15345,94249271,CLX5
2025-09-24 19:31:52.042247063+00:00,160,1,432669,A,A,64.83,1,26,8058566323113,128,15430,94249272,CLX5
2025-09-24 19:31:52.042726811+00:00,160,1,432669,A,B,64.78,1,26,8058566323114,128,14957,94249277,CLX5
2025-09-24 19:31:52.043185747+00:00,160,1,432669,A,B,64.82,1,26,8058566323117,128,18584,94249283,CLX5
2025-09-24 19:31:52.043316761+00:00,160,1,432669,M,A,64.95,1,26,8058565075241,128,15089,94249299,CLX5
2025-09-24 19:31:52.043432285+00:00,160,1,432669,A,B,64.79,1,26,8058566323125,128,15263,94249305,CLX5
2025-09-24 19:31:52.044153385+00:00,160,1,432669,A,B,64.82,1,26,8058566323139,128,15337,94249339,CLX5
2025-09-24 19:31:52.044306939+00:00,160,1,432669,C,A,64.83,1,26,8058566323112,128,18974,94249345,CLX5
2025-09-24 19:31:52.044746561+00:00,160,1,432669,A,A,64.83,1,26,8058566323149,128,15184,94249367,CLX5
2025-09-24 19:31:52.045421815+00:00,160,1,432669,A,A,64.83,1,26,8058566323152,128,15471,94249378,CLX5
2025-09-24 19:31:52.045971621+00:00,160,1,432669,A,B,64.82,1,26,8058566323157,128,15286,94249391,CLX5
2025-09-24 19:31:52.047638569+00:00,160,1,432669,C,A,64.83,1,26,8058566323113,128,18675,94249515,CLX5
2025-09-24 19:31:52.047639509+00:00,160,1,432669,C,A,64.83,1,26,8058566323149,128,14639,94249516,CLX5
2025-09-24 19:31:52.048614827+00:00,160,1,432669,A,A,64.83,1,26,8058566323192,128,15158,94249588,CLX5
2025-09-24 19:31:52.048615001+00:00,160,1,432669,A,A,64.83,1,26,8058566323193,128,18497,94249590,CLX5
2025-09-24 19:31:52.050153255+00:00,160,1,432669,C,A,64.83,1,26,8058566323192,128,17596,94249655,CLX5
2025-09-24 19:31:52.050153829+00:00,160,1,432669,C,A,64.83,1,26,8058566323193,128,15722,94249656,CLX5
2025-09-24 19:31:52.050338775+00:00,160,1,432669,A,A,64.83,1,26,8058566323213,128,18166,94249660,CLX5
2025-09-24 19:31:52.065884925+00:00,160,1,432669,C,A,64.83,1,26,8058566323152,128,20457,94249685,CLX5
2025-09-24 19:31:52.066014001+00:00,160,1,432669,C,A,64.83,1,26,8058566323213,128,18370,94249686,CLX5
2025-09-24 19:31:52.088726331+00:00,160,1,432669,A,B,64.8,2,26,8058566323254,128,18285,94249763,CLX5
2025-09-24 19:31:52.088729075+00:00,160,1,432669,A,B,64.79,2,26,8058566323256,128,15077,94249765,CLX5
2025-09-24 19:31:52.101703709+00:00,160,1,432669,C,A,64.83,2,26,8058566322947,128,15451,94249798,CLX5
2025-09-24 19:31:52.209665849+00:00,160,1,432669,A,B,64.78,2,26,8058566323353,128,18698,94249954,CLX5
2025-09-24 19:31:52.341396885+00:00,160,1,432669,C,A,64.86,1,26,8058566322999,128,18512,94250105,CLX5
2025-09-24 19:31:54.162219287+00:00,160,1,432669,M,A,64.97,1,26,8058566157942,128,20035,94250305,CLX5
2025-09-24 19:31:54.464671017+00:00,160,1,432669,A,A,64.83,2,26,8058566323542,128,16152,94250318,CLX5
2025-09-24 19:31:54.464934009+00:00,160,1,432669,C,B,64.82,2,26,8058566323024,128,15788,94250321,CLX5
2025-09-24 19:31:55.016603251+00:00,160,1,432669,C,B,64.82,2,26,8058566323023,128,15751,94250339,CLX5
2025-09-24 19:31:55.016733153+00:00,160,1,432669,A,A,64.83,1,26,8058566323554,128,15256,94250349,CLX5
2025-09-24 19:31:55.016830011+00:00,160,1,432669,A,A,64.83,1,26,8058566323555,128,15238,94250354,CLX5
2025-09-24 19:31:55.017181453+00:00,160,1,432669,C,B,64.82,1,26,8058566323139,128,15774,94250361,CLX5
2025-09-24 19:31:55.017250973+00:00,160,1,432669,C,B,64.82,1,26,8058566323157,128,19880,94250366,CLX5
2025-09-24 19:31:55.017267943+00:00,160,1,432669,A,A,64.86,1,26,8058566323560,128,19132,94250369,CLX5
2025-09-24 19:31:55.017280463+00:00,160,1,432669,C,B,64.82,1,26,8058566323117,128,16229,94250376,CLX5
2025-09-24 19:31:55.017492249+00:00,160,1,432669,C,A,64.83,1,26,8058566323554,128,14921,94250391,CLX5
2025-09-24 19:31:55.017755737+00:00,160,1,432669,A,A,64.83,1,26,8058566323573,128,15056,94250412,CLX5
2025-09-24 19:31:55.017776165+00:00,160,1,432669,C,B,64.82,1,26,8058566323022,128,16209,94250415,CLX5
2025-09-24 19:31:55.017912017+00:00,160,1,432669,A,A,64.83,1,26,8058566323583,128,15699,94250443,CLX5
2025-09-24 19:31:55.018020783+00:00,160,1,432669,A,A,64.86,2,26,8058566323588,128,14822,94250453,CLX5
2025-09-24 19:31:55.018164525+00:00,160,1,432669,M,A,64.94,1,26,8058565075241,128,14920,94250465,CLX5
2025-09-24 19:31:55.018916807+00:00,160,1,432669,C,A,64.83,1,26,8058566323573,128,15333,94250493,CLX5
2025-09-24 19:31:55.018919303+00:00,160,1,432669,C,A,64.83,1,26,8058566323555,128,15346,94250494,CLX5
2025-09-24 19:31:55.019774875+00:00,160,1,432669,A,B,64.82,1,26,8058566323603,128,17077,94250517,CLX5
2025-09-24 19:31:55.019780615+00:00,160,1,432669,A,A,64.83,1,26,8058566323604,128,19256,94250519,CLX5
2025-09-24 19:31:55.019851115+00:00,160,1,432669,C,A,64.83,1,26,8058566323604,128,18916,94250523,CLX5
2025-09-24 19:31:55.020448841+00:00,160,1,432669,A,B,64.82,2,26,8058566323611,128,16593,94250541,CLX5
2025-09-24 19:31:55.020546141+00:00,160,1,432669,A,B,64.82,1,26,8058566323615,128,19032,94250548,CLX5
2025-09-24 19:31:55.020589571+00:00,160,1,432669,A,A,64.83,1,26,8058566323616,128,15718,94250549,CLX5
2025-09-24 19:31:55.020994041+00:00,160,1,432669,C,A,64.83,1,26,8058566323616,128,18995,94250576,CLX5
2025-09-24 19:31:55.029162185+00:00,160,1,432669,A,A,64.83,1,26,8058566323638,128,18705,94250643,CLX5
2025-09-24 19:31:55.092085835+00:00,160,1,432669,C,B,64.82,2,26,8058566323611,128,19419,94250681,CLX5
2025-09-24 19:31:55.092086163+00:00,160,1,432669,C,B,64.82,1,26,8058566323615,128,16399,94250682,CLX5
2025-09-24 19:31:55.092087295+00:00,160,1,432669,A,A,64.83,1,26,8058566323651,128,15209,94250683,CLX5
2025-09-24 19:31:55.092227025+00:00,160,1,432669,C,A,64.83,1,26,8058566323651,128,15586,94250688,CLX5
2025-09-24 19:31:55.092289711+00:00,160,1,432669,C,A,64.83,1,26,8058566323638,128,15463,94250689,CLX5
2025-09-24 19:31:55.092490343+00:00,160,1,432669,A,A,64.83,1,26,8058566323653,128,15876,94250692,CLX5
2025-09-24 19:31:55.092519581+00:00,160,1,432669,C,A,64.83,1,26,8058566323653,128,15413,94250693,CLX5
2025-09-24 19:31:55.092651135+00:00,160,1,432669,A,A,64.83,1,26,8058566323654,128,18782,94250694,CLX5
2025-09-24 19:31:55.109668325+00:00,160,1,432669,C,A,64.88,2,26,8058566321732,128,19166,94250705,CLX5
2025-09-24 19:31:55.242628451+00:00,160,1,432669,C,A,64.83,1,26,8058566323654,128,18023,94250788,CLX5
2025-09-24 19:31:55.242762749+00:00,160,1,432669,A,A,64.83,1,26,8058566323698,128,18783,94250790,CLX5
2025-09-24 19:31:55.242898141+00:00,160,1,432669,A,A,64.83,1,26,8058566323701,128,13922,94250796,CLX5
2025-09-24 19:31:55.299996001+00:00,160,1,432669,C,A,64.83,1,26,8058566323698,128,18854,94250828,CLX5
2025-09-24 19:31:55.299996405+00:00,160,1,432669,C,A,64.83,1,26,8058566323701,128,15264,94250829,CLX5
2025-09-24 19:31:55.300162131+00:00,160,1,432669,A,B,64.82,2,26,8058566323716,128,19980,94250831,CLX5
2025-09-24 19:31:55.300258953+00:00,160,1,432669,A,B,64.82,1,26,8058566323717,128,15159,94250832,CLX5
2025-09-24 19:31:55.304858763+00:00,160,1,432669,M,B,64.82,1,26,8058566321508,128,20089,94250836,CLX5
2025-09-24 19:31:55.305012453+00:00,160,1,432669,A,A,64.83,1,26,8058566323720,128,18827,94250837,CLX5
2025-09-24 19:31:55.305141107+00:00,160,1,432669,C,A,64.83,1,26,8058566323720,128,18973,94250838,CLX5
2025-09-24 19:31:55.367580997+00:00,160,1,432669,C,A,64.83,1,26,8058566323583,128,15288,94250851,CLX5
2025-09-24 19:31:55.371205719+00:00,160,1,432669,A,B,64.82,1,26,8058566323724,128,19033,94250852,CLX5
2025-09-24 19:31:55.456963057+00:00,160,1,432669,A,B,64.82,1,26,8058566323755,128,19641,94250928,CLX5
2025-09-24 19:31:55.456964689+00:00,160,1,432669,C,A,64.86,2,26,8058566323588,128,15044,94250935,CLX5
2025-09-24 19:31:55.457090347+00:00,160,1,432669,M,A,64.95,1,26,8058565075241,128,14845,94250942,CLX5
2025-09-24 19:31:55.457116515+00:00,160,1,432669,A,B,64.82,1,26,8058566323760,128,14845,94250942,CLX5
2025-09-24 19:31:55.457386475+00:00,160,1,432669,A,A,64.83,1,26,8058566323762,128,15428,94250951,CLX5
2025-09-24 19:31:55.457405693+00:00,160,1,432669,A,B,64.82,1,26,8058566323763,128,15152,94250952,CLX5
2025-09-24 19:31:55.460033635+00:00,160,1,432669,A,B,64.81,1,26,8058566323766,128,18242,94250973,CLX5
2025-09-24 19:31:55.509641791+00:00,160,1,432669,A,A,64.88,2,26,8058566323777,128,18476,94250989,CLX5
2025-09-24 19:31:55.563684337+00:00,160,1,432669,C,B,64.82,1,26,8058566323755,128,19175,94250998,CLX5
2025-09-24 19:31:59.446964141+00:00,160,1,432669,C,B,64.29,1,26,8058566137346,128,18340,94251791,CLX5
2025-09-24 19:32:00.408110559+00:00,160,1,432669,A,B,64.81,2,26,8058566324253,128,18679,94252132,CLX5
2025-09-24 19:32:00.408123153+00:00,160,1,432669,C,B,64.78,2,26,8058566323353,128,14849,94252136,CLX5
2025-09-24 19:32:00.408157981+00:00,160,1,432669,C,A,64.83,1,26,8058566323762,128,14796,94252142,CLX5
2025-09-24 19:32:00.408176717+00:00,160,1,432669,C,A,64.83,2,26,8058566323542,128,15433,94252143,CLX5
2025-09-24 19:32:00.408332845+00:00,160,1,432669,A,A,64.83,2,26,8058566324260,128,16238,94252148,CLX5
2025-09-24 19:32:00.408446811+00:00,160,1,432669,C,A,64.83,1,26,8058566323108,128,15449,94252151,CLX5
2025-09-24 19:32:00.408494233+00:00,160,1,432669,C,B,64.81,2,26,8058566324253,128,18554,94252157,CLX5
2025-09-24 19:32:00.408665355+00:00,160,1,432669,C,A,64.83,2,26,8058566324260,128,19601,94252165,CLX5
2025-09-24 19:32:00.408666413+00:00,160,1,432669,A,A,64.83,2,26,8058566324263,128,15056,94252166,CLX5
2025-09-24 19:32:00.408921973+00:00,160,1,432669,T,B,64.83,12,26,8058566324264,0,15636,94252176,CLX5
2025-09-24 19:32:00.408921973+00:00,160,1,432669,F,A,64.83,3,26,8058566322092,0,15636,94252176,CLX5
2025-09-24 19:32:00.408921973+00:00,160,1,432669,F,A,64.83,1,26,8058566322115,0,15636,94252176,CLX5
2025-09-24 19:32:00.408921973+00:00,160,1,432669,F,A,64.83,2,26,8058566322124,0,15636,94252176,CLX5
2025-09-24 19:32:00.408921973+00:00,160,1,432669,F,A,64.83,3,26,8058566322156,0,15636,94252176,CLX5
2025-09-24 19:32:00.408921973+00:00,160,1,432669,F,A,64.83,1,26,8058566322062,0,15636,94252176,CLX5
2025-09-24 19:32:00.408921973+00:00,160,1,432669,F,A,64.83,2,26,8058566324263,0,15636,94252176,CLX5
2025-09-24 19:32:00.408921973+00:00,160,1,432669,C,A,64.83,3,26,8058566322092,0,15458,94252177,CLX5
2025-09-24 19:32:00.408921973+00:00,160,1,432669,C,A,64.83,1,26,8058566322115,0,15458,94252177,CLX5
2025-09-24 19:32:00.408921973+00:00,160,1,432669,C,A,64.83,2,26,8058566322124,0,15458,94252177,CLX5
2025-09-24 19:32:00.408921973+00:00,160,1,432669,C,A,64.83,3,26,8058566322156,0,15458,94252177,CLX5
2025-09-24 19:32:00.408921973+00:00,160,1,432669,C,A,64.83,1,26,8058566322062,0,15458,94252177,CLX5
2025-09-24 19:32:00.408921973+00:00,160,1,432669,C,A,64.83,2,26,8058566324263,0,15458,94252177,CLX5
2025-09-24 19:32:00.408921973+00:00,160,1,432669,C,A,64.83,1,26,8058566322118,128,15458,94252177,CLX5
2025-09-24 19:32:00.408933799+00:00,160,1,432669,A,B,64.83,2,26,8058566324265,128,17494,94252181,CLX5
2025-09-24 19:32:00.409268971+00:00,160,1,432669,A,B,64.82,2,26,8058566324266,128,14693,94252192,CLX5
2025-09-24 19:32:00.409341703+00:00,160,1,432669,A,B,64.82,2,26,8058566324267,128,14291,94252194,CLX5
2025-09-24 19:32:00.409345735+00:00,160,1,432669,A,B,64.82,2,26,8058566324268,128,15132,94252195,CLX5
2025-09-24 19:32:00.409656129+00:00,160,1,432669,C,B,64.79,2,26,8058566323256,128,18619,94252246,CLX5
2025-09-24 19:32:00.409698981+00:00,160,1,432669,C,B,64.83,2,26,8058566324265,128,14274,94252250,CLX5
2025-09-24 19:32:00.409709215+00:00,160,1,432669,A,A,64.84,1,26,8058566324290,128,15489,94252257,CLX5
2025-09-24 19:32:00.409761781+00:00,160,1,432669,A,B,64.83,1,26,8058566324294,128,17992,94252264,CLX5
2025-09-24 19:32:00.409844183+00:00,160,1,432669,A,A,64.85,1,26,8058566324295,128,17232,94252266,CLX5
2025-09-24 19:32:00.409947341+00:00,160,1,432669,C,A,64.86,1,26,8058566323560,128,14836,94252276,CLX5
2025-09-24 19:32:00.410219201+00:00,160,1,432669,M,B,64.82,1,26,8058566311303,128,16274,94252296,CLX5
2025-09-24 19:32:00.410326235+00:00,160,1,432669,A,B,64.83,1,26,8058566324312,128,17312,94252326,CLX5
2025-09-24 19:32:00.411018269+00:00,160,1,432669,A,B,64.8,1,26,8058566324324,128,13984,94252374,CLX5
2025-09-24 19:32:00.411205787+00:00,160,1,432669,T,A,64.83,2,26,8058566324327,0,15107,94252399,CLX5
2025-09-24 19:32:00.411205787+00:00,160,1,432669,F,B,64.83,1,26,8058566324294,0,15107,94252399,CLX5
2025-09-24 19:32:00.411205787+00:00,160,1,432669,F,B,64.83,1,26,8058566324312,0,15107,94252399,CLX5
2025-09-24 19:32:00.411205787+00:00,160,1,432669,C,B,64.83,1,26,8058566324294,0,15604,94252400,CLX5
2025-09-24 19:32:00.411205787+00:00,160,1,432669,C,B,64.83,1,26,8058566324312,128,15604,94252400,CLX5
2025-09-24 19:32:00.411366043+00:00,160,1,432669,C,A,64.84,1,26,8058566324290,128,16860,94252414,CLX5
2025-09-24 19:32:00.412012363+00:00,160,1,432669,M,A,64.85,1,26,8058566173085,128,15292,94252440,CLX5
2025-09-24 19:32:00.412089871+00:00,160,1,432669,A,A,64.84,1,26,8058566324336,128,18093,94252442,CLX5
2025-09-24 19:32:00.413956835+00:00,160,1,432669,A,B,64.83,1,26,8058566324343,128,18967,94252485,CLX5
2025-09-24 19:32:00.414565083+00:00,160,1,432669,C,B,64.81,1,26,8058566323766,128,16898,94252535,CLX5
2025-09-24 19:32:00.414568481+00:00,160,1,432669,C,A,64.84,1,26,8058566324336,128,15344,94252536,CLX5
2025-09-24 19:32:00.415467809+00:00,160,1,432669,A,A,64.84,1,26,8058566324359,128,15213,94252551,CLX5
2025-09-24 19:32:00.415882663+00:00,160,1,432669,C,A,64.84,1,26,8058566324359,128,17866,94252554,CLX5
2025-09-24 19:32:00.416372029+00:00,160,1,432669,T,A,64.83,1,26,8058566324369,0,14781,94252588,CLX5
2025-09-24 19:32:00.416372029+00:00,160,1,432669,F,B,64.83,1,26,8058566324343,0,14781,94252588,CLX5
2025-09-24 19:32:00.416372029+00:00,160,1,432669,C,B,64.83,1,26,8058566324343,128,18354,94252589,CLX5
2025-09-24 19:32:00.416373029+00:00,160,1,432669,A,A,64.84,1,26,8058566324370,128,14779,94252593,CLX5
2025-09-24 19:32:00.416594011+00:00,160,1,432669,A,A,64.83,1,26,8058566324375,128,14779,94252603,CLX5
2025-09-24 19:32:00.418379783+00:00,160,1,432669,A,A,64.83,1,26,8058566324402,128,18991,94252700,CLX5
2025-09-24 19:32:00.418409407+00:00,160,1,432669,C,A,64.84,1,26,8058566324370,128,15102,94252704,CLX5
2025-09-24 19:32:00.419200277+00:00,160,1,432669,A,B,64.82,1,26,8058566324408,128,14384,94252730,CLX5
2025-09-24 19:32:00.420192739+00:00,160,1,432669,A,A,64.84,1,26,8058566324420,128,14258,94252757,CLX5
2025-09-24 19:32:00.433505393+00:00,160,1,432669,C,A,64.84,1,26,8058566324420,128,19187,94252844,CLX5
2025-09-24 19:32:00.447001419+00:00,160,1,432669,A,B,64.81,2,26,8058566324443,128,15336,94252858,CLX5
2025-09-24 19:32:00.591435193+00:00,160,1,432669,C,B,64.8,1,26,8058566324324,128,18291,94252972,CLX5
2025-09-24 19:32:00.862851517+00:00,160,1,432669,A,B,64.56,1,26,8058566324512,128,18286,94253013,CLX5
2025-09-24 19:32:01.729889307+00:00,160,1,432669,M,B,64.74,2,26,8058566262123,128,19036,94253082,CLX5
2025-09-24 19:32:02.502334537+00:00,160,1,432669,T,B,64.83,1,26,8058566324545,0,19085,94253154,CLX5
2025-09-24 19:32:02.502334537+00:00,160,1,432669,F,A,64.83,1,26,8058566324375,0,19085,94253154,CLX5
2025-09-24 19:32:02.502334537+00:00,160,1,432669,C,A,64.83,1,26,8058566324375,128,15240,94253155,CLX5
2025-09-24 19:32:02.502355293+00:00,160,1,432669,T,B,64.83,1,26,8058566324547,0,15219,94253158,CLX5
2025-09-24 19:32:02.502355293+00:00,160,1,432669,F,A,64.83,1,26,8058566324402,0,15219,94253158,CLX5
2025-09-24 19:32:02.502355293+00:00,160,1,432669,C,A,64.83,1,26,8058566324402,128,18445,94253159,CLX5
2025-09-24 19:32:02.502624541+00:00,160,1,432669,A,B,64.83,2,26,8058566324549,128,16778,94253165,CLX5
2025-09-24 19:32:02.502624721+00:00,160,1,432669,A,B,64.83,1,26,8058566324550,128,15633,94253167,CLX5
2025-09-24 19:32:02.502666607+00:00,160,1,432669,A,B,64.79,1,26,8058566324553,128,14942,94253171,CLX5
2025-09-24 19:32:02.502717715+00:00,160,1,432669,C,A,64.84,1,26,8058566322055,128,17064,94253174,CLX5
2025-09-24 19:32:02.502717863+00:00,160,1,432669,C,A,64.84,1,26,8058566322056,128,15452,94253175,CLX5
2025-09-24 19:32:02.502889087+00:00,160,1,432669,T,A,64.83,1,26,8058566324558,0,14311,94253185,CLX5
2025-09-24 19:32:02.502889087+00:00,160,1,432669,F,B,64.83,1,26,8058566324549,0,14311,94253185,CLX5
2025-09-24 19:32:02.502889087+00:00,160,1,432669,M,B,64.83,1,26,8058566324549,128,14311,94253185,CLX5
2025-09-24 19:32:02.502930443+00:00,160,1,432669,T,A,64.83,1,26,8058566324559,0,15177,94253190,CLX5
2025-09-24 19:32:02.502930443+00:00,160,1,432669,F,B,64.83,1,26,8058566324549,0,15177,94253190,CLX5
2025-09-24 19:32:02.502930443+00:00,160,1,432669,C,B,64.83,1,26,8058566324549,128,15374,94253191,CLX5
2025-09-24 19:32:02.503140001+00:00,160,1,432669,A,A,64.84,1,26,8058566324561,128,18545,94253199,CLX5
2025-09-24 19:32:02.503189111+00:00,160,1,432669,T,A,64.83,1,26,8058566324562,0,14973,94253200,CLX5
2025-09-24 19:32:02.503189111+00:00,160,1,432669,F,B,64.83,1,26,8058566324550,0,14973,94253200,CLX5
2025-09-24 19:32:02.503189111+00:00,160,1,432669,C,B,64.83,1,26,8058566324550,128,15378,94253201,CLX5
2025-09-24 19:32:02.503250837+00:00,160,1,432669,A,B,64.83,1,26,8058566324565,128,13905,94253209,CLX5
2025-09-24 19:32:02.503303501+00:00,160,1,432669,T,A,64.83,1,26,8058566324568,0,15003,94253215,CLX5
2025-09-24 19:32:02.503303501+00:00,160,1,432669,F,B,64.83,1,26,8058566324565,0,15003,94253215,CLX5
2025-09-24 19:32:02.503303501+00:00,160,1,432669,C,B,64.83,1,26,8058566324565,128,17584,94253216,CLX5
2025-09-24 19:32:02.503401261+00:00,160,1,432669,A,B,64.8,1,26,8058566324570,128,16441,94253220,CLX5
2025-09-24 19:32:02.503412169+00:00,160,1,432669,C,A,64.84,1,26,8058566324561,128,17473,94253222,CLX5
2025-09-24 19:32:02.503726075+00:00,160,1,432669,A,B,64.82,1,26,8058566324577,128,17921,94253237,CLX5
2025-09-24 19:32:02.503982939+00:00,160,1,432669,A,A,64.84,2,26,8058566324579,128,15151,94253242,CLX5
2025-09-24 19:32:02.503986875+00:00,160,1,432669,A,A,64.83,2,26,8058566324580,128,18089,94253244,CLX5
2025-09-24 19:32:02.504100169+00:00,160,1,432669,A,B,64.82,1,26,8058566324583,128,15216,94253250,CLX5
2025-09-24 19:32:02.504486571+00:00,160,1,432669,A,B,64.82,1,26,8058566324586,128,18891,94253264,CLX5
2025-09-24 19:32:02.504697109+00:00,160,1,432669,C,B,64.82,1,26,8058566324586,128,15127,94253271,CLX5
2025-09-24 19:32:02.504707745+00:00,160,1,432669,C,B,64.82,1,26,8058566324583,128,18905,94253273,CLX5
2025-09-24 19:32:02.509677445+00:00,160,1,432669,A,A,64.84,1,26,8058566324594,128,18457,94253301,CLX5
2025-09-24 19:32:02.514193491+00:00,160,1,432669,M,A,64.83,1,26,8058566324594,128,18389,94253304,CLX5
2025-09-24 19:32:02.514377151+00:00,160,1,432669,C,B,64.82,1,26,8058566324577,128,18337,94253307,CLX5
2025-09-24 19:32:02.565367375+00:00,160,1,432669,C,B,64.79,1,26,8058566324553,128,19059,94253361,CLX5
2025-09-24 19:32:02.681445975+00:00,160,1,432669,C,B,64.8,1,26,8058566324570,128,18619,94253427,CLX5
2025-09-24 19:32:04.315202061+00:00,160,1,432669,C,A,65.04,1,26,8058566320427,128,18183,94253672,CLX5
2025-09-24 19:32:04.341239953+00:00,160,1,432669,A,A,64.83,1,26,8058566324722,128,18447,94253674,CLX5
2025-09-24 19:32:04.341413647+00:00,160,1,432669,A,A,64.83,2,26,8058566324724,128,16580,94253678,CLX5
2025-09-24 19:32:04.377742957+00:00,160,1,432669,A,A,65.03,1,26,8058566324730,128,18033,94253690,CLX5
2025-09-24 19:32:06.750651941+00:00,160,1,432669,C,A,66.0,1,26,8058564175332,128,24519,94253916,CLX5
2025-09-24 19:32:08.203647011+00:00,160,1,432669,A,A,64.83,1,26,8058566324837,128,20077,94254128,CLX5
2025-09-24 19:32:09.016589697+00:00,160,1,432669,C,A,66.0,1,26,8058564180198,128,18954,94254192,CLX5
2025-09-24 19:32:09.318804471+00:00,160,1,432669,C,B,64.82,2,26,8058566324268,128,21557,94254317,CLX5
2025-09-24 19:32:09.318826993+00:00,160,1,432669,C,B,64.82,1,26,8058566323724,128,18041,94254321,CLX5
2025-09-24 19:32:09.318841411+00:00,160,1,432669,A,B,64.81,1,26,8058566324948,128,18041,94254321,CLX5
2025-09-24 19:32:09.319451463+00:00,160,1,432669,C,A,64.83,1,26,8058566324837,128,18823,94254350,CLX5
2025-09-24 19:32:14.528557307+00:00,160,1,432669,T,A,64.82,1,26,8058566325441,0,18409,94255296,CLX5
2025-09-24 19:32:14.528557307+00:00,160,1,432669,F,B,64.82,1,26,8058566321823,0,18409,94255296,CLX5
2025-09-24 19:32:14.528557307+00:00,160,1,432669,C,B,64.82,1,26,8058566321823,128,15395,94255297,CLX5
2025-09-24 19:32:14.528883657+00:00,160,1,432669,A,A,64.83,1,26,8058566325444,128,16536,94255301,CLX5
2025-09-24 19:32:14.528908729+00:00,160,1,432669,A,A,64.83,1,26,8058566325445,128,17612,94255302,CLX5
2025-09-24 19:32:15.045290367+00:00,160,1,432669,C,B,64.81,2,26,8058566324443,128,15222,94255346,CLX5
2025-09-24 19:32:15.045432193+00:00,160,1,432669,A,A,64.83,1,26,8058566325454,128,16217,94255357,CLX5
2025-09-24 19:32:15.045463065+00:00,160,1,432669,A,B,64.82,1,26,8058566325455,128,15053,94255363,CLX5
2025-09-24 19:32:15.109720445+00:00,160,1,432669,A,B,64.81,2,26,8058566325459,128,18453,94255380,CLX5
2025-09-24 19:32:15.136510097+00:00,160,1,432669,C,B,64.81,2,26,8058566325459,128,18882,94255382,CLX5
2025-09-24 19:32:15.136541067+00:00,160,1,432669,C,B,64.82,1,26,8058566325455,128,16422,94255388,CLX5
2025-09-24 19:32:15.137203093+00:00,160,1,432669,A,A,64.83,2,26,8058566325461,128,19894,94255401,CLX5
2025-09-24 19:32:15.137379685+00:00,160,1,432669,A,A,64.83,1,26,8058566325472,128,18463,94255436,CLX5
2025-09-24 19:32:15.138217575+00:00,160,1,432669,A,B,64.81,2,26,8058566325476,128,18541,94255455,CLX5
2025-09-24 19:32:15.138228403+00:00,160,1,432669,A,B,64.82,1,26,8058566325481,128,14954,94255460,CLX5
2025-09-24 19:32:15.138256089+00:00,160,1,432669,C,B,64.82,1,26,8058566325481,128,15280,94255463,CLX5
2025-09-24 19:32:15.138640185+00:00,160,1,432669,A,B,64.82,1,26,8058566325485,128,18563,94255476,CLX5
2025-09-24 19:32:15.138798137+00:00,160,1,432669,C,B,64.82,1,26,8058566325485,128,15169,94255479,CLX5
2025-09-24 19:32:15.141054807+00:00,160,1,432669,C,B,64.81,2,26,8058566325476,128,18530,94255495,CLX5
2025-09-24 19:32:15.141059185+00:00,160,1,432669,A,A,64.83,1,26,8058566325492,128,14841,94255497,CLX5
2025-09-24 19:32:15.142496969+00:00,160,1,432669,A,B,64.81,2,26,8058566325510,128,18495,94255559,CLX5
2025-09-24 19:32:15.286790953+00:00,160,1,432669,C,B,64.81,2,26,8058566325510,128,19080,94255600,CLX5
2025-09-24 19:32:15.286974305+00:00,160,1,432669,C,A,64.83,1,26,8058566325472,128,17907,94255609,CLX5
2025-09-24 19:32:15.287173055+00:00,160,1,432669,A,B,64.82,1,26,8058566325529,128,18433,94255623,CLX5
2025-09-24 19:32:15.287438405+00:00,160,1,432669,C,B,64.82,1,26,8058566325529,128,18608,94255630,CLX5
2025-09-24 19:32:15.288280655+00:00,160,1,432669,A,B,64.81,2,26,8058566325556,128,14200,94255728,CLX5
2025-09-24 19:32:15.289410945+00:00,160,1,432669,C,B,64.81,2,26,8058566325556,128,15127,94255788,CLX5
2025-09-24 19:32:15.310057083+00:00,160,1,432669,A,B,64.79,2,26,8058566325603,128,17251,94255865,CLX5
2025-09-24 19:32:15.387346961+00:00,160,1,432669,C,A,64.83,1,26,8058566325492,128,19632,94255909,CLX5
2025-09-24 19:32:15.387350225+00:00,160,1,432669,C,A,64.83,1,26,8058566325444,128,14736,94255910,CLX5
2025-09-24 19:32:15.387490781+00:00,160,1,432669,C,A,64.83,2,26,8058566325461,128,19204,94255912,CLX5
2025-09-24 19:32:15.409734615+00:00,160,1,432669,A,B,64.78,2,26,8058566325641,128,18116,94255937,CLX5
2025-09-24 19:32:16.013989259+00:00,160,1,432669,C,A,64.9,1,26,8058566303277,128,19138,94256057,CLX5
2025-09-24 19:32:16.086347621+00:00,160,1,432669,A,A,64.87,1,26,8058566325711,128,19092,94256059,CLX5
2025-09-24 19:32:18.177730247+00:00,160,1,432669,C,A,64.83,1,26,8058566325445,128,15143,94256162,CLX5
2025-09-24 19:32:18.177739195+00:00,160,1,432669,A,B,64.82,1,26,8058566325750,128,15317,94256163,CLX5
2025-09-24 19:32:18.177994945+00:00,160,1,432669,C,A,64.83,1,26,8058566325454,128,22223,94256177,CLX5
2025-09-24 19:32:25.289679789+00:00,160,1,432669,A,A,64.83,1,26,8058566325778,128,27296,94256235,CLX5
2025-09-24 19:32:25.289877597+00:00,160,1,432669,A,A,64.83,1,26,8058566325779,128,23149,94256236,CLX5
2025-09-24 19:32:25.289923387+00:00,160,1,432669,A,A,64.83,1,26,8058566325780,128,17762,94256240,CLX5
2025-09-24 19:32:25.290020651+00:00,160,1,432669,A,A,64.83,1,26,8058566325781,128,21608,94256242,CLX5
2025-09-24 19:32:25.290437713+00:00,160,1,432669,C,B,64.82,2,26,8058566324266,128,17702,94256253,CLX5
2025-09-24 19:32:25.290513723+00:00,160,1,432669,A,A,64.83,2,26,8058566325785,128,20038,94256256,CLX5
2025-09-24 19:32:28.785223269+00:00,160,1,432669,A,A,64.83,1,26,8058566325806,128,24765,94256311,CLX5
2025-09-24 19:32:28.785236863+00:00,160,1,432669,C,B,64.82,2,26,8058566324267,128,18643,94256312,CLX5
2025-09-24 19:32:28.785242469+00:00,160,1,432669,C,B,64.82,1,26,8058566325750,128,19365,94256313,CLX5
2025-09-24 19:32:28.785377305+00:00,160,1,432669,C,B,64.82,1,26,8058566323760,128,21955,94256314,CLX5
2025-09-24 19:32:28.785710601+00:00,160,1,432669,C,B,64.82,1,26,8058566323603,128,21337,94256321,CLX5
2025-09-24 19:32:28.786166177+00:00,160,1,432669,A,A,64.86,1,26,8058566325809,128,18763,94256323,CLX5
2025-09-24 19:32:29.325389295+00:00,160,1,432669,A,B,64.82,2,26,8058566325822,128,22107,94256343,CLX5
2025-09-24 19:32:29.325417345+00:00,160,1,432669,A,B,64.82,1,26,8058566325823,128,25645,94256344,CLX5
2025-09-24 19:32:29.325543117+00:00,160,1,432669,C,A,64.83,1,26,8058566325806,128,21960,94256345,CLX5
2025-09-24 19:32:31.120025143+00:00,160,1,432669,A,A,64.83,1,26,8058566325831,128,22443,94256377,CLX5
2025-09-24 19:32:31.835148175+00:00,160,1,432669,C,A,64.83,2,26,8058566325785,128,21298,94256453,CLX5
2025-09-24 19:32:31.835364511+00:00,160,1,432669,C,A,64.83,1,26,8058566325780,128,19978,94256454,CLX5
2025-09-24 19:32:31.835497717+00:00,160,1,432669,C,A,64.83,1,26,8058566325779,128,19443,94256455,CLX5
2025-09-24 19:32:35.910031297+00:00,160,1,432669,M,B,64.54,1,26,8058566324512,128,29735,94256750,CLX5
2025-09-24 19:32:39.957829595+00:00,160,1,432669,A,A,64.83,1,26,8058566325939,128,21657,94256767,CLX5
2025-09-24 19:32:39.957856473+00:00,160,1,432669,A,A,64.83,2,26,8058566325940,128,22577,94256768,CLX5
2025-09-24 19:32:39.957863635+00:00,160,1,432669,A,A,64.83,1,26,8058566325941,128,18715,94256769,CLX5
2025-09-24 19:32:39.957980883+00:00,160,1,432669,A,A,64.83,1,26,8058566325942,128,21965,94256772,CLX5
2025-09-24 19:32:39.958182379+00:00,160,1,432669,A,A,64.84,1,26,8058566325943,128,18371,94256775,CLX5
2025-09-24 19:32:39.958216687+00:00,160,1,432669,C,B,64.82,2,26,8058566325822,128,15563,94256776,CLX5
2025-09-24 19:32:40.058664257+00:00,160,1,432669,M,A,64.83,1,26,8058566325943,128,19841,94256795,CLX5
2025-09-24 19:32:40.058824071+00:00,160,1,432669,C,B,64.82,1,26,8058566325823,128,18883,94256796,CLX5
2025-09-24 19:32:40.058966643+00:00,160,1,432669,C,B,64.82,1,26,8058566323763,128,18765,94256797,CLX5
2025-09-24 19:32:40.058967795+00:00,160,1,432669,A,B,64.82,1,26,8058566325949,128,15503,94256798,CLX5
2025-09-24 19:32:40.059113403+00:00,160,1,432669,C,B,64.82,1,26,8058566325949,128,18505,94256799,CLX5
2025-09-24 19:32:40.059149035+00:00,160,1,432669,A,B,64.82,1,26,8058566325950,128,15297,94256800,CLX5
2025-09-24 19:32:40.059281931+00:00,160,1,432669,A,B,64.82,1,26,8058566325951,128,18279,94256801,CLX5
2025-09-24 19:32:40.059414867+00:00,160,1,432669,C,A,64.83,1,26,8058566325942,128,18895,94256802,CLX5
2025-09-24 19:32:40.699428297+00:00,160,1,432669,A,B,64.72,1,26,8058566325952,128,20364,94256804,CLX5
2025-09-24 19:32:40.699585865+00:00,160,1,432669,C,B,64.81,1,26,8058566324948,128,18879,94256805,CLX5
2025-09-24 19:32:42.919615081+00:00,160,1,432669,A,A,64.83,1,26,8058566325955,128,21381,94256829,CLX5
2025-09-24 19:32:42.919641747+00:00,160,1,432669,C,B,64.82,1,26,8058566325950,128,17941,94256835,CLX5
2025-09-24 19:32:42.919652421+00:00,160,1,432669,A,B,64.81,1,26,8058566325959,128,20472,94256837,CLX5
2025-09-24 19:32:42.919801619+00:00,160,1,432669,C,B,64.82,1,26,8058566325951,128,20828,94256839,CLX5
2025-09-24 19:32:42.920019913+00:00,160,1,432669,A,B,64.82,1,26,8058566325962,128,21443,94256847,CLX5
2025-09-24 19:32:42.920358413+00:00,160,1,432669,C,A,64.83,1,26,8058566325955,128,22108,94256849,CLX5
2025-09-24 19:32:42.920932237+00:00,160,1,432669,A,B,64.82,2,26,8058566325963,128,21519,94256853,CLX5
2025-09-24 19:32:47.945027047+00:00,160,1,432669,C,A,64.83,1,26,8058566325939,128,15647,94256963,CLX5
2025-09-24 19:32:47.945049931+00:00,160,1,432669,C,A,64.83,1,26,8058566325941,128,16019,94256967,CLX5
2025-09-24 19:32:47.945183441+00:00,160,1,432669,C,A,64.83,1,26,8058566325781,128,16100,94256973,CLX5
2025-09-24 19:32:47.945325037+00:00,160,1,432669,A,B,64.82,1,26,8058566326005,128,18839,94256982,CLX5
2025-09-24 19:32:47.945382039+00:00,160,1,432669,M,A,64.84,1,26,8058566325943,128,15444,94256985,CLX5
2025-09-24 19:32:50.953661689+00:00,160,1,432669,A,A,64.83,1,26,8058566326135,128,19167,94257249,CLX5
2025-09-24 19:32:50.953866889+00:00,160,1,432669,T,A,64.82,1,26,8058566326136,0,18171,94257251,CLX5
2025-09-24 19:32:50.953866889+00:00,160,1,432669,F,B,64.82,1,26,8058566323002,0,18171,94257251,CLX5
2025-09-24 19:32:50.953866889+00:00,160,1,432669,C,B,64.82,1,26,8058566323002,128,16685,94257252,CLX5
2025-09-24 19:32:50.954172865+00:00,160,1,432669,A,A,64.83,1,26,8058566326138,128,16087,94257257,CLX5
2025-09-24 19:32:50.954176013+00:00,160,1,432669,A,A,64.83,1,26,8058566326139,128,15648,94257259,CLX5
2025-09-24 19:32:50.954180563+00:00,160,1,432669,A,A,64.83,1,26,8058566326140,128,15857,94257260,CLX5
2025-09-24 19:32:50.954183501+00:00,160,1,432669,A,A,64.83,1,26,8058566326141,128,16059,94257261,CLX5
2025-09-24 19:32:50.954373247+00:00,160,1,432669,A,A,64.83,1,26,8058566326143,128,15339,94257264,CLX5
2025-09-24 19:32:50.954564259+00:00,160,1,432669,M,A,64.83,1,26,8058566325943,128,14692,94257275,CLX5
2025-09-24 19:32:50.954806263+00:00,160,1,432669,C,B,64.82,1,26,8058566326005,128,18931,94257283,CLX5
2025-09-24 19:32:51.199022547+00:00,160,1,432669,C,B,64.82,1,26,8058566325962,128,15258,94257335,CLX5
2025-09-24 19:32:51.199168097+00:00,160,1,432669,C,B,64.82,2,26,8058566325963,128,18582,94257344,CLX5
2025-09-24 19:32:51.199803243+00:00,160,1,432669,A,B,64.82,1,26,8058566326161,128,17987,94257345,CLX5
2025-09-24 19:32:51.199942265+00:00,160,1,432669,C,A,64.83,1,26,8058566326143,128,18796,94257349,CLX5
2025-09-24 19:32:51.200042061+00:00,160,1,432669,C,B,64.82,1,26,8058566326161,128,18356,94257353,CLX5
2025-09-24 19:32:51.200313709+00:00,160,1,432669,A,B,64.82,2,26,8058566326167,128,15231,94257368,CLX5
2025-09-24 19:32:51.200415695+00:00,160,1,432669,M,A,64.94,1,26,8058565075241,128,15013,94257370,CLX5
2025-09-24 19:32:51.200609011+00:00,160,1,432669,C,B,64.82,2,26,8058566326167,128,14377,94257381,CLX5
2025-09-24 19:32:51.201342419+00:00,160,1,432669,A,B,64.82,2,26,8058566326174,128,16328,94257403,CLX5
2025-09-24 19:32:51.202303779+00:00,160,1,432669,A,B,64.82,1,26,8058566326177,128,19113,94257416,CLX5
2025-09-24 19:32:51.202308023+00:00,160,1,432669,C,A,64.83,1,26,8058566326141,128,15419,94257417,CLX5
2025-09-24 19:32:51.202332865+00:00,160,1,432669,C,B,64.82,1,26,8058566326177,128,14829,94257421,CLX5
2025-09-24 19:32:51.202408223+00:00,160,1,432669,M,A,64.95,1,26,8058565075241,128,14958,94257423,CLX5
2025-09-24 19:32:51.202532305+00:00,160,1,432669,A,A,64.83,1,26,8058566326180,128,20524,94257425,CLX5
2025-09-24 19:32:51.202576521+00:00,160,1,432669,A,B,64.82,1,26,8058566326181,128,14476,94257426,CLX5
2025-09-24 19:32:51.252108935+00:00,160,1,432669,C,A,64.83,1,26,8058566326180,128,15333,94257467,CLX5
2025-09-24 19:32:51.252240489+00:00,160,1,432669,C,A,64.83,1,26,8058566326139,128,15499,94257470,CLX5
2025-09-24 19:32:51.252242487+00:00,160,1,432669,A,A,64.83,1,26,8058566326195,128,17703,94257471,CLX5
2025-09-24 19:32:51.252242965+00:00,160,1,432669,C,A,64.83,1,26,8058566326140,128,15410,94257472,CLX5
2025-09-24 19:32:51.252395465+00:00,160,1,432669,A,A,64.83,1,26,8058566326196,128,18457,94257476,CLX5
2025-09-24 19:32:51.252759883+00:00,160,1,432669,C,A,64.83,1,26,8058566326195,128,15517,94257489,CLX5
2025-09-24 19:32:51.954729425+00:00,160,1,432669,C,B,64.82,1,26,8058566326181,128,18560,94257581,CLX5
2025-09-24 19:32:51.954733363+00:00,160,1,432669,A,A,64.83,1,26,8058566326246,128,14657,94257582,CLX5
2025-09-24 19:32:53.934727825+00:00,160,1,432669,T,N,64.83,2,26,0,0,18491,94257796,CLX5
2025-09-24 19:32:53.934727825+00:00,160,1,432669,F,N,64.83,2,26,8058566324580,0,18491,94257796,CLX5
2025-09-24 19:32:53.934727825+00:00,160,1,432669,C,A,64.83,2,26,8058566324580,128,15197,94257797,CLX5
2025-09-24 19:32:53.935567079+00:00,160,1,432669,A,B,64.82,1,26,8058566326342,128,18320,94257821,CLX5
2025-09-24 19:32:53.935575659+00:00,160,1,432669,C,A,64.83,1,26,8058566326196,128,18555,94257826,CLX5
2025-09-24 19:32:53.935597989+00:00,160,1,432669,C,A,64.83,1,26,8058566326246,128,15412,94257834,CLX5
2025-09-24 19:32:53.935603671+00:00,160,1,432669,A,B,64.82,1,26,8058566326351,128,15503,94257837,CLX5
2025-09-24 19:32:53.935610351+00:00,160,1,432669,C,B,64.82,2,26,8058566326174,128,18458,94257839,CLX5
2025-09-24 19:32:53.935997815+00:00,160,1,432669,A,A,64.83,1,26,8058566326357,128,18491,94257863,CLX5
2025-09-24 19:32:53.936001939+00:00,160,1,432669,A,A,64.83,1,26,8058566326358,128,14363,94257865,CLX5
2025-09-24 19:32:53.936123391+00:00,160,1,432669,C,A,64.83,1,26,8058566326358,128,15677,94257867,CLX5
2025-09-24 19:32:53.936380199+00:00,160,1,432669,A,A,64.83,1,26,8058566326364,128,15130,94257875,CLX5
2025-09-24 19:32:53.936414105+00:00,160,1,432669,A,A,64.83,1,26,8058566326365,128,14600,94257878,CLX5
2025-09-24 19:32:53.939868609+00:00,160,1,432669,A,A,64.83,1,26,8058566326389,128,19418,94257979,CLX5
2025-09-24 19:32:53.946562681+00:00,160,1,432669,C,B,64.82,1,26,8058566326342,128,15232,94258027,CLX5
2025-09-24 19:32:53.946571053+00:00,160,1,432669,C,B,64.82,1,26,8058566326351,128,17406,94258029,CLX5
2025-09-24 19:32:53.946835445+00:00,160,1,432669,C,A,64.83,1,26,8058566326365,128,15209,94258033,CLX5
2025-09-24 19:32:53.946997351+00:00,160,1,432669,A,B,64.82,1,26,8058566326402,128,16217,94258035,CLX5
2025-09-24 19:32:53.987042945+00:00,160,1,432669,C,A,64.83,1,26,8058566326357,128,15389,94258058,CLX5
2025-09-24 19:32:53.987046267+00:00,160,1,432669,C,A,64.83,1,26,8058566326364,128,15735,94258060,CLX5
2025-09-24 19:32:53.987219539+00:00,160,1,432669,A,A,64.83,1,26,8058566326412,128,15322,94258063,CLX5
2025-09-24 19:32:53.987266923+00:00,160,1,432669,C,A,64.83,1,26,8058566326412,128,15343,94258071,CLX5
2025-09-24 19:32:53.987378259+00:00,160,1,432669,A,A,64.83,1,26,8058566326413,128,15188,94258077,CLX5
2025-09-24 19:32:53.987476347+00:00,160,1,432669,C,A,64.83,1,26,8058566326413,128,18662,94258092,CLX5
2025-09-24 19:32:53.987567101+00:00,160,1,432669,A,A,64.83,1,26,8058566326414,128,19384,94258101,CLX5
2025-09-24 19:32:53.987902971+00:00,160,1,432669,A,A,64.83,1,26,8058566326415,128,18414,94258105,CLX5
2025-09-24 19:32:54.316035913+00:00,160,1,432669,A,B,64.82,3,26,8058566326500,128,18693,94258253,CLX5
2025-09-24 19:32:54.316209513+00:00,160,1,432669,C,A,64.83,1,26,8058566326414,128,18772,94258254,CLX5
2025-09-24 19:32:54.316237217+00:00,160,1,432669,C,A,64.83,1,26,8058566326415,128,15324,94258255,CLX5
2025-09-24 19:32:54.316377177+00:00,160,1,432669,C,A,64.83,1,26,8058566326389,128,15819,94258257,CLX5
2025-09-24 19:32:55.354514435+00:00,160,1,432669,A,B,64.82,2,26,8058566326607,128,19313,94258480,CLX5
2025-09-24 19:32:55.354724513+00:00,160,1,432669,C,A,64.86,1,26,8058566325809,128,14693,94258490,CLX5
2025-09-24 19:32:55.354777139+00:00,160,1,432669,M,A,64.84,1,26,8058566325943,128,19853,94258491,CLX5
2025-09-24 19:32:55.356346841+00:00,160,1,432669,A,A,64.83,1,26,8058566326610,128,14701,94258493,CLX5
2025-09-24 19:32:55.356350353+00:00,160,1,432669,A,A,64.83,1,26,8058566326611,128,20037,94258494,CLX5
2025-09-24 19:32:55.356361547+00:00,160,1,432669,A,A,64.83,1,26,8058566326612,128,15824,94258495,CLX5
2025-09-24 19:32:55.356448021+00:00,160,1,432669,A,A,64.83,1,26,8058566326614,128,18887,94258499,CLX5
2025-09-24 19:32:55.356460309+00:00,160,1,432669,C,B,64.82,2,26,8058566326607,128,14500,94258502,CLX5
2025-09-24 19:32:55.356759103+00:00,160,1,432669,C,A,64.83,1,26,8058566326612,128,15384,94258517,CLX5
2025-09-24 19:32:55.356947697+00:00,160,1,432669,A,A,64.83,1,26,8058566326624,128,18608,94258523,CLX5
2025-09-24 19:32:55.357034631+00:00,160,1,432669,A,A,64.86,1,26,8058566326626,128,14772,94258530,CLX5
2025-09-24 19:32:55.357297467+00:00,160,1,432669,C,A,64.83,1,26,8058566326611,128,18215,94258545,CLX5
2025-09-24 19:32:55.357297639+00:00,160,1,432669,C,A,64.83,1,26,8058566326610,128,15105,94258546,CLX5
2025-09-24 19:32:55.357810641+00:00,160,1,432669,A,A,64.83,1,26,8058566326635,128,15625,94258561,CLX5
2025-09-24 19:32:55.358073573+00:00,160,1,432669,A,A,64.83,1,26,8058566326638,128,19055,94258569,CLX5
2025-09-24 19:32:55.358146147+00:00,160,1,432669,C,A,64.83,1,26,8058566326638,128,15826,94258571,CLX5
2025-09-24 19:32:55.358164137+00:00,160,1,432669,C,A,64.83,1,26,8058566326624,128,14499,94258573,CLX5
2025-09-24 19:32:55.381209687+00:00,160,1,432669,C,A,64.83,1,26,8058566326614,128,19519,94258587,CLX5
2025-09-24 19:32:55.381355925+00:00,160,1,432669,C,A,64.83,1,26,8058566326635,128,18889,94258588,CLX5
2025-09-24 19:32:55.410815703+00:00,160,1,432669,A,A,64.83,1,26,8058566326647,128,19564,94258602,CLX5
2025-09-24 19:32:55.410956835+00:00,160,1,432669,A,A,64.83,1,26,8058566326648,128,18854,94258604,CLX5
2025-09-24 19:32:55.456699931+00:00,160,1,432669,M,A,64.83,1,26,8058566325943,128,19669,94258624,CLX5
2025-09-24 19:32:55.661722643+00:00,160,1,432669,C,A,64.86,1,26,8058566326626,128,18805,94258656,CLX5
2025-09-24 19:32:56.885196949+00:00,160,1,432669,C,A,64.83,1,26,8058566326135,128,20710,94258742,CLX5
2025-09-24 19:32:56.885415359+00:00,160,1,432669,C,A,64.83,1,26,8058566326648,128,15326,94258746,CLX5
2025-09-24 19:32:56.885540191+00:00,160,1,432669,C,A,64.83,1,26,8058566326647,128,19091,94258747,CLX5
2025-09-24 19:32:56.885677349+00:00,160,1,432669,A,A,64.83,1,26,8058566326714,128,19242,94258748,CLX5
2025-09-24 19:32:57.031414073+00:00,160,1,432669,T,A,64.82,1,26,8058566326716,0,18319,94258791,CLX5
2025-09-24 19:32:57.031414073+00:00,160,1,432669,F,B,64.82,1,26,8058566323034,0,18319,94258791,CLX5
2025-09-24 19:32:57.031414073+00:00,160,1,432669,M,B,64.82,1,26,8058566323034,128,15910,94258792,CLX5
2025-09-24 19:32:57.031725405+00:00,160,1,432669,A,A,64.83,1,26,8058566326719,128,14906,94258795,CLX5
2025-09-24 19:32:57.031727709+00:00,160,1,432669,A,A,64.83,1,26,8058566326720,128,15457,94258796,CLX5
2025-09-24 19:32:57.031810457+00:00,160,1,432669,C,A,64.83,1,26,8058566326719,128,18488,94258806,CLX5
2025-09-24 19:32:57.032557325+00:00,160,1,432669,C,B,64.82,1,26,8058566326402,128,15452,94258838,CLX5
2025-09-24 19:32:57.032856753+00:00,160,1,432669,A,A,64.86,1,26,8058566326733,128,15118,94258843,CLX5
2025-09-24 19:32:57.033560711+00:00,160,1,432669,A,B,64.82,1,26,8058566326740,128,15796,94258868,CLX5
2025-09-24 19:32:57.033708333+00:00,160,1,432669,C,B,64.82,1,26,8058566326740,128,18921,94258871,CLX5
2025-09-24 19:32:57.071234959+00:00,160,1,432669,A,B,64.82,1,26,8058566326745,128,18798,94258880,CLX5
2025-09-24 19:32:57.071251721+00:00,160,1,432669,C,B,64.81,1,26,8058566325959,128,14887,94258881,CLX5
2025-09-24 19:32:57.071395637+00:00,160,1,432669,A,B,64.82,1,26,8058566326746,128,18610,94258882,CLX5
2025-09-24 19:33:00.593586879+00:00,160,1,432669,A,B,64.82,1,26,8058566326782,128,20111,94259059,CLX5
2025-09-24 19:33:00.593767371+00:00,160,1,432669,C,A,64.83,1,26,8058566326714,128,19114,94259060,CLX5
2025-09-24 19:33:00.593918987+00:00,160,1,432669,C,A,64.83,1,26,8058566326720,128,18918,94259063,CLX5
2025-09-24 19:33:00.594237981+00:00,160,1,432669,A,A,64.83,1,26,8058566326784,128,19926,94259068,CLX5
2025-09-24 19:33:00.594370703+00:00,160,1,432669,A,A,64.83,1,26,8058566326785,128,14162,94259072,CLX5
2025-09-24 19:33:01.080708849+00:00,160,1,432669,A,A,64.83,1,26,8058566326787,128,16626,94259089,CLX5
2025-09-24 19:33:01.080720505+00:00,160,1,432669,A,A,64.83,1,26,8058566326788,128,18575,94259090,CLX5
2025-09-24 19:33:01.080727299+00:00,160,1,432669,C,B,64.82,1,26,8058566326746,128,15425,94259096,CLX5
2025-09-24 19:33:01.081053437+00:00,160,1,432669,A,B,64.82,1,26,8058566326798,128,15475,94259132,CLX5
2025-09-24 19:33:01.081087457+00:00,160,1,432669,M,A,64.94,1,26,8058565075241,128,16059,94259135,CLX5
2025-09-24 19:33:01.081088301+00:00,160,1,432669,A,A,64.83,1,26,8058566326799,128,15701,94259136,CLX5
2025-09-24 19:33:01.081271117+00:00,160,1,432669,A,A,64.86,2,26,8058566326800,128,15269,94259138,CLX5
2025-09-24 19:33:01.081283135+00:00,160,1,432669,C,B,64.82,1,26,8058566326798,128,18534,94259143,CLX5
2025-09-24 19:33:01.082207863+00:00,160,1,432669,A,B,64.82,1,26,8058566326816,128,18360,94259182,CLX5
2025-09-24 19:33:01.082598257+00:00,160,1,432669,M,A,64.84,3,26,8058566288785,128,18291,94259201,CLX5
2025-09-24 19:33:01.088265847+00:00,160,1,432669,C,A,64.86,2,26,8058566326800,128,14899,94259272,CLX5
2025-09-24 19:33:01.088396267+00:00,160,1,432669,M,A,64.95,1,26,8058565075241,128,19619,94259279,CLX5
2025-09-24 19:33:01.088709347+00:00,160,1,432669,C,A,64.83,1,26,8058566326787,128,20080,94259291,CLX5
2025-09-24 19:33:01.089086035+00:00,160,1,432669,C,A,64.83,1,26,8058566326799,128,15593,94259300,CLX5
2025-09-24 19:33:01.096130587+00:00,160,1,432669,C,A,64.83,1,26,8058566326788,128,18991,94259326,CLX5
2025-09-24 19:33:01.096269379+00:00,160,1,432669,A,A,64.83,1,26,8058566326849,128,19046,94259327,CLX5
2025-09-24 19:33:01.096322041+00:00,160,1,432669,M,A,64.84,1,26,8058566325943,128,16600,94259329,CLX5
2025-09-24 19:33:01.196592155+00:00,160,1,432669,M,A,64.83,1,26,8058566325943,128,19487,94259363,CLX5
2025-09-24 19:33:01.196758149+00:00,160,1,432669,C,B,64.82,1,26,8058566326816,128,18674,94259364,CLX5
2025-09-24 19:33:01.196899839+00:00,160,1,432669,A,B,64.82,1,26,8058566326860,128,18341,94259365,CLX5
2025-09-24 19:33:03.067669185+00:00,160,1,432669,T,N,64.83,1,26,0,0,18340,94259435,CLX5
2025-09-24 19:33:03.067669185+00:00,160,1,432669,F,N,64.83,1,26,8058566324594,0,18340,94259435,CLX5
2025-09-24 19:33:03.067669185+00:00,160,1,432669,C,A,64.83,1,26,8058566324594,128,17181,94259436,CLX5
2025-09-24 19:33:03.068928285+00:00,160,1,432669,A,B,64.82,2,26,8058566326897,128,19183,94259471,CLX5
2025-09-24 19:33:03.069152511+00:00,160,1,432669,C,A,64.83,1,26,8058566326784,128,14913,94259481,CLX5
2025-09-24 19:33:03.069157217+00:00,160,1,432669,C,A,64.83,1,26,8058566326785,128,19241,94259483,CLX5
2025-09-24 19:33:03.069215657+00:00,160,1,432669,M,A,64.84,1,26,8058566325943,128,16593,94259493,CLX5
2025-09-24 19:33:03.069453631+00:00,160,1,432669,A,A,64.83,1,26,8058566326904,128,15950,94259504,CLX5
2025-09-24 19:33:03.069457913+00:00,160,1,432669,A,A,64.83,1,26,8058566326905,128,19140,94259505,CLX5
2025-09-24 19:33:03.069467609+00:00,160,1,432669,C,B,64.82,2,26,8058566326897,128,15188,94259506,CLX5
2025-09-24 19:33:03.069569787+00:00,160,1,432669,C,B,64.82,1,26,8058566326860,128,15156,94259514,CLX5
2025-09-24 19:33:03.069730119+00:00,160,1,432669,A,B,64.82,1,26,8058566326913,128,18796,94259528,CLX5
2025-09-24 19:33:03.069939427+00:00,160,1,432669,A,B,64.82,1,26,8058566326915,128,18220,94259534,CLX5
2025-09-24 19:33:03.075066215+00:00,160,1,432669,A,A,64.83,1,26,8058566326935,128,18871,94259585,CLX5
2025-09-24 19:33:03.169677857+00:00,160,1,432669,M,A,64.83,1,26,8058566325943,128,15751,94259642,CLX5
2025-09-24 19:33:03.169810159+00:00,160,1,432669,C,B,64.82,1,26,8058566326913,128,14640,94259647,CLX5
2025-09-24 19:33:03.169817973+00:00,160,1,432669,C,B,64.82,1,26,8058566326915,128,18673,94259649,CLX5
2025-09-24 19:33:03.170056081+00:00,160,1,432669,A,B,64.82,1,26,8058566326956,128,15431,94259654,CLX5
2025-09-24 19:33:03.488465935+00:00,160,1,432669,C,A,65.22,1,26,8058566273414,128,18884,94259705,CLX5
2025-09-24 19:33:03.519642307+00:00,160,1,432669,A,A,65.14,1,26,8058566326983,128,17852,94259716,CLX5
2025-09-24 19:33:05.017084449+00:00,160,1,432669,C,B,64.82,1,26,8058566326956,128,15452,94259918,CLX5
2025-09-24 19:33:12.739763309+00:00,160,1,432669,A,B,64.82,1,26,8058566327162,128,20059,94260161,CLX5
2025-09-24 19:33:12.740179315+00:00,160,1,432669,A,B,64.82,1,26,8058566327164,128,18533,94260166,CLX5
2025-09-24 19:33:15.597140181+00:00,160,1,432669,M,A,64.96,1,26,8058566157942,128,20184,94260224,CLX5
2025-09-24 19:33:15.855446051+00:00,160,1,432669,T,B,64.83,1,26,8058566327177,0,19391,94260234,CLX5
2025-09-24 19:33:15.855446051+00:00,160,1,432669,F,A,64.83,1,26,8058566324722,0,19391,94260234,CLX5
2025-09-24 19:33:15.855446051+00:00,160,1,432669,C,A,64.83,1,26,8058566324722,128,16902,94260235,CLX5
2025-09-24 19:33:15.855784841+00:00,160,1,432669,A,B,64.82,1,26,8058566327178,128,18945,94260236,CLX5
2025-09-24 19:33:15.855792443+00:00,160,1,432669,C,A,64.83,1,26,8058566326904,128,15363,94260239,CLX5
2025-09-24 19:33:15.856018801+00:00,160,1,432669,A,A,64.83,1,26,8058566327182,128,15707,94260241,CLX5
2025-09-24 19:33:15.856021393+00:00,160,1,432669,C,B,64.82,1,26,8058566327164,128,15667,94260242,CLX5
2025-09-24 19:33:15.856083771+00:00,160,1,432669,M,A,64.84,1,26,8058566325943,128,20095,94260244,CLX5
2025-09-24 19:33:15.856221007+00:00,160,1,432669,A,B,64.82,1,26,8058566327184,128,15522,94260247,CLX5
2025-09-24 19:33:16.388754317+00:00,160,1,432669,C,B,64.82,1,26,8058566327184,128,18365,94260275,CLX5
2025-09-24 19:33:16.389056243+00:00,160,1,432669,A,B,64.82,1,26,8058566327196,128,15414,94260286,CLX5
2025-09-24 19:33:16.389103703+00:00,160,1,432669,M,A,64.83,1,26,8058566325943,128,16769,94260293,CLX5
2025-09-24 19:33:16.389400157+00:00,160,1,432669,C,B,64.82,1,26,8058566327196,128,15867,94260297,CLX5
2025-09-24 19:33:16.389572393+00:00,160,1,432669,A,B,64.82,1,26,8058566327202,128,19148,94260298,CLX5
2025-09-24 19:33:16.389604569+00:00,160,1,432669,C,A,64.86,1,26,8058566326733,128,15265,94260299,CLX5
2025-09-24 19:33:16.695796431+00:00,160,1,432669,C,A,64.83,1,26,8058566327182,128,18817,94260323,CLX5
2025-09-24 19:33:16.695932207+00:00,160,1,432669,A,A,64.83,1,26,8058566327209,128,18629,94260324,CLX5
2025-09-24 19:33:16.695944785+00:00,160,1,432669,M,A,64.84,1,26,8058566325943,128,16144,94260325,CLX5
2025-09-24 19:33:16.695945109+00:00,160,1,432669,C,A,64.83,1,26,8058566326905,128,15858,94260326,CLX5
2025-09-24 19:33:17.218873717+00:00,160,1,432669,C,A,64.83,1,26,8058566326849,128,15821,94260562,CLX5
2025-09-24 19:33:17.220996049+00:00,160,1,432669,C,A,64.83,1,26,8058566327209,128,16551,94260692,CLX5
2025-09-24 19:33:17.222704871+00:00,160,1,432669,A,B,64.82,1,26,8058566327347,128,18616,94260798,CLX5
2025-09-24 19:33:17.222870211+00:00,160,1,432669,A,B,64.82,2,26,8058566327349,128,15272,94260811,CLX5
2025-09-24 19:33:17.223479959+00:00,160,1,432669,A,B,64.81,2,26,8058566327364,128,19204,94260861,CLX5
2025-09-24 19:33:17.223484661+00:00,160,1,432669,C,A,64.83,2,26,8058566325940,128,16552,94260865,CLX5
2025-09-24 19:33:17.223489635+00:00,160,1,432669,C,B,64.78,2,26,8058566325641,128,18644,94260867,CLX5
2025-09-24 19:33:17.224172203+00:00,160,1,432669,A,A,64.83,1,26,8058566327387,128,20778,94260920,CLX5
2025-09-24 19:33:17.224182763+00:00,160,1,432669,A,A,64.83,1,26,8058566327389,128,16159,94260923,CLX5
2025-09-24 19:33:17.224195971+00:00,160,1,432669,A,A,64.83,1,26,8058566327390,128,18152,94260924,CLX5
2025-09-24 19:33:17.224244835+00:00,160,1,432669,C,B,64.82,2,26,8058566327349,128,15750,94260926,CLX5
2025-09-24 19:33:17.224311915+00:00,160,1,432669,C,A,64.83,1,26,8058566327389,128,16489,94260929,CLX5
2025-09-24 19:33:17.224315257+00:00,160,1,432669,C,A,64.83,1,26,8058566327390,128,19433,94260930,CLX5
2025-09-24 19:33:17.224719571+00:00,160,1,432669,C,B,64.81,2,26,8058566327364,128,15714,94260940,CLX5
2025-09-24 19:33:17.225886841+00:00,160,1,432669,T,B,64.83,1,26,8058566327403,0,15138,94260979,CLX5
2025-09-24 19:33:17.225886841+00:00,160,1,432669,F,A,64.83,1,26,8058566324724,0,15138,94260979,CLX5
2025-09-24 19:33:17.225886841+00:00,160,1,432669,M,A,64.83,1,26,8058566324724,128,16896,94260980,CLX5
2025-09-24 19:33:17.225887457+00:00,160,1,432669,A,A,64.83,1,26,8058566327404,128,19434,94260981,CLX5
2025-09-24 19:33:17.226285455+00:00,160,1,432669,C,B,64.82,1,26,8058566327162,128,22543,94261020,CLX5
2025-09-24 19:33:17.226330725+00:00,160,1,432669,A,B,64.82,2,26,8058566327423,128,19386,94261032,CLX5
2025-09-24 19:33:17.226735847+00:00,160,1,432669,A,A,64.83,1,26,8058566327430,128,14820,94261051,CLX5
2025-09-24 19:33:17.226736153+00:00,160,1,432669,A,A,64.83,1,26,8058566327431,128,18834,94261053,CLX5
2025-09-24 19:33:17.226797821+00:00,160,1,432669,C,A,64.83,1,26,8058566327404,128,15957,94261057,CLX5
2025-09-24 19:33:17.226834185+00:00,160,1,432669,C,A,64.83,1,26,8058566327431,128,16318,94261060,CLX5
2025-09-24 19:33:17.227044013+00:00,160,1,432669,C,B,64.82,1,26,8058566327202,128,16407,94261065,CLX5
2025-09-24 19:33:17.227477107+00:00,160,1,432669,A,A,64.83,1,26,8058566327439,128,20298,94261069,CLX5
2025-09-24 19:33:17.227478393+00:00,160,1,432669,A,A,64.83,1,26,8058566327440,128,16046,94261070,CLX5
2025-09-24 19:33:17.227480103+00:00,160,1,432669,A,B,64.82,1,26,8058566327441,128,15727,94261071,CLX5
2025-09-24 19:33:17.227965131+00:00,160,1,432669,C,A,64.83,1,26,8058566327439,128,15268,94261100,CLX5
2025-09-24 19:33:17.227999477+00:00,160,1,432669,C,A,64.83,1,26,8058566327440,128,16457,94261107,CLX5
2025-09-24 19:33:17.228683947+00:00,160,1,432669,C,A,64.83,1,26,8058566327430,128,15437,94261137,CLX5
2025-09-24 19:33:17.229473397+00:00,160,1,432669,A,A,64.83,1,26,8058566327476,128,20148,94261171,CLX5
2025-09-24 19:33:17.229486913+00:00,160,1,432669,A,A,64.83,1,26,8058566327477,128,16382,94261172,CLX5
2025-09-24 19:33:17.229523277+00:00,160,1,432669,C,A,64.83,1,26,8058566327477,128,16339,94261174,CLX5
2025-09-24 19:33:17.229523487+00:00,160,1,432669,C,A,64.83,1,26,8058566327476,128,19829,94261175,CLX5
2025-09-24 19:33:17.229829465+00:00,160,1,432669,A,A,64.83,1,26,8058566327480,128,20679,94261182,CLX5
2025-09-24 19:33:17.231102713+00:00,160,1,432669,A,A,64.83,1,26,8058566327491,128,16590,94261213,CLX5
2025-09-24 19:33:17.231103231+00:00,160,1,432669,A,A,64.83,1,26,8058566327492,128,19630,94261214,CLX5
2025-09-24 19:33:17.231880069+00:00,160,1,432669,C,A,64.83,1,26,8058566327492,128,19920,94261253,CLX5
2025-09-24 19:33:17.231892701+00:00,160,1,432669,C,A,64.83,1,26,8058566327491,128,15169,94261254,CLX5
2025-09-24 19:33:17.232438341+00:00,160,1,432669,A,A,64.83,1,26,8058566327517,128,14826,94261286,CLX5
2025-09-24 19:33:17.233922341+00:00,160,1,432669,C,A,64.83,1,26,8058566327517,128,16360,94261330,CLX5
2025-09-24 19:33:17.234023193+00:00,160,1,432669,C,A,64.83,1,26,8058566327480,128,14820,94261334,CLX5
2025-09-24 19:33:17.234075261+00:00,160,1,432669,C,B,64.82,1,26,8058566326745,128,14502,94261336,CLX5
2025-09-24 19:33:17.235142561+00:00,160,1,432669,C,A,64.83,1,26,8058566327387,128,21165,94261359,CLX5
2025-09-24 19:33:17.237989067+00:00,160,1,432669,A,A,64.83,1,26,8058566327547,128,17432,94261371,CLX5
2025-09-24 19:33:17.237990469+00:00,160,1,432669,A,A,64.83,1,26,8058566327548,128,20255,94261372,CLX5
2025-09-24 19:33:17.238138877+00:00,160,1,432669,C,A,64.83,1,26,8058566327548,128,20336,94261386,CLX5
2025-09-24 19:33:17.240658881+00:00,160,1,432669,A,A,64.83,1,26,8058566327570,128,19670,94261458,CLX5
2025-09-24 19:33:17.240815085+00:00,160,1,432669,C,A,64.83,1,26,8058566327570,128,20914,94261460,CLX5
2025-09-24 19:33:17.240834995+00:00,160,1,432669,A,B,64.81,1,26,8058566327572,128,15273,94261461,CLX5
2025-09-24 19:33:17.256401437+00:00,160,1,432669,M,A,64.94,1,26,8058565075241,128,18525,94261518,CLX5
2025-09-24 19:33:17.258097185+00:00,160,1,432669,M,A,64.95,1,26,8058565075241,128,14878,94261568,CLX5
2025-09-24 19:33:17.259091739+00:00,160,1,432669,A,B,64.81,2,26,8058566327626,128,18549,94261589,CLX5
2025-09-24 19:33:17.259348777+00:00,160,1,432669,A,B,64.82,2,26,8058566327630,128,15415,94261595,CLX5
2025-09-24 19:33:17.296622031+00:00,160,1,432669,A,A,64.83,1,26,8058566327688,128,20241,94261723,CLX5
2025-09-24 19:33:17.296622665+00:00,160,1,432669,C,B,64.81,2,26,8058566327626,128,15942,94261724,CLX5
2025-09-24 19:33:17.296632207+00:00,160,1,432669,A,A,64.83,1,26,8058566327689,128,15972,94261731,CLX5
2025-09-24 19:33:17.296636163+00:00,160,1,432669,C,B,64.82,1,26,8058566327441,128,14201,94261732,CLX5
2025-09-24 19:33:17.296990847+00:00,160,1,432669,A,B,64.82,1,26,8058566327691,128,15906,94261744,CLX5
2025-09-24 19:33:17.297228993+00:00,160,1,432669,A,A,64.83,2,26,8058566327692,128,16372,94261748,CLX5
2025-09-24 19:33:17.300191481+00:00,160,1,432669,M,A,64.94,1,26,8058565075241,128,14644,94261807,CLX5
2025-09-24 19:33:17.302814335+00:00,160,1,432669,M,A,64.95,1,26,8058565075241,128,15525,94261862,CLX5
2025-09-24 19:33:17.308955665+00:00,160,1,432669,C,A,64.83,2,26,8058566327692,128,16693,94261883,CLX5
2025-09-24 19:33:17.309098373+00:00,160,1,432669,C,A,64.83,1,26,8058566327689,128,20085,94261885,CLX5
2025-09-24 19:33:17.309102845+00:00,160,1,432669,C,A,64.83,1,26,8058566327688,128,16537,94261886,CLX5
2025-09-24 19:33:17.309230233+00:00,160,1,432669,A,A,64.83,1,26,8058566327725,128,18925,94261887,CLX5
2025-09-24 19:33:17.309232325+00:00,160,1,432669,C,B,64.82,1,26,8058566327691,128,15387,94261888,CLX5
2025-09-24 19:33:17.309371021+00:00,160,1,432669,A,A,64.83,1,26,8058566327727,128,14949,94261891,CLX5
2025-09-24 19:33:17.310163771+00:00,160,1,432669,C,A,64.83,1,26,8058566327727,128,19976,94261894,CLX5
2025-09-24 19:33:17.310284861+00:00,160,1,432669,M,A,64.94,1,26,8058565075241,128,16045,94261896,CLX5
2025-09-24 19:33:17.310473723+00:00,160,1,432669,A,A,64.83,1,26,8058566327728,128,17812,94261899,CLX5
2025-09-24 19:33:17.310636109+00:00,160,1,432669,A,A,64.83,1,26,8058566327730,128,15596,94261905,CLX5
2025-09-24 19:33:17.310643173+00:00,160,1,432669,C,A,64.83,1,26,8058566327728,128,15978,94261906,CLX5
2025-09-24 19:33:17.312688403+00:00,160,1,432669,M,A,64.95,1,26,8058565075241,128,14461,94261919,CLX5
2025-09-24 19:33:17.314193903+00:00,160,1,432669,A,B,64.82,1,26,8058566327740,128,15305,94261941,CLX5
2025-09-24 19:33:17.314348189+00:00,160,1,432669,C,B,64.82,1,26,8058566327740,128,17468,94261942,CLX5
2025-09-24 19:33:17.314477705+00:00,160,1,432669,A,B,64.82,1,26,8058566327741,128,19376,94261943,CLX5
2025-09-24 19:33:17.314609431+00:00,160,1,432669,C,B,64.82,1,26,8058566327741,128,18856,94261944,CLX5
2025-09-24 19:33:17.314734225+00:00,160,1,432669,A,B,64.82,1,26,8058566327742,128,18577,94261945,CLX5
2025-09-24 19:33:17.314869081+00:00,160,1,432669,C,B,64.82,1,26,8058566327742,128,18982,94261946,CLX5
2025-09-24 19:33:17.315322181+00:00,160,1,432669,C,A,64.83,1,26,8058566327730,128,15369,94261957,CLX5
2025-09-24 19:33:17.315442521+00:00,160,1,432669,C,A,64.83,1,26,8058566327547,128,22156,94261958,CLX5
2025-09-24 19:33:17.316002233+00:00,160,1,432669,A,A,64.83,1,26,8058566327747,128,16350,94261965,CLX5
2025-09-24 19:33:17.316151507+00:00,160,1,432669,C,A,64.83,1,26,8058566327747,128,19666,94261966,CLX5
2025-09-24 19:33:17.316278163+00:00,160,1,432669,A,A,64.83,1,26,8058566327748,128,18252,94261967,CLX5
2025-09-24 19:33:17.319823499+00:00,160,1,432669,A,A,64.83,2,26,8058566327755,128,20047,94261984,CLX5
2025-09-24 19:33:17.319828663+00:00,160,1,432669,A,A,64.83,1,26,8058566327756,128,15987,94261985,CLX5
2025-09-24 19:33:17.319975019+00:00,160,1,432669,C,A,64.83,1,26,8058566327756,128,19494,94261986,CLX5
2025-09-24 19:33:17.320104727+00:00,160,1,432669,C,A,64.83,1,26,8058566327748,128,19459,94261990,CLX5
2025-09-24 19:33:17.320104997+00:00,160,1,432669,A,B,64.82,1,26,8058566327757,128,14471,94261991,CLX5
2025-09-24 19:33:17.320151803+00:00,160,1,432669,A,A,64.83,1,26,8058566327758,128,16179,94261993,CLX5
2025-09-24 19:33:17.320320123+00:00,160,1,432669,A,A,64.83,1,26,8058566327759,128,16635,94261997,CLX5
2025-09-24 19:33:17.320320737+00:00,160,1,432669,C,A,64.83,1,26,8058566327758,128,14579,94261998,CLX5
2025-09-24 19:33:17.341513741+00:00,160,1,432669,C,B,64.82,1,26,8058566327757,128,19695,94262035,CLX5
2025-09-24 19:33:17.341514357+00:00,160,1,432669,A,A,64.83,1,26,8058566327775,128,15955,94262036,CLX5
2025-09-24 19:33:17.341632737+00:00,160,1,432669,M,A,64.94,1,26,8058565075241,128,14575,94262037,CLX5
2025-09-24 19:33:17.343243951+00:00,160,1,432669,C,A,64.83,1,26,8058566327759,128,19455,94262075,CLX5
2025-09-24 19:33:17.343244393+00:00,160,1,432669,A,B,64.82,1,26,8058566327787,128,15074,94262076,CLX5
2025-09-24 19:33:17.343245717+00:00,160,1,432669,C,A,64.83,1,26,8058566327775,128,15044,94262077,CLX5
2025-09-24 19:33:17.343360085+00:00,160,1,432669,M,A,64.95,1,26,8058565075241,128,16362,94262078,CLX5
2025-09-24 19:33:17.343384681+00:00,160,1,432669,A,A,64.83,1,26,8058566327789,128,18666,94262079,CLX5
2025-09-24 19:33:17.343420911+00:00,160,1,432669,C,A,64.83,1,26,8058566327789,128,16079,94262080,CLX5
2025-09-24 19:33:17.343461093+00:00,160,1,432669,C,A,64.83,2,26,8058566327755,128,14638,94262083,CLX5
2025-09-24 19:33:17.343587519+00:00,160,1,432669,C,B,64.82,1,26,8058566327787,128,17685,94262086,CLX5
2025-09-24 19:33:17.343794275+00:00,160,1,432669,A,A,64.83,1,26,8058566327793,128,15264,94262089,CLX5
2025-09-24 19:33:17.488763779+00:00,160,1,432669,A,A,64.83,1,26,8058566327931,128,19954,94262307,CLX5
2025-09-24 19:33:17.610000327+00:00,160,1,432669,A,B,64.78,2,26,8058566327965,128,18166,94262362,CLX5
2025-09-24 19:33:17.745474221+00:00,160,1,432669,A,B,64.82,1,26,8058566327996,128,14978,94262432,CLX5
2025-09-24 19:33:17.745497085+00:00,160,1,432669,C,A,64.83,1,26,8058566327793,128,19921,94262433,CLX5
2025-09-24 19:33:17.745498007+00:00,160,1,432669,C,A,64.83,1,26,8058566327931,128,17080,94262434,CLX5
2025-09-24 19:33:17.745501425+00:00,160,1,432669,C,B,64.82,1,26,8058566327996,128,17316,94262436,CLX5
2025-09-24 19:33:17.745790621+00:00,160,1,432669,A,B,64.82,1,26,8058566328000,128,18715,94262442,CLX5
2025-09-24 19:33:18.080363305+00:00,160,1,432669,C,B,64.82,1,26,8058566328000,128,14654,94262671,CLX5
2025-09-24 19:33:18.080994055+00:00,160,1,432669,A,A,64.83,1,26,8058566328129,128,17468,94262708,CLX5
2025-09-24 19:33:18.081765093+00:00,160,1,432669,C,A,64.83,1,26,8058566328129,128,16727,94262782,CLX5
2025-09-24 19:33:18.081879961+00:00,160,1,432669,A,A,64.83,2,26,8058566328147,128,19349,94262785,CLX5
2025-09-24 19:33:18.082957861+00:00,160,1,432669,A,A,64.83,1,26,8058566328167,128,14174,94262846,CLX5
2025-09-24 19:33:18.082958667+00:00,160,1,432669,A,B,64.82,1,26,8058566328168,128,15295,94262848,CLX5
